Workbook
Name 积分定价: '2.0大富翁抽奖'!$E$129
Name 骰子价值: '2.0大富翁抽奖'!$E$20

Sheet 路线图
A3: 时间 | C3: 1 | D3: 2 | E3: 3 | F3: 4 | G3: 5 | H3: 6 | I3: 7 | J3: 8 | K3: 9 | L3: 10 | M3: 11 | N3: 12 | O3: 13 | P3: 14 | Q3: 第3周 | R3: 第4周 | S3: 第5周 | T3: 第6周 | U3: 第7周 | V3: 第8周 | W3: 第9周 | X3: 第10周 | Y3: 第11周 | Z3: 第12周 | AA3: 第13周 | AB3: 第14周 | AC3: 第15周 | AD3: 第16周 | AE3: 第17周
A4: 满活跃非r主线 | C4: 10 | D4: 15 | E4: 20 | F4: 25 | G4: 30 | H4: 35 | I4: 40 | J4: 45 | K4: 47 | L4: 49 | M4: 51 | N4: 53 | O4: 55 | P4: 57
A5: 满活跃小R主线（四卡党） | C5: 15 | D5: 25 | E5: 35 | F5: 45 | G5: 48 | H5: 50 | I5: 54 | J5: 55 | K5: 57 | L5: 59 | M5: 61 | N5: 63 | O5: 65 | P5: 67
A6: 满活跃中R主线（四卡党+活动）1000+，日产200抽 | C6: 25 | D6: 35 | E6: 45 | F6: 48 | G6: 50 | H6: 54 | I6: 55 | J6: 57 | K6: 60 | L6: 63 | M6: 66 | N6: 69 | O6: 71 | P6: 73
A7: 满活跃大R主线3000+ | C7: 35 | D7: 40 | E7: 45 | F7: 50 | G7: 55 | H7: 57 | I7: 60 | J7: 63 | K7: 66 | L7: 69 | M7: 73 | N7: 75 | O7: 77 | P7: 80 | Q7: 90.5 | R7: 101 | S7: 108 | T7: 115 | U7: 122 | V7: 129 | W7: 136 | X7: 143 | Y7: 150 | Z7: 157 | AA7: 164 | AB7: 171 | AC7: 178 | AD7: 185 | AE7: 192
A8: 养成 梦灵线 | B8: 梦灵 | C8: 2-3紫（5级 | D8: 东方/镭射 | E8: 亚瑟 | F8: 蜘蛛 | G8: 唐小僧 | H8: 神灯 | I8: 关羽 | J8: 后羿/诸葛/我爱沙 | Q8: 海拉/妲己 | R8: 白素贞 | S8: 零日骇客UP活动 (31天）（35天进普池） | W8: 雅典娜UP (59天） | AB8: 女娲UP (73天） | AE8: 杨戬UP (102天）
B9: 挂件 解锁条件-主角等级 | C9: 弹幕流/全图流/爆发流 | D9: 能量流 | F9: 召唤流 | H9: 共鸣流 | J9: 赛季挂件 (S0) | W9: 赛季挂件 (S1)
B10: 符文 | C10: 开启
A11: 养成 主角线 | B11: 装备 | C11: 开启 | E11: 红装 | Q11: 粉装 | T11: 彩装 | U11: 彩虹装
B12: 武器 | C12: 开局+1 | E12: 开局+1 | P12: 开局+1 | T12: 开局+1
B13: 秘宝 | H13: 开启
B14: 藏品 | Q14: 藏品系统（15天） （静默开启）
B15: 载具 | R15: 载具系统 （22天）
B16: 宠物 | V16: 宠物系统 （60天）
A17: 玩法 | B17: 荧幕争锋 | C17: 开启
B18: 梦域巡航 | C18: 难度1 | E18: 难度2 | H18: 难度3 | L18: 难度4 | P18: 难度5 | Q18: 难度6/难度7 | R18: 难度8 | S18: 难度9 | T18: 难度10 彩虹关1(藏品) | V18: 彩虹2 | Y18: 彩虹3 | AA18: 彩虹4
B19: 海底捞金 | C19: 开启
B20: 贪吃大作战 | E20: 开启 | Q20: 升级
B21: 梦隙迷廊 | R21: 开启
B22: 宠物玩法 | V22: 开启
B23: 赛季玩法 | X23: S1玩法
A24: 活动 | B24: 赛季循环 （长周期投辅线） | C24: S0赛季-梦境启航（过度赛季） | V24: S1赛季-我有一座恐怖屋（主推射手、法师)
C25: 主投：红梦灵及皮肤、红色符文（好词条） 辅投：橙、紫梦灵及皮肤、符文祝福石 进度：B级冒险家+散件 荣誉：主角氛围特效-白日梦想（S） | V25: 主投：粉梦灵皮肤、红色符文（好词条） 辅投：橙、红梦灵及皮肤、符文祝福石 进度：B级 小鬼当家+散件 荣誉：主角氛围特效-百鬼夜行（S）
B26: 周循环 （循环投养成） | D26: 开服冲刺//根据抽数达成配置奖励，同时玩家首日抽卡次数保留到开服冲刺 | J26: 招募冲刺【根据第7天招募次数达成中位数来设置首档和后续的奖励】 | Q26: 符文冲刺(boss) | R26: 秘宝冲刺 （排行投皮肤） | S26: 招募冲刺 | T26: 符文冲刺(boss) | U26: 秘宝冲刺 | V26: 招募冲刺 （跨服） | W26: 符文冲刺 | X26: 秘宝冲刺 | Y26: 招募冲刺 | Z26: 符文冲刺 | AA26: 秘宝冲刺 | AB26: 招募冲刺
Q27: 悬赏（1档） | T27: 悬赏（2档） | W27: 悬赏（3档） | Z27: 悬赏（4档）
Q28: 红符文、随机橙藏品、指定橙藏品 第三周（符文产品） 第四周（载具产品） 第五周（招募冲刺 | T28: 红符文、载具粉零件 第6周（彩虹关的藏品 | W28: 载具粉零件、红符文、指定橙藏品... | Z28: 载具粉零件、红符文、指定橙藏品...
B29: 限时活动 （短周期投核心线) | G29: 橙卡试炼 | K29: 时装抽奖【星轨探测】聚焦皮肤 | O29: 红卡试炼(13-16天) | S29: 粉卡试炼 | V29: 粉卡试炼 | Y29: 粉卡试炼 | AB29: 粉卡试炼
G30: 橙卡皮肤 专属符文（红卡预告） | K30: 天使套-A （S0） | O30: 红卡皮肤 专属符文 | S30: 粉卡皮肤 专属符文 | V30: 粉卡皮肤 专属符文 | Y30: 粉卡皮 肤专属符文 | AB30: 粉卡皮肤 专属符文
B34: 1.梦灵节奏适当压缩了一点（粉卡阶段采用的蔚蓝上一版本的节奏，因为我们存量不够）
B36: 2.三类活动线的做了调整：
B37: 月活动→赛季：主要做主轴目标和荣誉追求，投放辅线的资源
B38: 周循环活动：做中小R的钻石消耗和付费转化，主要承载中小R的长期目标和小额付费转化，投放养成资源
B39: 限时活动：拉收，短周期，投放核心资源
B40: 一个核心调整思路就是要把一些投放内容隔离到只有限时活动投放
B42: 3.目前盘下来，需要一个大颗粒度的投放内容去支撑上面这个投放结构，目前考虑下来还是藏品比较合适。对应的秘宝的价值要做上去，现在被当成藏品在投放。
B44: 首周：
B45: 1.关卡战力压制
B46: 2.梦灵节点追求
B48: 次周：
B49: 1.符文概率调整
...

Sheet 甘特图
A2: 功能新增 | P2: 藏品 | W2: 载具 | AF2: 粉卡
A3: 天数 | B3: 1 | C3: 2 | D3: 3 | E3: 4 | F3: 5 | G3: 6 | H3: 7 | I3: 8 | J3: 9 | K3: 10 | L3: 11 | M3: 12 | N3: 13 | O3: 14 | P3: 15 | Q3: 16 | R3: 17 | S3: 18 | T3: 19 | U3: 20 | V3: 21 | W3: 22 | X3: 23 | Y3: 24 | Z3: 25 | AA3: 26 | AB3: 27 | AC3: 28 | AD3: 29 | AE3: 30 | AF3: 31 | AG3: 32 | AH3: 33 | AI3: 34 | AJ3: 35 | AK3: 36 | AL3: 37 | AM3: 38 | AN3: 39 | AO3: 40 | AP3: 41 | AQ3: 42 | AR3: 43 | AS3: 44 | AT3: 45 | AU3: 46 | AV3: 47 | AW3: 48 | AX3: 49 | AY3: 50 | AZ3: 51 | BA3: 52 | BB3: 53 | BC3: 54 | BD3: 55 | BE3: 56 | BF3: 57 | BG3: 58 | BH3: 59 | BI3: 60 | BJ3: 61 | BK3: 62 | BL3: 63
A4: 活动 | B4: 6元首冲
A5: 活动 | B5: 每日特惠(1、6、18) 优化1、6、18元随机宝箱，提高返利
A6: 活动 | B6: 日/周/月礼包
A7: 活动 | B7: 每日充值(25元赠送1个传说祝福石)
A8: 活动 | B8: 大小月卡 18/30
A9: 活动 | B9: 体力战令28/68 | P9: 体力战令28/68（68元增加自选，加一些材料） | AD9: 体力战令28/68（68元增加自选）
A10: 活动 | B10: 周卡（新增金币扫荡） | I10: 周卡（金币扫荡） | P10: 周卡（金币扫荡） | W10: 周卡（（组队双倍）（金币扫荡） | AD10: 周卡（（组队双倍）（金币扫荡） | AK10: 周卡（（组队双倍）（金币扫荡）
A11: 活动 | B11: 钻石战令Ⅰ Ⅱ | W11: 载具战令
A12: 活动 | B12: 七日目标//玩法活跃引导
A13: 活动 | B13: 章节礼包
A14: 活动 | B14: 招募狂欢（3200） | I14: 招募冲刺（红卡魂魄） | P14: 符文冲刺（符文宝石） | W14: 秘宝冲刺（秘宝皮肤） | AD14: 招募冲刺（粉卡魂魄）（藏品） | AK14: 符文冲刺（符文宝石） | AR14: 秘宝冲刺（皮肤+藏品） | AY14: 招募冲刺（粉卡魂魄）（藏品） | BF14: 符文冲刺（符文宝石）
A15: 活动 | F15: 橙卡试炼【皮肤、符文】 | L15: 红卡试炼【符文、皮肤】
A16: 活动 | D16: 礼包
A17: 活动 | P17: 悬赏活动1【符文洗炼藏品】 | W17: 悬赏活动2【组队藏品】 | AD17: 悬赏活动3【招募藏品】 | AK17: 悬赏活动1【周卡迷廊藏品】 | AR17: 悬赏活动2【组队藏品】 | AY17: 悬赏活动3【招募藏品】 | BF17: 悬赏活动1【符文洗炼藏品、符文】
A18: 活动 | B18: 月度活动（红色皮肤、专属符文（限制1个4档）主要是投放皮肤） | AF18: 次月活动（粉卡皮肤）
A19: 限时活动 | I19: 皮肤（天使套）直抽月光炼梦改【5+5】A | P19: 神秘套【月光炼梦】 | AB19: 载具转盘（主投皮肤）星轨探测改（A）
A20: 限时UP | W20: 宇宙套【月光炼梦】 | AF20: 限时up（15天）（骇客） | AU20: 限时up（15天）（雅典娜）

Sheet 价值表
H2: 主要投放途径
B3: 序号 | C3: 道具名称 | D3: 道具ID | E3: 类别 | F3: 钻石价值 | G3: RMB售价 | H3: 途径1 | I3: 途径2 | J3: 标准折扣 | K3: 备注 | L3: 整体思路
B4: 1 | C4: 钻石 | D4: 1 | E4: 货币类 | F4: 1 | G4: 0.1 | H4: 任务/成就/主线三星 | I4: 充值 | J4: 5 | L4: 做各阶层的能力阶梯
B5: 2 | C5: 体力 | D5: 13 | F5: 2 | G5: 0.2 | H5: 快捷购买 | J5: 7
B6: 3 | C6: 金币 | D6: 2 | F6: 0.05 | G6: 0.005 | H6: 日周月商店 | J6: 5
B7: 4 | C7: 心梦宝石 | D7: 44 | F7: 10 | G7: 1.4 | H7: 每日特惠 | I7: 排行冲刺 | J7: 2 | L7: 做中R的付费质感（前期中R）
B8: 5 | C8: 战令宝箱 | D8: 20003 | F8: 30
B9: 6 | C9: 每日特惠宝箱 | D9: 20033 | F9: 40
B10: 7 | C10: 咩菲特的雕像 | D10: 5800004 | F10: 30 | G10: 3
B11: 8 | C11: 织梦宝箱 | D11: 5800005 | F11: 50
B12: 9 | C12: 筑梦快递箱 | D12: 20034 | F12: 250
B13: 10 | C13: 筑梦典藏箱 | D13: 20035 | F13: 700
B14: 11 | C14: 巡航门票 | D14: 28 | F14: 200 | G14: 20
B15: 12 | C15: 超能特饮 | D15: 5104001 | F15: 2 | G15: 0.2
B16: 13 | C16: 能量特饮 | D16: 5103001 | E16: 梦灵类 | F16: 1 | G16: 0.1 | H16: 体力产出 | J16: 5 | L16: 做非R的基础体验
B19: 14 | C19: 梦境招募器 | D19: 11 | F19: 30 | G19: 3 | H19: 情绪净化/主线任务 | I19: 商店购买 | J19: 6 | L19: 做各阶层的能力阶梯（前期质变）
B20: 15 | C20: 梦愿水晶 | D20: 35 | F20: 100 | G20: 10 | H20: 招募累计 | K20: 心愿招募
B21: 16 | C21: 神灯 | F21: 120 | G21: 10 | H21: 商店购买 | J21: 10 | K21: 限定招募 | L21: 做大R的付费边界（后期质变）
B22: 17 | C22: 稀有梦灵 | D22: 1310100 | F22: =F27*10 -> 60 | G22: =F27 -> 6 | H22: 英雄招募 | J22: 8 | L22: 本体；碎片*10
B23: 18 | C23: 史诗梦灵 | D23: 1420200 | F23: =F28*10 -> 120 | G23: =F28 -> 12 | H23: 英雄招募 | J23: 8 | L23: 本体；碎片*10
B24: 19 | C24: 传说梦灵 | D24: 1130100 | F24: =F29*10 -> 240 | G24: =F29 -> 24 | H24: 英雄招募 | J24: 8 | L24: 本体；碎片*10
B25: 20 | C25: 神话梦灵 | F25: =F30*10 -> 480 | G25: =F30 -> 48 | H25: 英雄招募 | J25: 8 | L25: 本体；碎片*10
B26: 21 | C26: 彩虹梦灵 | F26: =F31*10 -> 960 | G26: =F31 -> 96 | H26: 英雄招募 | J26: 8 | L26: 本体；碎片*10
B27: 22 | C27: 稀有梦灵碎片 | D27: 13101001 | F27: 6 | H27: 英雄招募 | J27: 8
B28: 23 | C28: 史诗梦灵碎片 | D28: 14202001 | F28: 12 | G28: 1.2 | H28: 英雄招募 | J28: 8
B29: 24 | C29: 传说梦灵碎片 | D29: 11301001 | F29: 24 | G29: 2.4 | H29: 英雄招募 | J29: 8
B30: 25 | C30: 神话梦灵碎片 | F30: 48 | G30: 4.8 | H30: 英雄招募 | J30: 8
B31: 26 | C31: 彩虹梦灵碎片 | F31: 96 | H31: 英雄招募 | J31: 8
C33: 零号骇客 | D33: 1610100 | F33: 暂不定价 | K33: 原估值引用已隐藏的旧粉卡试炼；现行配置无可复核估值锚，暂不定价
B34: 27 | C34: 公会贡献 | D34: 50 | F34: 0.1 | G34: 0.01
B35: 28 | C35: 转运石 | D35: 5523001 | F35: 0.33 | G35: 0.033 | J35: 5
B36: 29 | C36: 织梦能量 | D36: 47 | E36: 暂不定价 | F36: 暂不定价 | G36: 暂不定价 | K36: 友情值ID待核；ID47线上名称织梦能量
C37: 传说祝福石 | D37: 5305010 | F37: 1500 | G37: 150
C38: 神话祝福石 | F38: 5000 | G38: 500
C39: 创世祝福石 | F39: 16000 | G39: 1600
B41: 30 | C41: 装备图纸 | D41: 50002 | E41: 装备类 | F41: 3 | G41: 0.3 | H41: 体力产出 | J41: 6 | L41: 做非R长线活跃养成
B42: 31 | C42: 锻造晶石 | D42: 50001 | F42: 0.1 | G42: 0.01 | H42: 体力产出 | J42: 5 | K42: 装备洗练 | L42: 做非R的基础体验
B43: 32 | C43: 主线装备箱 | F43: 15 | H43: 体力产出
B44: 33 | C44: 队长大箱子 | F44: 50 | H44: 体力产出
B45: 34 | C45: 队长小箱子 | F45: 15 | H45: 体力产出
...

Sheet 活动评级标准
C4: 稀缺度
C6: 稀缺度 | D6: 定义 | E6: 投放约束 | M6: 设计思路
C7: 常规 | D7: 存在稳定、重复获取渠道 | E7: 可进入日常、常驻商店和普通礼包 | N7: 基于日周月礼包锚定性价比折算返利
C8: 受限 | D8: 稳定出现，但存在周期或数量限制 | E8: 可进入周循环、战令、限购礼包 | N8: 分层 | O8: 档位 | P8: 整体思路 | Q8: 总计花费 | R8: 返利比($) | S8: 总价/每月($)
C9: 稀缺 | D9: 只在少量运营活动中周期投放 | E9: 控制月度总量，禁止日常大量投放 | S9: 首充 | T9: 大小月卡 | U9: 周卡 | V9: 日周月礼包 | W9: 钻石基金 | X9: 战令 | Y9: 每日特惠 | Z9: 月度活动 | AA9: 节日活动 | AB9: 冲刺活动 | AC9: 皮肤转盘
C10: 限定 | D10: 赛季、联动、首发或特定时间独占 | E10: 限定渠道、限定周期，返场需单独审核 | N10: 非R | O10: 1 | P10: 豹子头 | Q10: 0
N11: 小R | O11: 1 | P11: 首冲玩家 | Q11: =SUM($S$10:AC11) -> 6 | R11: 50 | S11: 6
C12: 材料返利比 | O12: 2 | P12: 购买部分特权 | Q12: =SUM($S$10:AC12) -> 54 | R12: 20 | T12: 48
O13: 3 | P13: 特权买齐 | Q13: =SUM($S$10:AC13) -> 200 | R13: 10 | U13: 48 | W13: 98
C14: 直购档位/RMB | D14: 标准返比 | E14: 示例 | H14: 月卡、周卡、基金、战令类，返比>1000% | N14: 中R | O14: 1 | P14: 追求主养成模块 | Q14: =SUM($S$10:AC14) -> 824 | R14: 10 | X14: 192 | AB14: 432
C15: 6 | D15: 10 | E15: 6元=6高抽+60钻 | H15: 基础资源 | I15: 30元=36小时 | O15: 2 | P15: 追求多个养成模块 | Q15: =SUM($S$10:AC15) -> 1280 | R15: 5 | Z15: 180 | AA15: 108 | AC15: 168
C16: 12 | D16: 8 | I16: 68元=72小时 | O16: 4 | P16: 追求全部养成模块 在边界上不付费 | Q16: =SUM($S$10:AC16) -> 3304 | R16: 2.5 | Y16: 750 | Z16: 490 | AA16: 294 | AC16: 490
C17: 30 | D17: 6 | E17: 30元=10心愿抽+300钻 | N17: 大R | O17: 1 | P17: 每月活动拉满 | Q17: =SUM($S$10:AC17) -> 10928 | R17: 2 | V17: 5000 | AA17: 1640 | AB17: 984
C18: 68 | D18: 5 | I18: 基金 | J18: 10 | O18: 2 | P18: 每周礼包拉满 | Q18: =SUM($S$10:AC18) -> 25928 | R18: 1.5 | V18: 15000
C19: 98 | D19: 4 | I19: 战令 | J19: 15 | O19: 3 | P19: 每日消费拉满 | Q19: =SUM($S$10:AC19) -> 55928 | R19: 1 | V19: 30000
C20: 128 | D20: 3.5 | N20: 超R | O20: 1 | P20: 付费内容拉满 | Q20: =SUM($S$10:AC20) -> 255928 | R20: 1 | V20: 200000
C21: 198 | D21: 3
C22: 328 | D22: 2.5
C23: 648 | D23: 2 | N23: 基于养成系统对应
N24: 类 | O24: 模块 | P24: 贡献占比/每月
C25: 钻石消耗活动直购礼包返利比 | P25: 首充 | Q25: 大小月卡 | R25: 周卡 | S25: 日周月礼包 | T25: 钻石基金 | U25: 战令 | V25: 每日特惠 | W25: 月度活动 | X25: 节日活动 | Y25: 冲刺活动 | Z25: 皮肤转盘 | AA25: 充值返利
C26: 直购档位/RMB | D26: 标准返比 | E26: 示例 | N26: 梦灵 | O26: 梦灵升级 | P26: 20
C27: 6 | D27: 10
C28: 30 | D28: 4
C29: 98 | D29: 2.5
C30: 328 | D30: 1.5
C32: 活动返利比
C34: 活动评级 | D34: 标准返比
C35: S | D35: 3
C36: A | D36: 200%-225%
C37: B | D37: 150%-175%

Sheet 商店
A1: 5 | B1: 6 | C1: 0.5
G5: 单价（人民币） | N5: 道具id | O5: 道具【梦境】 | P5: 单价（钻石） | Q5: 单价（人民币） | R5: 稀有程度 | S5: 特殊运营活动价格（人民币） | T5: 类型 | U5: 品质 | V5: 针对玩家 | W5: 备注
A6: 刷新权重 | B6: 总权重 | C6: 刷新几率 | D6: 每日个数 | G6: =IFERROR(VLOOKUP(D6,O:Q,3,0),"") | N6: 1 | O6: 钻石 | P6: 1 | Q6: 0.1 | R6: 常规 | T6: 货币 | U6: 橙 | W6: /
A7: 梦幻遥感 | B7: 1200 | C7: =$B$1*B7/SUM($B$7:$B$13) -> 0.72 | D7: =C7*$A$1 -> 3.6 | G7: =IFERROR(VLOOKUP(D7,O:Q,3,0),"") | N7: 2 | O7: 金币 | P7: 0.05 | Q7: 0.005 | R7: 常规 | T7: 货币 | U7: 蓝 | W7: /
A8: 职业经验 | B8: 2400 | C8: =$B$1*B8/SUM($B$7:$B$13) -> 1.44 | D8: =C8*$A$1 -> 7.2 | G8: =IFERROR(VLOOKUP(D8,O:Q,3,0),"") | N8: 9800301 | O8: 金币吸收器 | P8: 50 | Q8: 5
A9: 装备图纸 | B9: 2400 | C9: =$B$1*B9/SUM($B$7:$B$13) -> 1.44 | D9: =C9*$A$1 -> 7.2 | G9: =IFERROR(VLOOKUP(D9,O:Q,3,0),"") | N9: 44 | O9: 心梦宝石 | P9: 14 | Q9: 1.4 | R9: 受限 | T9: 兑换道具 | U9: 橙 | W9: 每日特惠/循环冲刺活动，兑换商店货币）
A10: 洗练石 | B10: 400 | C10: =$B$1*B10/SUM($B$7:$B$13) -> 0.24 | D10: =C10*$A$1 -> 1.2 | G10: =IFERROR(VLOOKUP(D10,O:Q,3,0),"") | N10: 13 | O10: 体力 | P10: 2 | Q10: 0.2 | R10: 常规 | T10: 消耗道具 | U10: 紫
A11: 锤子 | B11: 1200 | C11: =$B$1*B11/SUM($B$7:$B$13) -> 0.72 | D11: =C11*$A$1 -> 3.6 | G11: =IFERROR(VLOOKUP(D11,O:Q,3,0),"") | N11: 20002 | O11: 梦境奇迹宝箱 | P11: 10 | Q11: 1 | R11: 受限 | T11: 消耗道具 | U11: 紫 | W11: 每日特惠礼包
A12: 英雄碎片 | B12: 2400 | C12: =$B$1*B12/SUM($B$7:$B$13) -> 1.44 | D12: =C12*$A$1 -> 7.2 | G12: =IFERROR(VLOOKUP(D12,O:Q,3,0),"") | N12: 20038 | O12: 梦境惊喜宝箱 | P12: 80 | Q12: 8 | R12: 受限 | W12: 每日特惠礼包
C13: 5800005 | G13: =IFERROR(VLOOKUP(D13,O:Q,3,0),"") | N13: 5600208 | O13: 悬赏线索 | P13: 3 | Q13: 0.3 | R13: 受限 | U13: 橙 | W13: 悬赏活动产出的价值
G14: =IFERROR(VLOOKUP(D14,O:Q,3,0),"") | N14: 5203001 | O14: 织梦微尘 | P14: 3 | Q14: 0.3 | R14: 受限 | T14: 队长道具 | U14: 蓝 | W14: /
G15: =IFERROR(VLOOKUP(D15,O:Q,3,0),"") | N15: 5103001 | O15: 随机能量特饮 | P15: 1 | Q15: 0.1 | R15: 常规 | T15: 梦灵道具 | U15: 蓝 | W15: /
G16: =IFERROR(VLOOKUP(D16,O:Q,3,0),"") | N16: 5104001 | O16: 超能特饮 | P16: 2 | Q16: 0.2 | R16: 常规 | T16: 梦灵道具 | U16: 紫 | W16: /
G17: =IFERROR(VLOOKUP(D17,O:Q,3,0),"") | L17: 万能特饮 | N17: 5600014 | O17: 随机史诗梦灵碎片 | P17: 12 | Q17: 1.2 | R17: 常规 | T17: 梦灵 | U17: 紫 | W17: /
A18: id | B18: 物品 | C18: 随机库 | D18: 随机权重 | E18: 购买消耗 | G18: =IFERROR(VLOOKUP(D18,O:Q,3,0),"") | H18: 原价 | I18: 商店备注 | L18: 做非R的基础体验，随机职业特饮 | N18: 5600015 | O18: 随机史诗梦灵碎片 | P18: 24 | Q18: 2.4 | R18: 受限 | T18: 梦灵 | U18: 橙
A19: 31001 | B19: 11,2}] | G19: =IFERROR(VLOOKUP(D19,O:Q,3,0),"") | O19: 随机史诗梦灵碎片 | P19: 48 | Q19: 4.8 | R19: 稀缺 | T19: 梦灵 | U19: 红
G20: =IFERROR(VLOOKUP(D20,O:Q,3,0),"") | O20: 随机史诗梦灵碎片 | P20: 96 | Q20: 9.6 | R20: 稀缺 | T20: 梦灵
A21: 31101 | B21: 11 | C21: 311 | D21: =INT(VLOOKUP(J21,$A$7:$D$12,2,0)/COUNTIF($J$21:$J$194,J21)) -> 200 | E21: 2,6000}] | G21: =IFERROR(VLOOKUP(D21,O:Q,3,0),"") | H21: [] | I21: 梦幻摇杆*5 | J21: 梦幻遥感 | K21: 5 | L21: 11 | M21: =SUBSTITUTE(SUBSTITUTE(SUBSTITUTE(E21,""&#REF!,""),"}]",""),",","") -> #REF! | O21: 自选史诗梦灵碎片 | P21: 12 | Q21: 1.2 | R21: 受限 | T21: 梦灵 | W21: /
A22: 31102 | B22: 11,10}] | C22: 311 | D22: =INT(VLOOKUP(J22,$A$7:$D$12,2,0)/COUNTIF($J$21:$J$194,J22)) -> 200 | E22: 2,12000}] | G22: =IFERROR(VLOOKUP(D22,O:Q,3,0),"") | H22: [] | I22: 梦幻摇杆*10 | J22: 梦幻遥感 | K22: 10 | L22: 11 | O22: 自选传说梦灵碎片 | P22: 24 | Q22: 2.4 | R22: 受限 | T22: 梦灵
A23: 31103 | O23: 自选神话梦灵碎片 | P23: 48 | Q23: 4.8 | R23: 稀缺 | T23: 梦灵
A24: 31104 | B24: 11,20}] | C24: 1310100 | D24: 稀有梦灵 | E24: 2,24000}] | G24: =F24*0.1 -> 0 | H24: [] | I24: 梦幻摇杆*20 | J24: 梦幻遥感 | K24: 20 | L24: 本体；碎片*10 | O24: 自选创世梦灵碎片 | P24: 96 | Q24: 9.6 | R24: 稀缺 | T24: 梦灵
A25: 31105 | B25: 11 | C25: 1420200 | D25: =INT(VLOOKUP(J25,$A$7:$D$12,2,0)/COUNTIF($J$21:$J$194,J25)) -> 200 | E25: 1,120}] | G25: =F25*0.1 -> 0 | H25: [] | I25: 梦幻摇杆*5 | J25: 梦幻遥感 | K25: 5 | L25: 本体；碎片*10 | O25: 随机史诗梦灵 | P25: 120 | Q25: 12 | R25: 受限 | T25: 梦灵 | W25: 48
A26: 31106 | B26: 11,10}] | C26: 1130100 | D26: =INT(VLOOKUP(J26,$A$7:$D$12,2,0)/COUNTIF($J$21:$J$194,J26)) -> 200 | E26: 1,240}] | G26: =F26*0.1 -> 0 | H26: [] | I26: 梦幻摇杆*10 | J26: 梦幻遥感 | K26: 10 | L26: 本体；碎片*10 | O26: 随机传说梦灵 | P26: 240 | Q26: 24 | R26: 受限 | T26: 梦灵 | W26: 96
A27: 31107 | B27: 11,20}] | C27: 311 | D27: =INT(VLOOKUP(J27,$A$7:$D$12,2,0)/COUNTIF($J$21:$J$194,J27)) -> 200 | E27: 1,480}] | G27: =F27*0.1 -> 0 | H27: [] | I27: 梦幻摇杆*20 | J27: 梦幻遥感 | K27: 20 | L27: 本体 | O27: 随机神话梦灵 | P27: 480 | Q27: 48 | R27: 稀缺 | T27: 梦灵 | W27: 192
A28: 31108 | B28: 5103002,50}] | C28: 311 | D28: =INT(VLOOKUP(J28,$A$7:$D$12,2,0)/COUNTIF($J$21:$J$194,J28)) -> 400 | E28: 2,2000}] | G28: =F28*0.1 -> 0 | I28: 职业经验*50 | J28: 职业经验 | K28: 50 | L28: 本体 | O28: 随机创世梦灵 | P28: 960 | Q28: 96 | R28: 稀缺 | T28: 梦灵 | W28: 384
A29: 31109 | B29: 5103002,100}] | D29: 随机稀有梦灵碎片 | E29: 2,4000}] | G29: =F29*0.1 -> 0 | I29: 职业经验*100 | J29: 职业经验 | K29: 100 | L29: 5103001 | M29: =SUBSTITUTE(SUBSTITUTE(SUBSTITUTE(E30,""&#REF!,""),"}]",""),",","") -> #REF! | O29: 自选史诗梦灵 | P29: 120 | Q29: 12 | R29: 受限 | T29: 梦灵
A30: 31110 | B30: 5103002,200}] | D30: 随机史诗梦灵碎片 | E30: 2,8000}] | G30: =F30*0.1 -> 0 | I30: 职业经验*200 | J30: 职业经验 | K30: 200 | L30: 5103001 | M30: =SUBSTITUTE(SUBSTITUTE(SUBSTITUTE(E31,""&#REF!,""),"}]",""),",","") -> #REF! | O30: 自选传说梦灵 | P30: 240 | Q30: 24 | R30: 受限 | T30: 梦灵
A31: 31111 | B31: 5103002,50}] | D31: 随机传说梦灵碎片 | E31: 1,50}] | G31: =F31*0.1 -> 0 | I31: 职业经验*50 | J31: 职业经验 | K31: =K28 -> 50 | L31: 5103001 | M31: =SUBSTITUTE(SUBSTITUTE(SUBSTITUTE(E32,""&#REF!,""),"}]",""),",","") -> #REF! | O31: 自选神话梦灵 | P31: 480 | Q31: 48 | R31: 稀缺 | T31: 梦灵 | W31: /
A32: 31112 | B32: 5103002,100}] | C32: 311 | D32: 随机神话梦灵碎片 | E32: 1,100}] | G32: =F32*0.1 -> 0 | I32: 职业经验*100 | J32: 职业经验 | K32: =K29 -> 100 | L32: 5103001 | M32: =SUBSTITUTE(SUBSTITUTE(SUBSTITUTE(E33,""&#REF!,""),"}]",""),",","") -> #REF! | O32: 自选创世梦灵 | P32: 960 | Q32: 96 | R32: 稀缺 | T32: 梦灵
A33: 31113 | B33: 5103002,200}] | C33: 311 | D33: 随机彩虹梦灵碎片 | E33: 1,200}] | G33: =F33*0.1 -> 0 | I33: 职业经验*200 | J33: 职业经验 | K33: =K30 -> 200 | L33: 5103001 | M33: =SUBSTITUTE(SUBSTITUTE(SUBSTITUTE(E39,""&#REF!,""),"}]",""),",","") -> #REF! | N33: 50002 | O33: 装备图纸 | P33: 3 | Q33: 0.3 | R33: 常规 | T33: 装备道具 | U33: 蓝 | W33: /
D34: 自选稀有梦灵碎片 | F34: 6 | G34: 0.6
D35: 自选史诗梦灵碎片 | F35: 12 | G35: 1.2
D36: 自选传说梦灵碎片 | F36: 24 | G36: 2.4
D37: 自选神话梦灵碎片 | F37: 48 | G37: 4.8
D38: 自选创世梦灵碎片 | F38: 96 | G38: 9.6
A39: 31114 | B39: 50003,10}] | C39: 311 | D39: =INT(VLOOKUP(J39,$A$7:$D$12,2,0)/COUNTIF($J$21:$J$194,J39)) -> 68 | E39: 2,1000}] | G39: =IFERROR(VLOOKUP(D39,O:Q,2,0),"") | I39: 头盔图纸*10 | J39: 装备图纸 | K39: 10 | L39: 50002 | M39: =SUBSTITUTE(SUBSTITUTE(SUBSTITUTE(E40,""&#REF!,""),"}]",""),",","") -> #REF! | O39: 固定部位装备图纸 | P39: 5 | Q39: 0.5 | R39: 受限 | T39: 装备道具 | W39: /
A40: 31115 | B40: 50003,20}] | C40: 311 | D40: =INT(VLOOKUP(J40,$A$7:$D$12,2,0)/COUNTIF($J$21:$J$194,J40)) -> 68 | E40: 2,2000}] | G40: =IFERROR(VLOOKUP(D40,O:Q,2,0),"") | I40: 头盔图纸*20 | J40: 装备图纸 | K40: 20 | L40: 50002 | M40: =SUBSTITUTE(SUBSTITUTE(SUBSTITUTE(E41,""&#REF!,""),"}]",""),",","") -> #REF! | N40: 50001 | O40: 锻造晶石 | P40: 0.1 | Q40: 0.01 | R40: 常规 | T40: 装备道具 | U40: 蓝 | W40: /
A41: 31116 | B41: 50003,40}] | C41: 311 | D41: =INT(VLOOKUP(J41,$A$7:$D$12,2,0)/COUNTIF($J$21:$J$194,J41)) -> 68 | E41: 2,4000}] | G41: =IFERROR(VLOOKUP(D41,O:Q,2,0),"") | I41: 头盔图纸*40 | J41: 装备图纸 | K41: 40 | L41: 50002 | M41: =SUBSTITUTE(SUBSTITUTE(SUBSTITUTE(E42,""&#REF!,""),"}]",""),",","") -> #REF! | N41: 5303001 | O41: 符引结晶 | P41: 5 | Q41: 0.5 | R41: 常规 | T41: 符文 | U41: 蓝 | W41: 200个合成1个，紫色的需要符引结晶
A42: 31117 | B42: 50003,10}] | C42: 311 | D42: =INT(VLOOKUP(J42,$A$7:$D$12,2,0)/COUNTIF($J$21:$J$194,J42)) -> 68 | E42: 1,40}] | G42: =IFERROR(VLOOKUP(D42,O:Q,2,0),"") | I42: 头盔图纸*10 | J42: 装备图纸 | K42: =K39 -> 10 | L42: 50002 | M42: =SUBSTITUTE(SUBSTITUTE(SUBSTITUTE(E43,""&#REF!,""),"}]",""),",","") -> #REF! | N42: 5305001 | O42: 幻梦晶核 | P42: 60 | Q42: 6 | R42: 受限 | T42: 符文 | U42: 橙 | W42: /
A43: 31118 | B43: 50003,20}] | C43: 311 | D43: =INT(VLOOKUP(J43,$A$7:$D$12,2,0)/COUNTIF($J$21:$J$194,J43)) -> 68 | E43: 1,80}] | G43: =IFERROR(VLOOKUP(D43,O:Q,2,0),"") | I43: 头盔图纸*20 | J43: 装备图纸 | K43: =K40 -> 20 | L43: 50002 | M43: =SUBSTITUTE(SUBSTITUTE(SUBSTITUTE(E44,""&#REF!,""),"}]",""),",","") -> #REF! | N43: 5305010 | O43: 传说祝福石 | P43: 1500 | Q43: 150 | R43: 稀缺 | T43: 符文 | U43: 橙
...

Sheet 新商店
B2: 设计预期
C3: 前7天小非R日均消耗8000~12000, 7天后日均16000~24000. 中大R日均16000, 7日后日均32000
E5: 1001 | F5: =E5+1000 -> 2001 | G5: =F5+1000 -> 3001 | H5: =G5+1000 -> 4001 | I5: =H5+1000 -> 5001 | J5: =I5+1000 -> 6001 | K5: 7002 | L5: 8001
B6: 天数 | C6: 非R | D6: 大R | E6: =_xlfn.XLOOKUP(E5,$C$30:$C$85,$E$30:$E$85) -> #N/A | F6: =_xlfn.XLOOKUP(F5,$C$30:$C$85,$E$30:$E$85) -> 90 | G6: =_xlfn.XLOOKUP(G5,$C$30:$C$85,$E$30:$E$85) -> 0 | H6: =_xlfn.XLOOKUP(H5,$C$30:$C$85,$E$30:$E$85) -> #N/A | I6: =_xlfn.XLOOKUP(I5,$C$30:$C$85,$E$30:$E$85) -> #N/A | J6: =_xlfn.XLOOKUP(J5,$C$30:$C$85,$E$30:$E$85) -> #N/A | K6: =_xlfn.XLOOKUP(K5,$C$30:$C$85,$E$30:$E$85) -> #N/A | L6: =_xlfn.XLOOKUP(L5,$C$30:$C$85,$E$30:$E$85) -> #N/A
B7: 1 | C7: =SUMIF($B$30:$B$86,$B7,N$30:N$86) -> #N/A | D7: =SUMIF($B$30:$B$86,$B7,O$30:O$86) -> #N/A | E7: 1001 | F7: 2001 | G7: 3001 | H7: 4001 | I7: 5001 | J7: 6001 | K7: 7002 | L7: 8001
B8: 2 | C8: =SUMIF($B$30:$B$86,$B8,N$30:N$86) -> #N/A | D8: =SUMIF($B$30:$B$86,$B8,O$30:O$86) -> #N/A | E8: 1001 | F8: 2001 | G8: 3001 | H8: 4001 | I8: 5002 | J8: 6001 | K8: 7002 | L8: 8001
B9: 3 | C9: =SUMIF($B$30:$B$86,$B9,N$30:N$86) -> #N/A | D9: =SUMIF($B$30:$B$86,$B9,O$30:O$86) -> #N/A | E9: 1001 | F9: 2001 | G9: 3001 | H9: 4001 | I9: 5002 | J9: 6002 | K9: 7002 | L9: 8001
B10: 4 | C10: =SUMIF($B$30:$B$86,$B10,N$30:N$86) -> #N/A | D10: =SUMIF($B$30:$B$86,$B10,O$30:O$86) -> #N/A | E10: 1002 | F10: 2001 | G10: 3001 | H10: 4001 | I10: 5002 | J10: 6002 | K10: 7003 | L10: 8001
B11: 5 | C11: =SUMIF($B$30:$B$86,$B11,N$30:N$86) -> #N/A | D11: =SUMIF($B$30:$B$86,$B11,O$30:O$86) -> #N/A | E11: 1002 | F11: 2001 | G11: 3001 | H11: 4001 | I11: 5002 | J11: 6003 | K11: 7003 | L11: 8001
B12: 6 | C12: =SUMIF($B$30:$B$86,$B12,N$30:N$86) -> #N/A | D12: =SUMIF($B$30:$B$86,$B12,O$30:O$86) -> #N/A | E12: 1002 | F12: 2001 | G12: 3001 | H12: 4001 | I12: 5003 | J12: 6003 | K12: 7003 | L12: 8001
B13: 7 | C13: =SUMIF($B$30:$B$86,$B13,N$30:N$86) -> #N/A | D13: =SUMIF($B$30:$B$86,$B13,O$30:O$86) -> #N/A | E13: 1003 | F13: 2001 | G13: 3001 | H13: 4001 | I13: 5003 | J13: 6003 | K13: 7003 | L13: 8001
C14: =AVERAGE(C7:C12) -> #N/A | D14: =AVERAGE(D7:D12) -> #N/A
E15: 1001 | F15: =E15+1000 -> 2001 | G15: =F15+1000 -> 3001 | H15: =G15+1000 -> 4001 | I15: =H15+1000 -> 5001 | J15: =I15+1000 -> 6001 | K15: 7002 | L15: 8001
B16: 天数 | C16: 非R | D16: 大R | E16: =_xlfn.XLOOKUP(E15,$C$30:$C$85,$E$30:$E$85) -> #N/A | F16: =_xlfn.XLOOKUP(F15,$C$30:$C$85,$E$30:$E$85) -> 90 | G16: =_xlfn.XLOOKUP(G15,$C$30:$C$85,$E$30:$E$85) -> 0 | H16: =_xlfn.XLOOKUP(H15,$C$30:$C$85,$E$30:$E$85) -> #N/A | I16: =_xlfn.XLOOKUP(I15,$C$30:$C$85,$E$30:$E$85) -> #N/A | J16: =_xlfn.XLOOKUP(J15,$C$30:$C$85,$E$30:$E$85) -> #N/A | K16: =_xlfn.XLOOKUP(K15,$C$30:$C$85,$E$30:$E$85) -> #N/A | L16: =_xlfn.XLOOKUP(L15,$C$30:$C$85,$E$30:$E$85) -> #N/A
B17: 1 | E17: 1 | F17: 1 | G17: 0 | H17: 0
B18: 2 | E18: 1 | F18: 0 | G18: 1 | H18: 0
B19: 3 | E19: 0 | F19: 1 | G19: 0 | H19: 0
B20: 4 | E20: 1 | F20: 0 | G20: 0 | H20: 0
B21: 5 | E21: 0 | H21: 0
B22: 6 | E22: 0 | H22: 0
B23: 7 | E23: 1 | H23: 1
H28: 5 | I28: =H28+3 -> 8 | N28: 1 | O28: 2
B29: 组id | C29: 随机库 | D29: id | E29: 内容名 | F29: 随机权重 | G29: 钻石比例 | H29: 小R日均次数 | I29: 大R日均次数 | J29: 最小天数 | K29: 最大天数 | L29: 上限次数 | M29: 目标用户 | N29: 小R | O29: 大R | P29: 小R | Q29: 大R
B30: 1 | C30: =OFFSET($D$6,B30,COUNTIF($B$29:B30,B30)) -> 1001 | D30: 11 | E30: =_xlfn.XLOOKUP(D30,价值表!$D:$D,价值表!$C:$C) | F30: 700 | G30: 0.5 | H30: =$F30/10000*6*H$28*(1-$G30) -> 1.05 | I30: =$F30/10000*6*I$28*(1-$G30) -> 1.68 | J30: 1 | K30: 2 | L30: =IF(OFFSET($D$16,B30,MATCH(E30,$E$16:$L$16,0))="","",OFFSET($D$16,B30,MATCH(E30,$E$16:$L$16,0))) -> #N/A | M30: 非R | N30: {=IF(_xlfn.XLOOKUP($M30,$X$30:$X$34,$Y$30:$Y$34)<=MATCH(N$29,$N$29:$O$29,0),SUMPRODUCT(--($C$91:$C$234=$C30),$G$91:$G$234,$J$91:$J$234)/SUMPRODUCT(--($J$91:$J$234>0),$G$91:$G$234,--($C$91:$C$234=$C30))*MIN(H30,$L30),0)} -> #N/A | O30: {=IF(_xlfn.XLOOKUP($M30,$X$30:$X$34,$Y$30:$Y$34)<=MATCH(O$29,$N$29:$O$29,0),SUMPRODUCT(--($C$91:$C$234=$C30),$G$91:$G$234,$J$91:$J$234)/SUMPRODUCT(--($J$91:$J$234>0),$G$91:$G$234,--($C$91:$C$234=$C30))*MIN(I30,$L30),0)} -> #N/A | P30: {=IF(_xlfn.XLOOKUP($M30,$X$30:$X$34,$Y$30:$Y$34)<=MATCH(N$29,$N$29:$O$29,0),SUMPRODUCT(--($C$91:$C$234=$C30),$G$91:$G$234,$F$91:$F$234,--($J$91:$J$234>0))/SUMPRODUCT(--($J$91:$J$234>0),$G$91:$G$234,--($C$91:$C$234=$C30))*MIN(H30,$L30),0)} -> #N/A | Q30: {=IF(_xlfn.XLOOKUP($M30,$X$30:$X$34,$Y$30:$Y$34)<=MATCH(O$29,$N$29:$O$29,0),SUMPRODUCT(--($C$91:$C$234=$C30),$G$91:$G$234,$F$91:$F$234,--($J$91:$J$234>0))/SUMPRODUCT(--($J$91:$J$234>0),$G$91:$G$234,--($C$91:$C$234=$C30))*MIN(I30,$L30),0)} -> #N/A | U30: 1001 | V30: =_xlfn.XLOOKUP(INT(U30/1000)*1000+1,$C$29:$C$85,$E$29:$E$85) -> #N/A | X30: 非R | Y30: 1
B31: 1 | C31: =OFFSET($D$6,B31,COUNTIF($B$29:B31,B31)) -> 2001 | D31: 9 | E31: =_xlfn.XLOOKUP(D31,价值表!$D:$D,价值表!$C:$C) | F31: 600 | G31: 0.5 | H31: =$F31/10000*6*H$28*(1-$G31) -> 0.9 | I31: =$F31/10000*6*I$28*(1-$G31) -> 1.44 | J31: 1 | K31: 2 | L31: =IF(OFFSET($D$16,B31,MATCH(E31,$E$16:$L$16,0))="","",OFFSET($D$16,B31,MATCH(E31,$E$16:$L$16,0))) -> 1 | M31: 非R | N31: {=IF(_xlfn.XLOOKUP($M31,$X$30:$X$34,$Y$30:$Y$34)<=MATCH(N$29,$N$29:$O$29,0),SUMPRODUCT(--($C$91:$C$234=$C31),$G$91:$G$234,$J$91:$J$234)/SUMPRODUCT(--($J$91:$J$234>0),$G$91:$G$234,--($C$91:$C$234=$C31))*MIN(H31,$L31),0)} -> 1800 | O31: {=IF(_xlfn.XLOOKUP($M31,$X$30:$X$34,$Y$30:$Y$34)<=MATCH(O$29,$N$29:$O$29,0),SUMPRODUCT(--($C$91:$C$234=$C31),$G$91:$G$234,$J$91:$J$234)/SUMPRODUCT(--($J$91:$J$234>0),$G$91:$G$234,--($C$91:$C$234=$C31))*MIN(I31,$L31),0)} -> 2000 | P31: {=IF(_xlfn.XLOOKUP($M31,$X$30:$X$34,$Y$30:$Y$34)<=MATCH(N$29,$N$29:$O$29,0),SUMPRODUCT(--($C$91:$C$234=$C31),$G$91:$G$234,$F$91:$F$234,--($J$91:$J$234>0))/SUMPRODUCT(--($J$91:$J$234>0),$G$91:$G$234,--($C$91:$C$234=$C31))*MIN(H31,$L31),0)} -> 0.9 | Q31: {=IF(_xlfn.XLOOKUP($M31,$X$30:$X$34,$Y$30:$Y$34)<=MATCH(O$29,$N$29:$O$29,0),SUMPRODUCT(--($C$91:$C$234=$C31),$G$91:$G$234,$F$91:$F$234,--($J$91:$J$234>0))/SUMPRODUCT(--($J$91:$J$234>0),$G$91:$G$234,--($C$91:$C$234=$C31))*MIN(I31,$L31),0)} -> 1 | U31: 1002 | V31: =_xlfn.XLOOKUP(INT(U31/1000)*1000+1,$C$29:$C$85,$E$29:$E$85) -> #N/A | X31: 小R | Y31: 1
B32: 1 | C32: =OFFSET($D$6,B32,COUNTIF($B$29:B32,B32)) -> 3001 | D32: 30 | E32: =_xlfn.XLOOKUP(D32,价值表!$D:$D,价值表!$C:$C) | F32: 200 | G32: 0.5 | H32: =$F32/10000*6*H$28*(1-$G32) -> 0.3 | I32: =$F32/10000*6*I$28*(1-$G32) -> 0.48 | J32: 1 | K32: 2 | L32: =IF(OFFSET($D$16,B32,MATCH(E32,$E$16:$L$16,0))="","",OFFSET($D$16,B32,MATCH(E32,$E$16:$L$16,0))) -> 0 | M32: 非R | N32: {=IF(_xlfn.XLOOKUP($M32,$X$30:$X$34,$Y$30:$Y$34)<=MATCH(N$29,$N$29:$O$29,0),SUMPRODUCT(--($C$91:$C$234=$C32),$G$91:$G$234,$J$91:$J$234)/SUMPRODUCT(--($J$91:$J$234>0),$G$91:$G$234,--($C$91:$C$234=$C32))*MIN(H32,$L32),0)} -> 0 | O32: {=IF(_xlfn.XLOOKUP($M32,$X$30:$X$34,$Y$30:$Y$34)<=MATCH(O$29,$N$29:$O$29,0),SUMPRODUCT(--($C$91:$C$234=$C32),$G$91:$G$234,$J$91:$J$234)/SUMPRODUCT(--($J$91:$J$234>0),$G$91:$G$234,--($C$91:$C$234=$C32))*MIN(I32,$L32),0)} -> 0 | P32: {=IF(_xlfn.XLOOKUP($M32,$X$30:$X$34,$Y$30:$Y$34)<=MATCH(N$29,$N$29:$O$29,0),SUMPRODUCT(--($C$91:$C$234=$C32),$G$91:$G$234,$F$91:$F$234,--($J$91:$J$234>0))/SUMPRODUCT(--($J$91:$J$234>0),$G$91:$G$234,--($C$91:$C$234=$C32))*MIN(H32,$L32),0)} -> 0 | Q32: {=IF(_xlfn.XLOOKUP($M32,$X$30:$X$34,$Y$30:$Y$34)<=MATCH(O$29,$N$29:$O$29,0),SUMPRODUCT(--($C$91:$C$234=$C32),$G$91:$G$234,$F$91:$F$234,--($J$91:$J$234>0))/SUMPRODUCT(--($J$91:$J$234>0),$G$91:$G$234,--($C$91:$C$234=$C32))*MIN(I32,$L32),0)} -> 0 | U32: 1003 | V32: =_xlfn.XLOOKUP(INT(U32/1000)*1000+1,$C$29:$C$85,$E$29:$E$85) -> #N/A | X32: 中R | Y32: 1
B33: 1 | C33: =OFFSET($D$6,B33,COUNTIF($B$29:B33,B33)) -> 4001 | D33: 5305001 | E33: =_xlfn.XLOOKUP(D33,价值表!$D:$D,价值表!$C:$C) | F33: 300 | G33: 0.5 | H33: =$F33/10000*6*H$28*(1-$G33) -> 0.45 | I33: =$F33/10000*6*I$28*(1-$G33) -> 0.72 | J33: 1 | K33: 2 | L33: =IF(OFFSET($D$16,B33,MATCH(E33,$E$16:$L$16,0))="","",OFFSET($D$16,B33,MATCH(E33,$E$16:$L$16,0))) -> #N/A | M33: 非R | N33: {=IF(_xlfn.XLOOKUP($M33,$X$30:$X$34,$Y$30:$Y$34)<=MATCH(N$29,$N$29:$O$29,0),SUMPRODUCT(--($C$91:$C$234=$C33),$G$91:$G$234,$J$91:$J$234)/SUMPRODUCT(--($J$91:$J$234>0),$G$91:$G$234,--($C$91:$C$234=$C33))*MIN(H33,$L33),0)} -> #N/A | O33: {=IF(_xlfn.XLOOKUP($M33,$X$30:$X$34,$Y$30:$Y$34)<=MATCH(O$29,$N$29:$O$29,0),SUMPRODUCT(--($C$91:$C$234=$C33),$G$91:$G$234,$J$91:$J$234)/SUMPRODUCT(--($J$91:$J$234>0),$G$91:$G$234,--($C$91:$C$234=$C33))*MIN(I33,$L33),0)} -> #N/A | P33: {=IF(_xlfn.XLOOKUP($M33,$X$30:$X$34,$Y$30:$Y$34)<=MATCH(N$29,$N$29:$O$29,0),SUMPRODUCT(--($C$91:$C$234=$C33),$G$91:$G$234,$F$91:$F$234,--($J$91:$J$234>0))/SUMPRODUCT(--($J$91:$J$234>0),$G$91:$G$234,--($C$91:$C$234=$C33))*MIN(H33,$L33),0)} -> #N/A | Q33: {=IF(_xlfn.XLOOKUP($M33,$X$30:$X$34,$Y$30:$Y$34)<=MATCH(O$29,$N$29:$O$29,0),SUMPRODUCT(--($C$91:$C$234=$C33),$G$91:$G$234,$F$91:$F$234,--($J$91:$J$234>0))/SUMPRODUCT(--($J$91:$J$234>0),$G$91:$G$234,--($C$91:$C$234=$C33))*MIN(I33,$L33),0)} -> #N/A | U33: 2001 | V33: =_xlfn.XLOOKUP(INT(U33/1000)*1000+1,$C$29:$C$85,$E$29:$E$85) -> 90 | X33: 大R | Y33: 2
B34: 1 | C34: =OFFSET($D$6,B34,COUNTIF($B$29:B34,B34)) -> 5001 | D34: 50002 | E34: =_xlfn.XLOOKUP(D34,价值表!$D:$D,价值表!$C:$C) | F34: 2400 | G34: 0.5 | H34: =$F34/10000*6*H$28*(1-$G34) -> 3.6 | I34: =$F34/10000*6*I$28*(1-$G34) -> 5.76 | J34: 1 | K34: 2 | L34: =IF(OFFSET($D$16,B34,MATCH(E34,$E$16:$L$16,0))="","",OFFSET($D$16,B34,MATCH(E34,$E$16:$L$16,0))) -> #N/A | M34: 非R | N34: {=IF(_xlfn.XLOOKUP($M34,$X$30:$X$34,$Y$30:$Y$34)<=MATCH(N$29,$N$29:$O$29,0),SUMPRODUCT(--($C$91:$C$234=$C34),$G$91:$G$234,$J$91:$J$234)/SUMPRODUCT(--($J$91:$J$234>0),$G$91:$G$234,--($C$91:$C$234=$C34))*MIN(H34,$L34),0)} -> #N/A | O34: {=IF(_xlfn.XLOOKUP($M34,$X$30:$X$34,$Y$30:$Y$34)<=MATCH(O$29,$N$29:$O$29,0),SUMPRODUCT(--($C$91:$C$234=$C34),$G$91:$G$234,$J$91:$J$234)/SUMPRODUCT(--($J$91:$J$234>0),$G$91:$G$234,--($C$91:$C$234=$C34))*MIN(I34,$L34),0)} -> #N/A | P34: {=IF(_xlfn.XLOOKUP($M34,$X$30:$X$34,$Y$30:$Y$34)<=MATCH(N$29,$N$29:$O$29,0),SUMPRODUCT(--($C$91:$C$234=$C34),$G$91:$G$234,$F$91:$F$234,--($J$91:$J$234>0))/SUMPRODUCT(--($J$91:$J$234>0),$G$91:$G$234,--($C$91:$C$234=$C34))*MIN(H34,$L34),0)} -> #N/A | Q34: {=IF(_xlfn.XLOOKUP($M34,$X$30:$X$34,$Y$30:$Y$34)<=MATCH(O$29,$N$29:$O$29,0),SUMPRODUCT(--($C$91:$C$234=$C34),$G$91:$G$234,$F$91:$F$234,--($J$91:$J$234>0))/SUMPRODUCT(--($J$91:$J$234>0),$G$91:$G$234,--($C$91:$C$234=$C34))*MIN(I34,$L34),0)} -> #N/A | U34: 3001 | V34: =_xlfn.XLOOKUP(INT(U34/1000)*1000+1,$C$29:$C$85,$E$29:$E$85) -> 0 | X34: 超R | Y34: 3
B35: 1 | C35: =OFFSET($D$6,B35,COUNTIF($B$29:B35,B35)) -> 6001 | D35: 5203001 | E35: =_xlfn.XLOOKUP(D35,价值表!$D:$D,价值表!$C:$C) | F35: 600 | G35: 0.5 | H35: =$F35/10000*6*H$28*(1-$G35) -> 0.9 | I35: =$F35/10000*6*I$28*(1-$G35) -> 1.44 | J35: 1 | K35: 2 | L35: =IF(OFFSET($D$16,B35,MATCH(E35,$E$16:$L$16,0))="","",OFFSET($D$16,B35,MATCH(E35,$E$16:$L$16,0))) -> #N/A | M35: 大R | N35: {=IF(_xlfn.XLOOKUP($M35,$X$30:$X$34,$Y$30:$Y$34)<=MATCH(N$29,$N$29:$O$29,0),SUMPRODUCT(--($C$91:$C$234=$C35),$G$91:$G$234,$J$91:$J$234)/SUMPRODUCT(--($J$91:$J$234>0),$G$91:$G$234,--($C$91:$C$234=$C35))*MIN(H35,$L35),0)} -> 0 | O35: {=IF(_xlfn.XLOOKUP($M35,$X$30:$X$34,$Y$30:$Y$34)<=MATCH(O$29,$N$29:$O$29,0),SUMPRODUCT(--($C$91:$C$234=$C35),$G$91:$G$234,$J$91:$J$234)/SUMPRODUCT(--($J$91:$J$234>0),$G$91:$G$234,--($C$91:$C$234=$C35))*MIN(I35,$L35),0)} -> #N/A | P35: {=IF(_xlfn.XLOOKUP($M35,$X$30:$X$34,$Y$30:$Y$34)<=MATCH(N$29,$N$29:$O$29,0),SUMPRODUCT(--($C$91:$C$234=$C35),$G$91:$G$234,$F$91:$F$234,--($J$91:$J$234>0))/SUMPRODUCT(--($J$91:$J$234>0),$G$91:$G$234,--($C$91:$C$234=$C35))*MIN(H35,$L35),0)} -> 0 | Q35: {=IF(_xlfn.XLOOKUP($M35,$X$30:$X$34,$Y$30:$Y$34)<=MATCH(O$29,$N$29:$O$29,0),SUMPRODUCT(--($C$91:$C$234=$C35),$G$91:$G$234,$F$91:$F$234,--($J$91:$J$234>0))/SUMPRODUCT(--($J$91:$J$234>0),$G$91:$G$234,--($C$91:$C$234=$C35))*MIN(I35,$L35),0)} -> #N/A | U35: 4001 | V35: =_xlfn.XLOOKUP(INT(U35/1000)*1000+1,$C$29:$C$85,$E$29:$E$85) -> #N/A
B36: 1 | C36: =OFFSET($D$6,B36,COUNTIF($B$29:B36,B36)) -> 7002 | D36: 5103001 | E36: =_xlfn.XLOOKUP(D36,价值表!$D:$D,价值表!$C:$C) | F36: 2000 | G36: 0.5 | H36: =$F36/10000*6*H$28*(1-$G36) -> 3 | I36: =$F36/10000*6*I$28*(1-$G36) -> 4.8 | J36: 1 | K36: 2 | L36: =IF(OFFSET($D$16,B36,MATCH(E36,$E$16:$L$16,0))="","",OFFSET($D$16,B36,MATCH(E36,$E$16:$L$16,0))) -> #N/A | M36: 超R | N36: {=IF(_xlfn.XLOOKUP($M36,$X$30:$X$34,$Y$30:$Y$34)<=MATCH(N$29,$N$29:$O$29,0),SUMPRODUCT(--($C$91:$C$234=$C36),$G$91:$G$234,$J$91:$J$234)/SUMPRODUCT(--($J$91:$J$234>0),$G$91:$G$234,--($C$91:$C$234=$C36))*MIN(H36,$L36),0)} -> 0 | O36: {=IF(_xlfn.XLOOKUP($M36,$X$30:$X$34,$Y$30:$Y$34)<=MATCH(O$29,$N$29:$O$29,0),SUMPRODUCT(--($C$91:$C$234=$C36),$G$91:$G$234,$J$91:$J$234)/SUMPRODUCT(--($J$91:$J$234>0),$G$91:$G$234,--($C$91:$C$234=$C36))*MIN(I36,$L36),0)} -> 0 | P36: {=IF(_xlfn.XLOOKUP($M36,$X$30:$X$34,$Y$30:$Y$34)<=MATCH(N$29,$N$29:$O$29,0),SUMPRODUCT(--($C$91:$C$234=$C36),$G$91:$G$234,$F$91:$F$234,--($J$91:$J$234>0))/SUMPRODUCT(--($J$91:$J$234>0),$G$91:$G$234,--($C$91:$C$234=$C36))*MIN(H36,$L36),0)} -> 0 | Q36: {=IF(_xlfn.XLOOKUP($M36,$X$30:$X$34,$Y$30:$Y$34)<=MATCH(O$29,$N$29:$O$29,0),SUMPRODUCT(--($C$91:$C$234=$C36),$G$91:$G$234,$F$91:$F$234,--($J$91:$J$234>0))/SUMPRODUCT(--($J$91:$J$234>0),$G$91:$G$234,--($C$91:$C$234=$C36))*MIN(I36,$L36),0)} -> 0 | U36: 5001 | V36: =_xlfn.XLOOKUP(INT(U36/1000)*1000+1,$C$29:$C$85,$E$29:$E$85) -> #N/A
B37: 1 | C37: =OFFSET($D$6,B37,COUNTIF($B$29:B37,B37)) -> 8001 | D37: 1310100 | E37: =_xlfn.XLOOKUP(D37,价值表!$D:$D,价值表!$C:$C) | F37: 3200 | G37: 0.5 | H37: =$F37/10000*6*H$28*(1-$G37) -> 4.8 | I37: =$F37/10000*6*I$28*(1-$G37) -> 7.68 | J37: 1 | K37: 2 | L37: =IF(OFFSET($D$16,B37,MATCH(E37,$E$16:$L$16,0))="","",OFFSET($D$16,B37,MATCH(E37,$E$16:$L$16,0))) -> #N/A | M37: 超R | N37: {=IF(_xlfn.XLOOKUP($M37,$X$30:$X$34,$Y$30:$Y$34)<=MATCH(N$29,$N$29:$O$29,0),SUMPRODUCT(--($C$91:$C$234=$C37),$G$91:$G$234,$J$91:$J$234)/SUMPRODUCT(--($J$91:$J$234>0),$G$91:$G$234,--($C$91:$C$234=$C37))*MIN(H37,$L37),0)} -> 0 | O37: {=IF(_xlfn.XLOOKUP($M37,$X$30:$X$34,$Y$30:$Y$34)<=MATCH(O$29,$N$29:$O$29,0),SUMPRODUCT(--($C$91:$C$234=$C37),$G$91:$G$234,$J$91:$J$234)/SUMPRODUCT(--($J$91:$J$234>0),$G$91:$G$234,--($C$91:$C$234=$C37))*MIN(I37,$L37),0)} -> 0 | P37: {=IF(_xlfn.XLOOKUP($M37,$X$30:$X$34,$Y$30:$Y$34)<=MATCH(N$29,$N$29:$O$29,0),SUMPRODUCT(--($C$91:$C$234=$C37),$G$91:$G$234,$F$91:$F$234,--($J$91:$J$234>0))/SUMPRODUCT(--($J$91:$J$234>0),$G$91:$G$234,--($C$91:$C$234=$C37))*MIN(H37,$L37),0)} -> 0 | Q37: {=IF(_xlfn.XLOOKUP($M37,$X$30:$X$34,$Y$30:$Y$34)<=MATCH(O$29,$N$29:$O$29,0),SUMPRODUCT(--($C$91:$C$234=$C37),$G$91:$G$234,$F$91:$F$234,--($J$91:$J$234>0))/SUMPRODUCT(--($J$91:$J$234>0),$G$91:$G$234,--($C$91:$C$234=$C37))*MIN(I37,$L37),0)} -> 0 | U37: 5002 | V37: =_xlfn.XLOOKUP(INT(U37/1000)*1000+1,$C$29:$C$85,$E$29:$E$85) -> #N/A
B38: =B30+1 -> 2 | C38: =OFFSET($D$6,B38,COUNTIF($B$29:B38,B38)) -> 1001 | D38: 11 | E38: =_xlfn.XLOOKUP(D38,价值表!$D:$D,价值表!$C:$C) | F38: 700 | G38: 0.5 | H38: =$F38/10000*6*H$28*(1-$G38) -> 1.05 | I38: =$F38/10000*6*I$28*(1-$G38) -> 1.68 | J38: 1 | K38: 2 | L38: =IF(OFFSET($D$16,B38,MATCH(E38,$E$16:$L$16,0))="","",OFFSET($D$16,B38,MATCH(E38,$E$16:$L$16,0))) -> #N/A | M38: 非R | N38: {=IF(_xlfn.XLOOKUP($M38,$X$30:$X$34,$Y$30:$Y$34)<=MATCH(N$29,$N$29:$O$29,0),SUMPRODUCT(--($C$91:$C$234=$C38),$G$91:$G$234,$J$91:$J$234)/SUMPRODUCT(--($J$91:$J$234>0),$G$91:$G$234,--($C$91:$C$234=$C38))*MIN(H38,$L38),0)} -> #N/A | O38: {=IF(_xlfn.XLOOKUP($M38,$X$30:$X$34,$Y$30:$Y$34)<=MATCH(O$29,$N$29:$O$29,0),SUMPRODUCT(--($C$91:$C$234=$C38),$G$91:$G$234,$J$91:$J$234)/SUMPRODUCT(--($J$91:$J$234>0),$G$91:$G$234,--($C$91:$C$234=$C38))*MIN(I38,$L38),0)} -> #N/A | P38: {=IF(_xlfn.XLOOKUP($M38,$X$30:$X$34,$Y$30:$Y$34)<=MATCH(N$29,$N$29:$O$29,0),SUMPRODUCT(--($C$91:$C$234=$C38),$G$91:$G$234,$F$91:$F$234,--($J$91:$J$234>0))/SUMPRODUCT(--($J$91:$J$234>0),$G$91:$G$234,--($C$91:$C$234=$C38))*MIN(H38,$L38),0)} -> #N/A | Q38: {=IF(_xlfn.XLOOKUP($M38,$X$30:$X$34,$Y$30:$Y$34)<=MATCH(O$29,$N$29:$O$29,0),SUMPRODUCT(--($C$91:$C$234=$C38),$G$91:$G$234,$F$91:$F$234,--($J$91:$J$234>0))/SUMPRODUCT(--($J$91:$J$234>0),$G$91:$G$234,--($C$91:$C$234=$C38))*MIN(I38,$L38),0)} -> #N/A | U38: 5003 | V38: =_xlfn.XLOOKUP(INT(U38/1000)*1000+1,$C$29:$C$85,$E$29:$E$85) -> #N/A
B39: =B31+1 -> 2 | C39: =OFFSET($D$6,B39,COUNTIF($B$29:B39,B39)) -> 2001 | D39: 9 | E39: =_xlfn.XLOOKUP(D39,价值表!$D:$D,价值表!$C:$C) | F39: 600 | G39: 0.5 | H39: =$F39/10000*6*H$28*(1-$G39) -> 0.9 | I39: =$F39/10000*6*I$28*(1-$G39) -> 1.44 | J39: 1 | K39: 2 | L39: =IF(OFFSET($D$16,B39,MATCH(E39,$E$16:$L$16,0))="","",OFFSET($D$16,B39,MATCH(E39,$E$16:$L$16,0))) -> 0 | M39: 非R | N39: {=IF(_xlfn.XLOOKUP($M39,$X$30:$X$34,$Y$30:$Y$34)<=MATCH(N$29,$N$29:$O$29,0),SUMPRODUCT(--($C$91:$C$234=$C39),$G$91:$G$234,$J$91:$J$234)/SUMPRODUCT(--($J$91:$J$234>0),$G$91:$G$234,--($C$91:$C$234=$C39))*MIN(H39,$L39),0)} -> 0 | O39: {=IF(_xlfn.XLOOKUP($M39,$X$30:$X$34,$Y$30:$Y$34)<=MATCH(O$29,$N$29:$O$29,0),SUMPRODUCT(--($C$91:$C$234=$C39),$G$91:$G$234,$J$91:$J$234)/SUMPRODUCT(--($J$91:$J$234>0),$G$91:$G$234,--($C$91:$C$234=$C39))*MIN(I39,$L39),0)} -> 0 | P39: {=IF(_xlfn.XLOOKUP($M39,$X$30:$X$34,$Y$30:$Y$34)<=MATCH(N$29,$N$29:$O$29,0),SUMPRODUCT(--($C$91:$C$234=$C39),$G$91:$G$234,$F$91:$F$234,--($J$91:$J$234>0))/SUMPRODUCT(--($J$91:$J$234>0),$G$91:$G$234,--($C$91:$C$234=$C39))*MIN(H39,$L39),0)} -> 0 | Q39: {=IF(_xlfn.XLOOKUP($M39,$X$30:$X$34,$Y$30:$Y$34)<=MATCH(O$29,$N$29:$O$29,0),SUMPRODUCT(--($C$91:$C$234=$C39),$G$91:$G$234,$F$91:$F$234,--($J$91:$J$234>0))/SUMPRODUCT(--($J$91:$J$234>0),$G$91:$G$234,--($C$91:$C$234=$C39))*MIN(I39,$L39),0)} -> 0 | U39: 6001 | V39: =_xlfn.XLOOKUP(INT(U39/1000)*1000+1,$C$29:$C$85,$E$29:$E$85) -> #N/A
B40: =B32+1 -> 2 | C40: =OFFSET($D$6,B40,COUNTIF($B$29:B40,B40)) -> 3001 | D40: 30 | E40: =_xlfn.XLOOKUP(D40,价值表!$D:$D,价值表!$C:$C) | F40: 200 | G40: 0.5 | H40: =$F40/10000*6*H$28*(1-$G40) -> 0.3 | I40: =$F40/10000*6*I$28*(1-$G40) -> 0.48 | J40: 1 | K40: 2 | L40: =IF(OFFSET($D$16,B40,MATCH(E40,$E$16:$L$16,0))="","",OFFSET($D$16,B40,MATCH(E40,$E$16:$L$16,0))) -> 1 | M40: 非R | N40: {=IF(_xlfn.XLOOKUP($M40,$X$30:$X$34,$Y$30:$Y$34)<=MATCH(N$29,$N$29:$O$29,0),SUMPRODUCT(--($C$91:$C$234=$C40),$G$91:$G$234,$J$91:$J$234)/SUMPRODUCT(--($J$91:$J$234>0),$G$91:$G$234,--($C$91:$C$234=$C40))*MIN(H40,$L40),0)} -> 3360 | O40: {=IF(_xlfn.XLOOKUP($M40,$X$30:$X$34,$Y$30:$Y$34)<=MATCH(O$29,$N$29:$O$29,0),SUMPRODUCT(--($C$91:$C$234=$C40),$G$91:$G$234,$J$91:$J$234)/SUMPRODUCT(--($J$91:$J$234>0),$G$91:$G$234,--($C$91:$C$234=$C40))*MIN(I40,$L40),0)} -> 5376 | P40: {=IF(_xlfn.XLOOKUP($M40,$X$30:$X$34,$Y$30:$Y$34)<=MATCH(N$29,$N$29:$O$29,0),SUMPRODUCT(--($C$91:$C$234=$C40),$G$91:$G$234,$F$91:$F$234,--($J$91:$J$234>0))/SUMPRODUCT(--($J$91:$J$234>0),$G$91:$G$234,--($C$91:$C$234=$C40))*MIN(H40,$L40),0)} -> 0.3 | Q40: {=IF(_xlfn.XLOOKUP($M40,$X$30:$X$34,$Y$30:$Y$34)<=MATCH(O$29,$N$29:$O$29,0),SUMPRODUCT(--($C$91:$C$234=$C40),$G$91:$G$234,$F$91:$F$234,--($J$91:$J$234>0))/SUMPRODUCT(--($J$91:$J$234>0),$G$91:$G$234,--($C$91:$C$234=$C40))*MIN(I40,$L40),0)} -> 0.48 | U40: 6002 | V40: =_xlfn.XLOOKUP(INT(U40/1000)*1000+1,$C$29:$C$85,$E$29:$E$85) -> #N/A
B41: =B33+1 -> 2 | C41: =OFFSET($D$6,B41,COUNTIF($B$29:B41,B41)) -> 4001 | D41: 5305001 | E41: =_xlfn.XLOOKUP(D41,价值表!$D:$D,价值表!$C:$C) | F41: 300 | G41: 0.5 | H41: =$F41/10000*6*H$28*(1-$G41) -> 0.45 | I41: =$F41/10000*6*I$28*(1-$G41) -> 0.72 | J41: 1 | K41: 2 | L41: =IF(OFFSET($D$16,B41,MATCH(E41,$E$16:$L$16,0))="","",OFFSET($D$16,B41,MATCH(E41,$E$16:$L$16,0))) -> #N/A | M41: 非R | N41: {=IF(_xlfn.XLOOKUP($M41,$X$30:$X$34,$Y$30:$Y$34)<=MATCH(N$29,$N$29:$O$29,0),SUMPRODUCT(--($C$91:$C$234=$C41),$G$91:$G$234,$J$91:$J$234)/SUMPRODUCT(--($J$91:$J$234>0),$G$91:$G$234,--($C$91:$C$234=$C41))*MIN(H41,$L41),0)} -> #N/A | O41: {=IF(_xlfn.XLOOKUP($M41,$X$30:$X$34,$Y$30:$Y$34)<=MATCH(O$29,$N$29:$O$29,0),SUMPRODUCT(--($C$91:$C$234=$C41),$G$91:$G$234,$J$91:$J$234)/SUMPRODUCT(--($J$91:$J$234>0),$G$91:$G$234,--($C$91:$C$234=$C41))*MIN(I41,$L41),0)} -> #N/A | P41: {=IF(_xlfn.XLOOKUP($M41,$X$30:$X$34,$Y$30:$Y$34)<=MATCH(N$29,$N$29:$O$29,0),SUMPRODUCT(--($C$91:$C$234=$C41),$G$91:$G$234,$F$91:$F$234,--($J$91:$J$234>0))/SUMPRODUCT(--($J$91:$J$234>0),$G$91:$G$234,--($C$91:$C$234=$C41))*MIN(H41,$L41),0)} -> #N/A | Q41: {=IF(_xlfn.XLOOKUP($M41,$X$30:$X$34,$Y$30:$Y$34)<=MATCH(O$29,$N$29:$O$29,0),SUMPRODUCT(--($C$91:$C$234=$C41),$G$91:$G$234,$F$91:$F$234,--($J$91:$J$234>0))/SUMPRODUCT(--($J$91:$J$234>0),$G$91:$G$234,--($C$91:$C$234=$C41))*MIN(I41,$L41),0)} -> #N/A | U41: 6003 | V41: =_xlfn.XLOOKUP(INT(U41/1000)*1000+1,$C$29:$C$85,$E$29:$E$85) -> #N/A
B42: =B34+1 -> 2 | C42: =OFFSET($D$6,B42,COUNTIF($B$29:B42,B42)) -> 5002 | D42: 50002 | E42: =_xlfn.XLOOKUP(D42,价值表!$D:$D,价值表!$C:$C) | F42: 2400 | G42: 0.5 | H42: =$F42/10000*6*H$28*(1-$G42) -> 3.6 | I42: =$F42/10000*6*I$28*(1-$G42) -> 5.76 | J42: 1 | K42: 2 | L42: =IF(OFFSET($D$16,B42,MATCH(E42,$E$16:$L$16,0))="","",OFFSET($D$16,B42,MATCH(E42,$E$16:$L$16,0))) -> #N/A | M42: 非R | N42: {=IF(_xlfn.XLOOKUP($M42,$X$30:$X$34,$Y$30:$Y$34)<=MATCH(N$29,$N$29:$O$29,0),SUMPRODUCT(--($C$91:$C$234=$C42),$G$91:$G$234,$J$91:$J$234)/SUMPRODUCT(--($J$91:$J$234>0),$G$91:$G$234,--($C$91:$C$234=$C42))*MIN(H42,$L42),0)} -> #N/A | O42: {=IF(_xlfn.XLOOKUP($M42,$X$30:$X$34,$Y$30:$Y$34)<=MATCH(O$29,$N$29:$O$29,0),SUMPRODUCT(--($C$91:$C$234=$C42),$G$91:$G$234,$J$91:$J$234)/SUMPRODUCT(--($J$91:$J$234>0),$G$91:$G$234,--($C$91:$C$234=$C42))*MIN(I42,$L42),0)} -> #N/A | P42: {=IF(_xlfn.XLOOKUP($M42,$X$30:$X$34,$Y$30:$Y$34)<=MATCH(N$29,$N$29:$O$29,0),SUMPRODUCT(--($C$91:$C$234=$C42),$G$91:$G$234,$F$91:$F$234,--($J$91:$J$234>0))/SUMPRODUCT(--($J$91:$J$234>0),$G$91:$G$234,--($C$91:$C$234=$C42))*MIN(H42,$L42),0)} -> #N/A | Q42: {=IF(_xlfn.XLOOKUP($M42,$X$30:$X$34,$Y$30:$Y$34)<=MATCH(O$29,$N$29:$O$29,0),SUMPRODUCT(--($C$91:$C$234=$C42),$G$91:$G$234,$F$91:$F$234,--($J$91:$J$234>0))/SUMPRODUCT(--($J$91:$J$234>0),$G$91:$G$234,--($C$91:$C$234=$C42))*MIN(I42,$L42),0)} -> #N/A | U42: 7001 | V42: =_xlfn.XLOOKUP(INT(U42/1000)*1000+2,$C$29:$C$85,$E$29:$E$85) -> #N/A
B43: =B35+1 -> 2 | C43: =OFFSET($D$6,B43,COUNTIF($B$29:B43,B43)) -> 6001 | D43: 5203001 | E43: =_xlfn.XLOOKUP(D43,价值表!$D:$D,价值表!$C:$C) | F43: 600 | G43: 0.5 | H43: =$F43/10000*6*H$28*(1-$G43) -> 0.9 | I43: =$F43/10000*6*I$28*(1-$G43) -> 1.44 | J43: 1 | K43: 2 | L43: =IF(OFFSET($D$16,B43,MATCH(E43,$E$16:$L$16,0))="","",OFFSET($D$16,B43,MATCH(E43,$E$16:$L$16,0))) -> #N/A | M43: 大R | N43: {=IF(_xlfn.XLOOKUP($M43,$X$30:$X$34,$Y$30:$Y$34)<=MATCH(N$29,$N$29:$O$29,0),SUMPRODUCT(--($C$91:$C$234=$C43),$G$91:$G$234,$J$91:$J$234)/SUMPRODUCT(--($J$91:$J$234>0),$G$91:$G$234,--($C$91:$C$234=$C43))*MIN(H43,$L43),0)} -> 0 | O43: {=IF(_xlfn.XLOOKUP($M43,$X$30:$X$34,$Y$30:$Y$34)<=MATCH(O$29,$N$29:$O$29,0),SUMPRODUCT(--($C$91:$C$234=$C43),$G$91:$G$234,$J$91:$J$234)/SUMPRODUCT(--($J$91:$J$234>0),$G$91:$G$234,--($C$91:$C$234=$C43))*MIN(I43,$L43),0)} -> #N/A | P43: {=IF(_xlfn.XLOOKUP($M43,$X$30:$X$34,$Y$30:$Y$34)<=MATCH(N$29,$N$29:$O$29,0),SUMPRODUCT(--($C$91:$C$234=$C43),$G$91:$G$234,$F$91:$F$234,--($J$91:$J$234>0))/SUMPRODUCT(--($J$91:$J$234>0),$G$91:$G$234,--($C$91:$C$234=$C43))*MIN(H43,$L43),0)} -> 0 | Q43: {=IF(_xlfn.XLOOKUP($M43,$X$30:$X$34,$Y$30:$Y$34)<=MATCH(O$29,$N$29:$O$29,0),SUMPRODUCT(--($C$91:$C$234=$C43),$G$91:$G$234,$F$91:$F$234,--($J$91:$J$234>0))/SUMPRODUCT(--($J$91:$J$234>0),$G$91:$G$234,--($C$91:$C$234=$C43))*MIN(I43,$L43),0)} -> #N/A | U43: 7002 | V43: =_xlfn.XLOOKUP(INT(U43/1000)*1000+2,$C$29:$C$85,$E$29:$E$85) -> #N/A
B44: =B36+1 -> 2 | C44: =OFFSET($D$6,B44,COUNTIF($B$29:B44,B44)) -> 7002 | D44: 5103001 | E44: =_xlfn.XLOOKUP(D44,价值表!$D:$D,价值表!$C:$C) | F44: 2000 | G44: 0.5 | H44: =$F44/10000*6*H$28*(1-$G44) -> 3 | I44: =$F44/10000*6*I$28*(1-$G44) -> 4.8 | J44: 1 | K44: 2 | L44: =IF(OFFSET($D$16,B44,MATCH(E44,$E$16:$L$16,0))="","",OFFSET($D$16,B44,MATCH(E44,$E$16:$L$16,0))) -> #N/A | M44: 超R | N44: {=IF(_xlfn.XLOOKUP($M44,$X$30:$X$34,$Y$30:$Y$34)<=MATCH(N$29,$N$29:$O$29,0),SUMPRODUCT(--($C$91:$C$234=$C44),$G$91:$G$234,$J$91:$J$234)/SUMPRODUCT(--($J$91:$J$234>0),$G$91:$G$234,--($C$91:$C$234=$C44))*MIN(H44,$L44),0)} -> 0 | O44: {=IF(_xlfn.XLOOKUP($M44,$X$30:$X$34,$Y$30:$Y$34)<=MATCH(O$29,$N$29:$O$29,0),SUMPRODUCT(--($C$91:$C$234=$C44),$G$91:$G$234,$J$91:$J$234)/SUMPRODUCT(--($J$91:$J$234>0),$G$91:$G$234,--($C$91:$C$234=$C44))*MIN(I44,$L44),0)} -> 0 | P44: {=IF(_xlfn.XLOOKUP($M44,$X$30:$X$34,$Y$30:$Y$34)<=MATCH(N$29,$N$29:$O$29,0),SUMPRODUCT(--($C$91:$C$234=$C44),$G$91:$G$234,$F$91:$F$234,--($J$91:$J$234>0))/SUMPRODUCT(--($J$91:$J$234>0),$G$91:$G$234,--($C$91:$C$234=$C44))*MIN(H44,$L44),0)} -> 0 | Q44: {=IF(_xlfn.XLOOKUP($M44,$X$30:$X$34,$Y$30:$Y$34)<=MATCH(O$29,$N$29:$O$29,0),SUMPRODUCT(--($C$91:$C$234=$C44),$G$91:$G$234,$F$91:$F$234,--($J$91:$J$234>0))/SUMPRODUCT(--($J$91:$J$234>0),$G$91:$G$234,--($C$91:$C$234=$C44))*MIN(I44,$L44),0)} -> 0 | U44: 7003 | V44: =_xlfn.XLOOKUP(INT(U44/1000)*1000+2,$C$29:$C$85,$E$29:$E$85) -> #N/A
B45: =B37+1 -> 2 | C45: =OFFSET($D$6,B45,COUNTIF($B$29:B45,B45)) -> 8001 | D45: 1310100 | E45: =_xlfn.XLOOKUP(D45,价值表!$D:$D,价值表!$C:$C) | F45: 3200 | G45: 0.5 | H45: =$F45/10000*6*H$28*(1-$G45) -> 4.8 | I45: =$F45/10000*6*I$28*(1-$G45) -> 7.68 | J45: 1 | K45: 2 | L45: =IF(OFFSET($D$16,B45,MATCH(E45,$E$16:$L$16,0))="","",OFFSET($D$16,B45,MATCH(E45,$E$16:$L$16,0))) -> #N/A | M45: 超R | N45: {=IF(_xlfn.XLOOKUP($M45,$X$30:$X$34,$Y$30:$Y$34)<=MATCH(N$29,$N$29:$O$29,0),SUMPRODUCT(--($C$91:$C$234=$C45),$G$91:$G$234,$J$91:$J$234)/SUMPRODUCT(--($J$91:$J$234>0),$G$91:$G$234,--($C$91:$C$234=$C45))*MIN(H45,$L45),0)} -> 0 | O45: {=IF(_xlfn.XLOOKUP($M45,$X$30:$X$34,$Y$30:$Y$34)<=MATCH(O$29,$N$29:$O$29,0),SUMPRODUCT(--($C$91:$C$234=$C45),$G$91:$G$234,$J$91:$J$234)/SUMPRODUCT(--($J$91:$J$234>0),$G$91:$G$234,--($C$91:$C$234=$C45))*MIN(I45,$L45),0)} -> 0 | P45: {=IF(_xlfn.XLOOKUP($M45,$X$30:$X$34,$Y$30:$Y$34)<=MATCH(N$29,$N$29:$O$29,0),SUMPRODUCT(--($C$91:$C$234=$C45),$G$91:$G$234,$F$91:$F$234,--($J$91:$J$234>0))/SUMPRODUCT(--($J$91:$J$234>0),$G$91:$G$234,--($C$91:$C$234=$C45))*MIN(H45,$L45),0)} -> 0 | Q45: {=IF(_xlfn.XLOOKUP($M45,$X$30:$X$34,$Y$30:$Y$34)<=MATCH(O$29,$N$29:$O$29,0),SUMPRODUCT(--($C$91:$C$234=$C45),$G$91:$G$234,$F$91:$F$234,--($J$91:$J$234>0))/SUMPRODUCT(--($J$91:$J$234>0),$G$91:$G$234,--($C$91:$C$234=$C45))*MIN(I45,$L45),0)} -> 0 | U45: 8001 | V45: =_xlfn.XLOOKUP(INT(U45/1000)*1000+1,$C$29:$C$85,$E$29:$E$85) -> #N/A
B46: =B38+1 -> 3 | C46: =OFFSET($D$6,B46,COUNTIF($B$29:B46,B46)) -> 1001 | D46: 11 | E46: =_xlfn.XLOOKUP(D46,价值表!$D:$D,价值表!$C:$C) | F46: 700 | G46: 0.5 | H46: =$F46/10000*6*H$28*(1-$G46) -> 1.05 | I46: =$F46/10000*6*I$28*(1-$G46) -> 1.68 | J46: 1 | K46: 2 | L46: =IF(OFFSET($D$16,B46,MATCH(E46,$E$16:$L$16,0))="","",OFFSET($D$16,B46,MATCH(E46,$E$16:$L$16,0))) -> #N/A | M46: 非R | N46: {=IF(_xlfn.XLOOKUP($M46,$X$30:$X$34,$Y$30:$Y$34)<=MATCH(N$29,$N$29:$O$29,0),SUMPRODUCT(--($C$91:$C$234=$C46),$G$91:$G$234,$J$91:$J$234)/SUMPRODUCT(--($J$91:$J$234>0),$G$91:$G$234,--($C$91:$C$234=$C46))*MIN(H46,$L46),0)} -> #N/A | O46: {=IF(_xlfn.XLOOKUP($M46,$X$30:$X$34,$Y$30:$Y$34)<=MATCH(O$29,$N$29:$O$29,0),SUMPRODUCT(--($C$91:$C$234=$C46),$G$91:$G$234,$J$91:$J$234)/SUMPRODUCT(--($J$91:$J$234>0),$G$91:$G$234,--($C$91:$C$234=$C46))*MIN(I46,$L46),0)} -> #N/A | P46: {=IF(_xlfn.XLOOKUP($M46,$X$30:$X$34,$Y$30:$Y$34)<=MATCH(N$29,$N$29:$O$29,0),SUMPRODUCT(--($C$91:$C$234=$C46),$G$91:$G$234,$F$91:$F$234,--($J$91:$J$234>0))/SUMPRODUCT(--($J$91:$J$234>0),$G$91:$G$234,--($C$91:$C$234=$C46))*MIN(H46,$L46),0)} -> #N/A | Q46: {=IF(_xlfn.XLOOKUP($M46,$X$30:$X$34,$Y$30:$Y$34)<=MATCH(O$29,$N$29:$O$29,0),SUMPRODUCT(--($C$91:$C$234=$C46),$G$91:$G$234,$F$91:$F$234,--($J$91:$J$234>0))/SUMPRODUCT(--($J$91:$J$234>0),$G$91:$G$234,--($C$91:$C$234=$C46))*MIN(I46,$L46),0)} -> #N/A
...

Sheet 首充
C2: 首充挡位 | D2: 首充类型 | E2: 道具 | F2: 数量 | G2: 价值 | H2: 总价值(钻石) | I2: 价格 | J2: 性价比
C3: 6 | D3: 首充 | E3: 总和 | J3: =SUM(H3:H14)/I4 -> 124.4
E4: 传说武器皮肤 | F4: 1 | G4: =_xlfn.XLOOKUP(E4,价值表!C:C,价值表!F:F)*F4 -> 4000 | H4: =SUM(G4:G6) -> 5324 | I4: 60 | J4: =H4/I4 -> 88.733333
E5: 梦境招募器 | F5: 10 | G5: =_xlfn.XLOOKUP(E5,价值表!C:C,价值表!F:F)*F5 -> 300
E6: 史诗符文 | F6: 1 | G6: =_xlfn.XLOOKUP(E6,价值表!C:C,价值表!F:F)*F6 -> 1024
E7: 当天特权体验卡 | F7: 1 | G7: 0
E9: 梦境招募器 | F9: 20 | G9: =_xlfn.XLOOKUP(E9,价值表!C:C,价值表!F:F)*F9 -> 600 | H9: =SUM(G9:G11) -> 1100 | I9: 60 | J9: =H9/I9 -> 18.333333
E10: 能量特饮 | F10: 500 | G10: =_xlfn.XLOOKUP(E10,价值表!C:C,价值表!F:F)*F10 -> 500
E12: 传说梦灵 | F12: 1 | G12: =_xlfn.XLOOKUP(E12,价值表!C:C,价值表!F:F)*F12 -> 240 | H12: =SUM(G12:G14) -> 1040 | I12: 60 | J12: =H12/I12 -> 17.333333
E13: 能量特饮 | F13: 800 | G13: =_xlfn.XLOOKUP(E13,价值表!C:C,价值表!F:F)*F13 -> 800
C16: 列1 | D16: 累充 | E16: 道具 | F16: 数量 | G16: 价值 | H16: 总价值(钻石) | I16: 价格 | J16: 性价比
C17: 30 | D17: 累充 | E17: 总和 | J17: =SUM(H17:H28)/I18 -> 11.386667 | L17: =IF(K17="","","{"&K17&","&F17&"}")
D18: 随机 | E18: 史诗梦灵皮肤 | F18: 1 | G18: =_xlfn.XLOOKUP(E18,价值表!C:C,价值表!F:F)*F18 -> 1500 | H18: =SUM(G18:G20) -> 2010 | I18: 300 | J18: =H18/I18 -> 6.7
E19: 装备图纸 | F19: 120 | G19: =_xlfn.XLOOKUP(E19,价值表!C:C,价值表!F:F)*F19 -> 360
E20: 金币 | F20: 3000 | G20: =_xlfn.XLOOKUP(E20,价值表!C:C,价值表!F:F)*F20 -> 150
D23: 第二天 | E23: 星之初愿 | F23: 5 | G23: =_xlfn.XLOOKUP(E23,价值表!C:C,价值表!F:F)*F23 -> 250 | H23: =SUM(G23:G25) -> 610 | I23: 300 | J23: =H23/I23 -> 2.0333333
E24: 装备图纸 | F24: 120 | G24: =_xlfn.XLOOKUP(E24,价值表!C:C,价值表!F:F)*F24 -> 360
D26: 第三天 | E26: 转运石 | F26: 1200 | G26: =_xlfn.XLOOKUP(E26,价值表!C:C,价值表!F:F)*F26 -> 396 | H26: =SUM(G26:G28) -> 796 | I26: 300 | J26: =H26/I26 -> 2.6533333
E27: 超能特饮 | F27: 200 | G27: =_xlfn.XLOOKUP(E27,价值表!C:C,价值表!F:F)*F27 -> 400
O29: 第二天开启
C30: 首充挡位 | D30: 累充 | E30: 道具 | F30: 数量 | G30: 价值 | H30: 总价值(钻石) | I30: 价格 | J30: 性价比 | N30: 首充挡位 | O30: 累充 | P30: 道具 | Q30: 数量 | R30: 价值 | S30: 总价值(钻石) | T30: 价格 | U30: 性价比 | V30: 列1
C31: 98 | D31: 累充 | E31: 总和 | J31: =SUM(H31:H42)/I32 -> 7.8163265 | N31: 128 | O31: 直充 | P31: 总和 | U31: =SUM(S31:S42)/T32 -> 5.9191919
D32: 玉如意 | E32: 传说武器皮肤 | F32: 1 | G32: =_xlfn.XLOOKUP(E32,价值表!$C:$C,价值表!$F:$F)*F32 -> 4000 | H32: =SUM(G32:G34) -> 4790 | I32: 980 | J32: =H32/I32 -> 4.8877551 | O32: 随机 | P32: 传说梦灵皮肤 | Q32: 1 | R32: =_xlfn.XLOOKUP(P32,价值表!$C:$C,价值表!$F:$F)*Q32 -> 4000 | S32: =SUM(R32:R35) -> 6280 | T32: 1980 | U32: =S32/T32 -> 3.1717172 | V32: 100008
E33: 装备图纸 | F33: 180 | G33: =_xlfn.XLOOKUP(E33,价值表!C:C,价值表!F:F)*F33 -> 540 | P33: 钻石 | Q33: 980 | R33: =_xlfn.XLOOKUP(P33,价值表!$C:$C,价值表!$F:$F)*Q33 -> 980 | V33: =_xlfn.XLOOKUP(P33,价值表!$C:$C,价值表!$D:$D) -> 1
E34: 金币 | F34: 5000 | G34: =_xlfn.XLOOKUP(E34,价值表!C:C,价值表!F:F)*F34 -> 250 | P34: 装备图纸 | Q34: 300 | R34: =_xlfn.XLOOKUP(P34,价值表!$C:$C,价值表!$F:$F)*Q34 -> 900 | V34: =_xlfn.XLOOKUP(P34,价值表!$C:$C,价值表!$D:$D) -> 50002
P35: 金币 | Q35: 8000 | R35: =_xlfn.XLOOKUP(P35,价值表!$C:$C,价值表!$F:$F)*Q35 -> 400 | V35: =_xlfn.XLOOKUP(P35,价值表!$C:$C,价值表!$D:$D) -> 2
D37: 第二天 | E37: 星辉秘契 | F37: 2 | G37: =_xlfn.XLOOKUP(E37,价值表!C:C,价值表!F:F)*F37 -> 560 | H37: =SUM(G37:G39) -> 1280 | I37: 980 | J37: =H37/I37 -> 1.3061224 | O37: 第二天 | P37: 梦境招募器 | Q37: 20 | R37: =_xlfn.XLOOKUP(P37,价值表!$C:$C,价值表!$F:$F)*Q37 -> 600 | S37: =SUM(R37:R39) -> 1200 | T37: 1980 | U37: =S37/T37 -> 0.60606061 | V37: =_xlfn.XLOOKUP(P37,价值表!$C:$C,价值表!$D:$D) -> 11
E38: 装备图纸 | F38: 240 | G38: =_xlfn.XLOOKUP(E38,价值表!C:C,价值表!F:F)*F38 -> 720 | P38: 超能特饮 | Q38: 300 | R38: =_xlfn.XLOOKUP(P38,价值表!$C:$C,价值表!$F:$F)*Q38 -> 600 | V38: =_xlfn.XLOOKUP(P38,价值表!$C:$C,价值表!$D:$D) -> 5104001
D40: 第三天 | E40: 转运石 | F40: 3000 | G40: =_xlfn.XLOOKUP(E40,价值表!C:C,价值表!F:F)*F40 -> 990 | H40: =SUM(G40:G42) -> 1590 | I40: 980 | J40: =H40/I40 -> 1.622449 | O40: 第三天 | P40: 星辉秘契 | Q40: 10 | R40: =_xlfn.XLOOKUP(P40,价值表!$C:$C,价值表!$F:$F)*Q40 -> 2800 | S40: =SUM(R40:R42) -> 4240 | T40: 1980 | U40: =S40/T40 -> 2.1414141 | V40: =_xlfn.XLOOKUP(P40,价值表!$C:$C,价值表!$D:$D) -> 30
E41: 超能特饮 | F41: 300 | G41: =_xlfn.XLOOKUP(E41,价值表!C:C,价值表!F:F)*F41 -> 600 | P41: 幻梦晶核 | Q41: 24 | R41: =_xlfn.XLOOKUP(P41,价值表!$C:$C,价值表!$F:$F)*Q41 -> 1440 | V41: =_xlfn.XLOOKUP(P41,价值表!$C:$C,价值表!$D:$D) -> 5305001

Sheet 日月周礼包
B2: 总产出
B3: ID | C3: 每日 | D3: 每周 | E3: 每月
B4: 体力 | C4: {=SUMPRODUCT(--($B$20:$B$62<999+MATCH(C$3,$C$3:$E$3,0)*1000),--($O$20:$O$62=$B4),$K$20:$K$62,$G$20:$G$62)/_xlfn.XLOOKUP($B4,价值表!$C:$C,价值表!$F:$F)} -> 70 | D4: {=SUMPRODUCT(--($B$20:$B$62<999+MATCH(D$3,$C$3:$E$3,0)*1000),--($O$20:$O$62=$B4),$K$20:$K$62,$G$20:$G$62)/_xlfn.XLOOKUP($B4,价值表!$C:$C,价值表!$F:$F)} -> 370 | E4: {=SUMPRODUCT(--($B$20:$B$62<999+MATCH(E$3,$C$3:$E$3,0)*1000),--($O$20:$O$62=$B4),$K$20:$K$62,$G$20:$G$62)/_xlfn.XLOOKUP($B4,价值表!$C:$C,价值表!$F:$F)} -> 370
B5: 金币 | C5: {=SUMPRODUCT(--($B$20:$B$62<999+MATCH(C$3,$C$3:$E$3,0)*1000),--($O$20:$O$62=$B5),$K$20:$K$62,$G$20:$G$62)/_xlfn.XLOOKUP($B5,价值表!$C:$C,价值表!$F:$F)} -> 10000 | D5: {=SUMPRODUCT(--($B$20:$B$62<999+MATCH(D$3,$C$3:$E$3,0)*1000),--($O$20:$O$62=$B5),$K$20:$K$62,$G$20:$G$62)/_xlfn.XLOOKUP($B5,价值表!$C:$C,价值表!$F:$F)} -> 20000 | E5: {=SUMPRODUCT(--($B$20:$B$62<999+MATCH(E$3,$C$3:$E$3,0)*1000),--($O$20:$O$62=$B5),$K$20:$K$62,$G$20:$G$62)/_xlfn.XLOOKUP($B5,价值表!$C:$C,价值表!$F:$F)} -> 20000
B6: 梦境招募器 | C6: {=SUMPRODUCT(--($B$20:$B$62<999+MATCH(C$3,$C$3:$E$3,0)*1000),--($O$20:$O$62=$B6),$K$20:$K$62,$G$20:$G$62)/_xlfn.XLOOKUP($B6,价值表!$C:$C,价值表!$F:$F)} -> 40 | D6: {=SUMPRODUCT(--($B$20:$B$62<999+MATCH(D$3,$C$3:$E$3,0)*1000),--($O$20:$O$62=$B6),$K$20:$K$62,$G$20:$G$62)/_xlfn.XLOOKUP($B6,价值表!$C:$C,价值表!$F:$F)} -> 490 | E6: {=SUMPRODUCT(--($B$20:$B$62<999+MATCH(E$3,$C$3:$E$3,0)*1000),--($O$20:$O$62=$B6),$K$20:$K$62,$G$20:$G$62)/_xlfn.XLOOKUP($B6,价值表!$C:$C,价值表!$F:$F)} -> 990 | H6: 日周月礼包这边核心道具的标准价值
B7: 能量特饮 | C7: {=SUMPRODUCT(--($B$20:$B$62<999+MATCH(C$3,$C$3:$E$3,0)*1000),--($O$20:$O$62=$B7),$K$20:$K$62,$G$20:$G$62)/_xlfn.XLOOKUP($B7,价值表!$C:$C,价值表!$F:$F)} -> 1200 | D7: {=SUMPRODUCT(--($B$20:$B$62<999+MATCH(D$3,$C$3:$E$3,0)*1000),--($O$20:$O$62=$B7),$K$20:$K$62,$G$20:$G$62)/_xlfn.XLOOKUP($B7,价值表!$C:$C,价值表!$F:$F)} -> 1200 | E7: {=SUMPRODUCT(--($B$20:$B$62<999+MATCH(E$3,$C$3:$E$3,0)*1000),--($O$20:$O$62=$B7),$K$20:$K$62,$G$20:$G$62)/_xlfn.XLOOKUP($B7,价值表!$C:$C,价值表!$F:$F)} -> 1200
B8: 超能特饮 | C8: {=SUMPRODUCT(--($B$20:$B$62<999+MATCH(C$3,$C$3:$E$3,0)*1000),--($O$20:$O$62=$B8),$K$20:$K$62,$G$20:$G$62)/_xlfn.XLOOKUP($B8,价值表!$C:$C,价值表!$F:$F)} -> 600 | D8: {=SUMPRODUCT(--($B$20:$B$62<999+MATCH(D$3,$C$3:$E$3,0)*1000),--($O$20:$O$62=$B8),$K$20:$K$62,$G$20:$G$62)/_xlfn.XLOOKUP($B8,价值表!$C:$C,价值表!$F:$F)} -> 4600 | E8: {=SUMPRODUCT(--($B$20:$B$62<999+MATCH(E$3,$C$3:$E$3,0)*1000),--($O$20:$O$62=$B8),$K$20:$K$62,$G$20:$G$62)/_xlfn.XLOOKUP($B8,价值表!$C:$C,价值表!$F:$F)} -> 14600 | H8: 周商店里面 | I8: 价值（钻 | J8: 折扣
B9: 装备图纸 | C9: {=SUMPRODUCT(--($B$20:$B$62<999+MATCH(C$3,$C$3:$E$3,0)*1000),--($O$20:$O$62=$B9),$K$20:$K$62,$G$20:$G$62)/_xlfn.XLOOKUP($B9,价值表!$C:$C,价值表!$F:$F)} -> 300 | D9: {=SUMPRODUCT(--($B$20:$B$62<999+MATCH(D$3,$C$3:$E$3,0)*1000),--($O$20:$O$62=$B9),$K$20:$K$62,$G$20:$G$62)/_xlfn.XLOOKUP($B9,价值表!$C:$C,价值表!$F:$F)} -> 900 | E9: {=SUMPRODUCT(--($B$20:$B$62<999+MATCH(E$3,$C$3:$E$3,0)*1000),--($O$20:$O$62=$B9),$K$20:$K$62,$G$20:$G$62)/_xlfn.XLOOKUP($B9,价值表!$C:$C,价值表!$F:$F)} -> 2100 | H9: 招募卷 | I9: =1050/50 -> 21 | J9: 7折礼包
B10: 星辉秘契 | C10: {=SUMPRODUCT(--($B$20:$B$62<999+MATCH(C$3,$C$3:$E$3,0)*1000),--($O$20:$O$62=$B10),$K$20:$K$62,$G$20:$G$62)/_xlfn.XLOOKUP($B10,价值表!$C:$C,价值表!$F:$F)} -> 21 | D10: {=SUMPRODUCT(--($B$20:$B$62<999+MATCH(D$3,$C$3:$E$3,0)*1000),--($O$20:$O$62=$B10),$K$20:$K$62,$G$20:$G$62)/_xlfn.XLOOKUP($B10,价值表!$C:$C,价值表!$F:$F)} -> 171 | E10: {=SUMPRODUCT(--($B$20:$B$62<999+MATCH(E$3,$C$3:$E$3,0)*1000),--($O$20:$O$62=$B10),$K$20:$K$62,$G$20:$G$62)/_xlfn.XLOOKUP($B10,价值表!$C:$C,价值表!$F:$F)} -> 321 | H10: 招募卷 | I10: =1800/100 -> 18 | J10: 6折礼包
B11: 符引结晶 | C11: {=SUMPRODUCT(--($B$20:$B$62<999+MATCH(C$3,$C$3:$E$3,0)*1000),--($O$20:$O$62=$B11),$K$20:$K$62,$G$20:$G$62)/_xlfn.XLOOKUP($B11,价值表!$C:$C,价值表!$F:$F)} -> 100 | D11: {=SUMPRODUCT(--($B$20:$B$62<999+MATCH(D$3,$C$3:$E$3,0)*1000),--($O$20:$O$62=$B11),$K$20:$K$62,$G$20:$G$62)/_xlfn.XLOOKUP($B11,价值表!$C:$C,价值表!$F:$F)} -> 400 | E11: {=SUMPRODUCT(--($B$20:$B$62<999+MATCH(E$3,$C$3:$E$3,0)*1000),--($O$20:$O$62=$B11),$K$20:$K$62,$G$20:$G$62)/_xlfn.XLOOKUP($B11,价值表!$C:$C,价值表!$F:$F)} -> 400 | H11: 体力 | I11: =96/60 -> 1.6 | J11: 8折
B12: 织梦微尘 | C12: {=SUMPRODUCT(--($B$20:$B$62<999+MATCH(C$3,$C$3:$E$3,0)*1000),--($O$20:$O$62=$B12),$K$20:$K$62,$G$20:$G$62)/_xlfn.XLOOKUP($B12,价值表!$C:$C,价值表!$F:$F)} -> 300 | D12: {=SUMPRODUCT(--($B$20:$B$62<999+MATCH(D$3,$C$3:$E$3,0)*1000),--($O$20:$O$62=$B12),$K$20:$K$62,$G$20:$G$62)/_xlfn.XLOOKUP($B12,价值表!$C:$C,价值表!$F:$F)} -> 900 | E12: {=SUMPRODUCT(--($B$20:$B$62<999+MATCH(E$3,$C$3:$E$3,0)*1000),--($O$20:$O$62=$B12),$K$20:$K$62,$G$20:$G$62)/_xlfn.XLOOKUP($B12,价值表!$C:$C,价值表!$F:$F)} -> 900 | H12: 星辉秘契 | I12: =840/5 -> 168 | J12: 6折
B13: 锻造晶石 | C13: {=SUMPRODUCT(--($B$20:$B$62<999+MATCH(C$3,$C$3:$E$3,0)*1000),--($O$20:$O$62=$B13),$K$20:$K$62,$G$20:$G$62)/_xlfn.XLOOKUP($B13,价值表!$C:$C,价值表!$F:$F)} -> 2500 | D13: {=SUMPRODUCT(--($B$20:$B$62<999+MATCH(D$3,$C$3:$E$3,0)*1000),--($O$20:$O$62=$B13),$K$20:$K$62,$G$20:$G$62)/_xlfn.XLOOKUP($B13,价值表!$C:$C,价值表!$F:$F)} -> 2500 | E13: {=SUMPRODUCT(--($B$20:$B$62<999+MATCH(E$3,$C$3:$E$3,0)*1000),--($O$20:$O$62=$B13),$K$20:$K$62,$G$20:$G$62)/_xlfn.XLOOKUP($B13,价值表!$C:$C,价值表!$F:$F)} -> 2500 | H13: 幻梦晶核 | I13: =216/6 -> 36 | J13: 6折
B14: 幻梦晶核 | C14: {=SUMPRODUCT(--($B$20:$B$62<999+MATCH(C$3,$C$3:$E$3,0)*1000),--($O$20:$O$62=$B14),$K$20:$K$62,$G$20:$G$62)/_xlfn.XLOOKUP($B14,价值表!$C:$C,价值表!$F:$F)} -> 12 | D14: {=SUMPRODUCT(--($B$20:$B$62<999+MATCH(D$3,$C$3:$E$3,0)*1000),--($O$20:$O$62=$B14),$K$20:$K$62,$G$20:$G$62)/_xlfn.XLOOKUP($B14,价值表!$C:$C,价值表!$F:$F)} -> 36 | E14: {=SUMPRODUCT(--($B$20:$B$62<999+MATCH(E$3,$C$3:$E$3,0)*1000),--($O$20:$O$62=$B14),$K$20:$K$62,$G$20:$G$62)/_xlfn.XLOOKUP($B14,价值表!$C:$C,价值表!$F:$F)} -> 256
B15: 转运石 | C15: {=SUMPRODUCT(--($B$20:$B$62<999+MATCH(C$3,$C$3:$E$3,0)*1000),--($O$20:$O$62=$B15),$K$20:$K$62,$G$20:$G$62)/_xlfn.XLOOKUP($B15,价值表!$C:$C,价值表!$F:$F)} -> 3000 | D15: {=SUMPRODUCT(--($B$20:$B$62<999+MATCH(D$3,$C$3:$E$3,0)*1000),--($O$20:$O$62=$B15),$K$20:$K$62,$G$20:$G$62)/_xlfn.XLOOKUP($B15,价值表!$C:$C,价值表!$F:$F)} -> 12000 | E15: {=SUMPRODUCT(--($B$20:$B$62<999+MATCH(E$3,$C$3:$E$3,0)*1000),--($O$20:$O$62=$B15),$K$20:$K$62,$G$20:$G$62)/_xlfn.XLOOKUP($B15,价值表!$C:$C,价值表!$F:$F)} -> 72000
B16: 加速沙漏 | C16: {=SUMPRODUCT(--($B$20:$B$62<999+MATCH(C$3,$C$3:$E$3,0)*1000),--($O$20:$O$62=$B16),$K$20:$K$62,$G$20:$G$62)/_xlfn.XLOOKUP($B16,价值表!$C:$C,价值表!$F:$F)} -> 0 | D16: {=SUMPRODUCT(--($B$20:$B$62<999+MATCH(D$3,$C$3:$E$3,0)*1000),--($O$20:$O$62=$B16),$K$20:$K$62,$G$20:$G$62)/_xlfn.XLOOKUP($B16,价值表!$C:$C,价值表!$F:$F)} -> 240 | E16: {=SUMPRODUCT(--($B$20:$B$62<999+MATCH(E$3,$C$3:$E$3,0)*1000),--($O$20:$O$62=$B16),$K$20:$K$62,$G$20:$G$62)/_xlfn.XLOOKUP($B16,价值表!$C:$C,价值表!$F:$F)} -> 240
B17: 传说符文 | C17: {=SUMPRODUCT(--($B$20:$B$62<999+MATCH(C$3,$C$3:$E$3,0)*1000),--($O$20:$O$62=$B17),$K$20:$K$62,$G$20:$G$62)/_xlfn.XLOOKUP($B17,价值表!$C:$C,价值表!$F:$F)} -> 0 | D17: {=SUMPRODUCT(--($B$20:$B$62<999+MATCH(D$3,$C$3:$E$3,0)*1000),--($O$20:$O$62=$B17),$K$20:$K$62,$G$20:$G$62)/_xlfn.XLOOKUP($B17,价值表!$C:$C,价值表!$F:$F)} -> 0 | E17: {=SUMPRODUCT(--($B$20:$B$62<999+MATCH(E$3,$C$3:$E$3,0)*1000),--($O$20:$O$62=$B17),$K$20:$K$62,$G$20:$G$62)/_xlfn.XLOOKUP($B17,价值表!$C:$C,价值表!$F:$F)} -> 1
B18: 神话符文 | C18: {=SUMPRODUCT(--($B$20:$B$62<999+MATCH(C$3,$C$3:$E$3,0)*1000),--($O$20:$O$62=$B18),$K$20:$K$62,$G$20:$G$62)/_xlfn.XLOOKUP($B18,价值表!$C:$C,价值表!$F:$F)} -> 0 | D18: {=SUMPRODUCT(--($B$20:$B$62<999+MATCH(D$3,$C$3:$E$3,0)*1000),--($O$20:$O$62=$B18),$K$20:$K$62,$G$20:$G$62)/_xlfn.XLOOKUP($B18,价值表!$C:$C,价值表!$F:$F)} -> 0 | E18: {=SUMPRODUCT(--($B$20:$B$62<999+MATCH(E$3,$C$3:$E$3,0)*1000),--($O$20:$O$62=$B18),$K$20:$K$62,$G$20:$G$62)/_xlfn.XLOOKUP($B18,价值表!$C:$C,价值表!$F:$F)} -> 1
B20: ID | C20: 开服时间节点 | D20: 商品名称 | E20: 奖励 | F20: 价格 | G20: 购买次数 | H20: 折扣 | I20: 物品ID | J20: 价值 | K20: 总价值 | L20: 性价比 | M20: 折扣配置 | N20: 标准折扣 | O20: 道具
B21: 1001 | C21: 2 | D21: 免费体力 | E21: [{13,10}] | G21: 1 | I21: =IF(B21="","",SUBSTITUTE(LEFT(E21,FIND(",",E21)-1),"","")) -> [{13 | J21: =_xlfn.XLOOKUP(--SUBSTITUTE(LEFT(E21,FIND(",",E21)-1),"[{",""),价值表!D:D,价值表!F:F) -> 2 | K21: =J21*SUBSTITUTE(SUBSTITUTE(E21,""&I21&",",""),"}]","") -> 20 | L21: =SUBSTITUTE(SUBSTITUTE(F21,"1,",""),"}]","") | N21: =_xlfn.XLOOKUP(--SUBSTITUTE(I21,"[{",""),价值表!D:D,价值表!J:J) -> 7 | O21: =IFERROR(_xlfn.XLOOKUP(IF(E21="","",--SUBSTITUTE(LEFT(E21,FIND(",",E21)-1),"[{","")),价值表!D:D,价值表!C:C),"") -> 体力
B22: 1002 | C22: 2 | D22: 体力 | E22: [{13,60}] | F22: [{1,96}] | G22: 1 | H22: 8折 | I22: =IF(B22="","",SUBSTITUTE(LEFT(E22,FIND(",",E22)-1),"","")) -> [{13 | J22: =_xlfn.XLOOKUP(--SUBSTITUTE(LEFT(E22,FIND(",",E22)-1),"[{",""),价值表!D:D,价值表!F:F) -> 2 | K22: =J22*SUBSTITUTE(SUBSTITUTE(E22,""&I22&",",""),"}]","") -> 120 | L22: =K22/SUBSTITUTE(SUBSTITUTE(SUBSTITUTE(F22,"1,",""),"}]",""),"[{","") -> 1.25 | M22: =ROUND(1/L22*10,0)&"折" -> 8折 | N22: =_xlfn.XLOOKUP(--SUBSTITUTE(I22,"[{",""),价值表!D:D,价值表!J:J) -> 7 | O22: =IFERROR(_xlfn.XLOOKUP(IF(E22="","",--SUBSTITUTE(LEFT(E22,FIND(",",E22)-1),"[{","")),价值表!D:D,价值表!C:C),"") -> 体力
B23: 1003 | C23: 2 | D23: 金币 | E23: [{2,5000}] | F23: [{1,125}] | G23: 2 | H23: 5折 | I23: =IF(B23="","",SUBSTITUTE(LEFT(E23,FIND(",",E23)-1),"","")) -> [{2 | J23: =_xlfn.XLOOKUP(--SUBSTITUTE(LEFT(E23,FIND(",",E23)-1),"[{",""),价值表!D:D,价值表!F:F) -> 0.05 | K23: =J23*SUBSTITUTE(SUBSTITUTE(E23,""&I23&",",""),"}]","") -> 250 | L23: =K23/SUBSTITUTE(SUBSTITUTE(SUBSTITUTE(F23,"1,",""),"}]",""),"[{","") -> 2 | M23: =ROUND(1/L23*10,0)&"折" -> 5折 | N23: =_xlfn.XLOOKUP(--SUBSTITUTE(I23,"[{",""),价值表!D:D,价值表!J:J) -> 5 | O23: =IFERROR(_xlfn.XLOOKUP(IF(E23="","",--SUBSTITUTE(LEFT(E23,FIND(",",E23)-1),"[{","")),价值表!D:D,价值表!C:C),"") -> 金币
