Workbook

Sheet 说明
A1: 载具养成
A3: 说明
C5: 载具强化与零件
D6: 载具属性=载具强化（耐久）+零件升级（攻击力/耐久），总坑深见「载具属性」
D7: 零件升级消耗【零件碎片】+【金币】；零件品质 史诗/传说/神话/创世，碎片价值200/400/800/1600钻
D8: 零件抽取产出见「载具产出」，各分层拿到的零件见「载具预期」
D9: 开放：配置为开服第22天+第60章（「养成规划」写的29天+50关已过时）
C11: 载具技能
D12: 零件技能（耐久、反伤、半场增伤、护盾等）见「载具属性」G519起
C16: 关联配置
D18: 配置 | E18: 字段 | F18: 值 | G18: 说明
D19: Z_载具养成_vehicle_data | G19: *强化、零件、技能
D20: D_道具_item_data | G20: *零件、碎片道具
G22: *预留最后一行
A24: 本页结束

Sheet 养成规划
A1: 养成属性
C3: 属性规划
D5: 功能开启
E6: 29天+50关
A21: 本页结束

Sheet 载具属性
A1: 设计思路
C3: 属性规划
D5: 属性总览 | E5: 载具耐久 | F5: 攻击力
D6: 载具强化 | E6: =SUM(F98:F497) -> 38950
D7: 零件升级 | E7: {=SUMPRODUCT(L30:O30,$L$93:$O$93)} -> 25200 | F7: {=SUMPRODUCT(P30:S30,P93:S93)} -> 9720
F9: =_xlfn.XLOOKUP(F10,价值表!$F:$F,价值表!$H:$H) -> 1 | G9: =_xlfn.XLOOKUP(G10,价值表!$F:$F,价值表!$H:$H) -> 0.05 | H9: =_xlfn.XLOOKUP(H10,价值表!$F:$F,价值表!$H:$H) -> 200 | I9: =_xlfn.XLOOKUP(I10,价值表!$F:$F,价值表!$H:$H) -> 400 | J9: =_xlfn.XLOOKUP(J10,价值表!$F:$F,价值表!$H:$H) -> 800 | K9: =_xlfn.XLOOKUP(K10,价值表!$F:$F,价值表!$H:$H) -> 1600
D10: 总坑深 | E10: 数量 | F10: 零件 | G10: 金币 | H10: 史诗零件碎片 | I10: 传说零件碎片 | J10: 神话零件碎片 | K10: 创世零件碎片 | L10: 总坑深
D11: 载具强化 | E11: 1 | F11: =SUM(H98:H497)*F9 -> 1024950 | L11: =SUM(F11:K11)*E11 -> 1024950
D12: 史诗零件升级 | E12: 3 | G12: =SUM(H33:H92)*G9 -> 10841.25 | H12: =SUM($F$33:$F$92)*H$9 -> 1211000 | L12: =SUM(F12:K12)*E12 -> 3665523.8
D13: 传说零件升级 | E13: 4 | G13: =SUM(I33:I92)*G9 -> 18068.75 | I13: =SUM($F$33:$F$92)*I$9 -> 2422000 | L13: =SUM(F13:K13)*E13 -> 9760275
D14: 神话零件升级 | E14: 6 | G14: =SUM(J33:J92)*G9 -> 28910 | J14: =SUM($F$33:$F$92)*J$9 -> 4844000 | L14: =SUM(F14:K14)*E14 -> 29237460
D15: 创世零件升级 | E15: 8 | G15: =SUM(K33:K92)*G9 -> 43365 | K15: =SUM($F$33:$F$92)*K$9 -> 9688000 | L15: =SUM(F15:K15)*E15 -> 77850920
A26: 载具养成数值和消耗
C28: 养成数值
F30: *升下级消耗 | H30: *升下级消耗 | L30: 2 | M30: 2 | N30: 2 | O30: 2 | P30: 1 | Q30: 2 | R30: 4 | S30: 6
H31: 金币消耗 | L31: 耐久加成 | P31: 攻击加成
D32: 载具零件 | E32: 等级 | F32: 升级消耗 | G32: 升级总消耗 | H32: 史诗零件 | I32: 传说零件 | J32: 神话零件 | K32: 创世零件 | L32: 史诗零件 | M32: 传说零件 | N32: 神话零件 | O32: 创世零件 | P32: 史诗零件 | Q32: 传说零件 | R32: 神话零件 | S32: 创世零件
D33: 零件 | E33: 0 | F33: 10 | G33: =SUM($F$33:F33) -> 10
D34: 零件 | E34: =E33+1 -> 1 | F34: 5 | G34: =SUM($F$33:F34) -> 15 | H34: 1500 | I34: 2500 | J34: 4000 | K34: 6000 | L34: 30 | M34: 45 | N34: 60 | O34: 75 | P34: 6 | Q34: 9 | R34: 12 | S34: 15 | U34: ="[{2,"&H34&"}]" -> [{2,1500}] | V34: ="[{2,"&I34&"}]" -> [{2,2500}] | W34: ="[{2,"&J34&"}]" -> [{2,4000}] | X34: ="[{2,"&K34&"}]" -> [{2,6000}]
D35: 零件 | E35: =E34+1 -> 2 | F35: 5 | G35: =SUM($F$33:F35) -> 20 | H35: =H34+75 -> 1575 | I35: =I34+125 -> 2625 | J35: =J34+200 -> 4200 | K35: =K34+300 -> 6300 | L35: =L$34*$E35 -> 60 | M35: =M$34*$E35 -> 90 | N35: =N$34*$E35 -> 120 | O35: =O$34*$E35 -> 150 | P35: =P$34*$E35 -> 12 | Q35: =Q$34*$E35 -> 18 | R35: =R$34*$E35 -> 24 | S35: =S$34*$E35 -> 30 | U35: ="[{2,"&H35&"}]" -> [{2,1575}] | V35: ="[{2,"&I35&"}]" -> [{2,2625}] | W35: ="[{2,"&J35&"}]" -> [{2,4200}] | X35: ="[{2,"&K35&"}]" -> [{2,6300}]
D36: 零件 | E36: =E35+1 -> 3 | F36: 5 | G36: =SUM($F$33:F36) -> 25 | H36: =H35+75 -> 1650 | I36: =I35+125 -> 2750 | J36: =J35+200 -> 4400 | K36: =K35+300 -> 6600 | L36: =L$34*$E36 -> 90 | M36: =M$34*$E36 -> 135 | N36: =N$34*$E36 -> 180 | O36: =O$34*$E36 -> 225 | P36: =P$34*$E36 -> 18 | Q36: =Q$34*$E36 -> 27 | R36: =R$34*$E36 -> 36 | S36: =S$34*$E36 -> 45 | U36: ="[{2,"&H36&"}]" -> [{2,1650}] | V36: ="[{2,"&I36&"}]" -> [{2,2750}] | W36: ="[{2,"&J36&"}]" -> [{2,4400}] | X36: ="[{2,"&K36&"}]" -> [{2,6600}]
D37: 零件 | E37: =E36+1 -> 4 | F37: 5 | G37: =SUM($F$33:F37) -> 30 | H37: =H36+75 -> 1725 | I37: =I36+125 -> 2875 | J37: =J36+200 -> 4600 | K37: =K36+300 -> 6900 | L37: =L$34*$E37 -> 120 | M37: =M$34*$E37 -> 180 | N37: =N$34*$E37 -> 240 | O37: =O$34*$E37 -> 300 | P37: =P$34*$E37 -> 24 | Q37: =Q$34*$E37 -> 36 | R37: =R$34*$E37 -> 48 | S37: =S$34*$E37 -> 60 | U37: ="[{2,"&H37&"}]" -> [{2,1725}] | V37: ="[{2,"&I37&"}]" -> [{2,2875}] | W37: ="[{2,"&J37&"}]" -> [{2,4600}] | X37: ="[{2,"&K37&"}]" -> [{2,6900}]
D38: 零件 | E38: =E37+1 -> 5 | F38: 10 | G38: =SUM($F$33:F38) -> 40 | H38: =H37+75 -> 1800 | I38: =I37+125 -> 3000 | J38: =J37+200 -> 4800 | K38: =K37+300 -> 7200 | L38: =L$34*$E38 -> 150 | M38: =M$34*$E38 -> 225 | N38: =N$34*$E38 -> 300 | O38: =O$34*$E38 -> 375 | P38: =P$34*$E38 -> 30 | Q38: =Q$34*$E38 -> 45 | R38: =R$34*$E38 -> 60 | S38: =S$34*$E38 -> 75 | U38: ="[{2,"&H38&"}]" -> [{2,1800}] | V38: ="[{2,"&I38&"}]" -> [{2,3000}] | W38: ="[{2,"&J38&"}]" -> [{2,4800}] | X38: ="[{2,"&K38&"}]" -> [{2,7200}]
D39: 零件 | E39: =E38+1 -> 6 | F39: 10 | G39: =SUM($F$33:F39) -> 50 | H39: =H38+75 -> 1875 | I39: =I38+125 -> 3125 | J39: =J38+200 -> 5000 | K39: =K38+300 -> 7500 | L39: =L$34*$E39 -> 180 | M39: =M$34*$E39 -> 270 | N39: =N$34*$E39 -> 360 | O39: =O$34*$E39 -> 450 | P39: =P$34*$E39 -> 36 | Q39: =Q$34*$E39 -> 54 | R39: =R$34*$E39 -> 72 | S39: =S$34*$E39 -> 90 | U39: ="[{2,"&H39&"}]" -> [{2,1875}] | V39: ="[{2,"&I39&"}]" -> [{2,3125}] | W39: ="[{2,"&J39&"}]" -> [{2,5000}] | X39: ="[{2,"&K39&"}]" -> [{2,7500}]
D40: 零件 | E40: =E39+1 -> 7 | F40: 10 | G40: =SUM($F$33:F40) -> 60 | H40: =H39+75 -> 1950 | I40: =I39+125 -> 3250 | J40: =J39+200 -> 5200 | K40: =K39+300 -> 7800 | L40: =L$34*$E40 -> 210 | M40: =M$34*$E40 -> 315 | N40: =N$34*$E40 -> 420 | O40: =O$34*$E40 -> 525 | P40: =P$34*$E40 -> 42 | Q40: =Q$34*$E40 -> 63 | R40: =R$34*$E40 -> 84 | S40: =S$34*$E40 -> 105 | U40: ="[{2,"&H40&"}]" -> [{2,1950}] | V40: ="[{2,"&I40&"}]" -> [{2,3250}] | W40: ="[{2,"&J40&"}]" -> [{2,5200}] | X40: ="[{2,"&K40&"}]" -> [{2,7800}]
D41: 零件 | E41: =E40+1 -> 8 | F41: 10 | G41: =SUM($F$33:F41) -> 70 | H41: =H40+75 -> 2025 | I41: =I40+125 -> 3375 | J41: =J40+200 -> 5400 | K41: =K40+300 -> 8100 | L41: =L$34*$E41 -> 240 | M41: =M$34*$E41 -> 360 | N41: =N$34*$E41 -> 480 | O41: =O$34*$E41 -> 600 | P41: =P$34*$E41 -> 48 | Q41: =Q$34*$E41 -> 72 | R41: =R$34*$E41 -> 96 | S41: =S$34*$E41 -> 120 | U41: ="[{2,"&H41&"}]" -> [{2,2025}] | V41: ="[{2,"&I41&"}]" -> [{2,3375}] | W41: ="[{2,"&J41&"}]" -> [{2,5400}] | X41: ="[{2,"&K41&"}]" -> [{2,8100}]
D42: 零件 | E42: =E41+1 -> 9 | F42: 10 | G42: =SUM($F$33:F42) -> 80 | H42: =H41+75 -> 2100 | I42: =I41+125 -> 3500 | J42: =J41+200 -> 5600 | K42: =K41+300 -> 8400 | L42: =L$34*$E42 -> 270 | M42: =M$34*$E42 -> 405 | N42: =N$34*$E42 -> 540 | O42: =O$34*$E42 -> 675 | P42: =P$34*$E42 -> 54 | Q42: =Q$34*$E42 -> 81 | R42: =R$34*$E42 -> 108 | S42: =S$34*$E42 -> 135 | U42: ="[{2,"&H42&"}]" -> [{2,2100}] | V42: ="[{2,"&I42&"}]" -> [{2,3500}] | W42: ="[{2,"&J42&"}]" -> [{2,5600}] | X42: ="[{2,"&K42&"}]" -> [{2,8400}]
D43: 零件 | E43: =E42+1 -> 10 | F43: 25 | G43: =SUM($F$33:F43) -> 105 | H43: =H42+75 -> 2175 | I43: =I42+125 -> 3625 | J43: =J42+200 -> 5800 | K43: =K42+300 -> 8700 | L43: =L$34*$E43 -> 300 | M43: =M$34*$E43 -> 450 | N43: =N$34*$E43 -> 600 | O43: =O$34*$E43 -> 750 | P43: =P$34*$E43 -> 60 | Q43: =Q$34*$E43 -> 90 | R43: =R$34*$E43 -> 120 | S43: =S$34*$E43 -> 150 | U43: ="[{2,"&H43&"}]" -> [{2,2175}] | V43: ="[{2,"&I43&"}]" -> [{2,3625}] | W43: ="[{2,"&J43&"}]" -> [{2,5800}] | X43: ="[{2,"&K43&"}]" -> [{2,8700}]
D44: 零件 | E44: =E43+1 -> 11 | F44: 25 | G44: =SUM($F$33:F44) -> 130 | H44: =H43+75 -> 2250 | I44: =I43+125 -> 3750 | J44: =J43+200 -> 6000 | K44: =K43+300 -> 9000 | L44: =L$34*$E44 -> 330 | M44: =M$34*$E44 -> 495 | N44: =N$34*$E44 -> 660 | O44: =O$34*$E44 -> 825 | P44: =P$34*$E44 -> 66 | Q44: =Q$34*$E44 -> 99 | R44: =R$34*$E44 -> 132 | S44: =S$34*$E44 -> 165 | U44: ="[{2,"&H44&"}]" -> [{2,2250}] | V44: ="[{2,"&I44&"}]" -> [{2,3750}] | W44: ="[{2,"&J44&"}]" -> [{2,6000}] | X44: ="[{2,"&K44&"}]" -> [{2,9000}]
D45: 零件 | E45: =E44+1 -> 12 | F45: 25 | G45: =SUM($F$33:F45) -> 155 | H45: =H44+75 -> 2325 | I45: =I44+125 -> 3875 | J45: =J44+200 -> 6200 | K45: =K44+300 -> 9300 | L45: =L$34*$E45 -> 360 | M45: =M$34*$E45 -> 540 | N45: =N$34*$E45 -> 720 | O45: =O$34*$E45 -> 900 | P45: =P$34*$E45 -> 72 | Q45: =Q$34*$E45 -> 108 | R45: =R$34*$E45 -> 144 | S45: =S$34*$E45 -> 180 | U45: ="[{2,"&H45&"}]" -> [{2,2325}] | V45: ="[{2,"&I45&"}]" -> [{2,3875}] | W45: ="[{2,"&J45&"}]" -> [{2,6200}] | X45: ="[{2,"&K45&"}]" -> [{2,9300}]
D46: 零件 | E46: =E45+1 -> 13 | F46: 25 | G46: =SUM($F$33:F46) -> 180 | H46: =H45+75 -> 2400 | I46: =I45+125 -> 4000 | J46: =J45+200 -> 6400 | K46: =K45+300 -> 9600 | L46: =L$34*$E46 -> 390 | M46: =M$34*$E46 -> 585 | N46: =N$34*$E46 -> 780 | O46: =O$34*$E46 -> 975 | P46: =P$34*$E46 -> 78 | Q46: =Q$34*$E46 -> 117 | R46: =R$34*$E46 -> 156 | S46: =S$34*$E46 -> 195 | U46: ="[{2,"&H46&"}]" -> [{2,2400}] | V46: ="[{2,"&I46&"}]" -> [{2,4000}] | W46: ="[{2,"&J46&"}]" -> [{2,6400}] | X46: ="[{2,"&K46&"}]" -> [{2,9600}]
... D92: 零件 | E92: =E91+1 -> 59 | F92: 210 | G92: =SUM($F$33:F92) -> 6055 | H92: =H91+75 -> 5850 | I92: =I91+125 -> 9750 | J92: =J91+200 -> 15600 | K92: =K91+300 -> 23400 | L92: =L$34*$E92 -> 1770 | M92: =M$34*$E92 -> 2655 | N92: =N$34*$E92 -> 3540 | O92: =O$34*$E92 -> 4425 | P92: =P$34*$E92 -> 354 | Q92: =Q$34*$E92 -> 531 | R92: =R$34*$E92 -> 708 | S92: =S$34*$E92 -> 885 | U92: ="[{2,"&H92&"}]" -> [{2,5850}] | V92: ="[{2,"&I92&"}]" -> [{2,9750}] | W92: ="[{2,"&J92&"}]" -> [{2,15600}] | X92: ="[{2,"&K92&"}]" -> [{2,23400}]
D93: 零件 | E93: =E92+1 -> 60 | L93: =L$34*$E93 -> 1800 | M93: =M$34*$E93 -> 2700 | N93: =N$34*$E93 -> 3600 | O93: =O$34*$E93 -> 4500 | P93: =P$34*$E93 -> 360 | Q93: =Q$34*$E93 -> 540 | R93: =R$34*$E93 -> 720 | S93: =S$34*$E93 -> 900
H96: 零件消耗
D97: 载具零件 | E97: 等级 | F97: 耐久加成 | G97: 当前耐久 | H97: 零件消耗 | I97: 零件总消耗
D98: 载具 | E98: 1 | I98: =SUM($H$98:H98) -> 0 | J98: ="[{max_hp,"&F98&"}]" -> [{max_hp,}] | K98: ="[{63,"&H98&"}]" -> [{63,}]
D99: 载具 | E99: =E98+1 -> 2 | F99: =G99-G98 -> 50 | G99: 50 | H99: 100 | I99: =SUM($H$98:H99) -> 100 | J99: ="[{max_hp,"&F99&"}]" -> [{max_hp,50}] | K99: ="[{63,"&H99&"}]" -> [{63,100}]
D100: 载具 | E100: =E99+1 -> 3 | F100: =G100-G99 -> 50 | G100: 100 | H100: 100 | I100: =SUM($H$98:H100) -> 200 | J100: ="[{max_hp,"&F100&"}]" -> [{max_hp,50}] | K100: ="[{63,"&H100&"}]" -> [{63,100}]
D101: 载具 | E101: =E100+1 -> 4 | F101: =G101-G100 -> 50 | G101: 150 | H101: 100 | I101: =SUM($H$98:H101) -> 300 | J101: ="[{max_hp,"&F101&"}]" -> [{max_hp,50}] | K101: ="[{63,"&H101&"}]" -> [{63,100}]
D102: 载具 | E102: =E101+1 -> 5 | F102: =G102-G101 -> 50 | G102: 200 | H102: 100 | I102: =SUM($H$98:H102) -> 400 | J102: ="[{max_hp,"&F102&"}]" -> [{max_hp,50}] | K102: ="[{63,"&H102&"}]" -> [{63,100}]
...

Sheet 载具产出
A1: 设计思路
C3: 载具抽卡
D6: 道具 | E6: 价值 | F6: 数量
D7: 零件 | E7: 1
D8: 零件核心 | E8: 150
D9: 史诗零件 | E9: 2000 | F9: 3 | G9: 4
D10: 传说零件 | E10: =E9*2 -> 4000 | F10: 4 | G10: 5
D11: 神话零件 | E11: =E10*2 -> 8000 | F11: 6 | G11: 6
D12: 创世零件 | E12: =E11*2 -> 16000 | F12: 8 | G12: 4
D13: 史诗零件碎片 | E13: =E9/10 -> 200
D14: 传说零件碎片 | E14: =E10/10 -> 400
D15: 神话零件碎片 | E15: =E11/10 -> 800
D16: 创世零件碎片 | E16: =E12/10 -> 1600
D19: 招募阶段 | E19: 招募所需次数 | F19: 招募释放 | G19: 载具品质 | H19: 类别 | I19: 非R | J19: 小R | K19: 中R | L19: 大R | M19: 预期关卡 | N19: 预期
D20: 1 | E20: 10 | F20: 硬硬护板 | G20: 3 | H20: 抵抗 | I20: =MAX($E20-30,0)/OFFSET($E$71,MATCH(I$19,$I$19:$L$19,0),0)+28 -> 28 | J20: =MAX($E20-80,0)/OFFSET($E$71,MATCH(J$19,$I$19:$L$19,0),0)+28 -> 28 | K20: =MAX($E20-30,0)/OFFSET($E$71,MATCH(K$19,$I$19:$L$19,0),0)+28 -> 28 | L20: =MAX($E20-30,0)/OFFSET($E$71,MATCH(L$19,$I$19:$L$19,0),0)+28 -> 28 | M20: =_xlfn.XLOOKUP(INT(K20),载具预期!D:D,载具预期!G:G) -> 84 | N20: 载具护盾+%d
D21: 2 | E21: 10 | F21: 厚到离谱壳 | G21: 3 | H21: 抵抗 | I21: =MAX($E21-30,0)/OFFSET($E$71,MATCH(I$19,$I$19:$L$19,0),0)+28 -> 28 | J21: =MAX($E21-30,0)/OFFSET($E$71,MATCH(J$19,$I$19:$L$19,0),0)+28 -> 28 | K21: =MAX($E21-30,0)/OFFSET($E$71,MATCH(K$19,$I$19:$L$19,0),0)+28 -> 28 | L21: =MAX($E21-30,0)/OFFSET($E$71,MATCH(L$19,$I$19:$L$19,0),0)+28 -> 28 | M21: =_xlfn.XLOOKUP(INT(K21),载具预期!D:D,载具预期!G:G) -> 84 | N21: 载具耐久+%d
D22: 3 | E22: 20 | F22: 你打你疼板 | G22: 3 | H22: 反击 | I22: =MAX($E22-30,0)/OFFSET($E$71,MATCH(I$19,$I$19:$L$19,0),0)+28 -> 28 | J22: =MAX($E22-30,0)/OFFSET($E$71,MATCH(J$19,$I$19:$L$19,0),0)+28 -> 28 | K22: =MAX($E22-30,0)/OFFSET($E$71,MATCH(K$19,$I$19:$L$19,0),0)+28 -> 28 | L22: =MAX($E22-30,0)/OFFSET($E$71,MATCH(L$19,$I$19:$L$19,0),0)+28 -> 28 | M22: =_xlfn.XLOOKUP(INT(K22),载具预期!D:D,载具预期!G:G) -> 84 | N22: 载具对攻击者造成队长%d%的伤害
C23: 1 | D23: 4 | E23: 30 | F23: 半场增伤钮 | G23: 4 | H23: 压制 | I23: =MAX($E23-30,0)/OFFSET($E$71,MATCH(I$19,$I$19:$L$19,0),0)+28 -> 28 | J23: =MAX($E23-30,0)/OFFSET($E$71,MATCH(J$19,$I$19:$L$19,0),0)+28 -> 28 | K23: =MAX($E23-30,0)/OFFSET($E$71,MATCH(K$19,$I$19:$L$19,0),0)+28 -> 28 | L23: =MAX($E23-30,0)/OFFSET($E$71,MATCH(L$19,$I$19:$L$19,0),0)+28 -> 28 | M23: =_xlfn.XLOOKUP(INT(K23),载具预期!D:D,载具预期!G:G) -> 84 | N23: 对半场内怪物伤害增加%d%
D24: 5 | E24: 40 | F24: 小弟补个胎 | G24: 4 | H24: 抵抗 | I24: =MAX($E24-30,0)/OFFSET($E$71,MATCH(I$19,$I$19:$L$19,0),0)+28 -> 30 | J24: =MAX($E24-30,0)/OFFSET($E$71,MATCH(J$19,$I$19:$L$19,0),0)+28 -> 29.346154 | K24: =MAX($E24-30,0)/OFFSET($E$71,MATCH(K$19,$I$19:$L$19,0),0)+28 -> 28.850202 | L24: =MAX($E24-30,0)/OFFSET($E$71,MATCH(L$19,$I$19:$L$19,0),0)+28 -> 28.269923 | M24: =_xlfn.XLOOKUP(INT(K24),载具预期!D:D,载具预期!G:G) -> 84 | N24: 每次召唤召唤物获得%d点耐久
D25: 6 | E25: 60 | F25: 波波套盾机 | G25: 4 | H25: 抵抗 | I25: =MAX($E25-30,0)/OFFSET($E$71,MATCH(I$19,$I$19:$L$19,0),0)+28 -> 34 | J25: =MAX($E25-30,0)/OFFSET($E$71,MATCH(J$19,$I$19:$L$19,0),0)+28 -> 32.038462 | K25: =MAX($E25-30,0)/OFFSET($E$71,MATCH(K$19,$I$19:$L$19,0),0)+28 -> 30.550607 | L25: =MAX($E25-30,0)/OFFSET($E$71,MATCH(L$19,$I$19:$L$19,0),0)+28 -> 28.809769 | M25: =_xlfn.XLOOKUP(INT(K25),载具预期!D:D,载具预期!G:G) -> 86 | N25: 每个波次开始时，载具获得%d点护盾
D26: 7 | E26: 80 | F26: 漏电小线圈 | G26: 4 | H26: 反击 | I26: =MAX($E26-30,0)/OFFSET($E$71,MATCH(I$19,$I$19:$L$19,0),0)+28 -> 38 | J26: =MAX($E26-30,0)/OFFSET($E$71,MATCH(J$19,$I$19:$L$19,0),0)+28 -> 34.730769 | K26: =MAX($E26-30,0)/OFFSET($E$71,MATCH(K$19,$I$19:$L$19,0),0)+28 -> 32.251012 | L26: =MAX($E26-30,0)/OFFSET($E$71,MATCH(L$19,$I$19:$L$19,0),0)+28 -> 29.349614 | M26: =_xlfn.XLOOKUP(INT(K26),载具预期!D:D,载具预期!G:G) -> 88 | N26: 载具每损失20%生命，电击附近敌人造成%d%伤害
D27: 8 | E27: 120 | F27: 前三波按钮 | G27: 5 | H27: 压制 | I27: =MAX($E27-30,0)/OFFSET($E$71,MATCH(I$19,$I$19:$L$19,0),0)+28 -> 46 | J27: =MAX($E27-30,0)/OFFSET($E$71,MATCH(J$19,$I$19:$L$19,0),0)+28 -> 40.115385 | K27: =MAX($E27-30,0)/OFFSET($E$71,MATCH(K$19,$I$19:$L$19,0),0)+28 -> 35.651822 | L27: =MAX($E27-30,0)/OFFSET($E$71,MATCH(L$19,$I$19:$L$19,0),0)+28 -> 30.429306 | M27: =_xlfn.XLOOKUP(INT(K27),载具预期!D:D,载具预期!G:G) -> 91 | N27: 梦灵对前三波怪物伤害+%d%
D28: 9 | E28: 140 | F28: 暴击放大镜 | G28: 5 | H28: 压制 | I28: =MAX($E28-30,0)/OFFSET($E$71,MATCH(I$19,$I$19:$L$19,0),0)+28 -> 50 | J28: =MAX($E28-30,0)/OFFSET($E$71,MATCH(J$19,$I$19:$L$19,0),0)+28 -> 42.807692 | K28: =MAX($E28-30,0)/OFFSET($E$71,MATCH(K$19,$I$19:$L$19,0),0)+28 -> 37.352227 | L28: =MAX($E28-30,0)/OFFSET($E$71,MATCH(L$19,$I$19:$L$19,0),0)+28 -> 30.969152 | M28: =_xlfn.XLOOKUP(INT(K28),载具预期!D:D,载具预期!G:G) -> 93 | N28: 暴击伤害+%d%
D29: 10 | E29: 160 | F29: 挨打充电宝 | G29: 5 | H29: 抵抗 | I29: =MAX($E29-30,0)/OFFSET($E$71,MATCH(I$19,$I$19:$L$19,0),0)+28 -> 54 | J29: =MAX($E29-30,0)/OFFSET($E$71,MATCH(J$19,$I$19:$L$19,0),0)+28 -> 45.5 | K29: =MAX($E29-30,0)/OFFSET($E$71,MATCH(K$19,$I$19:$L$19,0),0)+28 -> 39.052632 | L29: =MAX($E29-30,0)/OFFSET($E$71,MATCH(L$19,$I$19:$L$19,0),0)+28 -> 31.508997 | M29: =_xlfn.XLOOKUP(INT(K29),载具预期!D:D,载具预期!G:G) -> 95 | N29: 载具受到攻击时，梦灵充能冷却缩减+%d%
D30: 11 | E30: 180 | F30: 快修小泵 | G30: 5 | H30: 抵抗 | I30: =MAX($E30-30,0)/OFFSET($E$71,MATCH(I$19,$I$19:$L$19,0),0)+28 -> 58 | J30: =MAX($E30-30,0)/OFFSET($E$71,MATCH(J$19,$I$19:$L$19,0),0)+28 -> 48.192308 | K30: =MAX($E30-30,0)/OFFSET($E$71,MATCH(K$19,$I$19:$L$19,0),0)+28 -> 40.753036 | L30: =MAX($E30-30,0)/OFFSET($E$71,MATCH(L$19,$I$19:$L$19,0),0)+28 -> 32.048843 | M30: =_xlfn.XLOOKUP(INT(K30),载具预期!D:D,载具预期!G:G) -> 96 | N30: 当城墙血量低于30%时，持续修复%d血量
D31: 12 | E31: 200 | F31: 打我会晕钉 | G31: 5 | H31: 反击 | I31: =MAX($E31-30,0)/OFFSET($E$71,MATCH(I$19,$I$19:$L$19,0),0)+28 -> 62 | J31: =MAX($E31-30,0)/OFFSET($E$71,MATCH(J$19,$I$19:$L$19,0),0)+28 -> 50.884615 | K31: =MAX($E31-30,0)/OFFSET($E$71,MATCH(K$19,$I$19:$L$19,0),0)+28 -> 42.453441 | L31: =MAX($E31-30,0)/OFFSET($E$71,MATCH(L$19,$I$19:$L$19,0),0)+28 -> 32.588689 | M31: =_xlfn.XLOOKUP(INT(K31),载具预期!D:D,载具预期!G:G) -> 98 | N31: 载具受攻击有%d%概率使攻击者眩晕2秒
D32: 13 | E32: 220 | F32: 越打越疼贴 | G32: 5 | H32: 反击 | I32: =MAX($E32-30,0)/OFFSET($E$71,MATCH(I$19,$I$19:$L$19,0),0)+28 -> 66 | J32: =MAX($E32-30,0)/OFFSET($E$71,MATCH(J$19,$I$19:$L$19,0),0)+28 -> 53.576923 | K32: =MAX($E32-30,0)/OFFSET($E$71,MATCH(K$19,$I$19:$L$19,0),0)+28 -> 44.153846 | L32: =MAX($E32-30,0)/OFFSET($E$71,MATCH(L$19,$I$19:$L$19,0),0)+28 -> 33.128535 | M32: =_xlfn.XLOOKUP(INT(K32),载具预期!D:D,载具预期!G:G) -> 100 | N32: 怪物攻击城墙后，受到伤害+%d%
D33: 14 | E33: 240 | F33: 爆爆火花塞 | G33: 6 | H33: 压制 | I33: =MAX($E33-30,0)/OFFSET($E$71,MATCH(I$19,$I$19:$L$19,0),0)+28 -> 70 | J33: =MAX($E33-30,0)/OFFSET($E$71,MATCH(J$19,$I$19:$L$19,0),0)+28 -> 56.269231 | K33: =MAX($E33-30,0)/OFFSET($E$71,MATCH(K$19,$I$19:$L$19,0),0)+28 -> 45.854251 | L33: =MAX($E33-30,0)/OFFSET($E$71,MATCH(L$19,$I$19:$L$19,0),0)+28 -> 33.66838 | M33: =_xlfn.XLOOKUP(INT(K33),载具预期!D:D,载具预期!G:G) -> 101 | N33: 攻击有10%概率造成%d%范围伤害
D34: 15 | E34: 360 | F34: 三下蓄力阀 | G34: 6 | H34: 压制 | I34: =MAX($E34-30,0)/OFFSET($E$71,MATCH(I$19,$I$19:$L$19,0),0)+28 -> 94 | J34: =MAX($E34-30,0)/OFFSET($E$71,MATCH(J$19,$I$19:$L$19,0),0)+28 -> 72.423077 | K34: =MAX($E34-30,0)/OFFSET($E$71,MATCH(K$19,$I$19:$L$19,0),0)+28 -> 56.05668 | L34: =MAX($E34-30,0)/OFFSET($E$71,MATCH(L$19,$I$19:$L$19,0),0)+28 -> 36.907455 | M34: =_xlfn.XLOOKUP(INT(K34),载具预期!D:D,载具预期!G:G) -> 112 | N34: 每充能3次，下一次造成额外%d%伤害，持续5秒
D35: 16 | E35: 480 | F35: 毒火加班芯 | G35: 6 | H35: 压制 | I35: =MAX($E35-30,0)/OFFSET($E$71,MATCH(I$19,$I$19:$L$19,0),0)+28 -> 118 | J35: =MAX($E35-30,0)/OFFSET($E$71,MATCH(J$19,$I$19:$L$19,0),0)+28 -> 88.576923 | K35: =MAX($E35-30,0)/OFFSET($E$71,MATCH(K$19,$I$19:$L$19,0),0)+28 -> 66.259109 | L35: =MAX($E35-30,0)/OFFSET($E$71,MATCH(L$19,$I$19:$L$19,0),0)+28 -> 40.14653 | M35: =_xlfn.XLOOKUP(INT(K35),载具预期!D:D,载具预期!G:G) -> 121 | N35: 梦灵持续伤害有30%概率最终伤害+%d%
D36: 17 | E36: =E35+80 -> 560 | F36: 残血补刀镜 | G36: 6 | H36: 压制 | I36: =MAX($E36-30,0)/OFFSET($E$71,MATCH(I$19,$I$19:$L$19,0),0)+28 -> 134 | J36: =MAX($E36-30,0)/OFFSET($E$71,MATCH(J$19,$I$19:$L$19,0),0)+28 -> 99.346154 | K36: =MAX($E36-30,0)/OFFSET($E$71,MATCH(K$19,$I$19:$L$19,0),0)+28 -> 73.060729 | L36: =MAX($E36-30,0)/OFFSET($E$71,MATCH(L$19,$I$19:$L$19,0),0)+28 -> 42.305913 | M36: =_xlfn.XLOOKUP(INT(K36),载具预期!D:D,载具预期!G:G) -> 124 | N36: 梦灵对低于50%怪物血量，造成额外%d%伤害
D37: 18 | E37: 600 | F37: 不许死保险 | G37: 6 | H37: 抵抗 | I37: =MAX($E37-30,0)/OFFSET($E$71,MATCH(I$19,$I$19:$L$19,0),0)+28 -> 142 | J37: =MAX($E37-30,0)/OFFSET($E$71,MATCH(J$19,$I$19:$L$19,0),0)+28 -> 104.73077 | K37: =MAX($E37-30,0)/OFFSET($E$71,MATCH(K$19,$I$19:$L$19,0),0)+28 -> 76.461538 | L37: =MAX($E37-30,0)/OFFSET($E$71,MATCH(L$19,$I$19:$L$19,0),0)+28 -> 43.385604 | M37: =_xlfn.XLOOKUP(INT(K37),载具预期!D:D,载具预期!G:G) -> 126 | N37: 受到致命伤害，免疫所有受到的伤害，持续%d秒
D38: 19 | E38: 800 | F38: 越残越猛芯 | G38: 6 | H38: 反击 | I38: =MAX($E38-30,0)/OFFSET($E$71,MATCH(I$19,$I$19:$L$19,0),0)+28 -> 182 | J38: =MAX($E38-30,0)/OFFSET($E$71,MATCH(J$19,$I$19:$L$19,0),0)+28 -> 131.65385 | K38: =MAX($E38-30,0)/OFFSET($E$71,MATCH(K$19,$I$19:$L$19,0),0)+28 -> 93.465587 | L38: =MAX($E38-30,0)/OFFSET($E$71,MATCH(L$19,$I$19:$L$19,0),0)+28 -> 48.784062 | M38: =_xlfn.XLOOKUP(INT(K38),载具预期!D:D,载具预期!G:G) -> 134 | N38: 载具生命每降低10%，所有梦灵最终伤害+%d%
D39: 20 | E39: 1000 | F39: 乖乖减伤器 | G39: 6 | H39: 抵抗 | I39: =MAX($E39-30,0)/OFFSET($E$71,MATCH(I$19,$I$19:$L$19,0),0)+28 -> 222 | J39: =MAX($E39-30,0)/OFFSET($E$71,MATCH(J$19,$I$19:$L$19,0),0)+28 -> 158.57692 | K39: =MAX($E39-30,0)/OFFSET($E$71,MATCH(K$19,$I$19:$L$19,0),0)+28 -> 110.46964 | L39: =MAX($E39-30,0)/OFFSET($E$71,MATCH(L$19,$I$19:$L$19,0),0)+28 -> 54.182519 | M39: =_xlfn.XLOOKUP(INT(K39),载具预期!D:D,载具预期!G:G) -> 143 | N39: 怪物受到控制/魅惑后，造成伤害降低%d%
D40: 21 | E40: 1200 | F40: 套装快进芯 | G40: 6 | H40: 反击 | I40: =MAX($E40-30,0)/OFFSET($E$71,MATCH(I$19,$I$19:$L$19,0),0)+28 -> 262 | J40: =MAX($E40-30,0)/OFFSET($E$71,MATCH(J$19,$I$19:$L$19,0),0)+28 -> 185.5 | K40: =MAX($E40-30,0)/OFFSET($E$71,MATCH(K$19,$I$19:$L$19,0),0)+28 -> 127.47368 | L40: =MAX($E40-30,0)/OFFSET($E$71,MATCH(L$19,$I$19:$L$19,0),0)+28 -> 59.580977 | M40: =_xlfn.XLOOKUP(INT(K40),载具预期!D:D,载具预期!G:G) -> 151 | N40: 载具的套装效果-15%冷却，伤害+%d%
D42: #结构：碎片比例越来越低，本体比例越来越高
C43: =144-60 -> 84 | E43: =SUM(E45:E55) -> 1 | F43: =SUM(F45:F55) -> 1 | G43: =SUM(G45:G55) -> 1 | H43: =SUM(H45:H55) -> 1 | I43: =SUM(I45:I55) -> 1 | J43: =SUM(J45:J55) -> 1 | K43: =SUM(K45:K55) -> 1 | L43: =SUM(L45:L55) -> 1
C44: =C43/4 -> 21 | D44: 抽奖等级 | E44: 1 | F44: 2 | G44: 3 | H44: 4 | I44: 5 | J44: 6 | K44: 7 | L44: 8 | M44: 价值 | N44: 数量
D45: 史诗零件 | E45: 0.15 | F45: 0.15 | G45: 0.15 | H45: 0.15 | I45: 0.15 | J45: 0.15 | K45: 0.15 | L45: 0.15 | M45: =_xlfn.XLOOKUP(D45,$D$6:$D$16,$E$6:$E$16)*N45 -> 2000 | N45: 1
D46: 传说零件 | E46: 0.023 | F46: =F47*2 -> 0.024 | G46: =G47*2 -> 0.028 | H46: =H47*2 -> 0.032 | I46: =I47*2 -> 0.036 | J46: =J47*2 -> 0.04 | K46: =K47*2 -> 0.044 | L46: =L47*2 -> 0.048 | M46: =_xlfn.XLOOKUP(D46,$D$6:$D$16,$E$6:$E$16)*N46 -> 4000 | N46: 1
...

Sheet 载具预期
A1: 设计思路
C3: 载具抽卡
S4: =MATCH(OFFSET($D36,0,MATCH($D$5,$E$6:$H$6,0)),载具产出!$E$112:$E$151,1) -> 5
D5: 中R | F5: 产出占比 | J5: 补发模块 | K5: =_xlfn.XLOOKUP(K6,价值表!$F:$F,价值表!$E:$E) -> 62 | L5: =_xlfn.XLOOKUP(L6,价值表!$F:$F,价值表!$E:$E) -> 63 | M5: =_xlfn.XLOOKUP(M6,价值表!$F:$F,价值表!$E:$E) -> 2 | N5: =_xlfn.XLOOKUP(N6,价值表!$F:$F,价值表!$E:$E) -> 6030001 | O5: =_xlfn.XLOOKUP(O6,价值表!$F:$F,价值表!$E:$E) -> 6030002 | P5: =_xlfn.XLOOKUP(P6,价值表!$F:$F,价值表!$E:$E) -> 6030003 | Q5: =_xlfn.XLOOKUP(Q6,价值表!$F:$F,价值表!$E:$E) -> 6030004 | T5: 产出 | AE5: 载具玩法 | AI5: 抽奖产出 | AK5: 载具抽奖 | AO5: 总产出 | AS5: 等级预期
D6: 天数 | E6: 非R | F6: 小R | G6: 中R | H6: 大R | I6: 超R | J6: 补发关卡 | K6: 零件核心 | L6: 零件 | M6: 金币 | N6: 史诗零件碎片 | O6: 传说零件碎片 | P6: 神话零件碎片 | Q6: 创世零件碎片 | R6: 碾压 | S6: 关卡 | T6: 零件 | U6: 零件核心 | V6: 金币 | W6: 城墙血量 | X6: 强化 | Y6: 升星 | Z6: 城墙练度 | AA6: 史诗零件碎片 | AB6: 传说零件碎片 | AC6: 神话零件碎片 | AD6: 创世零件碎片 | AE6: 史诗零件碎片 | AF6: 传说零件碎片 | AG6: 神话零件碎片 | AH6: 创世零件碎片 | AI6: 零件核心 | AJ6: 卡池等级 | AK6: 史诗零件碎片 | AL6: 传说零件碎片 | AM6: 神话零件碎片 | AN6: 创世零件碎片 | AO6: 史诗零件碎片 | AP6: 传说零件碎片 | AQ6: 神话零件碎片 | AR6: 创世零件碎片 | AS6: 史诗零件 | AT6: 传说零件 | AU6: 神话零件 | AV6: 创世零件
D7: 1 | E7: 12 | F7: 16 | G7: 20 | H7: 25
D8: 2 | E8: 18 | F8: 24 | G8: 30 | H8: 37
D9: 3 | E9: 23 | F9: 29 | G9: 35 | H9: 43
D10: 4 | E10: 26 | F10: 34 | G10: 42 | H10: 52
D11: 5 | E11: 29 | F11: 38 | G11: 46 | H11: 57
D12: 6 | E12: 31 | F12: 41 | G12: 49 | H12: 61
D13: 7 | E13: 33 | F13: 44 | G13: 52 | H13: 65
D14: 8 | E14: 36 | F14: 47 | G14: 55 | H14: 68
D15: 9 | E15: 39 | F15: 49 | G15: 58 | H15: 72
D16: 10 | E16: 41 | F16: 52 | G16: 61 | H16: 76
D17: 11 | E17: 43 | F17: 54 | G17: 64 | H17: 80
D18: 12 | E18: 45 | F18: 56 | G18: 66 | H18: 82
... D35: 29 | E35: 65 | F35: 75 | G35: 85 | H35: 106
C36: =W36/G36 -> 73.953488 | D36: 30 | E36: 66 | F36: 76 | G36: 86 | H36: 107 | I36: 118 | J36: =MIN(INT(E36*(30-(D36-30))/30+(D36-30)/30*H36),H36) -> 66 | K36: =SUM(U$36:U36)-SUM(OFFSET(载具产出!H$399,0,0,$R36+1,1)) -> 6 | L36: =SUM(T$36:T36)-SUM(OFFSET(载具产出!G$399,0,0,$R36+1,1)) -> 125 | M36: 0 | N36: =SUM(AA$36:AA36)-SUM(OFFSET(载具产出!J$399,0,0,$R36+1,1)) -> 2.6 | O36: =SUM(AB$36:AB36)-SUM(OFFSET(载具产出!K$399,0,0,$R36+1,1)) -> 21.92 | P36: =SUM(AC$36:AC36)-SUM(OFFSET(载具产出!L$399,0,0,$R36+1,1)) -> 0.48 | Q36: =SUM(AD$36:AD36)-SUM(OFFSET(载具产出!M$399,0,0,$R36+1,1)) -> 0 | R36: 1 | S36: =OFFSET(载具产出!$D$111,IFERROR(MATCH(OFFSET($D36,0,MATCH($D$5,$E$6:$H$6,0)),载具产出!$E$112:$E$151,1),0),0) -> 精良Ⅴ | T36: =OFFSET(载具产出!$F$399,IFERROR(MATCH(OFFSET($D36,0,MATCH($D$5,$E$6:$H$6,0)),载具产出!$E$400:$E$439,1),0),MATCH(T$6,载具产出!$G$399:$O$399,0)) -> 750 | U36: 7 | V36: =OFFSET(载具产出!$F$399,IFERROR(MATCH(OFFSET($D36,0,MATCH($D$5,$E$6:$H$6,0)),载具产出!$E$400:$E$439,1),0),MATCH(V$6,载具产出!$G$399:$O$399,0)) -> 4800 | W36: =_xlfn.XLOOKUP(Z36,载具属性!$E$98:$E$497,载具属性!$G$98:$G$497)+6000+OFFSET(载具属性!L$33,AS36,0)*载具属性!M$30+OFFSET(载具属性!M$33,AT36,0)*载具属性!N$30+OFFSET(载具属性!N$33,AU36,0)*载具属性!O$30+OFFSET(载具属性!O$33,AV36,0)*载具属性!P$30 -> 6360 | X36: =_xlfn.XLOOKUP(Z36,载具属性!$E$98:$E$497,载具属性!$G$98:$G$497) -> 300 | Y36: =OFFSET(载具属性!L$33,AS36,0)*载具属性!M$30+OFFSET(载具属性!M$33,AT36,0)*载具属性!N$30+OFFSET(载具属性!N$33,AU36,0)*载具属性!O$30+OFFSET(载具属性!O$33,AV36,0)*载具属性!P$30 -> 60 | Z36: =MATCH(SUM($T$7:T36),载具属性!$I$98:$I$497,1) -> 7 | AA36: =OFFSET(载具产出!$F$399,IFERROR(MATCH(OFFSET($D36,0,MATCH($D$5,$E$6:$H$6,0)),载具产出!$E$112:$E$151,1),0),MATCH(AA$6,载具产出!$G$111:$O$111,0))*2 -> 27.6 | AB36: =OFFSET(载具产出!$F$399,IFERROR(MATCH(OFFSET($D36,0,MATCH($D$5,$E$6:$H$6,0)),载具产出!$E$112:$E$151,1),0),MATCH(AB$6,载具产出!$G$111:$O$111,0))*2 -> 21.92 | AC36: =OFFSET(载具产出!$F$399,IFERROR(MATCH(OFFSET($D36,0,MATCH($D$5,$E$6:$H$6,0)),载具产出!$E$112:$E$151,1),0),MATCH(AC$6,载具产出!$G$111:$O$111,0))*2 -> 0.48 | AD36: =OFFSET(载具产出!$F$399,IFERROR(MATCH(OFFSET($D36,0,MATCH($D$5,$E$6:$H$6,0)),载具产出!$E$112:$E$151,1),0),MATCH(AD$6,载具产出!$G$111:$O$111,0))*2 -> 0 | AE36: =SUM(AA$36:AA36)/3 -> 9.2 | AF36: =SUM(AB$36:AB36)/3 -> 7.3066667 | AG36: =SUM(AC$36:AC36)/3 -> 0.16 | AH36: =SUM(AD$36:AD36)/3 -> 0 | AI36: =_xlfn.XLOOKUP($D$5,载具产出!$D$71:$D$75,载具产出!$E$71:$E$75)*(D36-30+1) -> 11.761905 | AJ36: =IFERROR(MATCH(_xlfn.XLOOKUP($D$5,载具产出!$D$71:$D$75,载具产出!$E$71:$E$75)*(D36-30+1)*10,载具产出!$E$60:$E$67,1),0)+1 -> 1 | AK36: =IF($AJ36=1,($AI36)*(10*OFFSET(载具产出!$D$45,MATCH(AK$6,$AK$6:$AN$6,0)-1,$AJ36)+OFFSET(载具产出!$D$49,MATCH(AK$6,$AK$6:$AN$6,0)-1,$AJ36)*OFFSET(载具产出!$N$49,MATCH(AK$6,$AK$6:$AN$6,0)-1,0)),OFFSET(载具产出!F$59,$AJ36-1,0)*10+OFFSET(载具产出!J$59,$AJ36-1,0)+($AI36*10-_xlfn.XLOOKUP($AJ36-1,载具产出!$D$59:$D$67,载具产出!$E$59:$E$67))/10*(10*OFFSET(载具产出!$D$45,MATCH(AK$6,$AK$6:$AN$6,0)-1,$AJ36)+OFFSET(载具产出!$D$49,MATCH(AK$6,$AK$6:$AN$6,0)-1,$AJ36)*OFFSET(载具产出!$N$49,MATCH(AK$6,$AK$6:$AN$6,0)-1,0))) -> 35.285714 | AL36: =IF($AJ36=1,($AI36)*(10*OFFSET(载具产出!$D$45,MATCH(AL$6,$AK$6:$AN$6,0)-1,$AJ36)+OFFSET(载具产出!$D$49,MATCH(AL$6,$AK$6:$AN$6,0)-1,$AJ36)*OFFSET(载具产出!$N$49,MATCH(AL$6,$AK$6:$AN$6,0)-1,0)),OFFSET(载具产出!G$59,$AJ36-1,0)*10+OFFSET(载具产出!K$59,$AJ36-1,0)+($AI36*10-_xlfn.XLOOKUP($AJ36-1,载具产出!$D$59:$D$67,载具产出!$E$59:$E$67))/10*(10*OFFSET(载具产出!$D$45,MATCH(AL$6,$AK$6:$AN$6,0)-1,$AJ36)+OFFSET(载具产出!$D$49,MATCH(AL$6,$AK$6:$AN$6,0)-1,$AJ36)*OFFSET(载具产出!$N$49,MATCH(AL$6,$AK$6:$AN$6,0)-1,0))) -> 8.5861905 | AM36: =IF($AJ36=1,($AI36)*(10*OFFSET(载具产出!$D$45,MATCH(AM$6,$AK$6:$AN$6,0)-1,$AJ36)+OFFSET(载具产出!$D$49,MATCH(AM$6,$AK$6:$AN$6,0)-1,$AJ36)*OFFSET(载具产出!$N$49,MATCH(AM$6,$AK$6:$AN$6,0)-1,0)),OFFSET(载具产出!H$59,$AJ36-1,0)*10+OFFSET(载具产出!L$59,$AJ36-1,0)+($AI36*10-_xlfn.XLOOKUP($AJ36-1,载具产出!$D$59:$D$67,载具产出!$E$59:$E$67))/10*(10*OFFSET(载具产出!$D$45,MATCH(AM$6,$AK$6:$AN$6,0)-1,$AJ36)+OFFSET(载具产出!$D$49,MATCH(AM$6,$AK$6:$AN$6,0)-1,$AJ36)*OFFSET(载具产出!$N$49,MATCH(AM$6,$AK$6:$AN$6,0)-1,0))) -> 0 | AN36: =IF($AJ36=1,($AI36)*(10*OFFSET(载具产出!$D$45,MATCH(AN$6,$AK$6:$AN$6,0)-1,$AJ36)+OFFSET(载具产出!$D$49,MATCH(AN$6,$AK$6:$AN$6,0)-1,$AJ36)*OFFSET(载具产出!$N$49,MATCH(AN$6,$AK$6:$AN$6,0)-1,0)),OFFSET(载具产出!I$59,$AJ36-1,0)*10+OFFSET(载具产出!M$59,$AJ36-1,0)+($AI36*10-_xlfn.XLOOKUP($AJ36-1,载具产出!$D$59:$D$67,载具产出!$E$59:$E$67))/10*(10*OFFSET(载具产出!$D$45,MATCH(AN$6,$AK$6:$AN$6,0)-1,$AJ36)+OFFSET(载具产出!$D$49,MATCH(AN$6,$AK$6:$AN$6,0)-1,$AJ36)*OFFSET(载具产出!$N$49,MATCH(AN$6,$AK$6:$AN$6,0)-1,0))) -> 0 | AO36: =AE36+AK36 -> 44.485714 | AP36: =AF36+AL36 -> 15.892857 | AQ36: =AG36+AM36 -> 0.16 | AR36: =AH36+AN36 -> 0 | AS36: =IFERROR(MATCH(AO36/载具产出!R$58,载具属性!$G$33:$G$92,1),0) -> 1 | AT36: =IFERROR(MATCH(AP36/载具产出!S$58,载具属性!$G$33:$G$92,1),0) -> 0 | AU36: =IFERROR(MATCH(AQ36/载具产出!T$58,载具属性!$G$33:$G$92,1),0) -> 0 | AV36: =IFERROR(MATCH(AR36/载具产出!U$58,载具属性!$G$33:$G$92,1),0) -> 0 | AW36: ="["&_xlfn.TEXTJOIN(",",1,AX36:BD36)&"]" -> [{62,6},{63,125},{6030001,2},{6030002,21}] | AX36: =IF(INT(K36)<=0,"","{"&K$5&","&INT(K36)&"}") -> {62,6} | AY36: =IF(INT(L36)<=0,"","{"&L$5&","&INT(L36)&"}") -> {63,125} | AZ36: =IF(INT(M36)<=0,"","{"&M$5&","&INT(M36)&"}") | BA36: =IF(INT(N36)<=0,"","{"&N$5&","&INT(N36)&"}") -> {6030001,2} | BB36: =IF(INT(O36)<=0,"","{"&O$5&","&INT(O36)&"}") -> {6030002,21} | BC36: =IF(INT(P36)<=0,"","{"&P$5&","&INT(P36)&"}") | BD36: =IF(INT(Q36)<=0,"","{"&Q$5&","&INT(Q36)&"}")
C37: =W37/G37 -> 77.471264 | D37: 31 | E37: 67 | F37: 77 | G37: 87 | H37: 108 | I37: 118 | J37: =MIN(INT(E37*(30-(D37-30))/30+(D37-30)/30*H37),H37) -> 68 | K37: =SUM(U$36:U37)-SUM(OFFSET(载具产出!H$399,0,0,$R37+1,1)) -> 13 | L37: =SUM(T$36:T37)-SUM(OFFSET(载具产出!G$399,0,0,$R37+1,1)) -> 875 | M37: =SUM(V$36:V37)/2-SUM(OFFSET(载具产出!I$399,0,0,$R37+1,1)) -> 800 | N37: =SUM(AA$36:AA37)-SUM(OFFSET(载具产出!J$399,0,0,$R37+1,1)) -> 30.2 | O37: =SUM(AB$36:AB37)-SUM(OFFSET(载具产出!K$399,0,0,$R37+1,1)) -> 43.84 | P37: =SUM(AC$36:AC37)-SUM(OFFSET(载具产出!L$399,0,0,$R37+1,1)) -> 0.96 | Q37: =SUM(AD$36:AD37)-SUM(OFFSET(载具产出!M$399,0,0,$R37+1,1)) -> 0 | R37: 1 | S37: =OFFSET(载具产出!$D$111,IFERROR(MATCH(OFFSET($D37,0,MATCH($D$5,$E$6:$H$6,0)),载具产出!$E$112:$E$151,1),0),0) -> 精良Ⅴ | T37: =OFFSET(载具产出!$F$399,IFERROR(MATCH(OFFSET($D37,0,MATCH($D$5,$E$6:$H$6,0)),载具产出!$E$400:$E$439,1),0),MATCH(T$6,载具产出!$G$399:$O$399,0)) -> 750 | U37: 7 | V37: =OFFSET(载具产出!$F$399,IFERROR(MATCH(OFFSET($D37,0,MATCH($D$5,$E$6:$H$6,0)),载具产出!$E$400:$E$439,1),0),MATCH(V$6,载具产出!$G$399:$O$399,0)) -> 4800 | W37: =_xlfn.XLOOKUP(Z37,载具属性!$E$98:$E$497,载具属性!$G$98:$G$497)+6000+OFFSET(载具属性!L$33,AS37,0)*载具属性!M$30+OFFSET(载具属性!M$33,AT37,0)*载具属性!N$30+OFFSET(载具属性!N$33,AU37,0)*载具属性!O$30+OFFSET(载具属性!O$33,AV37,0)*载具属性!P$30 -> 6740 | X37: =_xlfn.XLOOKUP(Z37,载具属性!$E$98:$E$497,载具属性!$G$98:$G$497) -> 500 | Y37: =OFFSET(载具属性!L$33,AS37,0)*载具属性!M$30+OFFSET(载具属性!M$33,AT37,0)*载具属性!N$30+OFFSET(载具属性!N$33,AU37,0)*载具属性!O$30+OFFSET(载具属性!O$33,AV37,0)*载具属性!P$30 -> 240 | Z37: =MATCH(SUM($T$7:T37),载具属性!$I$98:$I$497,1) -> 11 | AA37: =OFFSET(载具产出!$F$399,IFERROR(MATCH(OFFSET($D37,0,MATCH($D$5,$E$6:$H$6,0)),载具产出!$E$112:$E$151,1),0),MATCH(AA$6,载具产出!$G$111:$O$111,0))*2 -> 27.6 | AB37: =OFFSET(载具产出!$F$399,IFERROR(MATCH(OFFSET($D37,0,MATCH($D$5,$E$6:$H$6,0)),载具产出!$E$112:$E$151,1),0),MATCH(AB$6,载具产出!$G$111:$O$111,0))*2 -> 21.92 | AC37: =OFFSET(载具产出!$F$399,IFERROR(MATCH(OFFSET($D37,0,MATCH($D$5,$E$6:$H$6,0)),载具产出!$E$112:$E$151,1),0),MATCH(AC$6,载具产出!$G$111:$O$111,0))*2 -> 0.48 | AD37: =OFFSET(载具产出!$F$399,IFERROR(MATCH(OFFSET($D37,0,MATCH($D$5,$E$6:$H$6,0)),载具产出!$E$112:$E$151,1),0),MATCH(AD$6,载具产出!$G$111:$O$111,0))*2 -> 0 | AE37: =SUM(AA$36:AA37)/3 -> 18.4 | AF37: =SUM(AB$36:AB37)/3 -> 14.613333 | AG37: =SUM(AC$36:AC37)/3 -> 0.32 | AH37: =SUM(AD$36:AD37)/3 -> 0 | AI37: =_xlfn.XLOOKUP($D$5,载具产出!$D$71:$D$75,载具产出!$E$71:$E$75)*(D37-30+1) -> 23.52381 | AJ37: =IFERROR(MATCH(_xlfn.XLOOKUP($D$5,载具产出!$D$71:$D$75,载具产出!$E$71:$E$75)*(D37-30+1)*10,载具产出!$E$60:$E$67,1),0)+1 -> 1 | AK37: =IF($AJ37=1,($AI37)*(10*OFFSET(载具产出!$D$45,MATCH(AK$6,$AK$6:$AN$6,0)-1,$AJ37)+OFFSET(载具产出!$D$49,MATCH(AK$6,$AK$6:$AN$6,0)-1,$AJ37)*OFFSET(载具产出!$N$49,MATCH(AK$6,$AK$6:$AN$6,0)-1,0)),OFFSET(载具产出!F$59,$AJ37-1,0)*10+OFFSET(载具产出!J$59,$AJ37-1,0)+($AI37*10-_xlfn.XLOOKUP($AJ37-1,载具产出!$D$59:$D$67,载具产出!$E$59:$E$67))/10*(10*OFFSET(载具产出!$D$45,MATCH(AK$6,$AK$6:$AN$6,0)-1,$AJ37)+OFFSET(载具产出!$D$49,MATCH(AK$6,$AK$6:$AN$6,0)-1,$AJ37)*OFFSET(载具产出!$N$49,MATCH(AK$6,$AK$6:$AN$6,0)-1,0))) -> 70.571429 | AL37: =IF($AJ37=1,($AI37)*(10*OFFSET(载具产出!$D$45,MATCH(AL$6,$AK$6:$AN$6,0)-1,$AJ37)+OFFSET(载具产出!$D$49,MATCH(AL$6,$AK$6:$AN$6,0)-1,$AJ37)*OFFSET(载具产出!$N$49,MATCH(AL$6,$AK$6:$AN$6,0)-1,0)),OFFSET(载具产出!G$59,$AJ37-1,0)*10+OFFSET(载具产出!K$59,$AJ37-1,0)+($AI37*10-_xlfn.XLOOKUP($AJ37-1,载具产出!$D$59:$D$67,载具产出!$E$59:$E$67))/10*(10*OFFSET(载具产出!$D$45,MATCH(AL$6,$AK$6:$AN$6,0)-1,$AJ37)+OFFSET(载具产出!$D$49,MATCH(AL$6,$AK$6:$AN$6,0)-1,$AJ37)*OFFSET(载具产出!$N$49,MATCH(AL$6,$AK$6:$AN$6,0)-1,0))) -> 17.172381 | AM37: =IF($AJ37=1,($AI37)*(10*OFFSET(载具产出!$D$45,MATCH(AM$6,$AK$6:$AN$6,0)-1,$AJ37)+OFFSET(载具产出!$D$49,MATCH(AM$6,$AK$6:$AN$6,0)-1,$AJ37)*OFFSET(载具产出!$N$49,MATCH(AM$6,$AK$6:$AN$6,0)-1,0)),OFFSET(载具产出!H$59,$AJ37-1,0)*10+OFFSET(载具产出!L$59,$AJ37-1,0)+($AI37*10-_xlfn.XLOOKUP($AJ37-1,载具产出!$D$59:$D$67,载具产出!$E$59:$E$67))/10*(10*OFFSET(载具产出!$D$45,MATCH(AM$6,$AK$6:$AN$6,0)-1,$AJ37)+OFFSET(载具产出!$D$49,MATCH(AM$6,$AK$6:$AN$6,0)-1,$AJ37)*OFFSET(载具产出!$N$49,MATCH(AM$6,$AK$6:$AN$6,0)-1,0))) -> 0 | AN37: =IF($AJ37=1,($AI37)*(10*OFFSET(载具产出!$D$45,MATCH(AN$6,$AK$6:$AN$6,0)-1,$AJ37)+OFFSET(载具产出!$D$49,MATCH(AN$6,$AK$6:$AN$6,0)-1,$AJ37)*OFFSET(载具产出!$N$49,MATCH(AN$6,$AK$6:$AN$6,0)-1,0)),OFFSET(载具产出!I$59,$AJ37-1,0)*10+OFFSET(载具产出!M$59,$AJ37-1,0)+($AI37*10-_xlfn.XLOOKUP($AJ37-1,载具产出!$D$59:$D$67,载具产出!$E$59:$E$67))/10*(10*OFFSET(载具产出!$D$45,MATCH(AN$6,$AK$6:$AN$6,0)-1,$AJ37)+OFFSET(载具产出!$D$49,MATCH(AN$6,$AK$6:$AN$6,0)-1,$AJ37)*OFFSET(载具产出!$N$49,MATCH(AN$6,$AK$6:$AN$6,0)-1,0))) -> 0 | AO37: =AE37+AK37 -> 88.971429 | AP37: =AF37+AL37 -> 31.785714 | AQ37: =AG37+AM37 -> 0.32 | AR37: =AH37+AN37 -> 0 | AS37: =IFERROR(MATCH(AO37/载具产出!R$58,载具属性!$G$33:$G$92,1),0) -> 4 | AT37: =IFERROR(MATCH(AP37/载具产出!S$58,载具属性!$G$33:$G$92,1),0) -> 0 | AU37: =IFERROR(MATCH(AQ37/载具产出!T$58,载具属性!$G$33:$G$92,1),0) -> 0 | AV37: =IFERROR(MATCH(AR37/载具产出!U$58,载具属性!$G$33:$G$92,1),0) -> 0 | AW37: ="["&_xlfn.TEXTJOIN(",",1,AX37:BD37)&"]" -> [{62,13},{63,875},{2,800},{6030001,30},{6030002,43}] | AX37: =IF(INT(K37)<=0,"","{"&K$5&","&INT(K37)&"}") -> {62,13} | AY37: =IF(INT(L37)<=0,"","{"&L$5&","&INT(L37)&"}") -> {63,875} | AZ37: =IF(INT(M37)<=0,"","{"&M$5&","&INT(M37)&"}") -> {2,800} | BA37: =IF(INT(N37)<=0,"","{"&N$5&","&INT(N37)&"}") -> {6030001,30} | BB37: =IF(INT(O37)<=0,"","{"&O$5&","&INT(O37)&"}") -> {6030002,43} | BC37: =IF(INT(P37)<=0,"","{"&P$5&","&INT(P37)&"}") | BD37: =IF(INT(Q37)<=0,"","{"&Q$5&","&INT(Q37)&"}")
C38: =W38/G38 -> 80.681818 | D38: 32 | E38: 68 | F38: 78 | G38: 88 | H38: 110 | I38: 121 | J38: =MIN(INT(E38*(30-(D38-30))/30+(D38-30)/30*H38),H38) -> 70 | K38: =SUM(U$36:U38)-SUM(OFFSET(载具产出!H$399,0,0,$R38+1,1)) -> 20 | L38: =SUM(T$36:T38)-SUM(OFFSET(载具产出!G$399,0,0,$R38+1,1)) -> 1625 | M38: =SUM(V$36:V38)/2-SUM(OFFSET(载具产出!I$399,0,0,$R38+1,1)) -> 3200 | N38: =SUM(AA$36:AA38)-SUM(OFFSET(载具产出!J$399,0,0,$R38+1,1)) -> 57.8 | O38: =SUM(AB$36:AB38)-SUM(OFFSET(载具产出!K$399,0,0,$R38+1,1)) -> 65.76 | P38: =SUM(AC$36:AC38)-SUM(OFFSET(载具产出!L$399,0,0,$R38+1,1)) -> 1.44 | Q38: =SUM(AD$36:AD38)-SUM(OFFSET(载具产出!M$399,0,0,$R38+1,1)) -> 0 | R38: 1 | S38: =OFFSET(载具产出!$D$111,IFERROR(MATCH(OFFSET($D38,0,MATCH($D$5,$E$6:$H$6,0)),载具产出!$E$112:$E$151,1),0),0) -> 精良Ⅴ | T38: =OFFSET(载具产出!$F$399,IFERROR(MATCH(OFFSET($D38,0,MATCH($D$5,$E$6:$H$6,0)),载具产出!$E$400:$E$439,1),0),MATCH(T$6,载具产出!$G$399:$O$399,0)) -> 750 | U38: 7 | V38: =OFFSET(载具产出!$F$399,IFERROR(MATCH(OFFSET($D38,0,MATCH($D$5,$E$6:$H$6,0)),载具产出!$E$400:$E$439,1),0),MATCH(V$6,载具产出!$G$399:$O$399,0)) -> 4800 | W38: =_xlfn.XLOOKUP(Z38,载具属性!$E$98:$E$497,载具属性!$G$98:$G$497)+6000+OFFSET(载具属性!L$33,AS38,0)*载具属性!M$30+OFFSET(载具属性!M$33,AT38,0)*载具属性!N$30+OFFSET(载具属性!N$33,AU38,0)*载具属性!O$30+OFFSET(载具属性!O$33,AV38,0)*载具属性!P$30 -> 7100 | X38: =_xlfn.XLOOKUP(Z38,载具属性!$E$98:$E$497,载具属性!$G$98:$G$497) -> 650 | Y38: =OFFSET(载具属性!L$33,AS38,0)*载具属性!M$30+OFFSET(载具属性!M$33,AT38,0)*载具属性!N$30+OFFSET(载具属性!N$33,AU38,0)*载具属性!O$30+OFFSET(载具属性!O$33,AV38,0)*载具属性!P$30 -> 450 | Z38: =MATCH(SUM($T$7:T38),载具属性!$I$98:$I$497,1) -> 14 | AA38: =OFFSET(载具产出!$F$399,IFERROR(MATCH(OFFSET($D38,0,MATCH($D$5,$E$6:$H$6,0)),载具产出!$E$112:$E$151,1),0),MATCH(AA$6,载具产出!$G$111:$O$111,0))*2 -> 27.6 | AB38: =OFFSET(载具产出!$F$399,IFERROR(MATCH(OFFSET($D38,0,MATCH($D$5,$E$6:$H$6,0)),载具产出!$E$112:$E$151,1),0),MATCH(AB$6,载具产出!$G$111:$O$111,0))*2 -> 21.92 | AC38: =OFFSET(载具产出!$F$399,IFERROR(MATCH(OFFSET($D38,0,MATCH($D$5,$E$6:$H$6,0)),载具产出!$E$112:$E$151,1),0),MATCH(AC$6,载具产出!$G$111:$O$111,0))*2 -> 0.48 | AD38: =OFFSET(载具产出!$F$399,IFERROR(MATCH(OFFSET($D38,0,MATCH($D$5,$E$6:$H$6,0)),载具产出!$E$112:$E$151,1),0),MATCH(AD$6,载具产出!$G$111:$O$111,0))*2 -> 0 | AE38: =SUM(AA$36:AA38)/3 -> 27.6 | AF38: =SUM(AB$36:AB38)/3 -> 21.92 | AG38: =SUM(AC$36:AC38)/3 -> 0.48 | AH38: =SUM(AD$36:AD38)/3 -> 0 | AI38: =_xlfn.XLOOKUP($D$5,载具产出!$D$71:$D$75,载具产出!$E$71:$E$75)*(D38-30+1) -> 35.285714 | AJ38: =IFERROR(MATCH(_xlfn.XLOOKUP($D$5,载具产出!$D$71:$D$75,载具产出!$E$71:$E$75)*(D38-30+1)*10,载具产出!$E$60:$E$67,1),0)+1 -> 2 | AK38: =IF($AJ38=1,($AI38)*(10*OFFSET(载具产出!$D$45,MATCH(AK$6,$AK$6:$AN$6,0)-1,$AJ38)+OFFSET(载具产出!$D$49,MATCH(AK$6,$AK$6:$AN$6,0)-1,$AJ38)*OFFSET(载具产出!$N$49,MATCH(AK$6,$AK$6:$AN$6,0)-1,0)),OFFSET(载具产出!F$59,$AJ38-1,0)*10+OFFSET(载具产出!J$59,$AJ38-1,0)+($AI38*10-_xlfn.XLOOKUP($AJ38-1,载具产出!$D$59:$D$67,载具产出!$E$59:$E$67))/10*(10*OFFSET(载具产出!$D$45,MATCH(AK$6,$AK$6:$AN$6,0)-1,$AJ38)+OFFSET(载具产出!$D$49,MATCH(AK$6,$AK$6:$AN$6,0)-1,$AJ38)*OFFSET(载具产出!$N$49,MATCH(AK$6,$AK$6:$AN$6,0)-1,0))) -> 103.81157 | AL38: =IF($AJ38=1,($AI38)*(10*OFFSET(载具产出!$D$45,MATCH(AL$6,$AK$6:$AN$6,0)-1,$AJ38)+OFFSET(载具产出!$D$49,MATCH(AL$6,$AK$6:$AN$6,0)-1,$AJ38)*OFFSET(载具产出!$N$49,MATCH(AL$6,$AK$6:$AN$6,0)-1,0)),OFFSET(载具产出!G$59,$AJ38-1,0)*10+OFFSET(载具产出!K$59,$AJ38-1,0)+($AI38*10-_xlfn.XLOOKUP($AJ38-1,载具产出!$D$59:$D$67,载具产出!$E$59:$E$67))/10*(10*OFFSET(载具产出!$D$45,MATCH(AL$6,$AK$6:$AN$6,0)-1,$AJ38)+OFFSET(载具产出!$D$49,MATCH(AL$6,$AK$6:$AN$6,0)-1,$AJ38)*OFFSET(载具产出!$N$49,MATCH(AL$6,$AK$6:$AN$6,0)-1,0))) -> 25.811429 | AM38: =IF($AJ38=1,($AI38)*(10*OFFSET(载具产出!$D$45,MATCH(AM$6,$AK$6:$AN$6,0)-1,$AJ38)+OFFSET(载具产出!$D$49,MATCH(AM$6,$AK$6:$AN$6,0)-1,$AJ38)*OFFSET(载具产出!$N$49,MATCH(AM$6,$AK$6:$AN$6,0)-1,0)),OFFSET(载具产出!H$59,$AJ38-1,0)*10+OFFSET(载具产出!L$59,$AJ38-1,0)+($AI38*10-_xlfn.XLOOKUP($AJ38-1,载具产出!$D$59:$D$67,载具产出!$E$59:$E$67))/10*(10*OFFSET(载具产出!$D$45,MATCH(AM$6,$AK$6:$AN$6,0)-1,$AJ38)+OFFSET(载具产出!$D$49,MATCH(AM$6,$AK$6:$AN$6,0)-1,$AJ38)*OFFSET(载具产出!$N$49,MATCH(AM$6,$AK$6:$AN$6,0)-1,0))) -> 1.9451429 | AN38: =IF($AJ38=1,($AI38)*(10*OFFSET(载具产出!$D$45,MATCH(AN$6,$AK$6:$AN$6,0)-1,$AJ38)+OFFSET(载具产出!$D$49,MATCH(AN$6,$AK$6:$AN$6,0)-1,$AJ38)*OFFSET(载具产出!$N$49,MATCH(AN$6,$AK$6:$AN$6,0)-1,0)),OFFSET(载具产出!I$59,$AJ38-1,0)*10+OFFSET(载具产出!M$59,$AJ38-1,0)+($AI38*10-_xlfn.XLOOKUP($AJ38-1,载具产出!$D$59:$D$67,载具产出!$E$59:$E$67))/10*(10*OFFSET(载具产出!$D$45,MATCH(AN$6,$AK$6:$AN$6,0)-1,$AJ38)+OFFSET(载具产出!$D$49,MATCH(AN$6,$AK$6:$AN$6,0)-1,$AJ38)*OFFSET(载具产出!$N$49,MATCH(AN$6,$AK$6:$AN$6,0)-1,0))) -> 0 | AO38: =AE38+AK38 -> 131.41157 | AP38: =AF38+AL38 -> 47.731429 | AQ38: =AG38+AM38 -> 2.4251429 | AR38: =AH38+AN38 -> 0 | AS38: =IFERROR(MATCH(AO38/载具产出!R$58,载具属性!$G$33:$G$92,1),0) -> 6 | AT38: =IFERROR(MATCH(AP38/载具产出!S$58,载具属性!$G$33:$G$92,1),0) -> 1 | AU38: =IFERROR(MATCH(AQ38/载具产出!T$58,载具属性!$G$33:$G$92,1),0) -> 0 | AV38: =IFERROR(MATCH(AR38/载具产出!U$58,载具属性!$G$33:$G$92,1),0) -> 0 | AW38: ="["&_xlfn.TEXTJOIN(",",1,AX38:BD38)&"]" -> [{62,20},{63,1625},{2,3200},{6030001,57},{6030002,65},{6030003,1}] | AX38: =IF(INT(K38)<=0,"","{"&K$5&","&INT(K38)&"}") -> {62,20} | AY38: =IF(INT(L38)<=0,"","{"&L$5&","&INT(L38)&"}") -> {63,1625} | AZ38: =IF(INT(M38)<=0,"","{"&M$5&","&INT(M38)&"}") -> {2,3200} | BA38: =IF(INT(N38)<=0,"","{"&N$5&","&INT(N38)&"}") -> {6030001,57} | BB38: =IF(INT(O38)<=0,"","{"&O$5&","&INT(O38)&"}") -> {6030002,65} | BC38: =IF(INT(P38)<=0,"","{"&P$5&","&INT(P38)&"}") -> {6030003,1} | BD38: =IF(INT(Q38)<=0,"","{"&Q$5&","&INT(Q38)&"}")
C39: =W39/G39 -> 83.146067 | D39: 33 | E39: 69 | F39: 79 | G39: 89 | H39: 111 | I39: 122 | J39: =MIN(INT(E39*(30-(D39-30))/30+(D39-30)/30*H39),H39) -> 73 | K39: =SUM(U$36:U39)-SUM(OFFSET(载具产出!H$399,0,0,$R39+1,1)) -> 27 | L39: =SUM(T$36:T39)-SUM(OFFSET(载具产出!G$399,0,0,$R39+1,1)) -> 2375 | M39: =SUM(V$36:V39)/2-SUM(OFFSET(载具产出!I$399,0,0,$R39+1,1)) -> 5600 | N39: =SUM(AA$36:AA39)-SUM(OFFSET(载具产出!J$399,0,0,$R39+1,1)) -> 85.4 | O39: =SUM(AB$36:AB39)-SUM(OFFSET(载具产出!K$399,0,0,$R39+1,1)) -> 87.68 | P39: =SUM(AC$36:AC39)-SUM(OFFSET(载具产出!L$399,0,0,$R39+1,1)) -> 1.92 | Q39: =SUM(AD$36:AD39)-SUM(OFFSET(载具产出!M$399,0,0,$R39+1,1)) -> 0 | R39: 1 | S39: =OFFSET(载具产出!$D$111,IFERROR(MATCH(OFFSET($D39,0,MATCH($D$5,$E$6:$H$6,0)),载具产出!$E$112:$E$151,1),0),0) -> 精良Ⅴ | T39: =OFFSET(载具产出!$F$399,IFERROR(MATCH(OFFSET($D39,0,MATCH($D$5,$E$6:$H$6,0)),载具产出!$E$400:$E$439,1),0),MATCH(T$6,载具产出!$G$399:$O$399,0)) -> 750 | U39: 7 | V39: =OFFSET(载具产出!$F$399,IFERROR(MATCH(OFFSET($D39,0,MATCH($D$5,$E$6:$H$6,0)),载具产出!$E$400:$E$439,1),0),MATCH(V$6,载具产出!$G$399:$O$399,0)) -> 4800 | W39: =_xlfn.XLOOKUP(Z39,载具属性!$E$98:$E$497,载具属性!$G$98:$G$497)+6000+OFFSET(载具属性!L$33,AS39,0)*载具属性!M$30+OFFSET(载具属性!M$33,AT39,0)*载具属性!N$30+OFFSET(载具属性!N$33,AU39,0)*载具属性!O$30+OFFSET(载具属性!O$33,AV39,0)*载具属性!P$30 -> 7400 | X39: =_xlfn.XLOOKUP(Z39,载具属性!$E$98:$E$497,载具属性!$G$98:$G$497) -> 800 | Y39: =OFFSET(载具属性!L$33,AS39,0)*载具属性!M$30+OFFSET(载具属性!M$33,AT39,0)*载具属性!N$30+OFFSET(载具属性!N$33,AU39,0)*载具属性!O$30+OFFSET(载具属性!O$33,AV39,0)*载具属性!P$30 -> 600 | Z39: =MATCH(SUM($T$7:T39),载具属性!$I$98:$I$497,1) -> 17 | AA39: =OFFSET(载具产出!$F$399,IFERROR(MATCH(OFFSET($D39,0,MATCH($D$5,$E$6:$H$6,0)),载具产出!$E$112:$E$151,1),0),MATCH(AA$6,载具产出!$G$111:$O$111,0))*2 -> 27.6 | AB39: =OFFSET(载具产出!$F$399,IFERROR(MATCH(OFFSET($D39,0,MATCH($D$5,$E$6:$H$6,0)),载具产出!$E$112:$E$151,1),0),MATCH(AB$6,载具产出!$G$111:$O$111,0))*2 -> 21.92 | AC39: =OFFSET(载具产出!$F$399,IFERROR(MATCH(OFFSET($D39,0,MATCH($D$5,$E$6:$H$6,0)),载具产出!$E$112:$E$151,1),0),MATCH(AC$6,载具产出!$G$111:$O$111,0))*2 -> 0.48 | AD39: =OFFSET(载具产出!$F$399,IFERROR(MATCH(OFFSET($D39,0,MATCH($D$5,$E$6:$H$6,0)),载具产出!$E$112:$E$151,1),0),MATCH(AD$6,载具产出!$G$111:$O$111,0))*2 -> 0 | AE39: =SUM(AA$36:AA39)/3 -> 36.8 | AF39: =SUM(AB$36:AB39)/3 -> 29.226667 | AG39: =SUM(AC$36:AC39)/3 -> 0.64 | AH39: =SUM(AD$36:AD39)/3 -> 0 | AI39: =_xlfn.XLOOKUP($D$5,载具产出!$D$71:$D$75,载具产出!$E$71:$E$75)*(D39-30+1) -> 47.047619 | AJ39: =IFERROR(MATCH(_xlfn.XLOOKUP($D$5,载具产出!$D$71:$D$75,载具产出!$E$71:$E$75)*(D39-30+1)*10,载具产出!$E$60:$E$67,1),0)+1 -> 2 | AK39: =IF($AJ39=1,($AI39)*(10*OFFSET(载具产出!$D$45,MATCH(AK$6,$AK$6:$AN$6,0)-1,$AJ39)+OFFSET(载具产出!$D$49,MATCH(AK$6,$AK$6:$AN$6,0)-1,$AJ39)*OFFSET(载具产出!$N$49,MATCH(AK$6,$AK$6:$AN$6,0)-1,0)),OFFSET(载具产出!F$59,$AJ39-1,0)*10+OFFSET(载具产出!J$59,$AJ39-1,0)+($AI39*10-_xlfn.XLOOKUP($AJ39-1,载具产出!$D$59:$D$67,载具产出!$E$59:$E$67))/10*(10*OFFSET(载具产出!$D$45,MATCH(AK$6,$AK$6:$AN$6,0)-1,$AJ39)+OFFSET(载具产出!$D$49,MATCH(AK$6,$AK$6:$AN$6,0)-1,$AJ39)*OFFSET(载具产出!$N$49,MATCH(AK$6,$AK$6:$AN$6,0)-1,0))) -> 134.54543 | AL39: =IF($AJ39=1,($AI39)*(10*OFFSET(载具产出!$D$45,MATCH(AL$6,$AK$6:$AN$6,0)-1,$AJ39)+OFFSET(载具产出!$D$49,MATCH(AL$6,$AK$6:$AN$6,0)-1,$AJ39)*OFFSET(载具产出!$N$49,MATCH(AL$6,$AK$6:$AN$6,0)-1,0)),OFFSET(载具产出!G$59,$AJ39-1,0)*10+OFFSET(载具产出!K$59,$AJ39-1,0)+($AI39*10-_xlfn.XLOOKUP($AJ39-1,载具产出!$D$59:$D$67,载具产出!$E$59:$E$67))/10*(10*OFFSET(载具产出!$D$45,MATCH(AL$6,$AK$6:$AN$6,0)-1,$AJ39)+OFFSET(载具产出!$D$49,MATCH(AL$6,$AK$6:$AN$6,0)-1,$AJ39)*OFFSET(载具产出!$N$49,MATCH(AL$6,$AK$6:$AN$6,0)-1,0))) -> 34.515238 | AM39: =IF($AJ39=1,($AI39)*(10*OFFSET(载具产出!$D$45,MATCH(AM$6,$AK$6:$AN$6,0)-1,$AJ39)+OFFSET(载具产出!$D$49,MATCH(AM$6,$AK$6:$AN$6,0)-1,$AJ39)*OFFSET(载具产出!$N$49,MATCH(AM$6,$AK$6:$AN$6,0)-1,0)),OFFSET(载具产出!H$59,$AJ39-1,0)*10+OFFSET(载具产出!L$59,$AJ39-1,0)+($AI39*10-_xlfn.XLOOKUP($AJ39-1,载具产出!$D$59:$D$67,载具产出!$E$59:$E$67))/10*(10*OFFSET(载具产出!$D$45,MATCH(AM$6,$AK$6:$AN$6,0)-1,$AJ39)+OFFSET(载具产出!$D$49,MATCH(AM$6,$AK$6:$AN$6,0)-1,$AJ39)*OFFSET(载具产出!$N$49,MATCH(AM$6,$AK$6:$AN$6,0)-1,0))) -> 6.2735238 | AN39: =IF($AJ39=1,($AI39)*(10*OFFSET(载具产出!$D$45,MATCH(AN$6,$AK$6:$AN$6,0)-1,$AJ39)+OFFSET(载具产出!$D$49,MATCH(AN$6,$AK$6:$AN$6,0)-1,$AJ39)*OFFSET(载具产出!$N$49,MATCH(AN$6,$AK$6:$AN$6,0)-1,0)),OFFSET(载具产出!I$59,$AJ39-1,0)*10+OFFSET(载具产出!M$59,$AJ39-1,0)+($AI39*10-_xlfn.XLOOKUP($AJ39-1,载具产出!$D$59:$D$67,载具产出!$E$59:$E$67))/10*(10*OFFSET(载具产出!$D$45,MATCH(AN$6,$AK$6:$AN$6,0)-1,$AJ39)+OFFSET(载具产出!$D$49,MATCH(AN$6,$AK$6:$AN$6,0)-1,$AJ39)*OFFSET(载具产出!$N$49,MATCH(AN$6,$AK$6:$AN$6,0)-1,0))) -> 0 | AO39: =AE39+AK39 -> 171.34543 | AP39: =AF39+AL39 -> 63.741905 | AQ39: =AG39+AM39 -> 6.9135238 | AR39: =AH39+AN39 -> 0 | AS39: =IFERROR(MATCH(AO39/载具产出!R$58,载具属性!$G$33:$G$92,1),0) -> 7 | AT39: =IFERROR(MATCH(AP39/载具产出!S$58,载具属性!$G$33:$G$92,1),0) -> 2 | AU39: =IFERROR(MATCH(AQ39/载具产出!T$58,载具属性!$G$33:$G$92,1),0) -> 0 | AV39: =IFERROR(MATCH(AR39/载具产出!U$58,载具属性!$G$33:$G$92,1),0) -> 0 | AW39: ="["&_xlfn.TEXTJOIN(",",1,AX39:BD39)&"]" -> [{62,27},{63,2375},{2,5600},{6030001,85},{6030002,87},{6030003,1}] | AX39: =IF(INT(K39)<=0,"","{"&K$5&","&INT(K39)&"}") -> {62,27} | AY39: =IF(INT(L39)<=0,"","{"&L$5&","&INT(L39)&"}") -> {63,2375} | AZ39: =IF(INT(M39)<=0,"","{"&M$5&","&INT(M39)&"}") -> {2,5600} | BA39: =IF(INT(N39)<=0,"","{"&N$5&","&INT(N39)&"}") -> {6030001,85} | BB39: =IF(INT(O39)<=0,"","{"&O$5&","&INT(O39)&"}") -> {6030002,87} | BC39: =IF(INT(P39)<=0,"","{"&P$5&","&INT(P39)&"}") -> {6030003,1} | BD39: =IF(INT(Q39)<=0,"","{"&Q$5&","&INT(Q39)&"}")
C40: =W40/G40 -> 85.222222 | D40: 34 | E40: 70 | F40: 80 | G40: 90 | H40: 112 | I40: 122 | J40: =MIN(INT(E40*(30-(D40-30))/30+(D40-30)/30*H40),H40) -> 75 | K40: =SUM(U$36:U40)-SUM(OFFSET(载具产出!H$399,0,0,$R40+1,1)) -> 33 | L40: =SUM(T$36:T40)-SUM(OFFSET(载具产出!G$399,0,0,$R40+1,1)) -> 2460 | M40: =SUM(V$36:V40)/2-SUM(OFFSET(载具产出!I$399,0,0,$R40+1,1)) -> 3800 | N40: =SUM(AA$36:AA40)-SUM(OFFSET(载具产出!J$399,0,0,$R40+1,1)) -> 98.4 | O40: =SUM(AB$36:AB40)-SUM(OFFSET(载具产出!K$399,0,0,$R40+1,1)) -> 104.2 | P40: =SUM(AC$36:AC40)-SUM(OFFSET(载具产出!L$399,0,0,$R40+1,1)) -> 2.4 | Q40: =SUM(AD$36:AD40)-SUM(OFFSET(载具产出!M$399,0,0,$R40+1,1)) -> 0 | R40: 2 | S40: =OFFSET(载具产出!$D$111,IFERROR(MATCH(OFFSET($D40,0,MATCH($D$5,$E$6:$H$6,0)),载具产出!$E$112:$E$151,1),0),0) -> 精良Ⅴ | T40: =OFFSET(载具产出!$F$399,IFERROR(MATCH(OFFSET($D40,0,MATCH($D$5,$E$6:$H$6,0)),载具产出!$E$400:$E$439,1),0),MATCH(T$6,载具产出!$G$399:$O$399,0)) -> 750 | U40: 7 | V40: =OFFSET(载具产出!$F$399,IFERROR(MATCH(OFFSET($D40,0,MATCH($D$5,$E$6:$H$6,0)),载具产出!$E$400:$E$439,1),0),MATCH(V$6,载具产出!$G$399:$O$399,0)) -> 4800 | W40: =_xlfn.XLOOKUP(Z40,载具属性!$E$98:$E$497,载具属性!$G$98:$G$497)+6000+OFFSET(载具属性!L$33,AS40,0)*载具属性!M$30+OFFSET(载具属性!M$33,AT40,0)*载具属性!N$30+OFFSET(载具属性!N$33,AU40,0)*载具属性!O$30+OFFSET(载具属性!O$33,AV40,0)*载具属性!P$30 -> 7670 | X40: =_xlfn.XLOOKUP(Z40,载具属性!$E$98:$E$497,载具属性!$G$98:$G$497) -> 950 | Y40: =OFFSET(载具属性!L$33,AS40,0)*载具属性!M$30+OFFSET(载具属性!M$33,AT40,0)*载具属性!N$30+OFFSET(载具属性!N$33,AU40,0)*载具属性!O$30+OFFSET(载具属性!O$33,AV40,0)*载具属性!P$30 -> 720 | Z40: =MATCH(SUM($T$7:T40),载具属性!$I$98:$I$497,1) -> 20 | AA40: =OFFSET(载具产出!$F$399,IFERROR(MATCH(OFFSET($D40,0,MATCH($D$5,$E$6:$H$6,0)),载具产出!$E$112:$E$151,1),0),MATCH(AA$6,载具产出!$G$111:$O$111,0))*2 -> 27.6 | AB40: =OFFSET(载具产出!$F$399,IFERROR(MATCH(OFFSET($D40,0,MATCH($D$5,$E$6:$H$6,0)),载具产出!$E$112:$E$151,1),0),MATCH(AB$6,载具产出!$G$111:$O$111,0))*2 -> 21.92 | AC40: =OFFSET(载具产出!$F$399,IFERROR(MATCH(OFFSET($D40,0,MATCH($D$5,$E$6:$H$6,0)),载具产出!$E$112:$E$151,1),0),MATCH(AC$6,载具产出!$G$111:$O$111,0))*2 -> 0.48 | AD40: =OFFSET(载具产出!$F$399,IFERROR(MATCH(OFFSET($D40,0,MATCH($D$5,$E$6:$H$6,0)),载具产出!$E$112:$E$151,1),0),MATCH(AD$6,载具产出!$G$111:$O$111,0))*2 -> 0 | AE40: =SUM(AA$36:AA40)/3 -> 46 | AF40: =SUM(AB$36:AB40)/3 -> 36.533333 | AG40: =SUM(AC$36:AC40)/3 -> 0.8 | AH40: =SUM(AD$36:AD40)/3 -> 0 | AI40: =_xlfn.XLOOKUP($D$5,载具产出!$D$71:$D$75,载具产出!$E$71:$E$75)*(D40-30+1) -> 58.809524 | AJ40: =IFERROR(MATCH(_xlfn.XLOOKUP($D$5,载具产出!$D$71:$D$75,载具产出!$E$71:$E$75)*(D40-30+1)*10,载具产出!$E$60:$E$67,1),0)+1 -> 2 | AK40: =IF($AJ40=1,($AI40)*(10*OFFSET(载具产出!$D$45,MATCH(AK$6,$AK$6:$AN$6,0)-1,$AJ40)+OFFSET(载具产出!$D$49,MATCH(AK$6,$AK$6:$AN$6,0)-1,$AJ40)*OFFSET(载具产出!$N$49,MATCH(AK$6,$AK$6:$AN$6,0)-1,0)),OFFSET(载具产出!F$59,$AJ40-1,0)*10+OFFSET(载具产出!J$59,$AJ40-1,0)+($AI40*10-_xlfn.XLOOKUP($AJ40-1,载具产出!$D$59:$D$67,载具产出!$E$59:$E$67))/10*(10*OFFSET(载具产出!$D$45,MATCH(AK$6,$AK$6:$AN$6,0)-1,$AJ40)+OFFSET(载具产出!$D$49,MATCH(AK$6,$AK$6:$AN$6,0)-1,$AJ40)*OFFSET(载具产出!$N$49,MATCH(AK$6,$AK$6:$AN$6,0)-1,0))) -> 165.27929 | AL40: =IF($AJ40=1,($AI40)*(10*OFFSET(载具产出!$D$45,MATCH(AL$6,$AK$6:$AN$6,0)-1,$AJ40)+OFFSET(载具产出!$D$49,MATCH(AL$6,$AK$6:$AN$6,0)-1,$AJ40)*OFFSET(载具产出!$N$49,MATCH(AL$6,$AK$6:$AN$6,0)-1,0)),OFFSET(载具产出!G$59,$AJ40-1,0)*10+OFFSET(载具产出!K$59,$AJ40-1,0)+($AI40*10-_xlfn.XLOOKUP($AJ40-1,载具产出!$D$59:$D$67,载具产出!$E$59:$E$67))/10*(10*OFFSET(载具产出!$D$45,MATCH(AL$6,$AK$6:$AN$6,0)-1,$AJ40)+OFFSET(载具产出!$D$49,MATCH(AL$6,$AK$6:$AN$6,0)-1,$AJ40)*OFFSET(载具产出!$N$49,MATCH(AL$6,$AK$6:$AN$6,0)-1,0))) -> 43.219048 | AM40: =IF($AJ40=1,($AI40)*(10*OFFSET(载具产出!$D$45,MATCH(AM$6,$AK$6:$AN$6,0)-1,$AJ40)+OFFSET(载具产出!$D$49,MATCH(AM$6,$AK$6:$AN$6,0)-1,$AJ40)*OFFSET(载具产出!$N$49,MATCH(AM$6,$AK$6:$AN$6,0)-1,0)),OFFSET(载具产出!H$59,$AJ40-1,0)*10+OFFSET(载具产出!L$59,$AJ40-1,0)+($AI40*10-_xlfn.XLOOKUP($AJ40-1,载具产出!$D$59:$D$67,载具产出!$E$59:$E$67))/10*(10*OFFSET(载具产出!$D$45,MATCH(AM$6,$AK$6:$AN$6,0)-1,$AJ40)+OFFSET(载具产出!$D$49,MATCH(AM$6,$AK$6:$AN$6,0)-1,$AJ40)*OFFSET(载具产出!$N$49,MATCH(AM$6,$AK$6:$AN$6,0)-1,0))) -> 10.601905 | AN40: =IF($AJ40=1,($AI40)*(10*OFFSET(载具产出!$D$45,MATCH(AN$6,$AK$6:$AN$6,0)-1,$AJ40)+OFFSET(载具产出!$D$49,MATCH(AN$6,$AK$6:$AN$6,0)-1,$AJ40)*OFFSET(载具产出!$N$49,MATCH(AN$6,$AK$6:$AN$6,0)-1,0)),OFFSET(载具产出!I$59,$AJ40-1,0)*10+OFFSET(载具产出!M$59,$AJ40-1,0)+($AI40*10-_xlfn.XLOOKUP($AJ40-1,载具产出!$D$59:$D$67,载具产出!$E$59:$E$67))/10*(10*OFFSET(载具产出!$D$45,MATCH(AN$6,$AK$6:$AN$6,0)-1,$AJ40)+OFFSET(载具产出!$D$49,MATCH(AN$6,$AK$6:$AN$6,0)-1,$AJ40)*OFFSET(载具产出!$N$49,MATCH(AN$6,$AK$6:$AN$6,0)-1,0))) -> 0 | AO40: =AE40+AK40 -> 211.27929 | AP40: =AF40+AL40 -> 79.752381 | AQ40: =AG40+AM40 -> 11.401905 | AR40: =AH40+AN40 -> 0 | AS40: =IFERROR(MATCH(AO40/载具产出!R$58,载具属性!$G$33:$G$92,1),0) -> 9 | AT40: =IFERROR(MATCH(AP40/载具产出!S$58,载具属性!$G$33:$G$92,1),0) -> 2 | AU40: =IFERROR(MATCH(AQ40/载具产出!T$58,载具属性!$G$33:$G$92,1),0) -> 0 | AV40: =IFERROR(MATCH(AR40/载具产出!U$58,载具属性!$G$33:$G$92,1),0) -> 0 | AW40: ="["&_xlfn.TEXTJOIN(",",1,AX40:BD40)&"]" -> [{62,33},{63,2460},{2,3800},{6030001,98},{6030002,104},{6030003,2}] | AX40: =IF(INT(K40)<=0,"","{"&K$5&","&INT(K40)&"}") -> {62,33} | AY40: =IF(INT(L40)<=0,"","{"&L$5&","&INT(L40)&"}") -> {63,2460} | AZ40: =IF(INT(M40)<=0,"","{"&M$5&","&INT(M40)&"}") -> {2,3800} | BA40: =IF(INT(N40)<=0,"","{"&N$5&","&INT(N40)&"}") -> {6030001,98} | BB40: =IF(INT(O40)<=0,"","{"&O$5&","&INT(O40)&"}") -> {6030002,104} | BC40: =IF(INT(P40)<=0,"","{"&P$5&","&INT(P40)&"}") -> {6030003,2} | BD40: =IF(INT(Q40)<=0,"","{"&Q$5&","&INT(Q40)&"}")
C41: =W41/G41 -> 87.142857 | D41: 35 | E41: 71 | F41: 81 | G41: 91 | H41: 113 | I41: 122 | J41: =MIN(INT(E41*(30-(D41-30))/30+(D41-30)/30*H41),H41) -> 78 | K41: =SUM(U$36:U41)-SUM(OFFSET(载具产出!H$399,0,0,$R41+1,1)) -> 40 | L41: =SUM(T$36:T41)-SUM(OFFSET(载具产出!G$399,0,0,$R41+1,1)) -> 3210 | M41: =SUM(V$36:V41)/2-SUM(OFFSET(载具产出!I$399,0,0,$R41+1,1)) -> 6200 | N41: =SUM(AA$36:AA41)-SUM(OFFSET(载具产出!J$399,0,0,$R41+1,1)) -> 126 | O41: =SUM(AB$36:AB41)-SUM(OFFSET(载具产出!K$399,0,0,$R41+1,1)) -> 126.12 | P41: =SUM(AC$36:AC41)-SUM(OFFSET(载具产出!L$399,0,0,$R41+1,1)) -> 2.88 | Q41: =SUM(AD$36:AD41)-SUM(OFFSET(载具产出!M$399,0,0,$R41+1,1)) -> 0 | R41: 2 | S41: =OFFSET(载具产出!$D$111,IFERROR(MATCH(OFFSET($D41,0,MATCH($D$5,$E$6:$H$6,0)),载具产出!$E$112:$E$151,1),0),0) -> 精良Ⅴ | T41: =OFFSET(载具产出!$F$399,IFERROR(MATCH(OFFSET($D41,0,MATCH($D$5,$E$6:$H$6,0)),载具产出!$E$400:$E$439,1),0),MATCH(T$6,载具产出!$G$399:$O$399,0)) -> 750 | U41: 7 | V41: =OFFSET(载具产出!$F$399,IFERROR(MATCH(OFFSET($D41,0,MATCH($D$5,$E$6:$H$6,0)),载具产出!$E$400:$E$439,1),0),MATCH(V$6,载具产出!$G$399:$O$399,0)) -> 4800 | W41: =_xlfn.XLOOKUP(Z41,载具属性!$E$98:$E$497,载具属性!$G$98:$G$497)+6000+OFFSET(载具属性!L$33,AS41,0)*载具属性!M$30+OFFSET(载具属性!M$33,AT41,0)*载具属性!N$30+OFFSET(载具属性!N$33,AU41,0)*载具属性!O$30+OFFSET(载具属性!O$33,AV41,0)*载具属性!P$30 -> 7930 | X41: =_xlfn.XLOOKUP(Z41,载具属性!$E$98:$E$497,载具属性!$G$98:$G$497) -> 1060 | Y41: =OFFSET(载具属性!L$33,AS41,0)*载具属性!M$30+OFFSET(载具属性!M$33,AT41,0)*载具属性!N$30+OFFSET(载具属性!N$33,AU41,0)*载具属性!O$30+OFFSET(载具属性!O$33,AV41,0)*载具属性!P$30 -> 870 | Z41: =MATCH(SUM($T$7:T41),载具属性!$I$98:$I$497,1) -> 22 | AA41: =OFFSET(载具产出!$F$399,IFERROR(MATCH(OFFSET($D41,0,MATCH($D$5,$E$6:$H$6,0)),载具产出!$E$112:$E$151,1),0),MATCH(AA$6,载具产出!$G$111:$O$111,0))*2 -> 27.6 | AB41: =OFFSET(载具产出!$F$399,IFERROR(MATCH(OFFSET($D41,0,MATCH($D$5,$E$6:$H$6,0)),载具产出!$E$112:$E$151,1),0),MATCH(AB$6,载具产出!$G$111:$O$111,0))*2 -> 21.92 | AC41: =OFFSET(载具产出!$F$399,IFERROR(MATCH(OFFSET($D41,0,MATCH($D$5,$E$6:$H$6,0)),载具产出!$E$112:$E$151,1),0),MATCH(AC$6,载具产出!$G$111:$O$111,0))*2 -> 0.48 | AD41: =OFFSET(载具产出!$F$399,IFERROR(MATCH(OFFSET($D41,0,MATCH($D$5,$E$6:$H$6,0)),载具产出!$E$112:$E$151,1),0),MATCH(AD$6,载具产出!$G$111:$O$111,0))*2 -> 0 | AE41: =SUM(AA$36:AA41)/3 -> 55.2 | AF41: =SUM(AB$36:AB41)/3 -> 43.84 | AG41: =SUM(AC$36:AC41)/3 -> 0.96 | AH41: =SUM(AD$36:AD41)/3 -> 0 | AI41: =_xlfn.XLOOKUP($D$5,载具产出!$D$71:$D$75,载具产出!$E$71:$E$75)*(D41-30+1) -> 70.571429 | AJ41: =IFERROR(MATCH(_xlfn.XLOOKUP($D$5,载具产出!$D$71:$D$75,载具产出!$E$71:$E$75)*(D41-30+1)*10,载具产出!$E$60:$E$67,1),0)+1 -> 3 | AK41: =IF($AJ41=1,($AI41)*(10*OFFSET(载具产出!$D$45,MATCH(AK$6,$AK$6:$AN$6,0)-1,$AJ41)+OFFSET(载具产出!$D$49,MATCH(AK$6,$AK$6:$AN$6,0)-1,$AJ41)*OFFSET(载具产出!$N$49,MATCH(AK$6,$AK$6:$AN$6,0)-1,0)),OFFSET(载具产出!F$59,$AJ41-1,0)*10+OFFSET(载具产出!J$59,$AJ41-1,0)+($AI41*10-_xlfn.XLOOKUP($AJ41-1,载具产出!$D$59:$D$67,载具产出!$E$59:$E$67))/10*(10*OFFSET(载具产出!$D$45,MATCH(AK$6,$AK$6:$AN$6,0)-1,$AJ41)+OFFSET(载具产出!$D$49,MATCH(AK$6,$AK$6:$AN$6,0)-1,$AJ41)*OFFSET(载具产出!$N$49,MATCH(AK$6,$AK$6:$AN$6,0)-1,0))) -> 195.66429 | AL41: =IF($AJ41=1,($AI41)*(10*OFFSET(载具产出!$D$45,MATCH(AL$6,$AK$6:$AN$6,0)-1,$AJ41)+OFFSET(载具产出!$D$49,MATCH(AL$6,$AK$6:$AN$6,0)-1,$AJ41)*OFFSET(载具产出!$N$49,MATCH(AL$6,$AK$6:$AN$6,0)-1,0)),OFFSET(载具产出!G$59,$AJ41-1,0)*10+OFFSET(载具产出!K$59,$AJ41-1,0)+($AI41*10-_xlfn.XLOOKUP($AJ41-1,载具产出!$D$59:$D$67,载具产出!$E$59:$E$67))/10*(10*OFFSET(载具产出!$D$45,MATCH(AL$6,$AK$6:$AN$6,0)-1,$AJ41)+OFFSET(载具产出!$D$49,MATCH(AL$6,$AK$6:$AN$6,0)-1,$AJ41)*OFFSET(载具产出!$N$49,MATCH(AL$6,$AK$6:$AN$6,0)-1,0))) -> 52.345714 | AM41: =IF($AJ41=1,($AI41)*(10*OFFSET(载具产出!$D$45,MATCH(AM$6,$AK$6:$AN$6,0)-1,$AJ41)+OFFSET(载具产出!$D$49,MATCH(AM$6,$AK$6:$AN$6,0)-1,$AJ41)*OFFSET(载具产出!$N$49,MATCH(AM$6,$AK$6:$AN$6,0)-1,0)),OFFSET(载具产出!H$59,$AJ41-1,0)*10+OFFSET(载具产出!L$59,$AJ41-1,0)+($AI41*10-_xlfn.XLOOKUP($AJ41-1,载具产出!$D$59:$D$67,载具产出!$E$59:$E$67))/10*(10*OFFSET(载具产出!$D$45,MATCH(AM$6,$AK$6:$AN$6,0)-1,$AJ41)+OFFSET(载具产出!$D$49,MATCH(AM$6,$AK$6:$AN$6,0)-1,$AJ41)*OFFSET(载具产出!$N$49,MATCH(AM$6,$AK$6:$AN$6,0)-1,0))) -> 15.268571 | AN41: =IF($AJ41=1,($AI41)*(10*OFFSET(载具产出!$D$45,MATCH(AN$6,$AK$6:$AN$6,0)-1,$AJ41)+OFFSET(载具产出!$D$49,MATCH(AN$6,$AK$6:$AN$6,0)-1,$AJ41)*OFFSET(载具产出!$N$49,MATCH(AN$6,$AK$6:$AN$6,0)-1,0)),OFFSET(载具产出!I$59,$AJ41-1,0)*10+OFFSET(载具产出!M$59,$AJ41-1,0)+($AI41*10-_xlfn.XLOOKUP($AJ41-1,载具产出!$D$59:$D$67,载具产出!$E$59:$E$67))/10*(10*OFFSET(载具产出!$D$45,MATCH(AN$6,$AK$6:$AN$6,0)-1,$AJ41)+OFFSET(载具产出!$D$49,MATCH(AN$6,$AK$6:$AN$6,0)-1,$AJ41)*OFFSET(载具产出!$N$49,MATCH(AN$6,$AK$6:$AN$6,0)-1,0))) -> 0 | AO41: =AE41+AK41 -> 250.86429 | AP41: =AF41+AL41 -> 96.185714 | AQ41: =AG41+AM41 -> 16.228571 | AR41: =AH41+AN41 -> 0 | AS41: =IFERROR(MATCH(AO41/载具产出!R$58,载具属性!$G$33:$G$92,1),0) -> 10 | AT41: =IFERROR(MATCH(AP41/载具产出!S$58,载具属性!$G$33:$G$92,1),0) -> 3 | AU41: =IFERROR(MATCH(AQ41/载具产出!T$58,载具属性!$G$33:$G$92,1),0) -> 0 | AV41: =IFERROR(MATCH(AR41/载具产出!U$58,载具属性!$G$33:$G$92,1),0) -> 0 | AW41: ="["&_xlfn.TEXTJOIN(",",1,AX41:BD41)&"]" -> [{62,40},{63,3210},{2,6200},{6030001,126},{6030002,126},{6030003,2}] | AX41: =IF(INT(K41)<=0,"","{"&K$5&","&INT(K41)&"}") -> {62,40} | AY41: =IF(INT(L41)<=0,"","{"&L$5&","&INT(L41)&"}") -> {63,3210} | AZ41: =IF(INT(M41)<=0,"","{"&M$5&","&INT(M41)&"}") -> {2,6200} | BA41: =IF(INT(N41)<=0,"","{"&N$5&","&INT(N41)&"}") -> {6030001,126} | BB41: =IF(INT(O41)<=0,"","{"&O$5&","&INT(O41)&"}") -> {6030002,126} | BC41: =IF(INT(P41)<=0,"","{"&P$5&","&INT(P41)&"}") -> {6030003,2} | BD41: =IF(INT(Q41)<=0,"","{"&Q$5&","&INT(Q41)&"}")
