Workbook

Sheet 说明
A1: 基因养成
A3: 说明
C5: 基因升级
D6: 梦灵升级消耗【基因罐】＋【金币】＋【时间】，大节点消耗【大基因罐】 | P6: 基因养成体验
D7: 基因升级的属性加给主角攻击力，对标装备养成节奏 | P7: 1、养成：全绑定主角伤害，少量攻击力丢到这里来。
P8: 2、加速产出： 大量在前期运营活动、主线通关奖励（快速释放）、每日任务（主要）里面产加速材料
P9: 3、天赋石产出：体力扫荡（主要）、个人挑战本商店（肝度）、
P10: 整体体验：前期用主线和活动产的加速去释放，每天固定产很多小时加速（48h+），防止需要高频点击带来的肝度提升
C12: 关联配置
D14: 配置 | E14: 字段 | F14: 值 | G14: 说明
D15: J_基因_evolve_data
D16: X_效果映射_effect_mapping_data | G16: *基因节点引用效果映射表，具体技能内容根据实际进行配置
G17: *预留最后一行
A19: 本页结束

Sheet 养成属性
A1: 养成属性
C3: 属性规划
H4: 对标梦灵升级 | N4: 对标技能 | O4: 对标梦灵升阶
D5: 天数 | E5: 玩家等级 | F5: 挂件属性 | G5: 主角属性倍率 | H5: 配置属性 | I5: 主角伤害加成 | J5: 主角爆伤加成 | K5: 主角暴击加成 | L5: 主角攻速加成 | M5: 预估倍率 | N5: 主角成长倍率 | O5: 攻击力
D6: 1 | E6: 12 | F6: 600 | G6: 1.2 | H6: =F6*(G6-1) -> 120 | I6: =SQRT(N6) -> 1.5165751 | J6: =(F6-1)/($F$29-1)*$J$29 -> 0.069634969 | K6: =(F6-1)/($F$29-1)*$K$29 -> 0.0069634969 | L6: =SQRT(SQRT(N6)) -> 1.231493 | M6: =L6*I6*(1+K6*(J6+600%)) -> 1.9465896 | N6: 2.3 | O6: 1000 | Q6: 解锁技能
D7: 2 | E7: 18 | F7: 900 | G7: 1.2835 | H7: =F7*(G7-1) -> 255.15 | I7: =SQRT(N7) -> 1.5165751 | J7: =(F7-1)/($F$29-1)*$J$29 -> 0.10451058 | K7: =(F7-1)/($F$29-1)*$K$29 -> 0.010451058 | L7: =SQRT(SQRT(N7)) -> 1.231493 | M7: =L7*I7*(1+K7*(J7+600%)) -> 1.9868052 | N7: 2.3 | Q7: 解锁复活
D8: 3 | E8: 24 | F8: 1080 | G8: 1.367 | H8: =F8*(G8-1) -> 396.36 | I8: =SQRT(N8) -> 1.5165751 | J8: =(F8-1)/($F$29-1)*$J$29 -> 0.12543595 | K8: =(F8-1)/($F$29-1)*$K$29 -> 0.012543595 | L8: =SQRT(SQRT(N8)) -> 1.231493 | M8: =L8*I8*(1+K8*(J8+600%)) -> 2.0111526 | N8: 2.3 | Q8: 初始召唤+1【上限2】
D9: 4 | E9: 29 | F9: 1296 | G9: 1.367 | H9: =F9*(G9-1) -> 475.632 | I9: =SQRT(N9) -> 1.7320508 | J9: =(F9-1)/($F$29-1)*$J$29 -> 0.15054638 | K9: =(F9-1)/($F$29-1)*$K$29 -> 0.015054638 | L9: =SQRT(SQRT(N9)) -> 1.316074 | M9: =L9*I9*(1+K9*(J9+600%)) -> 2.4905763 | N9: 3 | Q9: 梦灵召唤后，伤害+n%，持续m秒
D10: 5 | E10: 33 | F10: 1490 | G10: 1.27 | H10: =F10*(G10-1) -> 402.3 | I10: =SQRT(N10) -> 1.7320508 | J10: =(F10-1)/($F$29-1)*$J$29 -> 0.17309928 | K10: =(F10-1)/($F$29-1)*$K$29 -> 0.017309928 | L10: =SQRT(SQRT(N10)) -> 1.316074 | M10: =L10*I10*(1+K10*(J10+600%)) -> 2.5230858 | N10: 3 | Q10: 梦灵召唤后，攻速+n%，持续m秒
D11: 6 | E11: 37 | F11: 1713 | G11: 1.3 | H11: =F11*(G11-1) -> 513.9 | I11: =SQRT(N11) -> 1.7320508 | J11: =(F11-1)/($F$29-1)*$J$29 -> 0.19902348 | K11: =(F11-1)/($F$29-1)*$K$29 -> 0.019902348 | L11: =SQRT(SQRT(N11)) -> 1.316074 | M11: =L11*I11*(1+K11*(J11+600%)) -> 2.5607415 | N11: 3 | Q11: 梦灵复活后，无敌n秒
D12: 7 | E12: 40 | F12: 1971 | G12: 1.33 | H12: =F12*(G12-1) -> 650.43 | I12: =SQRT(N12) -> 1.7320508 | J12: =(F12-1)/($F$29-1)*$J$29 -> 0.22901651 | K12: =(F12-1)/($F$29-1)*$K$29 -> 0.022901651 | L12: =SQRT(SQRT(N12)) -> 1.316074 | M12: =L12*I12*(1+K12*(J12+600%)) -> 2.6046896 | N12: 3 | Q12: 梦灵复活后，n个梦灵伤害+n%，持续m秒
D13: 8 | E13: 43 | F13: 2168 | G13: 1.36 | H13: =F13*(G13-1) -> 780.48 | I13: =SQRT(N13) -> 1.7320508 | J13: =(F13-1)/($F$29-1)*$J$29 -> 0.25191816 | K13: =(F13-1)/($F$29-1)*$K$29 -> 0.025191816 | L13: =SQRT(SQRT(N13)) -> 1.316074 | M13: =L13*I13*(1+K13*(J13+600%)) -> 2.638523 | N13: 3 | Q13: 梦灵复活后，n个梦灵全体攻速+n%，持续m秒
D14: 9 | E14: 46 | F14: 2276 | G14: 1.39 | H14: =F14*(G14-1) -> 887.64 | I14: =SQRT(N14) -> 1.7320508 | J14: =(F14-1)/($F$29-1)*$J$29 -> 0.26447338 | K14: =(F14-1)/($F$29-1)*$K$29 -> 0.026447338 | L14: =SQRT(SQRT(N14)) -> 1.316074 | M14: =L14*I14*(1+K14*(J14+600%)) -> 2.6571727 | N14: 3 | Q14: 梦灵复活后，触发击退
D15: 10 | E15: 49 | F15: 2390 | G15: 1.42 | H15: =F15*(G15-1) -> 1003.8 | I15: =SQRT(N15) -> 1.7320508 | J15: =(F15-1)/($F$29-1)*$J$29 -> 0.27772611 | K15: =(F15-1)/($F$29-1)*$K$29 -> 0.027772611 | L15: =SQRT(SQRT(N15)) -> 1.316074 | M15: =L15*I15*(1+K15*(J15+600%)) -> 2.6769365 | N15: 3 | Q15: 复活次数+1
D16: 11 | E16: 51 | F16: 2509 | G16: 1.45 | H16: =F16*(G16-1) -> 1129.05 | I16: =SQRT(N16) -> 1.7320508 | J16: =(F16-1)/($F$29-1)*$J$29 -> 0.2915601 | K16: =(F16-1)/($F$29-1)*$K$29 -> 0.02915601 | L16: =SQRT(SQRT(N16)) -> 1.316074 | M16: =L16*I16*(1+K16*(J16+600%)) -> 2.6976525 | N16: 3 | Q16: 梦灵复活后，击退距离+n
D17: 12 | E17: 53 | F17: 2635 | G17: 1.48 | H17: =F17*(G17-1) -> 1264.8 | I17: =SQRT(N17) -> 1.7320508 | J17: =(F17-1)/($F$29-1)*$J$29 -> 0.30620786 | K17: =(F17-1)/($F$29-1)*$K$29 -> 0.030620786 | L17: =SQRT(SQRT(N17)) -> 1.316074 | M17: =L17*I17*(1+K17*(J17+600%)) -> 2.7196822 | N17: 3 | Q17: 复活血量+n%
D18: 13 | E18: 55 | F18: 2767 | G18: 1.51 | H18: =F18*(G18-1) -> 1411.17 | I18: =SQRT(N18) -> 1.7320508 | J18: =(F18-1)/($F$29-1)*$J$29 -> 0.32155313 | K18: =(F18-1)/($F$29-1)*$K$29 -> 0.032155313 | L18: =SQRT(SQRT(N18)) -> 1.316074 | M18: =L18*I18*(1+K18*(J18+600%)) -> 2.7428659 | N18: 3
D19: 14 | E19: 56 | F19: 2905 | G19: 1.54 | H19: =F19*(G19-1) -> 1568.7 | I19: =SQRT(N19) -> 1.8165902 | J19: =(F19-1)/($F$29-1)*$J$29 -> 0.33759591 | K19: =(F19-1)/($F$29-1)*$K$29 -> 0.033759591 | L19: =SQRT(SQRT(N19)) -> 1.3478094 | M19: =L19*I19*(1+K19*(J19+600%)) -> 2.9722677 | N19: 3.3
D20: 15 | E20: 57 | F20: 3050 | G20: 1.555 | H20: =F20*(G20-1) -> 1692.75 | I20: =SQRT(N20) -> 1.8165902 | J20: =(F20-1)/($F$29-1)*$J$29 -> 0.35445245 | K20: =(F20-1)/($F$29-1)*$K$29 -> 0.035445245 | L20: =SQRT(SQRT(N20)) -> 1.3478094 | M20: =L20*I20*(1+K20*(J20+600%)) -> 2.999887 | N20: 3.3
D21: 16 | E21: 58 | F21: 3203 | G21: 1.57 | H21: =F21*(G21-1) -> 1825.71 | I21: =SQRT(N21) -> 1.8165902 | J21: =(F21-1)/($F$29-1)*$J$29 -> 0.37223901 | K21: =(F21-1)/($F$29-1)*$K$29 -> 0.037223901 | L21: =SQRT(SQRT(N21)) -> 1.3478094 | M21: =L21*I21*(1+K21*(J21+600%)) -> 3.029181 | N21: 3.3
D22: 20 | E22: 62 | F22: 3893 | G22: 1.57 | H22: =F22*(G22-1) -> 2219.01 | I22: =SQRT(N22) -> 1.8973666 | J22: =(F22-1)/($F$29-1)*$J$29 -> 0.45245292 | K22: =(F22-1)/($F$29-1)*$K$29 -> 0.045245292 | L22: =SQRT(SQRT(N22)) -> 1.3774493 | M22: =L22*I22*(1+K22*(J22+600%)) -> 3.3765273 | N22: 3.6
D23: 27 | E23: 69 | F23: 4321 | G23: 1.61 | H23: =F23*(G23-1) -> 2635.81 | I23: =SQRT(N23) -> 1.8973666 | J23: =(F23-1)/($F$29-1)*$J$29 -> 0.50220879 | K23: =(F23-1)/($F$29-1)*$K$29 -> 0.050220879 | L23: =SQRT(SQRT(N23)) -> 1.3774493 | M23: =L23*I23*(1+K23*(J23+600%)) -> 3.4669645 | N23: 3.6
D24: 34 | E24: 74 | F24: 4796 | G24: 1.82 | H24: =F24*(G24-1) -> 3932.72 | I24: =SQRT(N24) -> 1.8973666 | J24: =(F24-1)/($F$29-1)*$J$29 -> 0.5574285 | K24: =(F24-1)/($F$29-1)*$K$29 -> 0.05574285 | L24: =SQRT(SQRT(N24)) -> 1.3774493 | M24: =L24*I24*(1+K24*(J24+600%)) -> 3.5688479 | N24: 3.6
D25: 41 | E25: 79 | F25: 5322 | G25: 1.99 | H25: =F25*(G25-1) -> 5268.78 | I25: =SQRT(N25) -> 2.034699 | J25: =(F25-1)/($F$29-1)*$J$29 -> 0.61857708 | K25: =(F25-1)/($F$29-1)*$K$29 -> 0.061857708 | L25: =SQRT(SQRT(N25)) -> 1.4264288 | M25: =L25*I25*(1+K25*(J25+600%)) -> 4.0906056 | N25: 4.14
D26: 48 | E26: 84 | F26: 5907 | G26: 2 | H26: =F26*(G26-1) -> 5907 | I26: =SQRT(N26) -> 2.034699 | J26: =(F26-1)/($F$29-1)*$J$29 -> 0.68658452 | K26: =(F26-1)/($F$29-1)*$K$29 -> 0.068658452 | L26: =SQRT(SQRT(N26)) -> 1.4264288 | M26: =L26*I26*(1+K26*(J26+600%)) -> 4.234796 | N26: 4.14
D27: 55 | E27: 89 | F27: 6556 | G27: 2 | H27: =F27*(G27-1) -> 6556 | I27: =SQRT(N27) -> 2.034699 | J27: =(F27-1)/($F$29-1)*$J$29 -> 0.76203209 | K27: =(F27-1)/($F$29-1)*$K$29 -> 0.076203209 | L27: =SQRT(SQRT(N27)) -> 1.4264288 | M27: =L27*I27*(1+K27*(J27+600%)) -> 4.3979025 | N27: 4.14
D28: 62 | E28: 91.5 | F28: 7276 | G28: 2 | H28: =F28*(G28-1) -> 7276 | I28: =SQRT(N28) -> 2 | J28: =(F28-1)/($F$29-1)*$J$29 -> 0.84573355 | K28: =(F28-1)/($F$29-1)*$K$29 -> 0.084573355 | L28: =SQRT(SQRT(N28)) -> 1.4142136 | M28: =L28*I28*(1+K28*(J28+600%)) -> 4.4659921 | N28: 4
D29: 90 | E29: 101.5 | F29: 8603 | G29: 2 | H29: =F29*(G29-1) -> 8603 | I29: =SQRT(N29) -> 2.1725561 | J29: 1 | K29: 0.1 | L29: =SQRT(SQRT(N29)) -> 1.4739593 | M29: =L29*I29*(1+K29*(J29+600%)) -> 5.4438409 | N29: 4.72
D30: 120 | E30: 106.85714 | F30: 10294 | G30: 2 | H30: =F30*(G30-1) -> 10294 | I30: =SQRT(N30) -> 2.3323808 | J30: =(F30-1)/($F$29-1)*$J$29 -> 1.1965822 | K30: =K29 -> 0.1 | L30: =SQRT(SQRT(N30)) -> 1.5272134 | M30: =L30*I30*(1+K30*(J30+600%)) -> 6.1254968 | N30: 5.44
D31: 150 | E31: 112.21429 | F31: 12318 | G31: 2 | H31: =F31*(G31-1) -> 12318 | I31: =SQRT(N31) -> 2.3323808 | J31: =(F31-1)/($F$29-1)*$J$29 -> 1.4318763 | K31: =K30 -> 0.1 | L31: =SQRT(SQRT(N31)) -> 1.5272134 | M31: =L31*I31*(1+K31*(J31+600%)) -> 6.2093095 | N31: 5.44
D32: 190 | E32: 119.35714 | F32: 13886 | G32: 2 | H32: =F32*(G32-1) -> 13886 | I32: =SQRT(N32) -> 2.4819347 | J32: =(F32-1)/($F$29-1)*$J$29 -> 1.6141595 | K32: =K31 -> 0.1 | L32: =SQRT(SQRT(N32)) -> 1.5754157 | M32: =L32*I32*(1+K32*(J32+600%)) -> 6.8872755 | N32: 6.16
D33: 250 | E33: 130.07143 | F33: 16620 | G33: 2 | H33: =F33*(G33-1) -> 16620 | I33: =SQRT(N33) -> 2.4819347 | J33: =(F33-1)/($F$29-1)*$J$29 -> 1.9319926 | K33: =K32 -> 0.1 | L33: =SQRT(SQRT(N33)) -> 1.5754157 | M33: =L33*I33*(1+K33*(J33+600%)) -> 7.0115508 | N33: 6.16
D34: 310 | E34: 140.78571 | F34: 19893 | G34: 2 | H34: =F34*(G34-1) -> 19893 | I34: =SQRT(N34) -> 2.6229754 | J34: =(F34-1)/($F$29-1)*$J$29 -> 2.3124855 | K34: =K33 -> 0.1 | L34: =SQRT(SQRT(N34)) -> 1.6195603 | M34: =L34*I34*(1+K34*(J34+600%)) -> 7.779266 | N34: 6.88
D35: 370 | E35: 151.5 | F35: 23810 | G35: 2 | H35: =F35*(G35-1) -> 23810 | I35: =SQRT(N35) -> 2.6229754 | J35: =(F35-1)/($F$29-1)*$J$29 -> 2.7678447 | K35: =K34 -> 0.1 | L35: =SQRT(SQRT(N35)) -> 1.6195603 | M35: =L35*I35*(1+K35*(J35+600%)) -> 7.9727056 | N35: 6.88
D36: 430 | E36: 162.21429 | F36: 28498 | G36: 2 | H36: =F36*(G36-1) -> 28498 | I36: =SQRT(N36) -> 2.7568098 | J36: =(F36-1)/($F$29-1)*$J$29 -> 3.3128342 | K36: =K35 -> 0.1 | L36: =SQRT(SQRT(N36)) -> 1.6603643 | M36: =L36*I36*(1+K36*(J36+600%)) -> 8.8400802 | N36: 7.6
D37: 520 | E37: 178.28571 | F37: 32614 | G37: 2 | H37: =F37*(G37-1) -> 32614 | I37: =SQRT(N37) -> 2.7568098 | J37: =(F37-1)/($F$29-1)*$J$29 -> 3.7913276 | K37: =K36 -> 0.1 | L37: =SQRT(SQRT(N37)) -> 1.6603643 | M37: =L37*I37*(1+K37*(J37+600%)) -> 9.0591014 | N37: 7.6
A41: 本页结束

Sheet 基因升级
A1: 基因升级
C3: 属性规划
D4: #基因属性主要主角部分的养成，对标装备数值 | H4: 17天1w7 | K4: 少部分攻击力有追求
D5: 途径 | E5: 主角攻击力 | G5: 主角伤害加成 | H5: 主角爆伤加成 | I5: 主角暴击加成 | J5: 主角攻速加成 | K5: 攻击力 | L5: 战斗机制 | M5: 汇总
D6: 小节点 | E6: =养成属性!F32 -> 13886 | G6: =养成属性!I32 -> 2.4819347 | H6: =养成属性!J32 -> 1.6141595 | I6: =养成属性!K32 -> 0.1 | J6: =养成属性!L32 -> 1.5754157 | K6: 500 | L6: 30
D7: 中节点
D8: 大节点
D9: 单次加成
D10: 节点数
C12: 效果规划
D14: 基因节点 | E14: 基因效果 | I14: 基因节点 | J14: 基因效果 期望关卡数 | L14: 期望关卡 | M14: 颜色与标识
D15: 1 | E15: 解锁队长武器和技能，咻咻的弹簧锤 | I15: 1 | J15: 解锁队长武器和技能，咻咻的弹簧锤 | M15: 主角武器类
D16: 4 | E16: 主线关卡召唤梦灵次数+1 | I16: 4 | J16: 主线关卡召唤梦灵次数+1 | M16: 关键机制释放
D17: 8 | E17: 梦灵获得自动复活能力，倒下后可自动复活1次 | I17: 8 | J17: 攻击+50 | M17: 属性成长类
D18: 12 | E18: 梦灵复活时可以击退敌人 | I18: 12 | J18: 梦灵获得自动复活能力，倒下后可自动复活1次
D19: 16 | E19: 怪物靠近主角时，立即释放弹簧锤击退怪物 | I19: 16 | J19: 攻击+50
D20: 20 | E20: 梦灵复活血量增加20% | I20: 20 | J20: 弹簧锤数量+1，伤害-20% | N20: 梦灵复活时可以击退敌人
D21: 24 | E21: 主线关卡召唤梦灵次数+1 | I21: 24 | J21: 主线关卡召唤梦灵次数+1 | N21: 梦灵复活血量增加20%
D22: 28 | E22: 弹簧锤数量+1，伤害-20% | I22: 28 | J22: 攻击+60 | N22: 梦灵复活时可以击退敌人更远
D23: 32 | E23: 弹簧锤体积+15% | I23: 32 | J23: 弹簧锤体积+15% | N23: 梦灵复活次数+1
D24: 36 | E24: 梦灵复活时可以击退敌人更远 | I24: 36 | N24: 梦灵复活血量增加20%
D25: 40 | E25: 攻击+40 | I25: 40 | J25: 攻击+60 | N25: 梦灵复活时可以击退敌人更远
D26: 44 | E26: 弹簧锤连发+1，伤害-20% | I26: 44 | J26: 怪物靠近主角时，立即释放弹簧锤击退怪物
D27: 48 | E27: 梦灵复活次数+1 | I27: 48
D28: 52 | E28: 咻咻的弹簧锤10%几率眩晕怪物2秒 | I28: 52 | J28: 攻击+70
D29: 56 | E29: 梦灵复活血量增加20% | I29: 56 | J29: 弹簧锤连发+1，伤害-20%
D30: 60 | E30: 首次有梦灵血量低于50%时，立即释放一次弹簧锤击退怪物 | I30: 60
D31: 64 | E31: 攻击+45 | I31: 64 | J31: 攻击+70
D32: 68 | E32: 弹簧锤数量增加不再减少伤害 | I32: 68 | J32: 咻咻的弹簧锤10%几率眩晕怪物2秒
D33: 72 | E33: 攻击+45 | I33: 72
D34: 76 | E34: 首次有梦灵血量低于25%时，立即释放一次弹簧锤击退怪物 | I34: 76 | J34: 攻击+80
D35: 80 | E35: 梦灵复活时可以击退敌人更远 | I35: 80 | J35: 首次有梦灵血量低于50%时，立即释放一次弹簧锤击退怪物
D36: 84 | E36: 弹簧锤连发不再减少伤害 | I36: 84
D37: 88 | E37: 攻击+45 | I37: 88 | J37: 攻击+80
D38: 92 | E38: 弹簧锤体积+15% | I38: 92 | J38: 弹簧锤数量增加不再减少伤害
D39: 96 | E39: 攻击+50 | I39: 96
D40: 100 | E40: 弹簧锤伤害+20% | I40: 100 | J40: 攻击+90
D41: 104 | E41: 攻击+50 | I41: 104 | J41: 首次有梦灵血量低于25%时，立即释放一次弹簧锤击退怪物
D42: 108 | E42: 弹簧锤体积+20% | I42: 108
D43: 112 | E43: 攻击+55 | I43: 112 | J43: 攻击+90
...

Sheet 基因产出
A1: 设计思路
C3: 产出规划
D5: 道具 | E5: 来源 | F5: 周期 | G5: 是否分层
D6: 基因罐 | E6: 体力 | F6: 每日 | G6: 竞速
E7: 首通奖励（三星） | F7: 一次性 | G7: 无差异
E8: 竞技场商店 | F8: 每日 | G8: 无差异
D12: 加速卡 | E12: 日常任务 | F12: 每日 | G12: 无差异
E13: 首通奖励（一星） | F13: 一次性 | G13: 无差异
E14: 每周任务 | F14: 每周 | G14: 无差异
E15: 运营活动 | F15: 每日 | G15: 对标体力产的差异 | H15: #预留填充物
D18: 高级基因罐 | E18: 首通奖励（三星） | F18: 一次性 | G18: 无差异 | H18: #每五关的三星奖励
C22: 基因罐产出
D24: 体力产出
D25: 次数 | E25: 基因罐 | F25: 非R | G25: 小R | H25: 中R | I25: 大R
D26: 1 | E26: 5 | F26: =H34/10 -> 40 | G26: =H35/10 -> 41 | H26: =H38/10 -> 46 | I26: =H41/10 -> 71.285714
D29: 途径 | E29: 每日次数 | F29: 单次体力 | G29: 单项体力 | H29: 累计体力 | I29: 钻石价格 | J29: rmb价格 | K29: 定位 | L29: 额外说明 汇总
D30: 创号初始 | E30: 0 | F30: 60 | I30: 0 | K30: 全体
D31: 时间恢复 | E31: =10*24 -> 240 | F31: 1 | G31: =E31*F31 -> 240 | H31: =G31 -> 240 | I31: 0 | K31: 全体
D32: 每日广告 | E32: 3 | F32: 10 | G32: =E32*F32 -> 30 | H32: =G32+H31 -> 270 | I32: 0 | K32: 全体
D33: 食堂奖励 | E33: 4 | F33: 30 | G33: =E33*F33 -> 120 | H33: =G33+H32 -> 390 | I33: 0 | K33: 全体
D34: 日礼包免费 | E34: 1 | F34: 10 | G34: =E34*F34 -> 10 | H34: =G34+H33 -> 400 | I34: 0 | K34: 全体
D35: 月卡福利 | E35: 1 | F35: 10 | G35: =E35*F35 -> 10 | H35: =G35+H34 -> 410 | J35: 1 | K35: 小R
D36: 每日特惠礼包1 | E36: 1 | F36: 10 | G36: =E36*F36 -> 10 | H36: =G36+H35 -> 420 | J36: 1 | K36: 小R | L36: 预留给小R
D37: 每日特惠礼包2 | E37: 1 | F37: 15 | G37: =E37*F37 -> 15 | H37: =G37+H36 -> 435 | J37: 6 | K37: 小R | L37: 预留给小R
D38: 每日特惠礼包3 | E38: 1 | F38: 25 | G38: =E38*F38 -> 25 | H38: =G38+H37 -> 460 | J38: 18 | K38: 小R | L38: 预留给小R
D39: 日礼包购买 | E39: 1 | F39: 60 | G39: =E39*F39 -> 60 | H39: =G39+H38 -> 520 | I39: 96 | K39: 中R
D40: 周礼包购买 | E40: =1/7 -> 0.14285714 | F40: =60*5 -> 300 | G40: =E40*F40 -> 42.857143 | H40: =G40+H39 -> 562.85714 | I40: =84*5 -> 420 | K40: 中R | L40: 每周1次
D41: 宝石购买 | E41: 5 | F41: 30 | G41: =E41*F41 -> 150 | H41: =G41+H40 -> 712.85714 | I41: 60 | K41: 大R
D44: 主线
D45: 次数 | E45: 基因罐
D46: 1 | E46: 30 | G46: =E26*F26 -> 200
C49: 加速卡产出
D51: #核心从运营活动做分层，保证运营活动拿满=基本没有加速时间上的缺口，非SLG体验不在加速上做大额付费，意义不大
D54: 日常任务 | G54: 加速花费/h
D55: 周期 | E55: 1小时加速 | G55: 钻石
D56: 1 | E56: 0 | G56: 20
D57: 7 | E57: 0
D59: 主线
D60: 次数 | E60: 1小时加速
D61: 1 | E61: 0
...

Sheet 属性汇总
A2: #目前只计算双月卡玩家进度，后续等数值总表一起拓展
A6: 开服天数 | B6: 基因等级练度 | C6: 攻击 | D6: 生命 | E6: 攻击百分比 | F6: 生命百分比 | G6: 暴击 | H6: 爆伤 | I6: 伤害增加 | J6: 伤害减免 | K6: 主角攻击力 | L6: 主角伤害加成 | M6: 主角爆伤加成 | N6: 主角暴击加成 | O6: 主角攻速加成 | R6: 基因等级 | S6: 攻击力 | T6: 主角攻击力 | U6: 主角伤害加成 | V6: 主角爆伤加成 | W6: 主角暴击加成 | X6: 主角攻速加成
A7: 1 | B7: =IFERROR(_xlfn.XLOOKUP(A7+1,基因升级!$E$141:$E$500,基因升级!$D$141:$D$500)-1,B6) -> 15 | C7: =SUMIF(基因升级!$D$141:$D$500,"<"&$B7,基因升级!$U$141:$U$500) -> 0 | K7: =SUMIF(基因升级!$D$141:$D$500,"<"&$B7,基因升级!J$141:J$500) -> 120 | L7: =SUMIF(基因升级!$D$141:$D$500,"<"&$B7,基因升级!K$141:K$500) -> 0.2 | M7: =SUMIF(基因升级!$D$141:$D$500,"<"&$B7,基因升级!L$141:L$500) -> 0.09 | N7: =SUMIF(基因升级!$D$141:$D$500,"<"&$B7,基因升级!M$141:M$500) -> 0.006 | O7: =SUMIF(基因升级!$D$141:$D$500,"<"&$B7,基因升级!N$141:N$500) -> 0.03 | R7: 1 | S7: =SUMIF(基因升级!$D$141:$D$500,"<="&$R7,基因升级!$U$141:$U$500) -> 0 | T7: =SUMIF(基因升级!$D$141:$D$500,"<="&$R7,基因升级!J$141:J$500) -> 6 | U7: =SUMIF(基因升级!$D$141:$D$500,"<="&$R7,基因升级!K$141:K$500) -> 0.05 | V7: =SUMIF(基因升级!$D$141:$D$500,"<="&$R7,基因升级!L$141:L$500) -> 0 | W7: =SUMIF(基因升级!$D$141:$D$500,"<="&$R7,基因升级!M$141:M$500) -> 0 | X7: =SUMIF(基因升级!$D$141:$D$500,"<="&$R7,基因升级!N$141:N$500) -> 0
A8: 2 | B8: =IFERROR(_xlfn.XLOOKUP(A8+1,基因升级!$E$141:$E$500,基因升级!$D$141:$D$500)-1,B7) -> 19 | C8: =SUMIF(基因升级!$D$141:$D$500,"<"&$B8,基因升级!$U$141:$U$500) -> 0 | K8: =SUMIF(基因升级!$D$141:$D$500,"<"&$B8,基因升级!J$141:J$500) -> 180 | L8: =SUMIF(基因升级!$D$141:$D$500,"<"&$B8,基因升级!K$141:K$500) -> 0.25 | M8: =SUMIF(基因升级!$D$141:$D$500,"<"&$B8,基因升级!L$141:L$500) -> 0.12 | N8: =SUMIF(基因升级!$D$141:$D$500,"<"&$B8,基因升级!M$141:M$500) -> 0.008 | O8: =SUMIF(基因升级!$D$141:$D$500,"<"&$B8,基因升级!N$141:N$500) -> 0.0375 | R8: 2 | S8: =SUMIF(基因升级!$D$141:$D$500,"<="&$R8,基因升级!$U$141:$U$500) -> 0 | T8: =SUMIF(基因升级!$D$141:$D$500,"<="&$R8,基因升级!J$141:J$500) -> 12 | U8: =SUMIF(基因升级!$D$141:$D$500,"<="&$R8,基因升级!K$141:K$500) -> 0.05 | V8: =SUMIF(基因升级!$D$141:$D$500,"<="&$R8,基因升级!L$141:L$500) -> 0 | W8: =SUMIF(基因升级!$D$141:$D$500,"<="&$R8,基因升级!M$141:M$500) -> 0 | X8: =SUMIF(基因升级!$D$141:$D$500,"<="&$R8,基因升级!N$141:N$500) -> 0.0075
A9: 3 | B9: =IFERROR(_xlfn.XLOOKUP(A9+1,基因升级!$E$141:$E$500,基因升级!$D$141:$D$500)-1,B8) -> 22 | C9: =SUMIF(基因升级!$D$141:$D$500,"<"&$B9,基因升级!$U$141:$U$500) -> 0 | K9: =SUMIF(基因升级!$D$141:$D$500,"<"&$B9,基因升级!J$141:J$500) -> 234 | L9: =SUMIF(基因升级!$D$141:$D$500,"<"&$B9,基因升级!K$141:K$500) -> 0.3 | M9: =SUMIF(基因升级!$D$141:$D$500,"<"&$B9,基因升级!L$141:L$500) -> 0.15 | N9: =SUMIF(基因升级!$D$141:$D$500,"<"&$B9,基因升级!M$141:M$500) -> 0.01 | O9: =SUMIF(基因升级!$D$141:$D$500,"<"&$B9,基因升级!N$141:N$500) -> 0.0375 | R9: 3 | S9: =SUMIF(基因升级!$D$141:$D$500,"<="&$R9,基因升级!$U$141:$U$500) -> 0 | T9: =SUMIF(基因升级!$D$141:$D$500,"<="&$R9,基因升级!J$141:J$500) -> 18 | U9: =SUMIF(基因升级!$D$141:$D$500,"<="&$R9,基因升级!K$141:K$500) -> 0.05 | V9: =SUMIF(基因升级!$D$141:$D$500,"<="&$R9,基因升级!L$141:L$500) -> 0 | W9: =SUMIF(基因升级!$D$141:$D$500,"<="&$R9,基因升级!M$141:M$500) -> 0.002 | X9: =SUMIF(基因升级!$D$141:$D$500,"<="&$R9,基因升级!N$141:N$500) -> 0.0075
A10: 4 | B10: =IFERROR(_xlfn.XLOOKUP(A10+1,基因升级!$E$141:$E$500,基因升级!$D$141:$D$500)-1,B9) -> 25 | C10: =SUMIF(基因升级!$D$141:$D$500,"<"&$B10,基因升级!$U$141:$U$500) -> 0 | K10: =SUMIF(基因升级!$D$141:$D$500,"<"&$B10,基因升级!J$141:J$500) -> 288 | L10: =SUMIF(基因升级!$D$141:$D$500,"<"&$B10,基因升级!K$141:K$500) -> 0.3 | M10: =SUMIF(基因升级!$D$141:$D$500,"<"&$B10,基因升级!L$141:L$500) -> 0.18 | N10: =SUMIF(基因升级!$D$141:$D$500,"<"&$B10,基因升级!M$141:M$500) -> 0.012 | O10: =SUMIF(基因升级!$D$141:$D$500,"<"&$B10,基因升级!N$141:N$500) -> 0.045 | R10: 4 | S10: =SUMIF(基因升级!$D$141:$D$500,"<="&$R10,基因升级!$U$141:$U$500) -> 0 | T10: =SUMIF(基因升级!$D$141:$D$500,"<="&$R10,基因升级!J$141:J$500) -> 24 | U10: =SUMIF(基因升级!$D$141:$D$500,"<="&$R10,基因升级!K$141:K$500) -> 0.05 | V10: =SUMIF(基因升级!$D$141:$D$500,"<="&$R10,基因升级!L$141:L$500) -> 0.03 | W10: =SUMIF(基因升级!$D$141:$D$500,"<="&$R10,基因升级!M$141:M$500) -> 0.002 | X10: =SUMIF(基因升级!$D$141:$D$500,"<="&$R10,基因升级!N$141:N$500) -> 0.0075
A11: 5 | B11: =IFERROR(_xlfn.XLOOKUP(A11+1,基因升级!$E$141:$E$500,基因升级!$D$141:$D$500)-1,B10) -> 27 | C11: =SUMIF(基因升级!$D$141:$D$500,"<"&$B11,基因升级!$U$141:$U$500) -> 0 | K11: =SUMIF(基因升级!$D$141:$D$500,"<"&$B11,基因升级!J$141:J$500) -> 336 | L11: =SUMIF(基因升级!$D$141:$D$500,"<"&$B11,基因升级!K$141:K$500) -> 0.35 | M11: =SUMIF(基因升级!$D$141:$D$500,"<"&$B11,基因升级!L$141:L$500) -> 0.18 | N11: =SUMIF(基因升级!$D$141:$D$500,"<"&$B11,基因升级!M$141:M$500) -> 0.012 | O11: =SUMIF(基因升级!$D$141:$D$500,"<"&$B11,基因升级!N$141:N$500) -> 0.0525 | R11: 5 | S11: =SUMIF(基因升级!$D$141:$D$500,"<="&$R11,基因升级!$U$141:$U$500) -> 0 | T11: =SUMIF(基因升级!$D$141:$D$500,"<="&$R11,基因升级!J$141:J$500) -> 30 | U11: =SUMIF(基因升级!$D$141:$D$500,"<="&$R11,基因升级!K$141:K$500) -> 0.1 | V11: =SUMIF(基因升级!$D$141:$D$500,"<="&$R11,基因升级!L$141:L$500) -> 0.03 | W11: =SUMIF(基因升级!$D$141:$D$500,"<="&$R11,基因升级!M$141:M$500) -> 0.002 | X11: =SUMIF(基因升级!$D$141:$D$500,"<="&$R11,基因升级!N$141:N$500) -> 0.0075
A12: 6 | B12: =IFERROR(_xlfn.XLOOKUP(A12+1,基因升级!$E$141:$E$500,基因升级!$D$141:$D$500)-1,B11) -> 29 | C12: =SUMIF(基因升级!$D$141:$D$500,"<"&$B12,基因升级!$U$141:$U$500) -> 0 | K12: =SUMIF(基因升级!$D$141:$D$500,"<"&$B12,基因升级!J$141:J$500) -> 384 | L12: =SUMIF(基因升级!$D$141:$D$500,"<"&$B12,基因升级!K$141:K$500) -> 0.35 | M12: =SUMIF(基因升级!$D$141:$D$500,"<"&$B12,基因升级!L$141:L$500) -> 0.21 | N12: =SUMIF(基因升级!$D$141:$D$500,"<"&$B12,基因升级!M$141:M$500) -> 0.014 | O12: =SUMIF(基因升级!$D$141:$D$500,"<"&$B12,基因升级!N$141:N$500) -> 0.0525 | R12: 6 | S12: =SUMIF(基因升级!$D$141:$D$500,"<="&$R12,基因升级!$U$141:$U$500) -> 0 | T12: =SUMIF(基因升级!$D$141:$D$500,"<="&$R12,基因升级!J$141:J$500) -> 36 | U12: =SUMIF(基因升级!$D$141:$D$500,"<="&$R12,基因升级!K$141:K$500) -> 0.1 | V12: =SUMIF(基因升级!$D$141:$D$500,"<="&$R12,基因升级!L$141:L$500) -> 0.03 | W12: =SUMIF(基因升级!$D$141:$D$500,"<="&$R12,基因升级!M$141:M$500) -> 0.002 | X12: =SUMIF(基因升级!$D$141:$D$500,"<="&$R12,基因升级!N$141:N$500) -> 0.015
A13: 7 | B13: =IFERROR(_xlfn.XLOOKUP(A13+1,基因升级!$E$141:$E$500,基因升级!$D$141:$D$500)-1,B12) -> 30 | C13: =SUMIF(基因升级!$D$141:$D$500,"<"&$B13,基因升级!$U$141:$U$500) -> 0 | K13: =SUMIF(基因升级!$D$141:$D$500,"<"&$B13,基因升级!J$141:J$500) -> 408 | L13: =SUMIF(基因升级!$D$141:$D$500,"<"&$B13,基因升级!K$141:K$500) -> 0.4 | M13: =SUMIF(基因升级!$D$141:$D$500,"<"&$B13,基因升级!L$141:L$500) -> 0.21 | N13: =SUMIF(基因升级!$D$141:$D$500,"<"&$B13,基因升级!M$141:M$500) -> 0.014 | O13: =SUMIF(基因升级!$D$141:$D$500,"<"&$B13,基因升级!N$141:N$500) -> 0.0525 | R13: 7 | S13: =SUMIF(基因升级!$D$141:$D$500,"<="&$R13,基因升级!$U$141:$U$500) -> 0 | T13: =SUMIF(基因升级!$D$141:$D$500,"<="&$R13,基因升级!J$141:J$500) -> 42 | U13: =SUMIF(基因升级!$D$141:$D$500,"<="&$R13,基因升级!K$141:K$500) -> 0.1 | V13: =SUMIF(基因升级!$D$141:$D$500,"<="&$R13,基因升级!L$141:L$500) -> 0.03 | W13: =SUMIF(基因升级!$D$141:$D$500,"<="&$R13,基因升级!M$141:M$500) -> 0.004 | X13: =SUMIF(基因升级!$D$141:$D$500,"<="&$R13,基因升级!N$141:N$500) -> 0.015
A14: 8 | B14: =IFERROR(_xlfn.XLOOKUP(A14+1,基因升级!$E$141:$E$500,基因升级!$D$141:$D$500)-1,B13) -> 32 | C14: =SUMIF(基因升级!$D$141:$D$500,"<"&$B14,基因升级!$U$141:$U$500) -> 0 | K14: =SUMIF(基因升级!$D$141:$D$500,"<"&$B14,基因升级!J$141:J$500) -> 456 | L14: =SUMIF(基因升级!$D$141:$D$500,"<"&$B14,基因升级!K$141:K$500) -> 0.4 | M14: =SUMIF(基因升级!$D$141:$D$500,"<"&$B14,基因升级!L$141:L$500) -> 0.21 | N14: =SUMIF(基因升级!$D$141:$D$500,"<"&$B14,基因升级!M$141:M$500) -> 0.016 | O14: =SUMIF(基因升级!$D$141:$D$500,"<"&$B14,基因升级!N$141:N$500) -> 0.06 | R14: 8 | S14: =SUMIF(基因升级!$D$141:$D$500,"<="&$R14,基因升级!$U$141:$U$500) -> 0 | T14: =SUMIF(基因升级!$D$141:$D$500,"<="&$R14,基因升级!J$141:J$500) -> 48 | U14: =SUMIF(基因升级!$D$141:$D$500,"<="&$R14,基因升级!K$141:K$500) -> 0.1 | V14: =SUMIF(基因升级!$D$141:$D$500,"<="&$R14,基因升级!L$141:L$500) -> 0.06 | W14: =SUMIF(基因升级!$D$141:$D$500,"<="&$R14,基因升级!M$141:M$500) -> 0.004 | X14: =SUMIF(基因升级!$D$141:$D$500,"<="&$R14,基因升级!N$141:N$500) -> 0.015
A15: 9 | B15: =IFERROR(_xlfn.XLOOKUP(A15+1,基因升级!$E$141:$E$500,基因升级!$D$141:$D$500)-1,B14) -> 33 | C15: =SUMIF(基因升级!$D$141:$D$500,"<"&$B15,基因升级!$U$141:$U$500) -> 0 | K15: =SUMIF(基因升级!$D$141:$D$500,"<"&$B15,基因升级!J$141:J$500) -> 480 | L15: =SUMIF(基因升级!$D$141:$D$500,"<"&$B15,基因升级!K$141:K$500) -> 0.4 | M15: =SUMIF(基因升级!$D$141:$D$500,"<"&$B15,基因升级!L$141:L$500) -> 0.24 | N15: =SUMIF(基因升级!$D$141:$D$500,"<"&$B15,基因升级!M$141:M$500) -> 0.016 | O15: =SUMIF(基因升级!$D$141:$D$500,"<"&$B15,基因升级!N$141:N$500) -> 0.06 | R15: 9 | S15: =SUMIF(基因升级!$D$141:$D$500,"<="&$R15,基因升级!$U$141:$U$500) -> 0 | T15: =SUMIF(基因升级!$D$141:$D$500,"<="&$R15,基因升级!J$141:J$500) -> 60 | U15: =SUMIF(基因升级!$D$141:$D$500,"<="&$R15,基因升级!K$141:K$500) -> 0.15 | V15: =SUMIF(基因升级!$D$141:$D$500,"<="&$R15,基因升级!L$141:L$500) -> 0.06 | W15: =SUMIF(基因升级!$D$141:$D$500,"<="&$R15,基因升级!M$141:M$500) -> 0.004 | X15: =SUMIF(基因升级!$D$141:$D$500,"<="&$R15,基因升级!N$141:N$500) -> 0.015
A16: 10 | B16: =IFERROR(_xlfn.XLOOKUP(A16+1,基因升级!$E$141:$E$500,基因升级!$D$141:$D$500)-1,B15) -> 34 | C16: =SUMIF(基因升级!$D$141:$D$500,"<"&$B16,基因升级!$U$141:$U$500) -> 0 | K16: =SUMIF(基因升级!$D$141:$D$500,"<"&$B16,基因升级!J$141:J$500) -> 510 | L16: =SUMIF(基因升级!$D$141:$D$500,"<"&$B16,基因升级!K$141:K$500) -> 0.45 | M16: =SUMIF(基因升级!$D$141:$D$500,"<"&$B16,基因升级!L$141:L$500) -> 0.24 | N16: =SUMIF(基因升级!$D$141:$D$500,"<"&$B16,基因升级!M$141:M$500) -> 0.016 | O16: =SUMIF(基因升级!$D$141:$D$500,"<"&$B16,基因升级!N$141:N$500) -> 0.06 | R16: 10 | S16: =SUMIF(基因升级!$D$141:$D$500,"<="&$R16,基因升级!$U$141:$U$500) -> 0 | T16: =SUMIF(基因升级!$D$141:$D$500,"<="&$R16,基因升级!J$141:J$500) -> 72 | U16: =SUMIF(基因升级!$D$141:$D$500,"<="&$R16,基因升级!K$141:K$500) -> 0.15 | V16: =SUMIF(基因升级!$D$141:$D$500,"<="&$R16,基因升级!L$141:L$500) -> 0.06 | W16: =SUMIF(基因升级!$D$141:$D$500,"<="&$R16,基因升级!M$141:M$500) -> 0.004 | X16: =SUMIF(基因升级!$D$141:$D$500,"<="&$R16,基因升级!N$141:N$500) -> 0.0225
A17: 11 | B17: =IFERROR(_xlfn.XLOOKUP(A17+1,基因升级!$E$141:$E$500,基因升级!$D$141:$D$500)-1,B16) -> 36 | C17: =SUMIF(基因升级!$D$141:$D$500,"<"&$B17,基因升级!$U$141:$U$500) -> 0 | K17: =SUMIF(基因升级!$D$141:$D$500,"<"&$B17,基因升级!J$141:J$500) -> 570 | L17: =SUMIF(基因升级!$D$141:$D$500,"<"&$B17,基因升级!K$141:K$500) -> 0.45 | M17: =SUMIF(基因升级!$D$141:$D$500,"<"&$B17,基因升级!L$141:L$500) -> 0.24 | N17: =SUMIF(基因升级!$D$141:$D$500,"<"&$B17,基因升级!M$141:M$500) -> 0.018 | O17: =SUMIF(基因升级!$D$141:$D$500,"<"&$B17,基因升级!N$141:N$500) -> 0.0675 | R17: 11 | S17: =SUMIF(基因升级!$D$141:$D$500,"<="&$R17,基因升级!$U$141:$U$500) -> 0 | T17: =SUMIF(基因升级!$D$141:$D$500,"<="&$R17,基因升级!J$141:J$500) -> 84 | U17: =SUMIF(基因升级!$D$141:$D$500,"<="&$R17,基因升级!K$141:K$500) -> 0.15 | V17: =SUMIF(基因升级!$D$141:$D$500,"<="&$R17,基因升级!L$141:L$500) -> 0.06 | W17: =SUMIF(基因升级!$D$141:$D$500,"<="&$R17,基因升级!M$141:M$500) -> 0.006 | X17: =SUMIF(基因升级!$D$141:$D$500,"<="&$R17,基因升级!N$141:N$500) -> 0.0225
A18: 12 | B18: =IFERROR(_xlfn.XLOOKUP(A18+1,基因升级!$E$141:$E$500,基因升级!$D$141:$D$500)-1,B17) -> 37 | C18: =SUMIF(基因升级!$D$141:$D$500,"<"&$B18,基因升级!$U$141:$U$500) -> 0 | K18: =SUMIF(基因升级!$D$141:$D$500,"<"&$B18,基因升级!J$141:J$500) -> 600 | L18: =SUMIF(基因升级!$D$141:$D$500,"<"&$B18,基因升级!K$141:K$500) -> 0.45 | M18: =SUMIF(基因升级!$D$141:$D$500,"<"&$B18,基因升级!L$141:L$500) -> 0.27 | N18: =SUMIF(基因升级!$D$141:$D$500,"<"&$B18,基因升级!M$141:M$500) -> 0.018 | O18: =SUMIF(基因升级!$D$141:$D$500,"<"&$B18,基因升级!N$141:N$500) -> 0.0675 | R18: 12 | S18: =SUMIF(基因升级!$D$141:$D$500,"<="&$R18,基因升级!$U$141:$U$500) -> 0 | T18: =SUMIF(基因升级!$D$141:$D$500,"<="&$R18,基因升级!J$141:J$500) -> 96 | U18: =SUMIF(基因升级!$D$141:$D$500,"<="&$R18,基因升级!K$141:K$500) -> 0.15 | V18: =SUMIF(基因升级!$D$141:$D$500,"<="&$R18,基因升级!L$141:L$500) -> 0.09 | W18: =SUMIF(基因升级!$D$141:$D$500,"<="&$R18,基因升级!M$141:M$500) -> 0.006 | X18: =SUMIF(基因升级!$D$141:$D$500,"<="&$R18,基因升级!N$141:N$500) -> 0.0225
... A306: 300 | B306: =IFERROR(_xlfn.XLOOKUP(A306+1,基因升级!$E$141:$E$500,基因升级!$D$141:$D$500)-1,B305) -> 100 | C306: =SUMIF(基因升级!$D$141:$D$500,"<"&$B306,基因升级!$U$141:$U$500) -> 0 | K306: =SUMIF(基因升级!$D$141:$D$500,"<"&$B306,基因升级!J$141:J$500) -> 3924 | L306: =SUMIF(基因升级!$D$141:$D$500,"<"&$B306,基因升级!K$141:K$500) -> 1.25 | M306: =SUMIF(基因升级!$D$141:$D$500,"<"&$B306,基因升级!L$141:L$500) -> 0.72 | N306: =SUMIF(基因升级!$D$141:$D$500,"<"&$B306,基因升级!M$141:M$500) -> 0.05 | O306: =SUMIF(基因升级!$D$141:$D$500,"<"&$B306,基因升级!N$141:N$500) -> 0.1875 | R306: 300 | S306: =SUMIF(基因升级!$D$141:$D$500,"<="&$R306,基因升级!$U$141:$U$500) -> 0 | T306: =SUMIF(基因升级!$D$141:$D$500,"<="&$R306,基因升级!J$141:J$500) -> 27870 | U306: =SUMIF(基因升级!$D$141:$D$500,"<="&$R306,基因升级!K$141:K$500) -> 3.75 | V306: =SUMIF(基因升级!$D$141:$D$500,"<="&$R306,基因升级!L$141:L$500) -> 2.25 | W306: =SUMIF(基因升级!$D$141:$D$500,"<="&$R306,基因升级!M$141:M$500) -> 0.15 | X306: =SUMIF(基因升级!$D$141:$D$500,"<="&$R306,基因升级!N$141:N$500) -> 0.5625

Sheet 蔚蓝参考
M1: =COUNTA(M5:M202) -> 95
B2: 节点 | C2: 国王攻击力 | D2: 国王伤害% | E2: 国王暴击率 | F2: 国王爆伤 | G2: 国王攻击速度 | H2: 特殊解锁 | I2: 天赋石 | J2: 金币 | K2: 大节点 | L2: 攻击力 | M2: 核心加成 | N2: 传说天赋石 | O2: 金币2
B3: 1 | H3: 国王斩击 | I3: / | J3: / | O3: =IF(L3&M3="","",J3*5)
B4: =B3+1 -> 2 | C4: 6 | D4: 0.05 | I4: 10 | J4: 220 | O4: =IF(L4&M4="","",J4*5)
B5: =B4+1 -> 3 | C5: 6 | E5: 0.005 | I5: 15 | J5: =J6-140 -> 320 | O5: =IF(L5&M5="","",J5*5)
B6: =B5+1 -> 4 | C6: 6 | F6: 0.02 | I6: 20 | J6: =J7-140 -> 460 | O6: =IF(L6&M6="","",J6*5)
B7: =B6+1 -> 5 | C7: 6 | G7: 0.01 | I7: 25 | J7: =J8-140 -> 600 | M7: 剑气击退 | N7: 3 | O7: =IF(L7&M7="","",J7*5) -> 3000
B8: =B7+1 -> 6 | C8: 8 | D8: 0.05 | I8: 30 | J8: =J9-140 -> 740 | O8: =IF(L8&M8="","",J8*5) | S8: 剑气击退
B9: =B8+1 -> 7 | C9: 8 | E9: 0.005 | I9: 35 | J9: =J10-140 -> 880 | O9: =IF(L9&M9="","",J9*5) | S9: 增加剑气，-20%伤害
B10: =B9+1 -> 8 | C10: 8 | F10: 0.02 | I10: 40 | J10: =J11-140 -> 1020 | O10: =IF(L10&M10="","",J10*5) | S10: 剑气体积+15%
B11: =B10+1 -> 9 | C11: 8 | G11: 0.01 | I11: 45 | J11: =J12-140 -> 1160 | L11: 40 | N11: 3 | O11: =IF(L11&M11="","",J11*5) -> 5800 | S11: 低于75%血量释放一次击退
B12: =B11+1 -> 10 | C12: 12 | D12: 0.05 | I12: 50 | J12: =J13-140 -> 1300 | O12: =IF(L12&M12="","",J12*5) | S12: 连发
B13: =B12+1 -> 11 | C13: 12 | E13: 0.005 | I13: 55 | J13: =J14-140 -> 1440 | O13: =IF(L13&M13="","",J13*5) | S13: 巨剑眩晕
B14: =B13+1 -> 12 | C14: 12 | F14: 0.02 | I14: 60 | J14: =J15-140 -> 1580 | O14: =IF(L14&M14="","",J14*5) | S14: 低于50%血量释放一次击退
B15: =B14+1 -> 13 | C15: 12 | G15: 0.01 | I15: 65 | J15: =J16-140 -> 1720 | O15: =IF(L15&M15="","",J15*5) | S15: 不减少国王伤害
B16: =B15+1 -> 14 | C16: 12 | D16: 0.05 | I16: 70 | J16: =J17-140 -> 1860 | O16: =IF(L16&M16="","",J16*5) | S16: 低于25%血量释放一次击退
B17: =B16+1 -> 15 | C17: 12 | E17: 0.005 | I17: 75 | J17: =J18-140 -> 2000 | M17: 增加剑气，-20%伤害 | N17: 3 | O17: =IF(L17&M17="","",J17*5) -> 10000 | S17: 剑气连发不再减少伤害
B18: =B17+1 -> 16 | C18: 16 | F18: 0.02 | I18: 80 | J18: =J19-140 -> 2140 | O18: =IF(L18&M18="","",J18*5) | S18: 再加一道剑气
B19: =B18+1 -> 17 | C19: 16 | G19: 0.01 | I19: 85 | J19: =J20-140 -> 2280 | O19: =IF(L19&M19="","",J19*5) | S19: 剑气体积+20%
B20: =B19+1 -> 18 | C20: 16 | D20: 0.05 | I20: 90 | J20: =J21-275 -> 2420 | O20: =IF(L20&M20="","",J20*5) | S20: 剑气连发+1
B21: =B20+1 -> 19 | C21: 16 | E21: 0.005 | I21: 100 | J21: =J22-275 -> 2695 | O21: =IF(L21&M21="","",J21*5)
B22: =B21+1 -> 20 | C22: 16 | F22: 0.02 | I22: 110 | J22: =J23-275 -> 2970 | L22: 40 | N22: 6 | O22: =IF(L22&M22="","",J22*5) -> 14850
B23: =B22+1 -> 21 | C23: 20 | G23: 0.01 | I23: 120 | J23: =J24-275 -> 3245 | O23: =IF(L23&M23="","",J23*5)
B24: =B23+1 -> 22 | C24: 20 | D24: =IF(D20="","",D20) -> 0.05 | E24: =IF(E20="","",E20) | F24: =IF(F20="","",F20) | G24: =IF(G20="","",G20) | I24: 130 | J24: =J25-275 -> 3520 | O24: =IF(L24&M24="","",J24*5)
B25: =B24+1 -> 23 | C25: 20 | D25: =IF(D21="","",D21) | E25: =IF(E21="","",E21) -> 0.005 | F25: =IF(F21="","",F21) | G25: =IF(G21="","",G21) | I25: 140 | J25: =J26-275 -> 3795 | O25: =IF(L25&M25="","",J25*5)
B26: =B25+1 -> 24 | C26: 20 | D26: =IF(D22="","",D22) | E26: =IF(E22="","",E22) | F26: =IF(F22="","",F22) -> 0.02 | G26: =IF(G22="","",G22) | I26: 150 | J26: =J27-275 -> 4070 | O26: =IF(L26&M26="","",J26*5)
B27: =B26+1 -> 25 | C27: 20 | D27: =IF(D23="","",D23) | E27: =IF(E23="","",E23) | F27: =IF(F23="","",F23) | G27: =IF(G23="","",G23) -> 0.01 | I27: 160 | J27: =J28-275 -> 4345 | M27: 剑气体积+15% | N27: 6 | O27: =IF(L27&M27="","",J27*5) -> 21725
B28: =B27+1 -> 26 | C28: 24 | D28: =IF(D24="","",D24) -> 0.05 | E28: =IF(E24="","",E24) | F28: =IF(F24="","",F24) | G28: =IF(G24="","",G24) | I28: 170 | J28: =J29-275 -> 4620 | O28: =IF(L28&M28="","",J28*5)
B29: =B28+1 -> 27 | C29: 24 | D29: =IF(D25="","",D25) | E29: =IF(E25="","",E25) -> 0.005 | F29: =IF(F25="","",F25) | G29: =IF(G25="","",G25) | I29: 180 | J29: =J30-275 -> 4895 | O29: =IF(L29&M29="","",J29*5)
B30: =B29+1 -> 28 | C30: 24 | D30: =IF(D26="","",D26) | E30: =IF(E26="","",E26) | F30: =IF(F26="","",F26) -> 0.02 | G30: =IF(G26="","",G26) | I30: 190 | J30: =J31-275 -> 5170 | O30: =IF(L30&M30="","",J30*5)
B31: =B30+1 -> 29 | C31: 24 | D31: =IF(D27="","",D27) | E31: =IF(E27="","",E27) | F31: =IF(F27="","",F27) | G31: =IF(G27="","",G27) -> 0.01 | I31: 200 | J31: =J32-275 -> 5445 | O31: =IF(L31&M31="","",J31*5)
B32: =B31+1 -> 30 | C32: 24 | D32: =IF(D28="","",D28) -> 0.05 | E32: =IF(E28="","",E28) | F32: =IF(F28="","",F28) | G32: =IF(G28="","",G28) | I32: 210 | J32: =J33-275 -> 5720 | L32: 50 | N32: 6 | O32: =IF(L32&M32="","",J32*5) -> 28600
B33: =B32+1 -> 31 | C33: 28 | D33: =IF(D29="","",D29) | E33: =IF(E29="","",E29) -> 0.005 | F33: =IF(F29="","",F29) | G33: =IF(G29="","",G29) | I33: 220 | J33: =J34-275 -> 5995 | O33: =IF(L33&M33="","",J33*5)
B34: =B33+1 -> 32 | C34: 28 | D34: =IF(D30="","",D30) | E34: =IF(E30="","",E30) | F34: =IF(F30="","",F30) -> 0.02 | G34: =IF(G30="","",G30) | I34: 230 | J34: 6270 | O34: =IF(L34&M34="","",J34*5)
B35: =B34+1 -> 33 | C35: 28 | D35: =IF(D31="","",D31) | E35: =IF(E31="","",E31) | F35: =IF(F31="","",F31) | G35: =IF(G31="","",G31) -> 0.01 | I35: 240 | J35: 6545 | O35: =IF(L35&M35="","",J35*5)
B36: =B35+1 -> 34 | C36: 28 | D36: =IF(D32="","",D32) -> 0.05 | E36: =IF(E32="","",E32) | F36: =IF(F32="","",F32) | G36: =IF(G32="","",G32) | I36: 250 | J36: 6820 | O36: =IF(L36&M36="","",J36*5)
B37: =B36+1 -> 35 | C37: 28 | D37: =IF(D33="","",D33) | E37: =IF(E33="","",E33) -> 0.005 | F37: =IF(F33="","",F33) | G37: =IF(G33="","",G33) | I37: 260 | J37: 7095 | M37: 低于75%血量释放一次击退 | N37: 6 | O37: =IF(L37&M37="","",J37*5) -> 35475
B38: =B37+1 -> 36 | C38: 32 | D38: =IF(D34="","",D34) | E38: =IF(E34="","",E34) | F38: =IF(F34="","",F34) -> 0.02 | G38: =IF(G34="","",G34) | I38: 270 | J38: =J37+285 -> 7380 | O38: =IF(L38&M38="","",J38*5)
B39: =B38+1 -> 37 | C39: 32 | D39: =IF(D35="","",D35) | E39: =IF(E35="","",E35) | F39: =IF(F35="","",F35) | G39: =IF(G35="","",G35) -> 0.01 | I39: 280 | J39: =J38+285 -> 7665 | O39: =IF(L39&M39="","",J39*5)
B40: =B39+1 -> 38 | C40: 32 | D40: =IF(D36="","",D36) -> 0.05 | E40: =IF(E36="","",E36) | F40: =IF(F36="","",F36) | G40: =IF(G36="","",G36) | I40: 290 | J40: =J39+285 -> 7950 | O40: =IF(L40&M40="","",J40*5)
...

Sheet Sheet1
M2: [{5205001,3},{2,0}]
A3: =基因升级!$J$140&"+"&基因升级!J141 -> 队长攻击力+6 | B3: =IF(基因升级!K141="","",基因升级!K$140&"+"&基因升级!K141*100&"%") -> 队长伤害+5% | C3: =IF(基因升级!L141="","",基因升级!L$140&"+"&基因升级!L141*100&"%") | D3: =IF(基因升级!M141="","",基因升级!M$140&"+"&基因升级!M141*100&"%") | E3: =IF(基因升级!N141="","",基因升级!N$140&"+"&基因升级!N141*100&"%") | F3: =_xlfn.TEXTJOIN("\n",1,A3:E3) -> 队长攻击力+6\n队长伤害+5% | M3: [{5205001,3},{2,920}]
A4: =基因升级!$J$140&"+"&基因升级!J142 -> 队长攻击力+6 | B4: =IF(基因升级!K142="","",基因升级!K$140&"+"&基因升级!K142*100&"%") | C4: =IF(基因升级!L142="","",基因升级!L$140&"+"&基因升级!L142*100&"%") | D4: =IF(基因升级!M142="","",基因升级!M$140&"+"&基因升级!M142*100&"%") | E4: =IF(基因升级!N142="","",基因升级!N$140&"+"&基因升级!N142*100&"%") -> 队长技能冷却+0.75% | F4: =_xlfn.TEXTJOIN("\n",1,A4:E4) -> 队长攻击力+6\n队长技能冷却+0.75% | M4: [{5205001,3},{2,2040}]
A5: =基因升级!$J$140&"+"&基因升级!J143 -> 队长攻击力+6 | B5: =IF(基因升级!K143="","",基因升级!K$140&"+"&基因升级!K143*100&"%") | C5: =IF(基因升级!L143="","",基因升级!L$140&"+"&基因升级!L143*100&"%") | D5: =IF(基因升级!M143="","",基因升级!M$140&"+"&基因升级!M143*100&"%") -> 队长暴击++0.2% | E5: =IF(基因升级!N143="","",基因升级!N$140&"+"&基因升级!N143*100&"%") | F5: =_xlfn.TEXTJOIN("\n",1,A5:E5) -> 队长攻击力+6\n队长暴击++0.2% | M5: [{5205001,3},{2,3160}]
A6: =基因升级!$J$140&"+"&基因升级!J144 -> 队长攻击力+6 | B6: =IF(基因升级!K144="","",基因升级!K$140&"+"&基因升级!K144*100&"%") | C6: =IF(基因升级!L144="","",基因升级!L$140&"+"&基因升级!L144*100&"%") -> 队长暴击伤害+3% | D6: =IF(基因升级!M144="","",基因升级!M$140&"+"&基因升级!M144*100&"%") | E6: =IF(基因升级!N144="","",基因升级!N$140&"+"&基因升级!N144*100&"%") | F6: =_xlfn.TEXTJOIN("\n",1,A6:E6) -> 队长攻击力+6\n队长暴击伤害+3% | M6: [{5205001,3},{2,4280}]
A7: =基因升级!$J$140&"+"&基因升级!J145 -> 队长攻击力+6 | B7: =IF(基因升级!K145="","",基因升级!K$140&"+"&基因升级!K145*100&"%") -> 队长伤害+5% | C7: =IF(基因升级!L145="","",基因升级!L$140&"+"&基因升级!L145*100&"%") | D7: =IF(基因升级!M145="","",基因升级!M$140&"+"&基因升级!M145*100&"%") | E7: =IF(基因升级!N145="","",基因升级!N$140&"+"&基因升级!N145*100&"%") | F7: =_xlfn.TEXTJOIN("\n",1,A7:E7) -> 队长攻击力+6\n队长伤害+5% | M7: [{5205001,3},{2,5400}]
A8: =基因升级!$J$140&"+"&基因升级!J146 -> 队长攻击力+6 | B8: =IF(基因升级!K146="","",基因升级!K$140&"+"&基因升级!K146*100&"%") | C8: =IF(基因升级!L146="","",基因升级!L$140&"+"&基因升级!L146*100&"%") | D8: =IF(基因升级!M146="","",基因升级!M$140&"+"&基因升级!M146*100&"%") | E8: =IF(基因升级!N146="","",基因升级!N$140&"+"&基因升级!N146*100&"%") -> 队长技能冷却+0.75% | F8: =_xlfn.TEXTJOIN("\n",1,A8:E8) -> 队长攻击力+6\n队长技能冷却+0.75% | M8: [{5205001,3},{2,6520}]
A9: =基因升级!$J$140&"+"&基因升级!J147 -> 队长攻击力+6 | B9: =IF(基因升级!K147="","",基因升级!K$140&"+"&基因升级!K147*100&"%") | C9: =IF(基因升级!L147="","",基因升级!L$140&"+"&基因升级!L147*100&"%") | D9: =IF(基因升级!M147="","",基因升级!M$140&"+"&基因升级!M147*100&"%") -> 队长暴击++0.2% | E9: =IF(基因升级!N147="","",基因升级!N$140&"+"&基因升级!N147*100&"%") | F9: =_xlfn.TEXTJOIN("\n",1,A9:E9) -> 队长攻击力+6\n队长暴击++0.2% | M9: [{5205001,3},{2,7640}]
A10: =基因升级!$J$140&"+"&基因升级!J148 -> 队长攻击力+6 | B10: =IF(基因升级!K148="","",基因升级!K$140&"+"&基因升级!K148*100&"%") | C10: =IF(基因升级!L148="","",基因升级!L$140&"+"&基因升级!L148*100&"%") -> 队长暴击伤害+3% | D10: =IF(基因升级!M148="","",基因升级!M$140&"+"&基因升级!M148*100&"%") | E10: =IF(基因升级!N148="","",基因升级!N$140&"+"&基因升级!N148*100&"%") | F10: =_xlfn.TEXTJOIN("\n",1,A10:E10) -> 队长攻击力+6\n队长暴击伤害+3% | M10: [{5205001,3},{2,8760}]
A11: =基因升级!$J$140&"+"&基因升级!J149 -> 队长攻击力+12 | B11: =IF(基因升级!K149="","",基因升级!K$140&"+"&基因升级!K149*100&"%") -> 队长伤害+5% | C11: =IF(基因升级!L149="","",基因升级!L$140&"+"&基因升级!L149*100&"%") | D11: =IF(基因升级!M149="","",基因升级!M$140&"+"&基因升级!M149*100&"%") | E11: =IF(基因升级!N149="","",基因升级!N$140&"+"&基因升级!N149*100&"%") | F11: =_xlfn.TEXTJOIN("\n",1,A11:E11) -> 队长攻击力+12\n队长伤害+5% | M11: [{5205001,3},{2,9880}]
A12: =基因升级!$J$140&"+"&基因升级!J150 -> 队长攻击力+12 | B12: =IF(基因升级!K150="","",基因升级!K$140&"+"&基因升级!K150*100&"%") | C12: =IF(基因升级!L150="","",基因升级!L$140&"+"&基因升级!L150*100&"%") | D12: =IF(基因升级!M150="","",基因升级!M$140&"+"&基因升级!M150*100&"%") | E12: =IF(基因升级!N150="","",基因升级!N$140&"+"&基因升级!N150*100&"%") -> 队长技能冷却+0.75% | F12: =_xlfn.TEXTJOIN("\n",1,A12:E12) -> 队长攻击力+12\n队长技能冷却+0.75% | M12: [{5205001,3},{2,11000}]
A13: =基因升级!$J$140&"+"&基因升级!J151 -> 队长攻击力+12 | B13: =IF(基因升级!K151="","",基因升级!K$140&"+"&基因升级!K151*100&"%") | C13: =IF(基因升级!L151="","",基因升级!L$140&"+"&基因升级!L151*100&"%") | D13: =IF(基因升级!M151="","",基因升级!M$140&"+"&基因升级!M151*100&"%") -> 队长暴击++0.2% | E13: =IF(基因升级!N151="","",基因升级!N$140&"+"&基因升级!N151*100&"%") | F13: =_xlfn.TEXTJOIN("\n",1,A13:E13) -> 队长攻击力+12\n队长暴击++0.2% | M13: [{5205001,3},{2,12120}]
A14: =基因升级!$J$140&"+"&基因升级!J152 -> 队长攻击力+12 | B14: =IF(基因升级!K152="","",基因升级!K$140&"+"&基因升级!K152*100&"%") | C14: =IF(基因升级!L152="","",基因升级!L$140&"+"&基因升级!L152*100&"%") -> 队长暴击伤害+3% | D14: =IF(基因升级!M152="","",基因升级!M$140&"+"&基因升级!M152*100&"%") | E14: =IF(基因升级!N152="","",基因升级!N$140&"+"&基因升级!N152*100&"%") | F14: =_xlfn.TEXTJOIN("\n",1,A14:E14) -> 队长攻击力+12\n队长暴击伤害+3% | M14: [{5205001,3},{2,13240}]
... A62: =基因升级!$J$140&"+"&基因升级!J200 -> 队长攻击力+48 | B62: =IF(基因升级!K200="","",基因升级!K$140&"+"&基因升级!K200*100&"%") | C62: =IF(基因升级!L200="","",基因升级!L$140&"+"&基因升级!L200*100&"%") -> 队长暴击伤害+3% | D62: =IF(基因升级!M200="","",基因升级!M$140&"+"&基因升级!M200*100&"%") | E62: =IF(基因升级!N200="","",基因升级!N$140&"+"&基因升级!N200*100&"%") | F62: =_xlfn.TEXTJOIN("\n",1,A62:E62) -> 队长攻击力+48\n队长暴击伤害+3% | M62: [{5205001,3},{2,100600}]
A63: =基因升级!$J$140&"+"&基因升级!J201 -> 队长攻击力+48 | B63: =IF(基因升级!K201="","",基因升级!K$140&"+"&基因升级!K201*100&"%") -> 队长伤害+5% | C63: =IF(基因升级!L201="","",基因升级!L$140&"+"&基因升级!L201*100&"%") | D63: =IF(基因升级!M201="","",基因升级!M$140&"+"&基因升级!M201*100&"%") | E63: =IF(基因升级!N201="","",基因升级!N$140&"+"&基因升级!N201*100&"%") | F63: =_xlfn.TEXTJOIN("\n",1,A63:E63) -> 队长攻击力+48\n队长伤害+5%
A64: =基因升级!$J$140&"+"&基因升级!J202 -> 队长攻击力+48 | B64: =IF(基因升级!K202="","",基因升级!K$140&"+"&基因升级!K202*100&"%") | C64: =IF(基因升级!L202="","",基因升级!L$140&"+"&基因升级!L202*100&"%") | D64: =IF(基因升级!M202="","",基因升级!M$140&"+"&基因升级!M202*100&"%") | E64: =IF(基因升级!N202="","",基因升级!N$140&"+"&基因升级!N202*100&"%") -> 队长技能冷却+0.75% | F64: =_xlfn.TEXTJOIN("\n",1,A64:E64) -> 队长攻击力+48\n队长技能冷却+0.75%
A65: =基因升级!$J$140&"+"&基因升级!J203 -> 队长攻击力+48 | B65: =IF(基因升级!K203="","",基因升级!K$140&"+"&基因升级!K203*100&"%") | C65: =IF(基因升级!L203="","",基因升级!L$140&"+"&基因升级!L203*100&"%") | D65: =IF(基因升级!M203="","",基因升级!M$140&"+"&基因升级!M203*100&"%") -> 队长暴击++0.2% | E65: =IF(基因升级!N203="","",基因升级!N$140&"+"&基因升级!N203*100&"%") | F65: =_xlfn.TEXTJOIN("\n",1,A65:E65) -> 队长攻击力+48\n队长暴击++0.2%
A66: =基因升级!$J$140&"+"&基因升级!J204 -> 队长攻击力+48 | B66: =IF(基因升级!K204="","",基因升级!K$140&"+"&基因升级!K204*100&"%") | C66: =IF(基因升级!L204="","",基因升级!L$140&"+"&基因升级!L204*100&"%") -> 队长暴击伤害+3% | D66: =IF(基因升级!M204="","",基因升级!M$140&"+"&基因升级!M204*100&"%") | E66: =IF(基因升级!N204="","",基因升级!N$140&"+"&基因升级!N204*100&"%") | F66: =_xlfn.TEXTJOIN("\n",1,A66:E66) -> 队长攻击力+48\n队长暴击伤害+3%
A67: =基因升级!$J$140&"+"&基因升级!J205 -> 队长攻击力+54 | B67: =IF(基因升级!K205="","",基因升级!K$140&"+"&基因升级!K205*100&"%") -> 队长伤害+5% | C67: =IF(基因升级!L205="","",基因升级!L$140&"+"&基因升级!L205*100&"%") | D67: =IF(基因升级!M205="","",基因升级!M$140&"+"&基因升级!M205*100&"%") | E67: =IF(基因升级!N205="","",基因升级!N$140&"+"&基因升级!N205*100&"%") | F67: =_xlfn.TEXTJOIN("\n",1,A67:E67) -> 队长攻击力+54\n队长伤害+5%
A68: =基因升级!$J$140&"+"&基因升级!J206 -> 队长攻击力+54 | B68: =IF(基因升级!K206="","",基因升级!K$140&"+"&基因升级!K206*100&"%") | C68: =IF(基因升级!L206="","",基因升级!L$140&"+"&基因升级!L206*100&"%") | D68: =IF(基因升级!M206="","",基因升级!M$140&"+"&基因升级!M206*100&"%") | E68: =IF(基因升级!N206="","",基因升级!N$140&"+"&基因升级!N206*100&"%") -> 队长技能冷却+0.75% | F68: =_xlfn.TEXTJOIN("\n",1,A68:E68) -> 队长攻击力+54\n队长技能冷却+0.75%
A69: =基因升级!$J$140&"+"&基因升级!J207 -> 队长攻击力+54 | B69: =IF(基因升级!K207="","",基因升级!K$140&"+"&基因升级!K207*100&"%") | C69: =IF(基因升级!L207="","",基因升级!L$140&"+"&基因升级!L207*100&"%") | D69: =IF(基因升级!M207="","",基因升级!M$140&"+"&基因升级!M207*100&"%") -> 队长暴击++0.2% | E69: =IF(基因升级!N207="","",基因升级!N$140&"+"&基因升级!N207*100&"%") | F69: =_xlfn.TEXTJOIN("\n",1,A69:E69) -> 队长攻击力+54\n队长暴击++0.2%
A70: =基因升级!$J$140&"+"&基因升级!J208 -> 队长攻击力+54 | B70: =IF(基因升级!K208="","",基因升级!K$140&"+"&基因升级!K208*100&"%") | C70: =IF(基因升级!L208="","",基因升级!L$140&"+"&基因升级!L208*100&"%") -> 队长暴击伤害+3% | D70: =IF(基因升级!M208="","",基因升级!M$140&"+"&基因升级!M208*100&"%") | E70: =IF(基因升级!N208="","",基因升级!N$140&"+"&基因升级!N208*100&"%") | F70: =_xlfn.TEXTJOIN("\n",1,A70:E70) -> 队长攻击力+54\n队长暴击伤害+3%
A71: =基因升级!$J$140&"+"&基因升级!J209 -> 队长攻击力+54 | B71: =IF(基因升级!K209="","",基因升级!K$140&"+"&基因升级!K209*100&"%") -> 队长伤害+5% | C71: =IF(基因升级!L209="","",基因升级!L$140&"+"&基因升级!L209*100&"%") | D71: =IF(基因升级!M209="","",基因升级!M$140&"+"&基因升级!M209*100&"%") | E71: =IF(基因升级!N209="","",基因升级!N$140&"+"&基因升级!N209*100&"%") | F71: =_xlfn.TEXTJOIN("\n",1,A71:E71) -> 队长攻击力+54\n队长伤害+5%
A72: =基因升级!$J$140&"+"&基因升级!J210 -> 队长攻击力+54 | B72: =IF(基因升级!K210="","",基因升级!K$140&"+"&基因升级!K210*100&"%") | C72: =IF(基因升级!L210="","",基因升级!L$140&"+"&基因升级!L210*100&"%") | D72: =IF(基因升级!M210="","",基因升级!M$140&"+"&基因升级!M210*100&"%") | E72: =IF(基因升级!N210="","",基因升级!N$140&"+"&基因升级!N210*100&"%") -> 队长技能冷却+0.75% | F72: =_xlfn.TEXTJOIN("\n",1,A72:E72) -> 队长攻击力+54\n队长技能冷却+0.75%
A73: =基因升级!$J$140&"+"&基因升级!J211 -> 队长攻击力+54 | B73: =IF(基因升级!K211="","",基因升级!K$140&"+"&基因升级!K211*100&"%") | C73: =IF(基因升级!L211="","",基因升级!L$140&"+"&基因升级!L211*100&"%") | D73: =IF(基因升级!M211="","",基因升级!M$140&"+"&基因升级!M211*100&"%") -> 队长暴击++0.2% | E73: =IF(基因升级!N211="","",基因升级!N$140&"+"&基因升级!N211*100&"%") | F73: =_xlfn.TEXTJOIN("\n",1,A73:E73) -> 队长攻击力+54\n队长暴击++0.2%
A74: =基因升级!$J$140&"+"&基因升级!J212 -> 队长攻击力+54 | B74: =IF(基因升级!K212="","",基因升级!K$140&"+"&基因升级!K212*100&"%") | C74: =IF(基因升级!L212="","",基因升级!L$140&"+"&基因升级!L212*100&"%") -> 队长暴击伤害+3% | D74: =IF(基因升级!M212="","",基因升级!M$140&"+"&基因升级!M212*100&"%") | E74: =IF(基因升级!N212="","",基因升级!N$140&"+"&基因升级!N212*100&"%") | F74: =_xlfn.TEXTJOIN("\n",1,A74:E74) -> 队长攻击力+54\n队长暴击伤害+3%
... A362: =基因升级!$J$140&"+"&基因升级!J500 -> 队长攻击力+174 | B362: =IF(基因升级!K500="","",基因升级!K$140&"+"&基因升级!K500*100&"%") | C362: =IF(基因升级!L500="","",基因升级!L$140&"+"&基因升级!L500*100&"%") -> 队长暴击伤害+3% | D362: =IF(基因升级!M500="","",基因升级!M$140&"+"&基因升级!M500*100&"%") | E362: =IF(基因升级!N500="","",基因升级!N$140&"+"&基因升级!N500*100&"%") | F362: =_xlfn.TEXTJOIN("\n",1,A362:E362) -> 队长攻击力+174\n队长暴击伤害+3%
