Workbook

Sheet 版本日志
A4: 版本号 | B4: 修改内容 | C4: 负责人 | D4: 日期
A5: 1 | B5: 创建文档 | C5: 刁子文 | D5: 46059
A6: 2 | B6: 非R进度改为2-0强度推算值；价值表对齐6-1；删除隐藏的「组队产出旧」；补设计思路 | C6: Claude（按用户要求） | D6: 46315

Sheet 设计思路
A1: 商业化数值
A3: 说明
C5: 设计思路
D7: 金币调整
E8: '金币平衡'!A2:N24
D10: 基因调整
E12: '基因平衡'!A2:I13
D14: 产销汇总：C:G是各分层（非R/小R/中R/大R）的主线进度和每日玩法次数，2-0的宏按它取各玩法的练度档。
D15: 2026-10-20：非R进度（D13:D312）改为2-0强度推算的关卡（D30 82、D60 110、D120 157、D300 180）；小R以上未改。
D16: 各「产出_xxx」表是2-0宏的数据源；主线推图/巡逻/主线宝箱下方的字符串区直接生成配置奖励。
D17: 价值表以《6-1商业化数值2.0版》为准；金币平衡/图纸产出设计/基因平衡核算各资源的产出占比与坑深。
A19: 本页结束

Sheet 金币平衡
B2: 生命周期 | C2: 60
B3: 总坑深 | C3: =SUM(C7:C22)*0.05 -> #N/A
B6: 产出途径 | C6: 产出价值 | D6: 产出频率 | E6: 产出比例 | I6: 长周期提升幅度 | K6: 天数 | L6: 预期天数
B7: 装备分解 | C7: =IF(D7="每日",SUMIF($B$28:$B$327,"<="&$C$2,OFFSET($C$28:$C$327,0,MATCH($B7,$D$27:$T$27,0))),SUMIF($B$28:$B$327,"="&$C$2,OFFSET($C$28:$C$327,0,MATCH($B7,$D$27:$T$27,0)))) -> 710616 | D7: 每日 | E7: =C7/SUM($C$7:$C$23) -> #N/A | F7: #回调 | I7: =SUM(F7:F22)/SUM(C7:C22) -> #N/A | K7: =SUMPRODUCT(--(($U$28:$U$87-$W$28:$W$87)<0),--($B$28:$B$87>0)) -> #N/A | L7: 平衡装备
B8: 金币本扫荡 | C8: =IF(D8="每日",SUMIF($B$28:$B$327,"<="&$C$2,OFFSET($C$28:$C$327,0,MATCH($B8,$D$27:$T$27,0))),SUMIF($B$28:$B$327,"="&$C$2,OFFSET($C$28:$C$327,0,MATCH($B8,$D$27:$T$27,0)))) -> 1270500 | D8: 每日 | E8: =C8/SUM($C$7:$C$23) -> #N/A | F8: #卖一次 | K8: =SUMPRODUCT(--(($U$28:$U$87-$W$28:$W$87-$X$28:$X$87)<0),--($B$28:$B$87>0)) -> #N/A | L8: 装备+基因
B9: 金币本首通 | C9: =IF(D9="每日",SUMIF($B$28:$B$327,"<="&$C$2,OFFSET($C$28:$C$327,0,MATCH($B9,$D$27:$T$27,0))),SUMIF($B$28:$B$327,"="&$C$2,OFFSET($C$28:$C$327,0,MATCH($B9,$D$27:$T$27,0)))) -> 697000 | D9: 一次性产出 | E9: =C9/SUM($C$7:$C$23) -> #N/A | K9: =SUMPRODUCT(--(($U$28:$U$87-$W$28:$W$87-$X$28:$X$87-0.25*$Y$28:$Y$87)<0),--($B$28:$B$87>0)) -> #N/A | L9: 装备基因+商店
B10: 抽卡 | C10: =IF(D10="每日",SUMIF($B$28:$B$327,"<="&$C$2,OFFSET($C$28:$C$327,0,MATCH($B10,$D$27:$T$27,0))),SUMIF($B$28:$B$327,"="&$C$2,OFFSET($C$28:$C$327,0,MATCH($B10,$D$27:$T$27,0)))) -> 454896 | D10: 一次性产出 | E10: =C10/SUM($C$7:$C$23) -> #N/A | F10: #抬一些
B11: 挂机 | C11: =IF(D11="每日",SUMIF($B$28:$B$327,"<="&$C$2,OFFSET($C$28:$C$327,0,MATCH($B11,$D$27:$T$27,0))),SUMIF($B$28:$B$327,"="&$C$2,OFFSET($C$28:$C$327,0,MATCH($B11,$D$27:$T$27,0)))) -> #N/A | D11: 每日 | E11: =C11/SUM($C$7:$C$23) -> #N/A | F11: #翻倍
B12: 主线 | C12: =IF(D12="每日",SUMIF($B$28:$B$327,"<="&$C$2,OFFSET($C$28:$C$327,0,MATCH($B12,$D$27:$T$27,0))),SUMIF($B$28:$B$327,"="&$C$2,OFFSET($C$28:$C$327,0,MATCH($B12,$D$27:$T$27,0)))) -> #N/A | D12: 每日 | E12: =C12/SUM($C$7:$C$23) -> #N/A
B13: 体力扫荡 | C13: =IF(D13="每日",SUMIF($B$28:$B$327,"<="&$C$2,OFFSET($C$28:$C$327,0,MATCH($B13,$D$27:$T$27,0))),SUMIF($B$28:$B$327,"="&$C$2,OFFSET($C$28:$C$327,0,MATCH($B13,$D$27:$T$27,0)))) -> #N/A | D13: 每日 | E13: =C13/SUM($C$7:$C$23) -> #N/A
B14: 组队本 | C14: =IF(D14="每日",SUMIF($B$28:$B$327,"<="&$C$2,OFFSET($C$28:$C$327,0,MATCH($B14,$D$27:$T$27,0))),SUMIF($B$28:$B$327,"="&$C$2,OFFSET($C$28:$C$327,0,MATCH($B14,$D$27:$T$27,0)))) -> 340080 | D14: 每日 | E14: =C14/SUM($C$7:$C$23) -> #N/A
B15: 主线战斗 | C15: =IF(D15="每日",SUMIF($B$28:$B$327,"<="&$C$2,OFFSET($C$28:$C$327,0,MATCH($B15,$D$27:$T$27,0))),SUMIF($B$28:$B$327,"="&$C$2,OFFSET($C$28:$C$327,0,MATCH($B15,$D$27:$T$27,0)))) -> 234600 | D15: 一次性产出 | E15: =C15/SUM($C$7:$C$23) -> #N/A | F15: #放大为2.5
B16: 每日活跃 | C16: =IF(D16="每日",SUMIF($B$28:$B$327,"<="&$C$2,OFFSET($C$28:$C$327,0,MATCH($B16,$D$27:$T$27,0))),SUMIF($B$28:$B$327,"="&$C$2,OFFSET($C$28:$C$327,0,MATCH($B16,$D$27:$T$27,0)))) -> 147428.57 | D16: 每日 | E16: =C16/SUM($C$7:$C$23) -> #N/A
B17: 基因协助 | C17: =IF(D17="每日",SUMIF($B$28:$B$327,"<="&$C$2,OFFSET($C$28:$C$327,0,MATCH($B17,$D$27:$T$27,0))),SUMIF($B$28:$B$327,"="&$C$2,OFFSET($C$28:$C$327,0,MATCH($B17,$D$27:$T$27,0)))) -> 120000 | D17: 每日 | E17: =C17/SUM($C$7:$C$23) -> #N/A
B18: 组队首通 | C18: =IF(D18="每日",SUMIF($B$28:$B$327,"<="&$C$2,OFFSET($C$28:$C$327,0,MATCH($B18,$D$27:$T$27,0))),SUMIF($B$28:$B$327,"="&$C$2,OFFSET($C$28:$C$327,0,MATCH($B18,$D$27:$T$27,0)))) -> 99000 | D18: 一次性产出 | E18: =C18/SUM($C$7:$C$23) -> #N/A
B19: 商城领取 | C19: =IF(D19="每日",SUMIF($B$28:$B$327,"<="&$C$2,OFFSET($C$28:$C$327,0,MATCH($B19,$D$27:$T$27,0))),SUMIF($B$28:$B$327,"="&$C$2,OFFSET($C$28:$C$327,0,MATCH($B19,$D$27:$T$27,0)))) -> 64500 | D19: 每日 | E19: =C19/SUM($C$7:$C$23) -> #N/A
B20: 基金 | C20: =IF(D20="每日",SUMIF($B$28:$B$327,"<="&$C$2,OFFSET($C$28:$C$327,0,MATCH($B20,$D$27:$T$27,0))),SUMIF($B$28:$B$327,"="&$C$2,OFFSET($C$28:$C$327,0,MATCH($B20,$D$27:$T$27,0)))) -> 30000 | D20: 一次性产出 | E20: =C20/SUM($C$7:$C$23) -> #N/A
B21: 协力宝箱 | C21: =IF(D21="每日",SUMIF($B$28:$B$327,"<="&$C$2,OFFSET($C$28:$C$327,0,MATCH($B21,$D$27:$T$27,0))),SUMIF($B$28:$B$327,"="&$C$2,OFFSET($C$28:$C$327,0,MATCH($B21,$D$27:$T$27,0)))) -> 25680 | D21: 每日 | E21: =C21/SUM($C$7:$C$23) -> #N/A
B22: 任务 | C22: =IF(D22="每日",SUMIF($B$28:$B$327,"<="&$C$2,OFFSET($C$28:$C$327,0,MATCH($B22,$D$27:$T$27,0))),SUMIF($B$28:$B$327,"="&$C$2,OFFSET($C$28:$C$327,0,MATCH($B22,$D$27:$T$27,0)))) -> 14100 | D22: 一次性产出 | E22: =C22/SUM($C$7:$C$23) -> #N/A
D24: 修正参数 | E24: 1 | H24: 1 | M24: 1 | S24: 1
B26: =OFFSET(产销汇总!$C$1,0,$C$26) -> 大R | C26: 4 | D26: 一次性产出 | J26: 循环产出 | V26: 折损率 | W26: 1
B27: 天数 | C27: 关卡预期 | D27: 任务 | E27: 主线战斗 | F27: 组队首通 | G27: 基金 | H27: 抽卡 | I27: 金币本首通 | J27: 主线 | K27: 体力扫荡 | L27: 组队本 | M27: 挂机 | N27: 装备分解 | O27: 每日活跃 | P27: 协力宝箱 | Q27: 商城领取 | R27: 基因协助 | S27: 金币本扫荡 | T27: 总产出 | U27: 金币产出 | V27: 金币需求 | W27: 装备消耗 | X27: 基因消耗 | Y27: 商店消耗 | AA27: 金币亏损 | AC27: 预留
B28: 1 | C28: =OFFSET(产销汇总!$C$12,$B28,$C$26) -> 30 | D28: =5500+1800+2100+2700+2000 -> 14100 | E28: =(SUMIF(主线推图!$B$4:$B$303,"<"&C28,主线推图!$M$4:$M$303)+SUMIF(主线宝箱!$B$320:$B$620,"<"&C28,主线宝箱!$L$320:$L$620)+SUMIF(主线宝箱!$B$320:$B$620,"<"&C28,主线宝箱!$X$320:$X$620)+SUMIF(主线宝箱!$B$320:$B$620,"<"&C28,主线宝箱!$AL$320:$AL$620)) -> 49200 | F28: =SUMIF(组队产出!$B$24:$B$39,"<="&MAX(1,INT(C28/10-0.6)),组队产出!$R$24:$R$39) -> 9000 | G28: =SUMIF(运营活动!$O$3:$O$27,"<="&C28,运营活动!$P$3:$P$27) -> 4000 | H28: =OFFSET(产销汇总!$AM$12,B28,$C$26)*24 -> 12072 | I28: =SUMIF(金币本!$F$2:$F$52,"<="&C28,金币本!$D$2:$D$52) -> 49000 | J28: =OFFSET(产销汇总!$C$1,MATCH(J$27,产销汇总!$C$2:$C$8,0),$C$26)*(_xlfn.XLOOKUP(C28,主线推图!$B$313:$B$612,主线推图!$C$313:$C$612)+_xlfn.XLOOKUP(C28,主线推图!$B$313:$B$612,主线推图!$D$313:$D$612)) -> 7436 | K28: =OFFSET(产销汇总!$C$1,MATCH(K$27,产销汇总!$C$2:$C$8,0),$C$26)*_xlfn.XLOOKUP(C28,巡逻产出!$B$311:$B$610,巡逻产出!$C$311:$C$610)*1.3 -> 0 | L28: =OFFSET(产销汇总!$C$1,MATCH(L$27,产销汇总!$C$2:$C$8,0),$C$26)*(_xlfn.XLOOKUP(MAX(1,INT(C28/10-6/10)),组队产出!$B$24:$B$39,组队产出!$D$24:$D$39))+OFFSET(产销汇总!$C$1,MATCH(L$27,产销汇总!$C$2:$C$8,0),$C$26)*(_xlfn.XLOOKUP(MAX(1,INT(C28/10-6/10)),组队产出!$B$24:$B$39,组队产出!$C$24:$C$39)) -> 4056 | M28: =(OFFSET(产销汇总!$C$1,MATCH(M$27,产销汇总!$C$2:$C$8,0),$C$26)*_xlfn.XLOOKUP(C28,巡逻产出!$B$311:$B$610,巡逻产出!$D$311:$D$610))*$M$24 -> 5272.8 | N28: =OFFSET(产销汇总!$C$1,MATCH(L$27,产销汇总!$C$2:$C$8,0),$C$26)*(_xlfn.XLOOKUP(MAX(1,INT(C28/10-6/10)),组队产出!$B$24:$B$39,组队产出!$S$24:$S$39)) -> 2664 | O28: =任务!$D$36 -> 2457.1429 | P28: =INT(300*10/7) -> 428 | Q28: =IF(MOD(B28,7)=1,500,0)+1000+IF(AND($C$26=4,B28<=0),40000,0) -> 1500 | R28: 2000 | S28: =IFERROR(OFFSET(金币本!$E$2,MATCH(C28,金币本!$F$3:$F$302,1),0)*IF($C$26=1,2,3),0) -> 7500 | T28: =SUM($J$28:S28)+SUM(D28:I28) -> 170685.94 | U28: =T28 -> 170685.94 | V28: =SUM(W28:Y28) -> 175910 | W28: =OFFSET(装备强化!$U$6,MATCH(图纸产出设计!V29/6*W$26,装备强化!$T$7:$T$306,1),0)*6 -> 151200 | X28: 8710 | Y28: =IF(C26=1,12000,IF(C26=2,12000,IF(C26=3,16000,16000))) -> 16000 | AA28: =U28/V28 -> 0.97030267 | AB28: =U28-V28 -> -5224.0571 | AC28: =SUMIFS(装备强化!$Q$7:$Q$306,装备强化!$M$7:$M$306,"<="&MATCH(U28/6,装备强化!$U$7:$U$306,1),装备强化!$M$7:$M$306,">="&MATCH(V28/6,装备强化!$U$7:$U$306,1))*6 -> 354
B29: 2 | C29: =OFFSET(产销汇总!$C$12,$B29,$C$26) -> 35 | D29: =D28 -> 14100 | E29: =(SUMIF(主线推图!$B$4:$B$303,"<"&C29,主线推图!$M$4:$M$303)+SUMIF(主线宝箱!$B$320:$B$620,"<"&C29,主线宝箱!$L$320:$L$620)+SUMIF(主线宝箱!$B$320:$B$620,"<"&C29,主线宝箱!$X$320:$X$620)+SUMIF(主线宝箱!$B$320:$B$620,"<"&C29,主线宝箱!$AL$320:$AL$620)) -> 58200 | F29: =SUMIF(组队产出!$B$24:$B$39,"<="&MAX(1,INT(C29/10-0.6)),组队产出!$R$24:$R$39) -> 9000 | G29: =SUMIF(运营活动!$O$3:$O$27,"<="&C29,运营活动!$P$3:$P$27) -> 5000 | H29: =OFFSET(产销汇总!$AM$12,B29,$C$26)*24 -> 22752 | I29: =SUMIF(金币本!$F$2:$F$52,"<="&C29,金币本!$D$2:$D$52) -> 72000 | J29: =OFFSET(产销汇总!$C$1,MATCH(J$27,产销汇总!$C$2:$C$8,0),$C$26)*(_xlfn.XLOOKUP(C29,主线推图!$B$313:$B$612,主线推图!$C$313:$C$612)+_xlfn.XLOOKUP(C29,主线推图!$B$313:$B$612,主线推图!$D$313:$D$612)) -> 7656 | K29: =OFFSET(产销汇总!$C$1,MATCH(K$27,产销汇总!$C$2:$C$8,0),$C$26)*_xlfn.XLOOKUP(C29,巡逻产出!$B$311:$B$610,巡逻产出!$C$311:$C$610)*1.3 -> 0 | L29: =OFFSET(产销汇总!$C$1,MATCH(L$27,产销汇总!$C$2:$C$8,0),$C$26)*(_xlfn.XLOOKUP(MAX(1,INT(C29/10-6/10)),组队产出!$B$24:$B$39,组队产出!$D$24:$D$39))+OFFSET(产销汇总!$C$1,MATCH(L$27,产销汇总!$C$2:$C$8,0),$C$26)*(_xlfn.XLOOKUP(MAX(1,INT(C29/10-6/10)),组队产出!$B$24:$B$39,组队产出!$C$24:$C$39)) -> 4056 | M29: =(OFFSET(产销汇总!$C$1,MATCH(M$27,产销汇总!$C$2:$C$8,0),$C$26)*_xlfn.XLOOKUP(C29,巡逻产出!$B$311:$B$610,巡逻产出!$D$311:$D$610))*$M$24 -> 5428.8 | N29: =OFFSET(产销汇总!$C$1,MATCH(L$27,产销汇总!$C$2:$C$8,0),$C$26)*(_xlfn.XLOOKUP(MAX(1,INT(C29/10-6/10)),组队产出!$B$24:$B$39,组队产出!$S$24:$S$39)) -> 2664 | O29: =任务!$D$36 -> 2457.1429 | P29: =INT(300*10/7) -> 428 | Q29: =IF(MOD(B29,7)=1,500,0)+1000+IF(AND($C$26=4,B29<=0),40000,0) -> 1000 | R29: =R28 -> 2000 | S29: =IFERROR(OFFSET(金币本!$E$2,MATCH(C29,金币本!$F$3:$F$302,1),0)*IF($C$26=1,2,3),0) -> 9000 | T29: =SUM($J$28:S29)+SUM(D29:I29) -> 249055.89 | U29: =T29 -> 249055.89 | V29: =SUM(W29:Y29) -> 281110 | W29: =OFFSET(装备强化!$U$6,MATCH(图纸产出设计!V30/6*W$26,装备强化!$T$7:$T$306,1),0)*6 -> 234000 | X29: 15110 | Y29: =Y28+$Y$28*Z29 -> 32000 | Z29: 1 | AA29: =U29/V29 -> 0.88597306 | AB29: =U29-V29 -> -32054.114 | AC29: =SUMIFS(装备强化!$Q$7:$Q$306,装备强化!$M$7:$M$306,"<="&MATCH(U29/6,装备强化!$U$7:$U$306,1),装备强化!$M$7:$M$306,">="&MATCH(V29/6,装备强化!$U$7:$U$306,1))*6 -> 0 | AD29: =AC29/B29 -> 0 | AE29: =AVERAGE(AD29:AD327) -> 2.108616
B30: 3 | C30: =OFFSET(产销汇总!$C$12,$B30,$C$26) -> 40 | D30: =D29 -> 14100 | E30: =(SUMIF(主线推图!$B$4:$B$303,"<"&C30,主线推图!$M$4:$M$303)+SUMIF(主线宝箱!$B$320:$B$620,"<"&C30,主线宝箱!$L$320:$L$620)+SUMIF(主线宝箱!$B$320:$B$620,"<"&C30,主线宝箱!$X$320:$X$620)+SUMIF(主线宝箱!$B$320:$B$620,"<"&C30,主线宝箱!$AL$320:$AL$620)) -> 67200 | F30: =SUMIF(组队产出!$B$24:$B$39,"<="&MAX(1,INT(C30/10-0.6)),组队产出!$R$24:$R$39) -> 15000 | G30: =SUMIF(运营活动!$O$3:$O$27,"<="&C30,运营活动!$P$3:$P$27) -> 6000 | H30: =OFFSET(产销汇总!$AM$12,B30,$C$26)*24 -> 31464 | I30: =SUMIF(金币本!$F$2:$F$52,"<="&C30,金币本!$D$2:$D$52) -> 85000 | J30: =OFFSET(产销汇总!$C$1,MATCH(J$27,产销汇总!$C$2:$C$8,0),$C$26)*(_xlfn.XLOOKUP(C30,主线推图!$B$313:$B$612,主线推图!$C$313:$C$612)+_xlfn.XLOOKUP(C30,主线推图!$B$313:$B$612,主线推图!$D$313:$D$612)) -> 7876 | K30: =OFFSET(产销汇总!$C$1,MATCH(K$27,产销汇总!$C$2:$C$8,0),$C$26)*_xlfn.XLOOKUP(C30,巡逻产出!$B$311:$B$610,巡逻产出!$C$311:$C$610)*1.3 -> 0 | L30: =OFFSET(产销汇总!$C$1,MATCH(L$27,产销汇总!$C$2:$C$8,0),$C$26)*(_xlfn.XLOOKUP(MAX(1,INT(C30/10-6/10)),组队产出!$B$24:$B$39,组队产出!$D$24:$D$39))+OFFSET(产销汇总!$C$1,MATCH(L$27,产销汇总!$C$2:$C$8,0),$C$26)*(_xlfn.XLOOKUP(MAX(1,INT(C30/10-6/10)),组队产出!$B$24:$B$39,组队产出!$C$24:$C$39)) -> 4296 | M30: =(OFFSET(产销汇总!$C$1,MATCH(M$27,产销汇总!$C$2:$C$8,0),$C$26)*_xlfn.XLOOKUP(C30,巡逻产出!$B$311:$B$610,巡逻产出!$D$311:$D$610))*$M$24 -> 5584.8 | N30: =OFFSET(产销汇总!$C$1,MATCH(L$27,产销汇总!$C$2:$C$8,0),$C$26)*(_xlfn.XLOOKUP(MAX(1,INT(C30/10-6/10)),组队产出!$B$24:$B$39,组队产出!$S$24:$S$39)) -> 3396 | O30: =任务!$D$36 -> 2457.1429 | P30: =INT(300*10/7) -> 428 | Q30: =IF(MOD(B30,7)=1,500,0)+1000+IF(AND($C$26=4,B30<=0),40000,0) -> 1000 | R30: =R29 -> 2000 | S30: =IFERROR(OFFSET(金币本!$E$2,MATCH(C30,金币本!$F$3:$F$302,1),0)*IF($C$26=1,2,3),0) -> 9750 | T30: =SUM($J$28:S30)+SUM(D30:I30) -> 323555.83 | U30: =T30 -> 323555.83 | V30: =SUM(W30:Y30) -> 391660 | W30: =OFFSET(装备强化!$U$6,MATCH(图纸产出设计!V31/6*W$26,装备强化!$T$7:$T$306,1),0)*6 -> 320400 | X30: 23260 | Y30: =Y29+$Y$28*Z30 -> 48000 | Z30: 1 | AA30: =U30/V30 -> 0.82611405 | AB30: =U30-V30 -> -68104.171 | AC30: =SUMIFS(装备强化!$Q$7:$Q$306,装备强化!$M$7:$M$306,"<="&MATCH(U30/6,装备强化!$U$7:$U$306,1),装备强化!$M$7:$M$306,">="&MATCH(V30/6,装备强化!$U$7:$U$306,1))*6 -> 0 | AD30: =AC30/B30 -> 0
B31: 4 | C31: =OFFSET(产销汇总!$C$12,$B31,$C$26) -> 46 | D31: =D30 -> 14100 | E31: =(SUMIF(主线推图!$B$4:$B$303,"<"&C31,主线推图!$M$4:$M$303)+SUMIF(主线宝箱!$B$320:$B$620,"<"&C31,主线宝箱!$L$320:$L$620)+SUMIF(主线宝箱!$B$320:$B$620,"<"&C31,主线宝箱!$X$320:$X$620)+SUMIF(主线宝箱!$B$320:$B$620,"<"&C31,主线宝箱!$AL$320:$AL$620)) -> 78000 | F31: =SUMIF(组队产出!$B$24:$B$39,"<="&MAX(1,INT(C31/10-0.6)),组队产出!$R$24:$R$39) -> 21000 | G31: =SUMIF(运营活动!$O$3:$O$27,"<="&C31,运营活动!$P$3:$P$27) -> 7500 | H31: =OFFSET(产销汇总!$AM$12,B31,$C$26)*24 -> 42528 | I31: =SUMIF(金币本!$F$2:$F$52,"<="&C31,金币本!$D$2:$D$52) -> 114000 | J31: =OFFSET(产销汇总!$C$1,MATCH(J$27,产销汇总!$C$2:$C$8,0),$C$26)*(_xlfn.XLOOKUP(C31,主线推图!$B$313:$B$612,主线推图!$C$313:$C$612)+_xlfn.XLOOKUP(C31,主线推图!$B$313:$B$612,主线推图!$D$313:$D$612)) -> 8140 | K31: =OFFSET(产销汇总!$C$1,MATCH(K$27,产销汇总!$C$2:$C$8,0),$C$26)*_xlfn.XLOOKUP(C31,巡逻产出!$B$311:$B$610,巡逻产出!$C$311:$C$610)*1.3 -> 0 | L31: =OFFSET(产销汇总!$C$1,MATCH(L$27,产销汇总!$C$2:$C$8,0),$C$26)*(_xlfn.XLOOKUP(MAX(1,INT(C31/10-6/10)),组队产出!$B$24:$B$39,组队产出!$D$24:$D$39))+OFFSET(产销汇总!$C$1,MATCH(L$27,产销汇总!$C$2:$C$8,0),$C$26)*(_xlfn.XLOOKUP(MAX(1,INT(C31/10-6/10)),组队产出!$B$24:$B$39,组队产出!$C$24:$C$39)) -> 4536 | M31: =(OFFSET(产销汇总!$C$1,MATCH(M$27,产销汇总!$C$2:$C$8,0),$C$26)*_xlfn.XLOOKUP(C31,巡逻产出!$B$311:$B$610,巡逻产出!$D$311:$D$610))*$M$24 -> 5772 | N31: =OFFSET(产销汇总!$C$1,MATCH(L$27,产销汇总!$C$2:$C$8,0),$C$26)*(_xlfn.XLOOKUP(MAX(1,INT(C31/10-6/10)),组队产出!$B$24:$B$39,组队产出!$S$24:$S$39)) -> 4920 | O31: =任务!$D$36 -> 2457.1429 | P31: =INT(300*10/7) -> 428 | Q31: =IF(MOD(B31,7)=1,500,0)+1000+IF(AND($C$26=4,B31<=0),40000,0) -> 1000 | R31: =R30 -> 2000 | S31: =IFERROR(OFFSET(金币本!$E$2,MATCH(C31,金币本!$F$3:$F$302,1),0)*IF($C$26=1,2,3),0) -> 11250 | T31: =SUM($J$28:S31)+SUM(D31:I31) -> 422422.97 | U31: =T31 -> 422422.97 | V31: =SUM(W31:Y31) -> 469440 | W31: =OFFSET(装备强化!$U$6,MATCH(图纸产出设计!V32/6*W$26,装备强化!$T$7:$T$306,1),0)*6 -> 374400 | X31: 31040 | Y31: =Y30+$Y$28*Z31 -> 64000 | Z31: 1 | AA31: =U31/V31 -> 0.89984443 | AB31: =U31-V31 -> -47017.029 | AC31: =SUMIFS(装备强化!$Q$7:$Q$306,装备强化!$M$7:$M$306,"<="&MATCH(U31/6,装备强化!$U$7:$U$306,1),装备强化!$M$7:$M$306,">="&MATCH(V31/6,装备强化!$U$7:$U$306,1))*6 -> 0 | AD31: =AC31/B31 -> 0
B32: 5 | C32: =OFFSET(产销汇总!$C$12,$B32,$C$26) -> 55 | D32: =D31 -> 14100 | E32: =(SUMIF(主线推图!$B$4:$B$303,"<"&C32,主线推图!$M$4:$M$303)+SUMIF(主线宝箱!$B$320:$B$620,"<"&C32,主线宝箱!$L$320:$L$620)+SUMIF(主线宝箱!$B$320:$B$620,"<"&C32,主线宝箱!$X$320:$X$620)+SUMIF(主线宝箱!$B$320:$B$620,"<"&C32,主线宝箱!$AL$320:$AL$620)) -> 94200 | F32: =SUMIF(组队产出!$B$24:$B$39,"<="&MAX(1,INT(C32/10-0.6)),组队产出!$R$24:$R$39) -> 21000 | G32: =SUMIF(运营活动!$O$3:$O$27,"<="&C32,运营活动!$P$3:$P$27) -> 10500 | H32: =OFFSET(产销汇总!$AM$12,B32,$C$26)*24 -> 51120 | I32: =SUMIF(金币本!$F$2:$F$52,"<="&C32,金币本!$D$2:$D$52) -> 165000 | J32: =OFFSET(产销汇总!$C$1,MATCH(J$27,产销汇总!$C$2:$C$8,0),$C$26)*(_xlfn.XLOOKUP(C32,主线推图!$B$313:$B$612,主线推图!$C$313:$C$612)+_xlfn.XLOOKUP(C32,主线推图!$B$313:$B$612,主线推图!$D$313:$D$612)) -> 8536 | K32: =OFFSET(产销汇总!$C$1,MATCH(K$27,产销汇总!$C$2:$C$8,0),$C$26)*_xlfn.XLOOKUP(C32,巡逻产出!$B$311:$B$610,巡逻产出!$C$311:$C$610)*1.3 -> 0 | L32: =OFFSET(产销汇总!$C$1,MATCH(L$27,产销汇总!$C$2:$C$8,0),$C$26)*(_xlfn.XLOOKUP(MAX(1,INT(C32/10-6/10)),组队产出!$B$24:$B$39,组队产出!$D$24:$D$39))+OFFSET(产销汇总!$C$1,MATCH(L$27,产销汇总!$C$2:$C$8,0),$C$26)*(_xlfn.XLOOKUP(MAX(1,INT(C32/10-6/10)),组队产出!$B$24:$B$39,组队产出!$C$24:$C$39)) -> 4536 | M32: =(OFFSET(产销汇总!$C$1,MATCH(M$27,产销汇总!$C$2:$C$8,0),$C$26)*_xlfn.XLOOKUP(C32,巡逻产出!$B$311:$B$610,巡逻产出!$D$311:$D$610))*$M$24 -> 6052.8 | N32: =OFFSET(产销汇总!$C$1,MATCH(L$27,产销汇总!$C$2:$C$8,0),$C$26)*(_xlfn.XLOOKUP(MAX(1,INT(C32/10-6/10)),组队产出!$B$24:$B$39,组队产出!$S$24:$S$39)) -> 4920 | O32: =任务!$D$36 -> 2457.1429 | P32: =INT(300*10/7) -> 428 | Q32: =IF(MOD(B32,7)=1,500,0)+1000+IF(AND($C$26=4,B32<=0),40000,0) -> 1000 | R32: =R31 -> 2000 | S32: =IFERROR(OFFSET(金币本!$E$2,MATCH(C32,金币本!$F$3:$F$302,1),0)*IF($C$26=1,2,3),0) -> 13500 | T32: =SUM($J$28:S32)+SUM(D32:I32) -> 544644.91 | U32: =T32 -> 544644.91 | V32: =SUM(W32:Y32) -> 559140 | W32: =OFFSET(装备强化!$U$6,MATCH(图纸产出设计!V33/6*W$26,装备强化!$T$7:$T$306,1),0)*6 -> 439200 | X32: 39940 | Y32: =Y31+$Y$28*Z32 -> 80000 | Z32: 1 | AA32: =U32/V32 -> 0.97407611 | AB32: =U32-V32 -> -14495.086 | AC32: =SUMIFS(装备强化!$Q$7:$Q$306,装备强化!$M$7:$M$306,"<="&MATCH(U32/6,装备强化!$U$7:$U$306,1),装备强化!$M$7:$M$306,">="&MATCH(V32/6,装备强化!$U$7:$U$306,1))*6 -> 0 | AD32: =AC32/B32 -> 0
B33: 6 | C33: =OFFSET(产销汇总!$C$12,$B33,$C$26) -> 57 | D33: =D32 -> 14100 | E33: =(SUMIF(主线推图!$B$4:$B$303,"<"&C33,主线推图!$M$4:$M$303)+SUMIF(主线宝箱!$B$320:$B$620,"<"&C33,主线宝箱!$L$320:$L$620)+SUMIF(主线宝箱!$B$320:$B$620,"<"&C33,主线宝箱!$X$320:$X$620)+SUMIF(主线宝箱!$B$320:$B$620,"<"&C33,主线宝箱!$AL$320:$AL$620)) -> 97800 | F33: =SUMIF(组队产出!$B$24:$B$39,"<="&MAX(1,INT(C33/10-0.6)),组队产出!$R$24:$R$39) -> 28500 | G33: =SUMIF(运营活动!$O$3:$O$27,"<="&C33,运营活动!$P$3:$P$27) -> 12000 | H33: =OFFSET(产销汇总!$AM$12,B33,$C$26)*24 -> 59544 | I33: =SUMIF(金币本!$F$2:$F$52,"<="&C33,金币本!$D$2:$D$52) -> 165000 | J33: =OFFSET(产销汇总!$C$1,MATCH(J$27,产销汇总!$C$2:$C$8,0),$C$26)*(_xlfn.XLOOKUP(C33,主线推图!$B$313:$B$612,主线推图!$C$313:$C$612)+_xlfn.XLOOKUP(C33,主线推图!$B$313:$B$612,主线推图!$D$313:$D$612)) -> 8624 | K33: =OFFSET(产销汇总!$C$1,MATCH(K$27,产销汇总!$C$2:$C$8,0),$C$26)*_xlfn.XLOOKUP(C33,巡逻产出!$B$311:$B$610,巡逻产出!$C$311:$C$610)*1.3 -> 0 | L33: =OFFSET(产销汇总!$C$1,MATCH(L$27,产销汇总!$C$2:$C$8,0),$C$26)*(_xlfn.XLOOKUP(MAX(1,INT(C33/10-6/10)),组队产出!$B$24:$B$39,组队产出!$D$24:$D$39))+OFFSET(产销汇总!$C$1,MATCH(L$27,产销汇总!$C$2:$C$8,0),$C$26)*(_xlfn.XLOOKUP(MAX(1,INT(C33/10-6/10)),组队产出!$B$24:$B$39,组队产出!$C$24:$C$39)) -> 4776 | M33: =(OFFSET(产销汇总!$C$1,MATCH(M$27,产销汇总!$C$2:$C$8,0),$C$26)*_xlfn.XLOOKUP(C33,巡逻产出!$B$311:$B$610,巡逻产出!$D$311:$D$610))*$M$24 -> 6115.2 | N33: =OFFSET(产销汇总!$C$1,MATCH(L$27,产销汇总!$C$2:$C$8,0),$C$26)*(_xlfn.XLOOKUP(MAX(1,INT(C33/10-6/10)),组队产出!$B$24:$B$39,组队产出!$S$24:$S$39)) -> 6138 | O33: =任务!$D$36 -> 2457.1429 | P33: =INT(300*10/7) -> 428 | Q33: =IF(MOD(B33,7)=1,500,0)+1000+IF(AND($C$26=4,B33<=0),40000,0) -> 1000 | R33: =R32 -> 2000 | S33: =IFERROR(OFFSET(金币本!$E$2,MATCH(C33,金币本!$F$3:$F$302,1),0)*IF($C$26=1,2,3),0) -> 13500 | T33: =SUM($J$28:S33)+SUM(D33:I33) -> 610707.26 | U33: =T33 -> 610707.26 | V33: =SUM(W33:Y33) -> 625750 | W33: =OFFSET(装备强化!$U$6,MATCH(图纸产出设计!V34/6*W$26,装备强化!$T$7:$T$306,1),0)*6 -> 482400 | X33: 47350 | Y33: =Y32+$Y$28*Z33 -> 96000 | Z33: 1 | AA33: =U33/V33 -> 0.97596046 | AB33: =U33-V33 -> -15042.743 | AC33: =SUMIFS(装备强化!$Q$7:$Q$306,装备强化!$M$7:$M$306,"<="&MATCH(U33/6,装备强化!$U$7:$U$306,1),装备强化!$M$7:$M$306,">="&MATCH(V33/6,装备强化!$U$7:$U$306,1))*6 -> 744 | AD33: =AC33/B33 -> 124
B34: 7 | C34: =OFFSET(产销汇总!$C$12,$B34,$C$26) -> 60 | D34: =D33 -> 14100 | E34: =(SUMIF(主线推图!$B$4:$B$303,"<"&C34,主线推图!$M$4:$M$303)+SUMIF(主线宝箱!$B$320:$B$620,"<"&C34,主线宝箱!$L$320:$L$620)+SUMIF(主线宝箱!$B$320:$B$620,"<"&C34,主线宝箱!$X$320:$X$620)+SUMIF(主线宝箱!$B$320:$B$620,"<"&C34,主线宝箱!$AL$320:$AL$620)) -> 103200 | F34: =SUMIF(组队产出!$B$24:$B$39,"<="&MAX(1,INT(C34/10-0.6)),组队产出!$R$24:$R$39) -> 28500 | G34: =SUMIF(运营活动!$O$3:$O$27,"<="&C34,运营活动!$P$3:$P$27) -> 12000 | H34: =OFFSET(产销汇总!$AM$12,B34,$C$26)*24 -> 70632 | I34: =SUMIF(金币本!$F$2:$F$52,"<="&C34,金币本!$D$2:$D$52) -> 184000 | J34: =OFFSET(产销汇总!$C$1,MATCH(J$27,产销汇总!$C$2:$C$8,0),$C$26)*(_xlfn.XLOOKUP(C34,主线推图!$B$313:$B$612,主线推图!$C$313:$C$612)+_xlfn.XLOOKUP(C34,主线推图!$B$313:$B$612,主线推图!$D$313:$D$612)) -> 8756 | K34: =OFFSET(产销汇总!$C$1,MATCH(K$27,产销汇总!$C$2:$C$8,0),$C$26)*_xlfn.XLOOKUP(C34,巡逻产出!$B$311:$B$610,巡逻产出!$C$311:$C$610)*1.3 -> 0 | L34: =OFFSET(产销汇总!$C$1,MATCH(L$27,产销汇总!$C$2:$C$8,0),$C$26)*(_xlfn.XLOOKUP(MAX(1,INT(C34/10-6/10)),组队产出!$B$24:$B$39,组队产出!$D$24:$D$39))+OFFSET(产销汇总!$C$1,MATCH(L$27,产销汇总!$C$2:$C$8,0),$C$26)*(_xlfn.XLOOKUP(MAX(1,INT(C34/10-6/10)),组队产出!$B$24:$B$39,组队产出!$C$24:$C$39)) -> 4776 | M34: =(OFFSET(产销汇总!$C$1,MATCH(M$27,产销汇总!$C$2:$C$8,0),$C$26)*_xlfn.XLOOKUP(C34,巡逻产出!$B$311:$B$610,巡逻产出!$D$311:$D$610))*$M$24 -> 6208.8 | N34: =OFFSET(产销汇总!$C$1,MATCH(L$27,产销汇总!$C$2:$C$8,0),$C$26)*(_xlfn.XLOOKUP(MAX(1,INT(C34/10-6/10)),组队产出!$B$24:$B$39,组队产出!$S$24:$S$39)) -> 6138 | O34: =任务!$D$36 -> 2457.1429 | P34: =INT(300*10/7) -> 428 | Q34: =IF(MOD(B34,7)=1,500,0)+1000+IF(AND($C$26=4,B34<=0),40000,0) -> 1000 | R34: =R33 -> 2000 | S34: =IFERROR(OFFSET(金币本!$E$2,MATCH(C34,金币本!$F$3:$F$302,1),0)*IF($C$26=1,2,3),0) -> 14250 | T34: =SUM($J$28:S34)+SUM(D34:I34) -> 692209.2 | U34: =T34 -> 692209.2 | V34: =SUM(W34:Y34) -> 696590 | W34: =OFFSET(装备强化!$U$6,MATCH(图纸产出设计!V35/6*W$26,装备强化!$T$7:$T$306,1),0)*6 -> 529200 | X34: 55390 | Y34: =Y33+$Y$28*Z34 -> 112000 | Z34: 1 | AA34: =U34/V34 -> 0.99371108 | AB34: =U34-V34 -> -4380.8 | AC34: =SUMIFS(装备强化!$Q$7:$Q$306,装备强化!$M$7:$M$306,"<="&MATCH(U34/6,装备强化!$U$7:$U$306,1),装备强化!$M$7:$M$306,">="&MATCH(V34/6,装备强化!$U$7:$U$306,1))*6 -> 792 | AD34: =AC34/B34 -> 113.14286
B35: 8 | C35: =OFFSET(产销汇总!$C$12,$B35,$C$26) -> 63 | D35: =D34 -> 14100 | E35: =(SUMIF(主线推图!$B$4:$B$303,"<"&C35,主线推图!$M$4:$M$303)+SUMIF(主线宝箱!$B$320:$B$620,"<"&C35,主线宝箱!$L$320:$L$620)+SUMIF(主线宝箱!$B$320:$B$620,"<"&C35,主线宝箱!$X$320:$X$620)+SUMIF(主线宝箱!$B$320:$B$620,"<"&C35,主线宝箱!$AL$320:$AL$620)) -> 108600 | F35: =SUMIF(组队产出!$B$24:$B$39,"<="&MAX(1,INT(C35/10-0.6)),组队产出!$R$24:$R$39) -> 28500 | G35: =SUMIF(运营活动!$O$3:$O$27,"<="&C35,运营活动!$P$3:$P$27) -> 12000 | H35: =OFFSET(产销汇总!$AM$12,B35,$C$26)*24 -> 77880 | I35: =SUMIF(金币本!$F$2:$F$52,"<="&C35,金币本!$D$2:$D$52) -> 204000 | J35: =OFFSET(产销汇总!$C$1,MATCH(J$27,产销汇总!$C$2:$C$8,0),$C$26)*(_xlfn.XLOOKUP(C35,主线推图!$B$313:$B$612,主线推图!$C$313:$C$612)+_xlfn.XLOOKUP(C35,主线推图!$B$313:$B$612,主线推图!$D$313:$D$612)) -> 8888 | K35: =OFFSET(产销汇总!$C$1,MATCH(K$27,产销汇总!$C$2:$C$8,0),$C$26)*_xlfn.XLOOKUP(C35,巡逻产出!$B$311:$B$610,巡逻产出!$C$311:$C$610)*1.3 -> 0 | L35: =OFFSET(产销汇总!$C$1,MATCH(L$27,产销汇总!$C$2:$C$8,0),$C$26)*(_xlfn.XLOOKUP(MAX(1,INT(C35/10-6/10)),组队产出!$B$24:$B$39,组队产出!$D$24:$D$39))+OFFSET(产销汇总!$C$1,MATCH(L$27,产销汇总!$C$2:$C$8,0),$C$26)*(_xlfn.XLOOKUP(MAX(1,INT(C35/10-6/10)),组队产出!$B$24:$B$39,组队产出!$C$24:$C$39)) -> 4776 | M35: =(OFFSET(产销汇总!$C$1,MATCH(M$27,产销汇总!$C$2:$C$8,0),$C$26)*_xlfn.XLOOKUP(C35,巡逻产出!$B$311:$B$610,巡逻产出!$D$311:$D$610))*$M$24 -> 6302.4 | N35: =OFFSET(产销汇总!$C$1,MATCH(L$27,产销汇总!$C$2:$C$8,0),$C$26)*(_xlfn.XLOOKUP(MAX(1,INT(C35/10-6/10)),组队产出!$B$24:$B$39,组队产出!$S$24:$S$39)) -> 6138 | O35: =任务!$D$36 -> 2457.1429 | P35: =INT(300*10/7) -> 428 | Q35: =IF(MOD(B35,7)=1,500,0)+1000+IF(AND($C$26=4,B35<=0),40000,0) -> 1500 | R35: =R34 -> 2000 | S35: =IFERROR(OFFSET(金币本!$E$2,MATCH(C35,金币本!$F$3:$F$302,1),0)*IF($C$26=1,2,3),0) -> 15000 | T35: =SUM($J$28:S35)+SUM(D35:I35) -> 772346.74 | U35: =T35 -> 772346.74 | V35: =SUM(W35:Y35) -> 787660 | W35: =OFFSET(装备强化!$U$6,MATCH(图纸产出设计!V36/6*W$26,装备强化!$T$7:$T$306,1),0)*6 -> 579600 | X35: 64060 | Y35: =Y34+$Y$28*Z35 -> 144000 | Z35: 2 | AA35: =U35/V35 -> 0.98055854 | AB35: =U35-V35 -> -15313.257 | AC35: =SUMIFS(装备强化!$Q$7:$Q$306,装备强化!$M$7:$M$306,"<="&MATCH(U35/6,装备强化!$U$7:$U$306,1),装备强化!$M$7:$M$306,">="&MATCH(V35/6,装备强化!$U$7:$U$306,1))*6 -> 864 | AD35: =AC35/B35 -> 108
B36: 9 | C36: =OFFSET(产销汇总!$C$12,$B36,$C$26) -> 66 | D36: =D35 -> 14100 | E36: =(SUMIF(主线推图!$B$4:$B$303,"<"&C36,主线推图!$M$4:$M$303)+SUMIF(主线宝箱!$B$320:$B$620,"<"&C36,主线宝箱!$L$320:$L$620)+SUMIF(主线宝箱!$B$320:$B$620,"<"&C36,主线宝箱!$X$320:$X$620)+SUMIF(主线宝箱!$B$320:$B$620,"<"&C36,主线宝箱!$AL$320:$AL$620)) -> 114000 | F36: =SUMIF(组队产出!$B$24:$B$39,"<="&MAX(1,INT(C36/10-0.6)),组队产出!$R$24:$R$39) -> 36000 | G36: =SUMIF(运营活动!$O$3:$O$27,"<="&C36,运营活动!$P$3:$P$27) -> 14000 | H36: =OFFSET(产销汇总!$AM$12,B36,$C$26)*24 -> 85128 | I36: =SUMIF(金币本!$F$2:$F$52,"<="&C36,金币本!$D$2:$D$52) -> 204000 | J36: =OFFSET(产销汇总!$C$1,MATCH(J$27,产销汇总!$C$2:$C$8,0),$C$26)*(_xlfn.XLOOKUP(C36,主线推图!$B$313:$B$612,主线推图!$C$313:$C$612)+_xlfn.XLOOKUP(C36,主线推图!$B$313:$B$612,主线推图!$D$313:$D$612)) -> 9020 | K36: =OFFSET(产销汇总!$C$1,MATCH(K$27,产销汇总!$C$2:$C$8,0),$C$26)*_xlfn.XLOOKUP(C36,巡逻产出!$B$311:$B$610,巡逻产出!$C$311:$C$610)*1.3 -> 0 | L36: =OFFSET(产销汇总!$C$1,MATCH(L$27,产销汇总!$C$2:$C$8,0),$C$26)*(_xlfn.XLOOKUP(MAX(1,INT(C36/10-6/10)),组队产出!$B$24:$B$39,组队产出!$D$24:$D$39))+OFFSET(产销汇总!$C$1,MATCH(L$27,产销汇总!$C$2:$C$8,0),$C$26)*(_xlfn.XLOOKUP(MAX(1,INT(C36/10-6/10)),组队产出!$B$24:$B$39,组队产出!$C$24:$C$39)) -> 5016 | M36: =(OFFSET(产销汇总!$C$1,MATCH(M$27,产销汇总!$C$2:$C$8,0),$C$26)*_xlfn.XLOOKUP(C36,巡逻产出!$B$311:$B$610,巡逻产出!$D$311:$D$610))*$M$24 -> 6396 | N36: =OFFSET(产销汇总!$C$1,MATCH(L$27,产销汇总!$C$2:$C$8,0),$C$26)*(_xlfn.XLOOKUP(MAX(1,INT(C36/10-6/10)),组队产出!$B$24:$B$39,组队产出!$S$24:$S$39)) -> 6474 | O36: =任务!$D$36 -> 2457.1429 | P36: =INT(300*10/7) -> 428 | Q36: =IF(MOD(B36,7)=1,500,0)+1000+IF(AND($C$26=4,B36<=0),40000,0) -> 1000 | R36: =R35 -> 2000 | S36: =IFERROR(OFFSET(金币本!$E$2,MATCH(C36,金币本!$F$3:$F$302,1),0)*IF($C$26=1,2,3),0) -> 15000 | T36: =SUM($J$28:S36)+SUM(D36:I36) -> 842285.89 | U36: =T36 -> 842285.89 | V36: =SUM(W36:Y36) -> 857760 | W36: =OFFSET(装备强化!$U$6,MATCH(图纸产出设计!V37/6*W$26,装备强化!$T$7:$T$306,1),0)*6 -> 608400 | X36: 73360 | Y36: =Y35+$Y$28*Z36 -> 176000 | Z36: =Z35 -> 2 | AA36: =U36/V36 -> 0.98195986 | AB36: =U36-V36 -> -15474.114 | AC36: =SUMIFS(装备强化!$Q$7:$Q$306,装备强化!$M$7:$M$306,"<="&MATCH(U36/6,装备强化!$U$7:$U$306,1),装备强化!$M$7:$M$306,">="&MATCH(V36/6,装备强化!$U$7:$U$306,1))*6 -> 912 | AD36: =AC36/B36 -> 101.33333
B37: 10 | C37: =OFFSET(产销汇总!$C$12,$B37,$C$26) -> 69 | D37: =D36 -> 14100 | E37: =(SUMIF(主线推图!$B$4:$B$303,"<"&C37,主线推图!$M$4:$M$303)+SUMIF(主线宝箱!$B$320:$B$620,"<"&C37,主线宝箱!$L$320:$L$620)+SUMIF(主线宝箱!$B$320:$B$620,"<"&C37,主线宝箱!$X$320:$X$620)+SUMIF(主线宝箱!$B$320:$B$620,"<"&C37,主线宝箱!$AL$320:$AL$620)) -> 119400 | F37: =SUMIF(组队产出!$B$24:$B$39,"<="&MAX(1,INT(C37/10-0.6)),组队产出!$R$24:$R$39) -> 36000 | G37: =SUMIF(运营活动!$O$3:$O$27,"<="&C37,运营活动!$P$3:$P$27) -> 16000 | H37: =OFFSET(产销汇总!$AM$12,B37,$C$26)*24 -> 92376 | I37: =SUMIF(金币本!$F$2:$F$52,"<="&C37,金币本!$D$2:$D$52) -> 225000 | J37: =OFFSET(产销汇总!$C$1,MATCH(J$27,产销汇总!$C$2:$C$8,0),$C$26)*(_xlfn.XLOOKUP(C37,主线推图!$B$313:$B$612,主线推图!$C$313:$C$612)+_xlfn.XLOOKUP(C37,主线推图!$B$313:$B$612,主线推图!$D$313:$D$612)) -> 9152 | K37: =OFFSET(产销汇总!$C$1,MATCH(K$27,产销汇总!$C$2:$C$8,0),$C$26)*_xlfn.XLOOKUP(C37,巡逻产出!$B$311:$B$610,巡逻产出!$C$311:$C$610)*1.3 -> 0 | L37: =OFFSET(产销汇总!$C$1,MATCH(L$27,产销汇总!$C$2:$C$8,0),$C$26)*(_xlfn.XLOOKUP(MAX(1,INT(C37/10-6/10)),组队产出!$B$24:$B$39,组队产出!$D$24:$D$39))+OFFSET(产销汇总!$C$1,MATCH(L$27,产销汇总!$C$2:$C$8,0),$C$26)*(_xlfn.XLOOKUP(MAX(1,INT(C37/10-6/10)),组队产出!$B$24:$B$39,组队产出!$C$24:$C$39)) -> 5016 | M37: =(OFFSET(产销汇总!$C$1,MATCH(M$27,产销汇总!$C$2:$C$8,0),$C$26)*_xlfn.XLOOKUP(C37,巡逻产出!$B$311:$B$610,巡逻产出!$D$311:$D$610))*$M$24 -> 6489.6 | N37: =OFFSET(产销汇总!$C$1,MATCH(L$27,产销汇总!$C$2:$C$8,0),$C$26)*(_xlfn.XLOOKUP(MAX(1,INT(C37/10-6/10)),组队产出!$B$24:$B$39,组队产出!$S$24:$S$39)) -> 6474 | O37: =任务!$D$36 -> 2457.1429 | P37: =INT(300*10/7) -> 428 | Q37: =IF(MOD(B37,7)=1,500,0)+1000+IF(AND($C$26=4,B37<=0),40000,0) -> 1000 | R37: =R36 -> 2000 | S37: =IFERROR(OFFSET(金币本!$E$2,MATCH(C37,金币本!$F$3:$F$302,1),0)*IF($C$26=1,2,3),0) -> 15750 | T37: =SUM($J$28:S37)+SUM(D37:I37) -> 926700.63 | U37: =T37 -> 926700.63 | V37: =SUM(W37:Y37) -> 953910 | W37: =OFFSET(装备强化!$U$6,MATCH(图纸产出设计!V38/6*W$26,装备强化!$T$7:$T$306,1),0)*6 -> 666000 | X37: 79910 | Y37: =Y36+$Y$28*Z37 -> 208000 | Z37: =Z36 -> 2 | AA37: =U37/V37 -> 0.97147596 | AB37: =U37-V37 -> -27209.371 | AC37: =SUMIFS(装备强化!$Q$7:$Q$306,装备强化!$M$7:$M$306,"<="&MATCH(U37/6,装备强化!$U$7:$U$306,1),装备强化!$M$7:$M$306,">="&MATCH(V37/6,装备强化!$U$7:$U$306,1))*6 -> 960 | AD37: =AC37/B37 -> 96
B38: 11 | C38: =OFFSET(产销汇总!$C$12,$B38,$C$26) -> 73 | D38: =D37 -> 14100 | E38: =(SUMIF(主线推图!$B$4:$B$303,"<"&C38,主线推图!$M$4:$M$303)+SUMIF(主线宝箱!$B$320:$B$620,"<"&C38,主线宝箱!$L$320:$L$620)+SUMIF(主线宝箱!$B$320:$B$620,"<"&C38,主线宝箱!$X$320:$X$620)+SUMIF(主线宝箱!$B$320:$B$620,"<"&C38,主线宝箱!$AL$320:$AL$620)) -> 126600 | F38: =SUMIF(组队产出!$B$24:$B$39,"<="&MAX(1,INT(C38/10-0.6)),组队产出!$R$24:$R$39) -> 36000 | G38: =SUMIF(运营活动!$O$3:$O$27,"<="&C38,运营活动!$P$3:$P$27) -> 18000 | H38: =OFFSET(产销汇总!$AM$12,B38,$C$26)*24 -> 99624 | I38: =SUMIF(金币本!$F$2:$F$52,"<="&C38,金币本!$D$2:$D$52) -> 247000 | J38: =OFFSET(产销汇总!$C$1,MATCH(J$27,产销汇总!$C$2:$C$8,0),$C$26)*(_xlfn.XLOOKUP(C38,主线推图!$B$313:$B$612,主线推图!$C$313:$C$612)+_xlfn.XLOOKUP(C38,主线推图!$B$313:$B$612,主线推图!$D$313:$D$612)) -> 9328 | K38: =OFFSET(产销汇总!$C$1,MATCH(K$27,产销汇总!$C$2:$C$8,0),$C$26)*_xlfn.XLOOKUP(C38,巡逻产出!$B$311:$B$610,巡逻产出!$C$311:$C$610)*1.3 -> 0 | L38: =OFFSET(产销汇总!$C$1,MATCH(L$27,产销汇总!$C$2:$C$8,0),$C$26)*(_xlfn.XLOOKUP(MAX(1,INT(C38/10-6/10)),组队产出!$B$24:$B$39,组队产出!$D$24:$D$39))+OFFSET(产销汇总!$C$1,MATCH(L$27,产销汇总!$C$2:$C$8,0),$C$26)*(_xlfn.XLOOKUP(MAX(1,INT(C38/10-6/10)),组队产出!$B$24:$B$39,组队产出!$C$24:$C$39)) -> 5016 | M38: =(OFFSET(产销汇总!$C$1,MATCH(M$27,产销汇总!$C$2:$C$8,0),$C$26)*_xlfn.XLOOKUP(C38,巡逻产出!$B$311:$B$610,巡逻产出!$D$311:$D$610))*$M$24 -> 6614.4 | N38: =OFFSET(产销汇总!$C$1,MATCH(L$27,产销汇总!$C$2:$C$8,0),$C$26)*(_xlfn.XLOOKUP(MAX(1,INT(C38/10-6/10)),组队产出!$B$24:$B$39,组队产出!$S$24:$S$39)) -> 6474 | O38: =任务!$D$36 -> 2457.1429 | P38: =INT(300*10/7) -> 428 | Q38: =IF(MOD(B38,7)=1,500,0)+1000+IF(AND($C$26=4,B38<=0),40000,0) -> 1000 | R38: =R37 -> 2000 | S38: =IFERROR(OFFSET(金币本!$E$2,MATCH(C38,金币本!$F$3:$F$302,1),0)*IF($C$26=1,2,3),0) -> 16500 | T38: =SUM($J$28:S38)+SUM(D38:I38) -> 1014966.2 | U38: =T38 -> 1014966.2 | V38: =SUM(W38:Y38) -> 1057540 | W38: =OFFSET(装备强化!$U$6,MATCH(图纸产出设计!V39/6*W$26,装备强化!$T$7:$T$306,1),0)*6 -> 730800 | X38: 86740 | Y38: =Y37+$Y$28*Z38 -> 240000 | Z38: =Z37 -> 2 | AA38: =U38/V38 -> 0.95974258 | AB38: =U38-V38 -> -42573.829 | AC38: =SUMIFS(装备强化!$Q$7:$Q$306,装备强化!$M$7:$M$306,"<="&MATCH(U38/6,装备强化!$U$7:$U$306,1),装备强化!$M$7:$M$306,">="&MATCH(V38/6,装备强化!$U$7:$U$306,1))*6 -> 0 | AD38: =AC38/B38 -> 0
B39: 12 | C39: =OFFSET(产销汇总!$C$12,$B39,$C$26) -> 75 | D39: =D38 -> 14100 | E39: =(SUMIF(主线推图!$B$4:$B$303,"<"&C39,主线推图!$M$4:$M$303)+SUMIF(主线宝箱!$B$320:$B$620,"<"&C39,主线宝箱!$L$320:$L$620)+SUMIF(主线宝箱!$B$320:$B$620,"<"&C39,主线宝箱!$X$320:$X$620)+SUMIF(主线宝箱!$B$320:$B$620,"<"&C39,主线宝箱!$AL$320:$AL$620)) -> 130200 | F39: =SUMIF(组队产出!$B$24:$B$39,"<="&MAX(1,INT(C39/10-0.6)),组队产出!$R$24:$R$39) -> 36000 | G39: =SUMIF(运营活动!$O$3:$O$27,"<="&C39,运营活动!$P$3:$P$27) -> 18000 | H39: =OFFSET(产销汇总!$AM$12,B39,$C$26)*24 -> 106872 | I39: =SUMIF(金币本!$F$2:$F$52,"<="&C39,金币本!$D$2:$D$52) -> 270000 | J39: =OFFSET(产销汇总!$C$1,MATCH(J$27,产销汇总!$C$2:$C$8,0),$C$26)*(_xlfn.XLOOKUP(C39,主线推图!$B$313:$B$612,主线推图!$C$313:$C$612)+_xlfn.XLOOKUP(C39,主线推图!$B$313:$B$612,主线推图!$D$313:$D$612)) -> 9416 | K39: =OFFSET(产销汇总!$C$1,MATCH(K$27,产销汇总!$C$2:$C$8,0),$C$26)*_xlfn.XLOOKUP(C39,巡逻产出!$B$311:$B$610,巡逻产出!$C$311:$C$610)*1.3 -> 0 | L39: =OFFSET(产销汇总!$C$1,MATCH(L$27,产销汇总!$C$2:$C$8,0),$C$26)*(_xlfn.XLOOKUP(MAX(1,INT(C39/10-6/10)),组队产出!$B$24:$B$39,组队产出!$D$24:$D$39))+OFFSET(产销汇总!$C$1,MATCH(L$27,产销汇总!$C$2:$C$8,0),$C$26)*(_xlfn.XLOOKUP(MAX(1,INT(C39/10-6/10)),组队产出!$B$24:$B$39,组队产出!$C$24:$C$39)) -> 5016 | M39: =(OFFSET(产销汇总!$C$1,MATCH(M$27,产销汇总!$C$2:$C$8,0),$C$26)*_xlfn.XLOOKUP(C39,巡逻产出!$B$311:$B$610,巡逻产出!$D$311:$D$610))*$M$24 -> 6676.8 | N39: =OFFSET(产销汇总!$C$1,MATCH(L$27,产销汇总!$C$2:$C$8,0),$C$26)*(_xlfn.XLOOKUP(MAX(1,INT(C39/10-6/10)),组队产出!$B$24:$B$39,组队产出!$S$24:$S$39)) -> 6474 | O39: =任务!$D$36 -> 2457.1429 | P39: =INT(300*10/7) -> 428 | Q39: =IF(MOD(B39,7)=1,500,0)+1000+IF(AND($C$26=4,B39<=0),40000,0) -> 1000 | R39: =R38 -> 2000 | S39: =IFERROR(OFFSET(金币本!$E$2,MATCH(C39,金币本!$F$3:$F$302,1),0)*IF($C$26=1,2,3),0) -> 17250 | T39: =SUM($J$28:S39)+SUM(D39:I39) -> 1099532.1 | U39: =T39 -> 1099532.1 | V39: =SUM(W39:Y39) -> 1129050 | W39: =OFFSET(装备强化!$U$6,MATCH(图纸产出设计!V40/6*W$26,装备强化!$T$7:$T$306,1),0)*6 -> 763200 | X39: 93850 | Y39: =Y38+$Y$28*Z39 -> 272000 | Z39: =Z38 -> 2 | AA39: =U39/V39 -> 0.973856 | AB39: =U39-V39 -> -29517.886 | AC39: =SUMIFS(装备强化!$Q$7:$Q$306,装备强化!$M$7:$M$306,"<="&MATCH(U39/6,装备强化!$U$7:$U$306,1),装备强化!$M$7:$M$306,">="&MATCH(V39/6,装备强化!$U$7:$U$306,1))*6 -> 1056 | AD39: =AC39/B39 -> 88
B40: 13 | C40: =OFFSET(产销汇总!$C$12,$B40,$C$26) -> 77 | D40: =D39 -> 14100 | E40: =(SUMIF(主线推图!$B$4:$B$303,"<"&C40,主线推图!$M$4:$M$303)+SUMIF(主线宝箱!$B$320:$B$620,"<"&C40,主线宝箱!$L$320:$L$620)+SUMIF(主线宝箱!$B$320:$B$620,"<"&C40,主线宝箱!$X$320:$X$620)+SUMIF(主线宝箱!$B$320:$B$620,"<"&C40,主线宝箱!$AL$320:$AL$620)) -> 133800 | F40: =SUMIF(组队产出!$B$24:$B$39,"<="&MAX(1,INT(C40/10-0.6)),组队产出!$R$24:$R$39) -> 45000 | G40: =SUMIF(运营活动!$O$3:$O$27,"<="&C40,运营活动!$P$3:$P$27) -> 20000 | H40: =OFFSET(产销汇总!$AM$12,B40,$C$26)*24 -> 114120 | I40: =SUMIF(金币本!$F$2:$F$52,"<="&C40,金币本!$D$2:$D$52) -> 270000 | J40: =OFFSET(产销汇总!$C$1,MATCH(J$27,产销汇总!$C$2:$C$8,0),$C$26)*(_xlfn.XLOOKUP(C40,主线推图!$B$313:$B$612,主线推图!$C$313:$C$612)+_xlfn.XLOOKUP(C40,主线推图!$B$313:$B$612,主线推图!$D$313:$D$612)) -> 9504 | K40: =OFFSET(产销汇总!$C$1,MATCH(K$27,产销汇总!$C$2:$C$8,0),$C$26)*_xlfn.XLOOKUP(C40,巡逻产出!$B$311:$B$610,巡逻产出!$C$311:$C$610)*1.3 -> 0 | L40: =OFFSET(产销汇总!$C$1,MATCH(L$27,产销汇总!$C$2:$C$8,0),$C$26)*(_xlfn.XLOOKUP(MAX(1,INT(C40/10-6/10)),组队产出!$B$24:$B$39,组队产出!$D$24:$D$39))+OFFSET(产销汇总!$C$1,MATCH(L$27,产销汇总!$C$2:$C$8,0),$C$26)*(_xlfn.XLOOKUP(MAX(1,INT(C40/10-6/10)),组队产出!$B$24:$B$39,组队产出!$C$24:$C$39)) -> 5256 | M40: =(OFFSET(产销汇总!$C$1,MATCH(M$27,产销汇总!$C$2:$C$8,0),$C$26)*_xlfn.XLOOKUP(C40,巡逻产出!$B$311:$B$610,巡逻产出!$D$311:$D$610))*$M$24 -> 6739.2 | N40: =OFFSET(产销汇总!$C$1,MATCH(L$27,产销汇总!$C$2:$C$8,0),$C$26)*(_xlfn.XLOOKUP(MAX(1,INT(C40/10-6/10)),组队产出!$B$24:$B$39,组队产出!$S$24:$S$39)) -> 8268 | O40: =任务!$D$36 -> 2457.1429 | P40: =INT(300*10/7) -> 428 | Q40: =IF(MOD(B40,7)=1,500,0)+1000+IF(AND($C$26=4,B40<=0),40000,0) -> 1000 | R40: =R39 -> 2000 | S40: =IFERROR(OFFSET(金币本!$E$2,MATCH(C40,金币本!$F$3:$F$302,1),0)*IF($C$26=1,2,3),0) -> 17250 | T40: =SUM($J$28:S40)+SUM(D40:I40) -> 1174282.5 | U40: =T40 -> 1174282.5 | V40: =SUM(W40:Y40) -> 1240440 | W40: =OFFSET(装备强化!$U$6,MATCH(图纸产出设计!V41/6*W$26,装备强化!$T$7:$T$306,1),0)*6 -> 835200 | X40: 101240 | Y40: =Y39+$Y$28*Z40 -> 304000 | Z40: =Z39 -> 2 | AA40: =U40/V40 -> 0.94666607 | AB40: =U40-V40 -> -66157.543 | AC40: =SUMIFS(装备强化!$Q$7:$Q$306,装备强化!$M$7:$M$306,"<="&MATCH(U40/6,装备强化!$U$7:$U$306,1),装备强化!$M$7:$M$306,">="&MATCH(V40/6,装备强化!$U$7:$U$306,1))*6 -> 0 | AD40: =AC40/B40 -> 0
B41: 14 | C41: =OFFSET(产销汇总!$C$12,$B41,$C$26) -> 80 | D41: =D40 -> 14100 | E41: =(SUMIF(主线推图!$B$4:$B$303,"<"&C41,主线推图!$M$4:$M$303)+SUMIF(主线宝箱!$B$320:$B$620,"<"&C41,主线宝箱!$L$320:$L$620)+SUMIF(主线宝箱!$B$320:$B$620,"<"&C41,主线宝箱!$X$320:$X$620)+SUMIF(主线宝箱!$B$320:$B$620,"<"&C41,主线宝箱!$AL$320:$AL$620)) -> 139200 | F41: =SUMIF(组队产出!$B$24:$B$39,"<="&MAX(1,INT(C41/10-0.6)),组队产出!$R$24:$R$39) -> 45000 | G41: =SUMIF(运营活动!$O$3:$O$27,"<="&C41,运营活动!$P$3:$P$27) -> 20000 | H41: =OFFSET(产销汇总!$AM$12,B41,$C$26)*24 -> 121392 | I41: =SUMIF(金币本!$F$2:$F$52,"<="&C41,金币本!$D$2:$D$52) -> 294000 | J41: =OFFSET(产销汇总!$C$1,MATCH(J$27,产销汇总!$C$2:$C$8,0),$C$26)*(_xlfn.XLOOKUP(C41,主线推图!$B$313:$B$612,主线推图!$C$313:$C$612)+_xlfn.XLOOKUP(C41,主线推图!$B$313:$B$612,主线推图!$D$313:$D$612)) -> 9636 | K41: =OFFSET(产销汇总!$C$1,MATCH(K$27,产销汇总!$C$2:$C$8,0),$C$26)*_xlfn.XLOOKUP(C41,巡逻产出!$B$311:$B$610,巡逻产出!$C$311:$C$610)*1.3 -> 0 | L41: =OFFSET(产销汇总!$C$1,MATCH(L$27,产销汇总!$C$2:$C$8,0),$C$26)*(_xlfn.XLOOKUP(MAX(1,INT(C41/10-6/10)),组队产出!$B$24:$B$39,组队产出!$D$24:$D$39))+OFFSET(产销汇总!$C$1,MATCH(L$27,产销汇总!$C$2:$C$8,0),$C$26)*(_xlfn.XLOOKUP(MAX(1,INT(C41/10-6/10)),组队产出!$B$24:$B$39,组队产出!$C$24:$C$39)) -> 5256 | M41: =(OFFSET(产销汇总!$C$1,MATCH(M$27,产销汇总!$C$2:$C$8,0),$C$26)*_xlfn.XLOOKUP(C41,巡逻产出!$B$311:$B$610,巡逻产出!$D$311:$D$610))*$M$24 -> 6832.8 | N41: =OFFSET(产销汇总!$C$1,MATCH(L$27,产销汇总!$C$2:$C$8,0),$C$26)*(_xlfn.XLOOKUP(MAX(1,INT(C41/10-6/10)),组队产出!$B$24:$B$39,组队产出!$S$24:$S$39)) -> 8268 | O41: =任务!$D$36 -> 2457.1429 | P41: =INT(300*10/7) -> 428 | Q41: =IF(MOD(B41,7)=1,500,0)+1000+IF(AND($C$26=4,B41<=0),40000,0) -> 1000 | R41: =R40 -> 2000 | S41: =IFERROR(OFFSET(金币本!$E$2,MATCH(C41,金币本!$F$3:$F$302,1),0)*IF($C$26=1,2,3),0) -> 18000 | T41: =SUM($J$28:S41)+SUM(D41:I41) -> 1264832.4 | U41: =T41 -> 1264832.4 | V41: =SUM(W41:Y41) -> 1319710 | W41: =OFFSET(装备强化!$U$6,MATCH(图纸产出设计!V42/6*W$26,装备强化!$T$7:$T$306,1),0)*6 -> 874800 | X41: 108910 | Y41: =Y40+$Y$28*Z41 -> 336000 | Z41: =Z40 -> 2 | AA41: =U41/V41 -> 0.95841692 | AB41: =U41-V41 -> -54877.6 | AC41: =SUMIFS(装备强化!$Q$7:$Q$306,装备强化!$M$7:$M$306,"<="&MATCH(U41/6,装备强化!$U$7:$U$306,1),装备强化!$M$7:$M$306,">="&MATCH(V41/6,装备强化!$U$7:$U$306,1))*6 -> 0 | AD41: =AC41/B41 -> 0
B42: 15 | C42: =OFFSET(产销汇总!$C$12,$B42,$C$26) -> 81.5 | D42: =D41 -> 14100 | E42: =(SUMIF(主线推图!$B$4:$B$303,"<"&C42,主线推图!$M$4:$M$303)+SUMIF(主线宝箱!$B$320:$B$620,"<"&C42,主线宝箱!$L$320:$L$620)+SUMIF(主线宝箱!$B$320:$B$620,"<"&C42,主线宝箱!$X$320:$X$620)+SUMIF(主线宝箱!$B$320:$B$620,"<"&C42,主线宝箱!$AL$320:$AL$620)) -> 142800 | F42: =SUMIF(组队产出!$B$24:$B$39,"<="&MAX(1,INT(C42/10-0.6)),组队产出!$R$24:$R$39) -> 45000 | G42: =SUMIF(运营活动!$O$3:$O$27,"<="&C42,运营活动!$P$3:$P$27) -> 20000 | H42: =OFFSET(产销汇总!$AM$12,B42,$C$26)*24 -> 128640 | I42: =SUMIF(金币本!$F$2:$F$52,"<="&C42,金币本!$D$2:$D$52) -> 294000 | J42: =OFFSET(产销汇总!$C$1,MATCH(J$27,产销汇总!$C$2:$C$8,0),$C$26)*(_xlfn.XLOOKUP(C42,主线推图!$B$313:$B$612,主线推图!$C$313:$C$612)+_xlfn.XLOOKUP(C42,主线推图!$B$313:$B$612,主线推图!$D$313:$D$612)) -> #N/A | K42: =OFFSET(产销汇总!$C$1,MATCH(K$27,产销汇总!$C$2:$C$8,0),$C$26)*_xlfn.XLOOKUP(C42,巡逻产出!$B$311:$B$610,巡逻产出!$C$311:$C$610)*1.3 -> #N/A | L42: =OFFSET(产销汇总!$C$1,MATCH(L$27,产销汇总!$C$2:$C$8,0),$C$26)*(_xlfn.XLOOKUP(MAX(1,INT(C42/10-6/10)),组队产出!$B$24:$B$39,组队产出!$D$24:$D$39))+OFFSET(产销汇总!$C$1,MATCH(L$27,产销汇总!$C$2:$C$8,0),$C$26)*(_xlfn.XLOOKUP(MAX(1,INT(C42/10-6/10)),组队产出!$B$24:$B$39,组队产出!$C$24:$C$39)) -> 5256 | M42: =(OFFSET(产销汇总!$C$1,MATCH(M$27,产销汇总!$C$2:$C$8,0),$C$26)*_xlfn.XLOOKUP(C42,巡逻产出!$B$311:$B$610,巡逻产出!$D$311:$D$610))*$M$24 -> #N/A | N42: =OFFSET(产销汇总!$C$1,MATCH(L$27,产销汇总!$C$2:$C$8,0),$C$26)*(_xlfn.XLOOKUP(MAX(1,INT(C42/10-6/10)),组队产出!$B$24:$B$39,组队产出!$S$24:$S$39)) -> 8268 | O42: =任务!$D$36 -> 2457.1429 | P42: =INT(300*10/7) -> 428 | Q42: =IF(MOD(B42,7)=1,500,0)+1000+IF(AND($C$26=4,B42<=0),40000,0) -> 1500 | R42: =R41 -> 2000 | S42: =IFERROR(OFFSET(金币本!$E$2,MATCH(C42,金币本!$F$3:$F$302,1),0)*IF($C$26=1,2,3),0) -> 18000 | T42: =SUM($J$28:S42)+SUM(D42:I42) -> #N/A | U42: =T42 -> #N/A | V42: =SUM(W42:Y42) -> #N/A | W42: =OFFSET(装备强化!$U$6,MATCH(图纸产出设计!V43/6*W$26,装备强化!$T$7:$T$306,1),0)*6 -> #N/A | X42: 112850 | Y42: =Y41+$Y$28*Z42 -> 368000 | Z42: =Z41 -> 2 | AA42: =U42/V42 -> #N/A | AB42: =U42-V42 -> #N/A | AC42: =SUMIFS(装备强化!$Q$7:$Q$306,装备强化!$M$7:$M$306,"<="&MATCH(U42/6,装备强化!$U$7:$U$306,1),装备强化!$M$7:$M$306,">="&MATCH(V42/6,装备强化!$U$7:$U$306,1))*6 -> 0 | AD42: =AC42/B42 -> 0
B43: 16 | C43: =OFFSET(产销汇总!$C$12,$B43,$C$26) -> 83 | D43: =D42 -> 14100 | E43: =(SUMIF(主线推图!$B$4:$B$303,"<"&C43,主线推图!$M$4:$M$303)+SUMIF(主线宝箱!$B$320:$B$620,"<"&C43,主线宝箱!$L$320:$L$620)+SUMIF(主线宝箱!$B$320:$B$620,"<"&C43,主线宝箱!$X$320:$X$620)+SUMIF(主线宝箱!$B$320:$B$620,"<"&C43,主线宝箱!$AL$320:$AL$620)) -> 144600 | F43: =SUMIF(组队产出!$B$24:$B$39,"<="&MAX(1,INT(C43/10-0.6)),组队产出!$R$24:$R$39) -> 45000 | G43: =SUMIF(运营活动!$O$3:$O$27,"<="&C43,运营活动!$P$3:$P$27) -> 20000 | H43: =OFFSET(产销汇总!$AM$12,B43,$C$26)*24 -> 135888 | I43: =SUMIF(金币本!$F$2:$F$52,"<="&C43,金币本!$D$2:$D$52) -> 319000 | J43: =OFFSET(产销汇总!$C$1,MATCH(J$27,产销汇总!$C$2:$C$8,0),$C$26)*(_xlfn.XLOOKUP(C43,主线推图!$B$313:$B$612,主线推图!$C$313:$C$612)+_xlfn.XLOOKUP(C43,主线推图!$B$313:$B$612,主线推图!$D$313:$D$612)) -> 9768 | K43: =OFFSET(产销汇总!$C$1,MATCH(K$27,产销汇总!$C$2:$C$8,0),$C$26)*_xlfn.XLOOKUP(C43,巡逻产出!$B$311:$B$610,巡逻产出!$C$311:$C$610)*1.3 -> 0 | L43: =OFFSET(产销汇总!$C$1,MATCH(L$27,产销汇总!$C$2:$C$8,0),$C$26)*(_xlfn.XLOOKUP(MAX(1,INT(C43/10-6/10)),组队产出!$B$24:$B$39,组队产出!$D$24:$D$39))+OFFSET(产销汇总!$C$1,MATCH(L$27,产销汇总!$C$2:$C$8,0),$C$26)*(_xlfn.XLOOKUP(MAX(1,INT(C43/10-6/10)),组队产出!$B$24:$B$39,组队产出!$C$24:$C$39)) -> 5256 | M43: =(OFFSET(产销汇总!$C$1,MATCH(M$27,产销汇总!$C$2:$C$8,0),$C$26)*_xlfn.XLOOKUP(C43,巡逻产出!$B$311:$B$610,巡逻产出!$D$311:$D$610))*$M$24 -> 6926.4 | N43: =OFFSET(产销汇总!$C$1,MATCH(L$27,产销汇总!$C$2:$C$8,0),$C$26)*(_xlfn.XLOOKUP(MAX(1,INT(C43/10-6/10)),组队产出!$B$24:$B$39,组队产出!$S$24:$S$39)) -> 8268 | O43: =任务!$D$36 -> 2457.1429 | P43: =INT(300*10/7) -> 428 | Q43: =IF(MOD(B43,7)=1,500,0)+1000+IF(AND($C$26=4,B43<=0),40000,0) -> 1000 | R43: =R42 -> 2000 | S43: =IFERROR(OFFSET(金币本!$E$2,MATCH(C43,金币本!$F$3:$F$302,1),0)*IF($C$26=1,2,3),0) -> 18750 | T43: =SUM($J$28:S43)+SUM(D43:I43) -> #N/A | U43: =T43 -> #N/A | V43: =SUM(W43:Y43) -> #N/A | W43: =OFFSET(装备强化!$U$6,MATCH(图纸产出设计!V44/6*W$26,装备强化!$T$7:$T$306,1),0)*6 -> #N/A | X43: 116860 | Y43: =Y42+$Y$28*Z43 -> 400000 | Z43: =Z42 -> 2 | AA43: =U43/V43 -> #N/A | AB43: =U43-V43 -> #N/A | AC43: =SUMIFS(装备强化!$Q$7:$Q$306,装备强化!$M$7:$M$306,"<="&MATCH(U43/6,装备强化!$U$7:$U$306,1),装备强化!$M$7:$M$306,">="&MATCH(V43/6,装备强化!$U$7:$U$306,1))*6 -> 0 | AD43: =AC43/B43 -> 0
B44: 17 | C44: =OFFSET(产销汇总!$C$12,$B44,$C$26) -> 84.5 | D44: =D43 -> 14100 | E44: =(SUMIF(主线推图!$B$4:$B$303,"<"&C44,主线推图!$M$4:$M$303)+SUMIF(主线宝箱!$B$320:$B$620,"<"&C44,主线宝箱!$L$320:$L$620)+SUMIF(主线宝箱!$B$320:$B$620,"<"&C44,主线宝箱!$X$320:$X$620)+SUMIF(主线宝箱!$B$320:$B$620,"<"&C44,主线宝箱!$AL$320:$AL$620)) -> 148200 | F44: =SUMIF(组队产出!$B$24:$B$39,"<="&MAX(1,INT(C44/10-0.6)),组队产出!$R$24:$R$39) -> 45000 | G44: =SUMIF(运营活动!$O$3:$O$27,"<="&C44,运营活动!$P$3:$P$27) -> 22500 | H44: =OFFSET(产销汇总!$AM$12,B44,$C$26)*24 -> 143136 | I44: =SUMIF(金币本!$F$2:$F$52,"<="&C44,金币本!$D$2:$D$52) -> 319000 | J44: =OFFSET(产销汇总!$C$1,MATCH(J$27,产销汇总!$C$2:$C$8,0),$C$26)*(_xlfn.XLOOKUP(C44,主线推图!$B$313:$B$612,主线推图!$C$313:$C$612)+_xlfn.XLOOKUP(C44,主线推图!$B$313:$B$612,主线推图!$D$313:$D$612)) -> #N/A | K44: =OFFSET(产销汇总!$C$1,MATCH(K$27,产销汇总!$C$2:$C$8,0),$C$26)*_xlfn.XLOOKUP(C44,巡逻产出!$B$311:$B$610,巡逻产出!$C$311:$C$610)*1.3 -> #N/A | L44: =OFFSET(产销汇总!$C$1,MATCH(L$27,产销汇总!$C$2:$C$8,0),$C$26)*(_xlfn.XLOOKUP(MAX(1,INT(C44/10-6/10)),组队产出!$B$24:$B$39,组队产出!$D$24:$D$39))+OFFSET(产销汇总!$C$1,MATCH(L$27,产销汇总!$C$2:$C$8,0),$C$26)*(_xlfn.XLOOKUP(MAX(1,INT(C44/10-6/10)),组队产出!$B$24:$B$39,组队产出!$C$24:$C$39)) -> 5256 | M44: =(OFFSET(产销汇总!$C$1,MATCH(M$27,产销汇总!$C$2:$C$8,0),$C$26)*_xlfn.XLOOKUP(C44,巡逻产出!$B$311:$B$610,巡逻产出!$D$311:$D$610))*$M$24 -> #N/A | N44: =OFFSET(产销汇总!$C$1,MATCH(L$27,产销汇总!$C$2:$C$8,0),$C$26)*(_xlfn.XLOOKUP(MAX(1,INT(C44/10-6/10)),组队产出!$B$24:$B$39,组队产出!$S$24:$S$39)) -> 8268 | O44: =任务!$D$36 -> 2457.1429 | P44: =INT(300*10/7) -> 428 | Q44: =IF(MOD(B44,7)=1,500,0)+1000+IF(AND($C$26=4,B44<=0),40000,0) -> 1000 | R44: =R43 -> 2000 | S44: =IFERROR(OFFSET(金币本!$E$2,MATCH(C44,金币本!$F$3:$F$302,1),0)*IF($C$26=1,2,3),0) -> 18750 | T44: =SUM($J$28:S44)+SUM(D44:I44) -> #N/A | U44: =T44 -> #N/A | V44: =SUM(W44:Y44) -> #N/A | W44: =OFFSET(装备强化!$U$6,MATCH(图纸产出设计!V45/6*W$26,装备强化!$T$7:$T$306,1),0)*6 -> #N/A | X44: 120940 | Y44: =Y43+$Y$28*Z44 -> 432000 | Z44: =Z43 -> 2 | AA44: =U44/V44 -> #N/A | AB44: =U44-V44 -> #N/A | AC44: =SUMIFS(装备强化!$Q$7:$Q$306,装备强化!$M$7:$M$306,"<="&MATCH(U44/6,装备强化!$U$7:$U$306,1),装备强化!$M$7:$M$306,">="&MATCH(V44/6,装备强化!$U$7:$U$306,1))*6 -> 0 | AD44: =AC44/B44 -> 0
B45: 18 | C45: =OFFSET(产销汇总!$C$12,$B45,$C$26) -> 86 | D45: =D44 -> 14100 | E45: =(SUMIF(主线推图!$B$4:$B$303,"<"&C45,主线推图!$M$4:$M$303)+SUMIF(主线宝箱!$B$320:$B$620,"<"&C45,主线宝箱!$L$320:$L$620)+SUMIF(主线宝箱!$B$320:$B$620,"<"&C45,主线宝箱!$X$320:$X$620)+SUMIF(主线宝箱!$B$320:$B$620,"<"&C45,主线宝箱!$AL$320:$AL$620)) -> 150000 | F45: =SUMIF(组队产出!$B$24:$B$39,"<="&MAX(1,INT(C45/10-0.6)),组队产出!$R$24:$R$39) -> 54000 | G45: =SUMIF(运营活动!$O$3:$O$27,"<="&C45,运营活动!$P$3:$P$27) -> 22500 | H45: =OFFSET(产销汇总!$AM$12,B45,$C$26)*24 -> 150384 | I45: =SUMIF(金币本!$F$2:$F$52,"<="&C45,金币本!$D$2:$D$52) -> 319000 | J45: =OFFSET(产销汇总!$C$1,MATCH(J$27,产销汇总!$C$2:$C$8,0),$C$26)*(_xlfn.XLOOKUP(C45,主线推图!$B$313:$B$612,主线推图!$C$313:$C$612)+_xlfn.XLOOKUP(C45,主线推图!$B$313:$B$612,主线推图!$D$313:$D$612)) -> 9900 | K45: =OFFSET(产销汇总!$C$1,MATCH(K$27,产销汇总!$C$2:$C$8,0),$C$26)*_xlfn.XLOOKUP(C45,巡逻产出!$B$311:$B$610,巡逻产出!$C$311:$C$610)*1.3 -> 0 | L45: =OFFSET(产销汇总!$C$1,MATCH(L$27,产销汇总!$C$2:$C$8,0),$C$26)*(_xlfn.XLOOKUP(MAX(1,INT(C45/10-6/10)),组队产出!$B$24:$B$39,组队产出!$D$24:$D$39))+OFFSET(产销汇总!$C$1,MATCH(L$27,产销汇总!$C$2:$C$8,0),$C$26)*(_xlfn.XLOOKUP(MAX(1,INT(C45/10-6/10)),组队产出!$B$24:$B$39,组队产出!$C$24:$C$39)) -> 5496 | M45: =(OFFSET(产销汇总!$C$1,MATCH(M$27,产销汇总!$C$2:$C$8,0),$C$26)*_xlfn.XLOOKUP(C45,巡逻产出!$B$311:$B$610,巡逻产出!$D$311:$D$610))*$M$24 -> 7020 | N45: =OFFSET(产销汇总!$C$1,MATCH(L$27,产销汇总!$C$2:$C$8,0),$C$26)*(_xlfn.XLOOKUP(MAX(1,INT(C45/10-6/10)),组队产出!$B$24:$B$39,组队产出!$S$24:$S$39)) -> 10062 | O45: =任务!$D$36 -> 2457.1429 | P45: =INT(300*10/7) -> 428 | Q45: =IF(MOD(B45,7)=1,500,0)+1000+IF(AND($C$26=4,B45<=0),40000,0) -> 1000 | R45: =R44 -> 2000 | S45: =IFERROR(OFFSET(金币本!$E$2,MATCH(C45,金币本!$F$3:$F$302,1),0)*IF($C$26=1,2,3),0) -> 18750 | T45: =SUM($J$28:S45)+SUM(D45:I45) -> #N/A | U45: =T45 -> #N/A | V45: =SUM(W45:Y45) -> #N/A | W45: =OFFSET(装备强化!$U$6,MATCH(图纸产出设计!V46/6*W$26,装备强化!$T$7:$T$306,1),0)*6 -> #N/A | X45: 125090 | Y45: =Y44+$Y$28*Z45 -> 464000 | Z45: =Z44 -> 2 | AA45: =U45/V45 -> #N/A | AB45: =U45-V45 -> #N/A | AC45: =SUMIFS(装备强化!$Q$7:$Q$306,装备强化!$M$7:$M$306,"<="&MATCH(U45/6,装备强化!$U$7:$U$306,1),装备强化!$M$7:$M$306,">="&MATCH(V45/6,装备强化!$U$7:$U$306,1))*6 -> 0 | AD45: =AC45/B45 -> 0
...

Sheet 图纸产出设计
B2: 生命周期 | C2: 60
B3: 总坑深 | C3: =SUM(C7:C23)*3 -> #N/A
B4: 战力换算 | C4: =OFFSET(装备强化!G6,MATCH(C3/3/6,装备强化!$T$7:$T$306,1),0)*6 -> #N/A
B6: 产出途径 | C6: 产出价值 | D6: 产出频率 | E6: 产出比例
B7: 挂机 | C7: =IF(D7="每日",SUMIF($B$29:$B$328,"<="&$C$2,OFFSET($C$29:$C$328,0,MATCH($B7,$D$28:$V$28,0))),SUMIF($B$29:$B$328,"="&$C$2,OFFSET($C$29:$C$328,0,MATCH($B7,$D$28:$V$28,0)))) -> #N/A | D7: 每日 | E7: =C7/SUM($C$7:$C$23) -> #N/A
B8: 公会 | C8: =IF(D8="每日",SUMIF($B$29:$B$328,"<="&$C$2,OFFSET($C$29:$C$328,0,MATCH($B8,$D$28:$V$28,0))),SUMIF($B$29:$B$328,"="&$C$2,OFFSET($C$29:$C$328,0,MATCH($B8,$D$28:$V$28,0)))) -> 7042.8571 | D8: 每日 | E8: =C8/SUM($C$7:$C$23) -> #N/A
B9: 商城购买 | C9: =IF(D9="每日",SUMIF($B$29:$B$328,"<="&$C$2,OFFSET($C$29:$C$328,0,MATCH($B9,$D$28:$V$28,0))),SUMIF($B$29:$B$328,"="&$C$2,OFFSET($C$29:$C$328,0,MATCH($B9,$D$28:$V$28,0)))) -> 5900 | D9: 每日 | E9: =C9/SUM($C$7:$C$23) -> #N/A
B10: 竞技场+公会商店 | C10: =IF(D10="每日",SUMIF($B$29:$B$328,"<="&$C$2,OFFSET($C$29:$C$328,0,MATCH($B10,$D$28:$V$28,0))),SUMIF($B$29:$B$328,"="&$C$2,OFFSET($C$29:$C$328,0,MATCH($B10,$D$28:$V$28,0)))) -> 8900 | D10: 每日 | E10: =C10/SUM($C$7:$C$23) -> #N/A
B11: 主线 | C11: =IF(D11="每日",SUMIF($B$29:$B$328,"<="&$C$2,OFFSET($C$29:$C$328,0,MATCH($B11,$D$28:$V$28,0))),SUMIF($B$29:$B$328,"="&$C$2,OFFSET($C$29:$C$328,0,MATCH($B11,$D$28:$V$28,0)))) -> #N/A | D11: 每日 | E11: =C11/SUM($C$7:$C$23) -> #N/A
B12: 竞技场 | C12: =IF(D12="每日",SUMIF($B$29:$B$328,"<="&$C$2,OFFSET($C$29:$C$328,0,MATCH($B12,$D$28:$V$28,0))),SUMIF($B$29:$B$328,"="&$C$2,OFFSET($C$29:$C$328,0,MATCH($B12,$D$28:$V$28,0)))) -> 10800 | D12: 每日 | E12: =C12/SUM($C$7:$C$23) -> #N/A
B13: 组队本 | C13: =IF(D13="每日",SUMIF($B$29:$B$328,"<="&$C$2,OFFSET($C$29:$C$328,0,MATCH($B13,$D$28:$V$28,0))),SUMIF($B$29:$B$328,"="&$C$2,OFFSET($C$29:$C$328,0,MATCH($B13,$D$28:$V$28,0)))) -> 5760 | D13: 每日 | E13: =C13/SUM($C$7:$C$23) -> #N/A
B14: 体力扫荡 | C14: =IF(D14="每日",SUMIF($B$29:$B$328,"<="&$C$2,OFFSET($C$29:$C$328,0,MATCH($B14,$D$28:$V$28,0))),SUMIF($B$29:$B$328,"="&$C$2,OFFSET($C$29:$C$328,0,MATCH($B14,$D$28:$V$28,0)))) -> #N/A | D14: 每日 | E14: =C14/SUM($C$7:$C$23) -> #N/A
B15: 主线宝箱 | C15: =IF(D15="每日",SUMIF($B$29:$B$328,"<="&$C$2,OFFSET($C$29:$C$328,0,MATCH($B15,$D$28:$V$28,0))),SUMIF($B$29:$B$328,"="&$C$2,OFFSET($C$29:$C$328,0,MATCH($B15,$D$28:$V$28,0)))) -> 5320 | D15: 一次性产出 | E15: =C15/SUM($C$7:$C$23) -> #N/A
B16: 个推礼包 | C16: =IF(D16="每日",SUMIF($B$29:$B$328,"<="&$C$2,OFFSET($C$29:$C$328,0,MATCH($B16,$D$28:$V$28,0))),SUMIF($B$29:$B$328,"="&$C$2,OFFSET($C$29:$C$328,0,MATCH($B16,$D$28:$V$28,0)))) -> 3890 | D16: 一次性产出 | E16: =C16/SUM($C$7:$C$23) -> #N/A
B17: 每日活跃 | C17: =IF(D17="每日",SUMIF($B$29:$B$328,"<="&$C$2,OFFSET($C$29:$C$328,0,MATCH($B17,$D$28:$V$28,0))),SUMIF($B$29:$B$328,"="&$C$2,OFFSET($C$29:$C$328,0,MATCH($B17,$D$28:$V$28,0)))) -> 2040 | D17: 每日 | E17: =C17/SUM($C$7:$C$23) -> #N/A
B18: 战令 | C18: =IF(D18="每日",SUMIF($B$29:$B$328,"<="&$C$2,OFFSET($C$29:$C$328,0,MATCH($B18,$D$28:$V$28,0))),SUMIF($B$29:$B$328,"="&$C$2,OFFSET($C$29:$C$328,0,MATCH($B18,$D$28:$V$28,0)))) -> 0 | D18: 每日 | E18: =C18/SUM($C$7:$C$23) -> #N/A
... B24: 协力宝箱 | C24: =IF(D24="每日",SUMIF($B$29:$B$328,"<="&$C$2,OFFSET($C$29:$C$328,0,MATCH($B24,$D$28:$V$28,0))),SUMIF($B$29:$B$328,"="&$C$2,OFFSET($C$29:$C$328,0,MATCH($B24,$D$28:$V$28,0)))) -> 102 | D24: 每日 | E24: =C24/SUM($C$7:$C$23) -> #N/A
B27: =金币平衡!B26 -> 大R | C27: =金币平衡!C26 -> 4 | D27: 一次性产出 | H27: 循环产出 | K27: 如果挂机砍一半 | P27: 体力消耗
B28: 天数 | C28: 关卡预期 | D28: 主线宝箱 | E28: 主线任务 | F28: 星铸之旅 | G28: 个推礼包 | H28: 主线 | I28: 体力扫荡 | J28: 组队本 | K28: 挂机 | L28: 竞技场 | M28: 每日活跃 | N28: 协力宝箱 | O28: 周签到战令 | P28: 战令 | Q28: 好朋友宝箱 | R28: 商城领取 | S28: 商城购买 | T28: 公会 | U28: 竞技场+公会商店 | V28: 总产出
B29: 1 | C29: =OFFSET(产销汇总!$C$12,$B29,$C$27) -> 30 | D29: =SUMIF(主线宝箱!$B$321:$B$620,"<="&C29,主线宝箱!$H$321:$H$620)+SUMIF(主线宝箱!$B$321:$B$620,"<="&C29,主线宝箱!$T$321:$T$620) -> 1200 | E29: 110 | F29: =0.225*100*5 -> 112.5 | G29: =IF(AND($C$27<3,B29>3),G28,SUMIF(图纸产出设计!$F$334:$F$342,"<="&B29,图纸产出设计!$C$334:$C$342)) -> 1590 | H29: =OFFSET(产销汇总!$C$1,MATCH(H$28,产销汇总!$C$2:$C$8,0),$C$27)*(_xlfn.XLOOKUP(C29,主线推图!$B$313:$B$612,主线推图!$G$313:$G$612)+_xlfn.XLOOKUP(C29,主线推图!$B$313:$B$612,主线推图!$H$313:$H$612)) -> 176 | I29: =OFFSET(产销汇总!$C$1,MATCH(I$28,产销汇总!$C$2:$C$8,0),$C$27)*_xlfn.XLOOKUP(C29,巡逻产出!$B$311:$B$610,巡逻产出!$H$311:$H$610) -> 0 | J29: =OFFSET(产销汇总!$C$1,MATCH(J$28,产销汇总!$C$2:$C$8,0),$C$27)*(_xlfn.XLOOKUP(MAX(1,INT(C29/10-6/10)),组队产出!$B$24:$B$39,组队产出!$J$24:$J$39)+_xlfn.XLOOKUP(MAX(1,INT(C29/10-6/10)),组队产出!$B$24:$B$39,组队产出!$K$24:$K$39)) -> 96 | K29: =OFFSET(产销汇总!$C$1,MATCH(K$28,产销汇总!$C$2:$C$8,0),$C$27)*_xlfn.XLOOKUP(C29,巡逻产出!$B$311:$B$610,巡逻产出!$I$311:$I$610)*IF($C$27=1,0.5,1) -> 312 | L29: =OFFSET(产销汇总!$C$1,MATCH(L$28,产销汇总!$C$2:$C$8,0),$C$27)*竞技场!$C$5 -> 180 | M29: =任务!$C$6+IF(MOD(B29,7)=0,任务!$M$25) -> 30 | N29: =ROUND(12/7,1) -> 1.7 | O29: =IF(MOD(B29,7)=2,10,0)+IF(MOD(B29,7)=5,10,0) -> 0 | P29: =OFFSET(产销汇总!$C$1,MATCH(P$27,产销汇总!$C$2:$C$8,0),$C$27)/200*协力宝箱!$Q$82 -> 0 | Q29: =0.2*5*10 -> 10 | R29: 10 | S29: 50 | U29: =IF($C$27<2,50,100)+IF(B29>=3,50,0) -> 100 | V29: =SUM($H$29:U29)+SUM(D29:G29) -> 3978.2
B30: 2 | C30: =OFFSET(产销汇总!$C$12,$B30,$C$27) -> 35 | D30: =SUMIF(主线宝箱!$B$321:$B$620,"<="&C30,主线宝箱!$H$321:$H$620)+SUMIF(主线宝箱!$B$321:$B$620,"<="&C30,主线宝箱!$T$321:$T$620) -> 1400 | E30: 110 | F30: =F29+22.5 -> 135 | G30: =IF(AND($C$27<3,B30>3),G29,SUMIF(图纸产出设计!$F$334:$F$342,"<="&B30,图纸产出设计!$C$334:$C$342)) -> 2690 | H30: =OFFSET(产销汇总!$C$1,MATCH(H$28,产销汇总!$C$2:$C$8,0),$C$27)*(_xlfn.XLOOKUP(C30,主线推图!$B$313:$B$612,主线推图!$G$313:$G$612)+_xlfn.XLOOKUP(C30,主线推图!$B$313:$B$612,主线推图!$H$313:$H$612)) -> 176 | I30: =OFFSET(产销汇总!$C$1,MATCH(I$28,产销汇总!$C$2:$C$8,0),$C$27)*_xlfn.XLOOKUP(C30,巡逻产出!$B$311:$B$610,巡逻产出!$H$311:$H$610) -> 0 | J30: =OFFSET(产销汇总!$C$1,MATCH(J$28,产销汇总!$C$2:$C$8,0),$C$27)*(_xlfn.XLOOKUP(MAX(1,INT(C30/10-6/10)),组队产出!$B$24:$B$39,组队产出!$J$24:$J$39)+_xlfn.XLOOKUP(MAX(1,INT(C30/10-6/10)),组队产出!$B$24:$B$39,组队产出!$K$24:$K$39)) -> 96 | K30: =OFFSET(产销汇总!$C$1,MATCH(K$28,产销汇总!$C$2:$C$8,0),$C$27)*_xlfn.XLOOKUP(C30,巡逻产出!$B$311:$B$610,巡逻产出!$I$311:$I$610)*IF($C$27=1,0.5,1) -> 312 | L30: =OFFSET(产销汇总!$C$1,MATCH(L$28,产销汇总!$C$2:$C$8,0),$C$27)*竞技场!$C$5 -> 180 | M30: =任务!$C$6+IF(MOD(B30,7)=0,任务!$M$25) -> 30 | N30: =ROUND(12/7,1) -> 1.7 | O30: =IF(MOD(B30,7)=2,10,0)+IF(MOD(B30,7)=5,10,0) -> 10 | P30: =OFFSET(产销汇总!$C$1,MATCH(P$27,产销汇总!$C$2:$C$8,0),$C$27)/200*协力宝箱!$Q$82 -> 0 | Q30: =0.2*5*10 -> 10 | R30: 10 | S30: 50 | U30: =IF($C$27<2,50,100)+IF(B30>=3,50,0) -> 100 | V30: =SUM($H$29:U30)+SUM(D30:G30) -> 6276.4 | W30: =V30-V29 -> 2298.2
B31: 3 | C31: =OFFSET(产销汇总!$C$12,$B31,$C$27) -> 40 | D31: =SUMIF(主线宝箱!$B$321:$B$620,"<="&C31,主线宝箱!$H$321:$H$620)+SUMIF(主线宝箱!$B$321:$B$620,"<="&C31,主线宝箱!$T$321:$T$620) -> 1600 | E31: 110 | F31: =F30+22.5 -> 157.5 | G31: =IF(AND($C$27<3,B31>3),G30,SUMIF(图纸产出设计!$F$334:$F$342,"<="&B31,图纸产出设计!$C$334:$C$342)) -> 3890 | H31: =OFFSET(产销汇总!$C$1,MATCH(H$28,产销汇总!$C$2:$C$8,0),$C$27)*(_xlfn.XLOOKUP(C31,主线推图!$B$313:$B$612,主线推图!$G$313:$G$612)+_xlfn.XLOOKUP(C31,主线推图!$B$313:$B$612,主线推图!$H$313:$H$612)) -> 176 | I31: =OFFSET(产销汇总!$C$1,MATCH(I$28,产销汇总!$C$2:$C$8,0),$C$27)*_xlfn.XLOOKUP(C31,巡逻产出!$B$311:$B$610,巡逻产出!$H$311:$H$610) -> 0 | J31: =OFFSET(产销汇总!$C$1,MATCH(J$28,产销汇总!$C$2:$C$8,0),$C$27)*(_xlfn.XLOOKUP(MAX(1,INT(C31/10-6/10)),组队产出!$B$24:$B$39,组队产出!$J$24:$J$39)+_xlfn.XLOOKUP(MAX(1,INT(C31/10-6/10)),组队产出!$B$24:$B$39,组队产出!$K$24:$K$39)) -> 96 | K31: =OFFSET(产销汇总!$C$1,MATCH(K$28,产销汇总!$C$2:$C$8,0),$C$27)*_xlfn.XLOOKUP(C31,巡逻产出!$B$311:$B$610,巡逻产出!$I$311:$I$610)*IF($C$27=1,0.5,1) -> 312 | L31: =OFFSET(产销汇总!$C$1,MATCH(L$28,产销汇总!$C$2:$C$8,0),$C$27)*竞技场!$C$5 -> 180 | M31: =任务!$C$6+IF(MOD(B31,7)=0,任务!$M$25) -> 30 | N31: =ROUND(12/7,1) -> 1.7 | O31: =IF(MOD(B31,7)=2,10,0)+IF(MOD(B31,7)=5,10,0) -> 0 | P31: =OFFSET(产销汇总!$C$1,MATCH(P$27,产销汇总!$C$2:$C$8,0),$C$27)/200*协力宝箱!$Q$82 -> 0 | Q31: =0.2*5*10 -> 10 | R31: 10 | S31: 100 | T31: =(公会!$F$12+公会!$F$13+公会!$F$14+公会!$F$18/7)/2 -> 121.42857 | U31: =IF($C$27<2,50,100)+IF(B31>=3,50,0) -> 150 | V31: =SUM($H$29:U31)+SUM(D31:G31) -> 8886.0286 | W31: =V31-V30 -> 2609.6286
B32: 4 | C32: =OFFSET(产销汇总!$C$12,$B32,$C$27) -> 46 | D32: =SUMIF(主线宝箱!$B$321:$B$620,"<="&C32,主线宝箱!$H$321:$H$620)+SUMIF(主线宝箱!$B$321:$B$620,"<="&C32,主线宝箱!$T$321:$T$620) -> 1840 | E32: 110 | F32: =F31+22.5 -> 180 | G32: =IF(AND($C$27<3,B32>3),G31,SUMIF(图纸产出设计!$F$334:$F$342,"<="&B32,图纸产出设计!$C$334:$C$342)) -> 3890 | H32: =OFFSET(产销汇总!$C$1,MATCH(H$28,产销汇总!$C$2:$C$8,0),$C$27)*(_xlfn.XLOOKUP(C32,主线推图!$B$313:$B$612,主线推图!$G$313:$G$612)+_xlfn.XLOOKUP(C32,主线推图!$B$313:$B$612,主线推图!$H$313:$H$612)) -> 176 | I32: =OFFSET(产销汇总!$C$1,MATCH(I$28,产销汇总!$C$2:$C$8,0),$C$27)*_xlfn.XLOOKUP(C32,巡逻产出!$B$311:$B$610,巡逻产出!$H$311:$H$610) -> 0 | J32: =OFFSET(产销汇总!$C$1,MATCH(J$28,产销汇总!$C$2:$C$8,0),$C$27)*(_xlfn.XLOOKUP(MAX(1,INT(C32/10-6/10)),组队产出!$B$24:$B$39,组队产出!$J$24:$J$39)+_xlfn.XLOOKUP(MAX(1,INT(C32/10-6/10)),组队产出!$B$24:$B$39,组队产出!$K$24:$K$39)) -> 96 | K32: =OFFSET(产销汇总!$C$1,MATCH(K$28,产销汇总!$C$2:$C$8,0),$C$27)*_xlfn.XLOOKUP(C32,巡逻产出!$B$311:$B$610,巡逻产出!$I$311:$I$610)*IF($C$27=1,0.5,1) -> 312 | L32: =OFFSET(产销汇总!$C$1,MATCH(L$28,产销汇总!$C$2:$C$8,0),$C$27)*竞技场!$C$5 -> 180 | M32: =任务!$C$6+IF(MOD(B32,7)=0,任务!$M$25) -> 30 | N32: =ROUND(12/7,1) -> 1.7 | O32: =IF(MOD(B32,7)=2,10,0)+IF(MOD(B32,7)=5,10,0) -> 0 | P32: =OFFSET(产销汇总!$C$1,MATCH(P$27,产销汇总!$C$2:$C$8,0),$C$27)/200*协力宝箱!$Q$82 -> 0 | Q32: =0.2*5*10 -> 10 | R32: 10 | S32: =S31 -> 100 | T32: =(公会!$F$12+公会!$F$13+公会!$F$14+公会!$F$18/7)/2 -> 121.42857 | U32: =IF($C$27<2,50,100)+IF(B32>=3,50,0) -> 150 | V32: =SUM($H$29:U32)+SUM(D32:G32) -> 10335.657 | W32: =V32-V31 -> 1449.6286
B33: 5 | C33: =OFFSET(产销汇总!$C$12,$B33,$C$27) -> 55 | D33: =SUMIF(主线宝箱!$B$321:$B$620,"<="&C33,主线宝箱!$H$321:$H$620)+SUMIF(主线宝箱!$B$321:$B$620,"<="&C33,主线宝箱!$T$321:$T$620) -> 2200 | E33: 110 | F33: =F32+22.5 -> 202.5 | G33: =IF(AND($C$27<3,B33>3),G32,SUMIF(图纸产出设计!$F$334:$F$342,"<="&B33,图纸产出设计!$C$334:$C$342)) -> 3890 | H33: =OFFSET(产销汇总!$C$1,MATCH(H$28,产销汇总!$C$2:$C$8,0),$C$27)*(_xlfn.XLOOKUP(C33,主线推图!$B$313:$B$612,主线推图!$G$313:$G$612)+_xlfn.XLOOKUP(C33,主线推图!$B$313:$B$612,主线推图!$H$313:$H$612)) -> 176 | I33: =OFFSET(产销汇总!$C$1,MATCH(I$28,产销汇总!$C$2:$C$8,0),$C$27)*_xlfn.XLOOKUP(C33,巡逻产出!$B$311:$B$610,巡逻产出!$H$311:$H$610) -> 0 | J33: =OFFSET(产销汇总!$C$1,MATCH(J$28,产销汇总!$C$2:$C$8,0),$C$27)*(_xlfn.XLOOKUP(MAX(1,INT(C33/10-6/10)),组队产出!$B$24:$B$39,组队产出!$J$24:$J$39)+_xlfn.XLOOKUP(MAX(1,INT(C33/10-6/10)),组队产出!$B$24:$B$39,组队产出!$K$24:$K$39)) -> 96 | K33: =OFFSET(产销汇总!$C$1,MATCH(K$28,产销汇总!$C$2:$C$8,0),$C$27)*_xlfn.XLOOKUP(C33,巡逻产出!$B$311:$B$610,巡逻产出!$I$311:$I$610)*IF($C$27=1,0.5,1) -> 312 | L33: =OFFSET(产销汇总!$C$1,MATCH(L$28,产销汇总!$C$2:$C$8,0),$C$27)*竞技场!$C$5 -> 180 | M33: =任务!$C$6+IF(MOD(B33,7)=0,任务!$M$25) -> 30 | N33: =ROUND(12/7,1) -> 1.7 | O33: =IF(MOD(B33,7)=2,10,0)+IF(MOD(B33,7)=5,10,0) -> 10 | P33: =OFFSET(产销汇总!$C$1,MATCH(P$27,产销汇总!$C$2:$C$8,0),$C$27)/200*协力宝箱!$Q$82 -> 0 | Q33: =0.2*5*10 -> 10 | R33: 10 | S33: =S32 -> 100 | T33: =(公会!$F$12+公会!$F$13+公会!$F$14+公会!$F$18/7)/2 -> 121.42857 | U33: =IF($C$27<2,50,100)+IF(B33>=3,50,0) -> 150 | V33: =SUM($H$29:U33)+SUM(D33:G33) -> 11915.286 | W33: =V33-V32 -> 1579.6286
B34: 6 | C34: =OFFSET(产销汇总!$C$12,$B34,$C$27) -> 57 | D34: =SUMIF(主线宝箱!$B$321:$B$620,"<="&C34,主线宝箱!$H$321:$H$620)+SUMIF(主线宝箱!$B$321:$B$620,"<="&C34,主线宝箱!$T$321:$T$620) -> 2280 | E34: 110 | F34: =F33+22.5 -> 225 | G34: =IF(AND($C$27<3,B34>3),G33,SUMIF(图纸产出设计!$F$334:$F$342,"<="&B34,图纸产出设计!$C$334:$C$342)) -> 3890 | H34: =OFFSET(产销汇总!$C$1,MATCH(H$28,产销汇总!$C$2:$C$8,0),$C$27)*(_xlfn.XLOOKUP(C34,主线推图!$B$313:$B$612,主线推图!$G$313:$G$612)+_xlfn.XLOOKUP(C34,主线推图!$B$313:$B$612,主线推图!$H$313:$H$612)) -> 176 | I34: =OFFSET(产销汇总!$C$1,MATCH(I$28,产销汇总!$C$2:$C$8,0),$C$27)*_xlfn.XLOOKUP(C34,巡逻产出!$B$311:$B$610,巡逻产出!$H$311:$H$610) -> 0 | J34: =OFFSET(产销汇总!$C$1,MATCH(J$28,产销汇总!$C$2:$C$8,0),$C$27)*(_xlfn.XLOOKUP(MAX(1,INT(C34/10-6/10)),组队产出!$B$24:$B$39,组队产出!$J$24:$J$39)+_xlfn.XLOOKUP(MAX(1,INT(C34/10-6/10)),组队产出!$B$24:$B$39,组队产出!$K$24:$K$39)) -> 96 | K34: =OFFSET(产销汇总!$C$1,MATCH(K$28,产销汇总!$C$2:$C$8,0),$C$27)*_xlfn.XLOOKUP(C34,巡逻产出!$B$311:$B$610,巡逻产出!$I$311:$I$610)*IF($C$27=1,0.5,1) -> 312 | L34: =OFFSET(产销汇总!$C$1,MATCH(L$28,产销汇总!$C$2:$C$8,0),$C$27)*竞技场!$C$5 -> 180 | M34: =任务!$C$6+IF(MOD(B34,7)=0,任务!$M$25) -> 30 | N34: =ROUND(12/7,1) -> 1.7 | O34: =IF(MOD(B34,7)=2,10,0)+IF(MOD(B34,7)=5,10,0) -> 0 | P34: =OFFSET(产销汇总!$C$1,MATCH(P$27,产销汇总!$C$2:$C$8,0),$C$27)/200*协力宝箱!$Q$82 -> 0 | Q34: =0.2*5*10 -> 10 | R34: 10 | S34: =S33 -> 100 | T34: =(公会!$F$12+公会!$F$13+公会!$F$14+公会!$F$18/7)/2 -> 121.42857 | U34: =IF($C$27<2,50,100)+IF(B34>=3,50,0) -> 150 | V34: =SUM($H$29:U34)+SUM(D34:G34) -> 13204.914 | W34: =V34-V33 -> 1289.6286
B35: 7 | C35: =OFFSET(产销汇总!$C$12,$B35,$C$27) -> 60 | D35: =SUMIF(主线宝箱!$B$321:$B$620,"<="&C35,主线宝箱!$H$321:$H$620)+SUMIF(主线宝箱!$B$321:$B$620,"<="&C35,主线宝箱!$T$321:$T$620) -> 2400 | E35: 110 | F35: =F34+22.5 -> 247.5 | G35: =IF(AND($C$27<3,B35>3),G34,SUMIF(图纸产出设计!$F$334:$F$342,"<="&B35,图纸产出设计!$C$334:$C$342)) -> 3890 | H35: =OFFSET(产销汇总!$C$1,MATCH(H$28,产销汇总!$C$2:$C$8,0),$C$27)*(_xlfn.XLOOKUP(C35,主线推图!$B$313:$B$612,主线推图!$G$313:$G$612)+_xlfn.XLOOKUP(C35,主线推图!$B$313:$B$612,主线推图!$H$313:$H$612)) -> 176 | I35: =OFFSET(产销汇总!$C$1,MATCH(I$28,产销汇总!$C$2:$C$8,0),$C$27)*_xlfn.XLOOKUP(C35,巡逻产出!$B$311:$B$610,巡逻产出!$H$311:$H$610) -> 0 | J35: =OFFSET(产销汇总!$C$1,MATCH(J$28,产销汇总!$C$2:$C$8,0),$C$27)*(_xlfn.XLOOKUP(MAX(1,INT(C35/10-6/10)),组队产出!$B$24:$B$39,组队产出!$J$24:$J$39)+_xlfn.XLOOKUP(MAX(1,INT(C35/10-6/10)),组队产出!$B$24:$B$39,组队产出!$K$24:$K$39)) -> 96 | K35: =OFFSET(产销汇总!$C$1,MATCH(K$28,产销汇总!$C$2:$C$8,0),$C$27)*_xlfn.XLOOKUP(C35,巡逻产出!$B$311:$B$610,巡逻产出!$I$311:$I$610)*IF($C$27=1,0.5,1) -> 312 | L35: =OFFSET(产销汇总!$C$1,MATCH(L$28,产销汇总!$C$2:$C$8,0),$C$27)*竞技场!$C$5 -> 180 | M35: =任务!$C$6+IF(MOD(B35,7)=0,任务!$M$25) -> 60 | N35: =ROUND(12/7,1) -> 1.7 | O35: =IF(MOD(B35,7)=2,10,0)+IF(MOD(B35,7)=5,10,0) -> 0 | P35: =OFFSET(产销汇总!$C$1,MATCH(P$27,产销汇总!$C$2:$C$8,0),$C$27)/200*协力宝箱!$Q$82 -> 0 | Q35: =0.2*5*10 -> 10 | R35: 10 | S35: 100 | T35: =(公会!$F$12+公会!$F$13+公会!$F$14+公会!$F$18/7)/2 -> 121.42857 | U35: =IF($C$27<2,50,100)+IF(B35>=3,50,0) -> 150 | V35: =SUM($H$29:U35)+SUM(D35:G35) -> 14564.543 | W35: =V35-V34 -> 1359.6286
B36: 8 | C36: =OFFSET(产销汇总!$C$12,$B36,$C$27) -> 63 | D36: =SUMIF(主线宝箱!$B$321:$B$620,"<="&C36,主线宝箱!$H$321:$H$620)+SUMIF(主线宝箱!$B$321:$B$620,"<="&C36,主线宝箱!$T$321:$T$620) -> 2520 | E36: 110 | F36: =F35+22.5 -> 270 | G36: =IF(AND($C$27<3,B36>3),G35,SUMIF(图纸产出设计!$F$334:$F$342,"<="&B36,图纸产出设计!$C$334:$C$342)) -> 3890 | H36: =OFFSET(产销汇总!$C$1,MATCH(H$28,产销汇总!$C$2:$C$8,0),$C$27)*(_xlfn.XLOOKUP(C36,主线推图!$B$313:$B$612,主线推图!$G$313:$G$612)+_xlfn.XLOOKUP(C36,主线推图!$B$313:$B$612,主线推图!$H$313:$H$612)) -> 176 | I36: =OFFSET(产销汇总!$C$1,MATCH(I$28,产销汇总!$C$2:$C$8,0),$C$27)*_xlfn.XLOOKUP(C36,巡逻产出!$B$311:$B$610,巡逻产出!$H$311:$H$610) -> 0 | J36: =OFFSET(产销汇总!$C$1,MATCH(J$28,产销汇总!$C$2:$C$8,0),$C$27)*(_xlfn.XLOOKUP(MAX(1,INT(C36/10-6/10)),组队产出!$B$24:$B$39,组队产出!$J$24:$J$39)+_xlfn.XLOOKUP(MAX(1,INT(C36/10-6/10)),组队产出!$B$24:$B$39,组队产出!$K$24:$K$39)) -> 96 | K36: =OFFSET(产销汇总!$C$1,MATCH(K$28,产销汇总!$C$2:$C$8,0),$C$27)*_xlfn.XLOOKUP(C36,巡逻产出!$B$311:$B$610,巡逻产出!$I$311:$I$610)*IF($C$27=1,0.5,1) -> 312 | L36: =OFFSET(产销汇总!$C$1,MATCH(L$28,产销汇总!$C$2:$C$8,0),$C$27)*竞技场!$C$5 -> 180 | M36: =任务!$C$6+IF(MOD(B36,7)=0,任务!$M$25) -> 30 | N36: =ROUND(12/7,1) -> 1.7 | O36: =IF(MOD(B36,7)=2,10,0)+IF(MOD(B36,7)=5,10,0) -> 0 | P36: =OFFSET(产销汇总!$C$1,MATCH(P$27,产销汇总!$C$2:$C$8,0),$C$27)/200*协力宝箱!$Q$82 -> 0 | Q36: =0.2*5*10 -> 10 | R36: 10 | S36: =S35 -> 100 | T36: =(公会!$F$12+公会!$F$13+公会!$F$14+公会!$F$18/7)/2 -> 121.42857 | U36: =IF($C$27<2,50,100)+IF(B36>=3,50,0) -> 150 | V36: =SUM($H$29:U36)+SUM(D36:G36) -> 15894.171 | W36: =V36-V35 -> 1329.6286
