Workbook

Sheet 路线图
A1: 时间 | C1: 1 | D1: 2 | E1: 3 | F1: 4 | G1: 5 | H1: 6 | I1: 7 | J1: 8 | K1: 9 | L1: 10 | M1: 11 | N1: 12 | O1: 13 | P1: 14 | Q1: 第3周 | R1: 第4周 | S1: 第5周 | T1: 第6周 | U1: 第7周 | V1: 第8周 | W1: 第9周 | X1: 第10周 | Y1: 第11周 | Z1: 第12周 | AA1: 第13周 | AB1: 第14周 | AC1: 第15周 | AD1: 第16周
A2: 满活跃非r主线 | C2: 10 | D2: 15 | E2: 20 | F2: 25 | G2: 30 | H2: 35 | I2: 40
A3: 满活跃小R主线（四卡党） | C3: 15 | D3: 25 | E3: 35 | F3: 45 | G3: 48 | H3: 50 | I3: 54
A4: 满活跃中R主线（四卡党+活动）1000+，日产200抽 | J4: 57 | K4: 60 | L4: 63 | M4: 66 | N4: 69 | O4: 71 | P4: 73
A5: 满活跃大R主线3000+ | Q5: 80 | R5: 87 | S5: 94 | T5: 101 | U5: 108 | V5: 115 | W5: 122 | X5: 129 | Y5: 136 | Z5: 143 | AA5: 150 | AB5: 157 | AC5: 164 | AD5: 171 | AE5: 178
A6: 养成 梦灵线 | B6: 梦灵 | C6: 2-3紫（5级 | D6: 东方/镭射 | E6: 亚瑟 | F6: 蜘蛛 | G6: 唐小僧 | H6: 神灯 | I6: 关羽 | J6: 后羿/诸葛/我爱沙 | Q6: 海拉/妲己 | R6: 白素贞 | S6: 零日骇客UP (31天） | W6: 雅典娜UP (59天） | AB6: 女娲UP (73天） | AE6: 杨戬UP (102天）
B7: 挂件 解锁条件-主角等级 | C7: 弹幕流/全图流/爆发流 | D7: 能量流 | F7: 召唤流 | H7: 共鸣流 | J7: 赛季挂件 (S0) | W7: 赛季挂件 (S1)
B8: 符文 | C8: 开启
A9: 养成 主角线 | B9: 装备 | C9: 开启 | E9: 红装 | Q9: 粉装 | T9: 彩装 | U9: 彩虹装
B10: 武器 | C10: 开局+1 | E10: 开局+1 | P10: 开局+1 | T10: 开局+1
B11: 秘宝 | H11: 开启
B12: 藏品 | Q12: 藏品系统（15天） （静默开启）
B13: 载具 | R13: 载具系统 （22天）
B14: 宠物 | V14: 宠物系统 （60天）
A15: 玩法 | B15: 荧幕争锋 | C15: 开启
B16: 梦域巡航 | C16: 难度1 | E16: 难度2 | H16: 难度3 | L16: 难度4 | P16: 难度5 | Q16: 难度6/难度7 | R16: 难度8 | S16: 难度9 | T16: 难度10 彩虹关1(藏品) | V16: 彩虹2 | Y16: 彩虹3 | AA16: 彩虹4
B17: 海底捞金 | C17: 开启
B18: 贪吃大作战 | E18: 开启 | Q18: 升级
B19: 梦隙迷廊 | R19: 开启
B20: 宠物玩法 | V20: 开启
B21: 赛季玩法 | X21: S1玩法
A22: 活动 | B22: 赛季循环 （长周期投辅线） | C22: S0赛季-梦境启航（过度赛季） | V22: S1赛季-我有一座恐怖屋（主推射手、法师)
C23: 主投：红梦灵及皮肤、红色符文（好词条） 辅投：橙、紫梦灵及皮肤、符文祝福石 进度：B级冒险家+散件 荣誉：主角氛围特效-白日梦想（S） | V23: 主投：粉梦灵皮肤、红色符文（好词条） 辅投：橙、红梦灵及皮肤、符文祝福石 进度：B级 小鬼当家+散件 荣誉：主角氛围特效-百鬼夜行（S）
B24: 周循环 （循环投养成） | D24: 开服冲刺//根据抽数达成配置奖励，同时玩家首日抽卡次数保留到开服冲刺 | J24: 招募冲刺【根据第7天招募次数达成中位数来设置首档和后续的奖励】 | Q24: 符文冲刺(boss) | R24: 秘宝冲刺 （排行投皮肤） | S24: 招募冲刺 | T24: 符文冲刺(boss) | U24: 秘宝冲刺 | V24: 招募冲刺 （跨服） | W24: 符文冲刺 | X24: 秘宝冲刺 | Y24: 招募冲刺 | Z24: 符文冲刺 | AA24: 秘宝冲刺 | AB24: 招募冲刺
Q25: 悬赏（1档） | T25: 悬赏（2档） | W25: 悬赏（3档） | Z25: 悬赏（4档）
Q26: 红符文、随机橙藏品、指定橙藏品 第三周（符文产品） 第四周（载具产品） 第五周（招募冲刺 | T26: 红符文、载具粉零件 第6周（彩虹关的藏品 | W26: 载具粉零件、红符文、指定橙藏品... | Z26: 载具粉零件、红符文、指定橙藏品...
B27: 限时活动 （短周期投核心线) | G27: 橙卡试炼 | K27: 时装抽奖【星轨探测】聚焦皮肤 | O27: 红卡试炼(13-16天) | S27: 粉卡试炼 | V27: 粉卡试炼 | Y27: 粉卡试炼 | AB27: 粉卡试炼
G28: 橙卡皮肤 专属符文（红卡预告） | K28: 天使套-A （S0） | O28: 红卡皮肤 专属符文 | S28: 粉卡皮肤 专属符文 | V28: 粉卡皮肤 专属符文 | Y28: 粉卡皮 肤专属符文 | AB28: 粉卡皮肤 专属符文
B32: 1.梦灵节奏适当压缩了一点（粉卡阶段采用的蔚蓝上一版本的节奏，因为我们存量不够）
B34: 2.三类活动线的做了调整：
B35: 月活动→赛季：主要做主轴目标和荣誉追求，投放辅线的资源
B36: 周循环活动：做中小R的钻石消耗和付费转化，主要承载中小R的长期目标和小额付费转化，投放养成资源
B37: 限时活动：拉收，短周期，投放核心资源
B38: 一个核心调整思路就是要把一些投放内容隔离到只有限时活动投放
B40: 3.目前盘下来，需要一个大颗粒度的投放内容去支撑上面这个投放结构，目前考虑下来还是藏品比较合适。对应的秘宝的价值要做上去，现在被当成藏品在投放。
B42: 首周：
B43: 1.关卡战力压制
B44: 2.梦灵节点追求
B46: 次周：
B47: 1.符文概率调整
...

Sheet 活动设计标准
C1: 稀缺度
C3: 稀缺度 | D3: 定义 | E3: 投放约束
C4: 常规 | D4: 存在稳定、重复获取渠道 | E4: 可进入日常、常驻商店和普通礼包
C5: 受限 | D5: 稳定出现，但存在周期或数量限制 | E5: 可进入周循环、战令、限购礼包
C6: 稀缺 | D6: 只在少量运营活动中周期投放 | E6: 控制月度总量，禁止日常大量投放
C7: 限定 | D7: 赛季、联动、首发或特定时间独占 | E7: 限定渠道、限定周期，返场需单独审核
C10: 材料返利比
C12: 直购档位/RMB | D12: 标准返比 | E12: 示例 | H12: 月卡、周卡、基金、战令类，返比>1000%
C13: 6 | D13: 10 | E13: 6元=6高抽+60钻 | H13: 基础资源 | I13: 30元=36小时
C14: 12 | D14: 8 | I14: 68元=72小时
C15: 30 | D15: 6 | E15: 30元=10心愿抽+300钻
C16: 68 | D16: 5 | I16: 基金 | J16: 10
C17: 98 | D17: 4 | I17: 战令 | J17: 15
C18: 128 | D18: 3.5
C19: 198 | D19: 3
C20: 328 | D20: 2.5
C21: 648 | D21: 2
C23: 钻石消耗活动直购礼包返利比
C24: 直购档位/RMB | D24: 标准返比 | E24: 示例
C25: 6 | D25: 10 | J25: 5
C26: 30 | D26: 4 | J26: 5
C27: 98 | D27: 2.5 | J27: 5
C28: 328 | D28: 1.5
C30: 活动返利比
C32: 活动评级 | D32: 标准返比
C33: S | D33: 3
C34: A | D34: 200%-225%
C35: B | D35: 150%-175%

Sheet 优化总内容
A1: 活动分类 | B1: 周期分类 | C1: 活动名字 | D1: 价格 | E1: 活动开始时间 | F1: 活动结束时间 | G1: 转化率 | H1: 优化思路 | I1: 目标用户 | J1: 截图1 | K1: 截图2
A2: 常驻活动 | B2: 终身限购 | C2: 首充 | D2: 6 | E2: 1 | F2: 99999 | G2: 跟用户质量有关 | H2: 1、新增30元（橙卡皮）、68元 直购（橙色角色皮） 2、搭配6元武器，制作一个橙色队长皮肤跟武器搭配，提高转化目标提高首日LTV。 3、128元送橙色皮肤后续玩家会觉得亏，数据上来看购买128元橙色皮肤的流失率会比不买的高了一些。让玩家感觉首充是赚的。而且可以把这个奖励剥离开，不会重复投放。 | I2: 小R/破冰
C3: 钻石战令（Ⅰ、Ⅱ、Ⅲ） | D3: 98 | E3: 1 | F3: 99999 | G3: 0.095 | H3: 首月战令投放68元战令皮，后续期数暂定投放其他限时内容 比如载具、宠物 或者其他 | I3: 中R钻石转化需要提升
B4: 周期活动 | C4: 大/小月卡 | D4: 18、30 | E4: 1 | F4: 30 | G4: 26%/30% | H4: 1、提高特权点 2、双卡激活奖励加一个聊天框带一点属性，提高双卡的标识。 | I4: 中小R核心付费点
C5: 大/小体力战令 | D5: 28、68 | E5: 1 | F5: 14 | G5: 20%/10% | H5: 1、28元体力战令保持，2、68元应该在反比不动太多的情况下投放一些可自选的内容，选择多一些。 | I5: 中小R核心付费点
C6: 周卡 | D6: 12 | E6: 1 | F6: 7 | G6: 0.15 | H6: 1、初始增加金币券 2、开启载具副本后，减负用户 可增加对组队的减负的道具（比如打1次队员可以抵2次的券）。 | I6: 中核心付费点
C7: 每日特惠 | D7: 1、6、18 | E7: 1 | F7: 1 | G7: 3%/1.5%/0.2% | H7: 1、礼包心梦宝石增加2-3档次随机 比如可以在 1元可在1、2、3、5个之间随机 2、梦境奇迹宝箱可以给固定碎片，按照玩家拥有的英雄和卡池等级可选择获取的量。 | I7: 中大R核心付费点
C8: 特惠礼包（日、周、月） | D8: 钻石 | E8: 1 | F8: 30 | H8: 1、根据数据来调整售价策略 2、后续可计划根据购买的量越大越有折扣，这样后续的体感价值可以根据玩家的进度活动进度可以进行贬值也不影响玩家的体感。 | I8: 中大R购买
C9: 连充活动（6、25） | D9: 6、25 | E9: 1 | F9: 7 | G9: 10%/6% | H9: 开启新玩法后会考虑新增新成长点的自选奖励 | I9: 中大R购买
C10: 兑换商店【心梦宝石】 | E10: 1 | F10: 7 | H10: 1、降低钻石的限购次数为1次， 2、若首充增加橙色皮肤可新增到这里当成短期的升星目标 （武器的购买不错） 3、新增新的成长点内容 比如载具、藏品等需要添加 4、会额外增加心梦宝石的产量（核心与付费有关系） 5、核心就每日、冲刺获取，其他地方不投放。
A11: 循环活动 | C11: 招募冲刺 | E11: 7 | H11: 1、根据玩家的资源获取和内容，来评估奖励和消耗的配置是否需要更新。 2、生态影响什么时候加入跨服。 3、如果没跨服则需要根据数据来计算排行榜的保底机制。
C12: 符文冲刺 | E12: 7 | H12: 根据玩家的资源获取和内容，来评估奖励和消耗的配置是否需要更新。
C13: 秘宝冲刺 | E13: 7 | H13: 根据玩家的资源获取和内容，来评估奖励和消耗的配置是否需要更新。
C14: 悬赏活动1 | E14: 10 | H14: 1、规划5层的奖励 前4层基本每层都会又一个玩家热衷度较高的内容 2、第5层是稀有道具是为了提高玩家的付费冲动，核心是神话符文、载具、秘宝、藏品、角色皮肤等 3、如果7天一期的话，类似二游复刻一样提高稀缺性，相似的道具投放时间间隔长一些，规划5层的奖励内容。
C15: 悬赏活动2 | E15: 10
C16: 悬赏活动3【载具】 | E16: 10
C17: 悬赏活动4【载具】 | E17: 10
A18: 限时活动 | B18: 服务器限时 | C18: 招募狂欢（橙卡） | E18: 2 | F18: 7 | H18: 1、首轮的次数降低到400（500就可以抽橙色了，第2天开启这个时候玩家对橙色的追求没那么大了） 2、第2轮开始放随机、固定橙色皮肤
C19: 招募狂欢（红卡） | E19: 8 | F19: 14 | H19: 1、这个时候如果玩家已经开到4级卡池 那么这个奖励无所谓 2、但是如果玩家还未开4级卡池，那么这个给固定卡的感受会更强一些。 3、可仿照招募狂欢后续的活动做一定优化，下期在走纯粹排行
C20: 橙卡试炼 | E20: 5 | F20: 8 | H20: 搭配限时激活礼包
C21: 红卡试炼 | E21: 12 | F21: 15 | H21: 1、增加抽卡额外转盘，提高玩家抽卡转盘（需求需额外开发，待定） 2、周期时间需要规划下，是否间隔太近，让玩家感觉自己橙卡的付费保值性大幅度下滑（蔚蓝放到了19天）
C22: 粉卡试炼（星光炼梦）【转盘2】
C23: 月光炼梦【转盘2】 | E23: 20 | F23: 22 | H23: 核心思路3个 1、钻石购买限制次数 2、提高礼包限制次数 3、抽奖道具活动结束后不使用则回收或者给予一定的资源。付费进行分层，保证普通玩家可以快基本拿到一个保底，如果想拿其他的必须充钱。（目前我们的付费留存和活跃留存远远低于蔚蓝，所以付费分层和服务器生态需要进行优化）
C24: 星轨探测【转盘1】 | E24: 27 | F24: 29
C25: 粉卡限时up
C26: 限时激活礼包
B27: 节日限时 | C27: 大富翁活动
C28: 端午活动
A29: 月度活动 | C29: 首月 | H29: 1、活跃+签到+战令+核心转盘【首月根据玩家进度投放一个主角皮肤，后续则以粉皮为主】+预约奖励 2、是否参考限时活动一样保证一个月的保底策略

Sheet 追求表
B1: 紫 | C1: 东方/镭射 | D1: 亚瑟 | E1: 蜘蛛 | F1: 唐小僧 | G1: 神灯 | H1: 关羽 | I1: 后羿/诸葛/我爱沙 | P1: 海拉/妲己 | W1: 白素贞
A2: 功能新增 | P2: 藏品 | W2: 载具 | AF2: 粉卡
A3: 天数 | B3: 1 | C3: 2 | D3: 3 | E3: 4 | F3: 5 | G3: 6 | H3: 7 | I3: 8 | J3: 9 | K3: 10 | L3: 11 | M3: 12 | N3: 13 | O3: 14 | P3: 15 | Q3: 16 | R3: 17 | S3: 18 | T3: 19 | U3: 20 | V3: 21 | W3: 22 | X3: 23 | Y3: 24 | Z3: 25 | AA3: 26 | AB3: 27 | AC3: 28 | AD3: 29 | AE3: 30 | AF3: 31 | AG3: 32 | AH3: 33 | AI3: 34 | AJ3: 35 | AK3: 36 | AL3: 37 | AM3: 38 | AN3: 39 | AO3: 40 | AP3: 41 | AQ3: 42 | AR3: 43 | AS3: 44 | AT3: 45 | AU3: 46 | AV3: 47 | AW3: 48 | AX3: 49 | AY3: 50 | AZ3: 51 | BA3: 52 | BB3: 53 | BC3: 54 | BD3: 55 | BE3: 56 | BF3: 57 | BG3: 58 | BH3: 59 | BI3: 60
A4: 活动 | B4: 6元首冲
A5: 活动 | B5: 每日特惠(1、6、18) 优化1、6、18元随机宝箱，提高返利
A6: 活动 | B6: 日/周/月礼包
A7: 活动 | B7: 每日充值(25元赠送1个传说祝福石)
A8: 活动 | B8: 大小月卡 18/30
A9: 活动 | B9: 体力战令28/68 | P9: 体力战令28/68（68元增加自选，加一些材料） | AD9: 体力战令28/68（68元增加自选）
A10: 活动 | B10: 周卡（新增金币扫荡） | I10: 周卡（金币扫荡） | P10: 周卡（金币扫荡） | W10: 周卡（（组队双倍）（金币扫荡） | AD10: 周卡（（组队双倍）（金币扫荡） | AK10: 周卡（（组队双倍）（金币扫荡）
A11: 活动 | B11: 钻石战令Ⅰ Ⅱ | W11: 载具战令
A12: 活动 | B12: 七日目标//玩法活跃引导【洗练石引导的问题要不要去掉？改成送个祝福石？】
A13: 活动 | B13: 章节礼包
A14: 活动 | B14: 招募狂欢（3200） | I14: 招募冲刺（红卡魂魄） | P14: 符文冲刺（符文宝石） | W14: 秘宝冲刺（秘宝皮肤） | AD14: 招募冲刺（粉卡魂魄）（藏品） | AK14: 符文冲刺（符文宝石） | AR14: 秘宝冲刺（皮肤+藏品） | AY14: 招募冲刺（粉卡魂魄）（藏品） | BF14: 符文冲刺（符文宝石）
A15: 活动 | F15: 橙卡试炼【皮肤、符文】 | L15: 红卡试炼【符文、皮肤】
A16: 活动 | D16: 礼包
A17: 活动 | P17: 悬赏活动1【符文洗炼藏品】 | W17: 悬赏活动2【组队藏品】 | AD17: 悬赏活动3【招募藏品】 | AK17: 悬赏活动1【周卡迷廊藏品】 | AR17: 悬赏活动2【组队藏品】 | AY17: 悬赏活动3【招募藏品】 | BF17: 悬赏活动1【符文洗炼藏品、符文】
A18: 活动 | B18: 月度活动（红色皮肤、专属符文（限制1个4档）主要是投放皮肤） | AF18: 次月活动（粉卡皮肤）
A19: 限时活动 | I19: 皮肤（天使套）直抽月光炼梦改【5+5】A | P19: 神秘套【月光炼梦】 | AB19: 载具转盘（主投皮肤）星轨探测改（A）
A20: 限时UP | W20: 宇宙套【月光炼梦】 | AF20: 限时up（15天）（骇客） | AU20: 限时up（15天）（雅典娜）
A87: 天数 | B87: 1 | C87: 2 | D87: 3 | E87: 4 | F87: 5 | G87: 6 | H87: 7 | I87: 8 | J87: 9 | K87: 10 | L87: 11 | M87: 12 | N87: 13 | O87: 14 | P87: 15 | Q87: 16 | R87: 17 | S87: 18 | T87: 19 | U87: 20 | V87: 21 | W87: 22 | X87: 23 | Y87: 24 | Z87: 25 | AA87: 26 | AB87: 27 | AC87: 28 | AD87: 29 | AE87: 30 | AF87: 31 | AG87: 32 | AH87: 33 | AI87: 34 | AJ87: 35 | AK87: 36 | AL87: 37 | AM87: 38 | AN87: 39 | AO87: 40 | AP87: 41 | AQ87: 42 | AR87: 43 | AS87: 44 | AT87: 45 | AU87: 46 | AV87: 47 | AW87: 48 | AX87: 49 | AY87: 50 | AZ87: 51 | BA87: 52 | BB87: 53 | BC87: 54 | BD87: 55 | BE87: 56 | BF87: 57 | BG87: 58 | BH87: 59 | BI87: 60
A88: 活动 | B88: 小R
A89: 活动 | B89: 中小R，1元提高付费率，搏一搏，6元和25元搭配连充给予一个长期的目标
A90: 活动 | B90: 日/周/月礼包
A91: 活动 | B91: 每日充值(25元赠送1个传说祝福石) 中 大R的日常付费追求
A92: 活动 | B92: 大小月卡 18/30 全体
A93: 活动 | B93: 体力战令28/68（28元必追，68元后续迭代） | P93: 体力战令28/68（68元增加自选，加一些材料） | AD93: 体力战令28/68（68元增加自选）
A94: 活动 | B94: 周卡（新增金币扫荡）【必追】 | I94: 周卡（金币扫荡） | P94: 周卡（金币扫荡） | W94: 周卡（（组队双倍）（金币扫荡） | AD94: 周卡（（组队双倍）（金币扫荡） | AK94: 周卡（（组队双倍）（金币扫荡）
A95: 活动 | B95: 钻石战令Ⅰ Ⅱ （提高钻石价值后必追） | W95: 载具战令
A96: 活动 | B96: 七日目标//玩法活跃引导
A97: 活动 | B97: 章节礼包
A98: 活动 | C98: 招募狂欢（3000） | I98: 招募冲刺（红卡魂魄） | P98: 符文冲刺（符文宝石） | W98: 秘宝冲刺（皮肤） | AD98: 招募冲刺（粉卡魂魄）（藏品） | AK98: 符文冲刺（符文宝石） | AR98: 秘宝冲刺（皮肤+藏品） | AY98: 招募冲刺（粉卡魂魄）（藏品）
A99: 活动 | F99: 橙卡试炼【皮肤】 | L99: 红卡试炼【符文】
A100: 活动 | E100: 推送
A101: 活动 | P101: 悬赏活动1【符文洗炼藏品、符文】 | W101: 悬赏活动2【月卡藏品、超级洗练石】 | AD101: 悬赏活动3【载具、招募藏品】 | AK101: 悬赏活动1【符文藏品、符文、】 | AR101: 悬赏活动2【增加载具、月卡藏品】 | AY101: 悬赏活动3【招募藏品】
A102: 活动 | B102: 月度活动（红色皮肤、专属符文（限制1个4档）主要是投放皮肤）长线活跃 | AF102: 次月活动（粉卡皮肤）
A103: 限时活动 | I103: 皮肤（天使套）直抽月光炼梦改【5+5】 | AB103: 载具直抽 星轨探测
A104: 限时UP | AF104: 限时up（15天）（骇客） | AU104: 限时up（15天）（雅典娜）
A117: 天数 | B117: 1 | C117: 2~4 | D117: 5~7 | E117: 8 | F117: 9~14 | G117: 15~18 | H117: 19~21 | I117: 22 | J117: 23~24 | K117: 25~27 | L117: 28 | M117: 29~30
A118: 目标定位 | B118: 小R
...

Sheet 道具价值表-汇总
A1: 道具id | B1: 道具【梦境】 | C1: 单价（人民币） | D1: 单价（钻石） | E1: 稀有程度 | F1: 特殊运营活动价格（人民币） | G1: 类型 | H1: 品质 | I1: 针对玩家 | J1: 备注 | K1: 计算
A2: 1 | B2: 钻石 | C2: 0.1 | D2: =C2*10 | E2: 常规 | G2: 货币 | H2: 橙 | J2: /
A3: 2 | B3: 金币 | C3: 0.005 | D3: =C3*10 | E3: 常规 | G3: 货币 | H3: 蓝 | J3: /
A4: 9800301 | B4: 金币吸收器 | C4: 5 | D4: 50
A5: 44 | B5: 心梦宝石 | C5: 1.4 | D5: =C5*10 | E5: 受限 | G5: 兑换道具 | H5: 橙 | J5: 每日特惠/循环冲刺活动，兑换商店货币）
A6: 13 | B6: 体力 | C6: 0.2 | D6: =C6*10 | E6: 常规 | G6: 消耗道具 | H6: 紫
A7: 20002 | B7: 梦境奇迹宝箱 | C7: 1 | D7: =C7*10 | E7: 受限 | G7: 消耗道具 | H7: 紫 | J7: 每日特惠礼包
A8: 20038 | B8: 梦境惊喜宝箱 | C8: 8 | D8: 80 | E8: 受限 | J8: 每日特惠礼包
A9: 5600208 | B9: 悬赏线索 | C9: 0.3 | D9: 3 | E9: 受限 | H9: 橙 | J9: 悬赏活动产出的价值
A10: 5203001 | B10: 织梦微尘 | C10: 0.3 | D10: =C10*10 | E10: 受限 | G10: 队长道具 | H10: 蓝 | J10: /
A11: 5103001 | B11: 随机能量特饮 | C11: 0.1 | D11: =C11*10 | E11: 常规 | G11: 梦灵道具 | H11: 蓝 | J11: /
A12: 5104001 | B12: 超能特饮 | C12: 0.2 | D12: =C12*10 | E12: 常规 | G12: 梦灵道具 | H12: 紫 | J12: /
A13: 5600014 | B13: 史诗梦灵碎片 | C13: 1.2 | D13: =C13*10 | E13: 常规 | G13: 梦灵 | H13: 紫 | J13: /
A14: 5600015 | B14: 传说梦灵碎片 | C14: 2.4 | D14: =C14*10 | E14: 受限 | G14: 梦灵 | H14: 橙
B15: 神话梦灵碎片 | C15: 4.8 | D15: =C15*10 | E15: 稀缺 | G15: 梦灵 | H15: 红
B16: 创世梦灵碎片 | C16: 9.6 | D16: =C16*10 | E16: 稀缺 | G16: 梦灵
B17: 自选史诗梦灵碎片 | C17: 1.2 | D17: =C17*10 | E17: 受限 | G17: 梦灵 | J17: /
B18: 自选传说梦灵碎片 | C18: 2.4 | D18: =C18*10 | E18: 受限 | G18: 梦灵
B19: 自选神话梦灵碎片 | C19: 4.8 | D19: =C19*10 | E19: 稀缺 | G19: 梦灵
B20: 自选创世梦灵碎片 | C20: 9.6 | D20: =C20*10 | E20: 稀缺 | G20: 梦灵
B21: 随机史诗梦灵 | C21: 12 | D21: =C21*10 | E21: 受限 | G21: 梦灵 | J21: =D21*0.4
B22: 随机传说梦灵 | C22: 24 | D22: =C22*10 | E22: 受限 | G22: 梦灵 | J22: =D22*0.4
B23: 随机神话梦灵 | C23: 48 | D23: =C23*10 | E23: 稀缺 | G23: 梦灵 | J23: =D23*0.4
B24: 随机创世梦灵 | C24: 96 | D24: =C24*10 | E24: 稀缺 | G24: 梦灵 | J24: =D24*0.4
B25: 自选史诗梦灵 | C25: 12 | D25: =C25*10 | E25: 受限 | G25: 梦灵
B26: 自选传说梦灵 | C26: 24 | D26: =C26*10 | E26: 受限 | G26: 梦灵
B27: 自选神话梦灵 | C27: 48 | D27: =C27*10 | E27: 稀缺 | G27: 梦灵 | J27: /
B28: 自选创世梦灵 | C28: 96 | D28: =C28*10 | E28: 稀缺 | G28: 梦灵
A29: 50002 | B29: 装备图纸 | C29: 0.3 | D29: =C29*10 | E29: 常规 | G29: 装备道具 | H29: 蓝 | J29: /
B30: 固定部位装备图纸 | C30: 0.5 | D30: =C30*10 | E30: 受限 | G30: 装备道具 | J30: /
A31: 50001 | B31: 锻造晶石 | C31: 0.01 | D31: =C31*10 | E31: 常规 | G31: 装备道具 | H31: 蓝 | J31: /
A32: 5303001 | B32: 符引结晶 | C32: 0.5 | D32: =C32*10 | E32: 常规 | G32: 符文 | H32: 蓝 | J32: 200个合成1个，紫色的需要符引结晶
A33: 5305001 | B33: 幻梦晶核 | C33: 6 | D33: =C33*10 | E33: 受限 | G33: 符文 | H33: 橙 | J33: /
A34: 5305010 | B34: 传说祝福石 | C34: 150 | D34: 1500 | E34: 稀缺 | G34: 符文 | H34: 橙
A35: 5305008 | B35: 神话祝福石 | C35: 500 | D35: 5000 | E35: 稀缺 | G35: 符文 | H35: 红
A36: 5305009 | B36: 创世祝福石 | C36: 1600 | D36: 16000 | E36: 稀缺 | G36: 符文 | H36: 粉
A37: 5301000 | B37: 普通符文 | C37: 1.6 | D37: =C37*10 | E37: 常规 | G37: 符文
A38: 5302000 | B38: 优秀符文 | C38: 6.4 | D38: =C38*10 | E38: 常规 | G38: 符文
A39: 5303000 | B39: 稀有符文 | C39: 25.6 | D39: =C39*10 | E39: 常规 | G39: 符文
A40: 5304000 | B40: 史诗符文 | C40: 102.4 | D40: =C40*10 | E40: 受限 | G40: 符文 | J40: 日常获取4折
...

Sheet item
A1: 道具id | B1: 道具名字 | C1: 道具描述
A2: id | B2: name | C2: desc
B5: 货币 | C5: 道具id段：1~10000，基础货币和各种活动代币
A8: 1 | B8: 钻石 | C8: 梦境由认知构成，因此钻石成为了梦境中非常稀有的流通货币，珍贵的钻石总是蕴含着宛若星辰的辉芒
A9: 2 | B9: 金币 | C9: 梦境由认知构成，因此金币便成了梦境中最为通用的货币，没有人能拒绝金光闪闪的东西
A10: 5 | B10: 日活跃度 | C10: 是护卫队每日在梦境中活跃完成任务的象征，达到一定目标即可领取额外奖励
A11: 6 | B11: 周活跃度 | C11: 是护卫队每周在梦境中活跃完成任务的象征，达到一定目标即可领取额外奖励
A12: 7 | B12: 通行证积分 | C12: 消耗1点体力获取1点积分，达到积分可获得相应奖励
A13: 9 | B13: 星之初愿 | C13: 星愿铸成的指引之钥，可用于商店进行符文招募
A14: 10 | B14: 代金券 | C14: 存在于虚幻与现实中的货币，在梦境中能代替现实货币用于购买付费商品
A15: 11 | B15: 梦境招募器 | C15: 梦境中彩虹机器的启动器，可用于商店进行梦灵招募
A16: 12 | B16: 成就点 | C16: 任务中获得的成就点
A17: 13 | B17: 体力 | C17: 梦境护卫队在梦境中的行动都需要消耗体力，如果体力不足，则需要养精蓄锐，择时再战
A18: 14 | B18: 等级经验 | C18: 梦境护卫队的每次行动都会获得等级经验，累积等级经验可以提高梦境护卫队的等级，从而进行更高难度的行动
A19: 15 | B19: 七日挑战活跃点 | C19: 在七日挑战中完成任务后可以获得活跃点，达到指定数量即可领取节点奖励
... A64: 65 | B64: 星铸等级经验 | C64: 获得后可增加星铸之路等级经验
B66: 实物奖励
A67: 1001 | B67: 5万梦想基金 | C67: 次元旅行启动！美团联名消费卡，助你实现双人现世游。
A68: 1002 | B68: 睡衣套装 | C68: 联动定制，软糯亲肤触感。
A69: 1003 | B69: 喜马拉雅月卡 | C69: 喜马拉雅会员权益，海量疗愈声波，带你沉浸式漫游次元。
A70: 1004 | B70: 眼罩周边 | C70: 梦境伴侣，带您沉浸入梦。
A71: 1005 | B71: 助眠枕头 | C71: 跨界补给，让你一秒进入深度梦境。
A72: 1006 | B72: 黄金金钞 | C72: 专属定制黄金金钞，定格梦境高光时刻。
A73: 1007 | B73: 盲盒 | C73: 梦境盲盒，玩转你的梦灵人格！
A74: 1008 | B74: 苹果手机 | C74: 限定实物大奖，梦境限定稀有奖励。
A75: 1009 | B75: 好梦枕头 | C75: 助眠好梦枕头实物奖励，让你一秒进入深度梦境。
A76: 1010 | B76: 睡衣套装 | C76: 联动定制，软糯亲肤触感。
A77: 1011 | B77: 喜马拉雅月卡 | C77: 喜马拉雅会员权益，海量疗愈声波，带你沉浸式漫游次元。
A78: 1012 | B78: 眼罩周边 | C78: 梦境伴侣，带您沉浸入梦。
... A85: 1019 | B85: 黄金金钞 | C85: 专属定制黄金金钞，定格梦境高光时刻。
B89: 梦灵养成道具【正式】 | C89: 道具id段：51+职业【1位】+品质【1位】+排序【3位】
A91: 5103001 | B91: 随机能量特饮 | C91: 职业的能量特饮，可获得随机的职业能量特饮
A92: 5103002 | B92: 随机能量特饮 | C92: 职业的能量特饮，可获得随机的职业能量特饮
A93: 5103003 | B93: 随机能量特饮 | C93: 职业的能量特饮，可获得随机的职业能量特饮
A94: 5104001 | B94: 超能特饮 | C94: 超级能量特饮，对应梦灵特饮不足时，可用超能特饮替代消耗
A95: 5113001 | B95: 战士特饮 | C95: 战士职业的能量特饮，可用于战士梦灵升级
A96: 5123001 | B96: 法师特饮 | C96: 法师职业的能量特饮，可用于法师梦灵升级
A97: 5133001 | B97: 射手特饮 | C97: 射手职业的能量特饮，可用于射手梦灵升级
A98: 5143001 | B98: 辅助特饮 | C98: 辅助职业的能量特饮，可用于辅助梦灵升级
A99: 5153001 | B99: 控制特饮 | C99: 控制职业的能量特饮，可用于控制梦灵升级
...

Sheet 特惠+充值
A1: 日礼包
H2: 汇总
A3: 免费/广告 | B3: 道具 | C3: 道具id | D3: 数量 | E3: 单价 | F3: 价值 | H3: 体力 | I3: =SUMIF($B$4:$B$30,H3,$D$4:$D$35)
B4: 装备图纸 | C4: {=B4} | D4: 10 | E4: {=B4} | F4: =D4*E4 | H4: 梦境招募器 | I4: =SUMIF($B$4:$B$30,H4,$D$4:$D$35)
B5: 心梦宝石 | C5: {=B5} | D5: 1 | E5: {=B5} | F5: =D5*E5 | H5: 梦境奇迹宝箱 | I5: =SUMIF($B$4:$B$30,H5,$D$4:$D$35)
H6: 心梦宝石 | I6: =SUMIF($B$4:$B$30,H6,$D$4:$D$35) | M6: 价值
J7: 调整前 | L7: 梦境奇迹宝箱 | M7: 40
B8: 超值礼包 | J8: 道具 | K8: 道具id | L8: 道具数量 | M8: 单价 | N8: 权重
A9: 1元 | B9: 道具 | C9: 道具id | D9: 数量 | E9: 单价 | F9: 价值 | G9: =SUM(F10:F13)/10 | J9: 幻梦晶核 | K9: {=J9} | L9: 1 | M9: {=J9} | N9: 250
B10: 体力 | C10: {=B10} | D10: 10 | E10: {=B10} | F10: =D10*E10 | J10: 星辉秘契 | K10: {=J10} | L10: 1 | M10: {=J10} | N10: 250
B11: 梦境招募器 | C11: {=B11} | D11: 5 | E11: {=B11} | F11: =D11*E11 | J11: 梦境招募器 | K11: {=J11} | L11: 5 | M11: {=J11} | N11: 500
B12: 梦境奇迹宝箱 | C12: {=B12} | D12: 1 | E12: 80 | F12: =D12*E12 | J12: 随机能量特饮 | K12: {=J12} | L12: 25 | M12: {=J12} | N12: 2000
B13: 心梦宝石 | C13: {=B13} | D13: 2 | E13: {=B13} | F13: =D13*E13 | J13: 星之初愿 | K13: {=J13} | L13: 1 | M13: {=J13} | N13: 1000
J14: 符引结晶 | K14: {=J14} | L14: 5 | M14: {=J14} | N14: 2000
B15: 优选礼包 | J15: 装备图纸 | K15: {=J15} | L15: 10 | M15: {=J15} | N15: 2000
A16: 6元 | B16: 道具 | C16: 道具id | D16: 数量 | E16: 单价 | F16: 价值 | G16: =SUM(F17:F20)/60 | J16: 金币 | K16: {=J16} | L16: 200 | M16: {=J16} | N16: 2000
B17: 体力 | C17: {=B17} | D17: 15 | E17: {=B17} | F17: =D17*E17
B18: 梦境招募器 | C18: {=B18} | D18: 15 | E18: {=B18} | F18: =D18*E18
B19: 梦境奇迹宝箱 | C19: {=B19} | D19: 2 | E19: 80 | F19: =D19*E19 | M19: 价值
B20: 心梦宝石 | C20: {=B20} | D20: 6 | E20: {=B20} | F20: =D20*E20 | J20: 调整后 | L20: 梦境奇迹宝箱 | M20: 80 | P20: 梦境惊喜宝箱
J21: 道具 | K21: 道具id | L21: 道具数量 | M21: 价格 | N21: 权重 | O21: 概率 | P21: 单价
B22: 尊享礼包 | J22: 梦境招募器 | K22: {=J22} | L22: 66 | M22: {=J22} | N22: 50 | O22: =N22/10000 | P22: =O22*M22*L22
A23: 18元 | B23: 道具 | C23: 道具id | D23: 数量 | E23: 单价 | F23: 价值 | G23: =SUM(F24:F27)/180 | J23: 梦境招募器 | K23: {=J23} | L23: 10 | M23: {=J23} | N23: 290 | O23: =N23/10000 | P23: =O23*M23*L23
B24: 体力 | C24: {=B24} | D24: 25 | E24: {=B24} | F24: =D24*E24 | J24: 梦境招募器 | K24: {=J24} | L24: 5 | M24: {=J24} | N24: 800 | O24: =N24/10000 | P24: =O24*M24*L24
B25: 星辉秘契 | C25: {=B25} | D25: 2 | E25: {=B25} | F25: =D25*E25 | J25: 随机能量特饮 | K25: {=J25} | L25: 50 | M25: {=J25} | N25: 1450 | O25: =N25/10000 | P25: =O25*M25*L25
B26: 梦境奇迹宝箱 | C26: {=B26} | D26: 3 | E26: 80 | F26: =D26*E26 | J26: 星之初愿 | K26: {=J26} | L26: 2 | M26: {=J26} | N26: 1810 | O26: =N26/10000 | P26: =O26*M26*L26
B27: 心梦宝石 | C27: {=B27} | D27: 15 | E27: {=B27} | F27: =D27*E27 | J27: 符引结晶 | K27: {=J27} | L27: 10 | M27: {=J27} | N27: 1500 | O27: =N27/10000 | P27: =O27*M27*L27
J28: 装备图纸 | K28: {=J28} | L28: 20 | M28: {=J28} | N28: 1800 | O28: =N28/10000 | P28: =O28*M28*L28
J29: 金币 | K29: {=J29} | L29: 500 | M29: {=J29} | N29: 2300 | O29: =N29/10000 | P29: =O29*M29*L29
A30: 累充
A32: 仅钻石商店和冲刺礼包计入额度
D34: 赠送
B35: 钻石 | D35: 道具 | E35: id | F35: 数量 | G35: 单价 | H35: 整体价值 | I35: 返利比
A36: 累计充值 | B36: 60 | D36: 体力 | E36: {=D36} | F36: 20 | G36: {=D36} | H36: =G36*F36 | I36: =H36/B36
A37: 累计充值 | B37: 300 | D37: 梦境招募器 | E37: {=D37} | F37: 10 | G37: {=D37} | H37: =G37*F37 | I37: =H37/(B37-B36)
A38: 累计充值 | B38: 600 | D38: 金币 | E38: {=D38} | F38: 3000 | G38: {=D38} | H38: =G38*F38 | I38: =H38/(B38-B37)
A39: 累计充值 | B39: 1280 | D39: 星辉秘契 | E39: {=D39} | F39: 1 | G39: {=D39} | H39: =G39*F39 | I39: =H39/(B39-B38)
A40: 累计充值 | B40: 3280 | D40: 幻梦晶核 | E40: {=D40} | F40: 24 | G40: {=D40} | H40: =G40*F40 | I40: =H40/(B40-B39)
A44: 每日充值
B47: 6元档次 | N47: 25元档次
...

Sheet 首充+三卡
A1: 首充活动 | W1: 8
A3: 价格 | B3: 备注 | C3: 道具 | D3: 道具id | E3: 数量 | F3: 单价 | G3: 价值 | H3: 道具 | I3: 道具id | J3: 数量 | K3: 单价 | L3: 价值 | M3: 道具 | N3: 道具id | O3: 数量 | P3: 单价 | Q3: 价值 | R3: 道具 | S3: 道具id | T3: 数量 | U3: 单价 | V3: 价值
A4: 6 | B4: 直购 | C4: 喵喵锤 | D4: 5505001 | E4: 1 | F4: 4000 | G4: =F4*E4 | H4: 梦境招募器 | I4: 11 | J4: 10 | K4: {=H4} | L4: =K4*J4 | M4: 史诗符文 | N4: 5304000 | O4: 1 | Q4: 256 | R4: 当天特权卡 | S4: 100040 | T4: 1 | V4: 300
C5: 梦境招募器 | D5: 11 | E5: 20 | F5: {=C5} | G5: =F5*E5 | H5: 超能特饮 | I5: 5104001 | J5: 300 | K5: {=H5} | L5: =K5*J5 | V5: =V4+Q4+L4+G4 | W5: =V5/60
C6: 随机传说梦灵 | D6: 5600005 | E6: 1 | F6: {=C6} | G6: =F6*E6 | H6: 超能特饮 | I6: 5104001 | J6: 500 | K6: {=H6} | L6: =K6*J6 | V6: =L5+G5 | W6: =V6/60
V7: =L6+G6 | W7: =V7/60
A8: 30 | B8: 累充 | C8: 镭射 | D8: 1530100 | E8: 1 | F8: 480 | G8: =F8*E8 | H8: 超能特饮 | I8: 5104001 | J8: 300 | K8: {=H8} | L8: =K8*J8 | M8: 金币 | N8: 2 | O8: 3000 | P8: {=M8} | Q8: =P8*O8
C9: 星之初愿 | D9: {=C9} | E9: 5 | F9: {=C9} | G9: =F9*E9 | H9: 装备图纸 | I9: {=H9} | J9: 100 | K9: {=H9} | L9: =K9*J9
C10: 梦境招募器 | D10: {=C10} | E10: 10 | F10: {=C10} | G10: =F10*E10 | H10: 装备图纸 | I10: {=H10} | J10: 150 | K10: {=H10} | L10: =K10*J10
A12: 68 | B12: 累充 | C12: 无心睡眠 | D12: 15301011 | E12: 1 | F12: 4000 | G12: =F12*E12 | H12: 装备图纸 | I12: {=H12} | J12: 100 | K12: {=H12} | L12: =K12*J12 | M12: 金币 | N12: 2 | O12: 5000 | P12: {=M12} | Q12: =P12*O12
C13: 星辉秘契 | D13: {=C13} | E13: 2 | F13: {=C13} | G13: =F13*E13 | H13: 梦境招募器 | I13: {=H13} | J13: 10 | K13: {=H13} | L13: =K13*J13
C14: 星辉秘契 | D14: {=C14} | E14: 3 | F14: {=C14} | G14: =F14*E14 | H14: 梦境招募器 | I14: {=H14} | J14: 20 | K14: {=H14} | L14: =K14*J14
R15: 价值 | S15: 反比
C16: 道具 | D16: 道具id | E16: 数量 | F16: 单价 | G16: 价值 | H16: 道具 | I16: 道具id | J16: 数量 | K16: 单价 | L16: 价值 | M16: 道具 | N16: 道具id | O16: 数量 | P16: 单价 | Q16: 价值
A17: 68 | B17: 单笔 | C17: 镭射 | D17: 1530100 | E17: 1 | F17: 480 | G17: =F17*E17 | H17: 无心睡眠 | I17: 15301011 | J17: 1 | K17: 4000 | L17: =K17*J17 | M17: 超能特饮 | N17: {=M17} | O17: 200 | P17: {=M17} | Q17: =P17*O17 | R17: =Q17+L17+G17 | S17: =R17/A17/10 | T17: =S17+S18+S19
C18: 镭射 | D18: 1530100 | E18: 2 | F18: 480 | G18: =F18*E18 | H18: 装备图纸 | I18: {=H18} | J18: 100 | K18: {=H18} | L18: =K18*J18 | R18: =Q18+L18+G18 | S18: =R18/A17/10
C19: 镭射 | D19: 1530100 | E19: 3 | F19: 480 | G19: =F19*E19 | H19: 装备图纸 | I19: {=H19} | J19: 200 | K19: {=H19} | L19: =K19*J19 | R19: =Q19+L19+G19 | S19: =R19/A17/10
A21: 128 | B21: 单笔 | C21: 紫色勇者服 | D21: 101400302 | E21: 1 | F21: 4000 | G21: =F21*E21 | H21: 紫色勇者发饰 | I21: {=H21} | J21: 1 | K21: 1 | L21: 1000 | M21: 金币 | N21: {=M21} | O21: 3000 | P21: {=M21} | Q21: =P21*O21 | R21: =Q21+L21+G21 | S21: =R21/A21/10 | T21: =S21+S22+S23
C22: 星辉秘契 | D22: {=C22} | E22: 3 | F22: {=C22} | G22: =F22*E22 | H22: 金币 | I22: {=H22} | J22: 4000 | K22: {=H22} | L22: =K22*J22 | R22: =Q22+L22+G22 | S22: =R22/A21/10
C23: 星辉秘契 | D23: {=C23} | E23: 5 | F23: {=C23} | G23: =F23*E23 | H23: 金币 | I23: {=H23} | J23: 5000 | K23: {=H23} | L23: =K23*J23 | R23: =Q23+L23+G23 | S23: =R23/A21/10
A25: 月卡
B27: 新增一些广告点
B28: 特权月卡 | H28: 福利月卡
B30: 道具 | C30: 道具id | D30: 数量 | H30: 道具 | I30: 道具id | J30: 数量
A31: 每日 | B31: 钻石 | C31: 1 | D31: 60 | G31: 每日 | H31: 钻石 | I31: 1 | J31: 100
B32: 梦境招募器 | C32: 11 | D32: 2 | H32: 体力 | I32: 13 | J32: 10
H34: 已通关主线支持2倍速
B35: 特权无限使用 | C35: 无限 | H35: 争锋、捞金、贪吃支持2倍速
B36: 精品商店刷新次数 | C36: 3 | H36: 睡眠时间+4小时，收益+30%
B37: 心愿招募刷新 | C37: 1 | H37: 梦域巡航可领取特权门票+1
A41: 激活 | B41: 双卡奖励 | C41: 道具id | D41: 数量
B42: 梦境招募器 | C42: 11 | D42: 20
B43: 星辉秘契 | C43: 30 | D43: 2
B44: 聊天框 | C44: 1 | D44: 1%暴击
A47: 特权周卡（签到）
C52: 特权
C54: 合作模式可获得双倍奖励
C55: 每天首次协助合作，可获得队长奖励
C56: 梦隙迷廊通关迷廊币+20%
C58: 签到奖励
...

Sheet 日周月礼包
A1: 日礼包
B3: 道具 | C3: 道具id | D3: 数量 | E3: 单价 | F3: 价值 | G3: 原价 | H3: 售价 | I3: 限购次数 | J3: 折扣
B4: 体力 | C4: {=B4} | D4: 10 | E4: {=B4} | F4: =E4*D4 | G4: =IFERROR(H4/J4*10,"") | H4: 0 | I4: 1 | J4: 0
A5: 新增 | B5: 体力 | C5: {=B5} | D5: 10 | E5: {=B5} | F5: =E5*D5 | H5: 广告 | I5: 1 | J5: 0
B6: 体力 | C6: {=B6} | D6: 60 | E6: {=B6} | F6: =E6*D6 | G6: =IFERROR(H6/J6*10,"") | H6: 96 | I6: 1 | J6: 8
B7: 金币 | C7: {=B7} | D7: 5000 | E7: {=B7} | F7: =E7*D7 | G7: =IFERROR(H7/J7*10,"") | H7: 125 | I7: 2 | J7: 5
B8: 梦境招募器 | C8: {=B8} | D8: 20 | E8: {=B8} | F8: =E8*D8 | G8: =IFERROR(H8/J8*10,"") | H8: 480 | I8: 2 | J8: 8
B9: 随机能量特饮 | C9: {=B9} | D9: 400 | E9: {=B9} | F9: =E9*D9 | G9: =IFERROR(H9/J9*10,"") | H9: 200 | I9: 3 | J9: 5
B10: 超能特饮 | C10: {=B10} | D10: 200 | E10: {=B10} | F10: =E10*D10 | G10: =IFERROR(H10/J10*10,"") | H10: 200 | I10: 3 | J10: 5
B11: 装备图纸 | C11: {=B11} | D11: 100 | E11: {=B11} | F11: =E11*D11 | G11: =IFERROR(H11/J11*10,"") | H11: 240 | I11: 3 | J11: 8
B12: 星辉秘契 | C12: {=B12} | D12: 2 | E12: {=B12} | F12: =E12*D12 | G12: =IFERROR(H12/J12*10,"") | H12: 392 | I12: 3 | J12: 7
B13: 星辉秘契 | C13: {=B13} | D13: 5 | E13: {=B13} | F13: =E13*D13 | G13: =IFERROR(H13/J13*10,"") | H13: 840 | I13: 3 | J13: 6
B14: 符引结晶 | C14: {=B14} | D14: 50 | E14: {=B14} | F14: =E14*D14 | G14: =IFERROR(H14/J14*10,"") | H14: 225 | I14: 2 | J14: 9
B15: 织梦微尘 | C15: {=B15} | D15: 50 | E15: {=B15} | F15: =E15*D15 | G15: =IFERROR(H15/J15*10,"") | H15: 210 | I15: 3 | J15: 7
B16: 锻造晶石 | C16: {=B16} | D16: 500 | E16: {=B16} | F16: =E16*D16 | G16: =IFERROR(H16/J16*10,"") | H16: 300 | I16: 5 | J16: 6
B17: 幻梦晶核 | C17: {=B17} | D17: 6 | E17: {=B17} | F17: =E17*D17 | G17: =IFERROR(H17/J17*10,"") | H17: 216 | I17: 2 | J17: 6
B18: 转运石 | C18: {=B18} | D18: 1000 | E18: {=B18} | F18: =E18*D18 | G18: =IFERROR(H18/J18*10,"") | H18: 196 | I18: 3 | J18: 6
B19: 智械发条 | C19: {=B19} | D19: 3 | E19: {=B19} | F19: =E19*D19 | G19: =IFERROR(H19/J19*10,"") | H19: 225 | I19: 5 | J19: 5 | K19: 载具开启 | L19: 配置天数开启
A25: 周礼包
B27: 道具 | C27: 道具id | D27: 数量 | E27: 单价 | F27: 价值 | G27: 原价 | H27: 售价 | I27: 限购次数 | J27: 折扣
B28: 体力 | C28: {=B28} | D28: 10 | E28: {=B28} | F28: =E28*D28 | H28: 0
A29: 新增 | B29: 体力 | C29: {=B29} | D29: 10 | E29: {=B29} | F29: =E29*D29 | H29: 广告
B30: 体力 | C30: {=B30} | D30: 60 | E30: {=B30} | F30: =E30*D30 | G30: =IFERROR(H30/J30*10,"") | H30: 84 | I30: 5 | J30: 7
B31: 金币 | C31: {=B31} | D31: 10000 | E31: {=B31} | F31: =E31*D31 | G31: =IFERROR(H31/J31*10,"") | H31: 200 | I31: 1 | J31: 4
B32: 梦境招募器 | C32: {=B32} | D32: 50 | E32: {=B32} | F32: =E32*D32 | G32: =IFERROR(H32/J32*10,"") | H32: 1050 | I32: 3 | J32: 7
B33: 梦境招募器 | C33: {=B33} | D33: 100 | E33: {=B33} | F33: =E33*D33 | G33: =IFERROR(H33/J33*10,"") | H33: 1800 | I33: 3 | J33: 6
B34: 超能特饮 | C34: {=B34} | D34: 400 | E34: {=B34} | F34: =E34*D34 | G34: =IFERROR(H34/J34*10,"") | H34: 320 | I34: 10 | J34: 7
B35: 装备图纸 | C35: {=B35} | D35: 200 | E35: {=B35} | F35: =E35*D35 | G35: =IFERROR(H35/J35*10,"") | H35: 360 | I35: 3 | J35: 6
B36: 星辉秘契 | C36: {=B36} | D36: 10 | E36: {=B36} | F36: =E36*D36 | G36: =IFERROR(H36/J36*10,"") | H36: 1400 | I36: 5 | J36: 5
B37: 星辉秘契 | C37: {=B37} | D37: 20 | E37: {=B37} | F37: =E37*D37 | G37: =IFERROR(H37/J37*10,"") | H37: 2240 | I37: 5 | J37: 4
B38: 符引结晶 | C38: {=B38} | D38: 100 | E38: {=B38} | F38: =E38*D38 | G38: =IFERROR(H38/J38*10,"") | H38: 400 | I38: 3 | J38: 8
B39: 幻梦晶核 | C39: {=B39} | D39: 12 | E39: {=B39} | F39: =E39*D39 | G39: =IFERROR(H39/J39*10,"") | H39: 360 | I39: 2 | J39: 5
B40: 织梦微尘 | C40: {=B40} | D40: 200 | E40: {=B40} | F40: =E40*D40 | G40: =IFERROR(H40/J40*10,"") | H40: 360 | I40: 3 | J40: 6 | P40: 1、符文
B41: 加速沙漏 | C41: {=B41} | D41: 50 | E41: {=B41} | F41: =E41*D41 | G41: =IFERROR(H41/J41*10,"") | H41: 200 | I41: 10 | J41: 8 | L41: 删除投放 | P41: 2、皮肤 | Q41: 周礼包限购 | R41: 跟着玩家节奏走
B42: 梦境衣橱礼包 | C42: {=B42} | D42: 1 | G42: =IFERROR(H42/J42*10,"") | H42: 980 | I42: 3 | J42: 1
B43: 转运石 | C43: {=B43} | D43: 3000 | E43: {=B43} | F43: =E43*D43 | G43: =IFERROR(H43/J43*10,"") | H43: 500 | I43: 4 | J43: 5 | P43: 橙色梦灵
B44: 智械发条 | C44: {=B44} | D44: 10 | E44: {=B44} | F44: =E44*D44 | G44: =IFERROR(H44/J44*10,"") | H44: 600 | I44: 3 | J44: 4 | K44: 22日开启 | L44: 配置天数开启
B45: 精密齿轮 | C45: {=B45} | D45: 300 | E45: {=B45} | F45: =E45*D45 | G45: =H45/J45*10 | H45: 180 | I45: 5 | J45: 6 | K45: 22日开启 | L45: 配置天数开启
B46: 随机史诗藏品 | C46: 6220021 | D46: 1 | E46: 2400 | F46: =E46*D46 | G46: =IFERROR(H46/J46*10,"") | H46: 1400 | I46: 3 | J46: 6 | K46: 15日开启 | L46: 配置天数开启
B47: 万象自选宝盒Ⅰ | C47: {=B47} | D47: 1 | E47: 6000 | F47: =E47*D47 | G47: 6000 | H47: 1800 | I47: 1 | J47: 3 | K47: 15日开启 | L47: 配置天数开启
...

Sheet 心梦商店
A1: 商店ID | B1: 格子 | C1: 展示排序 （序号越小越靠前） | D1: 购买次数范围 通过已购买次数来取数据 比如配置了2表示购已买次数大于等于2时取这条 不分段的话不配或者配0 | E1: 开启条件 | F1: 购买条件 | G1: 是否屏蔽 1：不屏蔽 0：屏蔽 用于项目有线上服时又需要删除某个格子 | H1: 商品名称 | I1: 商品 | J1: 购买消耗 不填则无消耗，由广告控制 | K1: 刷新前可购买次数 0-不限购买次数 其余-可购买次数 | L1: 商店刷新类型 0-不刷新 1-日 2-周 3-月 | M1: 客户端 展示结束时间
A2: shop_id | B2: id | C2: order | D2: buy_count_range | E2: condition | F2: buy_cond | G2: is_close | H2: name | I2: reward | J2: need | K2: buy_count | L2: refresh | M2: end_time
C3: 心梦商店
A4: 4 | B4: 1 | C4: 100 | G4: 1 | H4: 金币 | I4: [{2,500}] | J4: [] | K4: 1 | L4: 2
A5: 4 | B5: 2 | C5: 601 | G5: 1 | H5: 随机神话符文 | I5: [{5306000,1}] | J5: [{44,480}] | K5: 1 | L5: 2
A6: 4 | B6: 3 | C6: 765 | E6: [{server_open_day,29}] | G6: 1 | H6: 钻石 | I6: [{1,1688}] | J6: [{44,120}] | K6: 2 | L6: 2
A7: 4 | B7: 4 | C7: 766 | E7: [{server_open_day,15}] | G7: 1 | H7: 钻石 | I7: [{1,888}] | J7: [{44,60}] | K7: 2 | L7: 2
A8: 4 | B8: 5 | C8: 800 | G8: 1 | H8: 幻梦晶核 | I8: [{5305001,50}] | J8: [{44,188}] | K8: 2 | L8: 2
A9: 4 | B9: 6 | C9: 1300 | G9: 1 | H9: 招募器 | I9: [{11,50}] | J9: [{44,60}] | K9: 1 | L9: 2
A10: 4 | B10: 7 | C10: 900 | G10: 1 | H10: 星辉秘契 | I10: [{30,20}] | J10: [{44,150}] | K10: 1 | L10: 2
A11: 4 | B11: 8 | C11: 500 | E11: [{server_open_day,31}] | G11: 1 | H11: 绮梦衣橱礼盒 | I11: [{100119,1}] | J11: [{44,380}] | K11: 2 | L11: 2
A12: 4 | B12: 9 | C12: 600 | G12: 1 | H12: 喵喵锤子 | I12: [{5505001,1}] | J12: [{44,300}] | K12: 5 | L12: 0
A13: 4 | B13: 10 | C13: 700 | G13: 1 | H13: 神话祝福石 | I13: [{5305008,1}] | J13: [{44,350}] | K13: 1 | L13: 2
A14: 4 | B14: 11 | C14: 200 | G14: 1 | H14: 童话造物幻衣 | I14: [{100041,1}] | J14: [{44,1200}] | K14: 5 | L14: 0
A15: 4 | B15: 12 | C15: 300 | G15: 1 | H15: 小狗锤 | I15: [{5506002,1}] | J15: [{44,600}] | K15: 5 | L15: 0
A16: 4 | B16: 13 | C16: 400 | E16: [{server_open_day,31}] | G16: 1 | H16: 繁星衣橱礼盒 | I16: [{100123,1}] | J16: [{44,750}] | K16: 2 | L16: 3
A17: 4 | B17: 14 | C17: 301 | G17: 1 | H17: 小狗锤 | I17: [{5506002,1}] | J17: [{44,600}] | K17: 5 | M17: {{2026,5,29},{23,59,59}}
A18: 4 | B18: 15 | C18: 1100 | E18: [{server_open_day,22},{chapter_pve,60}] | G18: 1 | H18: 智械发条 | I18: [{62,10}] | J18: [{44,100}] | K18: 2 | L18: 2
A19: 4 | B19: 16 | C19: 1200 | E19: [{server_open_day,22},{chapter_pve,60}] | G19: 1 | H19: 精密齿轮 | I19: [{63,1500}] | J19: [{44,100}] | K19: 5 | L19: 2
A20: 4 | B20: 17 | C20: 401 | E20: [{server_open_day,15}] | G20: 1 | H20: 抵达深空 | I20: [{6200016,1}] | J20: [{44,680}] | K20: 1 | L20: 3
A21: 4 | B21: 18 | C21: 601 | E21: [{server_open_day,15}] | G21: 1 | H21: 酣眠的祝福 | I21: [{6200015,1}] | J21: [{44,380}] | K21: 1 | L21: 2

Sheet 招募狂欢
A1: 招募狂欢 | C1: 开服第2-7天开启
B3: 轮次 | C3: 物品类型 | D3: 数量 | E3: 价值 | F3: 物品类型 | G3: 数量 | H3: 价值 | I3: 物品类型 | J3: 数量 | K3: 价值 | L3: 总价值 | M3: 道具id
B4: 第1轮 | C4: 随机传说梦灵 | D4: 1 | E4: {=C4} | F4: 随机紫色专属【紫色】 | G4: 1 | H4: 1024 | I4: 超能特饮 | J4: 300 | K4: 600 | L4: =K4+H4+E4 | M4: 5800012
B5: 第2轮 | C5: 自选传说梦灵 | D5: 1 | E5: {=C5} | F5: 自选紫色专属【紫色】 | G5: 1 | H5: 1024 | I5: 超能特饮 | J5: 500 | K5: 1000 | L5: =K5+H5+E5 | M5: 5800012
B6: 第3轮 | C6: 自选传说梦灵 | D6: 2 | E6: {=C6} | F6: 自选紫色专属【紫色】 | G6: 1 | H6: 1024 | I6: 超能特饮 | J6: 800 | K6: 1600 | L6: =K6+H6+E6 | M6: 5800012 | O6: 3卡用户的引导
B7: 第4轮 | C7: 随机神话梦灵 | D7: 1 | E7: {=C7} | F7: 随机橙色稀有【橙色】 | G7: 1 | H7: 4000 | I7: 超能特饮 | J7: 1000 | K7: 2000 | L7: =K7+H7+E7 | M7: 5600082 | N7: 去掉 | O7: 300+的用户
M8: 星辉秘契
M9: 星辉秘契
B10: 节点数值 | M10: 星辉秘契
M11: 星辉秘契
A12: 一轮 | B12: 节点数值 | C12: 物品类型 | D12: 数量 | E12: 价值 | F12: 物品类型 | G12: 数量 | H12: 价值 | I12: 总价值 | J12: 返利比
B13: 60 | C13: 梦境招募器 | D13: 5 | E13: 150 | F13: 随机能量特饮 | G13: 30 | H13: 30 | I13: 180 | J13: 0.1
B14: 120 | C14: 梦境招募器 | D14: 5 | E14: 150 | F14: 随机能量特饮 | G14: 30 | H14: 30 | I14: 180 | J14: 0.1
B15: 200 | C15: 梦境招募器 | D15: 5 | E15: 150 | F15: 随机能量特饮 | G15: 30 | H15: 30 | I15: 180 | J15: 0.08
B16: 300 | C16: 梦境招募器 | D16: 10 | E16: 300 | F16: 随机能量特饮 | G16: 50 | H16: 50 | I16: 350 | J16: 0.12
B17: 420 | C17: 梦境招募器 | D17: 10 | E17: 300 | F17: 随机能量特饮 | G17: 50 | H17: 50 | I17: 350 | J17: 0.1
B18: 600 | C18: 梦境招募器 | D18: 10 | E18: 300 | F18: 随机能量特饮 | G18: 50 | H18: 50 | I18: 350 | J18: 0.06
D19: 45 | G19: 240 | I19: =SUM(I13:I18) | J19: 0.0883
A21: 二轮 | B21: 节点数值 | C21: 物品类型 | D21: 数量 | E21: 价值 | F21: 物品类型 | G21: 数量 | H21: 价值 | I21: 总价值 | J21: 返利比
B22: 60 | C22: 梦境招募器 | D22: 5 | E22: 150 | F22: 随机能量特饮 | G22: 50 | H22: 50 | I22: 200 | J22: 0.11
B23: 120 | C23: 梦境招募器 | D23: 5 | E23: 150 | F23: 随机能量特饮 | G23: 50 | H23: 50 | I23: 200 | J23: 0.11
B24: 200 | C24: 梦境招募器 | D24: 5 | E24: 150 | F24: 随机能量特饮 | G24: 50 | H24: 50 | I24: 200 | J24: 0.08
B25: 300 | C25: 梦境招募器 | D25: 10 | E25: 300 | F25: 随机能量特饮 | G25: 80 | H25: 80 | I25: 380 | J25: 0.13
B26: 420 | C26: 梦境招募器 | D26: 10 | E26: 300 | F26: 随机能量特饮 | G26: 80 | H26: 80 | I26: 380 | J26: 0.11
B27: 600 | C27: 梦境招募器 | D27: 10 | E27: 300 | F27: 随机能量特饮 | G27: 80 | H27: 80 | I27: 380 | J27: 0.07
A30: 三轮 | B30: 节点数值 | C30: 物品类型 | D30: 数量 | E30: 价值 | F30: 物品类型 | G30: 数量 | H30: 价值 | I30: 总价值 | J30: 返利比
B31: 80 | C31: 梦境招募器 | D31: 5 | E31: 150 | F31: 随机能量特饮 | G31: 80 | H31: 80 | I31: 230 | J31: 0.1
B32: 160 | C32: 梦境招募器 | D32: 5 | E32: 150 | F32: 随机能量特饮 | G32: 80 | H32: 80 | I32: 230 | J32: 0.1
B33: 260 | C33: 梦境招募器 | D33: 5 | E33: 150 | F33: 随机能量特饮 | G33: 80 | H33: 80 | I33: 230 | J33: 0.08
B34: 400 | C34: 梦境招募器 | D34: 10 | E34: 300 | F34: 随机能量特饮 | G34: 100 | H34: 100 | I34: 400 | J34: 0.1
B35: 580 | C35: 梦境招募器 | D35: 10 | E35: 300 | F35: 随机能量特饮 | G35: 100 | H35: 100 | I35: 400 | J35: 0.07
B36: 800 | C36: 梦境招募器 | D36: 10 | E36: 300 | F36: 随机能量特饮 | G36: 100 | H36: 100 | I36: 400 | J36: 0.06
D37: 45 | G37: 540 | I37: =SUM(I31:I36) | J37: 0.0788
A39: 四轮 | B39: 节点数值 | C39: 物品类型 | D39: 数量 | E39: 价值 | F39: 物品类型 | G39: 数量 | H39: 价值 | I39: 总价值 | J39: 返利比
B40: 120 | C40: 梦境招募器 | D40: 5 | E40: 150 | F40: 随机能量特饮 | G40: 100 | H40: 100 | I40: 250 | J40: 0.08
B41: 240 | C41: 梦境招募器 | D41: 5 | E41: 150 | F41: 随机能量特饮 | G41: 100 | H41: 100 | I41: 250 | J41: 0.08
B42: 400 | C42: 梦境招募器 | D42: 5 | E42: 150 | F42: 随机能量特饮 | G42: 100 | H42: 100 | I42: 250 | J42: 0.07
B43: 600 | C43: 梦境招募器 | D43: 10 | E43: 300 | F43: 随机能量特饮 | G43: 120 | H43: 120 | I43: 420 | J43: 0.08
B44: 800 | C44: 梦境招募器 | D44: 10 | E44: 300 | F44: 随机能量特饮 | G44: 120 | H44: 120 | I44: 420 | J44: 0.06
B45: 1200 | C45: 梦境招募器 | D45: 10 | E45: 300 | F45: 随机能量特饮 | G45: 120 | H45: 120 | I45: 420 | J45: 0.05
...

Sheet 橙卡试炼活动
A1: 梦灵试炼 | B1: 卡牌品质 | C1: 开服第X天开启 | D1: 活动持续时间（天） | E1: 活动说明 | F1: 规则：
B2: 橙卡 | C2: 5 | D2: 4 | F2: 1、活动期间，可选择传说梦灵作为升级目标，可随时更换;
F3: 2、选中的梦灵达到指定等级后，可解锁对应等级的专属升级礼包;
F4: 3、每个礼包只能获取1次，已购买的专属升级礼包、已领取的免费奖励不会随更换梦灵重置。
A6: 梦灵试炼 | B6: 免费奖励 | F6: 升级专属礼包
A7: 梦灵等级 | B7: 道具 | C7: 单价 | D7: 数量 | E7: 总价值 | F7: 货币 | G7: 对应档位 | H7: 展示折扣 | I7: 道具1 | J7: 单价1 | K7: 数量1 | L7: 价值1 | M7: 道具2 | N7: 单价2 | O7: 数量2 | P7: 价值2 | Q7: 道具3 | R7: 单价3 | S7: 数量3 | T7: 价值3 | U7: 总价值 | V7: 返利
A8: 1 | B8: 梦境招募器 | C8: {=B8} | D8: 5 | E8: =PRODUCT(C8:D8) | F8: 钻石 | G8: 688 | H8: =G8/U8 | I8: 超能特饮 | J8: {=I8} | K8: 50 | L8: =PRODUCT(J8:K8) | M8: 梦境招募器 | N8: {=M8} | O8: 50 | P8: =PRODUCT(N8:O8) | U8: =SUMIF($B$7:$T$7,"价值*",B8:T8) | V8: =U8/(G8) | W8: =G8/H8*10
A9: 5 | B9: 梦境招募器 | C9: {=B9} | D9: 10 | E9: =PRODUCT(C9:D9) | F9: 钻石 | G9: 1688 | H9: =G9/U9 | I9: 自选传说梦灵 | J9: {=I9} | K9: 1 | L9: =PRODUCT(J9:K9) | M9: 梦境招募器 | N9: {=M9} | O9: 100 | P9: =PRODUCT(N9:O9) | Q9: 超能特饮 | R9: {=Q9} | S9: 100 | T9: =PRODUCT(R9:S9) | U9: =SUMIF($B$7:$T$7,"价值*",B9:T9) | V9: =U9/(G9) | W9: =G9/H9*10
A10: 10 | B10: 梦境招募器 | C10: {=B10} | D10: 15 | E10: =PRODUCT(C10:D10) | F10: 钻石 | G10: 2388 | H10: =G10/U10 | I10: 自选传说梦灵 | J10: {=I10} | K10: 2 | L10: =PRODUCT(J10:K10) | M10: 梦境招募器 | N10: {=M10} | O10: 150 | P10: =PRODUCT(N10:O10) | Q10: 传说梦灵随机珍稀符文 | R10: 2000 | S10: 1 | T10: =PRODUCT(R10:S10) | U10: =SUMIF($B$7:$T$7,"价值*",B10:T10) | V10: =U10/(G10) | W10: =G10/H10*10
A11: 12 | B11: 梦愿水晶 | C11: {=B11} | D11: 1 | E11: =PRODUCT(C11:D11) | F11: 钻石 | G11: 2688 | H11: =G11/U11 | I11: 自选传说梦灵 | J11: {=I11} | K11: 2 | L11: =PRODUCT(J11:K11) | M11: 星辉秘契 | N11: {=M11} | O11: 5 | P11: =PRODUCT(N11:O11) | Q11: 传说梦灵随机稀世符文 | R11: 5000 | S11: 1 | T11: =PRODUCT(R11:S11) | U11: =SUMIF($B$7:$T$7,"价值*",B11:T11) | V11: =U11/(G11) | W11: =G11/H11*10
A12: 15 | B12: 随机橙色皮肤 | C12: 4000 | D12: 1 | E12: =PRODUCT(C12:D12) | F12: 钻石 | G12: 3088 | H12: =G12/U12 | I12: 随机神话梦灵 | J12: 5000 | K12: 1 | L12: 5000 | M12: 星辉秘契 | N12: {=M12} | O12: 10 | P12: =PRODUCT(N12:O12) | Q12: 超能特饮 | R12: {=Q12} | S12: 300 | T12: =PRODUCT(R12:S12) | U12: =SUMIF($B$7:$T$7,"价值*",B12:T12) | V12: =U12/(G12) | W12: =G12/H12*10
A13: 17 | B13: 星辉秘契 | C13: {=B13} | D13: 2 | E13: =PRODUCT(C13:D13) | F13: 钻石 | G13: 3288 | H13: =G13/U13 | I13: 幻梦晶核 | J13: {=I13} | K13: 50 | L13: =PRODUCT(J13:K13) | M13: 星辉秘契 | N13: {=M13} | O13: 20 | P13: =PRODUCT(N13:O13) | S13: 1 | T13: =PRODUCT(R13:S13) | U13: =SUMIF($B$7:$T$7,"价值*",B13:T13) | V13: =U13/(G13) | W13: =G13/H13*10
A14: 20 | B14: 星辉秘契 | C14: {=B14} | D14: 3 | E14: =PRODUCT(C14:D14) | F14: 钻石 | G14: 4388 | H14: =G14/U14 | I14: 幻梦晶核 | J14: {=I14} | K14: 80 | L14: =PRODUCT(J14:K14) | M14: 星辉秘契 | N14: {=M14} | O14: 30 | P14: =PRODUCT(N14:O14) | U14: =SUMIF($B$7:$T$7,"价值*",B14:T14) | V14: =U14/(G14) | W14: =G14/H14*10
L18: 100144

Sheet 红卡试炼活动
A1: 梦灵试炼 | B1: 卡牌品质 | C1: 开服第X天开启 | D1: 活动持续时间（天） | E1: 活动说明 | F1: 规则：
B2: 红卡 | C2: 11 | D2: 4 | F2: 1、活动期间，可选择传说梦灵作为升级目标，可随时更换;
F3: 2、选中的梦灵达到指定等级后，可解锁对应等级的专属升级礼包;
F4: 3、每个礼包只能获取1次，已购买的专属升级礼包、已领取的免费奖励不会随更换梦灵重置。
A6: 梦灵试炼 | B6: 免费奖励 | F6: 升级专属礼包
A7: 梦灵等级 | B7: 道具 | C7: 单价 | D7: 数量 | E7: 总价值 | F7: 货币 | G7: 对应档位 | H7: 展示折扣 | I7: 道具1 | J7: 单价1 | K7: 数量1 | L7: 价值1 | M7: 道具2 | N7: 单价2 | O7: 数量2 | P7: 价值2 | Q7: 道具3 | R7: 单价3 | S7: 数量3 | T7: 价值3 | U7: 总价值 | V7: 返利 | W7: 历史
A8: 1 | B8: 梦境招募器 | C8: {=B8} | D8: 5 | E8: =PRODUCT(C8:D8) | F8: 钻石 | G8: 688 | H8: =G8/U8*10 | I8: 超能特饮 | J8: {=I8} | K8: 50 | L8: =PRODUCT(J8:K8) | M8: 梦境招募器 | N8: {=M8} | O8: 50 | P8: =PRODUCT(N8:O8) | U8: =SUMIF($B$7:$T$7,"价值*",B8:T8) | V8: =U8/(G8)
A9: 5 | B9: 梦境招募器 | C9: {=B9} | D9: 10 | E9: =PRODUCT(C9:D9) | F9: 钻石 | G9: 1688 | H9: =G9/U9*10 | I9: 自选神话梦灵 | J9: {=I9} | K9: 1 | L9: =PRODUCT(J9:K9) | M9: 梦境招募器 | N9: {=M9} | O9: 100 | P9: =PRODUCT(N9:O9) | Q9: 超能特饮 | R9: {=Q9} | S9: 100 | T9: =PRODUCT(R9:S9) | U9: =SUMIF($B$7:$T$7,"价值*",B9:T9) | V9: =U9/(G9) | W9: 超能特饮
A10: 8 | B10: 传说祝福石 | C10: {=B10} | D10: 1 | E10: =PRODUCT(C10:D10) | F10: 钻石 | G10: 1988 | H10: =G10/U10*10 | I10: 自选神话梦灵 | J10: {=I10} | K10: 2 | L10: =PRODUCT(J10:K10) | M10: 梦境招募器 | N10: {=M10} | O10: 150 | P10: =PRODUCT(N10:O10) | Q10: 超能特饮 | R10: {=Q10} | S10: 200 | T10: =PRODUCT(R10:S10) | U10: =SUMIF($B$7:$T$7,"价值*",B10:T10) | V10: =U10/(G10) | W10: 超能特饮
A11: 10 | B11: 梦境招募器 | C11: {=B11} | D11: 15 | E11: =PRODUCT(C11:D11) | F11: 钻石 | G11: 3588 | H11: =G11/U11*10 | I11: 自选神话梦灵 | J11: {=I11} | K11: 2 | L11: =PRODUCT(J11:K11) | M11: 梦境招募器 | N11: {=M11} | O11: 200 | P11: =PRODUCT(N11:O11) | Q11: 神话梦灵随机珍稀符文 | R11: 3000 | S11: 1 | T11: =PRODUCT(R11:S11) | U11: =SUMIF($B$7:$T$7,"价值*",B11:T11) | V11: =U11/(G11) | W11: 超能特饮
A12: 12 | B12: 梦愿水晶 | C12: {=B12} | D12: 1 | E12: =PRODUCT(C12:D12) | F12: 钻石 | G12: 3688 | H12: =G12/U12*10 | I12: 自选神话梦灵 | J12: {=I12} | K12: 1 | L12: =PRODUCT(J12:K12) | M12: 星辉秘契 | N12: {=M12} | O12: 5 | P12: =PRODUCT(N12:O12) | Q12: 神话梦灵随机稀世符文 | R12: 6000 | S12: 1 | T12: =PRODUCT(R12:S12) | U12: =SUMIF($B$7:$T$7,"价值*",B12:T12) | V12: =U12/(G12) | W12: 神话梦灵随机珍稀符文
A13: 15 | B13: 星辉秘契 | C13: {=B13} | D13: 2 | E13: =PRODUCT(C13:D13) | F13: 钻石 | G13: 5688 | H13: =G13/U13*10 | I13: 自选神话梦灵 | J13: {=I13} | K13: 2 | L13: =PRODUCT(J13:K13) | M13: 星辉秘契 | N13: {=M13} | O13: 10 | P13: =PRODUCT(N13:O13) | Q13: 自选神话梦灵皮肤 | R13: 8000 | S13: 1 | T13: =PRODUCT(R13:S13) | U13: =SUMIF($B$7:$T$7,"价值*",B13:T13) | V13: =U13/(G13) | W13: 神话梦灵随机稀世符文
A14: 17 | B14: 星辉秘契 | C14: {=B14} | D14: 2 | E14: =PRODUCT(C14:D14) | F14: 钻石 | G14: 5888 | H14: =G14/U14*10 | I14: 幻梦晶核 | J14: {=I14} | K14: 150 | L14: =PRODUCT(J14:K14) | M14: 星辉秘契 | N14: {=M14} | O14: 20 | P14: =PRODUCT(N14:O14) | U14: =SUMIF($B$7:$T$7,"价值*",B14:T14) | V14: =U14/(G14)
A15: 20 | B15: 星辉秘契 | C15: {=B15} | D15: 3 | E15: =PRODUCT(C15:D15) | F15: 钻石 | G15: 7888 | H15: =G15/U15*10 | M15: 星辉秘契 | N15: {=M15} | O15: 30 | P15: =PRODUCT(N15:O15) | Q15: 梦境招募器 | R15: {=Q15} | S15: 300 | T15: =S15*R15 | U15: =SUMIF($B$7:$T$7,"价值*",B15:T15) | V15: =U15/(G15)
Q16: 这个时候还未投放
Q17: 创世祝福石 | R17: 16000 | S17: 1

Sheet 冲刺活动
A1: 招募冲刺
B2: 节点数值 | D2: A_活动轮循任务_activity_round_cycle_data.xml | N2: 轮次数值 | P2: A_活动轮循任务_activity_round_cycle_data.xml
A3: 新节点
B4: 节点数值 | C4: 物品类型 | D4: 数量 | E4: 价值 | F4: 物品类型 | G4: 数量 | H4: 价值 | I4: 总价值 | J4: 返利比 | K4: 新返利比 | N4: 轮次 | O4: 物品类型 | P4: 数量 | Q4: 价值 | R4: 物品类型 | S4: 数量 | T4: 价值 | U4: 物品类型 | V4: 数量 | W4: 价值 | X4: 总价值 | Y4: 原反比 | Z4: 原节点 | AA4: 现节点 | AB4: 现反比
A5: 60 | B5: 60 | C5: 梦境招募器 | D5: 5 | E5: =D5*_xlfn.XLOOKUP(C5,'道具价值表-汇总'!$B:$B,'道具价值表-汇总'!$D:$D,,0,1) | F5: 超能特饮 | G5: 30 | H5: =G5*_xlfn.XLOOKUP(F5,'道具价值表-汇总'!$B:$B,'道具价值表-汇总'!$D:$D,,0,1) | I5: =H5+E5 | J5: 0.18 | K5: =I5/((A5-A4)*30) | N5: 第1轮 | O5: 钻石 | P5: 100 | Q5: =P5*_xlfn.XLOOKUP(O5,'道具价值表-汇总'!$B:$B,'道具价值表-汇总'!$D:$D,,0,1) | R5: 神话梦灵碎片 | S5: 10 | T5: =S5*_xlfn.XLOOKUP(R5,'道具价值表-汇总'!$B:$B,'道具价值表-汇总'!$D:$D,,0,1) | U5: 超能特饮 | V5: 500 | W5: =V5*_xlfn.XLOOKUP(U5,'道具价值表-汇总'!$B:$B,'道具价值表-汇总'!$D:$D,,0,1) | X5: =SUMIF($N$4:$W$4,"价值*",N5:W5) | Y5: 0.098333333 | AA5: 500 | AB5: =X5/(AA5*50)
A6: 120 | B6: 120 | C6: 梦境招募器 | D6: 5 | E6: =D6*_xlfn.XLOOKUP(C6,'道具价值表-汇总'!$B:$B,'道具价值表-汇总'!$D:$D,,0,1) | F6: 超能特饮 | G6: 30 | H6: =G6*_xlfn.XLOOKUP(F6,'道具价值表-汇总'!$B:$B,'道具价值表-汇总'!$D:$D,,0,1) | I6: =H6+E6 | J6: 0.18 | K6: =I6/((A6-A5)*30) | N6: 第2轮 | O6: 钻石 | P6: 150 | Q6: =P6*_xlfn.XLOOKUP(O6,'道具价值表-汇总'!$B:$B,'道具价值表-汇总'!$D:$D,,0,1) | R6: 神话梦灵碎片 | S6: 15 | T6: =S6*_xlfn.XLOOKUP(R6,'道具价值表-汇总'!$B:$B,'道具价值表-汇总'!$D:$D,,0,1) | U6: 超能特饮 | V6: 800 | W6: =V6*_xlfn.XLOOKUP(U6,'道具价值表-汇总'!$B:$B,'道具价值表-汇总'!$D:$D,,0,1) | X6: =SUMIF($N$4:$W$4,"价值*",N6:W6) | Y6: 0.090555556 | AA6: 700 | AB6: =X6/(AA6*50)
A7: 200 | B7: 200 | C7: 梦境招募器 | D7: 5 | E7: =D7*_xlfn.XLOOKUP(C7,'道具价值表-汇总'!$B:$B,'道具价值表-汇总'!$D:$D,,0,1) | F7: 超能特饮 | G7: 30 | H7: =G7*_xlfn.XLOOKUP(F7,'道具价值表-汇总'!$B:$B,'道具价值表-汇总'!$D:$D,,0,1) | I7: =H7+E7 | J7: 0.14 | K7: =I7/((A7-A6)*30) | N7: 第3轮 | O7: 心梦宝石 | P7: 50 | Q7: =P7*_xlfn.XLOOKUP(O7,'道具价值表-汇总'!$B:$B,'道具价值表-汇总'!$D:$D,,0,1) | R7: 神话梦灵碎片 | S7: 20 | T7: =S7*_xlfn.XLOOKUP(R7,'道具价值表-汇总'!$B:$B,'道具价值表-汇总'!$D:$D,,0,1) | U7: 超能特饮 | V7: 1000 | W7: =V7*_xlfn.XLOOKUP(U7,'道具价值表-汇总'!$B:$B,'道具价值表-汇总'!$D:$D,,0,1) | X7: =SUMIF($N$4:$W$4,"价值*",N7:W7) | Y7: 0.13583333 | AA7: 1200 | AB7: =X7/(AA7*50)
A8: 280 | B8: 280 | C8: 梦境招募器 | D8: 10 | E8: =D8*_xlfn.XLOOKUP(C8,'道具价值表-汇总'!$B:$B,'道具价值表-汇总'!$D:$D,,0,1) | F8: 超能特饮 | G8: 50 | H8: =G8*_xlfn.XLOOKUP(F8,'道具价值表-汇总'!$B:$B,'道具价值表-汇总'!$D:$D,,0,1) | I8: =H8+E8 | J8: 0.19 | K8: =I8/((A8-A7)*30) | N8: 第4轮 | O8: 心梦宝石 | P8: 100 | Q8: =P8*_xlfn.XLOOKUP(O8,'道具价值表-汇总'!$B:$B,'道具价值表-汇总'!$D:$D,,0,1) | R8: 神话梦灵碎片 | S8: 30 | T8: =S8*_xlfn.XLOOKUP(R8,'道具价值表-汇总'!$B:$B,'道具价值表-汇总'!$D:$D,,0,1) | U8: 超能特饮 | V8: 1200 | W8: =V8*_xlfn.XLOOKUP(U8,'道具价值表-汇总'!$B:$B,'道具价值表-汇总'!$D:$D,,0,1) | X8: =SUMIF($N$4:$W$4,"价值*",N8:W8) | Y8: 0.115 | AA8: 1600 | AB8: =X8/(AA8*50)
A9: 360 | B9: 360 | C9: 梦境招募器 | D9: 10 | E9: =D9*_xlfn.XLOOKUP(C9,'道具价值表-汇总'!$B:$B,'道具价值表-汇总'!$D:$D,,0,1) | F9: 超能特饮 | G9: 50 | H9: =G9*_xlfn.XLOOKUP(F9,'道具价值表-汇总'!$B:$B,'道具价值表-汇总'!$D:$D,,0,1) | I9: =H9+E9 | J9: 0.17 | K9: =I9/((A9-A8)*30)
A10: 500 | B10: 500 | C10: 梦境招募器 | D10: 10 | E10: =D10*_xlfn.XLOOKUP(C10,'道具价值表-汇总'!$B:$B,'道具价值表-汇总'!$D:$D,,0,1) | F10: 超能特饮 | G10: 50 | H10: =G10*_xlfn.XLOOKUP(F10,'道具价值表-汇总'!$B:$B,'道具价值表-汇总'!$D:$D,,0,1) | I10: =H10+E10 | J10: 0.11 | K10: =I10/((A10-A9)*30)
D11: 270 | G11: 1830 | N11: 任务数值 | P11: A_活动任务_activity_tasks_data.xml
T12: 25
B13: 节点数值 | C13: 物品类型 | D13: 数量 | E13: 价值 | F13: 物品类型 | G13: 数量 | H13: 价值 | I13: 总价值 | J13: 返利比 | K13: 新返利比 | N13: 任务 | O13: 奖励 | P13: 数量 | Q13: 价值
A14: 80 | B14: 80 | C14: 梦境招募器 | D14: 5 | E14: =D14*_xlfn.XLOOKUP(C14,'道具价值表-汇总'!$B:$B,'道具价值表-汇总'!$D:$D,,0,1) | F14: 超能特饮 | G14: 50 | H14: 100 | I14: =H14+E14 | J14: 0.14 | K14: =I14/((A14-A13)*30) | N14: 消耗200体力 | O14: 梦境招募器 | P14: 5 | Q14: 150
A15: 160 | B15: 160 | C15: 梦境招募器 | D15: 5 | E15: =D15*_xlfn.XLOOKUP(C15,'道具价值表-汇总'!$B:$B,'道具价值表-汇总'!$D:$D,,0,1) | F15: 超能特饮 | G15: 50 | H15: 100 | I15: =H15+E15 | J15: 0.14 | K15: =I15/((A15-A14)*30) | N15: 消耗500体力 | O15: 梦境招募器 | P15: 10 | Q15: 300
A16: 260 | B16: 260 | C16: 梦境招募器 | D16: 5 | E16: =D16*_xlfn.XLOOKUP(C16,'道具价值表-汇总'!$B:$B,'道具价值表-汇总'!$D:$D,,0,1) | F16: 超能特饮 | G16: 50 | H16: 100 | I16: =H16+E16 | J16: 0.1 | K16: =I16/((A16-A15)*30) | N16: 消耗1000体力 | O16: 钻石 | P16: 188 | Q16: 188
A17: 380 | B17: 380 | C17: 梦境招募器 | D17: 10 | E17: =D17*_xlfn.XLOOKUP(C17,'道具价值表-汇总'!$B:$B,'道具价值表-汇总'!$D:$D,,0,1) | F17: 超能特饮 | G17: 80 | H17: 160 | I17: =H17+E17 | J17: 0.15 | K17: =I17/((A17-A16)*30) | N17: 参与5次竞技场 | O17: 梦境招募器 | P17: 5 | Q17: 150
A18: 520 | B18: 520 | C18: 梦境招募器 | D18: 10 | E18: =D18*_xlfn.XLOOKUP(C18,'道具价值表-汇总'!$B:$B,'道具价值表-汇总'!$D:$D,,0,1) | F18: 超能特饮 | G18: 80 | H18: 160 | I18: =H18+E18 | J18: 0.11 | K18: =I18/((A18-A17)*30) | N18: 参与10次竞技场 | O18: 梦境招募器 | P18: 10 | Q18: 300
A19: 700 | B19: 700 | C19: 梦境招募器 | D19: 10 | E19: =D19*_xlfn.XLOOKUP(C19,'道具价值表-汇总'!$B:$B,'道具价值表-汇总'!$D:$D,,0,1) | F19: 超能特饮 | G19: 80 | H19: 160 | I19: =H19+E19 | J19: 0.1 | K19: =I19/((A19-A18)*30) | N19: 参与20次竞技场 | O19: 梦愿水晶 | P19: 1 | Q19: 600
D20: 45 | G20: 390 | I20: 2130 | J20: 0.1183
B22: 节点数值 | C22: 物品类型 | D22: 数量 | E22: 价值 | F22: 物品类型 | G22: 数量 | H22: 价值 | I22: 总价值 | J22: 返利比
A23: 120 | B23: 120 | C23: 梦境招募器 | D23: 10 | E23: =D23*_xlfn.XLOOKUP(C23,'道具价值表-汇总'!$B:$B,'道具价值表-汇总'!$D:$D,,0,1) | F23: 超能特饮 | G23: 80 | H23: 160 | I23: =H23+E23 | J23: 0.19 | K23: =I23/((A23-A22)*30)
A24: 240 | B24: 240 | C24: 梦境招募器 | D24: 10 | E24: =D24*_xlfn.XLOOKUP(C24,'道具价值表-汇总'!$B:$B,'道具价值表-汇总'!$D:$D,,0,1) | F24: 超能特饮 | G24: 80 | H24: 160 | I24: =H24+E24 | J24: 0.19 | K24: =I24/((A24-A23)*30)
A25: 360 | B25: 360 | C25: 梦境招募器 | D25: 10 | E25: =D25*_xlfn.XLOOKUP(C25,'道具价值表-汇总'!$B:$B,'道具价值表-汇总'!$D:$D,,0,1) | F25: 超能特饮 | G25: 80 | H25: 160 | I25: =H25+E25 | J25: 0.15 | K25: =I25/((A25-A24)*30)
A26: 560 | B26: 560 | C26: 梦境招募器 | D26: 15 | E26: =D26*_xlfn.XLOOKUP(C26,'道具价值表-汇总'!$B:$B,'道具价值表-汇总'!$D:$D,,0,1) | F26: 超能特饮 | G26: 100 | H26: 200 | I26: =H26+E26 | J26: 0.15 | K26: =I26/((A26-A25)*30)
A27: 800 | B27: 800 | C27: 梦境招募器 | D27: 15 | E27: =D27*_xlfn.XLOOKUP(C27,'道具价值表-汇总'!$B:$B,'道具价值表-汇总'!$D:$D,,0,1) | F27: 超能特饮 | G27: 100 | H27: 200 | I27: =H27+E27 | J27: 0.14 | K27: =I27/((A27-A26)*30) | N27: 需求头像框 | O27: 可以升星给属性
A28: 1200 | B28: 1200 | C28: 梦境招募器 | D28: 15 | E28: =D28*_xlfn.XLOOKUP(C28,'道具价值表-汇总'!$B:$B,'道具价值表-汇总'!$D:$D,,0,1) | F28: 超能特饮 | G28: 100 | H28: 200 | I28: =H28+E28 | J28: 0.09 | K28: =I28/((A28-A27)*30) | N28: 每个冲刺 | O28: 头像框或者聊天框不一样 | Q28: 给与一定的属性
D29: 75 | G29: 540 | I29: 3330 | J29: 0.1388
B31: 节点数值 | C31: 物品类型 | D31: 数量 | E31: 价值 | F31: 物品类型 | G31: 数量 | H31: 价值 | I31: 总价值 | J31: 返利比
A32: 160 | B32: 160 | C32: 梦境招募器 | D32: 15 | E32: 450 | F32: 超能特饮 | G32: 100 | H32: 200 | I32: =H32+E32 | J32: 0.18 | K32: =I32/((A32-A31)*30)
A33: 300 | B33: 300 | C33: 梦境招募器 | D33: 15 | E33: 450 | F33: 超能特饮 | G33: 100 | H33: 200 | I33: =H33+E33 | J33: 0.18 | K33: =I33/((A33-A32)*30)
A34: 500 | B34: 500 | C34: 梦境招募器 | D34: 15 | E34: 450 | F34: 超能特饮 | G34: 100 | H34: 200 | I34: =H34+E34 | J34: 0.14 | K34: =I34/((A34-A33)*30)
A35: 800 | B35: 800 | C35: 梦境招募器 | D35: 20 | E35: 600 | F35: 超能特饮 | G35: 120 | H35: 240 | I35: =H35+E35 | J35: 0.14 | K35: =I35/((A35-A34)*30)
A36: 1200 | B36: 1200 | C36: 梦境招募器 | D36: 20 | E36: 600 | F36: 超能特饮 | G36: 120 | H36: 240 | I36: =H36+E36 | J36: 0.1 | K36: =I36/((A36-A35)*30)
A37: 1600 | B37: 1600 | C37: 梦境招募器 | D37: 20 | E37: 600 | F37: 超能特饮 | G37: 120 | H37: 240 | I37: =H37+E37 | J37: 0.09 | K37: =I37/((A37-A36)*30)
D38: 105 | G38: 660 | I38: 4470 | J38: 0.1242
B40: 商店数值 | D40: A_活动商店_activity_shop_data.xml
B42: 礼包名称 | C42: 价格 | D42: 限购次数 | E42: 物品类型 | F42: 数量 | G42: 价值 | H42: 物品类型 | I42: 数量 | J42: 价值 | K42: 物品类型 | L42: 数量 | M42: 价值 | N42: 总价值 | O42: 返利比 | P42: 折扣 | Q42: 2.5 | W42: 活动充钱上限 | X42: 耗钻上限
B43: 每日免费礼包 | C43: 0 | D43: 1 | E43: 梦境招募器 | F43: 2 | G43: 60 | N43: =SUMIF($B$42:$P$42,"价值*",B43:M43) | W43: 1092 | X43: 36912
B44: 钻石礼包 | C44: 268 | D44: 3 | E44: 梦境招募器 | F44: 20 | G44: 600 | H44: 随机能量特饮 | I44: 50 | J44: =I44*1 | N44: =SUMIF($B$42:$P$42,"价值*",B44:M44) | O44: =N44/C44 | P44: =1/O44*10 | Q44: =N44+N46+N48+N49+N51 | R44: =C44+C46+C48+C49+C51 | S44: =Q44/R44
...

Sheet 悬赏活动
A3: 第一层 | E3: 第一期商品 | K3: 第二期商品 | Q3: 第三期商品 | W3: 第四期商品
B4: 消耗代币 | C4: 道具id | D4: 代币数量 | E4: 奖励内容 | F4: 道具id | G4: 奖励数量 | H4: 单价 | I4: 价值 | K4: 奖励内容 | L4: 道具id | M4: 奖励数量 | N4: 单价 | O4: 价值 | Q4: 奖励内容 | R4: 道具id | S4: 奖励数量 | T4: 单价 | U4: 价值 | W4: 奖励内容 | X4: 道具id | Y4: 奖励数量 | Z4: 单价 | AA4: 价值
B5: 悬赏线索 | C5: 5600208 | D5: 200 | E5: 梦境招募器 | F5: 11 | G5: 20 | H5: 30 | I5: 600 | K5: 梦境招募器 | L5: 11 | M5: 20 | N5: 30 | O5: 600 | Q5: 梦境招募器 | R5: 11 | S5: 20 | T5: 30 | U5: 600 | W5: 梦境招募器 | X5: 11 | Y5: 20 | Z5: 30 | AA5: 600
B6: 悬赏线索 | C6: 5600208 | D6: 200 | E6: 装备图纸 | F6: 50002 | G6: 200 | H6: 3 | I6: 600 | K6: 星之初愿 | L6: 9 | M6: 10 | N6: 50 | O6: 500 | Q6: 星之初愿 | R6: 9 | S6: 10 | T6: 50 | U6: 500 | W6: 星之初愿 | X6: 9 | Y6: 10 | Z6: 50 | AA6: 500
B7: 悬赏线索 | C7: 5600208 | D7: 200 | E7: 随机能量特饮 | F7: 5103001 | G7: 500 | H7: 1 | I7: 500 | K7: 随机能量特饮 | L7: 5103001 | M7: 500 | N7: 1 | O7: 500 | Q7: 随机能量特饮 | R7: 5103001 | S7: 500 | T7: 1 | U7: 500 | W7: 随机能量特饮 | X7: 5103001 | Y7: 500 | Z7: 1 | AA7: 500
A9: 第二层 | G9: 解锁条件 | M9: 解锁条件 | S9: 解锁条件 | Y9: 解锁条件
B10: 消耗代币 | C10: 道具id | D10: 代币数量 | E10: 奖励内容 | F10: 道具id | G10: 奖励数量 | H10: 单价 | I10: 价值 | K10: 奖励内容 | L10: 道具id | M10: 奖励数量 | N10: 单价 | O10: 价值 | Q10: 奖励内容 | R10: 道具id | S10: 奖励数量 | T10: 单价 | U10: 价值 | W10: 奖励内容 | X10: 道具id | Y10: 奖励数量 | Z10: 单价 | AA10: 价值
B11: 悬赏线索 | C11: 5600208 | D11: 400 | E11: 星辉秘契 | F11: 30 | G11: 5 | H11: 280 | I11: 1400 | K11: 精密齿轮 | L11: 63 | M11: 1000 | N11: 1 | O11: 1000 | Q11: 精密齿轮 | R11: 63 | S11: 1000 | T11: 1 | U11: 1000 | W11: 精密齿轮 | X11: 63 | Y11: 1000 | Z11: 1 | AA11: 1000
B12: 悬赏线索 | C12: 5600208 | D12: 400 | E12: 转运石 | F12: 5523001 | G12: 3600 | H12: 0.33 | I12: 1188 | K12: 转运石 | L12: 5523001 | M12: 3600 | N12: 0.33 | O12: 1188 | Q12: 转运石 | R12: 5523001 | S12: 3600 | T12: 0.33 | U12: 1188 | W12: 转运石 | X12: 5523001 | Y12: 3600 | Z12: 0.33 | AA12: 1188
B13: 悬赏线索 | C13: 5600208 | D13: 400 | E13: 超能特饮 | F13: 5104001 | G13: 500 | H13: 2 | I13: 1000 | K13: 超能特饮 | L13: 5104001 | M13: 500 | N13: 2 | O13: 1000 | Q13: 超能特饮 | R13: 5104001 | S13: 500 | T13: 2 | U13: 1000 | W13: 超能特饮 | X13: 5104001 | Y13: 500 | Z13: 2 | AA13: 1000
A15: 第三层 | G15: 解锁条件 | M15: 解锁条件 | S15: 解锁条件 | Y15: 解锁条件
B16: 消耗代币 | C16: 道具id | D16: 代币数量 | E16: 奖励内容 | F16: 道具id | G16: 奖励数量 | H16: 单价 | I16: 价值 | K16: 奖励内容 | L16: 道具id | M16: 奖励数量 | N16: 单价 | O16: 价值 | Q16: 奖励内容 | R16: 道具id | S16: 奖励数量 | T16: 单价 | U16: 价值 | W16: 奖励内容 | X16: 道具id | Y16: 奖励数量 | Z16: 单价 | AA16: 价值
B17: 悬赏线索 | C17: 5600208 | D17: 600 | E17: 星辉秘契 | F17: 30 | G17: 8 | H17: 280 | I17: 2240 | K17: 星辉秘契 | L17: 30 | M17: 8 | N17: 280 | O17: 2240 | Q17: 星辉秘契 | R17: 30 | S17: 8 | T17: 280 | U17: 2240 | W17: 星辉秘契 | X17: 30 | Y17: 8 | Z17: 280 | AA17: 2240
B18: 悬赏线索 | C18: 5600208 | D18: 600 | E18: 梦愿水晶 | F18: 35 | G18: 3 | H18: 600 | I18: 1800 | K18: 梦愿水晶 | L18: 35 | M18: 5 | N18: 600 | O18: 3000 | Q18: 智械发条 | R18: 62 | S18: 10 | T18: 150 | U18: 1500 | W18: 智械发条 | X18: 62 | Y18: 10 | Z18: 150 | AA18: 1500
B19: 悬赏线索 | C19: 5600208 | D19: 600 | E19: 幻梦晶核 | F19: 5305001 | G19: 30 | H19: 60 | I19: 1800 | K19: 幻梦晶核 | L19: 5305001 | M19: 30 | N19: 60 | O19: 1800 | Q19: 幻梦晶核 | R19: 5305001 | S19: 30 | T19: 60 | U19: 1800 | W19: 幻梦晶核 | X19: 5305001 | Y19: 30 | Z19: 60 | AA19: 1800
A21: 第四层 | G21: 解锁条件 | M21: 解锁条件 | S21: 解锁条件 | Y21: 解锁条件
B22: 消耗代币 | C22: 道具id | D22: 代币数量 | E22: 奖励内容 | F22: 道具id | G22: 奖励数量 | H22: 单价 | I22: 价值 | K22: 奖励内容 | L22: 道具id | M22: 奖励数量 | N22: 单价 | O22: 价值 | Q22: 奖励内容 | R22: 道具id | S22: 奖励数量 | T22: 单价 | U22: 价值 | W22: 奖励内容 | X22: 道具id | Y22: 奖励数量 | Z22: 单价 | AA22: 价值
B23: 悬赏线索 | C23: 5600208 | D23: 800 | E23: 自选史诗藏品 | F23: 6220011 | G23: 1 | H23: 2400 | I23: 2400 | K23: 自选史诗藏品 | L23: 6220011 | M23: 1 | N23: 2400 | O23: 2400 | Q23: 自选史诗藏品 | R23: 6220011 | S23: 1 | T23: 2400 | U23: 2400 | W23: 自选史诗藏品 | X23: 6220011 | Y23: 1 | Z23: 2400 | AA23: 2400
B24: 悬赏线索 | C24: 5600208 | D24: 800 | E24: 绮梦随机礼盒Ⅱ | F24: 100122 | G24: 1 | H24: 4000 | I24: 4000 | K24: 传说祝福石 | L24: 5305010 | M24: 2 | N24: 1500 | O24: 3000 | Q24: 绮梦随机礼盒Ⅱ | R24: 100122 | S24: 1 | T24: 4000 | U24: 4000 | W24: 传说祝福石 | X24: 5305010 | Y24: 2 | Z24: 1500 | AA24: 3000
B25: 悬赏线索 | C25: 5600208 | D25: 800 | E25: 传说符文 | F25: 5305000 | G25: 1 | H25: 4000 | I25: 4000 | K25: 智械发条 | L25: 62 | M25: 20 | N25: 150 | O25: 3000 | Q25: 智械发条 | R25: 62 | S25: 20 | T25: 150 | U25: 3000 | W25: 智械发条 | X25: 62 | Y25: 20 | Z25: 150 | AA25: 3000
A27: 第五层 | G27: 解锁条件 | M27: 解锁条件 | S27: 解锁条件 | Y27: 解锁条件
B28: 消耗代币 | C28: 道具id | D28: 代币数量 | E28: 奖励内容 | F28: 道具id | G28: 奖励数量 | H28: 单价 | I28: 价值 | K28: 奖励内容 | L28: 道具id | M28: 奖励数量 | N28: 单价 | O28: 价值 | Q28: 奖励内容 | R28: 道具id | S28: 奖励数量 | T28: 单价 | U28: 价值 | W28: 奖励内容 | X28: 道具id | Y28: 奖励数量 | Z28: 单价 | AA28: 价值
B29: 悬赏线索 | C29: 5600208 | D29: 1300 | E29: 神话祝福石 | F29: 5305008 | G29: 2 | H29: 5000 | I29: 10000 | K29: 神话祝福石 | L29: 5305008 | M29: 2 | N29: 5000 | O29: 10000 | Q29: 神话祝福石 | R29: 5305008 | S29: 2 | T29: 5000 | U29: 10000 | W29: 神话符文 | X29: 5306000 | Y29: 1 | Z29: 16384 | AA29: 16384
B30: 悬赏线索 | C30: 5600208 | D30: 1300 | E30: 神话符文 | F30: 5306000 | G30: 1 | H30: 16384 | I30: 16384 | K30: 神话符文 | L30: 5306000 | M30: 1 | N30: 16384 | O30: 16384 | Q30: 随机创世零件 | R30: 6040004 | S30: 1 | T30: 16000 | U30: 16000 | W30: 随机创世零件 | X30: 6040004 | Y30: 1 | Z30: 16000 | AA30: 16000
B31: 悬赏线索 | C31: 5600208 | D31: 1300 | E31: 万福摇摇机 | F31: 6200011 | G31: 1 | H31: 4800 | I31: 4800 | K31: 双倍碰撞 | L31: 6200014 | M31: 1 | N31: 4800 | O31: 4800 | Q31: 意外之喜 | R31: 6200013 | S31: 1 | T31: 4800 | U31: 4800 | W31: 怦怦时刻 | X31: 6200012 | Y31: 1 | Z31: 4800 | AA31: 4800
G34: 冲刺活动
D35: 核心道具 | I35: 悬赏id
A36: 15 | B36: 1 | C36: 1 | D36: 神话祝福石 | E36: 神话符文 | F36: 万福摇摇机 | G36: 符文 | L36: 绮梦随机礼盒Ⅱ | M36: 随机传说符文
A37: =A36+7 | B37: 2 | C37: 2 | D37: 神话祝福石 | E37: 神话符文 | F37: 双倍碰撞 | G37: 秘宝 | L37: 传说祝福石 | M37: 智械发条
A38: =A37+7 | B38: 3 | C38: 3 | D38: 神话祝福石 | E38: 随机创世零件 | F38: 意外之喜 | G38: 招募 | L38: 绮梦随机礼盒Ⅱ | M38: 智械发条
A39: =A38+7 | B39: 4 | C39: 4 | D39: 神话符文 | E39: 随机创世零件 | F39: 怦怦时刻 | G39: 符文 | L39: 传说祝福石 | M39: 智械发条 | Q39: 3300
A40: =A39+7 | B40: 5 | C40: 2 | D40: 神话祝福石 | E40: 神话符文 | F40: 双倍碰撞 | G40: 秘宝 | L40: 传说祝福石 | M40: 智械发条
A41: =A40+7 | B41: 6 | C41: 3 | D41: 神话祝福石 | E41: 随机创世零件 | F41: 意外之喜 | G41: 招募 | L41: 绮梦随机礼盒Ⅱ | M41: 智械发条
A42: =A41+7 | B42: 7 | C42: 1 | D42: 神话祝福石 | E42: 神话符文 | F42: 万福摇摇机 | G42: 符文 | L42: 绮梦随机礼盒Ⅱ | M42: 随机传说符文
A43: =A42+7 | B43: 8 | C43: 4 | D43: 神话符文 | E43: 随机创世零件 | F43: 怦怦时刻 | G43: 秘宝 | L43: 传说祝福石 | M43: 智械发条
C44: 任务数值
C45: 类型 | D45: 任务详情 | E45: 奖励数值 | F45: 道具id | G45: 奖励数量 | K45: 奖励价值
C46: 每日 | D46: 今日上线登录 | E46: 悬赏线索 | F46: {=_xlfn.XLOOKUP(E46,item!$B$3:$B$100157,item!$A$3:$A$100157,0,0,1)} | G46: 20 | K46: =G46*3 | M46: 20 | N46: 怦怦时刻 | U46: 2 3 4循环
C47: 每日 | D47: 完成1次主线挑战 | E47: 悬赏线索 | F47: {=_xlfn.XLOOKUP(E47,item!$B$3:$B$100157,item!$A$3:$A$100157,0,0,1)} | G47: 30 | K47: =G47*3 | M47: 30
C48: 每日 | D48: 完成1次荧幕争锋 | E48: 悬赏线索 | F48: {=_xlfn.XLOOKUP(E48,item!$B$3:$B$100157,item!$A$3:$A$100157,0,0,1)} | G48: 20 | K48: =G48*3 | M48: 20
...

Sheet 月光炼梦
A1: 月光炼梦
A4: 活动与转盘核心
A5: 活动ID | B5: 时间 | C5: 门槛 | D5: 抽奖货币 | E5: 补足价 | F5: 轮数 | G5: 每轮格数 | H5: 大奖位置 | I5: 位置概率 | J5: 10轮最低 | K5: 10期望 | L5: 10最高
A6: 100342 | C6: 主线≥15关 | D6: 炼梦魔药 | E6: 120 | F6: 10 | G6: 10 | H6: 第8–10抽 | J6: =SUM(L32:L41) | K6: =SUM(M32:M41) | L6: =SUM(N32:N41)
A8: 转盘奖励库
A9: （神算诸葛 / 后羿 / 我爱沙）
A10: 位置 | B10: 当期奖励 | C10: 每轮数量 | D10: 10轮数量 | E10: 价格 | F10: 单次价值 | G10: 10轮固定价值 | H10: 权重 | I10: 单抽 | J10: 单抽价值 | K10: 前M抽必出 | L10: 前M抽禁出 | M10: 规则
A11: 1 | B11: 炼梦宝箱 | C11: 1 | D11: =C11*$F$6 | E11: 6000 | F11: =E11*C11 | G11: =F11*$F$6 | H11: 50 | I11: =H11/$H$21 | J11: =I11*F11 | K11: — | L11: 7 | M11: 大奖；前7抽禁出；抽中可跳轮
A12: 2 | B12: 随机神话梦灵 | C12: 1 | D12: =C12*$F$6 | E12: 480 | F12: =E12*C12 | G12: =F12*$F$6 | H12: 450 | I12: =H12/$H$21 | J12: =I12*F12 | K12: 4 | L12: — | M12: 前4抽内必出
A13: 3 | B13: 梦境招募器 | C13: 15 | D13: =C13*$F$6 | E13: 30 | F13: =E13*C13 | G13: =F13*$F$6 | H13: 600 | I13: =H13/$H$21 | J13: =I13*F13 | K13: — | L13: — | M13: 普通奖励；跳轮可能放弃
A14: 4 | B14: 幻梦晶核 | C14: 5 | D14: =C14*$F$6 | E14: 60 | F14: =E14*C14 | G14: =F14*$F$6 | H14: 850 | I14: =H14/$H$21 | J14: =I14*F14 | K14: — | L14: — | M14: 普通奖励；跳轮可能放弃
A15: 5 | B15: 星之初愿 | C15: 5 | D15: =C15*$F$6 | E15: 50 | F15: =E15*C15 | G15: =F15*$F$6 | H15: 950 | I15: =H15/$H$21 | J15: =I15*F15 | K15: — | L15: — | M15: 普通奖励；跳轮可能放弃
A16: 6 | B16: 星辉秘契 | C16: 1 | D16: =C16*$F$6 | E16: 280 | F16: =E16*C16 | G16: =F16*$F$6 | H16: 1300 | I16: =H16/$H$21 | J16: =I16*F16 | K16: — | L16: — | M16: 普通奖励；跳轮可能放弃
A17: 7 | B17: 超能特饮 | C17: 100 | D17: =C17*$F$6 | E17: 2 | F17: =E17*C17 | G17: =F17*$F$6 | H17: 1450 | I17: =H17/$H$21 | J17: =I17*F17 | K17: — | L17: — | M17: 普通奖励；跳轮可能放弃
A18: 8 | B18: 装备图纸 | C18: 50 | D18: =C18*$F$6 | E18: 3 | F18: =E18*C18 | G18: =F18*$F$6 | H18: 1450 | I18: =H18/$H$21 | J18: =I18*F18 | K18: — | L18: — | M18: 普通奖励；跳轮可能放弃
A19: 9 | B19: 转运石 | C19: 300 | D19: =C19*$F$6 | E19: 0.33 | F19: =E19*C19 | G19: =F19*$F$6 | H19: 1450 | I19: =H19/$H$21 | J19: =I19*F19 | K19: — | L19: — | M19: 普通奖励；跳轮可能放弃
A20: 10 | B20: 金币 | C20: 2000 | D20: =C20*$F$6 | E20: 0.05 | F20: =E20*C20 | G20: =F20*$F$6 | H20: 1450 | I20: =H20/$H$21 | J20: =I20*F20 | K20: — | L20: — | M20: 普通奖励；跳轮可能放弃
G21: =SUM(G11:G20) | H21: =SUM(H11:H20) | J21: =SUM(J11:J20) | K21: =J21/E6
F22: =120*46 | K22: 返利
A23: 大奖箱二级池
A24: 初始权重不是每次独立概率；条件锁定、限次和隐藏回退需按动态池理解。
A25: 类别 | B25: 初始权重 | C25: 最终内容 | D25: 价值 | E25: 道具价值 | F25: 单个箱子价值 | G25: 炼梦宝箱价值
A26: 天使套 | B26: 200 | D26: 8000 | E26: =D26*(B26/1000)
A27: 武器 | B27: 800 | D27: 4000 | E27: =D27*(B27/1000) | F27: 4800 | G27: 4800 | H27: 2次武器后第3次必然是天使套
A29: 轮次成本
A30: 逐抽成本与参考转盘表同样按轮次横向排列。
A31: 轮 | B31: 抽1 | C31: 抽2 | D31: 抽3 | E31: 抽4 | F31: 抽5 | G31: 抽6 | H31: 抽7 | I31: 抽8 | J31: 抽9 | K31: 抽10 | L31: 第8抽累计 | M31: 期望累计 | N31: 抽满累计
A32: 1 | B32: 1 | C32: 1 | D32: 2 | E32: 3 | F32: 4 | G32: 5 | H32: 6 | I32: 7 | J32: 8 | K32: 9 | L32: =SUM(B32:I32) | M32: =AVERAGE(L32,N32) | N32: =SUM(B32:K32)
A33: 2 | B33: 1 | C33: 1 | D33: 2 | E33: 3 | F33: 4 | G33: 5 | H33: 6 | I33: 8 | J33: 9 | K33: 10 | L33: =SUM(B33:I33) | M33: =AVERAGE(L33,N33) | N33: =SUM(B33:K33)
A34: 3 | B34: 1 | C34: 1 | D34: 2 | E34: 3 | F34: 4 | G34: 5 | H34: 6 | I34: 9 | J34: 10 | K34: 11 | L34: =SUM(B34:I34) | M34: =AVERAGE(L34,N34) | N34: =SUM(B34:K34)
A35: 4 | B35: 1 | C35: 1 | D35: 2 | E35: 3 | F35: 4 | G35: 5 | H35: 6 | I35: 10 | J35: 11 | K35: 12 | L35: =SUM(B35:I35) | M35: =AVERAGE(L35,N35) | N35: =SUM(B35:K35)
A36: 5 | B36: 1 | C36: 1 | D36: 2 | E36: 3 | F36: 4 | G36: 5 | H36: 6 | I36: 10 | J36: 12 | K36: 13 | L36: =SUM(B36:I36) | M36: =AVERAGE(L36,N36) | N36: =SUM(B36:K36)
A37: 6 | B37: 1 | C37: 1 | D37: 2 | E37: 3 | F37: 4 | G37: 5 | H37: 6 | I37: 10 | J37: 13 | K37: 15 | L37: =SUM(B37:I37) | M37: =AVERAGE(L37,N37) | N37: =SUM(B37:K37)
A38: 7 | B38: 1 | C38: 1 | D38: 2 | E38: 3 | F38: 4 | G38: 5 | H38: 6 | I38: 10 | J38: 13 | K38: 15 | L38: =SUM(B38:I38) | M38: =AVERAGE(L38,N38) | N38: =SUM(B38:K38)
A39: 8 | B39: 1 | C39: 1 | D39: 2 | E39: 3 | F39: 4 | G39: 5 | H39: 6 | I39: 10 | J39: 13 | K39: 15 | L39: =SUM(B39:I39) | M39: =AVERAGE(L39,N39) | N39: =SUM(B39:K39)
A40: 9 | B40: 1 | C40: 1 | D40: 2 | E40: 3 | F40: 4 | G40: 5 | H40: 6 | I40: 10 | J40: 13 | K40: 15 | L40: =SUM(B40:I40) | M40: =AVERAGE(L40,N40) | N40: =SUM(B40:K40)
A41: 10 | B41: 1 | C41: 1 | D41: 2 | E41: 3 | F41: 4 | G41: 5 | H41: 6 | I41: 10 | J41: 13 | K41: 15 | L41: =SUM(B41:I41) | M41: =AVERAGE(L41,N41) | N41: =SUM(B41:K41)
A43: 配套任务
A44: 完整3天做满共10瓶；仅列当期任务ID。
A45: 分类 | B45: 刷新 | C45: 任务 | D45: 最大次数 | E45: 奖励 | F45: 单次数量 | G45: 活动期数量 | H45: 任务ID | L45: =L41*120
...

Sheet 星轨探测
B2: 活动持续时间
B3: 卡池数值
C4: *钻石 | D4: *钻石
C5: 单抽价格 | D5: 五连价格 | E5: 保底 | F5: 期望 | G5: 实际概率 | H5: 期望比
C6: 100 | D6: 500 | E6: 90 | F6: 80 | G6: =1/F6 | H6: =F6/E6
T7: 450
C8: 物品类型 | D8: 数量 | E8: 价值 | F8: 权重 | G8: 抽取概率 | H8: 保底概率 | I8: 保底抽数 | J8: 单抽价值 | K8: 实际价值 | L8: 实际数量 | M8: 前N次不出 | N8: N次必出 | O8: 抽中后N次不出 | P8: 至多获取上限 | Q8: 展示概率 | T8: 450抽产出
A9: 8 | C9: 织梦补星机 | D9: 1 | E9: 12000 | F9: 10 | G9: =F9/$F$17 | H9: =1/I9 | I9: 90 | J9: =H9*E9 | K9: =J9 | L9: =H9*D9 | M9: 20 | N9: 90 | O9: 20 | P9: 5 | Q9: =H9 | R9: =Q9*10000 | S9: 织梦补星机 | T9: =$T$7*H9*D9
A10: 5 | C10: 探测器 | D10: 1 | E10: 100 | F10: 700 | G10: =F10/$F$17 | H10: =(1-$H$9)*(F10/($F$17-$F$9)) | I10: =1/H10 | J10: =H10*E10 | K10: =J10 | L10: =H10*D10 | Q10: =H10 | R10: =Q10*10000 | S10: 探测器 | T10: =$T$7*H10*D10
A11: 7 | C11: 智械发条 | D11: 1 | E11: 150 | F11: 600 | G11: =F11/$F$17 | H11: =(1-$H$9)*(F11/($F$17-$F$9)) | I11: =1/H11 | J11: =H11*E11 | K11: =J11 | L11: =H11*D11 | Q11: =H11 | R11: =Q11*10000 | S11: =C11 | T11: =$T$7*H11*D11
