Workbook

Sheet 说明
A1: 基因养成
A3: 说明
C5: 基因升级
D6: 梦灵升级消耗【基因罐】＋【金币】＋【时间】，大节点消耗【大基因罐】 | P6: 基因养成体验
D7: 基因升级的属性加给主角攻击力，对标装备养成节奏 | P7: 1、养成：全绑定主角伤害，少量攻击力丢到这里来。
P8: 2、加速产出： 大量在前期运营活动、主线通关奖励（快速释放）、每日任务（主要）里面产加速材料
P9: 3、天赋石产出：体力扫荡（主要）、个人挑战本商店（肝度）、
P10: 整体体验：前期用主线和活动产的加速去释放，每天固定产很多小时加速（48h+），防止需要高频点击带来的肝度提升
C12: 关联配置
D14: 配置 | E14: 字段 | F14: 值 | G14: 说明
D15: J_基因_evolve_data
D16: X_效果映射_effect_mapping_data | G16: *基因节点引用效果映射表，具体技能内容根据实际进行配置
G17: *预留最后一行
A19: 本页结束

Sheet 养成属性
A1: 养成属性
C3: 属性规划
H4: 对标梦灵升级 | N4: 对标技能 | O4: 对标梦灵升阶
A8: 本页结束

Sheet 秘宝养成
A1: 基因升级
C3: 秘宝概率
J4: 1 | K4: 2 | L4: 3 | M4: 4 | N4: 5 | O4: 6 | P4: 7 | Q4: 8 | R4: 9 | S4: 10
D5: 秘宝等级 | E5: 披风消耗 | F5: 技能升级消耗 | G5: 天数 | H5: 预期强度 | I5: 秘宝强度 | J5: 白 | K5: 绿 | L5: 蓝 | M5: 紫 | N5: 橙 | O5: 红 | P5: 粉 | Q5: 彩 | R5: 彩1 | S5: 彩2 | T5: 彩3 | U5: 1 | V5: 2 | W5: 3 | X5: 4 | Y5: 5 | Z5: 6 | AA5: 7 | AB5: 8 | AC5: 9 | AD5: 10
A6: =SUM($E$6:E6) -> 10000 | D6: 1 | E6: 10000 | F6: 3000 | G6: =E6/5000+2 -> 4 | H6: =OFFSET($E$69,0,D6)*5*0.5+1 -> 1.1446759 | I6: =1 -> 1 | J6: 0.5 | K6: 0.4 | L6: 0.09 | M6: 0.01 | T6: =_xlfn.TEXTJOIN(",",1,U6:AD6) -> {1,5000},{2,4000},{3,900},{4,100} | U6: =IF(J6="","","{"&J$4&","&J6*10000&"}") -> {1,5000} | V6: =IF(K6="","","{"&K$4&","&K6*10000&"}") -> {2,4000} | W6: =IF(L6="","","{"&L$4&","&L6*10000&"}") -> {3,900} | X6: =IF(M6="","","{"&M$4&","&M6*10000&"}") -> {4,100} | Y6: =IF(N6="","","{"&N$4&","&N6*10000&"}") | Z6: =IF(O6="","","{"&O$4&","&O6*10000&"}") | AA6: =IF(P6="","","{"&P$4&","&P6*10000&"}") | AB6: =IF(Q6="","","{"&Q$4&","&Q6*10000&"}") | ... AE6: =IF(T6="","","{"&T$4&","&T6*10000&"}") -> #VALUE! | AI6: =IF(Y6="","","{"&Y$4&","&Y6*10000&"}")
A7: =SUM($E$6:E7) -> 30000 | D7: 2 | E7: 20000 | F7: 6000 | G7: =E7/5000+G6+1 -> 9 | H7: =OFFSET($E$69,0,D7)*5+1 -> 1.3472222 | I7: =I6*2^0.2 -> 1.1486984 | J7: 0.3 | K7: 0.55 | L7: 0.12 | M7: 0.03 | T7: =_xlfn.TEXTJOIN(",",1,U7:AD7) -> {1,3000},{2,5500},{3,1200},{4,300} | U7: =IF(J7="","","{"&J$4&","&J7*10000&"}") -> {1,3000} | V7: =IF(K7="","","{"&K$4&","&K7*10000&"}") -> {2,5500} | W7: =IF(L7="","","{"&L$4&","&L7*10000&"}") -> {3,1200} | X7: =IF(M7="","","{"&M$4&","&M7*10000&"}") -> {4,300} | Y7: =IF(N7="","","{"&N$4&","&N7*10000&"}") | Z7: =IF(O7="","","{"&O$4&","&O7*10000&"}") | AA7: =IF(P7="","","{"&P$4&","&P7*10000&"}") | AB7: =IF(Q7="","","{"&Q$4&","&Q7*10000&"}") | ... AD7: =IF(S7="","","{"&S$4&","&S7*10000&"}")
A8: =SUM($E$6:E8) -> 70000 | D8: 3 | E8: 40000 | F8: =F7*2 -> 12000 | G8: =E8/6000+G7+1 -> 16.666667 | H8: =OFFSET($E$69,0,D8)*5+1 -> 1.4166667 | I8: =I7*2^0.2 -> 1.3195079 | K8: 0.65 | L8: 0.24 | M8: 0.1 | N8: 0.01 | T8: =_xlfn.TEXTJOIN(",",1,U8:AD8) -> {2,6500},{3,2400},{4,1000},{5,100} | U8: =IF(J8="","","{"&J$4&","&J8*10000&"}") | V8: =IF(K8="","","{"&K$4&","&K8*10000&"}") -> {2,6500} | W8: =IF(L8="","","{"&L$4&","&L8*10000&"}") -> {3,2400} | X8: =IF(M8="","","{"&M$4&","&M8*10000&"}") -> {4,1000} | Y8: =IF(N8="","","{"&N$4&","&N8*10000&"}") -> {5,100} | Z8: =IF(O8="","","{"&O$4&","&O8*10000&"}") | AA8: =IF(P8="","","{"&P$4&","&P8*10000&"}") | AB8: =IF(Q8="","","{"&Q$4&","&Q8*10000&"}") | ... AD8: =IF(S8="","","{"&S$4&","&S8*10000&"}")
A9: =SUM($E$6:E9) -> 150000 | D9: 4 | E9: 80000 | F9: 25000 | G9: =E9/7000+G8+1 -> 29.095238 | H9: =OFFSET($E$69,0,D9)*5+1 -> 1.5 | I9: =I8*2^0.2 -> 1.5157166 | L9: 0.65 | M9: 0.24 | N9: 0.1 | O9: 0.01 | T9: =_xlfn.TEXTJOIN(",",1,U9:AD9) -> {3,6500},{4,2400},{5,1000},{6,100} | U9: =IF(J9="","","{"&J$4&","&J9*10000&"}") | V9: =IF(K9="","","{"&K$4&","&K9*10000&"}") | W9: =IF(L9="","","{"&L$4&","&L9*10000&"}") -> {3,6500} | X9: =IF(M9="","","{"&M$4&","&M9*10000&"}") -> {4,2400} | Y9: =IF(N9="","","{"&N$4&","&N9*10000&"}") -> {5,1000} | Z9: =IF(O9="","","{"&O$4&","&O9*10000&"}") -> {6,100} | AA9: =IF(P9="","","{"&P$4&","&P9*10000&"}") | AB9: =IF(Q9="","","{"&Q$4&","&Q9*10000&"}") | ... AD9: =IF(S9="","","{"&S$4&","&S9*10000&"}")
A10: =SUM($E$6:E10) -> 300000 | D10: 5 | E10: 150000 | F10: =F9*2 -> 50000 | G10: =E10/8000+G9+1 -> 48.845238 | H10: =OFFSET($E$69,0,D10)*5+1 -> 1.6 | I10: =I9*2^0.2 -> 1.7411011 | M10: 0.65 | N10: 0.24 | O10: 0.1 | P10: 0.01 | T10: =_xlfn.TEXTJOIN(",",1,U10:AD10) -> {4,6500},{5,2400},{6,1000},{7,100} | U10: =IF(J10="","","{"&J$4&","&J10*10000&"}") | V10: =IF(K10="","","{"&K$4&","&K10*10000&"}") | W10: =IF(L10="","","{"&L$4&","&L10*10000&"}") | X10: =IF(M10="","","{"&M$4&","&M10*10000&"}") -> {4,6500} | Y10: =IF(N10="","","{"&N$4&","&N10*10000&"}") -> {5,2400} | Z10: =IF(O10="","","{"&O$4&","&O10*10000&"}") -> {6,1000} | AA10: =IF(P10="","","{"&P$4&","&P10*10000&"}") -> {7,100} | AB10: =IF(Q10="","","{"&Q$4&","&Q10*10000&"}") | ... AD10: =IF(S10="","","{"&S$4&","&S10*10000&"}")
A11: =SUM($E$6:E11) -> 600000 | D11: 6 | E11: 300000 | F11: =F10*2 -> 100000 | G11: =E11/8000+G10+1 -> 87.345238 | H11: =OFFSET($E$69,0,D11)*5+1 -> 1.72 | I11: =I10*2^0.2 -> 2 | M11: 0.25 | N11: 0.5 | O11: 0.2 | P11: 0.05 | T11: =_xlfn.TEXTJOIN(",",1,U11:AD11) -> {4,2500},{5,5000},{6,2000},{7,500} | U11: =IF(J11="","","{"&J$4&","&J11*10000&"}") | V11: =IF(K11="","","{"&K$4&","&K11*10000&"}") | W11: =IF(L11="","","{"&L$4&","&L11*10000&"}") | X11: =IF(M11="","","{"&M$4&","&M11*10000&"}") -> {4,2500} | Y11: =IF(N11="","","{"&N$4&","&N11*10000&"}") -> {5,5000} | Z11: =IF(O11="","","{"&O$4&","&O11*10000&"}") -> {6,2000} | AA11: =IF(P11="","","{"&P$4&","&P11*10000&"}") -> {7,500} | AB11: =IF(Q11="","","{"&Q$4&","&Q11*10000&"}") | ... AD11: =IF(S11="","","{"&S$4&","&S11*10000&"}")
A12: =SUM($E$6:E12) -> 1200000 | D12: 7 | E12: 600000 | F12: =F11*2 -> 200000 | G12: =E12/8000+G11+1 -> 163.34524 | H12: =OFFSET($E$69,0,D12)*5+1 -> 1.864 | I12: =I11*2^0.1 -> 2.1435469 | N12: 0.54 | O12: 0.35 | P12: 0.1 | Q12: 0.01 | T12: =_xlfn.TEXTJOIN(",",1,U12:AD12) -> {5,5400},{6,3500},{7,1000},{8,100} | U12: =IF(J12="","","{"&J$4&","&J12*10000&"}") | V12: =IF(K12="","","{"&K$4&","&K12*10000&"}") | W12: =IF(L12="","","{"&L$4&","&L12*10000&"}") | X12: =IF(M12="","","{"&M$4&","&M12*10000&"}") | Y12: =IF(N12="","","{"&N$4&","&N12*10000&"}") -> {5,5400} | Z12: =IF(O12="","","{"&O$4&","&O12*10000&"}") -> {6,3500} | AA12: =IF(P12="","","{"&P$4&","&P12*10000&"}") -> {7,1000} | AB12: =IF(Q12="","","{"&Q$4&","&Q12*10000&"}") -> {8,100} | ... AD12: =IF(S12="","","{"&S$4&","&S12*10000&"}")
A13: =SUM($E$6:E13) -> 2400000 | D13: 8 | E13: =E12*2 -> 1200000 | F13: =F12*2 -> 400000 | G13: =E13/8000+G12+1 -> 314.34524 | H13: =OFFSET($E$69,0,D13)*5+1 -> 2.0368 | I13: =I12*2^0.1 -> 2.2973967 | N13: 0.3 | O13: 0.35 | P13: 0.3 | Q13: 0.05 | T13: =_xlfn.TEXTJOIN(",",1,U13:AD13) -> {5,3000},{6,3500},{7,3000},{8,500} | U13: =IF(J13="","","{"&J$4&","&J13*10000&"}") | V13: =IF(K13="","","{"&K$4&","&K13*10000&"}") | W13: =IF(L13="","","{"&L$4&","&L13*10000&"}") | X13: =IF(M13="","","{"&M$4&","&M13*10000&"}") | Y13: =IF(N13="","","{"&N$4&","&N13*10000&"}") -> {5,3000} | Z13: =IF(O13="","","{"&O$4&","&O13*10000&"}") -> {6,3500} | AA13: =IF(P13="","","{"&P$4&","&P13*10000&"}") -> {7,3000} | AB13: =IF(Q13="","","{"&Q$4&","&Q13*10000&"}") -> {8,500} | ... AD13: =IF(S13="","","{"&S$4&","&S13*10000&"}")
A14: =SUM($E$6:E14) -> 4900000 | D14: 9 | E14: 2500000 | F14: =F13*2 -> 800000 | G14: =E14/8000+G13+1 -> 627.84524 | H14: =OFFSET($E$69,0,D14)*5+1 -> 2.24416 | I14: =I13*2^0.1 -> 2.4622888 | N14: 0.1 | O14: 0.4 | P14: 0.39 | Q14: 0.1 | R14: 0.01 | T14: =_xlfn.TEXTJOIN(",",1,U14:AD14) -> {5,1000},{6,4000},{7,3900},{8,1000},{9,100} | U14: =IF(J14="","","{"&J$4&","&J14*10000&"}") | V14: =IF(K14="","","{"&K$4&","&K14*10000&"}") | W14: =IF(L14="","","{"&L$4&","&L14*10000&"}") | X14: =IF(M14="","","{"&M$4&","&M14*10000&"}") | Y14: =IF(N14="","","{"&N$4&","&N14*10000&"}") -> {5,1000} | Z14: =IF(O14="","","{"&O$4&","&O14*10000&"}") -> {6,4000} | AA14: =IF(P14="","","{"&P$4&","&P14*10000&"}") -> {7,3900} | AB14: =IF(Q14="","","{"&Q$4&","&Q14*10000&"}") -> {8,1000} | ... AD14: =IF(S14="","","{"&S$4&","&S14*10000&"}")
A15: =SUM($E$6:E15) -> 9900000 | D15: 10 | E15: =E14*2 -> 5000000 | F15: =F14*2 -> 1600000 | G15: =E15/8000+G14+1 -> 1253.8452 | H15: =OFFSET($E$69,0,D15)*5+1 -> 2.492992 | I15: =I14*2^0.1 -> 2.6390158 | O15: 0.38 | P15: 0.45 | Q15: 0.15 | R15: 0.02 | T15: =_xlfn.TEXTJOIN(",",1,U15:AD15) -> {6,3800},{7,4500},{8,1500},{9,200} | U15: =IF(J15="","","{"&J$4&","&J15*10000&"}") | V15: =IF(K15="","","{"&K$4&","&K15*10000&"}") | W15: =IF(L15="","","{"&L$4&","&L15*10000&"}") | X15: =IF(M15="","","{"&M$4&","&M15*10000&"}") | Y15: =IF(N15="","","{"&N$4&","&N15*10000&"}") | Z15: =IF(O15="","","{"&O$4&","&O15*10000&"}") -> {6,3800} | AA15: =IF(P15="","","{"&P$4&","&P15*10000&"}") -> {7,4500} | AB15: =IF(Q15="","","{"&Q$4&","&Q15*10000&"}") -> {8,1500} | ... AD15: =IF(S15="","","{"&S$4&","&S15*10000&"}")
A16: =SUM($E$6:E16) -> 19900000 | D16: 11 | E16: =E15*2 -> 10000000 | F16: =F15*2 -> 3200000 | G16: =E16/8000+G15+1 -> 2504.8452 | H16: =OFFSET($E$69,0,D16)*5+1 -> 2.7915904 | I16: =I15*2^0.1 -> 2.8284271 | O16: 0.2 | P16: 0.5 | Q16: 0.24 | R16: 0.05 | S16: 0.01 | T16: =_xlfn.TEXTJOIN(",",1,U16:AD16) -> {6,2000},{7,5000},{8,2400},{9,500},{10,100} | U16: =IF(J16="","","{"&J$4&","&J16*10000&"}") | V16: =IF(K16="","","{"&K$4&","&K16*10000&"}") | W16: =IF(L16="","","{"&L$4&","&L16*10000&"}") | X16: =IF(M16="","","{"&M$4&","&M16*10000&"}") | Y16: =IF(N16="","","{"&N$4&","&N16*10000&"}") | Z16: =IF(O16="","","{"&O$4&","&O16*10000&"}") -> {6,2000} | AA16: =IF(P16="","","{"&P$4&","&P16*10000&"}") -> {7,5000} | AB16: =IF(Q16="","","{"&Q$4&","&Q16*10000&"}") -> {8,2400} | ... AD16: =IF(S16="","","{"&S$4&","&S16*10000&"}") -> {10,100}
A17: =SUM($E$6:E17) -> 39900000 | D17: 12 | E17: =E16*2 -> 20000000 | F17: =F16*2 -> 6400000 | G17: =E17/8000+G16+1 -> 5005.8452 | H17: =OFFSET($E$69,0,D17)*5+1 -> 3.1499085 | I17: =I16*2^0.1 -> 3.0314331 | O17: 0.1 | P17: 0.4 | Q17: 0.38 | R17: 0.1 | S17: 0.02 | T17: =_xlfn.TEXTJOIN(",",1,U17:AD17) -> {6,1000},{7,4000},{8,3800},{9,1000},{10,200} | U17: =IF(J17="","","{"&J$4&","&J17*10000&"}") | V17: =IF(K17="","","{"&K$4&","&K17*10000&"}") | W17: =IF(L17="","","{"&L$4&","&L17*10000&"}") | X17: =IF(M17="","","{"&M$4&","&M17*10000&"}") | Y17: =IF(N17="","","{"&N$4&","&N17*10000&"}") | Z17: =IF(O17="","","{"&O$4&","&O17*10000&"}") -> {6,1000} | AA17: =IF(P17="","","{"&P$4&","&P17*10000&"}") -> {7,4000} | AB17: =IF(Q17="","","{"&Q$4&","&Q17*10000&"}") -> {8,3800} | ... AD17: =IF(S17="","","{"&S$4&","&S17*10000&"}") -> {10,200}
T19: 1 | U19: 2 | V19: 3 | W19: 4 | X19: 5 | Y19: 6 | Z19: 7 | AA19: 8 | AB19: 9 | AC19: 10
A20: ="[{"&C20&","&G20&"}]" -> [{4,11}] | C20: 4 | D20: 1 | E20: =_xlfn.XLOOKUP(H20,$D$33:$D$37,$E$33:$E$37) -> 0.9881 | F20: =1-H20 -> 0.99 | G20: =_xlfn.XLOOKUP(H20,$D$33:$D$38,$F$33:$F$38)-1 -> 11 | H20: 0.01 | I20: =ROUND(J6/($F20)*($E20),4) -> 0.499 | J20: =ROUND(K6/($F20)*($E20),4) -> 0.3992 | K20: =ROUND(L6/($F20)*($E20),4) -> 0.0898 | L20: =1-_xlfn.XLOOKUP($H20,$D$33:$D$37,$E$33:$E$37) -> 0.0119 | S20: ="["&_xlfn.TEXTJOIN(",",1,T20:AC20)&"]" -> [{1,4990},{2,3992},{3,898},{4,119}] | T20: =IF(I20="","","{"&J$4&","&I20*10000&"}") -> {1,4990} | U20: =IF(J20="","","{"&K$4&","&J20*10000&"}") -> {2,3992} | V20: =IF(K20="","","{"&L$4&","&K20*10000&"}") -> {3,898} | W20: =IF(L20="","","{"&M$4&","&L20*10000&"}") -> {4,119} | X20: =IF(M20="","","{"&N$4&","&M20*10000&"}") | Y20: =IF(N20="","","{"&O$4&","&N20*10000&"}") | Z20: =IF(O20="","","{"&P$4&","&O20*10000&"}") | AA20: =IF(P20="","","{"&Q$4&","&P20*10000&"}") | ... AC20: =IF(R20="","","{"&S$4&","&R20*10000&"}")
A21: ="[{"&C21&","&G21&"}]" -> [{4,3}] | C21: 4 | D21: 2 | E21: =_xlfn.XLOOKUP(H21,$D$33:$D$37,$E$33:$E$37) -> 0.967 | F21: =1-H21 -> 0.97 | G21: =_xlfn.XLOOKUP(H21,$D$33:$D$38,$F$33:$F$38)-1 -> 3 | H21: 0.03 | I21: =ROUND(J7/($F21)*($E21),4) -> 0.2991 | J21: =ROUND(K7/($F21)*($E21),4) -> 0.5483 | K21: =ROUND(L7/($F21)*($E21),4) -> 0.1196 | L21: =1-_xlfn.XLOOKUP($H21,$D$33:$D$37,$E$33:$E$37) -> 0.033 | S21: ="["&_xlfn.TEXTJOIN(",",1,T21:AC21)&"]" -> [{1,2991},{2,5483},{3,1196},{4,330}] | T21: =IF(I21="","","{"&J$4&","&I21*10000&"}") -> {1,2991} | U21: =IF(J21="","","{"&K$4&","&J21*10000&"}") -> {2,5483} | V21: =IF(K21="","","{"&L$4&","&K21*10000&"}") -> {3,1196} | W21: =IF(L21="","","{"&M$4&","&L21*10000&"}") -> {4,330} | X21: =IF(M21="","","{"&N$4&","&M21*10000&"}") | Y21: =IF(N21="","","{"&O$4&","&N21*10000&"}") | Z21: =IF(O21="","","{"&P$4&","&O21*10000&"}") | AA21: =IF(P21="","","{"&Q$4&","&P21*10000&"}") | ... AC21: =IF(R21="","","{"&S$4&","&R21*10000&"}")
A22: ="[{"&C22&","&G22&"}]" -> [{5,11}] | C22: 5 | D22: 3 | E22: =_xlfn.XLOOKUP(H22,$D$33:$D$37,$E$33:$E$37) -> 0.9881 | F22: =1-H22 -> 0.99 | G22: =_xlfn.XLOOKUP(H22,$D$33:$D$38,$F$33:$F$38)-1 -> 11 | H22: 0.01 | J22: =ROUND(K8/($F22)*($E22),4) -> 0.6488 | K22: =ROUND(L8/($F22)*($E22),4) -> 0.2395 | L22: =ROUND(M8/($F22)*($E22),4) -> 0.0998 | M22: =1-_xlfn.XLOOKUP($H22,$D$33:$D$37,$E$33:$E$37) -> 0.0119 | S22: ="["&_xlfn.TEXTJOIN(",",1,T22:AC22)&"]" -> [{2,6488},{3,2395},{4,998},{5,119}] | T22: =IF(I22="","","{"&J$4&","&I22*10000&"}") | U22: =IF(J22="","","{"&K$4&","&J22*10000&"}") -> {2,6488} | V22: =IF(K22="","","{"&L$4&","&K22*10000&"}") -> {3,2395} | W22: =IF(L22="","","{"&M$4&","&L22*10000&"}") -> {4,998} | X22: =IF(M22="","","{"&N$4&","&M22*10000&"}") -> {5,119} | Y22: =IF(N22="","","{"&O$4&","&N22*10000&"}") | Z22: =IF(O22="","","{"&P$4&","&O22*10000&"}") | AA22: =IF(P22="","","{"&Q$4&","&P22*10000&"}") | ... AC22: =IF(R22="","","{"&S$4&","&R22*10000&"}")
A23: ="[{"&C23&","&G23&"}]" -> [{6,11}] | C23: 6 | D23: 4 | E23: =_xlfn.XLOOKUP(H23,$D$33:$D$37,$E$33:$E$37) -> 0.9881 | F23: =1-H23 -> 0.99 | G23: =_xlfn.XLOOKUP(H23,$D$33:$D$38,$F$33:$F$38)-1 -> 11 | H23: 0.01 | K23: =ROUND(L9/($F23)*($E23),4) -> 0.6488 | L23: =ROUND(M9/($F23)*($E23),4) -> 0.2395 | M23: =ROUND(N9/($F23)*($E23),4) -> 0.0998 | N23: =1-_xlfn.XLOOKUP($H23,$D$33:$D$37,$E$33:$E$37) -> 0.0119 | S23: ="["&_xlfn.TEXTJOIN(",",1,T23:AC23)&"]" -> [{3,6488},{4,2395},{5,998},{6,119}] | T23: =IF(I23="","","{"&J$4&","&I23*10000&"}") | U23: =IF(J23="","","{"&K$4&","&J23*10000&"}") | V23: =IF(K23="","","{"&L$4&","&K23*10000&"}") -> {3,6488} | W23: =IF(L23="","","{"&M$4&","&L23*10000&"}") -> {4,2395} | X23: =IF(M23="","","{"&N$4&","&M23*10000&"}") -> {5,998} | Y23: =IF(N23="","","{"&O$4&","&N23*10000&"}") -> {6,119} | Z23: =IF(O23="","","{"&P$4&","&O23*10000&"}") | AA23: =IF(P23="","","{"&Q$4&","&P23*10000&"}") | ... AC23: =IF(R23="","","{"&S$4&","&R23*10000&"}")
A24: ="[{"&C24&","&G24&"}]" -> [{7,11}] | C24: 7 | D24: 5 | E24: =_xlfn.XLOOKUP(H24,$D$33:$D$37,$E$33:$E$37) -> 0.9881 | F24: =1-H24 -> 0.99 | G24: =_xlfn.XLOOKUP(H24,$D$33:$D$38,$F$33:$F$38)-1 -> 11 | H24: 0.01 | L24: =ROUND(M10/($F24)*($E24),4) -> 0.6488 | M24: =ROUND(N10/($F24)*($E24),4) -> 0.2395 | N24: =ROUND(O10/($F24)*($E24),4) -> 0.0998 | O24: =1-_xlfn.XLOOKUP($H24,$D$33:$D$37,$E$33:$E$37) -> 0.0119 | S24: ="["&_xlfn.TEXTJOIN(",",1,T24:AC24)&"]" -> [{4,6488},{5,2395},{6,998},{7,119}] | T24: =IF(I24="","","{"&J$4&","&I24*10000&"}") | U24: =IF(J24="","","{"&K$4&","&J24*10000&"}") | V24: =IF(K24="","","{"&L$4&","&K24*10000&"}") | W24: =IF(L24="","","{"&M$4&","&L24*10000&"}") -> {4,6488} | X24: =IF(M24="","","{"&N$4&","&M24*10000&"}") -> {5,2395} | Y24: =IF(N24="","","{"&O$4&","&N24*10000&"}") -> {6,998} | Z24: =IF(O24="","","{"&P$4&","&O24*10000&"}") -> {7,119} | AA24: =IF(P24="","","{"&Q$4&","&P24*10000&"}") | ... AC24: =IF(R24="","","{"&S$4&","&R24*10000&"}")
A25: ="[{"&C25&","&G25&"}]" -> [{7,2}] | C25: 7 | D25: 6 | E25: =_xlfn.XLOOKUP(H25,$D$33:$D$37,$E$33:$E$37) -> 0.9444 | F25: =1-H25 -> 0.95 | G25: =_xlfn.XLOOKUP(H25,$D$33:$D$38,$F$33:$F$38)-1 -> 2 | H25: 0.05 | L25: =ROUND(M11/($F25)*($E25),4) -> 0.2485 | M25: =ROUND(N11/($F25)*($E25),4) -> 0.4971 | N25: =ROUND(O11/($F25)*($E25),4) -> 0.1988 | O25: =1-_xlfn.XLOOKUP($H25,$D$33:$D$37,$E$33:$E$37) -> 0.0556 | S25: ="["&_xlfn.TEXTJOIN(",",1,T25:AC25)&"]" -> [{4,2485},{5,4971},{6,1988},{7,556}] | T25: =IF(I25="","","{"&J$4&","&I25*10000&"}") | U25: =IF(J25="","","{"&K$4&","&J25*10000&"}") | V25: =IF(K25="","","{"&L$4&","&K25*10000&"}") | W25: =IF(L25="","","{"&M$4&","&L25*10000&"}") -> {4,2485} | X25: =IF(M25="","","{"&N$4&","&M25*10000&"}") -> {5,4971} | Y25: =IF(N25="","","{"&O$4&","&N25*10000&"}") -> {6,1988} | Z25: =IF(O25="","","{"&P$4&","&O25*10000&"}") -> {7,556} | AA25: =IF(P25="","","{"&Q$4&","&P25*10000&"}") | ... AC25: =IF(R25="","","{"&S$4&","&R25*10000&"}")
A26: ="[{"&C26&","&G26&"}]" -> [{8,11}] | C26: 8 | D26: 7 | E26: =_xlfn.XLOOKUP(H26,$D$33:$D$37,$E$33:$E$37) -> 0.9881 | F26: =1-H26 -> 0.99 | G26: =_xlfn.XLOOKUP(H26,$D$33:$D$38,$F$33:$F$38)-1 -> 11 | H26: 0.01 | M26: =ROUND(N12/($F26)*($E26),4) -> 0.539 | N26: =ROUND(O12/($F26)*($E26),4) -> 0.3493 | O26: =ROUND(P12/($F26)*($E26),4) -> 0.0998 | P26: =1-_xlfn.XLOOKUP($H26,$D$33:$D$37,$E$33:$E$37) -> 0.0119 | S26: ="["&_xlfn.TEXTJOIN(",",1,T26:AC26)&"]" -> [{5,5390},{6,3493},{7,998},{8,119}] | T26: =IF(I26="","","{"&J$4&","&I26*10000&"}") | U26: =IF(J26="","","{"&K$4&","&J26*10000&"}") | V26: =IF(K26="","","{"&L$4&","&K26*10000&"}") | W26: =IF(L26="","","{"&M$4&","&L26*10000&"}") | X26: =IF(M26="","","{"&N$4&","&M26*10000&"}") -> {5,5390} | Y26: =IF(N26="","","{"&O$4&","&N26*10000&"}") -> {6,3493} | Z26: =IF(O26="","","{"&P$4&","&O26*10000&"}") -> {7,998} | AA26: =IF(P26="","","{"&Q$4&","&P26*10000&"}") -> {8,119} | ... AC26: =IF(R26="","","{"&S$4&","&R26*10000&"}")
A27: ="[{"&C27&","&G27&"}]" -> [{8,2}] | C27: 8 | D27: 8 | E27: =_xlfn.XLOOKUP(H27,$D$33:$D$37,$E$33:$E$37) -> 0.9444 | F27: =1-H27 -> 0.95 | G27: =_xlfn.XLOOKUP(H27,$D$33:$D$38,$F$33:$F$38)-1 -> 2 | H27: 0.05 | M27: =ROUND(N13/($F27)*($E27),4) -> 0.2982 | N27: =ROUND(O13/($F27)*($E27),4) -> 0.3479 | O27: =ROUND(P13/($F27)*($E27),4) -> 0.2982 | P27: =1-_xlfn.XLOOKUP($H27,$D$33:$D$37,$E$33:$E$37) -> 0.0556 | S27: ="["&_xlfn.TEXTJOIN(",",1,T27:AC27)&"]" -> [{5,2982},{6,3479},{7,2982},{8,556}] | T27: =IF(I27="","","{"&J$4&","&I27*10000&"}") | U27: =IF(J27="","","{"&K$4&","&J27*10000&"}") | V27: =IF(K27="","","{"&L$4&","&K27*10000&"}") | W27: =IF(L27="","","{"&M$4&","&L27*10000&"}") | X27: =IF(M27="","","{"&N$4&","&M27*10000&"}") -> {5,2982} | Y27: =IF(N27="","","{"&O$4&","&N27*10000&"}") -> {6,3479} | Z27: =IF(O27="","","{"&P$4&","&O27*10000&"}") -> {7,2982} | AA27: =IF(P27="","","{"&Q$4&","&P27*10000&"}") -> {8,556} | ... AC27: =IF(R27="","","{"&S$4&","&R27*10000&"}")
A28: ="[{"&C28&","&G28&"}]" -> [{9,11}] | C28: 9 | D28: 9 | E28: =_xlfn.XLOOKUP(H28,$D$33:$D$37,$E$33:$E$37) -> 0.9881 | F28: =1-H28 -> 0.99 | G28: =_xlfn.XLOOKUP(H28,$D$33:$D$38,$F$33:$F$38)-1 -> 11 | H28: 0.01 | M28: =ROUND(N14/($F28)*($E28),4) -> 0.0998 | N28: =ROUND(O14/($F28)*($E28),4) -> 0.3992 | O28: =ROUND(P14/($F28)*($E28),4) -> 0.3893 | P28: =ROUND(Q14/($F28)*($E28),4) -> 0.0998 | Q28: =1-_xlfn.XLOOKUP($H28,$D$33:$D$37,$E$33:$E$37) -> 0.0119 | S28: ="["&_xlfn.TEXTJOIN(",",1,T28:AC28)&"]" -> [{5,998},{6,3992},{7,3893},{8,998},{9,119}] | T28: =IF(I28="","","{"&J$4&","&I28*10000&"}") | U28: =IF(J28="","","{"&K$4&","&J28*10000&"}") | V28: =IF(K28="","","{"&L$4&","&K28*10000&"}") | W28: =IF(L28="","","{"&M$4&","&L28*10000&"}") | X28: =IF(M28="","","{"&N$4&","&M28*10000&"}") -> {5,998} | Y28: =IF(N28="","","{"&O$4&","&N28*10000&"}") -> {6,3992} | Z28: =IF(O28="","","{"&P$4&","&O28*10000&"}") -> {7,3893} | AA28: =IF(P28="","","{"&Q$4&","&P28*10000&"}") -> {8,998} | ... AC28: =IF(R28="","","{"&S$4&","&R28*10000&"}")
A29: ="[{"&C29&","&G29&"}]" -> [{9,5}] | C29: 9 | D29: 10 | E29: =_xlfn.XLOOKUP(H29,$D$33:$D$37,$E$33:$E$37) -> 0.9778 | F29: =1-H29 -> 0.98 | G29: =_xlfn.XLOOKUP(H29,$D$33:$D$38,$F$33:$F$38)-1 -> 5 | H29: 0.02 | N29: =ROUND(O15/($F29)*($E29),4) -> 0.3791 | O29: =ROUND(P15/($F29)*($E29),4) -> 0.449 | P29: =ROUND(Q15/($F29)*($E29),4) -> 0.1497 | Q29: =1-_xlfn.XLOOKUP($H29,$D$33:$D$37,$E$33:$E$37) -> 0.0222 | S29: ="["&_xlfn.TEXTJOIN(",",1,T29:AC29)&"]" -> [{6,3791},{7,4490},{8,1497},{9,222}] | T29: =IF(I29="","","{"&J$4&","&I29*10000&"}") | U29: =IF(J29="","","{"&K$4&","&J29*10000&"}") | V29: =IF(K29="","","{"&L$4&","&K29*10000&"}") | W29: =IF(L29="","","{"&M$4&","&L29*10000&"}") | X29: =IF(M29="","","{"&N$4&","&M29*10000&"}") | Y29: =IF(N29="","","{"&O$4&","&N29*10000&"}") -> {6,3791} | Z29: =IF(O29="","","{"&P$4&","&O29*10000&"}") -> {7,4490} | AA29: =IF(P29="","","{"&Q$4&","&P29*10000&"}") -> {8,1497} | ... AC29: =IF(R29="","","{"&S$4&","&R29*10000&"}")
A30: ="[{"&C30&","&G30&"}]" -> [{10,11}] | C30: 10 | D30: 11 | E30: =_xlfn.XLOOKUP(H30,$D$33:$D$37,$E$33:$E$37) -> 0.9881 | F30: =1-H30 -> 0.99 | G30: =_xlfn.XLOOKUP(H30,$D$33:$D$38,$F$33:$F$38)-1 -> 11 | H30: 0.01 | N30: =ROUND(O16/($F30)*($E30),4) -> 0.1996 | O30: =ROUND(P16/($F30)*($E30),4) -> 0.499 | P30: =ROUND(Q16/($F30)*($E30),4) -> 0.2395 | Q30: =ROUND(R16/($F30)*($E30),4) -> 0.0499 | R30: =1-_xlfn.XLOOKUP($H30,$D$33:$D$37,$E$33:$E$37) -> 0.0119 | S30: ="["&_xlfn.TEXTJOIN(",",1,T30:AC30)&"]" -> [{6,1996},{7,4990},{8,2395},{9,499},{10,119}] | T30: =IF(I30="","","{"&J$4&","&I30*10000&"}") | U30: =IF(J30="","","{"&K$4&","&J30*10000&"}") | V30: =IF(K30="","","{"&L$4&","&K30*10000&"}") | W30: =IF(L30="","","{"&M$4&","&L30*10000&"}") | X30: =IF(M30="","","{"&N$4&","&M30*10000&"}") | Y30: =IF(N30="","","{"&O$4&","&N30*10000&"}") -> {6,1996} | Z30: =IF(O30="","","{"&P$4&","&O30*10000&"}") -> {7,4990} | AA30: =IF(P30="","","{"&Q$4&","&P30*10000&"}") -> {8,2395} | ... AC30: =IF(R30="","","{"&S$4&","&R30*10000&"}") -> {10,119}
A31: ="[{"&C31&","&G31&"}]" -> [{10,5}] | C31: 10 | D31: 12 | E31: =_xlfn.XLOOKUP(H31,$D$33:$D$37,$E$33:$E$37) -> 0.9778 | F31: =1-H31 -> 0.98 | G31: =_xlfn.XLOOKUP(H31,$D$33:$D$38,$F$33:$F$38)-1 -> 5 | H31: 0.02 | N31: =ROUND(O17/($F31)*($E31),4) -> 0.0998 | O31: =ROUND(P17/($F31)*($E31),4) -> 0.3991 | P31: =ROUND(Q17/($F31)*($E31),4) -> 0.3791 | Q31: =ROUND(R17/($F31)*($E31),4) -> 0.0998 | R31: =1-_xlfn.XLOOKUP($H31,$D$33:$D$37,$E$33:$E$37) -> 0.0222 | S31: ="["&_xlfn.TEXTJOIN(",",1,T31:AC31)&"]" -> [{6,998},{7,3991},{8,3791},{9,998},{10,222}] | T31: =IF(I31="","","{"&J$4&","&I31*10000&"}") | U31: =IF(J31="","","{"&K$4&","&J31*10000&"}") | V31: =IF(K31="","","{"&L$4&","&K31*10000&"}") | W31: =IF(L31="","","{"&M$4&","&L31*10000&"}") | X31: =IF(M31="","","{"&N$4&","&M31*10000&"}") | Y31: =IF(N31="","","{"&O$4&","&N31*10000&"}") -> {6,998} | Z31: =IF(O31="","","{"&P$4&","&O31*10000&"}") -> {7,3991} | AA31: =IF(P31="","","{"&Q$4&","&P31*10000&"}") -> {8,3791} | ... AC31: =IF(R31="","","{"&S$4&","&R31*10000&"}") -> {10,222}
D32: 预期概率 | E32: 稀释概率 | F32: 保底次数
D33: 0.01 | E33: =1-0.0119 -> 0.9881 | F33: 12
D34: 0.05 | E34: =1-0.0556 -> 0.9444 | F34: 3
D35: 0.02 | E35: =1-0.0222 -> 0.9778 | F35: 6
D36: 0.03 | E36: =1-0.033 -> 0.967 | F36: 4
C38: 秘宝属性 | H38: =37.4/0.62 -> 60.322581
F40: 1 | G40: 2 | H40: 3 | I40: 4 | J40: 5 | K40: 6 | L40: 7 | M40: 8
F41: 1.2 | G41: 1.2 | H41: 1.2 | I41: 1.2 | J41: 1.2 | K41: 1.2 | L41: 1.2 | M41: 1.2 | N41: 1.2 | O41: 1.2 | P41: 1.2 | Q41: 1.2
D42: 秘宝词条 | E42: 属性原子 | F42: 普通 | G42: 优秀 | H42: 稀有 | I42: 史诗 | J42: 传说 | K42: 神话 | L42: 创世 | M42: 炫彩1 | N42: 炫彩2 | O42: 炫彩3 | P42: 9 | Q42: 10
R43: 城墙血 | S43: 0.15 | T43: =SUM(U43:BE43) -> 30 | U43: 4 | X43: 1 | AA43: 1 | AB43: 1 | AC43: 1 | AE43: 1 | AH43: 1 | AI43: 1 | AK43: 1 | AL43: 1 | AM43: 1 | AO43: 2 | AQ43: 1 | AS43: 1 | AT43: 1 | AU43: 1 | AV43: 1 | AW43: 1 | AX43: 1 | AY43: 1 | AZ43: 1 | BA43: 2 | BC43: 2 | BE43: 1
R44: 怪物抵抗 | S44: 0.1 | T44: =SUM(U44:BE44) -> 26 | U44: 4 | Z44: 1 | AA44: 2 | AB44: 1 | AC44: 1 | AD44: 1 | AE44: 1 | AJ44: 2 | AL44: 1 | AP44: 1 | AQ44: 1 | AR44: 1 | AT44: 3 | AZ44: 1 | BA44: 1 | BB44: 2 | BD44: 1 | BE44: 1
...

Sheet 秘宝产销
A1: 基因升级
C3: 投放规划
F4: 100 | G4: 240
D5: 产出预期 | E5: 产出途径 | F5: 白银罗盘 | G5: 黄金罗盘 | H5: 总产出 | I5: 占比 | J5: 总和 | K5: 后期(加成)
D6: 蔚蓝 | E6: 公会商店 | F6: =10*60 -> 600 | G6: =2*60 -> 120 | H6: {=SUMPRODUCT(F$4:G$4,F6:G6)} -> 88800 | I6: =H6/SUM($H$6:$H$10) -> 0.27534884 | J6: =SUM(H6:H9) -> 296100 | K6: =J6*1.5 -> 444150
E7: 矿鼠之家 | F7: =15*60 -> 900 | H7: {=SUMPRODUCT(F$4:G$4,F7:G7)} -> 90000 | I7: =H7/SUM($H$6:$H$10) -> 0.27906977
E8: 竞技场商店 | F8: =10*60 -> 600 | G8: =2*60 -> 120 | H8: {=SUMPRODUCT(F$4:G$4,F8:G8)} -> 88800 | I8: =H8/SUM($H$6:$H$10) -> 0.27534884 | M8: =32*0.3 -> 9.6
E9: 公会boss | F9: =5*57 -> 285 | H9: {=SUMPRODUCT(F$4:G$4,F9:G9)} -> 28500 | I9: =H9/SUM($H$6:$H$10) -> 0.088372093
E10: 主线挑战 | F10: =2*60 -> 120 | G10: =60*1 -> 60 | H10: {=SUMPRODUCT(F$4:G$4,F10:G10)} -> 26400 | I10: =H10/SUM($H$6:$H$10) -> 0.081860465
D11: 梦境 | E11: 公会商店 | F11: =H11*57 -> 57000 | H11: 1000 | I11: =F11/SUM($F$11:$F$16) -> 0.18621366 | J11: =SUM(H11:H14) -> 3200 | K11: =J11+H11+H12 -> 5400
E12: 公会挂机 | F12: =H12*57 -> 68400 | H12: 1200 | I12: =F12/SUM($F$11:$F$16) -> 0.22345639
E13: 竞技场挑战
E14: 竞技场商店 | F14: =H14*57 -> 57000 | H14: 1000 | I14: =F14/SUM($F$11:$F$16) -> 0.18621366
E15: 公会boss | F15: =H15*57 -> 91200 | H15: 1600 | I15: =F15/SUM($F$11:$F$16) -> 0.29794185
E16: 主线挑战 | F16: =65*500 -> 32500 | I16: =F16/SUM($F$11:$F$16) -> 0.10617445
D18: 公会 | E18: 外围
D19: =SUM(H11:H12)/SUM(H11:H14) -> 0.6875 | E19: =SUM(H13:H14)/SUM(H11:H14) -> 0.3125
C21: 秘宝规划
D22: 一句话总结：我们秘宝太前置，养成资源拿的轻松了一些，释放感觉弱。蔚蓝偏后置不断拿地鼠材料去兑换
G23: 开启时间从先到后
D24: 产出预期 | E24: 产出途径 | F24: 系统定位 | G24: 开启时间 | H24: 产出占比 | I24: 定位分析
D25: 蔚蓝 | E25: 功能开启 | G25: 第15关（第一天）
E26: 竞技场商店 | F26: 每日商店（产出矿鼠材料） | G26: 第8关（第一天） | H26: =I8 -> 0.27534884
E27: 矿鼠之家 | F27: 玩法向（周期性产出） | G27: 第15关（第一天） | H27: =I7 -> 0.27906977 | I27: 提前开放，前期格子不够没啥体验
E28: 公会商店 | F28: 每日商店（产出矿鼠材料） | G28: 第3天 | H28: =I6 -> 0.27534884
E29: 公会boss | F29: 每日挑战（产出矿鼠材料） | G29: 第3天 | H29: =I9 -> 0.088372093
E30: 主线挑战 | F30: 一次产出 | G30: 第30关（第三、四天） | H30: =I10 -> 0.081860465
D32: 梦境 | E32: 功能开启 | G32: 第30关（第三、四天），快的话第二天
E33: 竞技场挑战 | F33: 每日挑战 | G33: 第8关（第一天） | H33: =I13 -> 0 | I33: 最早投放 | J33: 担心这里撑不起体验
E34: 公会挂机 | F34: 每日挂机（缺少这里的体验） | G34: 第二天 | H34: =I12 -> 0.22345639 | I34: 循环产出，有基础体验
E35: 公会商店 | F35: 每日商店 | G35: 第二天、14号服第三天 | H35: =I11 -> 0.18621366
E36: 竞技场商店 | F36: 每日商店 | G36: 第三天 | H36: =I14 -> 0.18621366
E37: 主线宝箱 | F37: 一次产出 | G37: 第30关（第三、四天） | H37: =I16 -> 0.10617445

Sheet 秘宝配置
D3: 1 | E3: 2 | F3: 3 | G3: 4 | H3: 5 | I3: 6 | J3: 7 | K3: 8 | L3: 9 | M3: 10 | R3: 1 | S3: 2 | T3: 3 | U3: 4 | V3: 5 | W3: 6 | X3: 7 | Y3: 8 | Z3: 9 | AA3: 10 | AB3: 11 | AC3: 12
A4: =500 -> 500 | B4: 对高速怪物增伤 | C4: 613 | D4: =秘宝养成!H101 -> 0.083333333 | E4: =秘宝养成!I101 -> 0.12 | F4: =秘宝养成!J101 -> 0.125 | G4: =秘宝养成!K101 -> 0.15 | H4: =秘宝养成!L101 -> 0.18 | I4: =秘宝养成!M101 -> 0.216 | J4: =秘宝养成!N101 -> 0.27 | K4: =秘宝养成!O101 -> 0.3375 | ... M4: =秘宝养成!Q101 -> 0.486 | N4: =M4*1.2 -> 0.5832 | O4: =N4*1.2 -> 0.69984 | Q4: 1 | R4: =INT(OFFSET($C$3,$Q4,_xlfn.XLOOKUP(R$3,秘宝养成!$D$20:$D$31,秘宝养成!$C$20:$C$31))*10000) -> 1500 | S4: =INT(OFFSET($C$3,$Q4,_xlfn.XLOOKUP(S$3,秘宝养成!$D$20:$D$31,秘宝养成!$C$20:$C$31))*10000) -> 1500 | T4: =INT(OFFSET($C$3,$Q4,_xlfn.XLOOKUP(T$3,秘宝养成!$D$20:$D$31,秘宝养成!$C$20:$C$31))*10000) -> 1800 | U4: =INT(OFFSET($C$3,$Q4,_xlfn.XLOOKUP(U$3,秘宝养成!$D$20:$D$31,秘宝养成!$C$20:$C$31))*10000) -> 2160 | V4: =INT(OFFSET($C$3,$Q4,_xlfn.XLOOKUP(V$3,秘宝养成!$D$20:$D$31,秘宝养成!$C$20:$C$31))*10000) -> 2700 | W4: =INT(OFFSET($C$3,$Q4,_xlfn.XLOOKUP(W$3,秘宝养成!$D$20:$D$31,秘宝养成!$C$20:$C$31))*10000) -> 2700 | X4: =INT(OFFSET($C$3,$Q4,_xlfn.XLOOKUP(X$3,秘宝养成!$D$20:$D$31,秘宝养成!$C$20:$C$31))*10000) -> 3375 | Y4: =INT(OFFSET($C$3,$Q4,_xlfn.XLOOKUP(Y$3,秘宝养成!$D$20:$D$31,秘宝养成!$C$20:$C$31))*10000) -> 3375 | ... AC4: =INT(OFFSET($C$3,$Q4,_xlfn.XLOOKUP(AC$3,秘宝养成!$D$20:$D$31,秘宝养成!$C$20:$C$31))*10000) -> 4860
A5: =500 -> 500 | B5: 对飞行怪物增伤 | C5: 614 | D5: =秘宝养成!H102 -> 0.083333333 | E5: =秘宝养成!I102 -> 0.12 | F5: =秘宝养成!J102 -> 0.125 | G5: =秘宝养成!K102 -> 0.15 | H5: =秘宝养成!L102 -> 0.18 | I5: =秘宝养成!M102 -> 0.216 | J5: =秘宝养成!N102 -> 0.27 | K5: =秘宝养成!O102 -> 0.3375 | ... M5: =秘宝养成!Q102 -> 0.486 | N5: =M5*1.2 -> 0.5832 | O5: =N5*1.2 -> 0.69984 | Q5: 2 | R5: =INT(OFFSET($C$3,$Q5,_xlfn.XLOOKUP(R$3,秘宝养成!$D$20:$D$31,秘宝养成!$C$20:$C$31))*10000) -> 1500 | S5: =INT(OFFSET($C$3,$Q5,_xlfn.XLOOKUP(S$3,秘宝养成!$D$20:$D$31,秘宝养成!$C$20:$C$31))*10000) -> 1500 | T5: =INT(OFFSET($C$3,$Q5,_xlfn.XLOOKUP(T$3,秘宝养成!$D$20:$D$31,秘宝养成!$C$20:$C$31))*10000) -> 1800 | U5: =INT(OFFSET($C$3,$Q5,_xlfn.XLOOKUP(U$3,秘宝养成!$D$20:$D$31,秘宝养成!$C$20:$C$31))*10000) -> 2160 | V5: =INT(OFFSET($C$3,$Q5,_xlfn.XLOOKUP(V$3,秘宝养成!$D$20:$D$31,秘宝养成!$C$20:$C$31))*10000) -> 2700 | W5: =INT(OFFSET($C$3,$Q5,_xlfn.XLOOKUP(W$3,秘宝养成!$D$20:$D$31,秘宝养成!$C$20:$C$31))*10000) -> 2700 | X5: =INT(OFFSET($C$3,$Q5,_xlfn.XLOOKUP(X$3,秘宝养成!$D$20:$D$31,秘宝养成!$C$20:$C$31))*10000) -> 3375 | Y5: =INT(OFFSET($C$3,$Q5,_xlfn.XLOOKUP(Y$3,秘宝养成!$D$20:$D$31,秘宝养成!$C$20:$C$31))*10000) -> 3375 | ... AC5: =INT(OFFSET($C$3,$Q5,_xlfn.XLOOKUP(AC$3,秘宝养成!$D$20:$D$31,秘宝养成!$C$20:$C$31))*10000) -> 4860
A6: =500 -> 500 | B6: 对肉盾怪物增伤 | C6: 615 | D6: =秘宝养成!H103 -> 0.083333333 | E6: =秘宝养成!I103 -> 0.12 | F6: =秘宝养成!J103 -> 0.125 | G6: =秘宝养成!K103 -> 0.15 | H6: =秘宝养成!L103 -> 0.18 | I6: =秘宝养成!M103 -> 0.216 | J6: =秘宝养成!N103 -> 0.27 | K6: =秘宝养成!O103 -> 0.3375 | ... M6: =秘宝养成!Q103 -> 0.486 | N6: =M6*1.2 -> 0.5832 | O6: =N6*1.2 -> 0.69984 | Q6: 3 | R6: =INT(OFFSET($C$3,$Q6,_xlfn.XLOOKUP(R$3,秘宝养成!$D$20:$D$31,秘宝养成!$C$20:$C$31))*10000) -> 1500 | S6: =INT(OFFSET($C$3,$Q6,_xlfn.XLOOKUP(S$3,秘宝养成!$D$20:$D$31,秘宝养成!$C$20:$C$31))*10000) -> 1500 | T6: =INT(OFFSET($C$3,$Q6,_xlfn.XLOOKUP(T$3,秘宝养成!$D$20:$D$31,秘宝养成!$C$20:$C$31))*10000) -> 1800 | U6: =INT(OFFSET($C$3,$Q6,_xlfn.XLOOKUP(U$3,秘宝养成!$D$20:$D$31,秘宝养成!$C$20:$C$31))*10000) -> 2160 | V6: =INT(OFFSET($C$3,$Q6,_xlfn.XLOOKUP(V$3,秘宝养成!$D$20:$D$31,秘宝养成!$C$20:$C$31))*10000) -> 2700 | W6: =INT(OFFSET($C$3,$Q6,_xlfn.XLOOKUP(W$3,秘宝养成!$D$20:$D$31,秘宝养成!$C$20:$C$31))*10000) -> 2700 | X6: =INT(OFFSET($C$3,$Q6,_xlfn.XLOOKUP(X$3,秘宝养成!$D$20:$D$31,秘宝养成!$C$20:$C$31))*10000) -> 3375 | Y6: =INT(OFFSET($C$3,$Q6,_xlfn.XLOOKUP(Y$3,秘宝养成!$D$20:$D$31,秘宝养成!$C$20:$C$31))*10000) -> 3375 | ... AC6: =INT(OFFSET($C$3,$Q6,_xlfn.XLOOKUP(AC$3,秘宝养成!$D$20:$D$31,秘宝养成!$C$20:$C$31))*10000) -> 4860
A7: =500 -> 500 | B7: 对首领增伤 | C7: 610 | D7: =秘宝养成!H104 -> 0.16666667 | E7: =秘宝养成!I104 -> 0.24 | F7: =秘宝养成!J104 -> 0.25 | G7: =秘宝养成!K104 -> 0.3 | H7: =秘宝养成!L104 -> 0.36 | I7: =秘宝养成!M104 -> 0.432 | J7: =秘宝养成!N104 -> 0.54 | K7: =秘宝养成!O104 -> 0.675 | ... M7: =秘宝养成!Q104 -> 0.972 | N7: =M7*1.2 -> 1.1664 | O7: =N7*1.2 -> 1.39968 | Q7: 4 | R7: =INT(OFFSET($C$3,$Q7,_xlfn.XLOOKUP(R$3,秘宝养成!$D$20:$D$31,秘宝养成!$C$20:$C$31))*10000) -> 3000 | S7: =INT(OFFSET($C$3,$Q7,_xlfn.XLOOKUP(S$3,秘宝养成!$D$20:$D$31,秘宝养成!$C$20:$C$31))*10000) -> 3000 | T7: =INT(OFFSET($C$3,$Q7,_xlfn.XLOOKUP(T$3,秘宝养成!$D$20:$D$31,秘宝养成!$C$20:$C$31))*10000) -> 3600 | U7: =INT(OFFSET($C$3,$Q7,_xlfn.XLOOKUP(U$3,秘宝养成!$D$20:$D$31,秘宝养成!$C$20:$C$31))*10000) -> 4320 | V7: =INT(OFFSET($C$3,$Q7,_xlfn.XLOOKUP(V$3,秘宝养成!$D$20:$D$31,秘宝养成!$C$20:$C$31))*10000) -> 5400 | W7: =INT(OFFSET($C$3,$Q7,_xlfn.XLOOKUP(W$3,秘宝养成!$D$20:$D$31,秘宝养成!$C$20:$C$31))*10000) -> 5400 | X7: =INT(OFFSET($C$3,$Q7,_xlfn.XLOOKUP(X$3,秘宝养成!$D$20:$D$31,秘宝养成!$C$20:$C$31))*10000) -> 6750 | Y7: =INT(OFFSET($C$3,$Q7,_xlfn.XLOOKUP(Y$3,秘宝养成!$D$20:$D$31,秘宝养成!$C$20:$C$31))*10000) -> 6750 | ... AC7: =INT(OFFSET($C$3,$Q7,_xlfn.XLOOKUP(AC$3,秘宝养成!$D$20:$D$31,秘宝养成!$C$20:$C$31))*10000) -> 9720
A8: 150 | B8: 无视战士抗性 | C8: 1113 | D8: =秘宝养成!H105 -> 0.05787037 | E8: =秘宝养成!I105 -> 0.08 | F8: =秘宝养成!J105 -> 0.083333333 | G8: =秘宝养成!K105 -> 0.1 | H8: =秘宝养成!L105 -> 0.12 | I8: =秘宝养成!M105 -> 0.144 | J8: =秘宝养成!N105 -> 0.18 | K8: =秘宝养成!O105 -> 0.225 | ... M8: =秘宝养成!Q105 -> 0.324 | N8: =M8*1.2 -> 0.3888 | O8: =N8*1.2 -> 0.46656 | Q8: 5 | R8: =INT(OFFSET($C$3,$Q8,_xlfn.XLOOKUP(R$3,秘宝养成!$D$20:$D$31,秘宝养成!$C$20:$C$31))*10000) -> 1000 | S8: =INT(OFFSET($C$3,$Q8,_xlfn.XLOOKUP(S$3,秘宝养成!$D$20:$D$31,秘宝养成!$C$20:$C$31))*10000) -> 1000 | T8: =INT(OFFSET($C$3,$Q8,_xlfn.XLOOKUP(T$3,秘宝养成!$D$20:$D$31,秘宝养成!$C$20:$C$31))*10000) -> 1200 | U8: =INT(OFFSET($C$3,$Q8,_xlfn.XLOOKUP(U$3,秘宝养成!$D$20:$D$31,秘宝养成!$C$20:$C$31))*10000) -> 1440 | V8: =INT(OFFSET($C$3,$Q8,_xlfn.XLOOKUP(V$3,秘宝养成!$D$20:$D$31,秘宝养成!$C$20:$C$31))*10000) -> 1800 | W8: =INT(OFFSET($C$3,$Q8,_xlfn.XLOOKUP(W$3,秘宝养成!$D$20:$D$31,秘宝养成!$C$20:$C$31))*10000) -> 1800 | X8: =INT(OFFSET($C$3,$Q8,_xlfn.XLOOKUP(X$3,秘宝养成!$D$20:$D$31,秘宝养成!$C$20:$C$31))*10000) -> 2250 | Y8: =INT(OFFSET($C$3,$Q8,_xlfn.XLOOKUP(Y$3,秘宝养成!$D$20:$D$31,秘宝养成!$C$20:$C$31))*10000) -> 2250 | ... AC8: =INT(OFFSET($C$3,$Q8,_xlfn.XLOOKUP(AC$3,秘宝养成!$D$20:$D$31,秘宝养成!$C$20:$C$31))*10000) -> 3240
A9: 150 | B9: 无视法师抗性 | C9: 1213 | D9: =秘宝养成!H106 -> 0.05787037 | E9: =秘宝养成!I106 -> 0.08 | F9: =秘宝养成!J106 -> 0.083333333 | G9: =秘宝养成!K106 -> 0.1 | H9: =秘宝养成!L106 -> 0.12 | I9: =秘宝养成!M106 -> 0.144 | J9: =秘宝养成!N106 -> 0.18 | K9: =秘宝养成!O106 -> 0.225 | ... M9: =秘宝养成!Q106 -> 0.324 | N9: =M9*1.2 -> 0.3888 | O9: =N9*1.2 -> 0.46656 | Q9: 6 | R9: =INT(OFFSET($C$3,$Q9,_xlfn.XLOOKUP(R$3,秘宝养成!$D$20:$D$31,秘宝养成!$C$20:$C$31))*10000) -> 1000 | S9: =INT(OFFSET($C$3,$Q9,_xlfn.XLOOKUP(S$3,秘宝养成!$D$20:$D$31,秘宝养成!$C$20:$C$31))*10000) -> 1000 | T9: =INT(OFFSET($C$3,$Q9,_xlfn.XLOOKUP(T$3,秘宝养成!$D$20:$D$31,秘宝养成!$C$20:$C$31))*10000) -> 1200 | U9: =INT(OFFSET($C$3,$Q9,_xlfn.XLOOKUP(U$3,秘宝养成!$D$20:$D$31,秘宝养成!$C$20:$C$31))*10000) -> 1440 | V9: =INT(OFFSET($C$3,$Q9,_xlfn.XLOOKUP(V$3,秘宝养成!$D$20:$D$31,秘宝养成!$C$20:$C$31))*10000) -> 1800 | W9: =INT(OFFSET($C$3,$Q9,_xlfn.XLOOKUP(W$3,秘宝养成!$D$20:$D$31,秘宝养成!$C$20:$C$31))*10000) -> 1800 | X9: =INT(OFFSET($C$3,$Q9,_xlfn.XLOOKUP(X$3,秘宝养成!$D$20:$D$31,秘宝养成!$C$20:$C$31))*10000) -> 2250 | Y9: =INT(OFFSET($C$3,$Q9,_xlfn.XLOOKUP(Y$3,秘宝养成!$D$20:$D$31,秘宝养成!$C$20:$C$31))*10000) -> 2250 | ... AC9: =INT(OFFSET($C$3,$Q9,_xlfn.XLOOKUP(AC$3,秘宝养成!$D$20:$D$31,秘宝养成!$C$20:$C$31))*10000) -> 3240
A10: 150 | B10: 无视射手抗性 | C10: 1413 | D10: =秘宝养成!H107 -> 0.05787037 | E10: =秘宝养成!I107 -> 0.08 | F10: =秘宝养成!J107 -> 0.083333333 | G10: =秘宝养成!K107 -> 0.1 | H10: =秘宝养成!L107 -> 0.12 | I10: =秘宝养成!M107 -> 0.144 | J10: =秘宝养成!N107 -> 0.18 | K10: =秘宝养成!O107 -> 0.225 | ... M10: =秘宝养成!Q107 -> 0.324 | N10: =M10*1.2 -> 0.3888 | O10: =N10*1.2 -> 0.46656 | Q10: 7 | R10: =INT(OFFSET($C$3,$Q10,_xlfn.XLOOKUP(R$3,秘宝养成!$D$20:$D$31,秘宝养成!$C$20:$C$31))*10000) -> 1000 | S10: =INT(OFFSET($C$3,$Q10,_xlfn.XLOOKUP(S$3,秘宝养成!$D$20:$D$31,秘宝养成!$C$20:$C$31))*10000) -> 1000 | T10: =INT(OFFSET($C$3,$Q10,_xlfn.XLOOKUP(T$3,秘宝养成!$D$20:$D$31,秘宝养成!$C$20:$C$31))*10000) -> 1200 | U10: =INT(OFFSET($C$3,$Q10,_xlfn.XLOOKUP(U$3,秘宝养成!$D$20:$D$31,秘宝养成!$C$20:$C$31))*10000) -> 1440 | V10: =INT(OFFSET($C$3,$Q10,_xlfn.XLOOKUP(V$3,秘宝养成!$D$20:$D$31,秘宝养成!$C$20:$C$31))*10000) -> 1800 | W10: =INT(OFFSET($C$3,$Q10,_xlfn.XLOOKUP(W$3,秘宝养成!$D$20:$D$31,秘宝养成!$C$20:$C$31))*10000) -> 1800 | X10: =INT(OFFSET($C$3,$Q10,_xlfn.XLOOKUP(X$3,秘宝养成!$D$20:$D$31,秘宝养成!$C$20:$C$31))*10000) -> 2250 | Y10: =INT(OFFSET($C$3,$Q10,_xlfn.XLOOKUP(Y$3,秘宝养成!$D$20:$D$31,秘宝养成!$C$20:$C$31))*10000) -> 2250 | ... AC10: =INT(OFFSET($C$3,$Q10,_xlfn.XLOOKUP(AC$3,秘宝养成!$D$20:$D$31,秘宝养成!$C$20:$C$31))*10000) -> 3240
A11: 150 | B11: 无视毒系抗性 | C11: 1513 | D11: =秘宝养成!H108 -> 0.05787037 | E11: =秘宝养成!I108 -> 0.08 | F11: =秘宝养成!J108 -> 0.083333333 | G11: =秘宝养成!K108 -> 0.1 | H11: =秘宝养成!L108 -> 0.12 | I11: =秘宝养成!M108 -> 0.144 | J11: =秘宝养成!N108 -> 0.18 | K11: =秘宝养成!O108 -> 0.225 | ... M11: =秘宝养成!Q108 -> 0.324 | N11: =M11*1.2 -> 0.3888 | O11: =N11*1.2 -> 0.46656 | Q11: 8 | R11: =INT(OFFSET($C$3,$Q11,_xlfn.XLOOKUP(R$3,秘宝养成!$D$20:$D$31,秘宝养成!$C$20:$C$31))*10000) -> 1000 | S11: =INT(OFFSET($C$3,$Q11,_xlfn.XLOOKUP(S$3,秘宝养成!$D$20:$D$31,秘宝养成!$C$20:$C$31))*10000) -> 1000 | T11: =INT(OFFSET($C$3,$Q11,_xlfn.XLOOKUP(T$3,秘宝养成!$D$20:$D$31,秘宝养成!$C$20:$C$31))*10000) -> 1200 | U11: =INT(OFFSET($C$3,$Q11,_xlfn.XLOOKUP(U$3,秘宝养成!$D$20:$D$31,秘宝养成!$C$20:$C$31))*10000) -> 1440 | V11: =INT(OFFSET($C$3,$Q11,_xlfn.XLOOKUP(V$3,秘宝养成!$D$20:$D$31,秘宝养成!$C$20:$C$31))*10000) -> 1800 | W11: =INT(OFFSET($C$3,$Q11,_xlfn.XLOOKUP(W$3,秘宝养成!$D$20:$D$31,秘宝养成!$C$20:$C$31))*10000) -> 1800 | X11: =INT(OFFSET($C$3,$Q11,_xlfn.XLOOKUP(X$3,秘宝养成!$D$20:$D$31,秘宝养成!$C$20:$C$31))*10000) -> 2250 | Y11: =INT(OFFSET($C$3,$Q11,_xlfn.XLOOKUP(Y$3,秘宝养成!$D$20:$D$31,秘宝养成!$C$20:$C$31))*10000) -> 2250 | ... AC11: =INT(OFFSET($C$3,$Q11,_xlfn.XLOOKUP(AC$3,秘宝养成!$D$20:$D$31,秘宝养成!$C$20:$C$31))*10000) -> 3240
A12: 150 | B12: 无视召唤抗性 | C12: 1713 | D12: =秘宝养成!H109 -> 0.05787037 | E12: =秘宝养成!I109 -> 0.08 | F12: =秘宝养成!J109 -> 0.083333333 | G12: =秘宝养成!K109 -> 0.1 | H12: =秘宝养成!L109 -> 0.12 | I12: =秘宝养成!M109 -> 0.144 | J12: =秘宝养成!N109 -> 0.18 | K12: =秘宝养成!O109 -> 0.225 | ... M12: =秘宝养成!Q109 -> 0.324 | N12: =M12*1.2 -> 0.3888 | O12: =N12*1.2 -> 0.46656 | Q12: 9 | R12: =INT(OFFSET($C$3,$Q12,_xlfn.XLOOKUP(R$3,秘宝养成!$D$20:$D$31,秘宝养成!$C$20:$C$31))*10000) -> 1000 | S12: =INT(OFFSET($C$3,$Q12,_xlfn.XLOOKUP(S$3,秘宝养成!$D$20:$D$31,秘宝养成!$C$20:$C$31))*10000) -> 1000 | T12: =INT(OFFSET($C$3,$Q12,_xlfn.XLOOKUP(T$3,秘宝养成!$D$20:$D$31,秘宝养成!$C$20:$C$31))*10000) -> 1200 | U12: =INT(OFFSET($C$3,$Q12,_xlfn.XLOOKUP(U$3,秘宝养成!$D$20:$D$31,秘宝养成!$C$20:$C$31))*10000) -> 1440 | V12: =INT(OFFSET($C$3,$Q12,_xlfn.XLOOKUP(V$3,秘宝养成!$D$20:$D$31,秘宝养成!$C$20:$C$31))*10000) -> 1800 | W12: =INT(OFFSET($C$3,$Q12,_xlfn.XLOOKUP(W$3,秘宝养成!$D$20:$D$31,秘宝养成!$C$20:$C$31))*10000) -> 1800 | X12: =INT(OFFSET($C$3,$Q12,_xlfn.XLOOKUP(X$3,秘宝养成!$D$20:$D$31,秘宝养成!$C$20:$C$31))*10000) -> 2250 | Y12: =INT(OFFSET($C$3,$Q12,_xlfn.XLOOKUP(Y$3,秘宝养成!$D$20:$D$31,秘宝养成!$C$20:$C$31))*10000) -> 2250 | ... AC12: =INT(OFFSET($C$3,$Q12,_xlfn.XLOOKUP(AC$3,秘宝养成!$D$20:$D$31,秘宝养成!$C$20:$C$31))*10000) -> 3240
A13: 525 | B13: 国王伤害 | C13: 806 | D13: =秘宝养成!H110 -> 0.083333333 | E13: =秘宝养成!I110 -> 0.12 | F13: =秘宝养成!J110 -> 0.125 | G13: =秘宝养成!K110 -> 0.15 | H13: =秘宝养成!L110 -> 0.18 | I13: =秘宝养成!M110 -> 0.216 | J13: =秘宝养成!N110 -> 0.27 | K13: =秘宝养成!O110 -> 0.3375 | ... M13: =秘宝养成!Q110 -> 0.486 | N13: =M13*1.2 -> 0.5832 | O13: =N13*1.2 -> 0.69984 | Q13: 10 | R13: =INT(OFFSET($C$3,$Q13,_xlfn.XLOOKUP(R$3,秘宝养成!$D$20:$D$31,秘宝养成!$C$20:$C$31))*10000) -> 1500 | S13: =INT(OFFSET($C$3,$Q13,_xlfn.XLOOKUP(S$3,秘宝养成!$D$20:$D$31,秘宝养成!$C$20:$C$31))*10000) -> 1500 | T13: =INT(OFFSET($C$3,$Q13,_xlfn.XLOOKUP(T$3,秘宝养成!$D$20:$D$31,秘宝养成!$C$20:$C$31))*10000) -> 1800 | U13: =INT(OFFSET($C$3,$Q13,_xlfn.XLOOKUP(U$3,秘宝养成!$D$20:$D$31,秘宝养成!$C$20:$C$31))*10000) -> 2160 | V13: =INT(OFFSET($C$3,$Q13,_xlfn.XLOOKUP(V$3,秘宝养成!$D$20:$D$31,秘宝养成!$C$20:$C$31))*10000) -> 2700 | W13: =INT(OFFSET($C$3,$Q13,_xlfn.XLOOKUP(W$3,秘宝养成!$D$20:$D$31,秘宝养成!$C$20:$C$31))*10000) -> 2700 | X13: =INT(OFFSET($C$3,$Q13,_xlfn.XLOOKUP(X$3,秘宝养成!$D$20:$D$31,秘宝养成!$C$20:$C$31))*10000) -> 3375 | Y13: =INT(OFFSET($C$3,$Q13,_xlfn.XLOOKUP(Y$3,秘宝养成!$D$20:$D$31,秘宝养成!$C$20:$C$31))*10000) -> 3375 | ... AC13: =INT(OFFSET($C$3,$Q13,_xlfn.XLOOKUP(AC$3,秘宝养成!$D$20:$D$31,秘宝养成!$C$20:$C$31))*10000) -> 4860
A14: 525 | B14: 全体英雄增伤 | C14: 908 | D14: =秘宝养成!H111 -> 0.05787037 | E14: =秘宝养成!I111 -> 0.08 | F14: =秘宝养成!J111 -> 0.083333333 | G14: =秘宝养成!K111 -> 0.1 | H14: =秘宝养成!L111 -> 0.12 | I14: =秘宝养成!M111 -> 0.144 | J14: =秘宝养成!N111 -> 0.18 | K14: =秘宝养成!O111 -> 0.225 | ... M14: =秘宝养成!Q111 -> 0.324 | N14: =M14*1.2 -> 0.3888 | O14: =N14*1.2 -> 0.46656 | Q14: 11 | R14: =INT(OFFSET($C$3,$Q14,_xlfn.XLOOKUP(R$3,秘宝养成!$D$20:$D$31,秘宝养成!$C$20:$C$31))*10000) -> 1000 | S14: =INT(OFFSET($C$3,$Q14,_xlfn.XLOOKUP(S$3,秘宝养成!$D$20:$D$31,秘宝养成!$C$20:$C$31))*10000) -> 1000 | T14: =INT(OFFSET($C$3,$Q14,_xlfn.XLOOKUP(T$3,秘宝养成!$D$20:$D$31,秘宝养成!$C$20:$C$31))*10000) -> 1200 | U14: =INT(OFFSET($C$3,$Q14,_xlfn.XLOOKUP(U$3,秘宝养成!$D$20:$D$31,秘宝养成!$C$20:$C$31))*10000) -> 1440 | V14: =INT(OFFSET($C$3,$Q14,_xlfn.XLOOKUP(V$3,秘宝养成!$D$20:$D$31,秘宝养成!$C$20:$C$31))*10000) -> 1800 | W14: =INT(OFFSET($C$3,$Q14,_xlfn.XLOOKUP(W$3,秘宝养成!$D$20:$D$31,秘宝养成!$C$20:$C$31))*10000) -> 1800 | X14: =INT(OFFSET($C$3,$Q14,_xlfn.XLOOKUP(X$3,秘宝养成!$D$20:$D$31,秘宝养成!$C$20:$C$31))*10000) -> 2250 | Y14: =INT(OFFSET($C$3,$Q14,_xlfn.XLOOKUP(Y$3,秘宝养成!$D$20:$D$31,秘宝养成!$C$20:$C$31))*10000) -> 2250 | ... AC14: =INT(OFFSET($C$3,$Q14,_xlfn.XLOOKUP(AC$3,秘宝养成!$D$20:$D$31,秘宝养成!$C$20:$C$31))*10000) -> 3240
A15: 525 | B15: 战士英雄增伤 | C15: 1106 | D15: =秘宝养成!H112 -> 0.083333333 | E15: =秘宝养成!I112 -> 0.12 | F15: =秘宝养成!J112 -> 0.125 | G15: =秘宝养成!K112 -> 0.15 | H15: =秘宝养成!L112 -> 0.18 | I15: =秘宝养成!M112 -> 0.216 | J15: =秘宝养成!N112 -> 0.27 | K15: =秘宝养成!O112 -> 0.3375 | ... M15: =秘宝养成!Q112 -> 0.486 | N15: =M15*1.2 -> 0.5832 | O15: =N15*1.2 -> 0.69984 | Q15: 12 | R15: =INT(OFFSET($C$3,$Q15,_xlfn.XLOOKUP(R$3,秘宝养成!$D$20:$D$31,秘宝养成!$C$20:$C$31))*10000) -> 1500 | S15: =INT(OFFSET($C$3,$Q15,_xlfn.XLOOKUP(S$3,秘宝养成!$D$20:$D$31,秘宝养成!$C$20:$C$31))*10000) -> 1500 | T15: =INT(OFFSET($C$3,$Q15,_xlfn.XLOOKUP(T$3,秘宝养成!$D$20:$D$31,秘宝养成!$C$20:$C$31))*10000) -> 1800 | U15: =INT(OFFSET($C$3,$Q15,_xlfn.XLOOKUP(U$3,秘宝养成!$D$20:$D$31,秘宝养成!$C$20:$C$31))*10000) -> 2160 | V15: =INT(OFFSET($C$3,$Q15,_xlfn.XLOOKUP(V$3,秘宝养成!$D$20:$D$31,秘宝养成!$C$20:$C$31))*10000) -> 2700 | W15: =INT(OFFSET($C$3,$Q15,_xlfn.XLOOKUP(W$3,秘宝养成!$D$20:$D$31,秘宝养成!$C$20:$C$31))*10000) -> 2700 | X15: =INT(OFFSET($C$3,$Q15,_xlfn.XLOOKUP(X$3,秘宝养成!$D$20:$D$31,秘宝养成!$C$20:$C$31))*10000) -> 3375 | Y15: =INT(OFFSET($C$3,$Q15,_xlfn.XLOOKUP(Y$3,秘宝养成!$D$20:$D$31,秘宝养成!$C$20:$C$31))*10000) -> 3375 | ... AC15: =INT(OFFSET($C$3,$Q15,_xlfn.XLOOKUP(AC$3,秘宝养成!$D$20:$D$31,秘宝养成!$C$20:$C$31))*10000) -> 4860
A16: 525 | B16: 法师英雄增伤 | C16: 1206 | D16: =秘宝养成!H113 -> 0.083333333 | E16: =秘宝养成!I113 -> 0.12 | F16: =秘宝养成!J113 -> 0.125 | G16: =秘宝养成!K113 -> 0.15 | H16: =秘宝养成!L113 -> 0.18 | I16: =秘宝养成!M113 -> 0.216 | J16: =秘宝养成!N113 -> 0.27 | K16: =秘宝养成!O113 -> 0.3375 | ... M16: =秘宝养成!Q113 -> 0.486 | N16: =M16*1.2 -> 0.5832 | O16: =N16*1.2 -> 0.69984 | Q16: 13 | R16: =INT(OFFSET($C$3,$Q16,_xlfn.XLOOKUP(R$3,秘宝养成!$D$20:$D$31,秘宝养成!$C$20:$C$31))*10000) -> 1500 | S16: =INT(OFFSET($C$3,$Q16,_xlfn.XLOOKUP(S$3,秘宝养成!$D$20:$D$31,秘宝养成!$C$20:$C$31))*10000) -> 1500 | T16: =INT(OFFSET($C$3,$Q16,_xlfn.XLOOKUP(T$3,秘宝养成!$D$20:$D$31,秘宝养成!$C$20:$C$31))*10000) -> 1800 | U16: =INT(OFFSET($C$3,$Q16,_xlfn.XLOOKUP(U$3,秘宝养成!$D$20:$D$31,秘宝养成!$C$20:$C$31))*10000) -> 2160 | V16: =INT(OFFSET($C$3,$Q16,_xlfn.XLOOKUP(V$3,秘宝养成!$D$20:$D$31,秘宝养成!$C$20:$C$31))*10000) -> 2700 | W16: =INT(OFFSET($C$3,$Q16,_xlfn.XLOOKUP(W$3,秘宝养成!$D$20:$D$31,秘宝养成!$C$20:$C$31))*10000) -> 2700 | X16: =INT(OFFSET($C$3,$Q16,_xlfn.XLOOKUP(X$3,秘宝养成!$D$20:$D$31,秘宝养成!$C$20:$C$31))*10000) -> 3375 | Y16: =INT(OFFSET($C$3,$Q16,_xlfn.XLOOKUP(Y$3,秘宝养成!$D$20:$D$31,秘宝养成!$C$20:$C$31))*10000) -> 3375 | ... AC16: =INT(OFFSET($C$3,$Q16,_xlfn.XLOOKUP(AC$3,秘宝养成!$D$20:$D$31,秘宝养成!$C$20:$C$31))*10000) -> 4860
A17: 525 | B17: 射手英雄增伤 | C17: 1406 | D17: =秘宝养成!H114 -> 0.083333333 | E17: =秘宝养成!I114 -> 0.12 | F17: =秘宝养成!J114 -> 0.125 | G17: =秘宝养成!K114 -> 0.15 | H17: =秘宝养成!L114 -> 0.18 | I17: =秘宝养成!M114 -> 0.216 | J17: =秘宝养成!N114 -> 0.27 | K17: =秘宝养成!O114 -> 0.3375 | ... M17: =秘宝养成!Q114 -> 0.486 | N17: =M17*1.2 -> 0.5832 | O17: =N17*1.2 -> 0.69984 | Q17: 14 | R17: =INT(OFFSET($C$3,$Q17,_xlfn.XLOOKUP(R$3,秘宝养成!$D$20:$D$31,秘宝养成!$C$20:$C$31))*10000) -> 1500 | S17: =INT(OFFSET($C$3,$Q17,_xlfn.XLOOKUP(S$3,秘宝养成!$D$20:$D$31,秘宝养成!$C$20:$C$31))*10000) -> 1500 | T17: =INT(OFFSET($C$3,$Q17,_xlfn.XLOOKUP(T$3,秘宝养成!$D$20:$D$31,秘宝养成!$C$20:$C$31))*10000) -> 1800 | U17: =INT(OFFSET($C$3,$Q17,_xlfn.XLOOKUP(U$3,秘宝养成!$D$20:$D$31,秘宝养成!$C$20:$C$31))*10000) -> 2160 | V17: =INT(OFFSET($C$3,$Q17,_xlfn.XLOOKUP(V$3,秘宝养成!$D$20:$D$31,秘宝养成!$C$20:$C$31))*10000) -> 2700 | W17: =INT(OFFSET($C$3,$Q17,_xlfn.XLOOKUP(W$3,秘宝养成!$D$20:$D$31,秘宝养成!$C$20:$C$31))*10000) -> 2700 | X17: =INT(OFFSET($C$3,$Q17,_xlfn.XLOOKUP(X$3,秘宝养成!$D$20:$D$31,秘宝养成!$C$20:$C$31))*10000) -> 3375 | Y17: =INT(OFFSET($C$3,$Q17,_xlfn.XLOOKUP(Y$3,秘宝养成!$D$20:$D$31,秘宝养成!$C$20:$C$31))*10000) -> 3375 | ... AC17: =INT(OFFSET($C$3,$Q17,_xlfn.XLOOKUP(AC$3,秘宝养成!$D$20:$D$31,秘宝养成!$C$20:$C$31))*10000) -> 4860
A18: 525 | B18: 毒系英雄增伤 | C18: 1506 | D18: =秘宝养成!H115 -> 0.083333333 | E18: =秘宝养成!I115 -> 0.12 | F18: =秘宝养成!J115 -> 0.125 | G18: =秘宝养成!K115 -> 0.15 | H18: =秘宝养成!L115 -> 0.18 | I18: =秘宝养成!M115 -> 0.216 | J18: =秘宝养成!N115 -> 0.27 | K18: =秘宝养成!O115 -> 0.3375 | ... M18: =秘宝养成!Q115 -> 0.486 | N18: =M18*1.2 -> 0.5832 | O18: =N18*1.2 -> 0.69984 | Q18: 15 | R18: =INT(OFFSET($C$3,$Q18,_xlfn.XLOOKUP(R$3,秘宝养成!$D$20:$D$31,秘宝养成!$C$20:$C$31))*10000) -> 1500 | S18: =INT(OFFSET($C$3,$Q18,_xlfn.XLOOKUP(S$3,秘宝养成!$D$20:$D$31,秘宝养成!$C$20:$C$31))*10000) -> 1500 | T18: =INT(OFFSET($C$3,$Q18,_xlfn.XLOOKUP(T$3,秘宝养成!$D$20:$D$31,秘宝养成!$C$20:$C$31))*10000) -> 1800 | U18: =INT(OFFSET($C$3,$Q18,_xlfn.XLOOKUP(U$3,秘宝养成!$D$20:$D$31,秘宝养成!$C$20:$C$31))*10000) -> 2160 | V18: =INT(OFFSET($C$3,$Q18,_xlfn.XLOOKUP(V$3,秘宝养成!$D$20:$D$31,秘宝养成!$C$20:$C$31))*10000) -> 2700 | W18: =INT(OFFSET($C$3,$Q18,_xlfn.XLOOKUP(W$3,秘宝养成!$D$20:$D$31,秘宝养成!$C$20:$C$31))*10000) -> 2700 | X18: =INT(OFFSET($C$3,$Q18,_xlfn.XLOOKUP(X$3,秘宝养成!$D$20:$D$31,秘宝养成!$C$20:$C$31))*10000) -> 3375 | Y18: =INT(OFFSET($C$3,$Q18,_xlfn.XLOOKUP(Y$3,秘宝养成!$D$20:$D$31,秘宝养成!$C$20:$C$31))*10000) -> 3375 | ... AC18: =INT(OFFSET($C$3,$Q18,_xlfn.XLOOKUP(AC$3,秘宝养成!$D$20:$D$31,秘宝养成!$C$20:$C$31))*10000) -> 4860
A19: 525 | B19: 召唤英雄增伤 | C19: 1706 | D19: =秘宝养成!H116 -> 0.083333333 | E19: =秘宝养成!I116 -> 0.12 | F19: =秘宝养成!J116 -> 0.125 | G19: =秘宝养成!K116 -> 0.15 | H19: =秘宝养成!L116 -> 0.18 | I19: =秘宝养成!M116 -> 0.216 | J19: =秘宝养成!N116 -> 0.27 | K19: =秘宝养成!O116 -> 0.3375 | ... M19: =秘宝养成!Q116 -> 0.486 | N19: =M19*1.2 -> 0.5832 | O19: =N19*1.2 -> 0.69984 | Q19: 16 | R19: =INT(OFFSET($C$3,$Q19,_xlfn.XLOOKUP(R$3,秘宝养成!$D$20:$D$31,秘宝养成!$C$20:$C$31))*10000) -> 1500 | S19: =INT(OFFSET($C$3,$Q19,_xlfn.XLOOKUP(S$3,秘宝养成!$D$20:$D$31,秘宝养成!$C$20:$C$31))*10000) -> 1500 | T19: =INT(OFFSET($C$3,$Q19,_xlfn.XLOOKUP(T$3,秘宝养成!$D$20:$D$31,秘宝养成!$C$20:$C$31))*10000) -> 1800 | U19: =INT(OFFSET($C$3,$Q19,_xlfn.XLOOKUP(U$3,秘宝养成!$D$20:$D$31,秘宝养成!$C$20:$C$31))*10000) -> 2160 | V19: =INT(OFFSET($C$3,$Q19,_xlfn.XLOOKUP(V$3,秘宝养成!$D$20:$D$31,秘宝养成!$C$20:$C$31))*10000) -> 2700 | W19: =INT(OFFSET($C$3,$Q19,_xlfn.XLOOKUP(W$3,秘宝养成!$D$20:$D$31,秘宝养成!$C$20:$C$31))*10000) -> 2700 | X19: =INT(OFFSET($C$3,$Q19,_xlfn.XLOOKUP(X$3,秘宝养成!$D$20:$D$31,秘宝养成!$C$20:$C$31))*10000) -> 3375 | Y19: =INT(OFFSET($C$3,$Q19,_xlfn.XLOOKUP(Y$3,秘宝养成!$D$20:$D$31,秘宝养成!$C$20:$C$31))*10000) -> 3375 | ... AC19: =INT(OFFSET($C$3,$Q19,_xlfn.XLOOKUP(AC$3,秘宝养成!$D$20:$D$31,秘宝养成!$C$20:$C$31))*10000) -> 4860
... A28: 300 | B28: 主线增伤 | C28: 616 | D28: =秘宝养成!H125 -> 0.08 | E28: =秘宝养成!I125 -> 0.12 | F28: =秘宝养成!J125 -> 0.125 | G28: =秘宝养成!K125 -> 0.15 | H28: =秘宝养成!L125 -> 0.18 | I28: =秘宝养成!M125 -> 0.216 | J28: =秘宝养成!N125 -> 0.27 | K28: =秘宝养成!O125 -> 0.3375 | ... M28: =秘宝养成!Q125 -> 0.486 | N28: =M28*1.2 -> 0.5832 | O28: =N28*1.2 -> 0.69984 | Q28: 25 | R28: =INT(OFFSET($C$3,$Q28,_xlfn.XLOOKUP(R$3,秘宝养成!$D$20:$D$31,秘宝养成!$C$20:$C$31))*10000) -> 1500 | S28: =INT(OFFSET($C$3,$Q28,_xlfn.XLOOKUP(S$3,秘宝养成!$D$20:$D$31,秘宝养成!$C$20:$C$31))*10000) -> 1500 | T28: =INT(OFFSET($C$3,$Q28,_xlfn.XLOOKUP(T$3,秘宝养成!$D$20:$D$31,秘宝养成!$C$20:$C$31))*10000) -> 1800 | U28: =INT(OFFSET($C$3,$Q28,_xlfn.XLOOKUP(U$3,秘宝养成!$D$20:$D$31,秘宝养成!$C$20:$C$31))*10000) -> 2160 | V28: =INT(OFFSET($C$3,$Q28,_xlfn.XLOOKUP(V$3,秘宝养成!$D$20:$D$31,秘宝养成!$C$20:$C$31))*10000) -> 2700 | W28: =INT(OFFSET($C$3,$Q28,_xlfn.XLOOKUP(W$3,秘宝养成!$D$20:$D$31,秘宝养成!$C$20:$C$31))*10000) -> 2700 | X28: =INT(OFFSET($C$3,$Q28,_xlfn.XLOOKUP(X$3,秘宝养成!$D$20:$D$31,秘宝养成!$C$20:$C$31))*10000) -> 3375 | Y28: =INT(OFFSET($C$3,$Q28,_xlfn.XLOOKUP(Y$3,秘宝养成!$D$20:$D$31,秘宝养成!$C$20:$C$31))*10000) -> 3375 | ... AC28: =INT(OFFSET($C$3,$Q28,_xlfn.XLOOKUP(AC$3,秘宝养成!$D$20:$D$31,秘宝养成!$C$20:$C$31))*10000) -> 4860
A29: =300 -> 300 | B29: 梦域巡航增伤 | C29: 617 | D29: =秘宝养成!H126 -> 0.08 | E29: =秘宝养成!I126 -> 0.12 | F29: =秘宝养成!J126 -> 0.125 | G29: =秘宝养成!K126 -> 0.15 | H29: =秘宝养成!L126 -> 0.18 | I29: =秘宝养成!M126 -> 0.216 | J29: =秘宝养成!N126 -> 0.27 | K29: =秘宝养成!O126 -> 0.3375 | ... M29: =秘宝养成!Q126 -> 0.486 | N29: =M29*1.2 -> 0.5832 | O29: =N29*1.2 -> 0.69984 | Q29: 26 | R29: =INT(OFFSET($C$3,$Q29,_xlfn.XLOOKUP(R$3,秘宝养成!$D$20:$D$31,秘宝养成!$C$20:$C$31))*10000) -> 1500 | S29: =INT(OFFSET($C$3,$Q29,_xlfn.XLOOKUP(S$3,秘宝养成!$D$20:$D$31,秘宝养成!$C$20:$C$31))*10000) -> 1500 | T29: =INT(OFFSET($C$3,$Q29,_xlfn.XLOOKUP(T$3,秘宝养成!$D$20:$D$31,秘宝养成!$C$20:$C$31))*10000) -> 1800 | U29: =INT(OFFSET($C$3,$Q29,_xlfn.XLOOKUP(U$3,秘宝养成!$D$20:$D$31,秘宝养成!$C$20:$C$31))*10000) -> 2160 | V29: =INT(OFFSET($C$3,$Q29,_xlfn.XLOOKUP(V$3,秘宝养成!$D$20:$D$31,秘宝养成!$C$20:$C$31))*10000) -> 2700 | W29: =INT(OFFSET($C$3,$Q29,_xlfn.XLOOKUP(W$3,秘宝养成!$D$20:$D$31,秘宝养成!$C$20:$C$31))*10000) -> 2700 | X29: =INT(OFFSET($C$3,$Q29,_xlfn.XLOOKUP(X$3,秘宝养成!$D$20:$D$31,秘宝养成!$C$20:$C$31))*10000) -> 3375 | Y29: =INT(OFFSET($C$3,$Q29,_xlfn.XLOOKUP(Y$3,秘宝养成!$D$20:$D$31,秘宝养成!$C$20:$C$31))*10000) -> 3375 | ... AC29: =INT(OFFSET($C$3,$Q29,_xlfn.XLOOKUP(AC$3,秘宝养成!$D$20:$D$31,秘宝养成!$C$20:$C$31))*10000) -> 4860
B36: 对高速怪物增伤 | C36: 613 | D36: ="{"&INT(D4*0.5*10000)&","&INT((D4)*10000)&"}" -> {416,833} | E36: ="{"&INT((D4)*10000)+1&","&INT((E4)*10000)&"}" -> {834,1200} | F36: ="{"&INT((E4)*10000)+1&","&INT((F4)*10000)&"}" -> {1201,1250} | G36: ="{"&INT((F4)*10000)+1&","&INT((G4)*10000)&"}" -> {1251,1500} | H36: ="{"&INT((G4)*10000)+1&","&INT((H4)*10000)&"}" -> {1501,1800} | I36: ="{"&INT((H4)*10000)+1&","&INT((I4)*10000)&"}" -> {1801,2160} | J36: ="{"&INT((I4)*10000)+1&","&INT((J4)*10000)&"}" -> {2161,2700} | K36: ="{"&INT((J4)*10000)+1&","&INT((K4)*10000)&"}" -> {2701,3375} | L36: ="{"&INT((K4)*10000)+1&","&INT((L4)*10000)&"}" -> {3376,4050} | M36: ="{"&INT((L4)*10000)+1&","&INT((M4)*10000)&"}" -> {4051,4860}
B37: 对飞行怪物增伤 | C37: 614 | D37: ="{"&INT(D5*0.5*10000)&","&INT((D5)*10000)&"}" -> {416,833} | E37: ="{"&INT((D5)*10000)+1&","&INT((E5)*10000)&"}" -> {834,1200} | F37: ="{"&INT((E5)*10000)+1&","&INT((F5)*10000)&"}" -> {1201,1250} | G37: ="{"&INT((F5)*10000)+1&","&INT((G5)*10000)&"}" -> {1251,1500} | H37: ="{"&INT((G5)*10000)+1&","&INT((H5)*10000)&"}" -> {1501,1800} | I37: ="{"&INT((H5)*10000)+1&","&INT((I5)*10000)&"}" -> {1801,2160} | J37: ="{"&INT((I5)*10000)+1&","&INT((J5)*10000)&"}" -> {2161,2700} | K37: ="{"&INT((J5)*10000)+1&","&INT((K5)*10000)&"}" -> {2701,3375} | L37: ="{"&INT((K5)*10000)+1&","&INT((L5)*10000)&"}" -> {3376,4050} | M37: ="{"&INT((L5)*10000)+1&","&INT((M5)*10000)&"}" -> {4051,4860} | Q37: 1 | R37: ="{"&R$3&","&R4&"}" -> {1,1500} | S37: ="{"&S$3&","&S4&"}" -> {2,1500} | T37: ="{"&T$3&","&T4&"}" -> {3,1800} | U37: ="{"&U$3&","&U4&"}" -> {4,2160} | V37: ="{"&V$3&","&V4&"}" -> {5,2700} | W37: ="{"&W$3&","&W4&"}" -> {6,2700} | X37: ="{"&X$3&","&X4&"}" -> {7,3375} | Y37: ="{"&Y$3&","&Y4&"}" -> {8,3375} | ... AC37: ="{"&AC$3&","&AC4&"}" -> {12,4860} | AD37: ="["&_xlfn.TEXTJOIN(",",1,$R37:$AC37)&"]" -> [{1,1500},{2,1500},{3,1800},{4,2160},{5,2700},{6,2700},{7,3375},{8,3375},{9,4050},{10,4050},{11,4860},{12,4860}]
B38: 对肉盾怪物增伤 | C38: 615 | D38: ="{"&INT(D6*0.5*10000)&","&INT((D6)*10000)&"}" -> {416,833} | E38: ="{"&INT((D6)*10000)+1&","&INT((E6)*10000)&"}" -> {834,1200} | F38: ="{"&INT((E6)*10000)+1&","&INT((F6)*10000)&"}" -> {1201,1250} | G38: ="{"&INT((F6)*10000)+1&","&INT((G6)*10000)&"}" -> {1251,1500} | H38: ="{"&INT((G6)*10000)+1&","&INT((H6)*10000)&"}" -> {1501,1800} | I38: ="{"&INT((H6)*10000)+1&","&INT((I6)*10000)&"}" -> {1801,2160} | J38: ="{"&INT((I6)*10000)+1&","&INT((J6)*10000)&"}" -> {2161,2700} | K38: ="{"&INT((J6)*10000)+1&","&INT((K6)*10000)&"}" -> {2701,3375} | L38: ="{"&INT((K6)*10000)+1&","&INT((L6)*10000)&"}" -> {3376,4050} | M38: ="{"&INT((L6)*10000)+1&","&INT((M6)*10000)&"}" -> {4051,4860} | Q38: 2 | R38: ="{"&R$3&","&R5&"}" -> {1,1500} | S38: ="{"&S$3&","&S5&"}" -> {2,1500} | T38: ="{"&T$3&","&T5&"}" -> {3,1800} | U38: ="{"&U$3&","&U5&"}" -> {4,2160} | V38: ="{"&V$3&","&V5&"}" -> {5,2700} | W38: ="{"&W$3&","&W5&"}" -> {6,2700} | X38: ="{"&X$3&","&X5&"}" -> {7,3375} | Y38: ="{"&Y$3&","&Y5&"}" -> {8,3375} | ... AC38: ="{"&AC$3&","&AC5&"}" -> {12,4860} | AD38: ="["&_xlfn.TEXTJOIN(",",1,$R38:$AC38)&"]" -> [{1,1500},{2,1500},{3,1800},{4,2160},{5,2700},{6,2700},{7,3375},{8,3375},{9,4050},{10,4050},{11,4860},{12,4860}]
B39: 对首领增伤 | C39: 610 | D39: ="{"&INT(D7*0.5*10000)&","&INT((D7)*10000)&"}" -> {833,1666} | E39: ="{"&INT((D7)*10000)+1&","&INT((E7)*10000)&"}" -> {1667,2400} | F39: ="{"&INT((E7)*10000)+1&","&INT((F7)*10000)&"}" -> {2401,2500} | G39: ="{"&INT((F7)*10000)+1&","&INT((G7)*10000)&"}" -> {2501,3000} | H39: ="{"&INT((G7)*10000)+1&","&INT((H7)*10000)&"}" -> {3001,3600} | I39: ="{"&INT((H7)*10000)+1&","&INT((I7)*10000)&"}" -> {3601,4320} | J39: ="{"&INT((I7)*10000)+1&","&INT((J7)*10000)&"}" -> {4321,5400} | K39: ="{"&INT((J7)*10000)+1&","&INT((K7)*10000)&"}" -> {5401,6750} | L39: ="{"&INT((K7)*10000)+1&","&INT((L7)*10000)&"}" -> {6751,8100} | M39: ="{"&INT((L7)*10000)+1&","&INT((M7)*10000)&"}" -> {8101,9720} | Q39: 3 | R39: ="{"&R$3&","&R6&"}" -> {1,1500} | S39: ="{"&S$3&","&S6&"}" -> {2,1500} | T39: ="{"&T$3&","&T6&"}" -> {3,1800} | U39: ="{"&U$3&","&U6&"}" -> {4,2160} | V39: ="{"&V$3&","&V6&"}" -> {5,2700} | W39: ="{"&W$3&","&W6&"}" -> {6,2700} | X39: ="{"&X$3&","&X6&"}" -> {7,3375} | Y39: ="{"&Y$3&","&Y6&"}" -> {8,3375} | ... AC39: ="{"&AC$3&","&AC6&"}" -> {12,4860} | AD39: ="["&_xlfn.TEXTJOIN(",",1,$R39:$AC39)&"]" -> [{1,1500},{2,1500},{3,1800},{4,2160},{5,2700},{6,2700},{7,3375},{8,3375},{9,4050},{10,4050},{11,4860},{12,4860}]
B40: 无视战士抗性 | C40: 1113 | D40: ="{"&INT(D8*0.5*10000)&","&INT((D8)*10000)&"}" -> {289,578} | E40: ="{"&INT((D8)*10000)+1&","&INT((E8)*10000)&"}" -> {579,800} | F40: ="{"&INT((E8)*10000)+1&","&INT((F8)*10000)&"}" -> {801,833} | G40: ="{"&INT((F8)*10000)+1&","&INT((G8)*10000)&"}" -> {834,1000} | H40: ="{"&INT((G8)*10000)+1&","&INT((H8)*10000)&"}" -> {1001,1200} | I40: ="{"&INT((H8)*10000)+1&","&INT((I8)*10000)&"}" -> {1201,1440} | J40: ="{"&INT((I8)*10000)+1&","&INT((J8)*10000)&"}" -> {1441,1800} | K40: ="{"&INT((J8)*10000)+1&","&INT((K8)*10000)&"}" -> {1801,2250} | L40: ="{"&INT((K8)*10000)+1&","&INT((L8)*10000)&"}" -> {2251,2700} | M40: ="{"&INT((L8)*10000)+1&","&INT((M8)*10000)&"}" -> {2701,3240} | Q40: 4 | R40: ="{"&R$3&","&R7&"}" -> {1,3000} | S40: ="{"&S$3&","&S7&"}" -> {2,3000} | T40: ="{"&T$3&","&T7&"}" -> {3,3600} | U40: ="{"&U$3&","&U7&"}" -> {4,4320} | V40: ="{"&V$3&","&V7&"}" -> {5,5400} | W40: ="{"&W$3&","&W7&"}" -> {6,5400} | X40: ="{"&X$3&","&X7&"}" -> {7,6750} | Y40: ="{"&Y$3&","&Y7&"}" -> {8,6750} | ... AC40: ="{"&AC$3&","&AC7&"}" -> {12,9720} | AD40: ="["&_xlfn.TEXTJOIN(",",1,$R40:$AC40)&"]" -> [{1,3000},{2,3000},{3,3600},{4,4320},{5,5400},{6,5400},{7,6750},{8,6750},{9,8100},{10,8100},{11,9720},{12,9720}]
B41: 无视法师抗性 | C41: 1213 | D41: ="{"&INT(D9*0.5*10000)&","&INT((D9)*10000)&"}" -> {289,578} | E41: ="{"&INT((D9)*10000)+1&","&INT((E9)*10000)&"}" -> {579,800} | F41: ="{"&INT((E9)*10000)+1&","&INT((F9)*10000)&"}" -> {801,833} | G41: ="{"&INT((F9)*10000)+1&","&INT((G9)*10000)&"}" -> {834,1000} | H41: ="{"&INT((G9)*10000)+1&","&INT((H9)*10000)&"}" -> {1001,1200} | I41: ="{"&INT((H9)*10000)+1&","&INT((I9)*10000)&"}" -> {1201,1440} | J41: ="{"&INT((I9)*10000)+1&","&INT((J9)*10000)&"}" -> {1441,1800} | K41: ="{"&INT((J9)*10000)+1&","&INT((K9)*10000)&"}" -> {1801,2250} | L41: ="{"&INT((K9)*10000)+1&","&INT((L9)*10000)&"}" -> {2251,2700} | M41: ="{"&INT((L9)*10000)+1&","&INT((M9)*10000)&"}" -> {2701,3240} | Q41: 5 | R41: ="{"&R$3&","&R8&"}" -> {1,1000} | S41: ="{"&S$3&","&S8&"}" -> {2,1000} | T41: ="{"&T$3&","&T8&"}" -> {3,1200} | U41: ="{"&U$3&","&U8&"}" -> {4,1440} | V41: ="{"&V$3&","&V8&"}" -> {5,1800} | W41: ="{"&W$3&","&W8&"}" -> {6,1800} | X41: ="{"&X$3&","&X8&"}" -> {7,2250} | Y41: ="{"&Y$3&","&Y8&"}" -> {8,2250} | ... AC41: ="{"&AC$3&","&AC8&"}" -> {12,3240} | AD41: ="["&_xlfn.TEXTJOIN(",",1,$R41:$AC41)&"]" -> [{1,1000},{2,1000},{3,1200},{4,1440},{5,1800},{6,1800},{7,2250},{8,2250},{9,2700},{10,2700},{11,3240},{12,3240}]
B42: 无视射手抗性 | C42: 1413 | D42: ="{"&INT(D10*0.5*10000)&","&INT((D10)*10000)&"}" -> {289,578} | E42: ="{"&INT((D10)*10000)+1&","&INT((E10)*10000)&"}" -> {579,800} | F42: ="{"&INT((E10)*10000)+1&","&INT((F10)*10000)&"}" -> {801,833} | G42: ="{"&INT((F10)*10000)+1&","&INT((G10)*10000)&"}" -> {834,1000} | H42: ="{"&INT((G10)*10000)+1&","&INT((H10)*10000)&"}" -> {1001,1200} | I42: ="{"&INT((H10)*10000)+1&","&INT((I10)*10000)&"}" -> {1201,1440} | J42: ="{"&INT((I10)*10000)+1&","&INT((J10)*10000)&"}" -> {1441,1800} | K42: ="{"&INT((J10)*10000)+1&","&INT((K10)*10000)&"}" -> {1801,2250} | L42: ="{"&INT((K10)*10000)+1&","&INT((L10)*10000)&"}" -> {2251,2700} | M42: ="{"&INT((L10)*10000)+1&","&INT((M10)*10000)&"}" -> {2701,3240} | Q42: 6 | R42: ="{"&R$3&","&R9&"}" -> {1,1000} | S42: ="{"&S$3&","&S9&"}" -> {2,1000} | T42: ="{"&T$3&","&T9&"}" -> {3,1200} | U42: ="{"&U$3&","&U9&"}" -> {4,1440} | V42: ="{"&V$3&","&V9&"}" -> {5,1800} | W42: ="{"&W$3&","&W9&"}" -> {6,1800} | X42: ="{"&X$3&","&X9&"}" -> {7,2250} | Y42: ="{"&Y$3&","&Y9&"}" -> {8,2250} | ... AC42: ="{"&AC$3&","&AC9&"}" -> {12,3240} | AD42: ="["&_xlfn.TEXTJOIN(",",1,$R42:$AC42)&"]" -> [{1,1000},{2,1000},{3,1200},{4,1440},{5,1800},{6,1800},{7,2250},{8,2250},{9,2700},{10,2700},{11,3240},{12,3240}]
B43: 无视毒系抗性 | C43: 1513 | D43: ="{"&INT(D11*0.5*10000)&","&INT((D11)*10000)&"}" -> {289,578} | E43: ="{"&INT((D11)*10000)+1&","&INT((E11)*10000)&"}" -> {579,800} | F43: ="{"&INT((E11)*10000)+1&","&INT((F11)*10000)&"}" -> {801,833} | G43: ="{"&INT((F11)*10000)+1&","&INT((G11)*10000)&"}" -> {834,1000} | H43: ="{"&INT((G11)*10000)+1&","&INT((H11)*10000)&"}" -> {1001,1200} | I43: ="{"&INT((H11)*10000)+1&","&INT((I11)*10000)&"}" -> {1201,1440} | J43: ="{"&INT((I11)*10000)+1&","&INT((J11)*10000)&"}" -> {1441,1800} | K43: ="{"&INT((J11)*10000)+1&","&INT((K11)*10000)&"}" -> {1801,2250} | L43: ="{"&INT((K11)*10000)+1&","&INT((L11)*10000)&"}" -> {2251,2700} | M43: ="{"&INT((L11)*10000)+1&","&INT((M11)*10000)&"}" -> {2701,3240} | Q43: 7 | R43: ="{"&R$3&","&R10&"}" -> {1,1000} | S43: ="{"&S$3&","&S10&"}" -> {2,1000} | T43: ="{"&T$3&","&T10&"}" -> {3,1200} | U43: ="{"&U$3&","&U10&"}" -> {4,1440} | V43: ="{"&V$3&","&V10&"}" -> {5,1800} | W43: ="{"&W$3&","&W10&"}" -> {6,1800} | X43: ="{"&X$3&","&X10&"}" -> {7,2250} | Y43: ="{"&Y$3&","&Y10&"}" -> {8,2250} | ... AC43: ="{"&AC$3&","&AC10&"}" -> {12,3240} | AD43: ="["&_xlfn.TEXTJOIN(",",1,$R43:$AC43)&"]" -> [{1,1000},{2,1000},{3,1200},{4,1440},{5,1800},{6,1800},{7,2250},{8,2250},{9,2700},{10,2700},{11,3240},{12,3240}]
B44: 无视召唤抗性 | C44: 1713 | D44: ="{"&INT(D12*0.5*10000)&","&INT((D12)*10000)&"}" -> {289,578} | E44: ="{"&INT((D12)*10000)+1&","&INT((E12)*10000)&"}" -> {579,800} | F44: ="{"&INT((E12)*10000)+1&","&INT((F12)*10000)&"}" -> {801,833} | G44: ="{"&INT((F12)*10000)+1&","&INT((G12)*10000)&"}" -> {834,1000} | H44: ="{"&INT((G12)*10000)+1&","&INT((H12)*10000)&"}" -> {1001,1200} | I44: ="{"&INT((H12)*10000)+1&","&INT((I12)*10000)&"}" -> {1201,1440} | J44: ="{"&INT((I12)*10000)+1&","&INT((J12)*10000)&"}" -> {1441,1800} | K44: ="{"&INT((J12)*10000)+1&","&INT((K12)*10000)&"}" -> {1801,2250} | L44: ="{"&INT((K12)*10000)+1&","&INT((L12)*10000)&"}" -> {2251,2700} | M44: ="{"&INT((L12)*10000)+1&","&INT((M12)*10000)&"}" -> {2701,3240} | Q44: 8 | R44: ="{"&R$3&","&R11&"}" -> {1,1000} | S44: ="{"&S$3&","&S11&"}" -> {2,1000} | T44: ="{"&T$3&","&T11&"}" -> {3,1200} | U44: ="{"&U$3&","&U11&"}" -> {4,1440} | V44: ="{"&V$3&","&V11&"}" -> {5,1800} | W44: ="{"&W$3&","&W11&"}" -> {6,1800} | X44: ="{"&X$3&","&X11&"}" -> {7,2250} | Y44: ="{"&Y$3&","&Y11&"}" -> {8,2250} | ... AC44: ="{"&AC$3&","&AC11&"}" -> {12,3240} | AD44: ="["&_xlfn.TEXTJOIN(",",1,$R44:$AC44)&"]" -> [{1,1000},{2,1000},{3,1200},{4,1440},{5,1800},{6,1800},{7,2250},{8,2250},{9,2700},{10,2700},{11,3240},{12,3240}]
