Workbook

Sheet 总览
A2: 总结
B4: 1、档次6几率过高，90天看不出问题，再往后可能有
A26: 预期付费
C27: 价值 | G27: 30 | H27: 5 | I27: 60 | N27: =694*90 -> 62460 | O27: =N27*0.4 -> 24984
B28: 用户层级 | C28: 级别 | D28: 体力 | E28: 首日付费 | F28: 每日付费 | G28: 梦灵养成 | H28: 强化养成 | I28: 符文养成 | J28: 秘宝养成 | K28: 皮肤养成 | L28: 钻石
B29: 非R | C29: 1 | D29: 210 | E29: 0 | F29: 0 | G29: 60 | H29: 1000 | I29: =4 -> 4 | L29: 450
B30: 小R | C30: 2 | D30: 280 | E30: =30+6 -> 36 | F30: =(18+30+28+68+12*4)/30 -> 6.4 | G30: 70 | H30: 1100 | I30: =F30/328*24+4 -> 4.4682927 | L30: 720
B31: 中R | C31: 3 | D31: 420 | E31: =198+128+30+6 -> 362 | F31: =(18+30+28+68+25*30+12*4)/30 -> 31.4 | G31: 90 | H31: 1300 | I31: =F31/328*24+4 -> 6.297561 | L31: 840
B32: 大R | C32: 4 | D32: 560 | E32: =648+328+198+128+30+6+4000 -> 5338 | F32: =(18+30+28*2+68*2+25*30+12*4+328+648*30)/30 -> 693.53333 | G32: 110 | H32: 1500 | I32: =F32/328*24+4 -> 54.746341 | L32: 1000
B33: 超R | C33: 5 | D33: 720 | E33: 20000 | F33: 2000 | G33: 120 | H33: 2000 | I33: =F33/328*24+4.5 -> 150.84146 | L33: 2000
B35: #不计入符文本体
B36: 养成模块 | C36: 每日产出 | D36: 首周产出 | E36: 付费比重 | F36: 价值
B37: 梦灵养成 | C37: =OFFSET($F$28,$C$44,MATCH($B37,$G$28:$M$28,0)) -> 60 | D37: =C37 -> 60 | E37: 0.5 | F37: 18
B38: 强化养成 | C38: =OFFSET($F$28,$C$44,MATCH($B38,$G$28:$M$28,0)) -> 1000 | E38: 0 | F38: 5
B39: 符文养成 | C39: =OFFSET($F$28,$C$44,MATCH($B39,$G$28:$M$28,0)) -> 4 | D39: =11 -> 11 | E39: 0.3 | F39: 60
B40: 秘宝养成 | C40: =OFFSET($F$28,$C$44,MATCH($B40,$G$28:$M$28,0)) -> 0 | E40: 0 | F40: 0.33
B41: 皮肤养成 | C41: =OFFSET($F$28,$C$44,MATCH($B41,$G$28:$M$28,0)) -> 0 | E41: 0 | F41: 2000
B42: 钻石 | C42: =OFFSET($F$28,$C$44,MATCH($B42,$G$28:$M$28,0)) -> 450 | D42: 1200 | E42: 0 | F42: 1
H43: =E46*0.07 -> 70
B44: =OFFSET($B$28,C44,0) -> 非R | C44: 1 | D44: 产出总览 | J44: 性价比
B45: 天数 | C45: 充值金额 | D45: 梦灵养成 | E45: 强化养成 | F45: 符文养成 | G45: 秘宝养成 | H45: 皮肤养成 | I45: 钻石 | J45: 梦灵养成 | K45: 强化养成 | L45: 符文养成 | M45: 秘宝养成 | N45: 皮肤养成 | O45: 钻石
B46: 1 | C46: =_xlfn.XLOOKUP(C44,$C$28:$C$33,$E$28:$E$33) -> 0 | D46: =OFFSET($B$36,MATCH(D$45,$B$37:$B$42,0),1)*$B46+OFFSET($B$36,MATCH(D$45,$B$37:$B$42,0),2)*MIN($B46,7)+OFFSET($E$36,MATCH(D$45,$B$37:$B$42,0),0)*$C46*1.1/OFFSET($F$36,MATCH(D$45,$B$37:$B$42,0),0) -> 120 | E46: =OFFSET($B$36,MATCH(E$45,$B$37:$B$42,0),1)*$B46+OFFSET($B$36,MATCH(E$45,$B$37:$B$42,0),2)*MIN($B46,7)+OFFSET($E$36,MATCH(E$45,$B$37:$B$42,0),0)*$C46*1.1/OFFSET($F$36,MATCH(E$45,$B$37:$B$42,0),0) -> 1000 | F46: =OFFSET($B$36,MATCH(F$45,$B$37:$B$42,0),1)*$B46+OFFSET($B$36,MATCH(F$45,$B$37:$B$42,0),2)*MIN($B46,7)+OFFSET($E$36,MATCH(F$45,$B$37:$B$42,0),0)*$C46*1.1/OFFSET($F$36,MATCH(F$45,$B$37:$B$42,0),0) -> 15 | G46: =OFFSET($B$36,MATCH(G$45,$B$37:$B$42,0),1)*$B46+OFFSET($B$36,MATCH(G$45,$B$37:$B$42,0),2)*MIN($B46,7)+OFFSET($E$36,MATCH(G$45,$B$37:$B$42,0),0)*$C46*1.1/OFFSET($F$36,MATCH(G$45,$B$37:$B$42,0),0) -> 0 | H46: =OFFSET($B$36,MATCH(H$45,$B$37:$B$42,0),1)*$B46+OFFSET($B$36,MATCH(H$45,$B$37:$B$42,0),2)*MIN($B46,7)+OFFSET($E$36,MATCH(H$45,$B$37:$B$42,0),0)*$C46*1.1/OFFSET($F$36,MATCH(H$45,$B$37:$B$42,0),0) -> 0 | I46: =OFFSET($B$36,MATCH(I$45,$B$37:$B$42,0),1)*$B46+OFFSET($B$36,MATCH(I$45,$B$37:$B$42,0),2)*MIN($B46,7)+OFFSET($E$36,MATCH(I$45,$B$37:$B$42,0),0)*$C46*1.1/OFFSET($F$36,MATCH(I$45,$B$37:$B$42,0),0) -> 1650 | J46: =OFFSET(梦灵养成!$Y$29,MATCH(D46,梦灵养成!$C$30:$C$629,1),0) -> 5400 | K46: =E46*0.07 -> 70 | L46: =OFFSET(洗练性价比!$N$52,MATCH(F46*60,洗练性价比!$C$53:$C$2052,1),0) -> 2880
B47: 2 | C47: =C46+_xlfn.XLOOKUP($C$44,$C$28:$C$33,$F$28:$F$33) -> 0 | D47: =OFFSET($B$36,MATCH(D$45,$B$37:$B$42,0),1)*$B47+OFFSET($B$36,MATCH(D$45,$B$37:$B$42,0),2)*MIN($B47,7)+OFFSET($E$36,MATCH(D$45,$B$37:$B$42,0),0)*$C47*1.1/OFFSET($F$36,MATCH(D$45,$B$37:$B$42,0),0) -> 240 | E47: =OFFSET($B$36,MATCH(E$45,$B$37:$B$42,0),1)*$B47+OFFSET($B$36,MATCH(E$45,$B$37:$B$42,0),2)*MIN($B47,7)+OFFSET($E$36,MATCH(E$45,$B$37:$B$42,0),0)*$C47*1.1/OFFSET($F$36,MATCH(E$45,$B$37:$B$42,0),0) -> 2000 | F47: =OFFSET($B$36,MATCH(F$45,$B$37:$B$42,0),1)*$B47+OFFSET($B$36,MATCH(F$45,$B$37:$B$42,0),2)*MIN($B47,7)+OFFSET($E$36,MATCH(F$45,$B$37:$B$42,0),0)*$C47*1.1/OFFSET($F$36,MATCH(F$45,$B$37:$B$42,0),0) -> 30 | G47: =OFFSET($B$36,MATCH(G$45,$B$37:$B$42,0),1)*$B47+OFFSET($B$36,MATCH(G$45,$B$37:$B$42,0),2)*MIN($B47,7)+OFFSET($E$36,MATCH(G$45,$B$37:$B$42,0),0)*$C47*1.1/OFFSET($F$36,MATCH(G$45,$B$37:$B$42,0),0) -> 0 | H47: =OFFSET($B$36,MATCH(H$45,$B$37:$B$42,0),1)*$B47+OFFSET($B$36,MATCH(H$45,$B$37:$B$42,0),2)*MIN($B47,7)+OFFSET($E$36,MATCH(H$45,$B$37:$B$42,0),0)*$C47*1.1/OFFSET($F$36,MATCH(H$45,$B$37:$B$42,0),0) -> 0 | I47: =OFFSET($B$36,MATCH(I$45,$B$37:$B$42,0),1)*$B47+OFFSET($B$36,MATCH(I$45,$B$37:$B$42,0),2)*MIN($B47,7)+OFFSET($E$36,MATCH(I$45,$B$37:$B$42,0),0)*$C47*1.1/OFFSET($F$36,MATCH(I$45,$B$37:$B$42,0),0) -> 3300 | J47: =OFFSET(梦灵养成!$Y$29,MATCH(D47,梦灵养成!$C$30:$C$629,1),0) -> 3600 | K47: =E47*0.07 -> 140 | L47: =OFFSET(洗练性价比!$N$52,MATCH(F47*60,洗练性价比!$C$53:$C$2052,1),0) -> 2880
B48: 3 | C48: =C47+_xlfn.XLOOKUP($C$44,$C$28:$C$33,$F$28:$F$33) -> 0 | D48: =OFFSET($B$36,MATCH(D$45,$B$37:$B$42,0),1)*$B48+OFFSET($B$36,MATCH(D$45,$B$37:$B$42,0),2)*MIN($B48,7)+OFFSET($E$36,MATCH(D$45,$B$37:$B$42,0),0)*$C48*1.1/OFFSET($F$36,MATCH(D$45,$B$37:$B$42,0),0) -> 360 | E48: =OFFSET($B$36,MATCH(E$45,$B$37:$B$42,0),1)*$B48+OFFSET($B$36,MATCH(E$45,$B$37:$B$42,0),2)*MIN($B48,7)+OFFSET($E$36,MATCH(E$45,$B$37:$B$42,0),0)*$C48*1.1/OFFSET($F$36,MATCH(E$45,$B$37:$B$42,0),0) -> 3000 | F48: =OFFSET($B$36,MATCH(F$45,$B$37:$B$42,0),1)*$B48+OFFSET($B$36,MATCH(F$45,$B$37:$B$42,0),2)*MIN($B48,7)+OFFSET($E$36,MATCH(F$45,$B$37:$B$42,0),0)*$C48*1.1/OFFSET($F$36,MATCH(F$45,$B$37:$B$42,0),0) -> 45 | G48: =OFFSET($B$36,MATCH(G$45,$B$37:$B$42,0),1)*$B48+OFFSET($B$36,MATCH(G$45,$B$37:$B$42,0),2)*MIN($B48,7)+OFFSET($E$36,MATCH(G$45,$B$37:$B$42,0),0)*$C48*1.1/OFFSET($F$36,MATCH(G$45,$B$37:$B$42,0),0) -> 0 | H48: =OFFSET($B$36,MATCH(H$45,$B$37:$B$42,0),1)*$B48+OFFSET($B$36,MATCH(H$45,$B$37:$B$42,0),2)*MIN($B48,7)+OFFSET($E$36,MATCH(H$45,$B$37:$B$42,0),0)*$C48*1.1/OFFSET($F$36,MATCH(H$45,$B$37:$B$42,0),0) -> 0 | I48: =OFFSET($B$36,MATCH(I$45,$B$37:$B$42,0),1)*$B48+OFFSET($B$36,MATCH(I$45,$B$37:$B$42,0),2)*MIN($B48,7)+OFFSET($E$36,MATCH(I$45,$B$37:$B$42,0),0)*$C48*1.1/OFFSET($F$36,MATCH(I$45,$B$37:$B$42,0),0) -> 4950 | J48: =OFFSET(梦灵养成!$Y$29,MATCH(D48,梦灵养成!$C$30:$C$629,1),0) -> 1800 | K48: =E48*0.07 -> 210 | L48: =OFFSET(洗练性价比!$N$52,MATCH(F48*60,洗练性价比!$C$53:$C$2052,1),0) -> 2880
B49: 4 | C49: =C48+_xlfn.XLOOKUP($C$44,$C$28:$C$33,$F$28:$F$33) -> 0 | D49: =OFFSET($B$36,MATCH(D$45,$B$37:$B$42,0),1)*$B49+OFFSET($B$36,MATCH(D$45,$B$37:$B$42,0),2)*MIN($B49,7)+OFFSET($E$36,MATCH(D$45,$B$37:$B$42,0),0)*$C49*1.1/OFFSET($F$36,MATCH(D$45,$B$37:$B$42,0),0) -> 480 | E49: =OFFSET($B$36,MATCH(E$45,$B$37:$B$42,0),1)*$B49+OFFSET($B$36,MATCH(E$45,$B$37:$B$42,0),2)*MIN($B49,7)+OFFSET($E$36,MATCH(E$45,$B$37:$B$42,0),0)*$C49*1.1/OFFSET($F$36,MATCH(E$45,$B$37:$B$42,0),0) -> 4000 | F49: =OFFSET($B$36,MATCH(F$45,$B$37:$B$42,0),1)*$B49+OFFSET($B$36,MATCH(F$45,$B$37:$B$42,0),2)*MIN($B49,7)+OFFSET($E$36,MATCH(F$45,$B$37:$B$42,0),0)*$C49*1.1/OFFSET($F$36,MATCH(F$45,$B$37:$B$42,0),0) -> 60 | G49: =OFFSET($B$36,MATCH(G$45,$B$37:$B$42,0),1)*$B49+OFFSET($B$36,MATCH(G$45,$B$37:$B$42,0),2)*MIN($B49,7)+OFFSET($E$36,MATCH(G$45,$B$37:$B$42,0),0)*$C49*1.1/OFFSET($F$36,MATCH(G$45,$B$37:$B$42,0),0) -> 0 | H49: =OFFSET($B$36,MATCH(H$45,$B$37:$B$42,0),1)*$B49+OFFSET($B$36,MATCH(H$45,$B$37:$B$42,0),2)*MIN($B49,7)+OFFSET($E$36,MATCH(H$45,$B$37:$B$42,0),0)*$C49*1.1/OFFSET($F$36,MATCH(H$45,$B$37:$B$42,0),0) -> 0 | I49: =OFFSET($B$36,MATCH(I$45,$B$37:$B$42,0),1)*$B49+OFFSET($B$36,MATCH(I$45,$B$37:$B$42,0),2)*MIN($B49,7)+OFFSET($E$36,MATCH(I$45,$B$37:$B$42,0),0)*$C49*1.1/OFFSET($F$36,MATCH(I$45,$B$37:$B$42,0),0) -> 6600 | J49: =OFFSET(梦灵养成!$Y$29,MATCH(D49,梦灵养成!$C$30:$C$629,1),0) -> 9000 | K49: =E49*0.07 -> 280 | L49: =OFFSET(洗练性价比!$N$52,MATCH(F49*60,洗练性价比!$C$53:$C$2052,1),0) -> 2880
B50: 5 | C50: =C49+_xlfn.XLOOKUP($C$44,$C$28:$C$33,$F$28:$F$33) -> 0 | D50: =OFFSET($B$36,MATCH(D$45,$B$37:$B$42,0),1)*$B50+OFFSET($B$36,MATCH(D$45,$B$37:$B$42,0),2)*MIN($B50,7)+OFFSET($E$36,MATCH(D$45,$B$37:$B$42,0),0)*$C50*1.1/OFFSET($F$36,MATCH(D$45,$B$37:$B$42,0),0) -> 600 | E50: =OFFSET($B$36,MATCH(E$45,$B$37:$B$42,0),1)*$B50+OFFSET($B$36,MATCH(E$45,$B$37:$B$42,0),2)*MIN($B50,7)+OFFSET($E$36,MATCH(E$45,$B$37:$B$42,0),0)*$C50*1.1/OFFSET($F$36,MATCH(E$45,$B$37:$B$42,0),0) -> 5000 | F50: =OFFSET($B$36,MATCH(F$45,$B$37:$B$42,0),1)*$B50+OFFSET($B$36,MATCH(F$45,$B$37:$B$42,0),2)*MIN($B50,7)+OFFSET($E$36,MATCH(F$45,$B$37:$B$42,0),0)*$C50*1.1/OFFSET($F$36,MATCH(F$45,$B$37:$B$42,0),0) -> 75 | G50: =OFFSET($B$36,MATCH(G$45,$B$37:$B$42,0),1)*$B50+OFFSET($B$36,MATCH(G$45,$B$37:$B$42,0),2)*MIN($B50,7)+OFFSET($E$36,MATCH(G$45,$B$37:$B$42,0),0)*$C50*1.1/OFFSET($F$36,MATCH(G$45,$B$37:$B$42,0),0) -> 0 | H50: =OFFSET($B$36,MATCH(H$45,$B$37:$B$42,0),1)*$B50+OFFSET($B$36,MATCH(H$45,$B$37:$B$42,0),2)*MIN($B50,7)+OFFSET($E$36,MATCH(H$45,$B$37:$B$42,0),0)*$C50*1.1/OFFSET($F$36,MATCH(H$45,$B$37:$B$42,0),0) -> 0 | I50: =OFFSET($B$36,MATCH(I$45,$B$37:$B$42,0),1)*$B50+OFFSET($B$36,MATCH(I$45,$B$37:$B$42,0),2)*MIN($B50,7)+OFFSET($E$36,MATCH(I$45,$B$37:$B$42,0),0)*$C50*1.1/OFFSET($F$36,MATCH(I$45,$B$37:$B$42,0),0) -> 8250 | J50: =OFFSET(梦灵养成!$Y$29,MATCH(D50,梦灵养成!$C$30:$C$629,1),0) -> 14400 | K50: =E50*0.07 -> 350 | L50: =OFFSET(洗练性价比!$N$52,MATCH(F50*60,洗练性价比!$C$53:$C$2052,1),0) -> 2880
B51: 6 | C51: =C50+_xlfn.XLOOKUP($C$44,$C$28:$C$33,$F$28:$F$33) -> 0 | D51: =OFFSET($B$36,MATCH(D$45,$B$37:$B$42,0),1)*$B51+OFFSET($B$36,MATCH(D$45,$B$37:$B$42,0),2)*MIN($B51,7)+OFFSET($E$36,MATCH(D$45,$B$37:$B$42,0),0)*$C51*1.1/OFFSET($F$36,MATCH(D$45,$B$37:$B$42,0),0) -> 720 | E51: =OFFSET($B$36,MATCH(E$45,$B$37:$B$42,0),1)*$B51+OFFSET($B$36,MATCH(E$45,$B$37:$B$42,0),2)*MIN($B51,7)+OFFSET($E$36,MATCH(E$45,$B$37:$B$42,0),0)*$C51*1.1/OFFSET($F$36,MATCH(E$45,$B$37:$B$42,0),0) -> 6000 | F51: =OFFSET($B$36,MATCH(F$45,$B$37:$B$42,0),1)*$B51+OFFSET($B$36,MATCH(F$45,$B$37:$B$42,0),2)*MIN($B51,7)+OFFSET($E$36,MATCH(F$45,$B$37:$B$42,0),0)*$C51*1.1/OFFSET($F$36,MATCH(F$45,$B$37:$B$42,0),0) -> 90 | G51: =OFFSET($B$36,MATCH(G$45,$B$37:$B$42,0),1)*$B51+OFFSET($B$36,MATCH(G$45,$B$37:$B$42,0),2)*MIN($B51,7)+OFFSET($E$36,MATCH(G$45,$B$37:$B$42,0),0)*$C51*1.1/OFFSET($F$36,MATCH(G$45,$B$37:$B$42,0),0) -> 0 | H51: =OFFSET($B$36,MATCH(H$45,$B$37:$B$42,0),1)*$B51+OFFSET($B$36,MATCH(H$45,$B$37:$B$42,0),2)*MIN($B51,7)+OFFSET($E$36,MATCH(H$45,$B$37:$B$42,0),0)*$C51*1.1/OFFSET($F$36,MATCH(H$45,$B$37:$B$42,0),0) -> 0 | I51: =OFFSET($B$36,MATCH(I$45,$B$37:$B$42,0),1)*$B51+OFFSET($B$36,MATCH(I$45,$B$37:$B$42,0),2)*MIN($B51,7)+OFFSET($E$36,MATCH(I$45,$B$37:$B$42,0),0)*$C51*1.1/OFFSET($F$36,MATCH(I$45,$B$37:$B$42,0),0) -> 9900 | J51: =OFFSET(梦灵养成!$Y$29,MATCH(D51,梦灵养成!$C$30:$C$629,1),0) -> 12600 | K51: =E51*0.07 -> 420 | L51: =OFFSET(洗练性价比!$N$52,MATCH(F51*60,洗练性价比!$C$53:$C$2052,1),0) -> 2880
B52: 7 | C52: =C51+_xlfn.XLOOKUP($C$44,$C$28:$C$33,$F$28:$F$33) -> 0 | D52: =OFFSET($B$36,MATCH(D$45,$B$37:$B$42,0),1)*$B52+OFFSET($B$36,MATCH(D$45,$B$37:$B$42,0),2)*MIN($B52,7)+OFFSET($E$36,MATCH(D$45,$B$37:$B$42,0),0)*$C52*1.1/OFFSET($F$36,MATCH(D$45,$B$37:$B$42,0),0) -> 840 | E52: =OFFSET($B$36,MATCH(E$45,$B$37:$B$42,0),1)*$B52+OFFSET($B$36,MATCH(E$45,$B$37:$B$42,0),2)*MIN($B52,7)+OFFSET($E$36,MATCH(E$45,$B$37:$B$42,0),0)*$C52*1.1/OFFSET($F$36,MATCH(E$45,$B$37:$B$42,0),0) -> 7000 | F52: =OFFSET($B$36,MATCH(F$45,$B$37:$B$42,0),1)*$B52+OFFSET($B$36,MATCH(F$45,$B$37:$B$42,0),2)*MIN($B52,7)+OFFSET($E$36,MATCH(F$45,$B$37:$B$42,0),0)*$C52*1.1/OFFSET($F$36,MATCH(F$45,$B$37:$B$42,0),0) -> 105 | G52: =OFFSET($B$36,MATCH(G$45,$B$37:$B$42,0),1)*$B52+OFFSET($B$36,MATCH(G$45,$B$37:$B$42,0),2)*MIN($B52,7)+OFFSET($E$36,MATCH(G$45,$B$37:$B$42,0),0)*$C52*1.1/OFFSET($F$36,MATCH(G$45,$B$37:$B$42,0),0) -> 0 | H52: =OFFSET($B$36,MATCH(H$45,$B$37:$B$42,0),1)*$B52+OFFSET($B$36,MATCH(H$45,$B$37:$B$42,0),2)*MIN($B52,7)+OFFSET($E$36,MATCH(H$45,$B$37:$B$42,0),0)*$C52*1.1/OFFSET($F$36,MATCH(H$45,$B$37:$B$42,0),0) -> 0 | I52: =OFFSET($B$36,MATCH(I$45,$B$37:$B$42,0),1)*$B52+OFFSET($B$36,MATCH(I$45,$B$37:$B$42,0),2)*MIN($B52,7)+OFFSET($E$36,MATCH(I$45,$B$37:$B$42,0),0)*$C52*1.1/OFFSET($F$36,MATCH(I$45,$B$37:$B$42,0),0) -> 11550 | J52: =OFFSET(梦灵养成!$Y$29,MATCH(D52,梦灵养成!$C$30:$C$629,1),0) -> 10800 | K52: =E52*0.07 -> 490 | L52: =OFFSET(洗练性价比!$N$52,MATCH(F52*60,洗练性价比!$C$53:$C$2052,1),0) -> 2880
B53: 8 | C53: =C52+_xlfn.XLOOKUP($C$44,$C$28:$C$33,$F$28:$F$33) -> 0 | D53: =OFFSET($B$36,MATCH(D$45,$B$37:$B$42,0),1)*$B53+OFFSET($B$36,MATCH(D$45,$B$37:$B$42,0),2)*MIN($B53,7)+OFFSET($E$36,MATCH(D$45,$B$37:$B$42,0),0)*$C53*1.1/OFFSET($F$36,MATCH(D$45,$B$37:$B$42,0),0) -> 900 | E53: =OFFSET($B$36,MATCH(E$45,$B$37:$B$42,0),1)*$B53+OFFSET($B$36,MATCH(E$45,$B$37:$B$42,0),2)*MIN($B53,7)+OFFSET($E$36,MATCH(E$45,$B$37:$B$42,0),0)*$C53*1.1/OFFSET($F$36,MATCH(E$45,$B$37:$B$42,0),0) -> 8000 | F53: =OFFSET($B$36,MATCH(F$45,$B$37:$B$42,0),1)*$B53+OFFSET($B$36,MATCH(F$45,$B$37:$B$42,0),2)*MIN($B53,7)+OFFSET($E$36,MATCH(F$45,$B$37:$B$42,0),0)*$C53*1.1/OFFSET($F$36,MATCH(F$45,$B$37:$B$42,0),0) -> 109 | G53: =OFFSET($B$36,MATCH(G$45,$B$37:$B$42,0),1)*$B53+OFFSET($B$36,MATCH(G$45,$B$37:$B$42,0),2)*MIN($B53,7)+OFFSET($E$36,MATCH(G$45,$B$37:$B$42,0),0)*$C53*1.1/OFFSET($F$36,MATCH(G$45,$B$37:$B$42,0),0) -> 0 | H53: =OFFSET($B$36,MATCH(H$45,$B$37:$B$42,0),1)*$B53+OFFSET($B$36,MATCH(H$45,$B$37:$B$42,0),2)*MIN($B53,7)+OFFSET($E$36,MATCH(H$45,$B$37:$B$42,0),0)*$C53*1.1/OFFSET($F$36,MATCH(H$45,$B$37:$B$42,0),0) -> 0 | I53: =OFFSET($B$36,MATCH(I$45,$B$37:$B$42,0),1)*$B53+OFFSET($B$36,MATCH(I$45,$B$37:$B$42,0),2)*MIN($B53,7)+OFFSET($E$36,MATCH(I$45,$B$37:$B$42,0),0)*$C53*1.1/OFFSET($F$36,MATCH(I$45,$B$37:$B$42,0),0) -> 12000 | J53: =OFFSET(梦灵养成!$Y$29,MATCH(D53,梦灵养成!$C$30:$C$629,1),0) -> 10800 | K53: =E53*0.07 -> 560 | L53: =OFFSET(洗练性价比!$N$52,MATCH(F53*60,洗练性价比!$C$53:$C$2052,1),0) -> 2880
B54: 9 | C54: =C53+_xlfn.XLOOKUP($C$44,$C$28:$C$33,$F$28:$F$33) -> 0 | D54: =OFFSET($B$36,MATCH(D$45,$B$37:$B$42,0),1)*$B54+OFFSET($B$36,MATCH(D$45,$B$37:$B$42,0),2)*MIN($B54,7)+OFFSET($E$36,MATCH(D$45,$B$37:$B$42,0),0)*$C54*1.1/OFFSET($F$36,MATCH(D$45,$B$37:$B$42,0),0) -> 960 | E54: =OFFSET($B$36,MATCH(E$45,$B$37:$B$42,0),1)*$B54+OFFSET($B$36,MATCH(E$45,$B$37:$B$42,0),2)*MIN($B54,7)+OFFSET($E$36,MATCH(E$45,$B$37:$B$42,0),0)*$C54*1.1/OFFSET($F$36,MATCH(E$45,$B$37:$B$42,0),0) -> 9000 | F54: =OFFSET($B$36,MATCH(F$45,$B$37:$B$42,0),1)*$B54+OFFSET($B$36,MATCH(F$45,$B$37:$B$42,0),2)*MIN($B54,7)+OFFSET($E$36,MATCH(F$45,$B$37:$B$42,0),0)*$C54*1.1/OFFSET($F$36,MATCH(F$45,$B$37:$B$42,0),0) -> 113 | G54: =OFFSET($B$36,MATCH(G$45,$B$37:$B$42,0),1)*$B54+OFFSET($B$36,MATCH(G$45,$B$37:$B$42,0),2)*MIN($B54,7)+OFFSET($E$36,MATCH(G$45,$B$37:$B$42,0),0)*$C54*1.1/OFFSET($F$36,MATCH(G$45,$B$37:$B$42,0),0) -> 0 | H54: =OFFSET($B$36,MATCH(H$45,$B$37:$B$42,0),1)*$B54+OFFSET($B$36,MATCH(H$45,$B$37:$B$42,0),2)*MIN($B54,7)+OFFSET($E$36,MATCH(H$45,$B$37:$B$42,0),0)*$C54*1.1/OFFSET($F$36,MATCH(H$45,$B$37:$B$42,0),0) -> 0 | I54: =OFFSET($B$36,MATCH(I$45,$B$37:$B$42,0),1)*$B54+OFFSET($B$36,MATCH(I$45,$B$37:$B$42,0),2)*MIN($B54,7)+OFFSET($E$36,MATCH(I$45,$B$37:$B$42,0),0)*$C54*1.1/OFFSET($F$36,MATCH(I$45,$B$37:$B$42,0),0) -> 12450 | J54: =OFFSET(梦灵养成!$Y$29,MATCH(D54,梦灵养成!$C$30:$C$629,1),0) -> 10800 | K54: =E54*0.07 -> 630 | L54: =OFFSET(洗练性价比!$N$52,MATCH(F54*60,洗练性价比!$C$53:$C$2052,1),0) -> 2880
B55: 10 | C55: =C54+_xlfn.XLOOKUP($C$44,$C$28:$C$33,$F$28:$F$33) -> 0 | D55: =OFFSET($B$36,MATCH(D$45,$B$37:$B$42,0),1)*$B55+OFFSET($B$36,MATCH(D$45,$B$37:$B$42,0),2)*MIN($B55,7)+OFFSET($E$36,MATCH(D$45,$B$37:$B$42,0),0)*$C55*1.1/OFFSET($F$36,MATCH(D$45,$B$37:$B$42,0),0) -> 1020 | E55: =OFFSET($B$36,MATCH(E$45,$B$37:$B$42,0),1)*$B55+OFFSET($B$36,MATCH(E$45,$B$37:$B$42,0),2)*MIN($B55,7)+OFFSET($E$36,MATCH(E$45,$B$37:$B$42,0),0)*$C55*1.1/OFFSET($F$36,MATCH(E$45,$B$37:$B$42,0),0) -> 10000 | F55: =OFFSET($B$36,MATCH(F$45,$B$37:$B$42,0),1)*$B55+OFFSET($B$36,MATCH(F$45,$B$37:$B$42,0),2)*MIN($B55,7)+OFFSET($E$36,MATCH(F$45,$B$37:$B$42,0),0)*$C55*1.1/OFFSET($F$36,MATCH(F$45,$B$37:$B$42,0),0) -> 117 | G55: =OFFSET($B$36,MATCH(G$45,$B$37:$B$42,0),1)*$B55+OFFSET($B$36,MATCH(G$45,$B$37:$B$42,0),2)*MIN($B55,7)+OFFSET($E$36,MATCH(G$45,$B$37:$B$42,0),0)*$C55*1.1/OFFSET($F$36,MATCH(G$45,$B$37:$B$42,0),0) -> 0 | H55: =OFFSET($B$36,MATCH(H$45,$B$37:$B$42,0),1)*$B55+OFFSET($B$36,MATCH(H$45,$B$37:$B$42,0),2)*MIN($B55,7)+OFFSET($E$36,MATCH(H$45,$B$37:$B$42,0),0)*$C55*1.1/OFFSET($F$36,MATCH(H$45,$B$37:$B$42,0),0) -> 0 | I55: =OFFSET($B$36,MATCH(I$45,$B$37:$B$42,0),1)*$B55+OFFSET($B$36,MATCH(I$45,$B$37:$B$42,0),2)*MIN($B55,7)+OFFSET($E$36,MATCH(I$45,$B$37:$B$42,0),0)*$C55*1.1/OFFSET($F$36,MATCH(I$45,$B$37:$B$42,0),0) -> 12900 | J55: =OFFSET(梦灵养成!$Y$29,MATCH(D55,梦灵养成!$C$30:$C$629,1),0) -> 9000 | K55: =E55*0.07 -> 700 | L55: =OFFSET(洗练性价比!$N$52,MATCH(F55*60,洗练性价比!$C$53:$C$2052,1),0) -> 2880
B56: 11 | C56: =C55+_xlfn.XLOOKUP($C$44,$C$28:$C$33,$F$28:$F$33) -> 0 | D56: =OFFSET($B$36,MATCH(D$45,$B$37:$B$42,0),1)*$B56+OFFSET($B$36,MATCH(D$45,$B$37:$B$42,0),2)*MIN($B56,7)+OFFSET($E$36,MATCH(D$45,$B$37:$B$42,0),0)*$C56*1.1/OFFSET($F$36,MATCH(D$45,$B$37:$B$42,0),0) -> 1080 | E56: =OFFSET($B$36,MATCH(E$45,$B$37:$B$42,0),1)*$B56+OFFSET($B$36,MATCH(E$45,$B$37:$B$42,0),2)*MIN($B56,7)+OFFSET($E$36,MATCH(E$45,$B$37:$B$42,0),0)*$C56*1.1/OFFSET($F$36,MATCH(E$45,$B$37:$B$42,0),0) -> 11000 | F56: =OFFSET($B$36,MATCH(F$45,$B$37:$B$42,0),1)*$B56+OFFSET($B$36,MATCH(F$45,$B$37:$B$42,0),2)*MIN($B56,7)+OFFSET($E$36,MATCH(F$45,$B$37:$B$42,0),0)*$C56*1.1/OFFSET($F$36,MATCH(F$45,$B$37:$B$42,0),0) -> 121 | G56: =OFFSET($B$36,MATCH(G$45,$B$37:$B$42,0),1)*$B56+OFFSET($B$36,MATCH(G$45,$B$37:$B$42,0),2)*MIN($B56,7)+OFFSET($E$36,MATCH(G$45,$B$37:$B$42,0),0)*$C56*1.1/OFFSET($F$36,MATCH(G$45,$B$37:$B$42,0),0) -> 0 | H56: =OFFSET($B$36,MATCH(H$45,$B$37:$B$42,0),1)*$B56+OFFSET($B$36,MATCH(H$45,$B$37:$B$42,0),2)*MIN($B56,7)+OFFSET($E$36,MATCH(H$45,$B$37:$B$42,0),0)*$C56*1.1/OFFSET($F$36,MATCH(H$45,$B$37:$B$42,0),0) -> 0 | I56: =OFFSET($B$36,MATCH(I$45,$B$37:$B$42,0),1)*$B56+OFFSET($B$36,MATCH(I$45,$B$37:$B$42,0),2)*MIN($B56,7)+OFFSET($E$36,MATCH(I$45,$B$37:$B$42,0),0)*$C56*1.1/OFFSET($F$36,MATCH(I$45,$B$37:$B$42,0),0) -> 13350 | J56: =OFFSET(梦灵养成!$Y$29,MATCH(D56,梦灵养成!$C$30:$C$629,1),0) -> 9000 | K56: =E56*0.07 -> 770 | L56: =OFFSET(洗练性价比!$N$52,MATCH(F56*60,洗练性价比!$C$53:$C$2052,1),0) -> 3240
B57: 12 | C57: =C56+_xlfn.XLOOKUP($C$44,$C$28:$C$33,$F$28:$F$33) -> 0 | D57: =OFFSET($B$36,MATCH(D$45,$B$37:$B$42,0),1)*$B57+OFFSET($B$36,MATCH(D$45,$B$37:$B$42,0),2)*MIN($B57,7)+OFFSET($E$36,MATCH(D$45,$B$37:$B$42,0),0)*$C57*1.1/OFFSET($F$36,MATCH(D$45,$B$37:$B$42,0),0) -> 1140 | E57: =OFFSET($B$36,MATCH(E$45,$B$37:$B$42,0),1)*$B57+OFFSET($B$36,MATCH(E$45,$B$37:$B$42,0),2)*MIN($B57,7)+OFFSET($E$36,MATCH(E$45,$B$37:$B$42,0),0)*$C57*1.1/OFFSET($F$36,MATCH(E$45,$B$37:$B$42,0),0) -> 12000 | F57: =OFFSET($B$36,MATCH(F$45,$B$37:$B$42,0),1)*$B57+OFFSET($B$36,MATCH(F$45,$B$37:$B$42,0),2)*MIN($B57,7)+OFFSET($E$36,MATCH(F$45,$B$37:$B$42,0),0)*$C57*1.1/OFFSET($F$36,MATCH(F$45,$B$37:$B$42,0),0) -> 125 | G57: =OFFSET($B$36,MATCH(G$45,$B$37:$B$42,0),1)*$B57+OFFSET($B$36,MATCH(G$45,$B$37:$B$42,0),2)*MIN($B57,7)+OFFSET($E$36,MATCH(G$45,$B$37:$B$42,0),0)*$C57*1.1/OFFSET($F$36,MATCH(G$45,$B$37:$B$42,0),0) -> 0 | H57: =OFFSET($B$36,MATCH(H$45,$B$37:$B$42,0),1)*$B57+OFFSET($B$36,MATCH(H$45,$B$37:$B$42,0),2)*MIN($B57,7)+OFFSET($E$36,MATCH(H$45,$B$37:$B$42,0),0)*$C57*1.1/OFFSET($F$36,MATCH(H$45,$B$37:$B$42,0),0) -> 0 | I57: =OFFSET($B$36,MATCH(I$45,$B$37:$B$42,0),1)*$B57+OFFSET($B$36,MATCH(I$45,$B$37:$B$42,0),2)*MIN($B57,7)+OFFSET($E$36,MATCH(I$45,$B$37:$B$42,0),0)*$C57*1.1/OFFSET($F$36,MATCH(I$45,$B$37:$B$42,0),0) -> 13800 | J57: =OFFSET(梦灵养成!$Y$29,MATCH(D57,梦灵养成!$C$30:$C$629,1),0) -> 7200 | K57: =E57*0.07 -> 840 | L57: =OFFSET(洗练性价比!$N$52,MATCH(F57*60,洗练性价比!$C$53:$C$2052,1),0) -> 3240
B58: 13 | C58: =C57+_xlfn.XLOOKUP($C$44,$C$28:$C$33,$F$28:$F$33) -> 0 | D58: =OFFSET($B$36,MATCH(D$45,$B$37:$B$42,0),1)*$B58+OFFSET($B$36,MATCH(D$45,$B$37:$B$42,0),2)*MIN($B58,7)+OFFSET($E$36,MATCH(D$45,$B$37:$B$42,0),0)*$C58*1.1/OFFSET($F$36,MATCH(D$45,$B$37:$B$42,0),0) -> 1200 | E58: =OFFSET($B$36,MATCH(E$45,$B$37:$B$42,0),1)*$B58+OFFSET($B$36,MATCH(E$45,$B$37:$B$42,0),2)*MIN($B58,7)+OFFSET($E$36,MATCH(E$45,$B$37:$B$42,0),0)*$C58*1.1/OFFSET($F$36,MATCH(E$45,$B$37:$B$42,0),0) -> 13000 | F58: =OFFSET($B$36,MATCH(F$45,$B$37:$B$42,0),1)*$B58+OFFSET($B$36,MATCH(F$45,$B$37:$B$42,0),2)*MIN($B58,7)+OFFSET($E$36,MATCH(F$45,$B$37:$B$42,0),0)*$C58*1.1/OFFSET($F$36,MATCH(F$45,$B$37:$B$42,0),0) -> 129 | G58: =OFFSET($B$36,MATCH(G$45,$B$37:$B$42,0),1)*$B58+OFFSET($B$36,MATCH(G$45,$B$37:$B$42,0),2)*MIN($B58,7)+OFFSET($E$36,MATCH(G$45,$B$37:$B$42,0),0)*$C58*1.1/OFFSET($F$36,MATCH(G$45,$B$37:$B$42,0),0) -> 0 | H58: =OFFSET($B$36,MATCH(H$45,$B$37:$B$42,0),1)*$B58+OFFSET($B$36,MATCH(H$45,$B$37:$B$42,0),2)*MIN($B58,7)+OFFSET($E$36,MATCH(H$45,$B$37:$B$42,0),0)*$C58*1.1/OFFSET($F$36,MATCH(H$45,$B$37:$B$42,0),0) -> 0 | I58: =OFFSET($B$36,MATCH(I$45,$B$37:$B$42,0),1)*$B58+OFFSET($B$36,MATCH(I$45,$B$37:$B$42,0),2)*MIN($B58,7)+OFFSET($E$36,MATCH(I$45,$B$37:$B$42,0),0)*$C58*1.1/OFFSET($F$36,MATCH(I$45,$B$37:$B$42,0),0) -> 14250 | J58: =OFFSET(梦灵养成!$Y$29,MATCH(D58,梦灵养成!$C$30:$C$629,1),0) -> 5400 | K58: =E58*0.07 -> 910 | L58: =OFFSET(洗练性价比!$N$52,MATCH(F58*60,洗练性价比!$C$53:$C$2052,1),0) -> 3600
... B345: 300 | C345: =C344+_xlfn.XLOOKUP($C$44,$C$28:$C$33,$F$28:$F$33) -> 0 | D345: =OFFSET($B$36,MATCH(D$45,$B$37:$B$42,0),1)*$B345+OFFSET($B$36,MATCH(D$45,$B$37:$B$42,0),2)*MIN($B345,7)+OFFSET($E$36,MATCH(D$45,$B$37:$B$42,0),0)*$C345*1.1/OFFSET($F$36,MATCH(D$45,$B$37:$B$42,0),0) -> 18420 | E345: =OFFSET($B$36,MATCH(E$45,$B$37:$B$42,0),1)*$B345+OFFSET($B$36,MATCH(E$45,$B$37:$B$42,0),2)*MIN($B345,7)+OFFSET($E$36,MATCH(E$45,$B$37:$B$42,0),0)*$C345*1.1/OFFSET($F$36,MATCH(E$45,$B$37:$B$42,0),0) -> 300000 | F345: =OFFSET($B$36,MATCH(F$45,$B$37:$B$42,0),1)*$B345+OFFSET($B$36,MATCH(F$45,$B$37:$B$42,0),2)*MIN($B345,7)+OFFSET($E$36,MATCH(F$45,$B$37:$B$42,0),0)*$C345*1.1/OFFSET($F$36,MATCH(F$45,$B$37:$B$42,0),0) -> 1277 | G345: =OFFSET($B$36,MATCH(G$45,$B$37:$B$42,0),1)*$B345+OFFSET($B$36,MATCH(G$45,$B$37:$B$42,0),2)*MIN($B345,7)+OFFSET($E$36,MATCH(G$45,$B$37:$B$42,0),0)*$C345*1.1/OFFSET($F$36,MATCH(G$45,$B$37:$B$42,0),0) -> 0 | H345: =OFFSET($B$36,MATCH(H$45,$B$37:$B$42,0),1)*$B345+OFFSET($B$36,MATCH(H$45,$B$37:$B$42,0),2)*MIN($B345,7)+OFFSET($E$36,MATCH(H$45,$B$37:$B$42,0),0)*$C345*1.1/OFFSET($F$36,MATCH(H$45,$B$37:$B$42,0),0) -> 0 | I345: =OFFSET($B$36,MATCH(I$45,$B$37:$B$42,0),1)*$B345+OFFSET($B$36,MATCH(I$45,$B$37:$B$42,0),2)*MIN($B345,7)+OFFSET($E$36,MATCH(I$45,$B$37:$B$42,0),0)*$C345*1.1/OFFSET($F$36,MATCH(I$45,$B$37:$B$42,0),0) -> 143400 | J345: =OFFSET(梦灵养成!$Y$29,MATCH(D345,梦灵养成!$C$30:$C$629,1),0) -> 104400 | K345: =E345*0.07 -> 21000 | L345: =OFFSET(洗练性价比!$N$52,MATCH(F345*60,洗练性价比!$C$53:$C$2052,1),0) -> 4680

Sheet 梦灵养成
B2: 参数
B3: 每周兑换个数 | C3: 5
L7: #当没有满图鉴基本概率低，满图鉴后产的多
B8: 来源 | C8: 阶段节点 | D8: 核心奖励 | E8: 梦灵品质 | F8: 梦灵倍率 | G8: 梦灵系数 | H8: 升阶系数 | I8: 主C | K8: 招募等级 | L8: 蓝卡 | M8: 紫卡 | N8: 橙卡 | O8: 红卡 | P8: 升级经验 | Q8: 升级经验2 | R8: 列1
B9: 星铸 | C9: 0 | D9: 寒冰射手 | E9: 1 | F9: 1 | G9: 0.04 | H9: 1 | I9: =D9 -> 寒冰射手 | K9: 1 | L9: 0.4 | M9: 0.1 | P9: 450 | Q9: =SUM($P$9:P9) -> 450
B10: 星铸 | C10: 0 | D10: 炽焰巫师 | E10: 1 | F10: 1 | G10: 0.04 | H10: 1 | I10: =I9 -> 寒冰射手 | K10: 2 | L10: 0.355 | M10: 0.12 | N10: 0.025 | P10: 909 | Q10: =SUM($P$9:P10) -> 1359
B11: 星铸 | C11: 0 | D11: 吟游诗人 | E11: 1 | F11: 1 | G11: 0.04 | H11: 1 | I11: =I10 -> 寒冰射手 | K11: 3 | L11: 0.31 | M11: 0.14 | N11: 0.05 | P11: 1818 | Q11: =SUM($P$9:P11) -> 3177
B12: 星铸 | C12: 10 | D12: 摇滚巨石 | E12: 2 | F12: 1.15 | G12: 0.05 | H12: 2 | I12: =D12 -> 摇滚巨石 | K12: 4 | L12: 0.26422632 | M12: 0.16 | N12: 0.06 | O12: 0.015773675 | P12: 2727 | Q12: =SUM($P$9:P12) -> 5904
B13: 星铸 | C13: 40 | D13: 泥巴少女 | E13: 2 | F13: 1.15 | G13: 0.05 | H13: 2 | I13: =D13 -> 泥巴少女 | K13: 5 | L13: 0.21694207 | M13: 0.18 | N13: 0.08 | O13: 0.023057933 | P13: 3636 | Q13: =SUM($P$9:P13) -> 9540
B14: 星铸 | C14: 80 | D14: 雷震子 | E14: 2 | F14: 1.15 | G14: 0.05 | H14: 2 | I14: =D14 -> 雷震子 | K14: 6 | L14: 0.1685022 | M14: 0.2 | N14: 0.1 | O14: 0.031497799 | P14: 4545 | Q14: =SUM($P$9:P14) -> 14085
B15: 星铸 | C15: 150 | D15: 忍者鲨手 | E15: 2 | F15: 1.15 | G15: 0.05 | H15: 2 | I15: =I14 -> 雷震子 | L15: 0.1685022 | M15: 0.2 | N15: 0.1 | O15: 0.031497799 | P15: 999999 | Q15: 9999999
B16: 星铸 | C16: 200 | D16: 甜心护士 | E16: 2 | F16: 1.15 | G16: 0.05 | H16: 2 | I16: =I15 -> 雷震子
B17: 星铸 | C17: 280 | D17: 路飞 | E17: 2 | F17: 1.15 | G17: 0.05 | H17: 3 | I17: =I16 -> 雷震子
B18: 星铸 | C18: =(351+431)/2 -> 391 | D18: 镭射眼 | E18: 3 | F18: 1.35 | G18: 0.06 | H18: 4 | I18: =D18 -> 镭射眼
B19: 轮巡 | C19: 699 | D19: 东方不败 | E19: 3 | F19: 1.35 | G19: 0.06 | H19: 4 | I19: =I18 -> 镭射眼 | L19: 1 | M19: 5 | N19: 10 | O19: 15 | P19: 20 | Q19: 25 | R19: 30
B20: 星铸 | C20: 600 | D20: 亚瑟 | E20: 3 | F20: 1.35 | G20: 0.06 | H20: 4 | I20: =I19 -> 镭射眼 | K20: 1 | L20: 1 | M20: 1 | N20: 1.1 | O20: 1.98 | P20: 2.2 | Q20: 2.64 | R20: 2.88
B21: 轮巡 | C21: 995 | D21: 唐小僧 | E21: 3 | F21: 1.35 | G21: 0.06 | H21: 4 | I21: =I20 -> 镭射眼 | K21: 2 | L21: 1.15 | M21: 1.15 | N21: 1.39 | O21: 1.95 | P21: 2.36 | Q21: 3.3 | R21: 3.63
B22: 星铸 | C22: 1450 | D22: 蜘蛛女王 | E22: 3 | F22: 1.35 | G22: 0.06 | H22: 5 | I22: =D22 -> 蜘蛛女王 | K22: 3 | L22: 1.15 | M22: 1.15 | N22: 1.61 | O22: 1.95 | P22: 2.73 | Q22: 3.3 | R22: 3.63
B23: 星铸 | C23: 1989.1501 | D23: 神灯王子 | E23: 3 | F23: 1.35 | G23: 0.06 | H23: 5 | I23: =D22 -> 蜘蛛女王 | K23: 4 | L23: 1.35 | M23: 1.35 | N23: 1.76 | O23: 3.16 | P23: 3.79 | Q23: 5.05 | R23: 7.28
B24: 星铸 | C24: 2201 | D24: 关羽 | E24: 3 | F24: 1.35 | G24: 0.06 | H24: 6 | I24: =I23 -> 蜘蛛女王 | K24: 5 | L24: 2.025 | M24: 2.025 | N24: 2.43 | O24: 4.38 | P24: 5.685 | Q24: 7.575 | R24: 10.92
B25: 轮巡 | C25: 3150 | D25: 神算诸葛 | E25: 4 | F25: 1.6 | G25: 0.1 | H25: 7 | I25: =D25 -> 神算诸葛 | K25: 6 | L25: 2.025 | M25: 2.025 | N25: 3.645 | O25: 4.38 | P25: 5.685 | Q25: 8.535 | R25: 10.92
B26: 星铸 | C26: 3842.6763 | D26: 我爱沙 | E26: 4 | F26: 1.6 | G26: 0.1 | H26: 7 | I26: =D25 -> 神算诸葛 | K26: 7 | L26: 2.025 | M26: 2.025 | N26: 3.645 | O26: 4.38 | P26: 5.685 | Q26: 8.535 | R26: 10.92
B27: 星铸 | C27: 4550 | D27: 后羿 | E27: 4 | F27: 1.6 | G27: 0.1 | H27: 7 | I27: =I26 -> 神算诸葛
B29: 天数 | C29: 抽数 | D29: 寒冰射手 | E29: 炽焰巫师 | F29: 吟游诗人 | G29: 摇滚巨石 | H29: 泥巴少女 | I29: 雷震子 | J29: 忍者鲨手 | K29: 甜心护士 | L29: 路飞 | M29: 镭射眼 | N29: 东方不败 | O29: 亚瑟 | P29: 蜘蛛女王 | Q29: 唐小僧 | R29: 神灯王子 | S29: 关羽 | T29: 后羿 | U29: 海拉 | V29: 神算诸葛 | W29: 强度系数 | X29: 主C角色 | Y29: 性价比 | Z29: 升阶系数
B30: 1 | C30: 100 | D30: =IFERROR(MATCH(D635*10,OFFSET($AP$635:$AP$734,0,D$631),1),0) -> 9 | E30: =IFERROR(MATCH(E635*10,OFFSET($AP$635:$AP$734,0,E$631),1),0) -> 9 | F30: =IFERROR(MATCH(F635*10,OFFSET($AP$635:$AP$734,0,F$631),1),0) -> 9 | G30: =IFERROR(MATCH(G635*10,OFFSET($AP$635:$AP$734,0,G$631),1),0) -> 6 | H30: =IFERROR(MATCH(H635*10,OFFSET($AP$635:$AP$734,0,H$631),1),0) -> 6 | I30: =IFERROR(MATCH(I635*10,OFFSET($AP$635:$AP$734,0,I$631),1),0) -> 6 | J30: =IFERROR(MATCH(J635*10,OFFSET($AP$635:$AP$734,0,J$631),1),0) -> 0 | K30: =IFERROR(MATCH(K635*10,OFFSET($AP$635:$AP$734,0,K$631),1),0) -> 0 | ... V30: =IFERROR(MATCH(V635*10,OFFSET($AP$635:$AP$734,0,V$631),1),0) -> 0 | W30: =OFFSET($K$19,_xlfn.XLOOKUP(X30,$D$9:$D$28,$H$9:$H$28),MATCH(OFFSET($C$29,B30,MATCH(X30,$D$29:$V$29,0)),$L$19:$R$19,1))*(1+(OFFSET($C$29,B30,MATCH(X30,$D$29:$V$29,0))-1)*_xlfn.XLOOKUP(X30,梦灵养成!$D$9:$D$28,梦灵养成!$G$9:$G$28)) -> 1.4375 | X30: =OFFSET($I$8,MATCH(C30,$C$9:$C$27,1),0) -> 雷震子 | Y30: =MAX((OFFSET($C$29,MATCH(W30*1.07,$W$30:$W$629,1)+1,0)-C30)*18,0) -> 5400 | Z30: =_xlfn.XLOOKUP(X30,$D$9:$D$27,$G$9:$G$27)*(OFFSET($B30,0,MATCH($X30,$D$29:$V$29,0)+1)-1)+1 -> 1.25
B31: 2 | C31: =C30+100 -> 200 | D31: =IFERROR(MATCH(D636*10,OFFSET($AP$635:$AP$734,0,D$631),1),0) -> 11 | E31: =IFERROR(MATCH(E636*10,OFFSET($AP$635:$AP$734,0,E$631),1),0) -> 11 | F31: =IFERROR(MATCH(F636*10,OFFSET($AP$635:$AP$734,0,F$631),1),0) -> 11 | G31: =IFERROR(MATCH(G636*10,OFFSET($AP$635:$AP$734,0,G$631),1),0) -> 6 | H31: =IFERROR(MATCH(H636*10,OFFSET($AP$635:$AP$734,0,H$631),1),0) -> 6 | I31: =IFERROR(MATCH(I636*10,OFFSET($AP$635:$AP$734,0,I$631),1),0) -> 6 | J31: =IFERROR(MATCH(J636*10,OFFSET($AP$635:$AP$734,0,J$631),1),0) -> 5 | K31: =IFERROR(MATCH(K636*10,OFFSET($AP$635:$AP$734,0,K$631),1),0) -> 0 | ... V31: =IFERROR(MATCH(V636*10,OFFSET($AP$635:$AP$734,0,V$631),1),0) -> 0 | W31: =OFFSET($K$19,_xlfn.XLOOKUP(X31,$D$9:$D$28,$H$9:$H$28),MATCH(OFFSET($C$29,B31,MATCH(X31,$D$29:$V$29,0)),$L$19:$R$19,1))*(1+(OFFSET($C$29,B31,MATCH(X31,$D$29:$V$29,0))-1)*_xlfn.XLOOKUP(X31,梦灵养成!$D$9:$D$28,梦灵养成!$G$9:$G$28)) -> 1.4375 | X31: =OFFSET($I$8,MATCH(C31,$C$9:$C$27,1),0) -> 雷震子 | Y31: =MAX((OFFSET($C$29,MATCH(W31*1.07,$W$30:$W$629,1)+1,0)-C31)*18,0) -> 3600 | Z31: =_xlfn.XLOOKUP(X31,$D$9:$D$27,$G$9:$G$27)*(OFFSET($B31,0,MATCH($X31,$D$29:$V$29,0)+1)-1)+1 -> 1.25
B32: 3 | C32: =C31+100 -> 300 | D32: =IFERROR(MATCH(D637*10,OFFSET($AP$635:$AP$734,0,D$631),1),0) -> 14 | E32: =IFERROR(MATCH(E637*10,OFFSET($AP$635:$AP$734,0,E$631),1),0) -> 14 | F32: =IFERROR(MATCH(F637*10,OFFSET($AP$635:$AP$734,0,F$631),1),0) -> 14 | G32: =IFERROR(MATCH(G637*10,OFFSET($AP$635:$AP$734,0,G$631),1),0) -> 7 | H32: =IFERROR(MATCH(H637*10,OFFSET($AP$635:$AP$734,0,H$631),1),0) -> 7 | I32: =IFERROR(MATCH(I637*10,OFFSET($AP$635:$AP$734,0,I$631),1),0) -> 7 | J32: =IFERROR(MATCH(J637*10,OFFSET($AP$635:$AP$734,0,J$631),1),0) -> 6 | K32: =IFERROR(MATCH(K637*10,OFFSET($AP$635:$AP$734,0,K$631),1),0) -> 5 | ... V32: =IFERROR(MATCH(V637*10,OFFSET($AP$635:$AP$734,0,V$631),1),0) -> 0 | W32: =OFFSET($K$19,_xlfn.XLOOKUP(X32,$D$9:$D$28,$H$9:$H$28),MATCH(OFFSET($C$29,B32,MATCH(X32,$D$29:$V$29,0)),$L$19:$R$19,1))*(1+(OFFSET($C$29,B32,MATCH(X32,$D$29:$V$29,0))-1)*_xlfn.XLOOKUP(X32,梦灵养成!$D$9:$D$28,梦灵养成!$G$9:$G$28)) -> 1.495 | X32: =OFFSET($I$8,MATCH(C32,$C$9:$C$27,1),0) -> 雷震子 | Y32: =MAX((OFFSET($C$29,MATCH(W32*1.07,$W$30:$W$629,1)+1,0)-C32)*18,0) -> 1800 | Z32: =_xlfn.XLOOKUP(X32,$D$9:$D$27,$G$9:$G$27)*(OFFSET($B32,0,MATCH($X32,$D$29:$V$29,0)+1)-1)+1 -> 1.3
B33: 4 | C33: =C32+100 -> 400 | D33: =IFERROR(MATCH(D638*10,OFFSET($AP$635:$AP$734,0,D$631),1),0) -> 15 | E33: =IFERROR(MATCH(E638*10,OFFSET($AP$635:$AP$734,0,E$631),1),0) -> 15 | F33: =IFERROR(MATCH(F638*10,OFFSET($AP$635:$AP$734,0,F$631),1),0) -> 15 | G33: =IFERROR(MATCH(G638*10,OFFSET($AP$635:$AP$734,0,G$631),1),0) -> 8 | H33: =IFERROR(MATCH(H638*10,OFFSET($AP$635:$AP$734,0,H$631),1),0) -> 8 | I33: =IFERROR(MATCH(I638*10,OFFSET($AP$635:$AP$734,0,I$631),1),0) -> 8 | J33: =IFERROR(MATCH(J638*10,OFFSET($AP$635:$AP$734,0,J$631),1),0) -> 6 | K33: =IFERROR(MATCH(K638*10,OFFSET($AP$635:$AP$734,0,K$631),1),0) -> 6 | ... V33: =IFERROR(MATCH(V638*10,OFFSET($AP$635:$AP$734,0,V$631),1),0) -> 0 | W33: =OFFSET($K$19,_xlfn.XLOOKUP(X33,$D$9:$D$28,$H$9:$H$28),MATCH(OFFSET($C$29,B33,MATCH(X33,$D$29:$V$29,0)),$L$19:$R$19,1))*(1+(OFFSET($C$29,B33,MATCH(X33,$D$29:$V$29,0))-1)*_xlfn.XLOOKUP(X33,梦灵养成!$D$9:$D$28,梦灵养成!$G$9:$G$28)) -> 1.674 | X33: =OFFSET($I$8,MATCH(C33,$C$9:$C$27,1),0) -> 镭射眼 | Y33: =MAX((OFFSET($C$29,MATCH(W33*1.07,$W$30:$W$629,1)+1,0)-C33)*18,0) -> 9000 | Z33: =_xlfn.XLOOKUP(X33,$D$9:$D$27,$G$9:$G$27)*(OFFSET($B33,0,MATCH($X33,$D$29:$V$29,0)+1)-1)+1 -> 1.24
B34: 5 | C34: =C33+100 -> 500 | D34: =IFERROR(MATCH(D639*10,OFFSET($AP$635:$AP$734,0,D$631),1),0) -> 17 | E34: =IFERROR(MATCH(E639*10,OFFSET($AP$635:$AP$734,0,E$631),1),0) -> 17 | F34: =IFERROR(MATCH(F639*10,OFFSET($AP$635:$AP$734,0,F$631),1),0) -> 17 | G34: =IFERROR(MATCH(G639*10,OFFSET($AP$635:$AP$734,0,G$631),1),0) -> 8 | H34: =IFERROR(MATCH(H639*10,OFFSET($AP$635:$AP$734,0,H$631),1),0) -> 8 | I34: =IFERROR(MATCH(I639*10,OFFSET($AP$635:$AP$734,0,I$631),1),0) -> 8 | J34: =IFERROR(MATCH(J639*10,OFFSET($AP$635:$AP$734,0,J$631),1),0) -> 7 | K34: =IFERROR(MATCH(K639*10,OFFSET($AP$635:$AP$734,0,K$631),1),0) -> 6 | ... V34: =IFERROR(MATCH(V639*10,OFFSET($AP$635:$AP$734,0,V$631),1),0) -> 0 | W34: =OFFSET($K$19,_xlfn.XLOOKUP(X34,$D$9:$D$28,$H$9:$H$28),MATCH(OFFSET($C$29,B34,MATCH(X34,$D$29:$V$29,0)),$L$19:$R$19,1))*(1+(OFFSET($C$29,B34,MATCH(X34,$D$29:$V$29,0))-1)*_xlfn.XLOOKUP(X34,梦灵养成!$D$9:$D$28,梦灵养成!$G$9:$G$28)) -> 1.674 | X34: =OFFSET($I$8,MATCH(C34,$C$9:$C$27,1),0) -> 镭射眼 | Y34: =MAX((OFFSET($C$29,MATCH(W34*1.07,$W$30:$W$629,1)+1,0)-C34)*18,0) -> 7200 | Z34: =_xlfn.XLOOKUP(X34,$D$9:$D$27,$G$9:$G$27)*(OFFSET($B34,0,MATCH($X34,$D$29:$V$29,0)+1)-1)+1 -> 1.24
B35: 6 | C35: =C34+100 -> 600 | D35: =IFERROR(MATCH(D640*10,OFFSET($AP$635:$AP$734,0,D$631),1),0) -> 18 | E35: =IFERROR(MATCH(E640*10,OFFSET($AP$635:$AP$734,0,E$631),1),0) -> 18 | F35: =IFERROR(MATCH(F640*10,OFFSET($AP$635:$AP$734,0,F$631),1),0) -> 18 | G35: =IFERROR(MATCH(G640*10,OFFSET($AP$635:$AP$734,0,G$631),1),0) -> 9 | H35: =IFERROR(MATCH(H640*10,OFFSET($AP$635:$AP$734,0,H$631),1),0) -> 9 | I35: =IFERROR(MATCH(I640*10,OFFSET($AP$635:$AP$734,0,I$631),1),0) -> 9 | J35: =IFERROR(MATCH(J640*10,OFFSET($AP$635:$AP$734,0,J$631),1),0) -> 8 | K35: =IFERROR(MATCH(K640*10,OFFSET($AP$635:$AP$734,0,K$631),1),0) -> 7 | ... V35: =IFERROR(MATCH(V640*10,OFFSET($AP$635:$AP$734,0,V$631),1),0) -> 0 | W35: =OFFSET($K$19,_xlfn.XLOOKUP(X35,$D$9:$D$28,$H$9:$H$28),MATCH(OFFSET($C$29,B35,MATCH(X35,$D$29:$V$29,0)),$L$19:$R$19,1))*(1+(OFFSET($C$29,B35,MATCH(X35,$D$29:$V$29,0))-1)*_xlfn.XLOOKUP(X35,梦灵养成!$D$9:$D$28,梦灵养成!$G$9:$G$28)) -> 1.755 | X35: =OFFSET($I$8,MATCH(C35,$C$9:$C$27,1),0) -> 镭射眼 | Y35: =MAX((OFFSET($C$29,MATCH(W35*1.07,$W$30:$W$629,1)+1,0)-C35)*18,0) -> 14400 | Z35: =_xlfn.XLOOKUP(X35,$D$9:$D$27,$G$9:$G$27)*(OFFSET($B35,0,MATCH($X35,$D$29:$V$29,0)+1)-1)+1 -> 1.3
B36: 7 | C36: =C35+100 -> 700 | D36: =IFERROR(MATCH(D641*10,OFFSET($AP$635:$AP$734,0,D$631),1),0) -> 19 | E36: =IFERROR(MATCH(E641*10,OFFSET($AP$635:$AP$734,0,E$631),1),0) -> 19 | F36: =IFERROR(MATCH(F641*10,OFFSET($AP$635:$AP$734,0,F$631),1),0) -> 19 | G36: =IFERROR(MATCH(G641*10,OFFSET($AP$635:$AP$734,0,G$631),1),0) -> 10 | H36: =IFERROR(MATCH(H641*10,OFFSET($AP$635:$AP$734,0,H$631),1),0) -> 10 | I36: =IFERROR(MATCH(I641*10,OFFSET($AP$635:$AP$734,0,I$631),1),0) -> 10 | J36: =IFERROR(MATCH(J641*10,OFFSET($AP$635:$AP$734,0,J$631),1),0) -> 8 | K36: =IFERROR(MATCH(K641*10,OFFSET($AP$635:$AP$734,0,K$631),1),0) -> 8 | ... V36: =IFERROR(MATCH(V641*10,OFFSET($AP$635:$AP$734,0,V$631),1),0) -> 0 | W36: =OFFSET($K$19,_xlfn.XLOOKUP(X36,$D$9:$D$28,$H$9:$H$28),MATCH(OFFSET($C$29,B36,MATCH(X36,$D$29:$V$29,0)),$L$19:$R$19,1))*(1+(OFFSET($C$29,B36,MATCH(X36,$D$29:$V$29,0))-1)*_xlfn.XLOOKUP(X36,梦灵养成!$D$9:$D$28,梦灵养成!$G$9:$G$28)) -> 1.755 | X36: =OFFSET($I$8,MATCH(C36,$C$9:$C$27,1),0) -> 镭射眼 | Y36: =MAX((OFFSET($C$29,MATCH(W36*1.07,$W$30:$W$629,1)+1,0)-C36)*18,0) -> 12600 | Z36: =_xlfn.XLOOKUP(X36,$D$9:$D$27,$G$9:$G$27)*(OFFSET($B36,0,MATCH($X36,$D$29:$V$29,0)+1)-1)+1 -> 1.3
B37: 8 | C37: =C36+100 -> 800 | D37: =IFERROR(MATCH(D642*10,OFFSET($AP$635:$AP$734,0,D$631),1),0) -> 20 | E37: =IFERROR(MATCH(E642*10,OFFSET($AP$635:$AP$734,0,E$631),1),0) -> 20 | F37: =IFERROR(MATCH(F642*10,OFFSET($AP$635:$AP$734,0,F$631),1),0) -> 20 | G37: =IFERROR(MATCH(G642*10,OFFSET($AP$635:$AP$734,0,G$631),1),0) -> 10 | H37: =IFERROR(MATCH(H642*10,OFFSET($AP$635:$AP$734,0,H$631),1),0) -> 10 | I37: =IFERROR(MATCH(I642*10,OFFSET($AP$635:$AP$734,0,I$631),1),0) -> 10 | J37: =IFERROR(MATCH(J642*10,OFFSET($AP$635:$AP$734,0,J$631),1),0) -> 9 | K37: =IFERROR(MATCH(K642*10,OFFSET($AP$635:$AP$734,0,K$631),1),0) -> 8 | ... V37: =IFERROR(MATCH(V642*10,OFFSET($AP$635:$AP$734,0,V$631),1),0) -> 0 | W37: =OFFSET($K$19,_xlfn.XLOOKUP(X37,$D$9:$D$28,$H$9:$H$28),MATCH(OFFSET($C$29,B37,MATCH(X37,$D$29:$V$29,0)),$L$19:$R$19,1))*(1+(OFFSET($C$29,B37,MATCH(X37,$D$29:$V$29,0))-1)*_xlfn.XLOOKUP(X37,梦灵养成!$D$9:$D$28,梦灵养成!$G$9:$G$28)) -> 1.755 | X37: =OFFSET($I$8,MATCH(C37,$C$9:$C$27,1),0) -> 镭射眼 | Y37: =MAX((OFFSET($C$29,MATCH(W37*1.07,$W$30:$W$629,1)+1,0)-C37)*18,0) -> 10800 | Z37: =_xlfn.XLOOKUP(X37,$D$9:$D$27,$G$9:$G$27)*(OFFSET($B37,0,MATCH($X37,$D$29:$V$29,0)+1)-1)+1 -> 1.3
B38: 9 | C38: =C37+100 -> 900 | D38: =IFERROR(MATCH(D643*10,OFFSET($AP$635:$AP$734,0,D$631),1),0) -> 21 | E38: =IFERROR(MATCH(E643*10,OFFSET($AP$635:$AP$734,0,E$631),1),0) -> 21 | F38: =IFERROR(MATCH(F643*10,OFFSET($AP$635:$AP$734,0,F$631),1),0) -> 21 | G38: =IFERROR(MATCH(G643*10,OFFSET($AP$635:$AP$734,0,G$631),1),0) -> 10 | H38: =IFERROR(MATCH(H643*10,OFFSET($AP$635:$AP$734,0,H$631),1),0) -> 10 | I38: =IFERROR(MATCH(I643*10,OFFSET($AP$635:$AP$734,0,I$631),1),0) -> 10 | J38: =IFERROR(MATCH(J643*10,OFFSET($AP$635:$AP$734,0,J$631),1),0) -> 10 | K38: =IFERROR(MATCH(K643*10,OFFSET($AP$635:$AP$734,0,K$631),1),0) -> 9 | ... V38: =IFERROR(MATCH(V643*10,OFFSET($AP$635:$AP$734,0,V$631),1),0) -> 0 | W38: =OFFSET($K$19,_xlfn.XLOOKUP(X38,$D$9:$D$28,$H$9:$H$28),MATCH(OFFSET($C$29,B38,MATCH(X38,$D$29:$V$29,0)),$L$19:$R$19,1))*(1+(OFFSET($C$29,B38,MATCH(X38,$D$29:$V$29,0))-1)*_xlfn.XLOOKUP(X38,梦灵养成!$D$9:$D$28,梦灵养成!$G$9:$G$28)) -> 1.836 | X38: =OFFSET($I$8,MATCH(C38,$C$9:$C$27,1),0) -> 镭射眼 | Y38: =MAX((OFFSET($C$29,MATCH(W38*1.07,$W$30:$W$629,1)+1,0)-C38)*18,0) -> 10800 | Z38: =_xlfn.XLOOKUP(X38,$D$9:$D$27,$G$9:$G$27)*(OFFSET($B38,0,MATCH($X38,$D$29:$V$29,0)+1)-1)+1 -> 1.36
B39: 10 | C39: =C38+100 -> 1000 | D39: =IFERROR(MATCH(D644*10,OFFSET($AP$635:$AP$734,0,D$631),1),0) -> 22 | E39: =IFERROR(MATCH(E644*10,OFFSET($AP$635:$AP$734,0,E$631),1),0) -> 22 | F39: =IFERROR(MATCH(F644*10,OFFSET($AP$635:$AP$734,0,F$631),1),0) -> 22 | G39: =IFERROR(MATCH(G644*10,OFFSET($AP$635:$AP$734,0,G$631),1),0) -> 11 | H39: =IFERROR(MATCH(H644*10,OFFSET($AP$635:$AP$734,0,H$631),1),0) -> 11 | I39: =IFERROR(MATCH(I644*10,OFFSET($AP$635:$AP$734,0,I$631),1),0) -> 11 | J39: =IFERROR(MATCH(J644*10,OFFSET($AP$635:$AP$734,0,J$631),1),0) -> 10 | K39: =IFERROR(MATCH(K644*10,OFFSET($AP$635:$AP$734,0,K$631),1),0) -> 10 | ... V39: =IFERROR(MATCH(V644*10,OFFSET($AP$635:$AP$734,0,V$631),1),0) -> 0 | W39: =OFFSET($K$19,_xlfn.XLOOKUP(X39,$D$9:$D$28,$H$9:$H$28),MATCH(OFFSET($C$29,B39,MATCH(X39,$D$29:$V$29,0)),$L$19:$R$19,1))*(1+(OFFSET($C$29,B39,MATCH(X39,$D$29:$V$29,0))-1)*_xlfn.XLOOKUP(X39,梦灵养成!$D$9:$D$28,梦灵养成!$G$9:$G$28)) -> 1.836 | X39: =OFFSET($I$8,MATCH(C39,$C$9:$C$27,1),0) -> 镭射眼 | Y39: =MAX((OFFSET($C$29,MATCH(W39*1.07,$W$30:$W$629,1)+1,0)-C39)*18,0) -> 9000 | Z39: =_xlfn.XLOOKUP(X39,$D$9:$D$27,$G$9:$G$27)*(OFFSET($B39,0,MATCH($X39,$D$29:$V$29,0)+1)-1)+1 -> 1.36
B40: 11 | C40: =C39+100 -> 1100 | D40: =IFERROR(MATCH(D645*10,OFFSET($AP$635:$AP$734,0,D$631),1),0) -> 23 | E40: =IFERROR(MATCH(E645*10,OFFSET($AP$635:$AP$734,0,E$631),1),0) -> 23 | F40: =IFERROR(MATCH(F645*10,OFFSET($AP$635:$AP$734,0,F$631),1),0) -> 23 | G40: =IFERROR(MATCH(G645*10,OFFSET($AP$635:$AP$734,0,G$631),1),0) -> 11 | H40: =IFERROR(MATCH(H645*10,OFFSET($AP$635:$AP$734,0,H$631),1),0) -> 11 | I40: =IFERROR(MATCH(I645*10,OFFSET($AP$635:$AP$734,0,I$631),1),0) -> 11 | J40: =IFERROR(MATCH(J645*10,OFFSET($AP$635:$AP$734,0,J$631),1),0) -> 10 | K40: =IFERROR(MATCH(K645*10,OFFSET($AP$635:$AP$734,0,K$631),1),0) -> 10 | ... V40: =IFERROR(MATCH(V645*10,OFFSET($AP$635:$AP$734,0,V$631),1),0) -> 0 | W40: =OFFSET($K$19,_xlfn.XLOOKUP(X40,$D$9:$D$28,$H$9:$H$28),MATCH(OFFSET($C$29,B40,MATCH(X40,$D$29:$V$29,0)),$L$19:$R$19,1))*(1+(OFFSET($C$29,B40,MATCH(X40,$D$29:$V$29,0))-1)*_xlfn.XLOOKUP(X40,梦灵养成!$D$9:$D$28,梦灵养成!$G$9:$G$28)) -> 1.836 | X40: =OFFSET($I$8,MATCH(C40,$C$9:$C$27,1),0) -> 镭射眼 | Y40: =MAX((OFFSET($C$29,MATCH(W40*1.07,$W$30:$W$629,1)+1,0)-C40)*18,0) -> 7200 | Z40: =_xlfn.XLOOKUP(X40,$D$9:$D$27,$G$9:$G$27)*(OFFSET($B40,0,MATCH($X40,$D$29:$V$29,0)+1)-1)+1 -> 1.36
B41: 12 | C41: =C40+100 -> 1200 | D41: =IFERROR(MATCH(D646*10,OFFSET($AP$635:$AP$734,0,D$631),1),0) -> 24 | E41: =IFERROR(MATCH(E646*10,OFFSET($AP$635:$AP$734,0,E$631),1),0) -> 24 | F41: =IFERROR(MATCH(F646*10,OFFSET($AP$635:$AP$734,0,F$631),1),0) -> 24 | G41: =IFERROR(MATCH(G646*10,OFFSET($AP$635:$AP$734,0,G$631),1),0) -> 11 | H41: =IFERROR(MATCH(H646*10,OFFSET($AP$635:$AP$734,0,H$631),1),0) -> 11 | I41: =IFERROR(MATCH(I646*10,OFFSET($AP$635:$AP$734,0,I$631),1),0) -> 11 | J41: =IFERROR(MATCH(J646*10,OFFSET($AP$635:$AP$734,0,J$631),1),0) -> 11 | K41: =IFERROR(MATCH(K646*10,OFFSET($AP$635:$AP$734,0,K$631),1),0) -> 10 | ... V41: =IFERROR(MATCH(V646*10,OFFSET($AP$635:$AP$734,0,V$631),1),0) -> 0 | W41: =OFFSET($K$19,_xlfn.XLOOKUP(X41,$D$9:$D$28,$H$9:$H$28),MATCH(OFFSET($C$29,B41,MATCH(X41,$D$29:$V$29,0)),$L$19:$R$19,1))*(1+(OFFSET($C$29,B41,MATCH(X41,$D$29:$V$29,0))-1)*_xlfn.XLOOKUP(X41,梦灵养成!$D$9:$D$28,梦灵养成!$G$9:$G$28)) -> 1.836 | X41: =OFFSET($I$8,MATCH(C41,$C$9:$C$27,1),0) -> 镭射眼 | Y41: =MAX((OFFSET($C$29,MATCH(W41*1.07,$W$30:$W$629,1)+1,0)-C41)*18,0) -> 5400 | Z41: =_xlfn.XLOOKUP(X41,$D$9:$D$27,$G$9:$G$27)*(OFFSET($B41,0,MATCH($X41,$D$29:$V$29,0)+1)-1)+1 -> 1.36
B42: 13 | C42: =C41+100 -> 1300 | D42: =IFERROR(MATCH(D647*10,OFFSET($AP$635:$AP$734,0,D$631),1),0) -> 25 | E42: =IFERROR(MATCH(E647*10,OFFSET($AP$635:$AP$734,0,E$631),1),0) -> 25 | F42: =IFERROR(MATCH(F647*10,OFFSET($AP$635:$AP$734,0,F$631),1),0) -> 25 | G42: =IFERROR(MATCH(G647*10,OFFSET($AP$635:$AP$734,0,G$631),1),0) -> 12 | H42: =IFERROR(MATCH(H647*10,OFFSET($AP$635:$AP$734,0,H$631),1),0) -> 12 | I42: =IFERROR(MATCH(I647*10,OFFSET($AP$635:$AP$734,0,I$631),1),0) -> 12 | J42: =IFERROR(MATCH(J647*10,OFFSET($AP$635:$AP$734,0,J$631),1),0) -> 11 | K42: =IFERROR(MATCH(K647*10,OFFSET($AP$635:$AP$734,0,K$631),1),0) -> 11 | ... V42: =IFERROR(MATCH(V647*10,OFFSET($AP$635:$AP$734,0,V$631),1),0) -> 0 | W42: =OFFSET($K$19,_xlfn.XLOOKUP(X42,$D$9:$D$28,$H$9:$H$28),MATCH(OFFSET($C$29,B42,MATCH(X42,$D$29:$V$29,0)),$L$19:$R$19,1))*(1+(OFFSET($C$29,B42,MATCH(X42,$D$29:$V$29,0))-1)*_xlfn.XLOOKUP(X42,梦灵养成!$D$9:$D$28,梦灵养成!$G$9:$G$28)) -> 1.836 | X42: =OFFSET($I$8,MATCH(C42,$C$9:$C$27,1),0) -> 镭射眼 | Y42: =MAX((OFFSET($C$29,MATCH(W42*1.07,$W$30:$W$629,1)+1,0)-C42)*18,0) -> 3600 | Z42: =_xlfn.XLOOKUP(X42,$D$9:$D$27,$G$9:$G$27)*(OFFSET($B42,0,MATCH($X42,$D$29:$V$29,0)+1)-1)+1 -> 1.36
... B469: 440 | C469: =C468+100 -> 44000 | D469: =IFERROR(MATCH(D1074*10,OFFSET($AP$635:$AP$734,0,D$631),1),0) -> 53 | E469: =IFERROR(MATCH(E1074*10,OFFSET($AP$635:$AP$734,0,E$631),1),0) -> 53 | F469: =IFERROR(MATCH(F1074*10,OFFSET($AP$635:$AP$734,0,F$631),1),0) -> 53 | G469: =IFERROR(MATCH(G1074*10,OFFSET($AP$635:$AP$734,0,G$631),1),0) -> 44 | H469: =IFERROR(MATCH(H1074*10,OFFSET($AP$635:$AP$734,0,H$631),1),0) -> 44 | I469: =IFERROR(MATCH(I1074*10,OFFSET($AP$635:$AP$734,0,I$631),1),0) -> 44 | J469: =IFERROR(MATCH(J1074*10,OFFSET($AP$635:$AP$734,0,J$631),1),0) -> 44 | K469: =IFERROR(MATCH(K1074*10,OFFSET($AP$635:$AP$734,0,K$631),1),0) -> 44 | ... V469: =IFERROR(MATCH(V1074*10,OFFSET($AP$635:$AP$734,0,V$631),1),0) -> 46 | W469: =OFFSET($K$19,_xlfn.XLOOKUP(X469,$D$9:$D$28,$H$9:$H$28),MATCH(OFFSET($C$29,B469,MATCH(X469,$D$29:$V$29,0)),$L$19:$R$19,1))*(1+(OFFSET($C$29,B469,MATCH(X469,$D$29:$V$29,0))-1)*_xlfn.XLOOKUP(X469,梦灵养成!$D$9:$D$28,梦灵养成!$G$9:$G$28)) -> 60.06 | X469: =OFFSET($I$8,MATCH(C469,$C$9:$C$27,1),0) -> 神算诸葛 | Y469: =MAX((OFFSET($C$29,MATCH(W469*1.07,$W$30:$W$629,1)+1,0)-C469)*18,0) -> 219600 | Z469: =_xlfn.XLOOKUP(X469,$D$9:$D$27,$G$9:$G$27)*(OFFSET($B469,0,MATCH($X469,$D$29:$V$29,0)+1)-1)+1 -> 5.5
B470: 441 | C470: =C469+100 -> 44100 | D470: =IFERROR(MATCH(D1075*10,OFFSET($AP$635:$AP$734,0,D$631),1),0) -> 53 | E470: =IFERROR(MATCH(E1075*10,OFFSET($AP$635:$AP$734,0,E$631),1),0) -> 53 | F470: =IFERROR(MATCH(F1075*10,OFFSET($AP$635:$AP$734,0,F$631),1),0) -> 53 | G470: =IFERROR(MATCH(G1075*10,OFFSET($AP$635:$AP$734,0,G$631),1),0) -> 44 | H470: =IFERROR(MATCH(H1075*10,OFFSET($AP$635:$AP$734,0,H$631),1),0) -> 44 | I470: =IFERROR(MATCH(I1075*10,OFFSET($AP$635:$AP$734,0,I$631),1),0) -> 44 | J470: =IFERROR(MATCH(J1075*10,OFFSET($AP$635:$AP$734,0,J$631),1),0) -> 44 | K470: =IFERROR(MATCH(K1075*10,OFFSET($AP$635:$AP$734,0,K$631),1),0) -> 44 | ... V470: =IFERROR(MATCH(V1075*10,OFFSET($AP$635:$AP$734,0,V$631),1),0) -> 46 | W470: =OFFSET($K$19,_xlfn.XLOOKUP(X470,$D$9:$D$28,$H$9:$H$28),MATCH(OFFSET($C$29,B470,MATCH(X470,$D$29:$V$29,0)),$L$19:$R$19,1))*(1+(OFFSET($C$29,B470,MATCH(X470,$D$29:$V$29,0))-1)*_xlfn.XLOOKUP(X470,梦灵养成!$D$9:$D$28,梦灵养成!$G$9:$G$28)) -> 60.06 | X470: =OFFSET($I$8,MATCH(C470,$C$9:$C$27,1),0) -> 神算诸葛 | Y470: =MAX(Y441:Y469) -> 246600 | Z470: =_xlfn.XLOOKUP(X470,$D$9:$D$27,$G$9:$G$27)*(OFFSET($B470,0,MATCH($X470,$D$29:$V$29,0)+1)-1)+1 -> 5.5
B471: 442 | C471: =C470+100 -> 44200 | D471: =IFERROR(MATCH(D1076*10,OFFSET($AP$635:$AP$734,0,D$631),1),0) -> 53 | E471: =IFERROR(MATCH(E1076*10,OFFSET($AP$635:$AP$734,0,E$631),1),0) -> 53 | F471: =IFERROR(MATCH(F1076*10,OFFSET($AP$635:$AP$734,0,F$631),1),0) -> 53 | G471: =IFERROR(MATCH(G1076*10,OFFSET($AP$635:$AP$734,0,G$631),1),0) -> 44 | H471: =IFERROR(MATCH(H1076*10,OFFSET($AP$635:$AP$734,0,H$631),1),0) -> 44 | I471: =IFERROR(MATCH(I1076*10,OFFSET($AP$635:$AP$734,0,I$631),1),0) -> 44 | J471: =IFERROR(MATCH(J1076*10,OFFSET($AP$635:$AP$734,0,J$631),1),0) -> 44 | K471: =IFERROR(MATCH(K1076*10,OFFSET($AP$635:$AP$734,0,K$631),1),0) -> 44 | ... V471: =IFERROR(MATCH(V1076*10,OFFSET($AP$635:$AP$734,0,V$631),1),0) -> 46 | W471: =OFFSET($K$19,_xlfn.XLOOKUP(X471,$D$9:$D$28,$H$9:$H$28),MATCH(OFFSET($C$29,B471,MATCH(X471,$D$29:$V$29,0)),$L$19:$R$19,1))*(1+(OFFSET($C$29,B471,MATCH(X471,$D$29:$V$29,0))-1)*_xlfn.XLOOKUP(X471,梦灵养成!$D$9:$D$28,梦灵养成!$G$9:$G$28)) -> 60.06 | X471: =OFFSET($I$8,MATCH(C471,$C$9:$C$27,1),0) -> 神算诸葛 | Y471: =MAX(Y442:Y470) -> 246600 | Z471: =_xlfn.XLOOKUP(X471,$D$9:$D$27,$G$9:$G$27)*(OFFSET($B471,0,MATCH($X471,$D$29:$V$29,0)+1)-1)+1 -> 5.5
...

Sheet 洗练性价比
A1: 实际概率集
K4: =1/COUNTA(C14:C20) -> 0.14285714
B5: 符文品质 | C5: 档次 | D5: 修正概率 | E5: 部位1 | F5: 部位2 | G5: 部位3 | H5: 部位4 | I5: 部位5 | J5: 部位6 | K5: 单颗定价 | L5: 洗练期望 | N5: 洗练品质 | O5: 洗练消耗
B6: 4 | C6: 1 | D6: =IF(C6="","",E6*OFFSET($E$51,0,MATCH(C6,$C$14:$C$20,0))) -> 0.31331331 | E6: =IF($B6="","",SUMIFS(符文总览!O:O,符文总览!$D:$D,$B6,符文总览!$AL:$AL,$C6)) -> 0.31331331 | F6: =IF($B6="","",SUMIFS(符文总览!N:N,符文总览!$D:$D,$B6,符文总览!$AL:$AL,$C6)) -> 0.31331331 | G6: =IF($B6="","",SUMIFS(符文总览!O:O,符文总览!$D:$D,$B6,符文总览!$AL:$AL,$C6)) -> 0.31331331 | H6: =IF($B6="","",SUMIFS(符文总览!P:P,符文总览!$D:$D,$B6,符文总览!$AL:$AL,$C6)) -> 0.31331331 | I6: =IF($B6="","",SUMIFS(符文总览!Q:Q,符文总览!$D:$D,$B6,符文总览!$AL:$AL,$C6)) -> 0.31331331 | J6: =IF($B6="","",SUMIFS(符文总览!R:R,符文总览!$D:$D,$B6,符文总览!$AL:$AL,$C6)) -> 0.31331331 | K6: =1/E6*_xlfn.XLOOKUP(B6,$N$5:$N$16,$O$5:$O$16)*K$4 -> 45.595618 | L6: {=SUMPRODUCT(K6:K12,E6:E12)} -> 85.714286
B7: 4 | C7: 2 | D7: =IF(C7="","",E7*OFFSET($E$51,0,MATCH(C7,$C$14:$C$20,0))) -> 0.31431431 | E7: =IF($B7="","",SUMIFS(符文总览!O:O,符文总览!$D:$D,$B7,符文总览!$AL:$AL,$C7)) -> 0.31431431 | F7: =IF($B7="","",SUMIFS(符文总览!N:N,符文总览!$D:$D,$B7,符文总览!$AL:$AL,$C7)) -> 0.31431431 | G7: =IF($B7="","",SUMIFS(符文总览!O:O,符文总览!$D:$D,$B7,符文总览!$AL:$AL,$C7)) -> 0.31431431 | H7: =IF($B7="","",SUMIFS(符文总览!P:P,符文总览!$D:$D,$B7,符文总览!$AL:$AL,$C7)) -> 0.31431431 | I7: =IF($B7="","",SUMIFS(符文总览!Q:Q,符文总览!$D:$D,$B7,符文总览!$AL:$AL,$C7)) -> 0.31431431 | J7: =IF($B7="","",SUMIFS(符文总览!R:R,符文总览!$D:$D,$B7,符文总览!$AL:$AL,$C7)) -> 0.31431431 | K7: =1/E7*_xlfn.XLOOKUP(B7,$N$5:$N$16,$O$5:$O$16)*K$4 -> 45.450409
B8: 4 | C8: 3 | D8: =IF(C8="","",E8*OFFSET($E$51,0,MATCH(C8,$C$14:$C$20,0))) -> 0.30317674 | E8: =IF($B8="","",SUMIFS(符文总览!O:O,符文总览!$D:$D,$B8,符文总览!$AL:$AL,$C8)) -> 0.30317674 | F8: =IF($B8="","",SUMIFS(符文总览!N:N,符文总览!$D:$D,$B8,符文总览!$AL:$AL,$C8)) -> 0.29996663 | G8: =IF($B8="","",SUMIFS(符文总览!O:O,符文总览!$D:$D,$B8,符文总览!$AL:$AL,$C8)) -> 0.30317674 | H8: =IF($B8="","",SUMIFS(符文总览!P:P,符文总览!$D:$D,$B8,符文总览!$AL:$AL,$C8)) -> 0.29996663 | I8: =IF($B8="","",SUMIFS(符文总览!Q:Q,符文总览!$D:$D,$B8,符文总览!$AL:$AL,$C8)) -> 0.29973155 | J8: =IF($B8="","",SUMIFS(符文总览!R:R,符文总览!$D:$D,$B8,符文总览!$AL:$AL,$C8)) -> 0.2966703 | K8: =1/E8*_xlfn.XLOOKUP(B8,$N$5:$N$16,$O$5:$O$16)*K$4 -> 47.120087
B9: 4 | C9: 4 | D9: =IF(C9="","",E9*OFFSET($E$51,0,MATCH(C9,$C$14:$C$20,0))) -> 0.018633634 | E9: =IF($B9="","",SUMIFS(符文总览!O:O,符文总览!$D:$D,$B9,符文总览!$AL:$AL,$C9)) -> 0.056465556 | F9: =IF($B9="","",SUMIFS(符文总览!N:N,符文总览!$D:$D,$B9,符文总览!$AL:$AL,$C9)) -> 0.040246128 | G9: =IF($B9="","",SUMIFS(符文总览!O:O,符文总览!$D:$D,$B9,符文总览!$AL:$AL,$C9)) -> 0.056465556 | H9: =IF($B9="","",SUMIFS(符文总览!P:P,符文总览!$D:$D,$B9,符文总览!$AL:$AL,$C9)) -> 0.056465556 | I9: =IF($B9="","",SUMIFS(符文总览!Q:Q,符文总览!$D:$D,$B9,符文总览!$AL:$AL,$C9)) -> 0.044976795 | J9: =IF($B9="","",SUMIFS(符文总览!R:R,符文总览!$D:$D,$B9,符文总览!$AL:$AL,$C9)) -> 0.055113937 | K9: =1/E9*_xlfn.XLOOKUP(B9,$N$5:$N$16,$O$5:$O$16)*K$4 -> 252.99873
B10: 4 | C10: 5 | D10: =IF(C10="","",E10*OFFSET($E$51,0,MATCH(C10,$C$14:$C$20,0))) -> 0.0035667852 | E10: =IF($B10="","",SUMIFS(符文总览!O:O,符文总览!$D:$D,$B10,符文总览!$AL:$AL,$C10)) -> 0.0071335704 | F10: =IF($B10="","",SUMIFS(符文总览!N:N,符文总览!$D:$D,$B10,符文总览!$AL:$AL,$C10)) -> 0.025211486 | G10: =IF($B10="","",SUMIFS(符文总览!O:O,符文总览!$D:$D,$B10,符文总览!$AL:$AL,$C10)) -> 0.0071335704 | H10: =IF($B10="","",SUMIFS(符文总览!P:P,符文总览!$D:$D,$B10,符文总览!$AL:$AL,$C10)) -> 0.010343677 | I10: =IF($B10="","",SUMIFS(符文总览!Q:Q,符文总览!$D:$D,$B10,符文总览!$AL:$AL,$C10)) -> 0.022067522 | J10: =IF($B10="","",SUMIFS(符文总览!R:R,符文总览!$D:$D,$B10,符文总览!$AL:$AL,$C10)) -> 0.013640014 | K10: =1/E10*_xlfn.XLOOKUP(B10,$N$5:$N$16,$O$5:$O$16)*K$4 -> 2002.6037
B11: 4 | C11: 6 | D11: =IF(C11="","",E11*OFFSET($E$51,0,MATCH(C11,$C$14:$C$20,0))) -> 0.0022386022 | E11: =IF($B11="","",SUMIFS(符文总览!O:O,符文总览!$D:$D,$B11,符文总览!$AL:$AL,$C11)) -> 0.0055965056 | F11: =IF($B11="","",SUMIFS(符文总览!N:N,符文总览!$D:$D,$B11,符文总览!$AL:$AL,$C11)) -> 0.0069481246 | G11: =IF($B11="","",SUMIFS(符文总览!O:O,符文总览!$D:$D,$B11,符文总览!$AL:$AL,$C11)) -> 0.0055965056 | H11: =IF($B11="","",SUMIFS(符文总览!P:P,符文总览!$D:$D,$B11,符文总览!$AL:$AL,$C11)) -> 0.0055965056 | I11: =IF($B11="","",SUMIFS(符文总览!Q:Q,符文总览!$D:$D,$B11,符文总览!$AL:$AL,$C11)) -> 0.0055965056 | J11: =IF($B11="","",SUMIFS(符文总览!R:R,符文总览!$D:$D,$B11,符文总览!$AL:$AL,$C11)) -> 0.0069481246 | K11: =1/E11*_xlfn.XLOOKUP(B11,$N$5:$N$16,$O$5:$O$16)*K$4 -> 2552.6132
N13: 4 | O13: =80*5/4 -> 100
B14: 5 | C14: 1 | D14: =IF(C14="","",E14*OFFSET($E$51,0,MATCH(C14,$C$14:$C$20,0))) -> 0.306 | E14: =IF($B14="","",SUMIFS(符文总览!O:O,符文总览!$D:$D,$B14,符文总览!$AL:$AL,$C14)) -> 0.306 | F14: =IF($B14="","",SUMIFS(符文总览!N:N,符文总览!$D:$D,$B14,符文总览!$AL:$AL,$C14)) -> 0.306 | G14: =IF($B14="","",SUMIFS(符文总览!O:O,符文总览!$D:$D,$B14,符文总览!$AL:$AL,$C14)) -> 0.306 | H14: =IF($B14="","",SUMIFS(符文总览!P:P,符文总览!$D:$D,$B14,符文总览!$AL:$AL,$C14)) -> 0.306 | I14: =IF($B14="","",SUMIFS(符文总览!Q:Q,符文总览!$D:$D,$B14,符文总览!$AL:$AL,$C14)) -> 0.306 | J14: =IF($B14="","",SUMIFS(符文总览!R:R,符文总览!$D:$D,$B14,符文总览!$AL:$AL,$C14)) -> 0.306 | K14: =1/E14*_xlfn.XLOOKUP(B14,$N$5:$N$16,$O$5:$O$16)*K$4 -> 168.06723 | L14: {=SUMPRODUCT(K14:K20,E14:E20)} -> 360 | N14: 5 | O14: =60*6 -> 360
B15: 5 | C15: 2 | D15: =IF(C15="","",E15*OFFSET($E$51,0,MATCH(C15,$C$14:$C$20,0))) -> 0.306 | E15: =IF($B15="","",SUMIFS(符文总览!O:O,符文总览!$D:$D,$B15,符文总览!$AL:$AL,$C15)) -> 0.306 | F15: =IF($B15="","",SUMIFS(符文总览!N:N,符文总览!$D:$D,$B15,符文总览!$AL:$AL,$C15)) -> 0.306 | G15: =IF($B15="","",SUMIFS(符文总览!O:O,符文总览!$D:$D,$B15,符文总览!$AL:$AL,$C15)) -> 0.306 | H15: =IF($B15="","",SUMIFS(符文总览!P:P,符文总览!$D:$D,$B15,符文总览!$AL:$AL,$C15)) -> 0.306 | I15: =IF($B15="","",SUMIFS(符文总览!Q:Q,符文总览!$D:$D,$B15,符文总览!$AL:$AL,$C15)) -> 0.306 | J15: =IF($B15="","",SUMIFS(符文总览!R:R,符文总览!$D:$D,$B15,符文总览!$AL:$AL,$C15)) -> 0.306 | K15: =1/E15*_xlfn.XLOOKUP(B15,$N$5:$N$16,$O$5:$O$16)*K$4 -> 168.06723 | N15: 6 | O15: =12*60 -> 720
B16: 5 | C16: 3 | D16: =IF(C16="","",E16*OFFSET($E$51,0,MATCH(C16,$C$14:$C$20,0))) -> 0.33385714 | E16: =IF($B16="","",SUMIFS(符文总览!O:O,符文总览!$D:$D,$B16,符文总览!$AL:$AL,$C16)) -> 0.33385714 | F16: =IF($B16="","",SUMIFS(符文总览!N:N,符文总览!$D:$D,$B16,符文总览!$AL:$AL,$C16)) -> 0.33025 | G16: =IF($B16="","",SUMIFS(符文总览!O:O,符文总览!$D:$D,$B16,符文总览!$AL:$AL,$C16)) -> 0.33385714 | H16: =IF($B16="","",SUMIFS(符文总览!P:P,符文总览!$D:$D,$B16,符文总览!$AL:$AL,$C16)) -> 0.33025 | I16: =IF($B16="","",SUMIFS(符文总览!Q:Q,符文总览!$D:$D,$B16,符文总览!$AL:$AL,$C16)) -> 0.32664286 | J16: =IF($B16="","",SUMIFS(符文总览!R:R,符文总览!$D:$D,$B16,符文总览!$AL:$AL,$C16)) -> 0.33025 | K16: =1/E16*_xlfn.XLOOKUP(B16,$N$5:$N$16,$O$5:$O$16)*K$4 -> 154.04365 | N16: 7 | O16: =24*60 -> 1440
B17: 5 | C17: 4 | D17: =IF(C17="","",E17*OFFSET($E$51,0,MATCH(C17,$C$14:$C$20,0))) -> 0.0071421429 | E17: =IF($B17="","",SUMIFS(符文总览!O:O,符文总览!$D:$D,$B17,符文总览!$AL:$AL,$C17)) -> 0.021642857 | F17: =IF($B17="","",SUMIFS(符文总览!N:N,符文总览!$D:$D,$B17,符文总览!$AL:$AL,$C17)) -> 0.02525 | G17: =IF($B17="","",SUMIFS(符文总览!O:O,符文总览!$D:$D,$B17,符文总览!$AL:$AL,$C17)) -> 0.021642857 | H17: =IF($B17="","",SUMIFS(符文总览!P:P,符文总览!$D:$D,$B17,符文总览!$AL:$AL,$C17)) -> 0.02525 | I17: =IF($B17="","",SUMIFS(符文总览!Q:Q,符文总览!$D:$D,$B17,符文总览!$AL:$AL,$C17)) -> 0.028857143 | J17: =IF($B17="","",SUMIFS(符文总览!R:R,符文总览!$D:$D,$B17,符文总览!$AL:$AL,$C17)) -> 0.02525 | K17: =1/E17*_xlfn.XLOOKUP(B17,$N$5:$N$16,$O$5:$O$16)*K$4 -> 2376.2376
B18: 5 | C18: 5 | D18: =IF(C18="","",E18*OFFSET($E$51,0,MATCH(C18,$C$14:$C$20,0))) -> 0.0075 | E18: =IF($B18="","",SUMIFS(符文总览!O:O,符文总览!$D:$D,$B18,符文总览!$AL:$AL,$C18)) -> 0.015 | F18: =IF($B18="","",SUMIFS(符文总览!N:N,符文总览!$D:$D,$B18,符文总览!$AL:$AL,$C18)) -> 0.015 | G18: =IF($B18="","",SUMIFS(符文总览!O:O,符文总览!$D:$D,$B18,符文总览!$AL:$AL,$C18)) -> 0.015 | H18: =IF($B18="","",SUMIFS(符文总览!P:P,符文总览!$D:$D,$B18,符文总览!$AL:$AL,$C18)) -> 0.015 | I18: =IF($B18="","",SUMIFS(符文总览!Q:Q,符文总览!$D:$D,$B18,符文总览!$AL:$AL,$C18)) -> 0.015 | J18: =IF($B18="","",SUMIFS(符文总览!R:R,符文总览!$D:$D,$B18,符文总览!$AL:$AL,$C18)) -> 0.015 | K18: =1/E18*_xlfn.XLOOKUP(B18,$N$5:$N$16,$O$5:$O$16)*K$4 -> 3428.5714
B19: 5 | C19: 6 | D19: =IF(C19="","",E19*OFFSET($E$51,0,MATCH(C19,$C$14:$C$20,0))) -> 0.0028 | E19: =IF($B19="","",SUMIFS(符文总览!O:O,符文总览!$D:$D,$B19,符文总览!$AL:$AL,$C19)) -> 0.007 | F19: =IF($B19="","",SUMIFS(符文总览!N:N,符文总览!$D:$D,$B19,符文总览!$AL:$AL,$C19)) -> 0.007 | G19: =IF($B19="","",SUMIFS(符文总览!O:O,符文总览!$D:$D,$B19,符文总览!$AL:$AL,$C19)) -> 0.007 | H19: =IF($B19="","",SUMIFS(符文总览!P:P,符文总览!$D:$D,$B19,符文总览!$AL:$AL,$C19)) -> 0.007 | I19: =IF($B19="","",SUMIFS(符文总览!Q:Q,符文总览!$D:$D,$B19,符文总览!$AL:$AL,$C19)) -> 0.007 | J19: =IF($B19="","",SUMIFS(符文总览!R:R,符文总览!$D:$D,$B19,符文总览!$AL:$AL,$C19)) -> 0.007 | K19: =1/E19*_xlfn.XLOOKUP(B19,$N$5:$N$16,$O$5:$O$16)*K$4 -> 7346.9388 | P19: =1/P26*P20 -> 100 | Q19: =1/Q26*Q20 -> 171.42857 | R19: =1/R26*R20 -> 300
B20: 5 | C20: 8 | D20: =IF(C20="","",E20*OFFSET($E$51,0,MATCH(C20,$C$14:$C$20,0))) -> 0.00525 | E20: =IF($B20="","",SUMIFS(符文总览!O:O,符文总览!$D:$D,$B20,符文总览!$AL:$AL,$C20)) -> 0.0105 | F20: =IF($B20="","",SUMIFS(符文总览!N:N,符文总览!$D:$D,$B20,符文总览!$AL:$AL,$C20)) -> 0.0105 | G20: =IF($B20="","",SUMIFS(符文总览!O:O,符文总览!$D:$D,$B20,符文总览!$AL:$AL,$C20)) -> 0.0105 | H20: =IF($B20="","",SUMIFS(符文总览!P:P,符文总览!$D:$D,$B20,符文总览!$AL:$AL,$C20)) -> 0.0105 | I20: =IF($B20="","",SUMIFS(符文总览!Q:Q,符文总览!$D:$D,$B20,符文总览!$AL:$AL,$C20)) -> 0.0105 | J20: =IF($B20="","",SUMIFS(符文总览!R:R,符文总览!$D:$D,$B20,符文总览!$AL:$AL,$C20)) -> 0.0105 | K20: =1/E20*_xlfn.XLOOKUP(B20,$N$5:$N$16,$O$5:$O$16)*K$4 -> 4897.9592 | P20: 6 | Q20: 12 | R20: 24
D21: =IF(C21="","",E21*OFFSET($E$51,0,MATCH(C21,$C$14:$C$20,0))) | E21: =IF($B21="","",SUMIFS(符文总览!O:O,符文总览!$D:$D,$B21,符文总览!$AL:$AL,$C21)) | F21: =IF($B21="","",SUMIFS(符文总览!N:N,符文总览!$D:$D,$B21,符文总览!$AL:$AL,$C21)) | G21: =IF($B21="","",SUMIFS(符文总览!O:O,符文总览!$D:$D,$B21,符文总览!$AL:$AL,$C21)) | H21: =IF($B21="","",SUMIFS(符文总览!P:P,符文总览!$D:$D,$B21,符文总览!$AL:$AL,$C21)) | I21: =IF($B21="","",SUMIFS(符文总览!Q:Q,符文总览!$D:$D,$B21,符文总览!$AL:$AL,$C21)) | J21: =IF($B21="","",SUMIFS(符文总览!R:R,符文总览!$D:$D,$B21,符文总览!$AL:$AL,$C21)) | P21: 橙色
B22: =B14+1 -> 6 | C22: =C14 -> 1 | D22: =IF(C22="","",E22*OFFSET($E$51,0,MATCH(C22,$C$14:$C$20,0))) -> 0.306 | E22: =IF($B22="","",SUMIFS(符文总览!O:O,符文总览!$D:$D,$B22,符文总览!$AL:$AL,$C22)) -> 0.306 | F22: =IF($B22="","",SUMIFS(符文总览!N:N,符文总览!$D:$D,$B22,符文总览!$AL:$AL,$C22)) -> 0.306 | G22: =IF($B22="","",SUMIFS(符文总览!O:O,符文总览!$D:$D,$B22,符文总览!$AL:$AL,$C22)) -> 0.306 | H22: =IF($B22="","",SUMIFS(符文总览!P:P,符文总览!$D:$D,$B22,符文总览!$AL:$AL,$C22)) -> 0.306 | I22: =IF($B22="","",SUMIFS(符文总览!Q:Q,符文总览!$D:$D,$B22,符文总览!$AL:$AL,$C22)) -> 0.306 | J22: =IF($B22="","",SUMIFS(符文总览!R:R,符文总览!$D:$D,$B22,符文总览!$AL:$AL,$C22)) -> 0.306 | K22: =1/E22*_xlfn.XLOOKUP(B22,$N$5:$N$16,$O$5:$O$16)*K$4 -> 336.13445 | L22: {=SUMPRODUCT(K22:K28,E22:E28)} -> 720 | P22: =SUM(E17:E20) -> 0.054142857 | Q22: =SUM(E25:E28) -> 0.054142857 | R22: =SUM(E33:E36) -> 0.054142857
B23: =B15+1 -> 6 | C23: =C15 -> 2 | D23: =IF(C23="","",E23*OFFSET($E$51,0,MATCH(C23,$C$14:$C$20,0))) -> 0.306 | E23: =IF($B23="","",SUMIFS(符文总览!O:O,符文总览!$D:$D,$B23,符文总览!$AL:$AL,$C23)) -> 0.306 | F23: =IF($B23="","",SUMIFS(符文总览!N:N,符文总览!$D:$D,$B23,符文总览!$AL:$AL,$C23)) -> 0.306 | G23: =IF($B23="","",SUMIFS(符文总览!O:O,符文总览!$D:$D,$B23,符文总览!$AL:$AL,$C23)) -> 0.306 | H23: =IF($B23="","",SUMIFS(符文总览!P:P,符文总览!$D:$D,$B23,符文总览!$AL:$AL,$C23)) -> 0.306 | I23: =IF($B23="","",SUMIFS(符文总览!Q:Q,符文总览!$D:$D,$B23,符文总览!$AL:$AL,$C23)) -> 0.306 | J23: =IF($B23="","",SUMIFS(符文总览!R:R,符文总览!$D:$D,$B23,符文总览!$AL:$AL,$C23)) -> 0.306 | K23: =1/E23*_xlfn.XLOOKUP(B23,$N$5:$N$16,$O$5:$O$16)*K$4 -> 336.13445 | O23: 5
B24: =B16+1 -> 6 | C24: =C16 -> 3 | D24: =IF(C24="","",E24*OFFSET($E$51,0,MATCH(C24,$C$14:$C$20,0))) -> 0.33385714 | E24: =IF($B24="","",SUMIFS(符文总览!O:O,符文总览!$D:$D,$B24,符文总览!$AL:$AL,$C24)) -> 0.33385714 | F24: =IF($B24="","",SUMIFS(符文总览!N:N,符文总览!$D:$D,$B24,符文总览!$AL:$AL,$C24)) -> 0.33025 | G24: =IF($B24="","",SUMIFS(符文总览!O:O,符文总览!$D:$D,$B24,符文总览!$AL:$AL,$C24)) -> 0.33385714 | H24: =IF($B24="","",SUMIFS(符文总览!P:P,符文总览!$D:$D,$B24,符文总览!$AL:$AL,$C24)) -> 0.33025 | I24: =IF($B24="","",SUMIFS(符文总览!Q:Q,符文总览!$D:$D,$B24,符文总览!$AL:$AL,$C24)) -> 0.32664286 | J24: =IF($B24="","",SUMIFS(符文总览!R:R,符文总览!$D:$D,$B24,符文总览!$AL:$AL,$C24)) -> 0.33025 | K24: =1/E24*_xlfn.XLOOKUP(B24,$N$5:$N$16,$O$5:$O$16)*K$4 -> 308.08729 | O24: 6
B25: =B17+1 -> 6 | C25: =C17 -> 4 | D25: =IF(C25="","",E25*OFFSET($E$51,0,MATCH(C25,$C$14:$C$20,0))) -> 0.0071421429 | E25: =IF($B25="","",SUMIFS(符文总览!O:O,符文总览!$D:$D,$B25,符文总览!$AL:$AL,$C25)) -> 0.021642857 | F25: =IF($B25="","",SUMIFS(符文总览!N:N,符文总览!$D:$D,$B25,符文总览!$AL:$AL,$C25)) -> 0.02525 | G25: =IF($B25="","",SUMIFS(符文总览!O:O,符文总览!$D:$D,$B25,符文总览!$AL:$AL,$C25)) -> 0.021642857 | H25: =IF($B25="","",SUMIFS(符文总览!P:P,符文总览!$D:$D,$B25,符文总览!$AL:$AL,$C25)) -> 0.02525 | I25: =IF($B25="","",SUMIFS(符文总览!Q:Q,符文总览!$D:$D,$B25,符文总览!$AL:$AL,$C25)) -> 0.028857143 | J25: =IF($B25="","",SUMIFS(符文总览!R:R,符文总览!$D:$D,$B25,符文总览!$AL:$AL,$C25)) -> 0.02525 | K25: =1/E25*_xlfn.XLOOKUP(B25,$N$5:$N$16,$O$5:$O$16)*K$4 -> 4752.4752 | O25: 8
B26: =B18+1 -> 6 | C26: =C18 -> 5 | D26: =IF(C26="","",E26*OFFSET($E$51,0,MATCH(C26,$C$14:$C$20,0))) -> 0.0075 | E26: =F26 -> 0.015 | F26: =IF($B26="","",SUMIFS(符文总览!N:N,符文总览!$D:$D,$B26,符文总览!$AL:$AL,$C26)) -> 0.015 | G26: =IF($B26="","",SUMIFS(符文总览!O:O,符文总览!$D:$D,$B26,符文总览!$AL:$AL,$C26)) -> 0.015 | H26: =IF($B26="","",SUMIFS(符文总览!P:P,符文总览!$D:$D,$B26,符文总览!$AL:$AL,$C26)) -> 0.015 | I26: =IF($B26="","",SUMIFS(符文总览!Q:Q,符文总览!$D:$D,$B26,符文总览!$AL:$AL,$C26)) -> 0.015 | J26: =IF($B26="","",SUMIFS(符文总览!R:R,符文总览!$D:$D,$B26,符文总览!$AL:$AL,$C26)) -> 0.015 | K26: =1/E26*_xlfn.XLOOKUP(B26,$N$5:$N$16,$O$5:$O$16)*K$4 -> 6857.1429 | P26: 0.06 | Q26: 0.07 | R26: 0.08
B27: =B19+1 -> 6 | C27: =C19 -> 6 | D27: =IF(C27="","",E27*OFFSET($E$51,0,MATCH(C27,$C$14:$C$20,0))) -> 0.0028 | E27: =IF($B27="","",SUMIFS(符文总览!O:O,符文总览!$D:$D,$B27,符文总览!$AL:$AL,$C27)) -> 0.007 | F27: =IF($B27="","",SUMIFS(符文总览!N:N,符文总览!$D:$D,$B27,符文总览!$AL:$AL,$C27)) -> 0.007 | G27: =IF($B27="","",SUMIFS(符文总览!O:O,符文总览!$D:$D,$B27,符文总览!$AL:$AL,$C27)) -> 0.007 | H27: =IF($B27="","",SUMIFS(符文总览!P:P,符文总览!$D:$D,$B27,符文总览!$AL:$AL,$C27)) -> 0.007 | I27: =IF($B27="","",SUMIFS(符文总览!Q:Q,符文总览!$D:$D,$B27,符文总览!$AL:$AL,$C27)) -> 0.007 | J27: =IF($B27="","",SUMIFS(符文总览!R:R,符文总览!$D:$D,$B27,符文总览!$AL:$AL,$C27)) -> 0.007 | K27: =1/E27*_xlfn.XLOOKUP(B27,$N$5:$N$16,$O$5:$O$16)*K$4 -> 14693.878
