Workbook

Sheet ChangeLog
B2: 版本号 | C2: 修改时间 | D2: 修改内容 | E2: 修改人
B3: V1.00 | C3: 45762 | D3: 文档创建 | E3: 童超

Sheet 核心循环
C2: 核心循环

Sheet 战斗公式
C3: 设计思路
D4: ID | E4: 设计思路
D5: 1 | E5: 无防御数值，基础伤害公式就是攻击和生命
D6: 2 | E6: 外围属性投放相对收敛，不做大数值
D7: 3 | E7: 公式可以拓展，预留新增特殊高价值属性的空间
D8: 4 | E8: 当所有梦灵生命值为0时，战斗失败
D9: 5 | E9: 后续在伤害的投放上，需要注意：角色自身养成提升的技能伤害走hit_result的技能系数【凸显专项的强度体验】，局内和局外的通用养成用dmg_rate【量大可以被稀释】，局外通用系统的专属角色养成用common_hit_rate【凸显专项的强度体验】且尽量避免减伤
C12: 战斗公式
D14: 战斗伤害计算：
D16: 基础伤害=面板攻击
D17: 注： | E17: 1、局外所有属性最终由服务端转换成相应的战斗属性发给客户端（除怪物增伤外）
E18: 2、面板攻击是不带属性类型的，理解为全局基础攻击力属性表的最终atk
D20: 乘区划分
D21: 常规伤害计算=（基础伤害乘区 * 1技能系数乘区 *2局外伤害加成乘区 *3局内伤害加成乘区 *暴击伤害-固定减伤）*4怪物抗性乘区* 5伤害减免乘区 * 6英雄蓝字伤害乘区 *8英雄机制伤害* 9角色伤害乘区*10距离伤害乘区*11怪物增伤乘区*12伤害波动乘区*13元素伤害乘区
D23: 注： | E23: 1、技能伤害乘区=（攻击者技能伤害系数*（1+技能类型效果增幅系数）+附加系数修正技能倍率）
F24: 修改计算方式成乘法，（攻击者技能伤害系数+附加系数修正技能倍率*（1+技能类型效果增幅系数））
E25: 2、局外伤害加成乘区=1+ Σ伤害加成的汇总 用旧的dmg_rate
F26: 存放职业伤害增加（队长伤害加成、全局伤害加成、战士/法师/毒/控制/辅助/射手伤害加成）
F27: 存放玩法伤害增加，如对小怪增伤属性616~618
F28: 存放怪物伤害增加，如对小怪增伤属性608~615
E29: 3、局内伤害加成乘区=1+ Σ伤害加成的汇总
F30: 新增乘区和属性：局内伤害加成 dmg_rate，大部分局内增伤都放到这里，如红温卡带加成到这里
E31: 4、怪物抗性乘区=min(max(0.2,1- 怪物最终抗性),2)
F32: 当怪物对应职业抗性<=0时候，
G33: 怪物最终抗性=怪物对应职业抗性
F34: 当怪物对应职业抗性>0时 ,
G35: 怪物最终抗性=max(怪物对应职业抗性-最终无视怪物抗性,0)
E36: 5、伤害减免乘区=1-伤害减免
F37: 新增乘区：从原本公式挪出来，伤害减免dmg_red_rate，易伤配置负数实现，英雄伤害减免配正数
E38: 6、英雄蓝字伤害乘区=1+蓝字伤害加成（新属性）
F39: 新增属性和乘区：蓝字字体伤害，保证字体颜色变化时，一定是有这么多百分比
E42: 8、英雄机制伤害=1+机制伤害加成（新属性）
F43: 新增属性和乘区：英雄机制伤害增加，如对中毒单位伤害增加、对冰冻伤害增加加到这里乘区
E44: 9、角色增伤乘区=1+英雄升阶伤害加成（新属性）
F45: 新增属性：角色升级伤害加成，如20级寒冰给的10%伤害加成
E46: 10、距离伤害乘区=1+近距离伤害加成/远距离伤害加成（新属性）
F47: 新增属性和乘区：短/远距离伤害加成，战斗给距离，给战士职业属性用
E48: 11、伤害波动乘区=1+伤害波动
F49: 新增乘区：属性后续加，先预留
E50: 12、元素伤害乘区=1+对应元素伤害加成+全元素伤害增加
...

Sheet 养成框架
C2: 养成框架
D3: 类型ID | E3: 定义
D4: 活跃 | E4: 定义为80%来源为日常游玩获取，极少付费加速。
D5: 活跃+付费 | E5: 定义为活跃有持续获取，且付费有比较大的加速空间。
D6: 付费 | E6: 定位为主要靠付费获取，活跃需要较长时间在活动或者商店兑换获取。（兑换周期一般在一周以上）
D8: 养成模块 | E8: 养成点 | F8: 开启时机 | G8: 简述 | H8: 商业化定位 | I8: 付费层级 | J8: 养成定位 | K8: 战斗影响 | L8: 主要获取途径
D9: 梦灵1 | E9: 升级 | F9: 首日 | G9: 游戏养成方面的主轴线，随英雄池拓展，步长稳定 | H9: 活跃 | I9: 免费 | J9: 细颗粒度 | K9: 属性+机制 | L9: 抽卡
D10: 梦灵2 | E10: 图鉴 | F10: 首日 | G10: 给老英雄提供价值，提供全局爆伤属性，为暴击属性铺垫 | H10: 活跃 | I10: 免费 | J10: 细颗粒度 | K10: 属性
D11: 梦灵3 | E11: 专属卡带 | F11: / | G11: 梦灵专武，变更梦灵技能效果，本体升星，拓宽梦灵深度 | H11: 活跃+付费 | I11: 大R | J11: 大颗粒度 | K11: 专属卡带+被动 | L11: 特殊商业化活动
D12: 梦灵4 | E12: 皮肤 | F12: 首日 | G12: 为高人气梦灵做全套定制的视觉差异，纯皮，针对超R | H12: 付费 | I12: 超R | J12: / | K12: / | L12: 运营活动
D13: 主角1 | E13: 装备 | F13: 首日 | G13: 前期高额基础属性，中期高额伤害加成，后期洗练拓宽保证步长稳定 | H13: 活跃 | I13: 免费 | J13: 细颗粒度 | K13: 固定属性 | L13: 挂机、组队玩法
D14: 主角2 | E14: 武器 | F14: 首日 | G14: 促进联盟发展，投放加速，围绕加速搭建生态 | H14: 活跃 | I14: 免费 | J14: 中颗粒度 | K14: 固定属性+技能 | L14: 日常+组队玩法+公会玩法
D15: 主角3 | E15: 宝石 | F15: 首日 | G15: 前期合成，中后期洗练 | H15: 活跃+付费 | I15: 中R | J15: 中颗粒度 | K15: 属性+技能+机制 | L15: 日常活跃
D16: 主角4 | E16: 武器皮肤 | F16: 首日 | G16: 个性化外观+局内触发类进攻技能售卖，超R追求满星 | H16: 付费 | I16: 大R | J16: / | K16: 属性+技能 | L16: 运营活动
D17: 主角5 | E17: 时装皮肤 | F17: 首日 | G17: 个性化外观+局内玩法机制类效果售卖，超R追求满星 | H17: 付费 | I17: 超R | J17: / | K17: 属性+机制 | L17: 运营活动
C19: 养成步长设计
D20: ID | E20: 养成步长思路
D21: 时期分类 | E21: 步长分为 新手期（前10关特殊调整产出，主要从首通、三星宝箱奖励上平衡步长）、前期（初始功能无，爽1~2天进入稳定期）、中期（稳定标准成长，小额进行衰减产出，基本不受新手期影响）、后期（性价比暴跌，被其他养成替代）
D22: 主轴分类 | E22: 核心cv包括主线关卡和等级两条线，天数&等级线是去控制基础属性的节奏（等级线是为技能系数服务的，确保成长的稳定和玩家差距），天数&关卡线是控制技能系数的节奏（通过核心产出关联，这样能确保英雄的释放节奏），天数&关卡线 和 天数&等级线都是单独出来的两条线，这里用关键节点去控体验
D23: 天数&关卡线
E24: 14天50关（大R7天50关，靠英雄释放节奏要爽），也是首月冲榜的关键节点
E25: 30天70关（每天1.5关，英雄转红卡节奏变慢，宝石慢慢成为主力）
E26: 60天100关（每天1关，宝石是主力，用最优解宝石组合去控成长）
E27: 120天150关（小R开始追不上大R，大R开始专项宝石拉开差距，拓展新养成和新英雄缩小差距）
D28: 天数&等级线（核心是基础装备，品质=>换代装备效率，等级=>换代装备节奏）
E29: 14天56级（装备换代定制到3~4天，到50级装备稳定打通50关，这里是关键节点），前期10~30级基础装备的体验核心是2天一个等级段、品质低换代效率高。40~50级是4天一个等极段，品质稍高但节奏依旧紧凑度更高，培养装备认识=多刷才跟得上，营造合作本中的交互
E30: 21天63级，28天70级（每周迭代一个版本装备），此处的假设是已经培养出装备的认识，要多刷，保证体验=将将好能实现 换代换代=换代效率+洗练节奏
E31: 34天~60天2周，60~120天2周一次是极限，品质进一步拉高，换代效率更慢了，两周一次换代，这里要能突出洗练的重要性（洗练属性的堆叠+词条的选择）
G61: 英雄 | K61: 2 | L61: 宝石 | N61: #不做保底 | R61: 玩家 | S61: 装备 | U61: 副本次数*5+扫荡*40/5 | V61: 基因 | W61: 对标装备
E62: 非r主线进度 | G62: 倍率成长 | R62: 挂件属性
D63: 天数 | E63: 主线进度 | F63: 每日关卡数 | G63: 品质 | H63: 蓝英雄 | I63: 紫英雄 | J63: 橙英雄 | K63: 红英雄 | L63: 宝石解锁 | M63: 宝石品质 | N63: 基础倍率 | O63: 英雄期望倍率 | P63: 宝石期望倍率 | Q63: 宝石总倍率 | R63: 每日升级 | S63: 玩家等级 | T63: 装备等级 | U63: 装备强化 | V63: 装备品质 | W63: 基因节点 | X63: 装备等级步长 | AA63: 专属符文 | AB63: 加成数值
D64: 1 | E64: 10 | F64: 10 | H64: 10 | I64: 5 | J64: 0 | K64: 0 | L64: 12 | M64: 绿 | N64: 1 | O64: 1.38 | Q64: 1.3 | R64: 12 | S64: =R64 -> 12 | T64: 10 | U64: =X64 -> 10 | V64: 蓝 | W64: 16 | X64: 10 | Z64: =30*4 -> 120 | AA64: 紫色符文 | AB64: 0.1
D65: 2 | E65: =E64+F65*(D65-D64) -> 15 | F65: 5 | G65: 橙卡1 | H65: 12 | I65: 6.67 | J65: 0 | K65: 0 | L65: 18 | N65: =N64+7% -> 1.07 | O65: 1.476025 | Q65: 1.3 | R65: 6 | S65: =INT(R65*(D65-D64)+S64) -> 18 | T65: =INT(S65/10)*10+10 -> 20 | U65: =U64+X65*(D65-D64) -> 16 | V65: 紫 | W65: 21 | X65: 6 | AA65: 橙色符文 | AB65: 0.15
D66: 3 | E66: =E65+F66*(D66-D65) -> 20 | F66: 5 | G66: 橙卡2 | H66: 14 | I66: 8.34 | J66: 5 | K66: 0 | L66: 22 | M66: 蓝 | N66: =N65+7% -> 1.14 | O66: 1.674 | Q66: =MAX(J107/N66/O66,Q65) -> 1.3 | R66: 4 | S66: =R66*(D66-D65)+S65 -> 22 | T66: =INT(S66/10)*10+10 -> 30 | U66: =U65+X66*(D66-D65) -> 20 | V66: 橙 | W66: 26 | X66: 4 | AA66: 红色符文 | AB66: 0.2
D67: 4 | E67: =E66+F67*(D67-D66) -> 24 | F67: 4 | G67: 橙卡3 | H67: 16 | I67: 10.01 | J67: 5.5 | K67: 0 | L67: 24 | M67: =AVERAGE(P71:P76) -> 0.019172963 | N67: =N66+7% -> 1.21 | O67: 1.734798 | P67: =((J108/N67/O67)^(1/L67*6)-1)/5 -> 0.014148227 | Q67: =MAX(J108/N67/O67,Q66) -> 1.3144315 | R67: 3 | S67: =R67*(D67-D66)+S66 -> 25 | T67: =INT(S67/10)*10+10 -> 30 | U67: =U66+X67*(D67-D66) -> 24 | V67: 橙 | W67: 30 | X67: 4 | Z67: 0.48 | AA67: 彩色符文 | AB67: 0.25
D68: 5 | E68: =E67+F68*(D68-D67) -> 27 | F68: 3 | G68: 橙卡4 | H68: 17 | I68: 10.71 | J68: 6 | K68: 0 | L68: 26 | N68: =N67+7% -> 1.28 | O68: 1.776658 | P68: =((J109/N68/O68)^(1/L68*6)-1)/5 -> 0.01439038 | Q68: =MAX(J109/N68/O68,Q67) -> 1.3513244 | R68: 3 | S68: =R68*(D68-D67)+S67 -> 28 | T68: =INT(S68/10)*10+10 -> 30 | U68: =U67+X68*(D68-D67) -> 27 | V68: 橙 | W68: 34 | X68: 3 | Z68: =0.36 -> 0.36
D69: 6 | E69: =E68+F69*(D69-D68) -> 30 | F69: 3 | G69: 橙卡5 | H69: 18 | I69: 11.41 | J69: 6.5 | K69: 0 | L69: 28 | N69: =N68+7% -> 1.35 | O69: 1.818518 | P69: =((J110/N69/O69)^(1/L69*6)-1)/5 -> 0.014108949 | Q69: =MAX(J110/N69/O69,Q68) -> 1.3745351 | R69: 2 | S69: =R69*(D69-D68)+S68 -> 30 | T69: =INT(S69/10)*10+10 -> 40 | U69: =U68+X69*(D69-D68) -> 30 | V69: 橙 | W69: 37 | X69: 3 | Z69: =0.75 -> 0.75
D70: 7 | E70: =E69+F70*(D70-D69) -> 33 | F70: 3 | G70: 橙卡6 | H70: 19 | I70: 12.11 | J70: 7 | K70: 0 | L70: 30 | N70: =N69+5% -> 1.4 | O70: 1.860378 | P70: =((J111/N70/O70)^(1/L70*6)-1)/5 -> 0.016444555 | Q70: =MAX(J111/N70/O70,Q69) -> 1.4845108 | R70: 2 | S70: =R70*(D70-D69)+S69 -> 32 | T70: =INT(S70/10)*10+10 -> 40 | U70: =U69+X70*(D70-D69) -> 32 | V70: 橙 | W70: 40 | X70: 2 | Z70: =0.9 -> 0.9
D71: 8 | E71: =E70+F71*(D71-D70) -> 35 | F71: 2 | G71: 红卡1 | H71: 20 | I71: 12.81 | J71: 7.5 | K71: 0 | L71: 30 | N71: =N70+5% -> 1.45 | O71: 1.902238 | P71: =((J112/N71/O71)^(1/L71*6)-1)/5 -> 0.017105817 | Q71: =MAX(J112/N71/O71,Q70) -> 1.5073264 | R71: 2 | S71: =R71*(D71-D70)+S70 -> 34 | T71: =INT(S71/10)*10+10 -> 40 | U71: =U70+X71*(D71-D70) -> 34 | V71: 红 | W71: 43 | X71: 2
D72: 9 | E72: =E71+F72*(D72-D71) -> 37 | F72: 2 | H72: 20.5 | I72: 13.51 | J72: 8 | K72: 0 | L72: 30 | N72: =N71+5% -> 1.5 | O72: 1.944098 | P72: =((J113/N72/O72)^(1/L72*6)-1)/5 -> 0.018005587 | Q72: =MAX(J113/N72/O72,Q71) -> 1.5388211 | R72: 2 | S72: =R72*(D72-D71)+S71 -> 36 | T72: =INT(S72/10)*10+10 -> 40 | U72: =U71+X72*(D72-D71) -> 36 | V72: 红 | W72: 46 | X72: 2
...

Sheet 养成框架(补充给运营)
C2: 练度预期
D3: 非R，不买体力，满肝度，每日三次组队本
D4: 当前计算为未折算的成长预期
D5: 后续优化：前七天具体计算，当前七天未核算的有体力
C7: 玩家等级
E9: 等级预期 | L9: 主线关卡数
D10: 天数 | E10: 非R | F10: 小R | G10: 中R | H10: 大R | K10: 天数 | L10: 非R | M10: 小R | N10: 中R | O10: 大R
D11: 1 | E11: 11 | F11: 11 | G11: 11 | H11: 15 | K11: 1 | L11: 12 | M11: 16 | N11: 20 | O11: 25
D12: 2 | E12: 16 | F12: 17 | G12: 17 | H12: 24 | K12: 2 | L12: 18 | M12: 24 | N12: 30 | O12: 37
D13: 3 | E13: 21 | F13: 23 | G13: 23 | H13: 31 | K13: 3 | L13: 23 | M13: 29 | N13: 35 | O13: 43
D14: 4 | E14: 26 | F14: 28 | G14: 28 | H14: 37 | K14: 4 | L14: 27 | M14: 34 | N14: 42 | O14: 52
D15: 5 | E15: 30 | F15: 32 | G15: 32 | H15: 42 | K15: 5 | L15: 30 | M15: 38 | N15: 46 | O15: 57
D16: 6 | E16: 33 | F16: 36 | G16: 36 | H16: 46 | K16: 6 | L16: 33 | M16: 41 | N16: 49 | O16: 61
D17: 7 | E17: 37 | F17: 39 | G17: 39 | H17: 50 | K17: 7 | L17: 36 | M17: 44 | N17: 52 | O17: 65
D18: 8 | E18: 39 | F18: 42 | G18: 42 | H18: 53 | K18: 8 | L18: 39 | M18: 47 | N18: 55 | O18: 68
D19: 9 | E19: 42 | F19: 45 | G19: 45 | H19: 55 | K19: 9 | L19: 41 | M19: 49 | N19: 58 | O19: 72
D20: 10 | E20: 45 | F20: 48 | G20: 48 | H20: 57 | K20: 10 | L20: 43 | M20: 52 | N20: 61 | O20: 76
D21: 11 | E21: 47 | F21: 50 | G21: 50 | H21: 58 | K21: 11 | L21: 45 | M21: 54 | N21: 64 | O21: 80
D22: 12 | E22: 49 | F22: 52 | G22: 52 | H22: 60 | K22: 12 | L22: 47 | M22: 56 | N22: 66 | O22: 82
... D70: 60 | E70: 86 | F70: 91 | G70: 91 | H70: 110 | K70: 60 | L70: 87 | M70: 101 | N70: 116 | O70: 145
C73: 装备预期（同基础属性汇总）
E75: 总属性预期 | J75: 练度预期 | K75: 强化等级 | Q75: 装备等级 | X75: 装备品质
D76: 天数 | E76: 非R | F76: 小R | G76: 中R | H76: 大R | J76: 天数 | K76: 非R | L76: 小R | M76: 中R | N76: 大R | P76: 天数 | Q76: 非R | R76: 小R | S76: 中R | T76: 大R | W76: 天数 | X76: 非R | Y76: 小R | Z76: 中R | AA76: 大R | AC76: 天数 | AD76: 非R | AE76: 小R | AF76: 中R | AG76: 大R
D77: 1 | E77: {=_xlfn.XLOOKUP(K77,[3]装备属性!$D$571:$D$870,[3]装备属性!$I$571:$I$870)*6+_xlfn.XLOOKUP(Q77&X77,[3]装备属性!$E$62:$E$277&[3]装备属性!$G$62:$G$277,[3]装备属性!$I$62:$I$277)*6+IFERROR(_xlfn.XLOOKUP(Q77&X77,[3]装备属性!$D$309:$D$557&[3]装备属性!$F$309:$F$557,[3]装备属性!$H$309:$H$557)*AD77*6,0)+VLOOKUP(E210,$V$209:$X$216,3,0)*Q210+100} -> 598 | F77: {=_xlfn.XLOOKUP(L77,[3]装备属性!$D$571:$D$870,[3]装备属性!$I$571:$I$870)*6+_xlfn.XLOOKUP(R77&Y77,[3]装备属性!$E$62:$E$277&[3]装备属性!$G$62:$G$277,[3]装备属性!$I$62:$I$277)*6+IFERROR(_xlfn.XLOOKUP(R77&Y77,[3]装备属性!$D$309:$D$557&[3]装备属性!$F$309:$F$557,[3]装备属性!$H$309:$H$557)*AE77*6,0)+VLOOKUP(F210,$V$209:$X$216,3,0)*R210+100} -> 674 | G77: {=_xlfn.XLOOKUP(M77,[3]装备属性!$D$571:$D$870,[3]装备属性!$I$571:$I$870)*6+_xlfn.XLOOKUP(S77&Z77,[3]装备属性!$E$62:$E$277&[3]装备属性!$G$62:$G$277,[3]装备属性!$I$62:$I$277)*6+IFERROR(_xlfn.XLOOKUP(S77&Z77,[3]装备属性!$D$309:$D$557&[3]装备属性!$F$309:$F$557,[3]装备属性!$H$309:$H$557)*AF77*6,0)+VLOOKUP(G210,$V$209:$X$216,3,0)*S210+100} -> 770 | H77: {=_xlfn.XLOOKUP(N77,[3]装备属性!$D$571:$D$870,[3]装备属性!$I$571:$I$870)*6+_xlfn.XLOOKUP(T77&AA77,[3]装备属性!$E$62:$E$277&[3]装备属性!$G$62:$G$277,[3]装备属性!$I$62:$I$277)*6+IFERROR(_xlfn.XLOOKUP(T77&AA77,[3]装备属性!$D$309:$D$557&[3]装备属性!$F$309:$F$557,[3]装备属性!$H$309:$H$557)*AG77*6,0)+VLOOKUP(H210,$V$209:$X$216,3,0)*T210+100} -> 898 | J77: 1 | K77: 9 | L77: 9 | M77: 11 | N77: 12 | P77: 1 | Q77: 10 | R77: 10 | S77: 20 | T77: 20 | W77: 1 | X77: 蓝 | Y77: =VLOOKUP(INT(M11/10),$AI$77:$AJ$96,2,0) -> 紫 | Z77: 紫 | AA77: =VLOOKUP(INT(O11/10),$AI$77:$AJ$96,2,0) -> 橙 | AC77: 1 | AD77: 0 | AE77: 0 | AF77: 0 | AG77: 0 | AI77: 1 | AJ77: 紫
D78: 2 | E78: {=_xlfn.XLOOKUP(K78,[3]装备属性!$D$571:$D$870,[3]装备属性!$I$571:$I$870)*6+_xlfn.XLOOKUP(Q78&X78,[3]装备属性!$E$62:$E$277&[3]装备属性!$G$62:$G$277,[3]装备属性!$I$62:$I$277)*6+IFERROR(_xlfn.XLOOKUP(Q78&X78,[3]装备属性!$D$309:$D$557&[3]装备属性!$F$309:$F$557,[3]装备属性!$H$309:$H$557)*AD78*6,0)+VLOOKUP(E211,$V$209:$X$216,3,0)*Q211+100} -> 858 | F78: {=_xlfn.XLOOKUP(L78,[3]装备属性!$D$571:$D$870,[3]装备属性!$I$571:$I$870)*6+_xlfn.XLOOKUP(R78&Y78,[3]装备属性!$E$62:$E$277&[3]装备属性!$G$62:$G$277,[3]装备属性!$I$62:$I$277)*6+IFERROR(_xlfn.XLOOKUP(R78&Y78,[3]装备属性!$D$309:$D$557&[3]装备属性!$F$309:$F$557,[3]装备属性!$H$309:$H$557)*AE78*6,0)+VLOOKUP(F211,$V$209:$X$216,3,0)*R211+100} -> 938 | G78: {=_xlfn.XLOOKUP(M78,[3]装备属性!$D$571:$D$870,[3]装备属性!$I$571:$I$870)*6+_xlfn.XLOOKUP(S78&Z78,[3]装备属性!$E$62:$E$277&[3]装备属性!$G$62:$G$277,[3]装备属性!$I$62:$I$277)*6+IFERROR(_xlfn.XLOOKUP(S78&Z78,[3]装备属性!$D$309:$D$557&[3]装备属性!$F$309:$F$557,[3]装备属性!$H$309:$H$557)*AF78*6,0)+VLOOKUP(G211,$V$209:$X$216,3,0)*S211+100} -> 1010 | H78: {=_xlfn.XLOOKUP(N78,[3]装备属性!$D$571:$D$870,[3]装备属性!$I$571:$I$870)*6+_xlfn.XLOOKUP(T78&AA78,[3]装备属性!$E$62:$E$277&[3]装备属性!$G$62:$G$277,[3]装备属性!$I$62:$I$277)*6+IFERROR(_xlfn.XLOOKUP(T78&AA78,[3]装备属性!$D$309:$D$557&[3]装备属性!$F$309:$F$557,[3]装备属性!$H$309:$H$557)*AG78*6,0)+VLOOKUP(H211,$V$209:$X$216,3,0)*T211+100} -> 1228 | J78: 2 | K78: 13 | L78: 13 | M78: 16 | N78: 17 | P78: 2 | Q78: 20 | R78: 20 | S78: 20 | T78: 30 | W78: 2 | X78: =VLOOKUP(INT(L12/10),$AI$77:$AJ$96,2,0) -> 紫 | Y78: =VLOOKUP(INT(M12/10),$AI$77:$AJ$96,2,0) -> 橙 | Z78: =VLOOKUP(INT(N12/10),$AI$77:$AJ$96,2,0) -> 橙 | AA78: =VLOOKUP(INT(O12/10),$AI$77:$AJ$96,2,0) -> 橙 | AC78: 2 | AD78: 0 | AE78: 0 | AF78: 0 | AG78: 0 | AI78: 2 | AJ78: 橙
D79: 3 | E79: {=_xlfn.XLOOKUP(K79,[3]装备属性!$D$571:$D$870,[3]装备属性!$I$571:$I$870)*6+_xlfn.XLOOKUP(Q79&X79,[3]装备属性!$E$62:$E$277&[3]装备属性!$G$62:$G$277,[3]装备属性!$I$62:$I$277)*6+IFERROR(_xlfn.XLOOKUP(Q79&X79,[3]装备属性!$D$309:$D$557&[3]装备属性!$F$309:$F$557,[3]装备属性!$H$309:$H$557)*AD79*6,0)+VLOOKUP(E212,$V$209:$X$216,3,0)*Q212+100} -> 1100 | F79: {=_xlfn.XLOOKUP(L79,[3]装备属性!$D$571:$D$870,[3]装备属性!$I$571:$I$870)*6+_xlfn.XLOOKUP(R79&Y79,[3]装备属性!$E$62:$E$277&[3]装备属性!$G$62:$G$277,[3]装备属性!$I$62:$I$277)*6+IFERROR(_xlfn.XLOOKUP(R79&Y79,[3]装备属性!$D$309:$D$557&[3]装备属性!$F$309:$F$557,[3]装备属性!$H$309:$H$557)*AE79*6,0)+VLOOKUP(F212,$V$209:$X$216,3,0)*R212+100} -> 1108 | G79: {=_xlfn.XLOOKUP(M79,[3]装备属性!$D$571:$D$870,[3]装备属性!$I$571:$I$870)*6+_xlfn.XLOOKUP(S79&Z79,[3]装备属性!$E$62:$E$277&[3]装备属性!$G$62:$G$277,[3]装备属性!$I$62:$I$277)*6+IFERROR(_xlfn.XLOOKUP(S79&Z79,[3]装备属性!$D$309:$D$557&[3]装备属性!$F$309:$F$557,[3]装备属性!$H$309:$H$557)*AF79*6,0)+VLOOKUP(G212,$V$209:$X$216,3,0)*S212+100} -> 1180 | H79: {=_xlfn.XLOOKUP(N79,[3]装备属性!$D$571:$D$870,[3]装备属性!$I$571:$I$870)*6+_xlfn.XLOOKUP(T79&AA79,[3]装备属性!$E$62:$E$277&[3]装备属性!$G$62:$G$277,[3]装备属性!$I$62:$I$277)*6+IFERROR(_xlfn.XLOOKUP(T79&AA79,[3]装备属性!$D$309:$D$557&[3]装备属性!$F$309:$F$557,[3]装备属性!$H$309:$H$557)*AG79*6,0)+VLOOKUP(H212,$V$209:$X$216,3,0)*T212+100} -> 1558 | J79: 3 | K79: 16 | L79: 16 | M79: 19 | N79: 20 | P79: 3 | Q79: 30 | R79: 30 | S79: 30 | T79: 40 | W79: 3 | X79: =VLOOKUP(INT(L13/10),$AI$77:$AJ$96,2,0) -> 橙 | Y79: =VLOOKUP(INT(M13/10),$AI$77:$AJ$96,2,0) -> 橙 | Z79: =VLOOKUP(INT(N13/10),$AI$77:$AJ$96,2,0) -> 橙 | AA79: =VLOOKUP(INT(O13/10),$AI$77:$AJ$96,2,0) -> 红 | AC79: 3 | AD79: 0 | AE79: 0 | AF79: 0 | AG79: 0 | AI79: 3 | AJ79: 橙
D80: 4 | E80: {=_xlfn.XLOOKUP(K80,[3]装备属性!$D$571:$D$870,[3]装备属性!$I$571:$I$870)*6+_xlfn.XLOOKUP(Q80&X80,[3]装备属性!$E$62:$E$277&[3]装备属性!$G$62:$G$277,[3]装备属性!$I$62:$I$277)*6+IFERROR(_xlfn.XLOOKUP(Q80&X80,[3]装备属性!$D$309:$D$557&[3]装备属性!$F$309:$F$557,[3]装备属性!$H$309:$H$557)*AD80*6,0)+VLOOKUP(E213,$V$209:$X$216,3,0)*Q213+100} -> 1172 | F80: {=_xlfn.XLOOKUP(L80,[3]装备属性!$D$571:$D$870,[3]装备属性!$I$571:$I$870)*6+_xlfn.XLOOKUP(R80&Y80,[3]装备属性!$E$62:$E$277&[3]装备属性!$G$62:$G$277,[3]装备属性!$I$62:$I$277)*6+IFERROR(_xlfn.XLOOKUP(R80&Y80,[3]装备属性!$D$309:$D$557&[3]装备属性!$F$309:$F$557,[3]装备属性!$H$309:$H$557)*AE80*6,0)+VLOOKUP(F213,$V$209:$X$216,3,0)*R213+100} -> 1204 | G80: {=_xlfn.XLOOKUP(M80,[3]装备属性!$D$571:$D$870,[3]装备属性!$I$571:$I$870)*6+_xlfn.XLOOKUP(S80&Z80,[3]装备属性!$E$62:$E$277&[3]装备属性!$G$62:$G$277,[3]装备属性!$I$62:$I$277)*6+IFERROR(_xlfn.XLOOKUP(S80&Z80,[3]装备属性!$D$309:$D$557&[3]装备属性!$F$309:$F$557,[3]装备属性!$H$309:$H$557)*AF80*6,0)+VLOOKUP(G213,$V$209:$X$216,3,0)*S213+100} -> 1414 | H80: {=_xlfn.XLOOKUP(N80,[3]装备属性!$D$571:$D$870,[3]装备属性!$I$571:$I$870)*6+_xlfn.XLOOKUP(T80&AA80,[3]装备属性!$E$62:$E$277&[3]装备属性!$G$62:$G$277,[3]装备属性!$I$62:$I$277)*6+IFERROR(_xlfn.XLOOKUP(T80&AA80,[3]装备属性!$D$309:$D$557&[3]装备属性!$F$309:$F$557,[3]装备属性!$H$309:$H$557)*AG80*6,0)+VLOOKUP(H213,$V$209:$X$216,3,0)*T213+100} -> 1684 | J80: 4 | K80: 18 | L80: 19 | M80: 22 | N80: 23 | P80: 4 | Q80: 30 | R80: 30 | S80: 30 | T80: 40 | W80: 4 | X80: =VLOOKUP(INT(L14/10),$AI$77:$AJ$96,2,0) -> 橙 | Y80: =VLOOKUP(INT(M14/10),$AI$77:$AJ$96,2,0) -> 橙 | Z80: =VLOOKUP(INT(N14/10),$AI$77:$AJ$96,2,0) -> 红 | AA80: =VLOOKUP(INT(O14/10),$AI$77:$AJ$96,2,0) -> 红 | AC80: 4 | AD80: 0 | AE80: 0 | AF80: 0 | AG80: 0 | AI80: 4 | AJ80: 红
D81: 5 | E81: {=_xlfn.XLOOKUP(K81,[3]装备属性!$D$571:$D$870,[3]装备属性!$I$571:$I$870)*6+_xlfn.XLOOKUP(Q81&X81,[3]装备属性!$E$62:$E$277&[3]装备属性!$G$62:$G$277,[3]装备属性!$I$62:$I$277)*6+IFERROR(_xlfn.XLOOKUP(Q81&X81,[3]装备属性!$D$309:$D$557&[3]装备属性!$F$309:$F$557,[3]装备属性!$H$309:$H$557)*AD81*6,0)+VLOOKUP(E214,$V$209:$X$216,3,0)*Q214+100} -> 1320 | F81: {=_xlfn.XLOOKUP(L81,[3]装备属性!$D$571:$D$870,[3]装备属性!$I$571:$I$870)*6+_xlfn.XLOOKUP(R81&Y81,[3]装备属性!$E$62:$E$277&[3]装备属性!$G$62:$G$277,[3]装备属性!$I$62:$I$277)*6+IFERROR(_xlfn.XLOOKUP(R81&Y81,[3]装备属性!$D$309:$D$557&[3]装备属性!$F$309:$F$557,[3]装备属性!$H$309:$H$557)*AE81*6,0)+VLOOKUP(F214,$V$209:$X$216,3,0)*R214+100} -> 1388 | G81: {=_xlfn.XLOOKUP(M81,[3]装备属性!$D$571:$D$870,[3]装备属性!$I$571:$I$870)*6+_xlfn.XLOOKUP(S81&Z81,[3]装备属性!$E$62:$E$277&[3]装备属性!$G$62:$G$277,[3]装备属性!$I$62:$I$277)*6+IFERROR(_xlfn.XLOOKUP(S81&Z81,[3]装备属性!$D$309:$D$557&[3]装备属性!$F$309:$F$557,[3]装备属性!$H$309:$H$557)*AF81*6,0)+VLOOKUP(G214,$V$209:$X$216,3,0)*S214+100} -> 1616 | H81: {=_xlfn.XLOOKUP(N81,[3]装备属性!$D$571:$D$870,[3]装备属性!$I$571:$I$870)*6+_xlfn.XLOOKUP(T81&AA81,[3]装备属性!$E$62:$E$277&[3]装备属性!$G$62:$G$277,[3]装备属性!$I$62:$I$277)*6+IFERROR(_xlfn.XLOOKUP(T81&AA81,[3]装备属性!$D$309:$D$557&[3]装备属性!$F$309:$F$557,[3]装备属性!$H$309:$H$557)*AG81*6,0)+VLOOKUP(H214,$V$209:$X$216,3,0)*T214+100} -> 1906 | J81: 5 | K81: 20 | L81: 22 | M81: 25 | N81: 26 | P81: 5 | Q81: 40 | R81: 40 | S81: 40 | T81: 50 | W81: 5 | X81: =VLOOKUP(INT(L15/10),$AI$77:$AJ$96,2,0) -> 橙 | Y81: =VLOOKUP(INT(M15/10),$AI$77:$AJ$96,2,0) -> 橙 | Z81: =VLOOKUP(INT(N15/10),$AI$77:$AJ$96,2,0) -> 红 | AA81: =VLOOKUP(INT(O15/10),$AI$77:$AJ$96,2,0) -> 红 | AC81: 5 | AD81: 0 | AE81: 0 | AF81: 0 | AG81: 0 | AI81: 5 | AJ81: 红
D82: 6 | E82: {=_xlfn.XLOOKUP(K82,[3]装备属性!$D$571:$D$870,[3]装备属性!$I$571:$I$870)*6+_xlfn.XLOOKUP(Q82&X82,[3]装备属性!$E$62:$E$277&[3]装备属性!$G$62:$G$277,[3]装备属性!$I$62:$I$277)*6+IFERROR(_xlfn.XLOOKUP(Q82&X82,[3]装备属性!$D$309:$D$557&[3]装备属性!$F$309:$F$557,[3]装备属性!$H$309:$H$557)*AD82*6,0)+VLOOKUP(E215,$V$209:$X$216,3,0)*Q215+100} -> 1388 | F82: {=_xlfn.XLOOKUP(L82,[3]装备属性!$D$571:$D$870,[3]装备属性!$I$571:$I$870)*6+_xlfn.XLOOKUP(R82&Y82,[3]装备属性!$E$62:$E$277&[3]装备属性!$G$62:$G$277,[3]装备属性!$I$62:$I$277)*6+IFERROR(_xlfn.XLOOKUP(R82&Y82,[3]装备属性!$D$309:$D$557&[3]装备属性!$F$309:$F$557,[3]装备属性!$H$309:$H$557)*AE82*6,0)+VLOOKUP(F215,$V$209:$X$216,3,0)*R215+100} -> 1602 | G82: {=_xlfn.XLOOKUP(M82,[3]装备属性!$D$571:$D$870,[3]装备属性!$I$571:$I$870)*6+_xlfn.XLOOKUP(S82&Z82,[3]装备属性!$E$62:$E$277&[3]装备属性!$G$62:$G$277,[3]装备属性!$I$62:$I$277)*6+IFERROR(_xlfn.XLOOKUP(S82&Z82,[3]装备属性!$D$309:$D$557&[3]装备属性!$F$309:$F$557,[3]装备属性!$H$309:$H$557)*AF82*6,0)+VLOOKUP(G215,$V$209:$X$216,3,0)*S215+100} -> 1692 | H82: {=_xlfn.XLOOKUP(N82,[3]装备属性!$D$571:$D$870,[3]装备属性!$I$571:$I$870)*6+_xlfn.XLOOKUP(T82&AA82,[3]装备属性!$E$62:$E$277&[3]装备属性!$G$62:$G$277,[3]装备属性!$I$62:$I$277)*6+IFERROR(_xlfn.XLOOKUP(T82&AA82,[3]装备属性!$D$309:$D$557&[3]装备属性!$F$309:$F$557,[3]装备属性!$H$309:$H$557)*AG82*6,0)+VLOOKUP(H215,$V$209:$X$216,3,0)*T215+100} -> 2206 | J82: 6 | K82: 22 | L82: 24 | M82: 27 | N82: 29 | P82: 6 | Q82: 40 | R82: 40 | S82: 40 | T82: 50 | W82: 6 | X82: =VLOOKUP(INT(L16/10),$AI$77:$AJ$96,2,0) -> 橙 | Y82: =VLOOKUP(INT(M16/10),$AI$77:$AJ$96,2,0) -> 红 | Z82: =VLOOKUP(INT(N16/10),$AI$77:$AJ$96,2,0) -> 红 | AA82: =VLOOKUP(INT(O16/10),$AI$77:$AJ$96,2,0) -> 粉 | AC82: 6 | AD82: 0 | AE82: 0 | AF82: 0 | AG82: 0 | AI82: 6 | AJ82: 粉
D83: 7 | E83: {=_xlfn.XLOOKUP(K83,[3]装备属性!$D$571:$D$870,[3]装备属性!$I$571:$I$870)*6+_xlfn.XLOOKUP(Q83&X83,[3]装备属性!$E$62:$E$277&[3]装备属性!$G$62:$G$277,[3]装备属性!$I$62:$I$277)*6+IFERROR(_xlfn.XLOOKUP(Q83&X83,[3]装备属性!$D$309:$D$557&[3]装备属性!$F$309:$F$557,[3]装备属性!$H$309:$H$557)*AD83*6,0)+VLOOKUP(E216,$V$209:$X$216,3,0)*Q216+100} -> 1464 | F83: {=_xlfn.XLOOKUP(L83,[3]装备属性!$D$571:$D$870,[3]装备属性!$I$571:$I$870)*6+_xlfn.XLOOKUP(R83&Y83,[3]装备属性!$E$62:$E$277&[3]装备属性!$G$62:$G$277,[3]装备属性!$I$62:$I$277)*6+IFERROR(_xlfn.XLOOKUP(R83&Y83,[3]装备属性!$D$309:$D$557&[3]装备属性!$F$309:$F$557,[3]装备属性!$H$309:$H$557)*AE83*6,0)+VLOOKUP(F216,$V$209:$X$216,3,0)*R216+100} -> 1786 | G83: {=_xlfn.XLOOKUP(M83,[3]装备属性!$D$571:$D$870,[3]装备属性!$I$571:$I$870)*6+_xlfn.XLOOKUP(S83&Z83,[3]装备属性!$E$62:$E$277&[3]装备属性!$G$62:$G$277,[3]装备属性!$I$62:$I$277)*6+IFERROR(_xlfn.XLOOKUP(S83&Z83,[3]装备属性!$D$309:$D$557&[3]装备属性!$F$309:$F$557,[3]装备属性!$H$309:$H$557)*AF83*6,0)+VLOOKUP(G216,$V$209:$X$216,3,0)*S216+100} -> 1876 | H83: {=_xlfn.XLOOKUP(N83,[3]装备属性!$D$571:$D$870,[3]装备属性!$I$571:$I$870)*6+_xlfn.XLOOKUP(T83&AA83,[3]装备属性!$E$62:$E$277&[3]装备属性!$G$62:$G$277,[3]装备属性!$I$62:$I$277)*6+IFERROR(_xlfn.XLOOKUP(T83&AA83,[3]装备属性!$D$309:$D$557&[3]装备属性!$F$309:$F$557,[3]装备属性!$H$309:$H$557)*AG83*6,0)+VLOOKUP(H216,$V$209:$X$216,3,0)*T216+100} -> 2452 | J83: 7 | K83: 24 | L83: 26 | M83: 29 | N83: 32 | P83: 7 | Q83: 40 | R83: 40 | S83: 40 | T83: 60 | W83: 7 | X83: =VLOOKUP(INT(L17/10),$AI$77:$AJ$96,2,0) -> 橙 | Y83: =VLOOKUP(INT(M17/10),$AI$77:$AJ$96,2,0) -> 红 | Z83: =VLOOKUP(INT(N17/10),$AI$77:$AJ$96,2,0) -> 红 | AA83: =VLOOKUP(INT(O17/10),$AI$77:$AJ$96,2,0) -> 粉 | AC83: 7 | AD83: 0 | AE83: 0 | AF83: 0 | AG83: 0 | AI83: 7 | AJ83: 粉
D84: 8 | E84: {=_xlfn.XLOOKUP(K84,[3]装备属性!$D$571:$D$870,[3]装备属性!$I$571:$I$870)*6+_xlfn.XLOOKUP(Q84&X84,[3]装备属性!$E$62:$E$277&[3]装备属性!$G$62:$G$277,[3]装备属性!$I$62:$I$277)*6+IFERROR(_xlfn.XLOOKUP(Q84&X84,[3]装备属性!$D$309:$D$557&[3]装备属性!$F$309:$F$557,[3]装备属性!$H$309:$H$557)*AD84*6,0)+VLOOKUP(E217,$V$209:$X$216,3,0)*Q217+100} -> 1532 | F84: {=_xlfn.XLOOKUP(L84,[3]装备属性!$D$571:$D$870,[3]装备属性!$I$571:$I$870)*6+_xlfn.XLOOKUP(R84&Y84,[3]装备属性!$E$62:$E$277&[3]装备属性!$G$62:$G$277,[3]装备属性!$I$62:$I$277)*6+IFERROR(_xlfn.XLOOKUP(R84&Y84,[3]装备属性!$D$309:$D$557&[3]装备属性!$F$309:$F$557,[3]装备属性!$H$309:$H$557)*AE84*6,0)+VLOOKUP(F217,$V$209:$X$216,3,0)*R217+100} -> 1966 | G84: {=_xlfn.XLOOKUP(M84,[3]装备属性!$D$571:$D$870,[3]装备属性!$I$571:$I$870)*6+_xlfn.XLOOKUP(S84&Z84,[3]装备属性!$E$62:$E$277&[3]装备属性!$G$62:$G$277,[3]装备属性!$I$62:$I$277)*6+IFERROR(_xlfn.XLOOKUP(S84&Z84,[3]装备属性!$D$309:$D$557&[3]装备属性!$F$309:$F$557,[3]装备属性!$H$309:$H$557)*AF84*6,0)+VLOOKUP(G217,$V$209:$X$216,3,0)*S217+100} -> 2086 | H84: {=_xlfn.XLOOKUP(N84,[3]装备属性!$D$571:$D$870,[3]装备属性!$I$571:$I$870)*6+_xlfn.XLOOKUP(T84&AA84,[3]装备属性!$E$62:$E$277&[3]装备属性!$G$62:$G$277,[3]装备属性!$I$62:$I$277)*6+IFERROR(_xlfn.XLOOKUP(T84&AA84,[3]装备属性!$D$309:$D$557&[3]装备属性!$F$309:$F$557,[3]装备属性!$H$309:$H$557)*AG84*6,0)+VLOOKUP(H217,$V$209:$X$216,3,0)*T217+100} -> 2512 | J84: 8 | K84: 26 | L84: 28 | M84: 32 | N84: 34 | P84: 8 | Q84: 40 | R84: 50 | S84: 50 | T84: 60 | W84: 8 | X84: =VLOOKUP(INT(L18/10),$AI$77:$AJ$96,2,0) -> 橙 | Y84: =VLOOKUP(INT(M18/10),$AI$77:$AJ$96,2,0) -> 红 | Z84: =VLOOKUP(INT(N18/10),$AI$77:$AJ$96,2,0) -> 红 | AA84: =VLOOKUP(INT(O18/10),$AI$77:$AJ$96,2,0) -> 粉 | AC84: 8 | AD84: 0 | AE84: 0 | AF84: 0 | AG84: 0 | AI84: 8 | AJ84: 粉
D85: 9 | E85: {=_xlfn.XLOOKUP(K85,[3]装备属性!$D$571:$D$870,[3]装备属性!$I$571:$I$870)*6+_xlfn.XLOOKUP(Q85&X85,[3]装备属性!$E$62:$E$277&[3]装备属性!$G$62:$G$277,[3]装备属性!$I$62:$I$277)*6+IFERROR(_xlfn.XLOOKUP(Q85&X85,[3]装备属性!$D$309:$D$557&[3]装备属性!$F$309:$F$557,[3]装备属性!$H$309:$H$557)*AD85*6,0)+VLOOKUP(E218,$V$209:$X$216,3,0)*Q218+100} -> 1846 | F85: {=_xlfn.XLOOKUP(L85,[3]装备属性!$D$571:$D$870,[3]装备属性!$I$571:$I$870)*6+_xlfn.XLOOKUP(R85&Y85,[3]装备属性!$E$62:$E$277&[3]装备属性!$G$62:$G$277,[3]装备属性!$I$62:$I$277)*6+IFERROR(_xlfn.XLOOKUP(R85&Y85,[3]装备属性!$D$309:$D$557&[3]装备属性!$F$309:$F$557,[3]装备属性!$H$309:$H$557)*AE85*6,0)+VLOOKUP(F218,$V$209:$X$216,3,0)*R218+100} -> 2026 | G85: {=_xlfn.XLOOKUP(M85,[3]装备属性!$D$571:$D$870,[3]装备属性!$I$571:$I$870)*6+_xlfn.XLOOKUP(S85&Z85,[3]装备属性!$E$62:$E$277&[3]装备属性!$G$62:$G$277,[3]装备属性!$I$62:$I$277)*6+IFERROR(_xlfn.XLOOKUP(S85&Z85,[3]装备属性!$D$309:$D$557&[3]装备属性!$F$309:$F$557,[3]装备属性!$H$309:$H$557)*AF85*6,0)+VLOOKUP(G218,$V$209:$X$216,3,0)*S218+100} -> 2146 | H85: {=_xlfn.XLOOKUP(N85,[3]装备属性!$D$571:$D$870,[3]装备属性!$I$571:$I$870)*6+_xlfn.XLOOKUP(T85&AA85,[3]装备属性!$E$62:$E$277&[3]装备属性!$G$62:$G$277,[3]装备属性!$I$62:$I$277)*6+IFERROR(_xlfn.XLOOKUP(T85&AA85,[3]装备属性!$D$309:$D$557&[3]装备属性!$F$309:$F$557,[3]装备属性!$H$309:$H$557)*AG85*6,0)+VLOOKUP(H218,$V$209:$X$216,3,0)*T218+100} -> 2674 | J85: 9 | K85: 28 | L85: 30 | M85: 34 | N85: 36 | P85: 9 | Q85: 50 | R85: 50 | S85: 50 | T85: 60 | W85: 9 | X85: =VLOOKUP(INT(L19/10),$AI$77:$AJ$96,2,0) -> 红 | Y85: =VLOOKUP(INT(M19/10),$AI$77:$AJ$96,2,0) -> 红 | Z85: =VLOOKUP(INT(N19/10),$AI$77:$AJ$96,2,0) -> 红 | AA85: =VLOOKUP(INT(O19/10),$AI$77:$AJ$96,2,0) -> 粉 | AC85: 9 | AD85: 0 | AE85: 0 | AF85: 0 | AG85: 0 | AI85: 9 | AJ85: 粉
D86: 10 | E86: {=_xlfn.XLOOKUP(K86,[3]装备属性!$D$571:$D$870,[3]装备属性!$I$571:$I$870)*6+_xlfn.XLOOKUP(Q86&X86,[3]装备属性!$E$62:$E$277&[3]装备属性!$G$62:$G$277,[3]装备属性!$I$62:$I$277)*6+IFERROR(_xlfn.XLOOKUP(Q86&X86,[3]装备属性!$D$309:$D$557&[3]装备属性!$F$309:$F$557,[3]装备属性!$H$309:$H$557)*AD86*6,0)+VLOOKUP(E219,$V$209:$X$216,3,0)*Q219+100} -> 1906 | F86: {=_xlfn.XLOOKUP(L86,[3]装备属性!$D$571:$D$870,[3]装备属性!$I$571:$I$870)*6+_xlfn.XLOOKUP(R86&Y86,[3]装备属性!$E$62:$E$277&[3]装备属性!$G$62:$G$277,[3]装备属性!$I$62:$I$277)*6+IFERROR(_xlfn.XLOOKUP(R86&Y86,[3]装备属性!$D$309:$D$557&[3]装备属性!$F$309:$F$557,[3]装备属性!$H$309:$H$557)*AE86*6,0)+VLOOKUP(F219,$V$209:$X$216,3,0)*R219+100} -> 2086 | G86: {=_xlfn.XLOOKUP(M86,[3]装备属性!$D$571:$D$870,[3]装备属性!$I$571:$I$870)*6+_xlfn.XLOOKUP(S86&Z86,[3]装备属性!$E$62:$E$277&[3]装备属性!$G$62:$G$277,[3]装备属性!$I$62:$I$277)*6+IFERROR(_xlfn.XLOOKUP(S86&Z86,[3]装备属性!$D$309:$D$557&[3]装备属性!$F$309:$F$557,[3]装备属性!$H$309:$H$557)*AF86*6,0)+VLOOKUP(G219,$V$209:$X$216,3,0)*S219+100} -> 2428 | H86: {=_xlfn.XLOOKUP(N86,[3]装备属性!$D$571:$D$870,[3]装备属性!$I$571:$I$870)*6+_xlfn.XLOOKUP(T86&AA86,[3]装备属性!$E$62:$E$277&[3]装备属性!$G$62:$G$277,[3]装备属性!$I$62:$I$277)*6+IFERROR(_xlfn.XLOOKUP(T86&AA86,[3]装备属性!$D$309:$D$557&[3]装备属性!$F$309:$F$557,[3]装备属性!$H$309:$H$557)*AG86*6,0)+VLOOKUP(H219,$V$209:$X$216,3,0)*T219+100} -> 2746 | J86: 10 | K86: 30 | L86: 32 | M86: 36 | N86: 38 | P86: 10 | Q86: 50 | R86: 50 | S86: 50 | T86: 60 | W86: 10 | X86: =VLOOKUP(INT(L20/10),$AI$77:$AJ$96,2,0) -> 红 | Y86: =VLOOKUP(INT(M20/10),$AI$77:$AJ$96,2,0) -> 红 | Z86: =VLOOKUP(INT(N20/10),$AI$77:$AJ$96,2,0) -> 粉 | AA86: =VLOOKUP(INT(O20/10),$AI$77:$AJ$96,2,0) -> 粉 | AC86: 10 | AD86: 0 | AE86: 0 | AF86: 0 | AG86: 0 | AI86: 10 | AJ86: 粉
D87: 11 | E87: {=_xlfn.XLOOKUP(K87,[3]装备属性!$D$571:$D$870,[3]装备属性!$I$571:$I$870)*6+_xlfn.XLOOKUP(Q87&X87,[3]装备属性!$E$62:$E$277&[3]装备属性!$G$62:$G$277,[3]装备属性!$I$62:$I$277)*6+IFERROR(_xlfn.XLOOKUP(Q87&X87,[3]装备属性!$D$309:$D$557&[3]装备属性!$F$309:$F$557,[3]装备属性!$H$309:$H$557)*AD87*6,0)+VLOOKUP(E220,$V$209:$X$216,3,0)*Q220+100} -> 1936 | F87: {=_xlfn.XLOOKUP(L87,[3]装备属性!$D$571:$D$870,[3]装备属性!$I$571:$I$870)*6+_xlfn.XLOOKUP(R87&Y87,[3]装备属性!$E$62:$E$277&[3]装备属性!$G$62:$G$277,[3]装备属性!$I$62:$I$277)*6+IFERROR(_xlfn.XLOOKUP(R87&Y87,[3]装备属性!$D$309:$D$557&[3]装备属性!$F$309:$F$557,[3]装备属性!$H$309:$H$557)*AE87*6,0)+VLOOKUP(F220,$V$209:$X$216,3,0)*R220+100} -> 2272 | G87: {=_xlfn.XLOOKUP(M87,[3]装备属性!$D$571:$D$870,[3]装备属性!$I$571:$I$870)*6+_xlfn.XLOOKUP(S87&Z87,[3]装备属性!$E$62:$E$277&[3]装备属性!$G$62:$G$277,[3]装备属性!$I$62:$I$277)*6+IFERROR(_xlfn.XLOOKUP(S87&Z87,[3]装备属性!$D$309:$D$557&[3]装备属性!$F$309:$F$557,[3]装备属性!$H$309:$H$557)*AF87*6,0)+VLOOKUP(G220,$V$209:$X$216,3,0)*S220+100} -> 2656 | H87: {=_xlfn.XLOOKUP(N87,[3]装备属性!$D$571:$D$870,[3]装备属性!$I$571:$I$870)*6+_xlfn.XLOOKUP(T87&AA87,[3]装备属性!$E$62:$E$277&[3]装备属性!$G$62:$G$277,[3]装备属性!$I$62:$I$277)*6+IFERROR(_xlfn.XLOOKUP(T87&AA87,[3]装备属性!$D$309:$D$557&[3]装备属性!$F$309:$F$557,[3]装备属性!$H$309:$H$557)*AG87*6,0)+VLOOKUP(H220,$V$209:$X$216,3,0)*T220+100} -> 2824 | J87: 11 | K87: 31 | L87: 34 | M87: 38 | N87: 40 | P87: 11 | Q87: 50 | R87: 60 | S87: 60 | T87: 60 | W87: 11 | X87: =VLOOKUP(INT(L21/10),$AI$77:$AJ$96,2,0) -> 红 | Y87: =VLOOKUP(INT(M21/10),$AI$77:$AJ$96,2,0) -> 红 | Z87: =VLOOKUP(INT(N21/10),$AI$77:$AJ$96,2,0) -> 粉 | AA87: =VLOOKUP(INT(O21/10),$AI$77:$AJ$96,2,0) -> 粉 | AC87: 11 | AD87: 0 | AE87: 0 | AF87: 0 | AG87: 0 | AI87: 11 | AJ87: 彩
D88: 12 | E88: {=_xlfn.XLOOKUP(K88,[3]装备属性!$D$571:$D$870,[3]装备属性!$I$571:$I$870)*6+_xlfn.XLOOKUP(Q88&X88,[3]装备属性!$E$62:$E$277&[3]装备属性!$G$62:$G$277,[3]装备属性!$I$62:$I$277)*6+IFERROR(_xlfn.XLOOKUP(Q88&X88,[3]装备属性!$D$309:$D$557&[3]装备属性!$F$309:$F$557,[3]装备属性!$H$309:$H$557)*AD88*6,0)+VLOOKUP(E221,$V$209:$X$216,3,0)*Q221+100} -> 1996 | F88: {=_xlfn.XLOOKUP(L88,[3]装备属性!$D$571:$D$870,[3]装备属性!$I$571:$I$870)*6+_xlfn.XLOOKUP(R88&Y88,[3]装备属性!$E$62:$E$277&[3]装备属性!$G$62:$G$277,[3]装备属性!$I$62:$I$277)*6+IFERROR(_xlfn.XLOOKUP(R88&Y88,[3]装备属性!$D$309:$D$557&[3]装备属性!$F$309:$F$557,[3]装备属性!$H$309:$H$557)*AE88*6,0)+VLOOKUP(F221,$V$209:$X$216,3,0)*R221+100} -> 2344 | G88: {=_xlfn.XLOOKUP(M88,[3]装备属性!$D$571:$D$870,[3]装备属性!$I$571:$I$870)*6+_xlfn.XLOOKUP(S88&Z88,[3]装备属性!$E$62:$E$277&[3]装备属性!$G$62:$G$277,[3]装备属性!$I$62:$I$277)*6+IFERROR(_xlfn.XLOOKUP(S88&Z88,[3]装备属性!$D$309:$D$557&[3]装备属性!$F$309:$F$557,[3]装备属性!$H$309:$H$557)*AF88*6,0)+VLOOKUP(G221,$V$209:$X$216,3,0)*S221+100} -> 2734 | H88: {=_xlfn.XLOOKUP(N88,[3]装备属性!$D$571:$D$870,[3]装备属性!$I$571:$I$870)*6+_xlfn.XLOOKUP(T88&AA88,[3]装备属性!$E$62:$E$277&[3]装备属性!$G$62:$G$277,[3]装备属性!$I$62:$I$277)*6+IFERROR(_xlfn.XLOOKUP(T88&AA88,[3]装备属性!$D$309:$D$557&[3]装备属性!$F$309:$F$557,[3]装备属性!$H$309:$H$557)*AG88*6,0)+VLOOKUP(H221,$V$209:$X$216,3,0)*T221+100} -> 3088 | J88: 12 | K88: 33 | L88: 36 | M88: 40 | N88: 42 | P88: 12 | Q88: 50 | R88: 60 | S88: 60 | T88: 70 | W88: 12 | X88: =VLOOKUP(INT(L22/10),$AI$77:$AJ$96,2,0) -> 红 | Y88: =VLOOKUP(INT(M22/10),$AI$77:$AJ$96,2,0) -> 红 | Z88: =VLOOKUP(INT(N22/10),$AI$77:$AJ$96,2,0) -> 粉 | AA88: =VLOOKUP(INT(O22/10),$AI$77:$AJ$96,2,0) -> 粉 | AC88: 12 | AD88: 0 | AE88: 0 | AF88: 0 | AG88: 0 | AI88: 12 | AJ88: 彩
D89: 13 | E89: {=_xlfn.XLOOKUP(K89,[3]装备属性!$D$571:$D$870,[3]装备属性!$I$571:$I$870)*6+_xlfn.XLOOKUP(Q89&X89,[3]装备属性!$E$62:$E$277&[3]装备属性!$G$62:$G$277,[3]装备属性!$I$62:$I$277)*6+IFERROR(_xlfn.XLOOKUP(Q89&X89,[3]装备属性!$D$309:$D$557&[3]装备属性!$F$309:$F$557,[3]装备属性!$H$309:$H$557)*AD89*6,0)+VLOOKUP(E222,$V$209:$X$216,3,0)*Q222+100} -> 2152 | F89: {=_xlfn.XLOOKUP(L89,[3]装备属性!$D$571:$D$870,[3]装备属性!$I$571:$I$870)*6+_xlfn.XLOOKUP(R89&Y89,[3]装备属性!$E$62:$E$277&[3]装备属性!$G$62:$G$277,[3]装备属性!$I$62:$I$277)*6+IFERROR(_xlfn.XLOOKUP(R89&Y89,[3]装备属性!$D$309:$D$557&[3]装备属性!$F$309:$F$557,[3]装备属性!$H$309:$H$557)*AE89*6,0)+VLOOKUP(F222,$V$209:$X$216,3,0)*R222+100} -> 2380 | G89: {=_xlfn.XLOOKUP(M89,[3]装备属性!$D$571:$D$870,[3]装备属性!$I$571:$I$870)*6+_xlfn.XLOOKUP(S89&Z89,[3]装备属性!$E$62:$E$277&[3]装备属性!$G$62:$G$277,[3]装备属性!$I$62:$I$277)*6+IFERROR(_xlfn.XLOOKUP(S89&Z89,[3]装备属性!$D$309:$D$557&[3]装备属性!$F$309:$F$557,[3]装备属性!$H$309:$H$557)*AF89*6,0)+VLOOKUP(G222,$V$209:$X$216,3,0)*S222+100} -> 2776 | H89: {=_xlfn.XLOOKUP(N89,[3]装备属性!$D$571:$D$870,[3]装备属性!$I$571:$I$870)*6+_xlfn.XLOOKUP(T89&AA89,[3]装备属性!$E$62:$E$277&[3]装备属性!$G$62:$G$277,[3]装备属性!$I$62:$I$277)*6+IFERROR(_xlfn.XLOOKUP(T89&AA89,[3]装备属性!$D$309:$D$557&[3]装备属性!$F$309:$F$557,[3]装备属性!$H$309:$H$557)*AG89*6,0)+VLOOKUP(H222,$V$209:$X$216,3,0)*T222+100} -> 3172 | J89: 13 | K89: 34 | L89: 37 | M89: 41 | N89: 44 | P89: 13 | Q89: 60 | R89: 60 | S89: 60 | T89: 70 | W89: 13 | X89: =VLOOKUP(INT(L23/10),$AI$77:$AJ$96,2,0) -> 红 | Y89: =VLOOKUP(INT(M23/10),$AI$77:$AJ$96,2,0) -> 红 | Z89: =VLOOKUP(INT(N23/10),$AI$77:$AJ$96,2,0) -> 粉 | AA89: =VLOOKUP(INT(O23/10),$AI$77:$AJ$96,2,0) -> 粉 | AC89: 13 | AD89: 0 | AE89: 0 | AF89: 0 | AG89: 0 | AI89: 13 | AJ89: 彩
... D96: 20 | E96: {=_xlfn.XLOOKUP(K96,[3]装备属性!$D$571:$D$870,[3]装备属性!$I$571:$I$870)*6+_xlfn.XLOOKUP(Q96&X96,[3]装备属性!$E$62:$E$277&[3]装备属性!$G$62:$G$277,[3]装备属性!$I$62:$I$277)*6+IFERROR(_xlfn.XLOOKUP(Q96&X96,[3]装备属性!$D$309:$D$557&[3]装备属性!$F$309:$F$557,[3]装备属性!$H$309:$H$557)*AD96*6,0)+VLOOKUP(E229,$V$209:$X$216,3,0)*Q229+100} -> 2620 | F96: {=_xlfn.XLOOKUP(L96,[3]装备属性!$D$571:$D$870,[3]装备属性!$I$571:$I$870)*6+_xlfn.XLOOKUP(R96&Y96,[3]装备属性!$E$62:$E$277&[3]装备属性!$G$62:$G$277,[3]装备属性!$I$62:$I$277)*6+IFERROR(_xlfn.XLOOKUP(R96&Y96,[3]装备属性!$D$309:$D$557&[3]装备属性!$F$309:$F$557,[3]装备属性!$H$309:$H$557)*AE96*6,0)+VLOOKUP(F229,$V$209:$X$216,3,0)*R229+100} -> 3208 | G96: {=_xlfn.XLOOKUP(M96,[3]装备属性!$D$571:$D$870,[3]装备属性!$I$571:$I$870)*6+_xlfn.XLOOKUP(S96&Z96,[3]装备属性!$E$62:$E$277&[3]装备属性!$G$62:$G$277,[3]装备属性!$I$62:$I$277)*6+IFERROR(_xlfn.XLOOKUP(S96&Z96,[3]装备属性!$D$309:$D$557&[3]装备属性!$F$309:$F$557,[3]装备属性!$H$309:$H$557)*AF96*6,0)+VLOOKUP(G229,$V$209:$X$216,3,0)*S229+100} -> 3412 | H96: {=_xlfn.XLOOKUP(N96,[3]装备属性!$D$571:$D$870,[3]装备属性!$I$571:$I$870)*6+_xlfn.XLOOKUP(T96&AA96,[3]装备属性!$E$62:$E$277&[3]装备属性!$G$62:$G$277,[3]装备属性!$I$62:$I$277)*6+IFERROR(_xlfn.XLOOKUP(T96&AA96,[3]装备属性!$D$309:$D$557&[3]装备属性!$F$309:$F$557,[3]装备属性!$H$309:$H$557)*AG96*6,0)+VLOOKUP(H229,$V$209:$X$216,3,0)*T229+100} -> 3886 | J96: 20 | K96: 43 | L96: 47 | M96: 51 | N96: 54 | P96: 20 | Q96: 60 | R96: 70 | S96: 70 | T96: 80 | W96: 20 | X96: =VLOOKUP(INT(L30/10),$AI$77:$AJ$96,2,0) -> 红 | Y96: =VLOOKUP(INT(M30/10),$AI$77:$AJ$96,2,0) -> 粉 | Z96: =VLOOKUP(INT(N30/10),$AI$77:$AJ$96,2,0) -> 粉 | AA96: =VLOOKUP(INT(O30/10),$AI$77:$AJ$96,2,0) -> 粉 | AC96: 20 | AD96: 0 | AE96: 0 | AF96: 0 | AG96: 0 | AI96: 20 | AJ96: 彩
D97: 21 | E97: {=_xlfn.XLOOKUP(K97,[3]装备属性!$D$571:$D$870,[3]装备属性!$I$571:$I$870)*6+_xlfn.XLOOKUP(Q97&X97,[3]装备属性!$E$62:$E$277&[3]装备属性!$G$62:$G$277,[3]装备属性!$I$62:$I$277)*6+IFERROR(_xlfn.XLOOKUP(Q97&X97,[3]装备属性!$D$309:$D$557&[3]装备属性!$F$309:$F$557,[3]装备属性!$H$309:$H$557)*AD97*6,0)+VLOOKUP(E230,$V$209:$X$216,3,0)*Q230+100} -> 2848 | F97: {=_xlfn.XLOOKUP(L97,[3]装备属性!$D$571:$D$870,[3]装备属性!$I$571:$I$870)*6+_xlfn.XLOOKUP(R97&Y97,[3]装备属性!$E$62:$E$277&[3]装备属性!$G$62:$G$277,[3]装备属性!$I$62:$I$277)*6+IFERROR(_xlfn.XLOOKUP(R97&Y97,[3]装备属性!$D$309:$D$557&[3]装备属性!$F$309:$F$557,[3]装备属性!$H$309:$H$557)*AE97*6,0)+VLOOKUP(F230,$V$209:$X$216,3,0)*R230+100} -> 3256 | G97: {=_xlfn.XLOOKUP(M97,[3]装备属性!$D$571:$D$870,[3]装备属性!$I$571:$I$870)*6+_xlfn.XLOOKUP(S97&Z97,[3]装备属性!$E$62:$E$277&[3]装备属性!$G$62:$G$277,[3]装备属性!$I$62:$I$277)*6+IFERROR(_xlfn.XLOOKUP(S97&Z97,[3]装备属性!$D$309:$D$557&[3]装备属性!$F$309:$F$557,[3]装备属性!$H$309:$H$557)*AF97*6,0)+VLOOKUP(G230,$V$209:$X$216,3,0)*S230+100} -> 3472 | H97: {=_xlfn.XLOOKUP(N97,[3]装备属性!$D$571:$D$870,[3]装备属性!$I$571:$I$870)*6+_xlfn.XLOOKUP(T97&AA97,[3]装备属性!$E$62:$E$277&[3]装备属性!$G$62:$G$277,[3]装备属性!$I$62:$I$277)*6+IFERROR(_xlfn.XLOOKUP(T97&AA97,[3]装备属性!$D$309:$D$557&[3]装备属性!$F$309:$F$557,[3]装备属性!$H$309:$H$557)*AG97*6,0)+VLOOKUP(H230,$V$209:$X$216,3,0)*T230+100} -> 3946 | J97: 21 | K97: 45 | L97: 48 | M97: 52 | N97: 55 | P97: 21 | Q97: 70 | R97: 70 | S97: 70 | T97: 80 | W97: 21 | X97: =VLOOKUP(INT(L31/10),$AI$77:$AJ$96,2,0) -> 红 | Y97: =VLOOKUP(INT(M31/10),$AI$77:$AJ$96,2,0) -> 粉 | Z97: =VLOOKUP(INT(N31/10),$AI$77:$AJ$96,2,0) -> 粉 | AA97: =VLOOKUP(INT(O31/10),$AI$77:$AJ$96,2,0) -> 粉 | AC97: 21 | AD97: 0 | AE97: 0 | AF97: 0 | AG97: 0
D98: 22 | E98: {=_xlfn.XLOOKUP(K98,[3]装备属性!$D$571:$D$870,[3]装备属性!$I$571:$I$870)*6+_xlfn.XLOOKUP(Q98&X98,[3]装备属性!$E$62:$E$277&[3]装备属性!$G$62:$G$277,[3]装备属性!$I$62:$I$277)*6+IFERROR(_xlfn.XLOOKUP(Q98&X98,[3]装备属性!$D$309:$D$557&[3]装备属性!$F$309:$F$557,[3]装备属性!$H$309:$H$557)*AD98*6,0)+VLOOKUP(E231,$V$209:$X$216,3,0)*Q231+100} -> 2890 | F98: {=_xlfn.XLOOKUP(L98,[3]装备属性!$D$571:$D$870,[3]装备属性!$I$571:$I$870)*6+_xlfn.XLOOKUP(R98&Y98,[3]装备属性!$E$62:$E$277&[3]装备属性!$G$62:$G$277,[3]装备属性!$I$62:$I$277)*6+IFERROR(_xlfn.XLOOKUP(R98&Y98,[3]装备属性!$D$309:$D$557&[3]装备属性!$F$309:$F$557,[3]装备属性!$H$309:$H$557)*AE98*6,0)+VLOOKUP(F231,$V$209:$X$216,3,0)*R231+100} -> 3304 | G98: {=_xlfn.XLOOKUP(M98,[3]装备属性!$D$571:$D$870,[3]装备属性!$I$571:$I$870)*6+_xlfn.XLOOKUP(S98&Z98,[3]装备属性!$E$62:$E$277&[3]装备属性!$G$62:$G$277,[3]装备属性!$I$62:$I$277)*6+IFERROR(_xlfn.XLOOKUP(S98&Z98,[3]装备属性!$D$309:$D$557&[3]装备属性!$F$309:$F$557,[3]装备属性!$H$309:$H$557)*AF98*6,0)+VLOOKUP(G231,$V$209:$X$216,3,0)*S231+100} -> 3532 | H98: {=_xlfn.XLOOKUP(N98,[3]装备属性!$D$571:$D$870,[3]装备属性!$I$571:$I$870)*6+_xlfn.XLOOKUP(T98&AA98,[3]装备属性!$E$62:$E$277&[3]装备属性!$G$62:$G$277,[3]装备属性!$I$62:$I$277)*6+IFERROR(_xlfn.XLOOKUP(T98&AA98,[3]装备属性!$D$309:$D$557&[3]装备属性!$F$309:$F$557,[3]装备属性!$H$309:$H$557)*AG98*6,0)+VLOOKUP(H231,$V$209:$X$216,3,0)*T231+100} -> 4006 | J98: 22 | K98: 46 | L98: 49 | M98: 53 | N98: 56 | P98: 22 | Q98: 70 | R98: 70 | S98: 70 | T98: 80 | W98: 22 | X98: =VLOOKUP(INT(L32/10),$AI$77:$AJ$96,2,0) -> 红 | Y98: =VLOOKUP(INT(M32/10),$AI$77:$AJ$96,2,0) -> 粉 | Z98: =VLOOKUP(INT(N32/10),$AI$77:$AJ$96,2,0) -> 粉 | AA98: =VLOOKUP(INT(O32/10),$AI$77:$AJ$96,2,0) -> 粉 | AC98: 22 | AD98: 0 | AE98: 0 | AF98: 0 | AG98: 0
D99: 23 | E99: {=_xlfn.XLOOKUP(K99,[3]装备属性!$D$571:$D$870,[3]装备属性!$I$571:$I$870)*6+_xlfn.XLOOKUP(Q99&X99,[3]装备属性!$E$62:$E$277&[3]装备属性!$G$62:$G$277,[3]装备属性!$I$62:$I$277)*6+IFERROR(_xlfn.XLOOKUP(Q99&X99,[3]装备属性!$D$309:$D$557&[3]装备属性!$F$309:$F$557,[3]装备属性!$H$309:$H$557)*AD99*6,0)+VLOOKUP(E232,$V$209:$X$216,3,0)*Q232+100} -> 3208 | F99: {=_xlfn.XLOOKUP(L99,[3]装备属性!$D$571:$D$870,[3]装备属性!$I$571:$I$870)*6+_xlfn.XLOOKUP(R99&Y99,[3]装备属性!$E$62:$E$277&[3]装备属性!$G$62:$G$277,[3]装备属性!$I$62:$I$277)*6+IFERROR(_xlfn.XLOOKUP(R99&Y99,[3]装备属性!$D$309:$D$557&[3]装备属性!$F$309:$F$557,[3]装备属性!$H$309:$H$557)*AE99*6,0)+VLOOKUP(F232,$V$209:$X$216,3,0)*R232+100} -> 3412 | G99: {=_xlfn.XLOOKUP(M99,[3]装备属性!$D$571:$D$870,[3]装备属性!$I$571:$I$870)*6+_xlfn.XLOOKUP(S99&Z99,[3]装备属性!$E$62:$E$277&[3]装备属性!$G$62:$G$277,[3]装备属性!$I$62:$I$277)*6+IFERROR(_xlfn.XLOOKUP(S99&Z99,[3]装备属性!$D$309:$D$557&[3]装备属性!$F$309:$F$557,[3]装备属性!$H$309:$H$557)*AF99*6,0)+VLOOKUP(G232,$V$209:$X$216,3,0)*S232+100} -> 3592 | H99: {=_xlfn.XLOOKUP(N99,[3]装备属性!$D$571:$D$870,[3]装备属性!$I$571:$I$870)*6+_xlfn.XLOOKUP(T99&AA99,[3]装备属性!$E$62:$E$277&[3]装备属性!$G$62:$G$277,[3]装备属性!$I$62:$I$277)*6+IFERROR(_xlfn.XLOOKUP(T99&AA99,[3]装备属性!$D$309:$D$557&[3]装备属性!$F$309:$F$557,[3]装备属性!$H$309:$H$557)*AG99*6,0)+VLOOKUP(H232,$V$209:$X$216,3,0)*T232+100} -> 4126 | J99: 23 | K99: 47 | L99: 51 | M99: 54 | N99: 58 | P99: 23 | Q99: 70 | R99: 70 | S99: 70 | T99: 80 | W99: 23 | X99: =VLOOKUP(INT(L33/10),$AI$77:$AJ$96,2,0) -> 粉 | Y99: =VLOOKUP(INT(M33/10),$AI$77:$AJ$96,2,0) -> 粉 | Z99: =VLOOKUP(INT(N33/10),$AI$77:$AJ$96,2,0) -> 粉 | AA99: =VLOOKUP(INT(O33/10),$AI$77:$AJ$96,2,0) -> 粉 | AC99: 23 | AD99: 0 | AE99: 0 | AF99: 0 | AG99: 0
...

Sheet 属性规划（旧）
C2: 属性对关卡贡献预期
D4: 1、角色基础面板以第十关为基础，后续每关释放7%给各个系统
F6: #偏泛用户 | G6: #梦灵易达成，后续转向符文 | I6: #外观为主 | K6: 额外20%
D7: 天数 | E7: 主要内容 | F7: 装备成长 | G7: 梦灵成长 | H7: 符文成长 | I7: 宠物成长 | J7: 主角成长 | K7: 赛季养成
D8: 1 | E8: 梦灵+装备 | F8: =1-SUM(G8:J8) -> 0.4 | G8: 0.35 | H8: 0.2 | J8: 0.05 | K8: 0.2
D9: 2 | E9: 梦灵+装备 | F9: =1-SUM(G9:J9) -> 0.4 | G9: 0.35 | H9: 0.2 | J9: 0.05 | K9: 0.2
D10: 3 | E10: 梦灵+装备 | F10: =1-SUM(G10:J10) -> 0.35 | G10: 0.35 | H10: 0.2 | I10: 0.05 | J10: 0.05 | K10: 0.2
D11: 5 | E11: 梦灵+装备 | F11: =1-SUM(G11:J11) -> 0.35 | G11: 0.35 | H11: 0.2 | I11: 0.05 | J11: 0.05 | K11: 0.2
D12: 7 | E12: 梦灵+装备 | F12: =1-SUM(G12:J12) -> 0.35 | G12: 0.32 | H12: 0.2 | I12: 0.08 | J12: 0.05 | K12: 0.2
D13: 10 | E13: 梦灵周期 | F13: =1-SUM(G13:J13) -> 0.33 | G13: 0.32 | H13: 0.22 | I13: 0.08 | J13: 0.05 | K13: 0.2
D14: 14 | E14: 符文周期 | F14: =1-SUM(G14:J14) -> 0.32 | G14: 0.32 | H14: 0.23 | I14: 0.08 | J14: 0.05 | K14: 0.2
D15: 20 | E15: 宠物周期 | F15: =1-SUM(G15:J15) -> 0.3 | G15: 0.3 | H15: 0.27 | I15: 0.08 | J15: 0.05 | K15: 0.2
D16: 27 | E16: 梦灵周期 | F16: =1-SUM(G16:J16) -> 0.3 | G16: 0.27 | H16: 0.28 | I16: 0.1 | J16: 0.05 | K16: 0.2
D17: 34 | E17: 符文周期 | F17: =1-SUM(G17:J17) -> 0.3 | G17: 0.27 | H17: 0.28 | I17: 0.1 | J17: 0.05 | K17: 0.2
D18: 41 | E18: 宠物周期 | F18: =1-SUM(G18:J18) -> 0.3 | G18: 0.25 | H18: 0.3 | I18: 0.1 | J18: 0.05 | K18: 0.2
D19: 48 | E19: 清仓甩卖 | F19: =1-SUM(G19:J19) -> 0.3 | G19: 0.25 | H19: 0.3 | I19: 0.1 | J19: 0.05 | K19: 0.2
D20: 55 | F20: =1-SUM(G20:J20) -> 0.3 | G20: 0.25 | H20: 0.3 | I20: 0.1 | J20: 0.05 | K20: 0.2
D21: 62 | F21: =1-SUM(G21:J21) -> 0.3 | G21: 0.25 | H21: 0.3 | I21: 0.1 | J21: 0.05 | K21: 0.2
D24: 2、以当前版本的七天双卡玩家为例，梦灵系统在当前版本上的占比最高
D26: 系统名 | E26: 养成玩法 | F26: 标准模板(10关) | G26: 属性贡献(七天) | H26: 关卡贡献 | I26: 玩法地位
D27: 装备系统 | E27: 装备攻击 | F27: =OFFSET($F$58,0,J27) -> 450 | G27: =OFFSET($F$76,0,J27) -> 1500 | H27: =OFFSET($F$80,0,J27) -> 15.376355 | I27: =SUM(H27:H28)/SUM($H$27:$H$42)*0.95 -> 0.49702681 | J27: 1
E28: 装备词条 | F28: =OFFSET($F$58,0,J28) -> 1 | G28: =OFFSET($F$76,0,J28) -> 1.2 | H28: =OFFSET($F$80,0,J28) -> 3.1533304 | J28: 2
D29: 梦灵系统 | E29: 主技能倍率 | F29: =OFFSET($F$58,0,J29) -> 1.15 | G29: =OFFSET($F$76,0,J29) -> 1.35 | H29: =OFFSET($F$80,0,J29) -> 2.4247488 | I29: =SUM(H29:H33)/SUM($H$27:$H$42)*0.95 -> 0.14042543 | J29: 3
E30: 升阶系数 | F30: =OFFSET($F$58,0,J30) -> 1 | G30: =OFFSET($F$76,0,J30) -> 1 | H30: =OFFSET($F$80,0,J30) -> 0 | J30: 4
E31: 皮肤倍率 | F31: =OFFSET($F$58,0,J31) -> 1 | G31: =OFFSET($F$76,0,J31) -> 1 | H31: =OFFSET($F$80,0,J31) -> 0 | J31: 5
E32: 卡带加成 | F32: =OFFSET($F$58,0,J32) -> 1 | G32: =OFFSET($F$76,0,J32) -> 1.1 | H32: =OFFSET($F$80,0,J32) -> 1.6484309 | J32: 6
E33: 等级系数 | F33: =OFFSET($F$58,0,J33) -> 1.2 | G33: =OFFSET($F$76,0,J33) -> 1.3 | H33: =OFFSET($F$80,0,J33) -> 1.1620289 | J33: 7
D34: 符文系统 | E34: 符文攻击 | F34: =OFFSET($F$58,0,J34) -> 80 | G34: =OFFSET($F$76,0,J34) -> 180 | H34: =OFFSET($F$80,0,J34) -> 1.6750066 | I34: =SUM(H34:H39)/SUM(H27:H42)*0.95 -> 0.31254776 | J34: 8
E35: 梦灵增伤 | F35: =OFFSET($F$58,0,J35) -> 1.16 | G35: =OFFSET($F$76,0,J35) -> 1.5 | H35: =OFFSET($F$80,0,J35) -> 3.8549632 | J35: 9
E36: 怪物增伤 | F36: =OFFSET($F$58,0,J36) -> 1.1 | G36: =OFFSET($F$76,0,J36) -> 1.8 | J36: 10
E37: 专属符文 | F37: =OFFSET($F$58,0,J37) -> 1 | G37: =OFFSET($F$76,0,J37) -> 1.28 | H37: =OFFSET($F$80,0,J37) -> 4.2695521 | J37: 11
E38: 特殊符文 | F38: =OFFSET($F$58,0,J38) -> 1 | G38: =OFFSET($F$76,0,J38) -> 1 | H38: =OFFSET($F$80,0,J38) -> 0 | J38: 12
E39: 暴击收益 | F39: =OFFSET($F$58,0,J39) -> 1.03 | G39: =OFFSET($F$76,0,J39) -> 1.15 | H39: =OFFSET($F$80,0,J39) -> 1.8525888 | J39: 13
E40: 暴击伤害 | F40: =OFFSET($F$58,0,J40) -> 1.6 | G40: =OFFSET($F$76,0,J40) -> 4 | H40: =OFFSET($F$80,0,J40) -> 0 | J40: 14
E41: 体系增伤 | F41: =OFFSET($F$58,0,J41) -> 1 | G41: =OFFSET($F$76,0,J41) -> 1 | H41: =OFFSET($F$80,0,J41) -> 0 | J41: 15
D42: 宠物系统 | E42: 宠物升级 | F42: =OFFSET($F$58,0,J42) -> 0 | G42: =OFFSET($F$76,0,J42) -> 0 | H42: =OFFSET($F$80,0,J42) -> 0 | I42: 0.05 | J42: 16
C45: 属性计算细节
D47: 符文规划
E48: 共六个符文乘区，每个独立乘区都是可稀释的衰减
E49: 1、梦灵增伤=>满血增伤/残血增伤
...

Sheet 属性规划(新)
C2: 规划模块
C4: 一、解决什么问题
D5: 提供稳定长线模型预期 | M5: #肉盾增伤验证
C6: 大类 | D6: 模块 | E6: 列1 | F6: 性质 | G6: 商业化性质 | H6: 养成预期 | I6: 膨胀周期 | J6: 验证类型 | K6: 极限关卡 | L6: 列5 | M6: 分层体验 | N6: 列6 | O6: 列7 | P6: 列8
C7: 基础模块1 | D7: 装备 | E7: 本体+强化+洗练 | F7: 会迭代，不适合投入超额付费 | G7: 无商业化 | H7: 每天100攻击+符文 | I7: 60天 | J7: 强验证 | K7: 每个周期局外拓展10关
C8: 基础模块2 | D8: 梦灵 | E8: 梦灵本体+升级 | F8: 会迭代，不适合投入超额付费，品质付费保留爆伤收益 | G8: 弱商业化，强反馈 | H8: 单梦灵25级极限 | K8: 每个周期局外拓展20关
C9: 迭代模块1 | D9: 符文 | E9: 符文洗练 | F9: 符文基础，提供洗练机会 | G9: 强商业化，弱反馈 | I9: 60天 | J9: 弱验证 | K9: 每个周期局外拓展80关 | M9: 非R3周期养60%,超R单周期养满,60天拓新系统
C10: 迭代模块2 | D10: 秘宝
C11: 迭代模块3 | D11: 主角皮肤 | E11: 皮肤本体+升星 | F11: 会迭代，跟关卡稀释，皮肤付费后保留攻击收益 | G11: 弱商业化，强反馈 | I11: 30天 | J11: 强验证 | K11: 每个周期局外拓展0
C12: 迭代模块4 | D12: 武器皮肤
C14: 二、实现逻辑
D15: 装备模块
E16: 前期靠战力提升，后期靠符文装、图腾装等洗练词条撑起来关卡数稳定
D17: 梦灵模块
E18: 梦灵品质 | F18: 梦灵倍率 | G18: 等级成长 | L18: 梦灵
E19: 3 | F19: 1.15 | G19: 0.05 | L19: 初始成长
E20: 4 | F20: 1.3 | G20: 0.06
E21: 5 | F21: 1.65 | G21: 0.1
E22: 6 | F22: =F21*2 -> 3.3 | G22: 0.1
E23: 7 | F23: =F22*2 -> 6.6 | G23: 0.1
E24: 7 | F24: =F23*2 -> 13.2 | G24: 0.1
E25: 8 | F25: =F24*2 -> 26.4 | G25: 0.1
E26: 9 | F26: =F25*2 -> 52.8 | G26: 0.1
E27: 10 | F27: =F26*2 -> 105.6 | G27: 0.1
E29: 梦灵品质：60天拓展一个品质（如蔚蓝哥斯拉间隔哪吒60天视作不同品质）
E30: 梦灵倍率：梦灵初始倍率大量膨胀，活动付费把梦灵推到10级，10级新品质高于旧品质梦灵25级强度。
E31: 梦灵等级成长：作为梦灵基础成长线，锚定10%的成长作为标准，20级时提升1级依旧有半关的体验
E32: 强验证：每个版本给关卡带入梦灵新系数（非该梦灵预期更难打过关卡）
D34: 符文模块
E35: 符文洗练通过性价比控制，低档次符文极限推关约100关
E36: 高档次符文性价比高于锚定50000钻石20%成长的预期
C39: 单关成长 | D39: 1.07 | E39: =LOG(1+D42,D39) -> 2.6947266
C41: 玩家层级 | D41: 锚定体验 | E41: 单关标准（钻石） | F41: 预期价格（钻石） | G41: 单关RMB
C42: 超R | D42: 0.2 | E42: =F42/LOG(D42+1,1.07) -> 18554.758 | F42: 50000 | G42: =E42/10 -> 1855.4758 | I42: 实际上这里砖比都是1：100
C43: 大R | D43: 0.2 | E43: =F43/LOG(D43+1,1.07) -> 3710.9517 | F43: 10000 | G43: =E43/10 -> 371.09517
C44: 中R | D44: 0.2 | E44: =F44/LOG(D44+1,1.07) -> 1113.2855 | F44: 3000 | G44: =E44/10 -> 111.32855
C45: 小R | D45: 0.2 | E45: =F45/LOG(D45+1,1.07) -> 371.09517 | F45: 1000 | G45: =E45/10 -> 37.109517
C48: 类型 | D48: 皮肤品质 | E48: 门槛强度 | F48: 白板数值 | G48: 定价 | H48: 回收价 | I48: 新回收价 | J48: 单关定价 | K48: 用户 | L48: 每点攻击价格 | M48: 每点倍率价格 | N48: 列2 | O48: 列12
A49: =IF(D49=$D$49,4,IF(D49=$D$50,5,6)) -> 4 | C49: 梦灵皮肤 | D49: 紫 | E49: =35% -> 0.35 | F49: 30 | G49: 1500 | H49: 300 | I49: 300 | J49: =IFERROR(G49/LOG(1+E49,1.07)+F49*5,0) -> 488.17534 | K49: =OFFSET($C$41,MATCH(J49,$E$42:$E$45,-1)+1,0) -> 小R | L49: =G49/F49 -> 50 | M49: =IFERROR(INT(G49/E49/100),"") -> 42 | N49: 皮肤倍率不保值，攻击做保值
A50: =IF(D50=$D$49,4,IF(D50=$D$50,5,6)) -> 5 | C50: 梦灵皮肤 | D50: 橙 | E50: =35% -> 0.35 | F50: 60 | G50: 4000 | H50: 1200 | I50: 2000 | J50: =IFERROR(G50/LOG(1+E50,1.07)+F50*5,0) -> 1201.8009 | K50: =OFFSET($C$41,MATCH(J50,$E$42:$E$45,-1)+1,0) -> 中R | L50: =G50/F50 -> 66.666667 | M50: =IFERROR(INT(G50/E50/100),"") -> 114
...

Sheet 玩法产出(新)
A2: 符文模块
B4: 充值金额 | C4: 符文洗练 | D4: 钻石价值
B5: 328 | C5: =24 -> 24 | D5: =C5*60 -> 1440
B6: 40000 | C6: =INT(B6/B5*C5) -> 2926 | D6: =C6*60 -> 175560
U7: A系统 | W7: B系统
C8: 增幅 | F8: 价格/钻石 | U8: 5万块钱 | W8: 10万
B9: 档次 | C9: 橙 | D9: 红 | E9: 粉 | F9: 橙 | G9: 红 | H9: 粉
B10: 3 | C10: 0.1 | D10: 0.125 | E10: 0.16 | F10: 5000 | G10: =F10*2 -> 10000 | H10: =G10*2 -> 20000 | I10: =$D$6/F10 -> 35.112 | J10: =$D$6/G10 -> 17.556 | N10: a | O10: bn | P10: c
B11: 4 | C11: 0.25 | D11: 0.32 | E11: 0.4 | F11: 12000 | G11: =F11*2 -> 24000 | H11: =G11*2 -> 48000 | I11: =$D$6/F11 -> 14.63 | J11: =$D$6/G11 -> 7.315 | N11: 2 | O11: 2 | P11: 2
B12: 5 | C12: 0.32 | D12: 0.4 | E12: 0.5 | F12: 25000 | G12: =F12*2 -> 50000 | H12: =G12*2 -> 100000 | I12: =$D$6/F12 -> 7.0224 | J12: =$D$6/G12 -> 3.5112 | N12: 46315
B13: 6 | C13: 0.2 | D13: 0.25 | E13: 0.32 | F13: 50000 | G13: =F13*2 -> 100000 | H13: =G13*2 -> 200000 | I13: =$D$6/F13 -> 3.5112 | J13: =$D$6/G13 -> 1.7556
N14: 5 | P14: 2 | Q14: 2 | R14: 4
N15: 50000
P16: 2
D17: 档次收益 | P17: 50000
B18: 等级 | C18: 攻击 | D18: 1 | E18: 2 | F18: 3 | G18: 4 | H18: 5 | I18: 6
B19: 白 | C19: 4 | D19: =E19 -> 0.02 | E19: 0.02
B20: 绿 | C20: =C19+4 -> 8 | D20: =E20 -> 0.03 | E20: 0.03
B21: 蓝 | C21: =C20+4 -> 12 | D21: =E21 -> 0.04 | E21: 0.04 | F21: 0.06 | G21: 0.075
B22: 紫 | C22: =C21+4 -> 16 | D22: =E22 -> 0.05 | E22: 0.05 | F22: 0.075 | G22: 0.1 | H22: 0.125 | I22: 0.15
B23: 橙 | C23: =C22+4 -> 20 | D23: =E23 -> 0.0625 | E23: 0.0625 | F23: 0.1 | G23: 0.25 | H23: 0.32 | I23: 0.2
B24: 红 | C24: =C23+4 -> 24 | D24: =E24 -> 0.075 | E24: 0.075 | F24: 0.125 | G24: 0.32 | H24: 0.4 | I24: 0.25
B25: 彩 | C25: =C24+4 -> 28 | D25: =E25 -> 0.1 | E25: 0.1 | F25: 0.16 | G25: 0.4 | H25: 0.5 | I25: 0.32
A28: 梦灵模块

Sheet 玩法框架
A2: 玩法规划
B3: 日常为标准产出，限次对标新手期的核心步长产出
F4: 设计思路 | L4: 100 | N4: 150
B5: 所属模块 | C5: 玩法名 | D5: 开启时间 | E5: 功能定位 | F5: 核心产出 | G5: 产出定位 | H5: 长周期占比 | I5: 分层方式 | M5: 125
B6: 卡牌PVE | C6: 主线推图 | D6: 初始 | E6: 多英雄练度验证 | G6: （一次性投放） | I6: 速率+能力 | Q6: =80+185 -> 265
B7: 卡牌PVP | C7: 情绪净化_单人 | D7: 第五关 | E7: 弱PVP冲榜 | F7: 招募券、金币 | I7: 活跃 | Q7: =Q6/2 -> 132.5
B8: 卡牌GVE | C8: 梦域巡航 | D8: 第十关 | E8: 最强一队验证 | F8: 装备 | I8: 速率+能力 | R8: =0.85-0.2 -> 0.65
B9: 卡牌GVG | C9: 情绪净化_双人 | D9: / | E9: 强GVG冲榜 | F9: 宝石 | I9: 速率+能力 | M9: 0.1
B10: 任务 | C10: 日常/周常 | D10: / | E10: 日常行为的引导 | I10: 无
B11: 商店 | C11: 每日商店 | D11: / | E11: 金币限量兑换高性价比 | I11: 无
B12: 常规商业化 | C12: 日·周·月礼包 | D12: / | E12: 中小R高性价比礼包 | F12: 招募券、宝石 | I12: 付费
B13: 核心活动 | C13: / | D13: /
B14: 开服活动 | C14: 七日目标 | D14: / | F14: 英雄、宝石
A17: 玩法产出
E47: #限次为前期控制步长的核心数据
F48: 英雄 | J48: 装备 | M48: 宝石 | R48: 武器 | U48: 专属卡带 | V48: 货币
B49: 所属模块 | C49: 玩法名 | D49: 产出途径 | E49: 玩法次数 | F49: 招募券 | G49: 高级招募 | H49: 英雄碎片 | I49: 英雄经验 | J49: 装备本体 | K49: 装备图纸 | L49: 装备洗练石 | M49: 宝石本体 | N49: 宝石锤 | O49: 高级宝石锤 | P49: 精灵木 | Q49: 宝石洗练石 | R49: 天赋石 | S49: 高级天赋石 | T49: 加速券 | U49: 专属卡带 | V49: 金币 | W49: 宝石 | X49: 星珀
B50: 卡牌_PVE | C50: 主线推图 | D50: 首通奖励 | R50: 限次 | V50: 限次
D51: 宝箱奖励 | F51: 限次 | G51: 限次 | I51: 限次 | J51: 限次 | K51: 限次 | N51: 限次 | P51: 限次 | R51: 限次 | S51: 限次
D52: 快速巡演/通关奖励 | F52: 日常 | I52: 日常 | J52: 填充 | K52: 填充 | M52: 日常 | P52: 日常*2 | R52: 日常*5 | V52: 日常 | W52: 一次性
D53: 收获人气（挂机） | I53: 日常 | M53: 日常 | N53: 日常*4 | V53: 日常 | W53: 日常
B54: 卡牌PVP | C54: 情绪净化_单人 | D54: 达成奖励 | F54: 日常*20 | V54: 日常
D55: 排行奖励 | I55: 周常 | N55: 日常*2 | O55: 日常*2
B56: 卡牌GVE | C56: 梦域巡航 | D56: 通关奖励 | J56: 日常 | K56: 日常 | M56: 日常 | N56: 日常*1 | P56: 日常*10 | R56: 日常*20 | T56: 日常
D57: 协助奖励 | J57: 日常 | K57: 日常 | M57: 日常 | N57: 日常*1 | P57: 日常*10 | R57: 日常*20 | T57: 日常
D58: 每周奖励 | L58: 周常 | W58: 周达标*300
D59: 成就奖励 | F59: 一次性 | W59: 一次性
B60: 卡牌_GVG | C60: 情绪净化_双人 | D60: 通关奖励
D61: 达成奖励 | N61: 周常*20 | O61: 周常*4
D62: 排行奖励 | O62: 周常*5 | Q62: 周常*12 | W62: 周常*300 | X62: 周常*50
B63: 氛围小游戏 | C63: / | D63: /
B64: 任务 | C64: 任务系统 | D64: 日常任务 | F64: 日常 | K64: 日常 | N64: 日常*1 | Q64: 日常*2 | W64: 日常*100
D65: 周常任务 | F65: 周常 | G65: 周常 | O65: 周常*2 | Q65: 周常*6 | W65: 周常*200
B66: 联盟社交 | C66: 联盟帮助 | D66: /
C67: 联盟商店 | D67: /
B68: 商店 | C68: 每日商店 | D68: 每日商店 | F68: 日常 | I68: 日常 | K68: 日常 | Q68: 日常
B69: 常规商业化 | C69: 抽卡（招募） | D69: 英雄招募 | H69: 日常 | I69: 日常 | R69: 日常 | V69: 日常
C70: 寻宝（图腾） | D70: 图腾寻宝
C71: 章节礼包 | D71: 章节礼包 | F71: 限次 | I71: 限次 | M71: 限次 | O71: 限次 | Q71: 限次
C72: 月卡 | D72: 特权月卡
...

Sheet 内容释放节奏
C2: 内容释放节奏
D4: 时间 | E4: 玩家等级 | F4: 梦灵品质 | G4: 全局养成 | H4: 赛季养成
D5: 1 | E5: =VLOOKUP(D5,$D$52:$H$551,4,0) -> 12
D6: 7 | E6: =VLOOKUP(D6,$D$52:$H$551,4,0) -> 32
D7: 30 | E7: =VLOOKUP(D7,$D$52:$H$551,4,0) -> 59
D8: 60 | E8: =VLOOKUP(D8,$D$52:$H$551,4,0) -> 81
D9: 90 | E9: =VLOOKUP(D9,$D$52:$H$551,4,0) -> 92
D10: 120 | E10: =VLOOKUP(D10,$D$52:$H$551,4,0) -> 102
C13: 每日体力产出
C15: * | D15: 当前体力投放，先参考《僵尸》的投放途径，价格待定
D16: 途径 | E16: 每日次数
D17: 非R | E17: =H27/10 -> 40
D18: 双月卡 | E18: =H31/10 -> 46
D19: 大R | E19: =H34/10 -> 71.285714
D22: 途径 | E22: 每日次数 | F22: 单次体力 | G22: 单项体力 | H22: 累计体力 | I22: 钻石价格 | J22: rmb价格 | K22: 定位 | L22: 汇总说明 | M22: 列1
D23: 创号初始 | E23: 0 | F23: 60 | I23: 0 | K23: 全体
D24: 时间恢复 | E24: =10*24 -> 240 | F24: 1 | G24: =E24*F24 -> 240 | H24: =G24 -> 240 | I24: 0 | K24: 全体
D25: 每日广告 | E25: 3 | F25: 10 | G25: =E25*F25 -> 30 | H25: =G25+H24 -> 270 | I25: 0 | K25: 全体
D26: 食堂奖励 | E26: 4 | F26: 30 | G26: =E26*F26 -> 120 | H26: =G26+H25 -> 390 | I26: 0 | K26: 全体
D27: 日礼包免费 | E27: 1 | F27: 10 | G27: =E27*F27 -> 10 | H27: =G27+H26 -> 400 | I27: 0 | K27: 全体
D28: 月卡福利 | E28: 1 | F28: 10 | G28: =E28*F28 -> 10 | H28: =G28+H27 -> 410 | J28: 1 | K28: 小R
D29: 每日特惠礼包1 | E29: 1 | F29: 10 | G29: =E29*F29 -> 10 | H29: =G29+H28 -> 420 | J29: 1 | K29: 小R | L29: 预留给小R
D30: 每日特惠礼包2 | E30: 1 | F30: 15 | G30: =E30*F30 -> 15 | H30: =G30+H29 -> 435 | J30: 6 | K30: 小R | L30: 预留给小R
D31: 每日特惠礼包3 | E31: 1 | F31: 25 | G31: =E31*F31 -> 25 | H31: =G31+H30 -> 460 | J31: 18 | K31: 小R | L31: 预留给小R
D32: 日礼包购买 | E32: 1 | F32: 60 | G32: =E32*F32 -> 60 | H32: =G32+H31 -> 520 | I32: 96 | K32: 中R
D33: 周礼包购买 | E33: =1/7 -> 0.14285714 | F33: =60*5 -> 300 | G33: =E33*F33 -> 42.857143 | H33: =G33+H32 -> 562.85714 | I33: =84*5 -> 420 | K33: 中R | L33: 每周1次
D34: 宝石购买 | E34: 5 | F34: 30 | G34: =E34*F34 -> 150 | H34: =G34+H33 -> 712.85714 | I34: 60 | K34: 大R
C36: 每日体力消耗
C38: * | D38: 月卡党的扫荡效率提升30%
D40: 途径 | E40: 每日次数 | F40: 点数
D41: 主线通关 | E41: 1 | F41: 10
D42: 扫荡【体力】 | E42: 3 | F42: 10
D43: 扫荡【月卡】 | E43: 无限 | F43: 10
D44: 精英副本 | E44: 无限 | F44: 20
C47: 具体天数内容
D51: 天数 | E51: 等级差值 | F51: 玩家等级 | G51: 玩家等级数值取整 | H51: 宝石数
D52: 1 | E52: =OFFSET(养成框架!$R$63,MATCH(D52,养成框架!$D$64:$D$96,1),0) -> 12 | F52: =E52 -> 12 | G52: =INT(F52) -> 12 | H52: =OFFSET($L$51,MATCH(F52,$K$52:$K$81,1),0) -> 12 | I52: 8 | J52: =OFFSET($L$51,MATCH(I52,$K$52:$K$81,1),0) -> 8 | K52: 1 | L52: 6 | M52: 12
D53: 2 | E53: =OFFSET(养成框架!$R$63,MATCH(D53,养成框架!$D$64:$D$96,1),0) -> 6 | F53: =E53+F52 -> 18 | G53: =INT(F53) -> 18 | H53: =OFFSET($L$51,MATCH(F53,$K$52:$K$81,1),0) -> 18 | I53: 12 | J53: =OFFSET($L$51,MATCH(I53,$K$52:$K$81,1),0) -> 12 | K53: 2 | L53: 6 | M53: 16
D54: 3 | E54: =OFFSET(养成框架!$R$63,MATCH(D54,养成框架!$D$64:$D$96,1),0) -> 4 | F54: =E54+F53 -> 22 | G54: =INT(F54) -> 22 | H54: =OFFSET($L$51,MATCH(F54,$K$52:$K$81,1),0) -> 21 | I54: 15 | J54: =OFFSET($L$51,MATCH(I54,$K$52:$K$81,1),0) -> 15 | K54: 3 | L54: 6 | M54: 18
D55: 4 | E55: =OFFSET(养成框架!$R$63,MATCH(D55,养成框架!$D$64:$D$96,1),0) -> 3 | F55: =E55+F54 -> 25 | G55: =INT(F55) -> 25 | H55: =OFFSET($L$51,MATCH(F55,$K$52:$K$81,1),0) -> 22 | I55: 18 | J55: =OFFSET($L$51,MATCH(I55,$K$52:$K$81,1),0) -> 18 | K55: 4 | L55: 6 | M55: 21
...

Sheet 商业化框架
C1: 设计思路
N4: 宠物
C7: 商业化框架
D8: 统一定义 | L8: =1/(1-L20) -> 7.6923077
E9: #单赛季目标建立按照60天去做
E10: #目标坑深根据预设追求去计算，如梦灵单赛季养成标准为双卡30级 | L10: =1/0.4 -> 2.5
F13: 系统规划 | J13: 投放路径及占比 | M13: 投放路径及占比
D14: 养成模块 | E14: 养成点 | F14: 目标坑深（钻石） | G14: 单个坑深（钻石） | H14: 养成周期（天数） | I14: 每日产出（钻石） | J14: 活跃 | K14: 目标用户 | L14: 付费比重 | M14: 养成深度 | N14: 养成策略 | O14: 迭代方式 | P14: 针对付费群体 | Q14: 分层体验
D15: 梦灵 | E15: 梦灵碎片 | F15: =G15*21 -> 1155000 | G15: 55000 | H15: =F15/I15 -> 77 | I15: =J15/(1-L15) -> 15000 | J15: =100*30*2 -> 6000 | K15: 全体 | L15: 0.6 | M15: 30级*21个 | N15: 1、各职业养成前2品质的梦灵，以两英雄构筑一个队伍 2、有余力养成后续队伍 | O15: 横向迭代 | P15: 中R | Q15: 非小R只能获取系统赠送的低品 中大R追求所有英雄
E16: 梦灵经验 | F16: =G16*21 -> 945000 | G16: 45000 | H16: =INT(F16/I16) -> 108 | I16: =J16/(1-L16) -> 8750 | J16: =3500*H59 -> 3500 | K16: 全体 | L16: 0.6 | M16: 30级*21个 | N16: 1、单赛季产出2*6名角色30级 2、多余资源给老英雄进行稀释 | O16: 纵向迭代 | P16: 全体 | Q16: 付费活跃型 严格控制产出量
D17: 主角 | E17: 装备本体 | F17: 0 | G17: 0 | H17: 60 | K17: 全体
E18: 装备强化 | F18: =G18 -> 420000 | G18: =12500*6*H79+650000*6*H49 -> 420000 | H18: =G18/I18 -> 50.4 | I18: =J18/(1-L18) -> 8333.3333 | J18: =H79*1250+75000*H49 -> 7500 | K18: 全体 | L18: 0.1 | M18: 90级 | N18: 1、纯活跃产出，少量投放在必买礼包
E19: 装备洗练 | F19: =H82*35*60 -> 105000 | G19: =F19 -> 105000 | H19: 60 | I19: =G19/H19 -> 1750 | J19: =I19-I19*L19 -> 700 | K19: 全体 | L19: 0.6
E20: 符文本体 | F20: =G20 -> 1081344 | G20: =(1024*18+4096*12)*H97 -> 1081344 | H20: =G20/I20 -> 65.080889 | I20: =J20/(1-L20) -> 16615.385 | J20: =135*H97 -> 2160 | K20: 中R | L20: 0.87 | N20: 大R一身红宝石+一个彩，非R一身橙
E21: 符文洗练 | F21: =G21 -> 240000 | G21: =4000*H96 -> 240000 | H21: =G21/I21 -> 60 | I21: =J21/(1-L21) -> 4000 | J21: =100*H96/60 -> 100 | K21: 大R | L21: 0.975 | N21: 大R单赛季1个彩色5档，2个彩色4档 红品3个四档、12个3档、60个2档
E22: 基因升级 | F22: =G22 -> 112500 | G22: =600000*H49+17500*H105+H106*60 -> 112500 | H22: =G22/I22 -> 60.267857 | I22: =J22/(1-L22) -> 1866.6667 | J22: =300*H105+10000*H49 -> 1400 | K22: 全体 | L22: 0.25 | N22: #暂时没算时间加速材料的投放
D29: 养成模块 | E29: 养成点 | F29: 目标坑深（RMB） | G29: 养成周期（天数） | H29: 每日产出RMB | I29: 单关所需RMB | J29: 付费比重 | M29: 养成模块 | N29: 养成点 | O29: 阶段 | P29: 性价比 | Q29: 上限关卡数
D30: 梦灵 | E30: 梦灵升级 | F30: =20000*18/10 -> 36000 | G30: 60 | H30: =100*18/10 -> 180 | I30: 500 | J30: =H30*G30/F30 -> 0.3 | M30: 梦灵 | N30: 梦灵碎片 | O30: 紫色 | P30: 100 | Q30: 10关 | R30: 梦灵 | S30: 1000钻石
D31: 主角 | E31: 装备本体 | N31: 梦灵经验 | O31: 橙色 | P31: 1000 | Q31: 20关
E32: 装备强化 | F32: =F18/10 -> 42000 | G32: 60 | H32: =360000/60/10 -> 600 | I32: 1500 | J32: =H32*G32/F32 -> 0.85714286 | M32: 主角 | N32: 装备本体 | O32: 红色 | P32: 5000 | Q32: 50关 | R32: 紫色梦里 | S32: 100=1关 | T32: 10关
E33: 符文本体 | F33: =H102*30/10 -> 49152 | G33: 60 | H33: =100 -> 100 | J33: =H33*G33/F33 -> 0.12207031 | N33: 装备强化 | R33: 橙色梦里 | S33: 500=1关 | T33: 2关
E34: 符文洗练 | N34: 装备洗练
E35: 基因升级 | N35: 符文本体
N36: 符文洗练 | O36: 符文
N37: 基因升级 | O37: 一档阶段 | R37: 梦灵 | S37: 1000钻石
R39: 紫色梦里 | S39: 100=1关 | T39: 10关
R40: 橙色梦里 | S40: 500=1关 | T40: 2关
E43: 总需求 | F43: =SUM(F15:F26) -> 4058844 | I43: =SUM(I15:I26) -> 56315.385 | J43: =SUM(J15:J26) -> 21360
C44: 关键道具定价 | F44: =H49*10000 -> 500
J45: 主要投放途径
D46: 序号 | E46: 道具ID | F46: 道具名称 | G46: 类别 | H46: 钻石价值 | I46: RMB售价 | J46: 途径1 | K46: 途径2 | L46: 标准折扣 | M46: 备注 | N46: 整体思路
D47: =IF(F47="","",MAX($D$46:D46)+1) -> 1 | E47: 1 | F47: 钻石 | G47: 货币类 | H47: 1 | J47: 任务/成就/主线三星 | K47: 充值 | L47: 5 | N47: 做各阶层的能力阶梯
D48: =IF(F48="","",MAX($D$46:D47)+1) -> 2 | E48: 13 | F48: 体力 | H48: 2 | J48: 快捷购买 | L48: 7
D49: =IF(F49="","",MAX($D$46:D48)+1) -> 3 | E49: 2 | F49: 金币 | H49: 0.05 | J49: 日周月商店 | L49: 5
D50: =IF(F50="","",MAX($D$46:D49)+1) -> 4 | E50: 44 | F50: 星珀 | H50: 10 | J50: 每日特惠 | K50: 排行冲刺 | L50: 2 | N50: 做中R的付费质感（前期中R）
D51: =IF(F51="","",MAX($D$46:D50)+1) -> 5 | E51: 20003 | F51: 战令宝箱 | H51: 30
D52: =IF(F52="","",MAX($D$46:D51)+1) -> 6 | E52: 20033 | F52: 每日特惠宝箱 | H52: 40
D53: =IF(F53="","",MAX($D$46:D52)+1) -> 7 | E53: 5800004 | F53: 咩菲特的雕像 | H53: 30
D54: =IF(F54="","",MAX($D$46:D53)+1) -> 8 | E54: 5800005 | F54: 织梦宝箱 | H54: 50
D55: =IF(F55="","",MAX($D$46:D54)+1) -> 9 | E55: 20034 | F55: 筑梦快递箱 | H55: 250
...

Sheet 商业化框架(续)
C1: 分层设计
D3: 短期内关注单个模块付费，长周期关注循环体验（SS型） | K3: 6 | L3: 18 | M3: 30 | N3: 48 | P3: 68 | Q3: 98
D4: 分层 | E4: 档位 | F4: 整体思路 | G4: 总价($) | H4: 平均折扣率 | I4: 实际价格 | J4: 日均消费($) | K4: 特权 | R4: 钻销 | S4: 运营活动 | V4: 循环返利
K5: 6340 | L5: 2040 | M5: 3900 | N5: =M5+L5+I92 -> 6820 | P5: =I94 -> 13520 | Q5: =I98 -> 14940
K6: 首充 | L6: 小月卡 | M6: 大月卡 | N6: 双月卡 | O6: 每周周卡 | P6: 战令 | Q6: 基金 | R6: 日/月/周礼包 | S6: 每日特惠 | T6: 冲刺礼包 | U6: 抽奖活动 | V6: 冲榜返钻
D7: 非R | E7: 1 | F7: 豹子头
D8: 小R | E8: 1 | F8: 首冲玩家 | G8: {=SUMPRODUCT(--(K8:Y8>0),K$3:Y$3)} -> 6 | H8: {=SUMPRODUCT(--($K8:$Y8>0),$K$5:$Y$5)/10/G8} -> 105.66667 | K8: 1
A9: =60+68 -> 128 | E9: 2 | F9: 仅买小月卡 | G9: {=SUMPRODUCT(--(K9:Y9>0),K$3:Y$3)} -> 24 | H9: {=SUMPRODUCT(--($K9:$Y9>0),$K$5:$Y$5)/10/G9} -> 34.916667 | K9: 1 | L9: 1
E10: 3 | F10: 购买双月卡 | G10: {=SUMPRODUCT(--(K10:Y10>0),K$3:Y$3)} -> 54 | H10: {=SUMPRODUCT(--($K10:$Y10>0),$K$5:$Y$5)/10/G10} -> 24.37037 | K10: 1 | N10: 1
E11: 4 | F11: 特权买齐 | G11: {=SUMPRODUCT(--(K11:Y11>0),K$3:Y$3)} -> 220 | H11: {=SUMPRODUCT(--($K11:$Y11>0),$K$5:$Y$5)/10/G11} -> 18.918182 | K11: 1 | N11: 1 | P11: 1 | Q11: 1
E12: 5 | F12: 追求少量的梦灵 | G12: {=SUMPRODUCT(--(K12:Y12>0),K$3:Y$3)} -> 220 | H12: {=SUMPRODUCT(--($K12:$Y12>0),$K$5:$Y$5)/10/G12} -> 18.918182 | K12: 1 | N12: 1 | P12: 1 | Q12: 1
D13: 中R | E13: 1 | F13: 追求梦灵模块 | G13: {=SUMPRODUCT(--(K13:Y13>0),K$3:Y$3)} -> 220 | H13: {=SUMPRODUCT(--($K13:$Y13>0),$K$5:$Y$5)/10/G13} -> 18.918182 | K13: 1 | N13: 1 | P13: 1 | Q13: 1
E14: 2 | F14: 追求多个养成模块 | G14: {=SUMPRODUCT(--(K14:Y14>0),K$3:Y$3)} -> 220 | H14: {=SUMPRODUCT(--($K14:$Y14>0),$K$5:$Y$5)/10/G14} -> 18.918182 | K14: 1 | N14: 1 | P14: 1 | Q14: 1
E15: 3 | F15: 追求全部养成模块 | G15: {=SUMPRODUCT(--(K15:Y15>0),K$3:Y$3)} -> 220 | H15: {=SUMPRODUCT(--($K15:$Y15>0),$K$5:$Y$5)/10/G15} -> 18.918182 | K15: 1 | N15: 1 | P15: 1 | Q15: 1
E16: 4 | F16: 追求养成模块 在边界上不付费 | G16: {=SUMPRODUCT(--(K16:Y16>0),K$3:Y$3)} -> 220 | H16: {=SUMPRODUCT(--($K16:$Y16>0),$K$5:$Y$5)/10/G16} -> 18.918182 | K16: 1 | N16: 1 | P16: 1 | Q16: 1
D17: 大R | E17: 1 | F17: 周期性活动拉满 | G17: {=SUMPRODUCT(--(K17:Y17>0),K$3:Y$3)} -> 220 | H17: {=SUMPRODUCT(--($K17:$Y17>0),$K$5:$Y$5)/10/G17} -> 18.918182 | K17: 1 | N17: 1 | P17: 1 | Q17: 1
E18: 2 | F18: 每周礼包拉满 | G18: {=SUMPRODUCT(--(K18:Y18>0),K$3:Y$3)} -> 220 | H18: {=SUMPRODUCT(--($K18:$Y18>0),$K$5:$Y$5)/10/G18} -> 18.918182 | K18: 1 | N18: 1 | P18: 1 | Q18: 1
E19: 3 | F19: 每日消费拉满 | G19: {=SUMPRODUCT(--(K19:Y19>0),K$3:Y$3)} -> 220 | H19: {=SUMPRODUCT(--($K19:$Y19>0),$K$5:$Y$5)/10/G19} -> 18.918182 | K19: 1 | N19: 1 | P19: 1 | Q19: 1
D20: 超R | E20: 1 | F20: 付费内容拉满 | G20: {=SUMPRODUCT(--(K20:Y20>0),K$3:Y$3)} -> 220 | H20: {=SUMPRODUCT(--($K20:$Y20>0),$K$5:$Y$5)/10/G20} -> 18.918182 | K20: 1 | N20: 1 | P20: 1 | Q20: 1
C24: 锚定价值
D26: 类型 | E26: 玩法产出 | F26: 内容 | G26: 数量 | H26: 价值 | I26: 总价值(钻石) | J26: 价格 | K26: 性价比
D27: 1 | E27: 每日产出 | F27: 能量特饮 | G27: =H27/VLOOKUP(F27,商业化框架!$F$47:$H$136,3,0) -> 3500 | H27: =SUMIFS(商业化框架!$G$146:$G$158,商业化框架!$F$146:$F$158,F27)/60 -> 3500 | I27: =SUM(H27:H34) -> 16695 | K27: 1
F28: 梦境招募券 | G28: =H28/VLOOKUP(F28,商业化框架!$F$47:$H$136,3,0) -> 100 | H28: =SUMIFS(商业化框架!$G$146:$G$158,商业化框架!$F$146:$F$158,F28)/60/2 -> 3000
F29: 金币 | G29: =H29/VLOOKUP(F29,商业化框架!$F$47:$H$136,3,0) -> 75000 | H29: =SUMIFS(商业化框架!$G$146:$G$158,商业化框架!$F$146:$F$158,F29)/60 -> 3750
F30: 装备强化书 | G30: =H30/VLOOKUP(F30,商业化框架!$F$47:$H$136,3,0) -> 1250 | H30: =SUMIFS(商业化框架!$G$146:$G$158,商业化框架!$F$146:$F$158,F30)/60 -> 3750
F31: 普通符文 | G31: =H31/VLOOKUP(F31,商业化框架!$F$47:$H$136,3,0) -> 62.5 | H31: =SUMIFS(商业化框架!$G$146:$G$158,商业化框架!$F$146:$F$158,F31)/60 -> 1000
F32: 幻梦晶核 | G32: =H32/VLOOKUP(F32,商业化框架!$F$47:$H$136,3,0) -> 1.6666667 | H32: =SUMIFS(商业化框架!$G$146:$G$158,商业化框架!$F$146:$F$158,F32)/60 -> 100
F33: 织梦微尘 | G33: =H33/VLOOKUP(F33,商业化框架!$F$47:$H$136,3,0) -> 291.66667 | H33: =SUMIFS(商业化框架!$G$146:$G$158,商业化框架!$F$146:$F$158,F33)/60 -> 875
F34: 加速沙漏 | G34: =H34/VLOOKUP(F34,商业化框架!$F$47:$H$136,3,0) -> 144 | H34: =SUMIFS(商业化框架!$G$146:$G$158,商业化框架!$F$146:$F$158,F34)/60 -> 720
