Workbook

Sheet 说明
A1: 梦灵养成
A3: 说明
C5: 梦灵升级
D6: 梦灵属性=梦灵初始属性×（1＋（梦灵等级－1）×等级系数）
D7: 梦灵升级消耗【能量特饮】＋【金币】
D8: 梦灵升级本质上是上阵编队位置的升级，替换梦灵，等级继承
D9: 梦灵升级不能超过上阵编队最低等级位置10级
C11: 梦灵升星
D12: 梦灵升星属性＝梦灵等级属性×（1+品质系数）＋梦灵初始属性×升星系数×（品质id-1）
D13: 梦灵升星消耗【本体碎片】＋【金币】
D14: 梦灵升星到一定阶段后，需要【进阶石】
C16: 关联配置
D18: 配置 | E18: 字段 | F18: 值 | G18: 说明
D19: D_单位_unit_data
D20: D_道具_item_data | G20: *涉及梦灵道具与梦灵初始品质
G22: *预留最后一行
D27: 表头
D29: 表头
D31: 表头
A35: 本页结束

Sheet 养成规划
A1: 养成属性
C3: 属性规划
D5: 天数 | E5: 玩家等级 | F5: 装备等级 | G5: 装备强化 | H5: 装备品质 | I5: 装备属性 | J5: 强化属性 | K5: 洗练属性 | L5: 强化属性 | R5: 天数 | S5: 玩家等级 | T5: 装备等级 | U5: 装备强化 | V5: 装备品质 | W5: 装备属性 | X5: 强化属性 | Y5: 洗练属性
A6: 270 | D6: 1 | E6: 12 | F6: 10 | G6: 10 | H6: 蓝 | I6: 270 | J6: 180 | K6: 90 | L6: =INT(J6/G6/6) -> 3 | P6: 365.4 | Q6: 180 | R6: 1 | S6: =IF([1]养成框架!S75=E6,"",[1]养成框架!S75) | T6: =IF([1]养成框架!T75=F6,"",[1]养成框架!T75) | U6: =IF([1]养成框架!U75=G6,"",[1]养成框架!U75) | V6: =IF([1]养成框架!V75=H6,"",[1]养成框架!V75) | W6: =IF(ABS([1]养成框架!L159-I6)<1,"",[1]养成框架!L159) | X6: =IF(ABS([1]养成框架!M159-J6)<1,"",[1]养成框架!M159) | Y6: =IF(ABS([1]养成框架!N159-K6)<1,"",[1]养成框架!N159) -> 72 | Z6: =IF(W6="",I6,W6) -> 270 | AA6: =IF(X6="",J6,X6) -> 180 | AB6: =IF(Y6="",K6,Y6) -> 72
A7: 372.6 | D7: 2 | E7: 18 | F7: 20 | G7: 16 | H7: 紫 | I7: 372.6 | J7: 324 | K7: 108 | L7: =INT((J7-J6)/(G7-G6)/6) -> 4 | P7: 518.75526 | Q7: 324 | R7: 2 | S7: =IF([1]养成框架!S76=E7,"",[1]养成框架!S76) | T7: =IF([1]养成框架!T76=F7,"",[1]养成框架!T76) | U7: =IF([1]养成框架!U76=G7,"",[1]养成框架!U76) | V7: =IF([1]养成框架!V76=H7,"",[1]养成框架!V76) | W7: =IF(ABS([1]养成框架!L160-I7)<1,"",[1]养成框架!L160) | X7: =IF(ABS([1]养成框架!M160-J7)<1,"",[1]养成框架!M160) | Y7: =IF(ABS([1]养成框架!N160-K7)<1,"",[1]养成框架!N160) | Z7: =IF(W7="",I7,W7) -> 372.6 | AA7: =IF(X7="",J7,X7) -> 324 | AB7: =IF(Y7="",K7,Y7) -> 108
A8: 514.8 | D8: 3 | E8: 22 | F8: 30 | G8: 20 | H8: 橙 | I8: 514.8 | J8: 420 | K8: 144 | L8: =INT((J8-J7)/(G8-G7)/6) -> 4 | P8: 688.97722 | Q8: 420 | R8: 3 | S8: =IF([1]养成框架!S77=E8,"",[1]养成框架!S77) | T8: =IF([1]养成框架!T77=F8,"",[1]养成框架!T77) | U8: =IF([1]养成框架!U77=G8,"",[1]养成框架!U77) | V8: =IF([1]养成框架!V77=H8,"",[1]养成框架!V77) | W8: =IF(ABS([1]养成框架!L161-I8)<1,"",[1]养成框架!L161) | X8: =IF(ABS([1]养成框架!M161-J8)<1,"",[1]养成框架!M161) | Y8: =IF(ABS([1]养成框架!N161-K8)<1,"",[1]养成框架!N161) -> 176 | Z8: =IF(W8="",I8,W8) -> 514.8 | AA8: =IF(X8="",J8,X8) -> 420 | AB8: =IF(Y8="",K8,Y8) -> 176
A9: 514.8 | D9: 4 | E9: 25 | F9: 30 | G9: 24 | H9: 橙 | I9: 514.8 | J9: 540 | K9: 174 | L9: =INT((J9-J8)/(G9-G8)/6) -> 5 | P9: 749.60982 | Q9: 540 | R9: 4 | S9: =IF([1]养成框架!S78=E9,"",[1]养成框架!S78) | T9: =IF([1]养成框架!T78=F9,"",[1]养成框架!T78) | U9: =IF([1]养成框架!U78=G9,"",[1]养成框架!U78) | V9: =IF([1]养成框架!V78=H9,"",[1]养成框架!V78) | W9: =IF(ABS([1]养成框架!L162-I9)<1,"",[1]养成框架!L162) | X9: =IF(ABS([1]养成框架!M162-J9)<1,"",[1]养成框架!M162) | Y9: =IF(ABS([1]养成框架!N162-K9)<1,"",[1]养成框架!N162) -> 192 | Z9: =IF(W9="",I9,W9) -> 514.8 | AA9: =IF(X9="",J9,X9) -> 540 | AB9: =IF(Y9="",K9,Y9) -> 192
A10: 514.8 | D10: 5 | E10: 28 | F10: 30 | G10: 27 | H10: 橙 | I10: 514.8 | J10: 630 | K10: 234 | L10: =INT((J10-J9)/(G10-G9)/6) -> 5 | P10: 793.85868 | Q10: 630 | R10: 5 | S10: =IF([1]养成框架!S79=E10,"",[1]养成框架!S79) | T10: =IF([1]养成框架!T79=F10,"",[1]养成框架!T79) | U10: =IF([1]养成框架!U79=G10,"",[1]养成框架!U79) | V10: =IF([1]养成框架!V79=H10,"",[1]养成框架!V79) | W10: =IF(ABS([1]养成框架!L163-I10)<1,"",[1]养成框架!L163) | X10: =IF(ABS([1]养成框架!M163-J10)<1,"",[1]养成框架!M163) | Y10: =IF(ABS([1]养成框架!N163-K10)<1,"",[1]养成框架!N163) -> 208 | Z10: =IF(W10="",I10,W10) -> 514.8 | AA10: =IF(X10="",J10,X10) -> 630 | AB10: =IF(Y10="",K10,Y10) -> 208
A11: 591.5 | D11: 6 | E11: 30 | F11: 40 | G11: 30 | H11: 橙 | I11: 591.5 | J11: 756 | K11: 240 | L11: =INT((J11-J10)/(G11-G10)/6) -> 7 | P11: 905.92353 | Q11: 756 | R11: 6 | S11: =IF([1]养成框架!S80=E11,"",[1]养成框架!S80) | T11: =IF([1]养成框架!T80=F11,"",[1]养成框架!T80) | U11: =IF([1]养成框架!U80=G11,"",[1]养成框架!U80) | V11: =IF([1]养成框架!V80=H11,"",[1]养成框架!V80) | W11: =IF(ABS([1]养成框架!L164-I11)<1,"",[1]养成框架!L164) | X11: =IF(ABS([1]养成框架!M164-J11)<1,"",[1]养成框架!M164) | Y11: =IF(ABS([1]养成框架!N164-K11)<1,"",[1]养成框架!N164) -> 224 | Z11: =IF(W11="",I11,W11) -> 591.5 | AA11: =IF(X11="",J11,X11) -> 756 | AB11: =IF(Y11="",K11,Y11) -> 224
A12: 591.5 | D12: 7 | E12: 32 | F12: 40 | G12: 32 | H12: 橙 | I12: 591.5 | J12: 840 | K12: 288 | L12: =INT((J12-J11)/(G12-G11)/6) -> 7 | P12: 946.86127 | Q12: 840 | R12: 7 | S12: =IF([1]养成框架!S81=E12,"",[1]养成框架!S81) | T12: =IF([1]养成框架!T81=F12,"",[1]养成框架!T81) | U12: =IF([1]养成框架!U81=G12,"",[1]养成框架!U81) | V12: =IF([1]养成框架!V81=H12,"",[1]养成框架!V81) | W12: =IF(ABS([1]养成框架!L165-I12)<1,"",[1]养成框架!L165) | X12: =IF(ABS([1]养成框架!M165-J12)<1,"",[1]养成框架!M165) | Y12: =IF(ABS([1]养成框架!N165-K12)<1,"",[1]养成框架!N165) -> 240 | Z12: =IF(W12="",I12,W12) -> 591.5 | AA12: =IF(X12="",J12,X12) -> 840 | AB12: =IF(Y12="",K12,Y12) -> 240
A13: 728 | D13: 8 | E13: 34 | F13: 40 | G13: 34 | H13: 红 | I13: 728 | J13: 924 | K13: 360 | L13: =INT((J13-J12)/(G13-G12)/6) -> 7 | P13: 1053.5 | Q13: 924 | R13: 8 | S13: =IF([1]养成框架!S82=E13,"",[1]养成框架!S82) | T13: =IF([1]养成框架!T82=F13,"",[1]养成框架!T82) | U13: =IF([1]养成框架!U82=G13,"",[1]养成框架!U82) | V13: =IF([1]养成框架!V82=H13,"",[1]养成框架!V82) | W13: =IF(ABS([1]养成框架!L166-I13)<1,"",[1]养成框架!L166) | X13: =IF(ABS([1]养成框架!M166-J13)<1,"",[1]养成框架!M166) | Y13: =IF(ABS([1]养成框架!N166-K13)<1,"",[1]养成框架!N166) -> 240 | Z13: =IF(W13="",I13,W13) -> 728 | AA13: =IF(X13="",J13,X13) -> 924 | AB13: =IF(Y13="",K13,Y13) -> 240
A14: 728 | D14: 9 | E14: 36 | F14: 40 | G14: 36 | H14: 红 | I14: 728 | J14: 1008 | K14: 420 | L14: =INT((J14-J13)/(G14-G13)/6) -> 7 | P14: 1081.8324 | Q14: 1008 | R14: 9 | S14: =IF([1]养成框架!S83=E14,"",[1]养成框架!S83) | T14: =IF([1]养成框架!T83=F14,"",[1]养成框架!T83) | U14: =IF([1]养成框架!U83=G14,"",[1]养成框架!U83) | V14: =IF([1]养成框架!V83=H14,"",[1]养成框架!V83) | W14: =IF(ABS([1]养成框架!L167-I14)<1,"",[1]养成框架!L167) | X14: =IF(ABS([1]养成框架!M167-J14)<1,"",[1]养成框架!M167) | Y14: =IF(ABS([1]养成框架!N167-K14)<1,"",[1]养成框架!N167) -> 240 | Z14: =IF(W14="",I14,W14) -> 728 | AA14: =IF(X14="",J14,X14) -> 1008 | AB14: =IF(Y14="",K14,Y14) -> 240
A15: 728 | D15: 10 | E15: 38 | F15: 40 | G15: 38 | H15: 红 | I15: 728 | J15: 1092 | K15: 486 | L15: =INT((J15-J14)/(G15-G14)/6) -> 7 | P15: 1115.3591 | Q15: 1092 | R15: 10 | S15: =IF([1]养成框架!S84=E15,"",[1]养成框架!S84) | T15: =IF([1]养成框架!T84=F15,"",[1]养成框架!T84) | U15: =IF([1]养成框架!U84=G15,"",[1]养成框架!U84) | V15: =IF([1]养成框架!V84=H15,"",[1]养成框架!V84) | W15: =IF(ABS([1]养成框架!L168-I15)<1,"",[1]养成框架!L168) | X15: =IF(ABS([1]养成框架!M168-J15)<1,"",[1]养成框架!M168) | Y15: =IF(ABS([1]养成框架!N168-K15)<1,"",[1]养成框架!N168) -> 240 | Z15: =IF(W15="",I15,W15) -> 728 | AA15: =IF(X15="",J15,X15) -> 1092 | AB15: =IF(Y15="",K15,Y15) -> 240
A16: 836.8 | D16: 11 | E16: 40 | F16: 50 | G16: 40 | H16: 红 | I16: 836.8 | J16: 1188 | K16: 558 | L16: =INT((J16-J15)/(G16-G15)/6) -> 8 | P16: 1212.8437 | Q16: 1188 | R16: 11 | S16: =IF([1]养成框架!S85=E16,"",[1]养成框架!S85) | T16: =IF([1]养成框架!T85=F16,"",[1]养成框架!T85) | U16: =IF([1]养成框架!U85=G16,"",[1]养成框架!U85) | V16: =IF([1]养成框架!V85=H16,"",[1]养成框架!V85) | W16: =IF(ABS([1]养成框架!L169-I16)<1,"",[1]养成框架!L169) | X16: =IF(ABS([1]养成框架!M169-J16)<1,"",[1]养成框架!M169) | Y16: =IF(ABS([1]养成框架!N169-K16)<1,"",[1]养成框架!N169) -> 240 | Z16: =IF(W16="",I16,W16) -> 836.8 | AA16: =IF(X16="",J16,X16) -> 1188 | AB16: =IF(Y16="",K16,Y16) -> 240
A17: 836.8 | D17: 12 | E17: 42 | F17: 50 | G17: 42 | H17: 红 | I17: 836.8 | J17: 1284 | K17: 792 | L17: =INT((J17-J16)/(G17-G16)/6) -> 8 | P17: 1250.5859 | Q17: 1284 | R17: 12 | S17: =IF([1]养成框架!S86=E17,"",[1]养成框架!S86) | T17: =IF([1]养成框架!T86=F17,"",[1]养成框架!T86) | U17: =IF([1]养成框架!U86=G17,"",[1]养成框架!U86) | V17: =IF([1]养成框架!V86=H17,"",[1]养成框架!V86) | W17: =IF(ABS([1]养成框架!L170-I17)<1,"",[1]养成框架!L170) | X17: =IF(ABS([1]养成框架!M170-J17)<1,"",[1]养成框架!M170) | Y17: =IF(ABS([1]养成框架!N170-K17)<1,"",[1]养成框架!N170) -> 240 | Z17: =IF(W17="",I17,W17) -> 836.8 | AA17: =IF(X17="",J17,X17) -> 1284 | AB17: =IF(Y17="",K17,Y17) -> 240
A18: 836.8 | D18: 13 | E18: 44 | F18: 50 | G18: 44 | H18: 红 | I18: 836.8 | J18: 1380 | K18: 990 | L18: =INT((J18-J17)/(G18-G17)/6) -> 8 | P18: 1287.5209 | Q18: 1380 | R18: 13 | S18: =IF([1]养成框架!S87=E18,"",[1]养成框架!S87) | T18: =IF([1]养成框架!T87=F18,"",[1]养成框架!T87) | U18: =IF([1]养成框架!U87=G18,"",[1]养成框架!U87) | V18: =IF([1]养成框架!V87=H18,"",[1]养成框架!V87) | W18: =IF(ABS([1]养成框架!L171-I18)<1,"",[1]养成框架!L171) | X18: =IF(ABS([1]养成框架!M171-J18)<1,"",[1]养成框架!M171) | Y18: =IF(ABS([1]养成框架!N171-K18)<1,"",[1]养成框架!N171) -> 240 | Z18: =IF(W18="",I18,W18) -> 836.8 | AA18: =IF(X18="",J18,X18) -> 1380 | AB18: =IF(Y18="",K18,Y18) -> 240
... A27: 1588 | D27: 55 | E27: 76 | F27: 80 | G27: 77.6 | H27: 粉 | I27: 1730 | J27: 3418.8 | K27: 3840 | L27: =INT((J27-J26)/(G27-G26)/6) -> 12 | P27: 2347.975 | Q27: 3286.8 | R27: 55 | S27: =IF([1]养成框架!S96=E27,"",[1]养成框架!S96) | T27: =IF([1]养成框架!T96=F27,"",[1]养成框架!T96) | U27: =IF([1]养成框架!U96=G27,"",[1]养成框架!U96) | V27: =IF([1]养成框架!V96=H27,"",[1]养成框架!V96) | W27: =IF(ABS([1]养成框架!L180-I27)<1,"",[1]养成框架!L180) -> 1588 | X27: =IF(ABS([1]养成框架!M180-J27)<1,"",[1]养成框架!M180) -> 3286.8 | Y27: =IF(ABS([1]养成框架!N180-K27)<1,"",[1]养成框架!N180) -> 360 | Z27: =IF(W27="",I27,W27) -> 1588 | AA27: =IF(X27="",J27,X27) -> 3286.8 | AB27: =IF(Y27="",K27,Y27) -> 360
A28: 1588 | D28: 62 | E28: 78.5 | F28: 85 | G28: 80.4 | H28: 粉 | I28: 1730 | J28: 3620.4 | K28: 4170 | L28: =INT((J28-J27)/(G28-G27)/6) -> 11 | Q28: 3488.4 | R28: 62 | S28: =IF([1]养成框架!S97=E28,"",[1]养成框架!S97) | T28: =IF([1]养成框架!T97=F28,"",[1]养成框架!T97) -> 80 | U28: =IF([1]养成框架!U97=G28,"",[1]养成框架!U97) | V28: =IF([1]养成框架!V97=H28,"",[1]养成框架!V97) | W28: =IF(ABS([1]养成框架!L181-I28)<1,"",[1]养成框架!L181) -> 1588 | X28: =IF(ABS([1]养成框架!M181-J28)<1,"",[1]养成框架!M181) -> 3488.4 | Y28: =IF(ABS([1]养成框架!N181-K28)<1,"",[1]养成框架!N181) -> 450 | Z28: =IF(W28="",I28,W28) -> 1588 | AA28: =IF(X28="",J28,X28) -> 3488.4 | AB28: =IF(Y28="",K28,Y28) -> 450
A29: 1826 | D29: 90 | E29: 88.5 | F29: 90 | G29: 91.6 | H29: 粉 | I29: 1858 | J29: 4695.6 | K29: 4500 | L29: =INT((J29-J28)/(G29-G28)/6) -> 16 | Q29: 4563.6 | R29: 90 | S29: =IF([1]养成框架!S98=E29,"",[1]养成框架!S98) | T29: =IF([1]养成框架!T98=F29,"",[1]养成框架!T98) | U29: =IF([1]养成框架!U98=G29,"",[1]养成框架!U98) | V29: =IF([1]养成框架!V98=H29,"",[1]养成框架!V98) | W29: =IF(ABS([1]养成框架!L182-I29)<1,"",[1]养成框架!L182) -> 1826 | X29: =IF(ABS([1]养成框架!M182-J29)<1,"",[1]养成框架!M182) -> 4563.6 | Y29: =IF(ABS([1]养成框架!N182-K29)<1,"",[1]养成框架!N182) -> 450 | Z29: =IF(W29="",I29,W29) -> 1826 | AA29: =IF(X29="",J29,X29) -> 4563.6 | AB29: =IF(Y29="",K29,Y29) -> 450
A30: 2622.5 | D30: 120 | E30: 93.857143 | F30: 100 | G30: 97.6 | H30: 彩 | I30: 2680 | J30: 5415.6 | K30: 4830 | L30: =INT((J30-J29)/(G30-G29)/6) -> 20 | Q30: 5283.6 | R30: 120 | S30: =IF([1]养成框架!S99=E30,"",[1]养成框架!S99) | T30: =IF([1]养成框架!T99=F30,"",[1]养成框架!T99) | U30: =IF([1]养成框架!U99=G30,"",[1]养成框架!U99) | V30: =IF([1]养成框架!V99=H30,"",[1]养成框架!V99) | W30: =IF(ABS([1]养成框架!L183-I30)<1,"",[1]养成框架!L183) -> 2622.5 | X30: =IF(ABS([1]养成框架!M183-J30)<1,"",[1]养成框架!M183) -> 5283.6 | Y30: =IF(ABS([1]养成框架!N183-K30)<1,"",[1]养成框架!N183) -> 450 | Z30: =IF(W30="",I30,W30) -> 2622.5 | AA30: =IF(X30="",J30,X30) -> 5283.6 | AB30: =IF(Y30="",K30,Y30) -> 450
A31: 2622.5 | D31: 150 | E31: 99.214286 | F31: 105 | G31: 103.6 | H31: 彩 | I31: 2880 | J31: 6135.6 | K31: 5466 | L31: =INT((J31-J30)/(G31-G30)/6) -> 20 | Q31: 6003.6 | R31: 150 | S31: =IF([1]养成框架!S100=E31,"",[1]养成框架!S100) | T31: =IF([1]养成框架!T100=F31,"",[1]养成框架!T100) -> 100 | U31: =IF([1]养成框架!U100=G31,"",[1]养成框架!U100) | V31: =IF([1]养成框架!V100=H31,"",[1]养成框架!V100) | W31: =IF(ABS([1]养成框架!L184-I31)<1,"",[1]养成框架!L184) -> 2622.5 | X31: =IF(ABS([1]养成框架!M184-J31)<1,"",[1]养成框架!M184) -> 6003.6 | Y31: =IF(ABS([1]养成框架!N184-K31)<1,"",[1]养成框架!N184) -> 450 | Z31: =IF(W31="",I31,W31) -> 2622.5 | AA31: =IF(X31="",J31,X31) -> 6003.6 | AB31: =IF(Y31="",K31,Y31) -> 450
A32: 3015 | D32: 190 | E32: 106.35714 | F32: 110 | G32: 111.6 | H32: 彩 | I32: 3095 | J32: 7287.6 | K32: 6546 | L32: =INT((J32-J31)/(G32-G31)/6) -> 24 | Q32: 7155.6 | R32: 190 | S32: =IF([1]养成框架!S101=E32,"",[1]养成框架!S101) | T32: =IF([1]养成框架!T101=F32,"",[1]养成框架!T101) | U32: =IF([1]养成框架!U101=G32,"",[1]养成框架!U101) | V32: =IF([1]养成框架!V101=H32,"",[1]养成框架!V101) | W32: =IF(ABS([1]养成框架!L185-I32)<1,"",[1]养成框架!L185) -> 3015 | X32: =IF(ABS([1]养成框架!M185-J32)<1,"",[1]养成框架!M185) -> 7155.6 | Y32: =IF(ABS([1]养成框架!N185-K32)<1,"",[1]养成框架!N185) -> 450 | Z32: =IF(W32="",I32,W32) -> 3015 | AA32: =IF(X32="",J32,X32) -> 7155.6 | AB32: =IF(Y32="",K32,Y32) -> 450
A33: 3465 | D33: 250 | E33: 117.07143 | F33: 120 | G33: 123.6 | H33: 彩 | I33: 3572.5 | J33: 9303.6 | K33: 7632 | L33: =INT((J33-J32)/(G33-G32)/6) -> 28 | Q33: 9171.6 | R33: 250 | S33: =IF([1]养成框架!S102=E33,"",[1]养成框架!S102) | T33: =IF([1]养成框架!T102=F33,"",[1]养成框架!T102) | U33: =IF([1]养成框架!U102=G33,"",[1]养成框架!U102) | V33: =IF([1]养成框架!V102=H33,"",[1]养成框架!V102) | W33: =IF(ABS([1]养成框架!L186-I33)<1,"",[1]养成框架!L186) -> 3465 | X33: =IF(ABS([1]养成框架!M186-J33)<1,"",[1]养成框架!M186) -> 9171.6 | Y33: =IF(ABS([1]养成框架!N186-K33)<1,"",[1]养成框架!N186) -> 540 | Z33: =IF(W33="",I33,W33) -> 3465 | AA33: =IF(X33="",J33,X33) -> 9171.6 | AB33: =IF(Y33="",K33,Y33) -> 540
A34: 3982.5 | D34: 310 | E34: 127.78571 | F34: 130 | G34: 135.6 | H34: 彩 | I34: 4127.5 | J34: 11607.6 | K34: 8712 | L34: =INT((J34-J33)/(G34-G33)/6) -> 32 | Q34: 11475.6 | R34: 310 | S34: =IF([1]养成框架!S103=E34,"",[1]养成框架!S103) | T34: =IF([1]养成框架!T103=F34,"",[1]养成框架!T103) | U34: =IF([1]养成框架!U103=G34,"",[1]养成框架!U103) | V34: =IF([1]养成框架!V103=H34,"",[1]养成框架!V103) | W34: =IF(ABS([1]养成框架!L187-I34)<1,"",[1]养成框架!L187) -> 3982.5 | X34: =IF(ABS([1]养成框架!M187-J34)<1,"",[1]养成框架!M187) -> 11475.6 | Y34: =IF(ABS([1]养成框架!N187-K34)<1,"",[1]养成框架!N187) -> 540 | Z34: =IF(W34="",I34,W34) -> 3982.5 | AA34: =IF(X34="",J34,X34) -> 11475.6 | AB34: =IF(Y34="",K34,Y34) -> 540
A35: 4577.5 | D35: 370 | E35: 138.5 | F35: 140 | G35: 147.6 | H35: 彩 | I35: 4767.5 | J35: 14343.6 | K35: 9078 | L35: =INT((J35-J34)/(G35-G34)/6) -> 38 | Q35: 14211.6 | R35: 370 | S35: =IF([1]养成框架!S104=E35,"",[1]养成框架!S104) | T35: =IF([1]养成框架!T104=F35,"",[1]养成框架!T104) | U35: =IF([1]养成框架!U104=G35,"",[1]养成框架!U104) | V35: =IF([1]养成框架!V104=H35,"",[1]养成框架!V104) | W35: =IF(ABS([1]养成框架!L188-I35)<1,"",[1]养成框架!L188) -> 4577.5 | X35: =IF(ABS([1]养成框架!M188-J35)<1,"",[1]养成框架!M188) -> 14211.6 | Y35: =IF(ABS([1]养成框架!N188-K35)<1,"",[1]养成框架!N188) -> 540 | Z35: =IF(W35="",I35,W35) -> 4577.5 | AA35: =IF(X35="",J35,X35) -> 14211.6 | AB35: =IF(Y35="",K35,Y35) -> 540
A36: 5262.5 | D36: 430 | E36: 149.21429 | F36: 150 | G36: 159.6 | H36: 彩 | I36: 5507.5 | J36: 17511.6 | K36: 9444 | L36: =INT((J36-J35)/(G36-G35)/6) -> 44 | Q36: 17379.6 | R36: 430 | S36: =IF([1]养成框架!S105=E36,"",[1]养成框架!S105) | T36: =IF([1]养成框架!T105=F36,"",[1]养成框架!T105) | U36: =IF([1]养成框架!U105=G36,"",[1]养成框架!U105) | V36: =IF([1]养成框架!V105=H36,"",[1]养成框架!V105) | W36: =IF(ABS([1]养成框架!L189-I36)<1,"",[1]养成框架!L189) -> 5262.5 | X36: =IF(ABS([1]养成框架!M189-J36)<1,"",[1]养成框架!M189) -> 17379.6 | Y36: =IF(ABS([1]养成框架!N189-K36)<1,"",[1]养成框架!N189) -> 540 | Z36: =IF(W36="",I36,W36) -> 5262.5 | AA36: =IF(X36="",J36,X36) -> 17379.6 | AB36: =IF(Y36="",K36,Y36) -> 540
A37: 6957.5 | D37: =ROUND((D36+D38)/2,0) -> 475 | E37: =ROUND((E36+E38)/2,0) -> 157 | F37: =ROUND((F36+F38)/2,0) -> 160 | G37: =ROUND((G36+G38)/2,0) -> 169 | H37: 彩 | I37: =ROUND((I36+I38)/2,0) -> 6429 | J37: =ROUND((J36+J38)/2,0) -> 20104 | K37: 9816 | L37: =INT((J37-J36)/(G37-G36)/6) -> 45 | Q37: 22563.6
D38: 520 | E38: 165.28571 | F38: 170 | G38: 177.6 | H38: 彩 | I38: 7350 | J38: 22695.6 | K38: 10182 | L38: =INT((J38-J37)/(G38-G37)/6) -> 50 | Q38: 27555.6 | R38: 520 | S38: =IF([1]养成框架!S106=E38,"",[1]养成框架!S106) -> 165.28571 | T38: =IF([1]养成框架!T106=F38,"",[1]养成框架!T106) | U38: =IF([1]养成框架!U106=G38,"",[1]养成框架!U106) | V38: =IF([1]养成框架!V106=H38,"",[1]养成框架!V106) | W38: =IF(ABS([1]养成框架!L190-I38)<1,"",[1]养成框架!L190) -> 6957.5 | X38: =IF(ABS([1]养成框架!M190-J38)<1,"",[1]养成框架!M190) -> 22563.6 | Y38: =IF(ABS([1]养成框架!N190-K38)<1,"",[1]养成框架!N190) -> 540 | Z38: =IF(W38="",I38,W38) -> 6957.5 | AA38: =IF(X38="",J38,X38) -> 22563.6 | AB38: =IF(Y38="",K38,Y38) -> 540
D39: =ROUND((D38+D40)/2,0) -> 560 | E39: =ROUND((E38+E40)/2,0) -> 173 | F39: =ROUND((F38+F40)/2,0) -> 180 | G39: =ROUND((G38+G40)/2,0) -> 184 | H39: 彩 | I39: =ROUND((I38+I40)/2,0) -> 7921 | J39: =ROUND((J38+J40)/2,0) -> 25288 | K39: 10944 | L39: =INT((J39-J38)/(G39-G38)/6) -> 67
D40: 600 | E40: 180 | F40: 190 | G40: 190 | H40: 彩 | I40: 8492.5 | J40: 27879.6 | K40: 11706 | L40: =INT((J40-J39)/(G40-G39)/6) -> 71
D41: 640 | E41: 190 | F41: 200 | G41: 200 | H41: 彩 | I41: =ROUND(I40*1.07,0) -> 9087 | J41: =ROUND(J40*1.07,0) -> 29831 | K41: =ROUND(K40*1.07,0) -> 12525 | L41: =INT((J41-J40)/(G41-G40)/6) -> 32
A46: 本页结束

Sheet 装备属性
A1: 装备本体
C3: 属性规划
D5: 见养成属性页签
A8: 装备基础属性
D10: #前期成长略低于升级，后期高于升级（相当于高品质可以用多一个等级）
C11: 等级模型
D12: *确定每一级属性
H13: #从玩家等级表里面拉，这里偏快
D14: 装备等级 | E14: 攻击 | F14: 生命 | G14: 成长幅度 | H14: 解锁时间 | I14: 停留时间 | J14: 品质 | K14: 等级时间 | L14: 算上品质 | M14: 装备提升 | N14: 装备性价比
D15: 0 | E15: 167 | F15: =E15*10 -> 1670 | H15: 1 | J15: =OFFSET(装备产出!$W$18,MATCH(H15,装备产出!$E$19:$E$33,1),0) -> 橙0.05 | K15: 0 | L15: =E15*E69 -> 180.36
D16: 1 | E16: 167 | F16: =E16*10 -> 1670 | G16: =E16/E15 -> 1 | H16: 1 | I16: =H16-H15 -> 0 | J16: =OFFSET(装备产出!$W$18,MATCH(H16,装备产出!$E$19:$E$33,1),0) -> 橙0.05 | K16: =H16-H15 -> 0 | L16: =E16*E70 -> 217.1 | M16: =LOG((G16-1)/6+1,1.07) -> 0
D17: 10 | E17: 300 | F17: =E17*10 -> 3000 | G17: =E17/E16 -> 1.7964072 | H17: 1 | I17: =H17-H16 -> 0 | J17: =OFFSET(装备产出!$W$18,MATCH(H17,装备产出!$E$19:$E$33,1),0) -> 橙0.05 | K17: =H17-H16 -> 0 | L17: =E17*E69 -> 324 | M17: =LOG((G17-1)/6+1,1.07) -> 1.8421096
D18: 20 | E18: =INT(E17*1.15) -> 345 | F18: =E18*10 -> 3450 | G18: =E18/E17 -> 1.15 | H18: 3 | I18: =H18-H17 -> 2 | J18: =OFFSET(装备产出!$W$18,MATCH(H18,装备产出!$E$19:$E$33,1),0) -> 橙0.1 | K18: =H18-H17 -> 2 | L18: =E18*$E$70 -> 448.5 | M18: =LOG((G18-1)/6+1,1.07) -> 0.3649587
D19: 30 | E19: =INT(E18*1.15) -> 396 | F19: =E19*10 -> 3960 | G19: =E19/E18 -> 1.1478261 | H19: 5 | I19: =H19-H18 -> 2 | J19: =OFFSET(装备产出!$W$18,MATCH(H19,装备产出!$E$19:$E$33,1),0) -> 红0.025 | K19: =H19-H18 -> 2 | L19: =E19*$E$71 -> 633.6 | M19: =LOG((G19-1)/6+1,1.07) -> 0.35973329
D20: 40 | E20: =INT(E19*1.15) -> 455 | F20: =E20*10 -> 4550 | G20: =E20/E19 -> 1.1489899 | H20: 7 | I20: =H20-H19 -> 2 | J20: =OFFSET(装备产出!$W$18,MATCH(H20,装备产出!$E$19:$E$33,1),0) -> 红0.05 | K20: =H20-H19 -> 2 | L20: =E20*$E$71 -> 728 | M20: =LOG((G20-1)/6+1,1.07) -> 0.36253096
D21: 50 | E21: =INT(E20*1.15) -> 523 | F21: =E21*10 -> 5230 | G21: =E21/E20 -> 1.1494505 | H21: 11 | I21: =H21-H20 -> 4 | J21: =OFFSET(装备产出!$W$18,MATCH(H21,装备产出!$E$19:$E$33,1),0) -> 红0.075 | K21: =H21-H20 -> 4 | L21: =E21*$E$71 -> 836.8 | M21: =LOG((G21-1)/6+1,1.07) -> 0.36363817
D22: 55 | E22: =(E21+E23)/2 -> 562 | F22: =E22*10 -> 5620 | G22: =E22/E21 -> 1.0745698 | H22: =(H21+H23)/2 -> 14.5 | I22: =H22-H21 -> 3.5 | J22: =OFFSET(装备产出!$W$18,MATCH(H22,装备产出!$E$19:$E$33,1),0) -> 红0.075 | K22: =H22-H21 -> 3.5 | L22: =E22*$E$71 -> 899.2 | M22: =LOG((G22-1)/6+1,1.07) -> 0.18255909
D23: 60 | E23: =INT(E21*1.15) -> 601 | F23: =E23*10 -> 6010 | G23: =E23/E22 -> 1.069395 | H23: 18 | I23: =H23-H22 -> 3.5 | J23: =OFFSET(装备产出!$W$18,MATCH(H23,装备产出!$E$19:$E$33,1),0) -> 粉0.025 | K23: =H23-H22 -> 3.5 | L23: =E23*$E$72 -> 1202 | M23: =LOG((G23-1)/6+1,1.07) -> 0.16996295
D24: 65 | E24: =(E23+E25)/2 -> 646 | F24: =E24*10 -> 6460 | G24: =E24/E23 -> 1.0748752 | H24: =(H23+H25)/2 -> 23 | I24: =H24-H23 -> 5 | J24: =OFFSET(装备产出!$W$18,MATCH(H24,装备产出!$E$19:$E$33,1),0) -> 粉0.04 | K24: =H24-H23 -> 5 | L24: =E24*$E$72 -> 1292 | M24: =LOG((G24-1)/6+1,1.07) -> 0.18330218
D25: 70 | E25: =INT(E23*1.15) -> 691 | F25: =E25*10 -> 6910 | G25: =E25/E24 -> 1.0696594 | H25: 28 | I25: =H25-H24 -> 5 | J25: =OFFSET(装备产出!$W$18,MATCH(H25,装备产出!$E$19:$E$33,1),0) -> 粉0.04 | K25: =H25-H24 -> 5 | L25: =E25*$E$72 -> 1382 | M25: =LOG((G25-1)/6+1,1.07) -> 0.17060686
D26: 75 | E26: =(E25+E27)/2 -> 742.5 | F26: =E26*10 -> 7425 | G26: =E26/E25 -> 1.0745297 | H26: =(H25+H27)/2 -> 35 | I26: =H26-H25 -> 7 | J26: =OFFSET(装备产出!$W$18,MATCH(H26,装备产出!$E$19:$E$33,1),0) -> 粉0.055 | K26: =H26-H25 -> 7 | L26: =E26*$E$72 -> 1485 | M26: =LOG((G26-1)/6+1,1.07) -> 0.18246146
D27: 80 | E27: =INT(E25*1.15) -> 794 | F27: =E27*10 -> 7940 | G27: =E27/E26 -> 1.0693603 | H27: 42 | I27: =H27-H26 -> 7 | J27: =OFFSET(装备产出!$W$18,MATCH(H27,装备产出!$E$19:$E$33,1),0) -> 粉0.075 | K27: =H27-H26 -> 7 | L27: =E27*$E$72 -> 1588 | M27: =LOG((G27-1)/6+1,1.07) -> 0.16987833
D28: 85 | E28: =(E27+E29)/2 -> 853.5 | F28: =E28*10 -> 8535 | G28: =E28/E27 -> 1.074937 | H28: =(H27+H29)/2 -> 49.5 | I28: =H28-H27 -> 7.5 | J28: =OFFSET(装备产出!$W$18,MATCH(H28,装备产出!$E$19:$E$33,1),0) -> 粉0.075 | K28: =H28-H27 -> 7.5 | L28: =E28*$E$72 -> 1707 | M28: =LOG((G28-1)/6+1,1.07) -> 0.18345259
D29: 90 | E29: =INT(E27*1.15) -> 913 | F29: =E29*10 -> 9130 | G29: =E29/E28 -> 1.0697129 | H29: 57 | I29: =H29-H28 -> 7.5 | J29: =OFFSET(装备产出!$W$18,MATCH(H29,装备产出!$E$19:$E$33,1),0) -> 彩0.015 | K29: =H29-H28 -> 7.5 | L29: =E29*$E$73 -> 2282.5 | M29: =LOG((G29-1)/6+1,1.07) -> 0.17073714
D30: 95 | E30: =(E29+E31)/2 -> 981 | F30: =E30*10 -> 9810 | G30: =E30/E29 -> 1.0744797 | H30: =(H29+H31)/2 -> 64.5 | I30: =H30-H29 -> 7.5 | J30: =OFFSET(装备产出!$W$18,MATCH(H30,装备产出!$E$19:$E$33,1),0) -> 彩0.025 | K30: =H30-H29 -> 7.5 | L30: =E30*$E$73 -> 2452.5 | M30: =LOG((G30-1)/6+1,1.07) -> 0.18233998
D31: 100 | E31: =INT(E29*1.15) -> 1049 | F31: =E31*10 -> 10490 | G31: =E31/E30 -> 1.069317 | H31: 72 | I31: =H31-H30 -> 7.5 | J31: =OFFSET(装备产出!$W$18,MATCH(H31,装备产出!$E$19:$E$33,1),0) -> 彩0.025 | K31: =H31-H30 -> 7.5 | L31: =E31*$E$73 -> 2622.5 | M31: =LOG((G31-1)/6+1,1.07) -> 0.16977302
D32: 105 | E32: =(E31+E33)/2 -> 1127.5 | F32: =E32*10 -> 11275 | G32: =E32/E31 -> 1.0748332 | H32: =(H31+H33)/2 -> 82 | I32: =H32-H31 -> 10 | J32: =OFFSET(装备产出!$W$18,MATCH(H32,装备产出!$E$19:$E$33,1),0) -> 彩0.04 | K32: =H32-H31 -> 10 | L32: =E32*$E$73 -> 2818.75 | M32: =LOG((G32-1)/6+1,1.07) -> 0.18319991
D33: 110 | E33: =INT(E31*1.15) -> 1206 | F33: =E33*10 -> 12060 | G33: =E33/E32 -> 1.0696231 | H33: 92 | I33: =H33-H32 -> 10 | J33: =OFFSET(装备产出!$W$18,MATCH(H33,装备产出!$E$19:$E$33,1),0) -> 彩0.04 | K33: =H33-H32 -> 10 | L33: =E33*$E$73 -> 3015 | M33: =LOG((G33-1)/6+1,1.07) -> 0.17051826
D34: 115 | E34: =(E33+E35)/2 -> 1296 | F34: =E34*10 -> 12960 | G34: =E34/E33 -> 1.0746269 | H34: =(H33+H35)/2 -> 102 | I34: =H34-H33 -> 10 | J34: =OFFSET(装备产出!$W$18,MATCH(H34,装备产出!$E$19:$E$33,1),0) -> 彩0.045 | K34: =H34-H33 -> 10 | L34: =E34*$E$73 -> 3240 | M34: =LOG((G34-1)/6+1,1.07) -> 0.18269796
D35: 120 | E35: =INT(E33*1.15) -> 1386 | F35: =E35*10 -> 13860 | G35: =E35/E34 -> 1.0694444 | H35: 112 | I35: =H35-H34 -> 10 | J35: =OFFSET(装备产出!$W$18,MATCH(H35,装备产出!$E$19:$E$33,1),0) -> 彩0.045 | K35: =H35-H34 -> 10 | L35: =E35*$E$73 -> 3465 | M35: =LOG((G35-1)/6+1,1.07) -> 0.17008331
D36: 125 | E36: =(E35+E37)/2 -> 1489.5 | F36: =E36*10 -> 14895 | G36: =E36/E35 -> 1.0746753 | H36: =(H35+H37)/2 -> 122 | I36: =H36-H35 -> 10 | J36: =OFFSET(装备产出!$W$18,MATCH(H36,装备产出!$E$19:$E$33,1),0) -> 彩0.05 | K36: =H36-H35 -> 10 | L36: =E36*$E$73 -> 3723.75 | M36: =LOG((G36-1)/6+1,1.07) -> 0.18281586
D37: 130 | E37: =INT(E35*1.15) -> 1593 | F37: =E37*10 -> 15930 | G37: =E37/E36 -> 1.0694864 | H37: 132 | I37: =H37-H36 -> 10 | J37: =OFFSET(装备产出!$W$18,MATCH(H37,装备产出!$E$19:$E$33,1),0) -> 彩0.05 | K37: =H37-H36 -> 10 | L37: =E37*$E$73 -> 3982.5 | M37: =LOG((G37-1)/6+1,1.07) -> 0.17018549
D38: 135 | E38: =(E37+E39)/2 -> 1712 | F38: =E38*10 -> 17120 | G38: =E38/E37 -> 1.0747018 | H38: =(H37+H39)/2 -> 142 | I38: =H38-H37 -> 10 | J38: =OFFSET(装备产出!$W$18,MATCH(H38,装备产出!$E$19:$E$33,1),0) -> 彩0.055 | K38: =H38-H37 -> 10 | L38: =E38*$E$73 -> 4280 | M38: =LOG((G38-1)/6+1,1.07) -> 0.18288033
D39: 140 | E39: =INT(E37*1.15) -> 1831 | F39: =E39*10 -> 18310 | G39: =E39/E38 -> 1.0695093 | H39: 152 | I39: =H39-H38 -> 10 | J39: =OFFSET(装备产出!$W$18,MATCH(H39,装备产出!$E$19:$E$33,1),0) -> 彩0.055 | K39: =H39-H38 -> 10 | L39: =E39*$E$73 -> 4577.5 | M39: =LOG((G39-1)/6+1,1.07) -> 0.17024135
D40: 145 | E40: =(E39+E41)/2 -> 1968 | F40: =E40*10 -> 19680 | G40: =E40/E39 -> 1.0748225 | H40: =(H39+H41)/2 -> 162 | I40: =H40-H39 -> 10 | J40: =OFFSET(装备产出!$W$18,MATCH(H40,装备产出!$E$19:$E$33,1),0) -> 彩0.055 | K40: =H40-H39 -> 10 | L40: =E40*$E$73 -> 4920 | M40: =LOG((G40-1)/6+1,1.07) -> 0.18317395
D41: 150 | E41: =INT(E39*1.15) -> 2105 | F41: =E41*10 -> 21050 | G41: =E41/E40 -> 1.0696138 | H41: 172 | I41: =H41-H40 -> 10 | J41: =OFFSET(装备产出!$W$18,MATCH(H41,装备产出!$E$19:$E$33,1),0) -> 彩0.055 | K41: =H41-H40 -> 10 | L41: =E41*$E$73 -> 5262.5 | M41: =LOG((G41-1)/6+1,1.07) -> 0.17049576
D42: 155 | E42: =(E41+E43)/2 -> 2262.5 | F42: =E42*10 -> 22625 | G42: =E42/E41 -> 1.0748219 | H42: =(H41+H43)/2 -> 182 | I42: =H42-H41 -> 10 | J42: =OFFSET(装备产出!$W$18,MATCH(H42,装备产出!$E$19:$E$33,1),0) -> 彩0.055 | K42: =H42-H41 -> 10 | L42: =E42*$E$73 -> 5656.25 | M42: =LOG((G42-1)/6+1,1.07) -> 0.18317237
D43: 160 | E43: =INT(E41*1.15) -> 2420 | F43: =E43*10 -> 24200 | G43: =E43/E42 -> 1.0696133 | H43: 192 | I43: =H43-H42 -> 10 | J43: =OFFSET(装备产出!$W$18,MATCH(H43,装备产出!$E$19:$E$33,1),0) -> 彩0.055 | K43: =H43-H42 -> 10 | L43: =E43*$E$73 -> 6050 | M43: =LOG((G43-1)/6+1,1.07) -> 0.1704944
D44: 165 | E44: =(E43+E45)/2 -> 2601.5 | F44: =E44*10 -> 26015 | G44: =E44/E43 -> 1.075 | H44: =(H43+H45)/2 -> 205 | I44: =H44-H43 -> 13 | J44: =OFFSET(装备产出!$W$18,MATCH(H44,装备产出!$E$19:$E$33,1),0) -> 彩0.055 | K44: =H44-H43 -> 13 | L44: =E44*$E$73 -> 6503.75 | M44: =LOG((G44-1)/6+1,1.07) -> 0.1836058
D45: 170 | E45: =INT(E43*1.15) -> 2783 | F45: =E45*10 -> 27830 | G45: =E45/E44 -> 1.0697674 | H45: 218 | I45: =H45-H44 -> 13 | J45: =OFFSET(装备产出!$W$18,MATCH(H45,装备产出!$E$19:$E$33,1),0) -> 彩0.055 | K45: =H45-H44 -> 13 | L45: =E45*$E$73 -> 6957.5 | M45: =LOG((G45-1)/6+1,1.07) -> 0.17086984
...

Sheet 装备产出
A1: 装备本体
D3: 满级参数
D4: 养成周期/天 | E4: 180 | F4: *引用商业化框架
D5: 单个深度(钻石) | E5: 60000 | F5: *引用商业化框架
D6: 每日产出(钻石) | E6: 2000
D8: 道具 | E8: 定价
D9: 装备洗练石 | E9: 1
D10: 装备强化书 | E10: 3
P11: =400*0.32/20 -> 6.4
A12: 装备产出
C14: 装备产出
D15: #先用他们的拍一版本
D16: #不提倡扫荡，只关注合作本产出（合作本可以让大R带，暂时不考虑分层），扫荡只有白~蓝，30%高10级，10%高20级（10倍坑深） | S16: #单次副本可洗练次数 | U16: #预估
D18: 组队副本 | E18: 预计通关天数 | F18: 白 | G18: 绿 | H18: 蓝 | I18: 紫 | J18: 橙 | K18: 红 | L18: 粉 | M18: 彩 | N18: 装备等级 | O18: 转运产出 | P18: 总产/天 | S18: 洗练步长 | T18: 分解步长 | U18: 每日次数 | V18: 每日产出 | W18: 装备品质 | Z18: 平均件数
D19: 1 | E19: 1 | F19: 0.1 | G19: 0.35 | H19: 0.3 | I19: 0.2 | J19: 0.05 | N19: =OFFSET(装备属性!$D$15,MATCH($E19,装备属性!$H$16:$H$61,1),0) -> 10 | O19: {=SUMPRODUCT(F19:M19,OFFSET($E$121:$L$121,MATCH(N19,$D$122:$D$147,0),0))*5} -> 390 | P19: =O19*5 -> 1950 | Q19: =P19/10*0.05*3.5 -> 34.125 | R19: =P19/10*0.05 -> 9.75 | S19: {=SUMPRODUCT($F19:$M19,OFFSET(E$92:L$92,MATCH(N19,$D$93:$D$118,0),0))*$E$74/OFFSET($N$92,MATCH(N19,$N$93:$N$118,0),MATCH(OFFSET($H$18,0,MATCH(MIN(H19:M19),H19:M19,0)-1),$O$92:$V$92,0))} -> 4.7454545 | T19: {=SUMPRODUCT($F19:$M19,OFFSET(E$121:L$121,MATCH(N19,$D$93:$D$118,0),0))*$E$74*3} -> 1404 | U19: 4 | V19: =_xlfn.MINIFS(F19:M19,F19:M19,">"&0)*$E$74*U19 -> 1.2 | W19: =OFFSET($E$18,0,MATCH(_xlfn.MINIFS(F19:M19,F19:M19,">"&0),F19:M19,0))&OFFSET($E19,0,MATCH(_xlfn.MINIFS(F19:M19,F19:M19,">"&0),F19:M19,0)) -> 橙0.05 | Z19: =6/6 -> 1
D20: 2 | E20: 2 | F20: 0 | G20: 0.25 | H20: 0.4 | I20: 0.25 | J20: 0.1 | N20: =OFFSET(装备属性!$D$15,MATCH($E20,装备属性!$H$16:$H$61,1),0) -> 10 | O20: {=SUMPRODUCT(F20:M20,OFFSET($E$121:$L$121,MATCH(N20,$D$122:$D$147,0),0))*5} -> 444 | P20: =O20*5 -> 2220 | Q20: =P20/10*0.05*3.5 -> 38.85 | R20: =P20/10*0.05 -> 11.1 | S20: {=SUMPRODUCT($F20:$M20,OFFSET(E$92:L$92,MATCH(N20,$D$93:$D$118,0),0))*$E$74/OFFSET($N$92,MATCH(N20,$N$93:$N$118,0),MATCH(OFFSET($H$18,0,MATCH(MIN(H20:M20),H20:M20,0)-1),$O$92:$V$92,0))} -> 5.7272727 | T20: {=SUMPRODUCT($F20:$M20,OFFSET(E$121:L$121,MATCH(N20,$D$93:$D$118,0),0))*$E$74*3} -> 1598.4 | U20: 4 | V20: =_xlfn.MINIFS(F20:M20,F20:M20,">"&0)*$E$74*U20 -> 2.4 | W20: =OFFSET($E$18,0,MATCH(_xlfn.MINIFS(F20:M20,F20:M20,">"&0),F20:M20,0))&OFFSET($E20,0,MATCH(_xlfn.MINIFS(F20:M20,F20:M20,">"&0),F20:M20,0)) -> 橙0.1 | Z20: =6/6+6/5 -> 2.2
D21: 3 | E21: 4 | F21: 0 | G21: 0.2 | H21: 0.4 | I21: 0.25 | J21: 0.125 | K21: 0.025 | N21: =OFFSET(装备属性!$D$15,MATCH($E21,装备属性!$H$16:$H$61,1),0) -> 20 | O21: {=SUMPRODUCT(F21:M21,OFFSET($E$121:$L$121,MATCH(N21,$D$122:$D$147,0),0))*5} -> 566.25 | P21: =O21*5 -> 2831.25 | Q21: =P21/10*0.05*3.5 -> 49.546875 | R21: =P21/10*0.05 -> 14.15625 | S21: {=SUMPRODUCT($F21:$M21,OFFSET(E$92:L$92,MATCH(N21,$D$93:$D$118,0),0))*$E$74/OFFSET($N$92,MATCH(N21,$N$93:$N$118,0),MATCH(OFFSET($H$18,0,MATCH(MIN(H21:M21),H21:M21,0)-1),$O$92:$V$92,0))} -> 4.8176471 | T21: {=SUMPRODUCT($F21:$M21,OFFSET(E$121:L$121,MATCH(N21,$D$93:$D$118,0),0))*$E$74*3} -> 2038.5 | U21: 4 | V21: =_xlfn.MINIFS(F21:M21,F21:M21,">"&0)*$E$74*U21 -> 0.6 | W21: =OFFSET($E$18,0,MATCH(_xlfn.MINIFS(F21:M21,F21:M21,">"&0),F21:M21,0))&OFFSET($E21,0,MATCH(_xlfn.MINIFS(F21:M21,F21:M21,">"&0),F21:M21,0)) -> 红0.025 | Z21: =6/6+6/5+6/4 -> 3.7
D22: 4 | E22: 7 | F22: 0 | G22: 0.175 | H22: 0.4 | I22: 0.25 | J22: 0.125 | K22: 0.05 | N22: =OFFSET(装备属性!$D$15,MATCH($E22,装备属性!$H$16:$H$61,1),0) -> 40 | O22: {=SUMPRODUCT(F22:M22,OFFSET($E$121:$L$121,MATCH(N22,$D$122:$D$147,0),0))*5} -> 819.75 | P22: =O22*5 -> 4098.75 | Q22: =P22/10*0.05*3.5 -> 71.728125 | R22: =P22/10*0.05 -> 20.49375 | S22: {=SUMPRODUCT($F22:$M22,OFFSET(E$92:L$92,MATCH(N22,$D$93:$D$118,0),0))*$E$74/OFFSET($N$92,MATCH(N22,$N$93:$N$118,0),MATCH(OFFSET($H$18,0,MATCH(MIN(H22:M22),H22:M22,0)-1),$O$92:$V$92,0))} -> 5.2116279 | T22: {=SUMPRODUCT($F22:$M22,OFFSET(E$121:L$121,MATCH(N22,$D$93:$D$118,0),0))*$E$74*3} -> 2951.1 | U22: 4 | V22: =_xlfn.MINIFS(F22:M22,F22:M22,">"&0)*$E$74*U22 -> 1.2 | W22: =OFFSET($E$18,0,MATCH(_xlfn.MINIFS(F22:M22,F22:M22,">"&0),F22:M22,0))&OFFSET($E22,0,MATCH(_xlfn.MINIFS(F22:M22,F22:M22,">"&0),F22:M22,0)) -> 红0.05 | Z22: =6/6+6/5+6/4+6/3 -> 5.7
D23: 5 | E23: 11 | F23: 0 | G23: 0.125 | H23: 0.4 | I23: 0.25 | J23: 0.15 | K23: 0.075 | N23: =OFFSET(装备属性!$D$15,MATCH($E23,装备属性!$H$16:$H$61,1),0) -> 50 | O23: {=SUMPRODUCT(F23:M23,OFFSET($E$121:$L$121,MATCH(N23,$D$122:$D$147,0),0))*5} -> 1022.5 | P23: =O23*5 -> 5112.5 | Q23: =P23/10*0.05*3.5 -> 89.46875 | R23: =P23/10*0.05 -> 25.5625 | S23: {=SUMPRODUCT($F23:$M23,OFFSET(E$92:L$92,MATCH(N23,$D$93:$D$118,0),0))*$E$74/OFFSET($N$92,MATCH(N23,$N$93:$N$118,0),MATCH(OFFSET($H$18,0,MATCH(MIN(H23:M23),H23:M23,0)-1),$O$92:$V$92,0))} -> 5.8085106 | T23: {=SUMPRODUCT($F23:$M23,OFFSET(E$121:L$121,MATCH(N23,$D$93:$D$118,0),0))*$E$74*3} -> 3681 | U23: 4 | V23: =_xlfn.MINIFS(F23:M23,F23:M23,">"&0)*$E$74*U23 -> 1.8 | W23: =OFFSET($E$18,0,MATCH(_xlfn.MINIFS(F23:M23,F23:M23,">"&0),F23:M23,0))&OFFSET($E23,0,MATCH(_xlfn.MINIFS(F23:M23,F23:M23,">"&0),F23:M23,0)) -> 红0.075 | Z23: =6/6+6/5+6/4+6/3+6/2 -> 8.7
D24: 6 | E24: 16 | F24: 0 | G24: 0.075 | H24: 0.4 | I24: 0.25 | J24: 0.15 | K24: 0.1 | L24: 0.025 | N24: =OFFSET(装备属性!$D$15,MATCH($E24,装备属性!$H$16:$H$61,1),0) -> 55 | O24: {=SUMPRODUCT(F24:M24,OFFSET($E$121:$L$121,MATCH(N24,$D$122:$D$147,0),0))*5} -> 1292.5 | P24: =O24*5 -> 6462.5 | Q24: =P24/10*0.05*3.5 -> 113.09375 | R24: =P24/10*0.05 -> 32.3125 | S24: {=SUMPRODUCT($F24:$M24,OFFSET(E$92:L$92,MATCH(N24,$D$93:$D$118,0),0))*$E$74/OFFSET($N$92,MATCH(N24,$N$93:$N$118,0),MATCH(OFFSET($H$18,0,MATCH(MIN(H24:M24),H24:M24,0)-1),$O$92:$V$92,0))} -> #N/A | T24: {=SUMPRODUCT($F24:$M24,OFFSET(E$121:L$121,MATCH(N24,$D$93:$D$118,0),0))*$E$74*3} -> #N/A | U24: 4 | V24: =_xlfn.MINIFS(F24:M24,F24:M24,">"&0)*$E$74*U24 -> 0.6 | W24: =OFFSET($E$18,0,MATCH(_xlfn.MINIFS(F24:M24,F24:M24,">"&0),F24:M24,0))&OFFSET($E24,0,MATCH(_xlfn.MINIFS(F24:M24,F24:M24,">"&0),F24:M24,0)) -> 粉0.025 | Z24: =6/6+6/5+6/4+6/3+6/2+6/1 -> 14.7
D25: 7 | E25: 22 | F25: 0 | G25: 0 | H25: 0.36 | I25: 0.32 | J25: 0.16 | K25: 0.12 | L25: 0.04 | N25: =OFFSET(装备属性!$D$15,MATCH($E25,装备属性!$H$16:$H$61,1),0) -> 60 | O25: {=SUMPRODUCT(F25:M25,OFFSET($E$121:$L$121,MATCH(N25,$D$122:$D$147,0),0))*5} -> 1626 | P25: =O25*5 -> 8130 | Q25: =P25/10*0.05*3.5 -> 142.275 | R25: =P25/10*0.05 -> 40.65 | S25: {=SUMPRODUCT($F25:$M25,OFFSET(E$92:L$92,MATCH(N25,$D$93:$D$118,0),0))*$E$74/OFFSET($N$92,MATCH(N25,$N$93:$N$118,0),MATCH(OFFSET($H$18,0,MATCH(MIN(H25:M25),H25:M25,0)-1),$O$92:$V$92,0))} -> 6.1768421 | T25: {=SUMPRODUCT($F25:$M25,OFFSET(E$121:L$121,MATCH(N25,$D$93:$D$118,0),0))*$E$74*3} -> 4960.8 | U25: 4 | V25: =_xlfn.MINIFS(F25:M25,F25:M25,">"&0)*$E$74*U25 -> 0.96 | W25: =OFFSET($E$18,0,MATCH(_xlfn.MINIFS(F25:M25,F25:M25,">"&0),F25:M25,0))&OFFSET($E25,0,MATCH(_xlfn.MINIFS(F25:M25,F25:M25,">"&0),F25:M25,0)) -> 粉0.04
D26: 8 | E26: 32 | F26: 0 | G26: 0 | H26: 0.3 | I26: 0.34 | J26: 0.17 | K26: 0.135 | L26: 0.055 | N26: =OFFSET(装备属性!$D$15,MATCH($E26,装备属性!$H$16:$H$61,1),0) -> 70 | O26: {=SUMPRODUCT(F26:M26,OFFSET($E$121:$L$121,MATCH(N26,$D$122:$D$147,0),0))*5} -> 2392.5 | P26: =O26*5 -> 11962.5 | Q26: =P26/10*0.05*3.5 -> 209.34375 | R26: =P26/10*0.05 -> 59.8125 | S26: {=SUMPRODUCT($F26:$M26,OFFSET(E$92:L$92,MATCH(N26,$D$93:$D$118,0),0))*$E$74/OFFSET($N$92,MATCH(N26,$N$93:$N$118,0),MATCH(OFFSET($H$18,0,MATCH(MIN(H26:M26),H26:M26,0)-1),$O$92:$V$92,0))} -> 6.8918182 | T26: {=SUMPRODUCT($F26:$M26,OFFSET(E$121:L$121,MATCH(N26,$D$93:$D$118,0),0))*$E$74*3} -> 6036.3 | U26: 4 | V26: =_xlfn.MINIFS(F26:M26,F26:M26,">"&0)*$E$74*U26 -> 1.32 | W26: =OFFSET($E$18,0,MATCH(_xlfn.MINIFS(F26:M26,F26:M26,">"&0),F26:M26,0))&OFFSET($E26,0,MATCH(_xlfn.MINIFS(F26:M26,F26:M26,">"&0),F26:M26,0)) -> 粉0.055 | Z26: 品质 | AA26: 停留时间
D27: 9 | E27: 42 | F27: 0 | G27: 0 | H27: 0.245 | I27: 0.35 | J27: 0.18 | K27: 0.15 | L27: 0.075 | N27: =OFFSET(装备属性!$D$15,MATCH($E27,装备属性!$H$16:$H$61,1),0) -> 80 | O27: {=SUMPRODUCT(F27:M27,OFFSET($E$121:$L$121,MATCH(N27,$D$122:$D$147,0),0))*5} -> 2678.4 | P27: =O27*5 -> 13392 | Q27: =P27/10*0.05*3.5 -> 234.36 | R27: =P27/10*0.05 -> 66.96 | S27: {=SUMPRODUCT($F27:$M27,OFFSET(E$92:L$92,MATCH(N27,$D$93:$D$118,0),0))*$E$74/OFFSET($N$92,MATCH(N27,$N$93:$N$118,0),MATCH(OFFSET($H$18,0,MATCH(MIN(H27:M27),H27:M27,0)-1),$O$92:$V$92,0))} -> 7.830303 | T27: {=SUMPRODUCT($F27:$M27,OFFSET(E$121:L$121,MATCH(N27,$D$93:$D$118,0),0))*$E$74*3} -> 7463.52 | U27: 4 | V27: =_xlfn.MINIFS(F27:M27,F27:M27,">"&0)*$E$74*U27 -> 1.8 | W27: =OFFSET($E$18,0,MATCH(_xlfn.MINIFS(F27:M27,F27:M27,">"&0),F27:M27,0))&OFFSET($E27,0,MATCH(_xlfn.MINIFS(F27:M27,F27:M27,">"&0),F27:M27,0)) -> 粉0.075 | Z27: 橙 | AA27: 1
D28: 10 | E28: 52 | F28: 0 | G28: 0 | H28: 0.15 | I28: 0.38 | J28: 0.2 | K28: 0.165 | L28: 0.09 | M28: 0.015 | N28: =OFFSET(装备属性!$D$15,MATCH($E28,装备属性!$H$16:$H$61,1),0) -> 85 | O28: {=SUMPRODUCT(F28:M28,OFFSET($E$121:$L$121,MATCH(N28,$D$122:$D$147,0),0))*5} -> 2964.7 | P28: =O28*5 -> 14823.5 | Q28: =P28/10*0.05*3.5 -> 259.41125 | R28: =P28/10*0.05 -> 74.1175 | S28: {=SUMPRODUCT($F28:$M28,OFFSET(E$92:L$92,MATCH(N28,$D$93:$D$118,0),0))*$E$74/OFFSET($N$92,MATCH(N28,$N$93:$N$118,0),MATCH(OFFSET($H$18,0,MATCH(MIN(H28:M28),H28:M28,0)-1),$O$92:$V$92,0))} -> #N/A | T28: {=SUMPRODUCT($F28:$M28,OFFSET(E$121:L$121,MATCH(N28,$D$93:$D$118,0),0))*$E$74*3} -> #N/A | U28: 4 | V28: =_xlfn.MINIFS(F28:M28,F28:M28,">"&0)*$E$74*U28 -> 0.36 | W28: =OFFSET($E$18,0,MATCH(_xlfn.MINIFS(F28:M28,F28:M28,">"&0),F28:M28,0))&OFFSET($E28,0,MATCH(_xlfn.MINIFS(F28:M28,F28:M28,">"&0),F28:M28,0)) -> 彩0.015 | Z28: 红 | AA28: 3
D29: 11 | E29: 62 | F29: 0 | G29: 0 | H29: 0 | I29: 0.44 | J29: 0.25 | K29: 0.185 | L29: 0.1 | M29: 0.025 | N29: =OFFSET(装备属性!$D$15,MATCH($E29,装备属性!$H$16:$H$61,1),0) -> 90 | O29: {=SUMPRODUCT(F29:M29,OFFSET($E$121:$L$121,MATCH(N29,$D$122:$D$147,0),0))*5} -> 3302 | P29: =O29*5 -> 16510 | Q29: =P29/10*0.05*3.5 -> 288.925 | R29: =P29/10*0.05 -> 82.55 | S29: {=SUMPRODUCT($F29:$M29,OFFSET(E$92:L$92,MATCH(N29,$D$93:$D$118,0),0))*$E$74/OFFSET($N$92,MATCH(N29,$N$93:$N$118,0),MATCH(OFFSET($H$18,0,MATCH(MIN(H29:M29),H29:M29,0)-1),$O$92:$V$92,0))} -> #DIV/0! | T29: {=SUMPRODUCT($F29:$M29,OFFSET(E$121:L$121,MATCH(N29,$D$93:$D$118,0),0))*$E$74*3} -> 9900 | U29: 4 | V29: =_xlfn.MINIFS(F29:M29,F29:M29,">"&0)*$E$74*U29 -> 0.6 | W29: =OFFSET($E$18,0,MATCH(_xlfn.MINIFS(F29:M29,F29:M29,">"&0),F29:M29,0))&OFFSET($E29,0,MATCH(_xlfn.MINIFS(F29:M29,F29:M29,">"&0),F29:M29,0)) -> 彩0.025 | Z29: 粉 | AA29: 10
D30: 12 | E30: 82 | F30: 0 | G30: 0 | H30: 0 | I30: 0.4 | J30: 0.25 | K30: 0.2 | L30: 0.11 | M30: 0.04 | N30: =OFFSET(装备属性!$D$15,MATCH($E30,装备属性!$H$16:$H$61,1),0) -> 105 | O30: {=SUMPRODUCT(F30:M30,OFFSET($E$121:$L$121,MATCH(N30,$D$122:$D$147,0),0))*5} -> 3835.2 | P30: =O30*5 -> 19176 | Q30: =P30/10*0.05*3.5 -> 335.58 | R30: =P30/10*0.05 -> 95.88 | S30: {=SUMPRODUCT($F30:$M30,OFFSET(E$92:L$92,MATCH(N30,$D$93:$D$118,0),0))*$E$74/OFFSET($N$92,MATCH(N30,$N$93:$N$118,0),MATCH(OFFSET($H$18,0,MATCH(MIN(H30:M30),H30:M30,0)-1),$O$92:$V$92,0))} -> #N/A | T30: {=SUMPRODUCT($F30:$M30,OFFSET(E$121:L$121,MATCH(N30,$D$93:$D$118,0),0))*$E$74*3} -> #N/A | U30: 4 | V30: =_xlfn.MINIFS(F30:M30,F30:M30,">"&0)*$E$74*U30 -> 0.96 | W30: =OFFSET($E$18,0,MATCH(_xlfn.MINIFS(F30:M30,F30:M30,">"&0),F30:M30,0))&OFFSET($E30,0,MATCH(_xlfn.MINIFS(F30:M30,F30:M30,">"&0),F30:M30,0)) -> 彩0.04 | Z30: 彩 | AA30: 20
D31: 13 | E31: 102 | F31: 0 | G31: 0 | H31: 0 | I31: 0.385 | J31: 0.25 | K31: 0.2 | L31: 0.12 | M31: 0.045 | N31: =OFFSET(装备属性!$D$15,MATCH($E31,装备属性!$H$16:$H$61,1),0) -> 115 | O31: {=SUMPRODUCT(F31:M31,OFFSET($E$121:$L$121,MATCH(N31,$D$122:$D$147,0),0))*5} -> 4262.5 | P31: =O31*5 -> 21312.5 | Q31: =P31/10*0.05*3.5 -> 372.96875 | R31: =P31/10*0.05 -> 106.5625 | S31: {=SUMPRODUCT($F31:$M31,OFFSET(E$92:L$92,MATCH(N31,$D$93:$D$118,0),0))*$E$74/OFFSET($N$92,MATCH(N31,$N$93:$N$118,0),MATCH(OFFSET($H$18,0,MATCH(MIN(H31:M31),H31:M31,0)-1),$O$92:$V$92,0))} -> #N/A | T31: {=SUMPRODUCT($F31:$M31,OFFSET(E$121:L$121,MATCH(N31,$D$93:$D$118,0),0))*$E$74*3} -> #N/A | U31: 4 | V31: =_xlfn.MINIFS(F31:M31,F31:M31,">"&0)*$E$74*U31 -> 1.08 | W31: =OFFSET($E$18,0,MATCH(_xlfn.MINIFS(F31:M31,F31:M31,">"&0),F31:M31,0))&OFFSET($E31,0,MATCH(_xlfn.MINIFS(F31:M31,F31:M31,">"&0),F31:M31,0)) -> 彩0.045
D32: 14 | E32: 122 | F32: 0 | G32: 0 | H32: 0 | I32: 0.365 | J32: 0.25 | K32: 0.2 | L32: 0.135 | M32: 0.05 | N32: =OFFSET(装备属性!$D$15,MATCH($E32,装备属性!$H$16:$H$61,1),0) -> 125 | O32: {=SUMPRODUCT(F32:M32,OFFSET($E$121:$L$121,MATCH(N32,$D$122:$D$147,0),0))*5} -> 4719.1 | P32: =O32*5 -> 23595.5 | Q32: =P32/10*0.05*3.5 -> 412.92125 | R32: =P32/10*0.05 -> 117.9775 | S32: {=SUMPRODUCT($F32:$M32,OFFSET(E$92:L$92,MATCH(N32,$D$93:$D$118,0),0))*$E$74/OFFSET($N$92,MATCH(N32,$N$93:$N$118,0),MATCH(OFFSET($H$18,0,MATCH(MIN(H32:M32),H32:M32,0)-1),$O$92:$V$92,0))} -> #N/A | T32: {=SUMPRODUCT($F32:$M32,OFFSET(E$121:L$121,MATCH(N32,$D$93:$D$118,0),0))*$E$74*3} -> #N/A | U32: 4 | V32: =_xlfn.MINIFS(F32:M32,F32:M32,">"&0)*$E$74*U32 -> 1.2 | W32: =OFFSET($E$18,0,MATCH(_xlfn.MINIFS(F32:M32,F32:M32,">"&0),F32:M32,0))&OFFSET($E32,0,MATCH(_xlfn.MINIFS(F32:M32,F32:M32,">"&0),F32:M32,0)) -> 彩0.05
D33: 15 | E33: 142 | F33: 0 | G33: 0 | H33: 0 | I33: 0.345 | J33: 0.25 | K33: 0.2 | L33: 0.15 | M33: 0.055 | N33: =OFFSET(装备属性!$D$15,MATCH($E33,装备属性!$H$16:$H$61,1),0) -> 135 | O33: {=SUMPRODUCT(F33:M33,OFFSET($E$121:$L$121,MATCH(N33,$D$122:$D$147,0),0))*5} -> 5238 | P33: =O33*5 -> 26190 | Q33: =P33/10*0.05*3.5 -> 458.325 | R33: =P33/10*0.05 -> 130.95 | S33: {=SUMPRODUCT($F33:$M33,OFFSET(E$92:L$92,MATCH(N33,$D$93:$D$118,0),0))*$E$74/OFFSET($N$92,MATCH(N33,$N$93:$N$118,0),MATCH(OFFSET($H$18,0,MATCH(MIN(H33:M33),H33:M33,0)-1),$O$92:$V$92,0))} -> #N/A | T33: {=SUMPRODUCT($F33:$M33,OFFSET(E$121:L$121,MATCH(N33,$D$93:$D$118,0),0))*$E$74*3} -> #N/A | U33: 4 | V33: =_xlfn.MINIFS(F33:M33,F33:M33,">"&0)*$E$74*U33 -> 1.32 | W33: =OFFSET($E$18,0,MATCH(_xlfn.MINIFS(F33:M33,F33:M33,">"&0),F33:M33,0))&OFFSET($E33,0,MATCH(_xlfn.MINIFS(F33:M33,F33:M33,">"&0),F33:M33,0)) -> 彩0.055
D35: 当前等级
D36: z主线副本 | E36: 预计通关天数 | F36: 白 | G36: 绿 | H36: 蓝 | I36: 紫 | J36: 橙 | K36: 红 | L36: 粉 | M36: 彩 | P36: 1 | Q36: 橙
D37: 1~10 | E37: 1 | F37: 0.8 | G37: 0.2
D38: 11~20 | E38: 1 | F38: 0.8 | G38: 0.2
D39: 21~30 | E39: 3 | F39: 0.8 | G39: 0.2
D40: 31~40 | E40: 5 | F40: 0.6 | G40: 0.3 | H40: 0.1
D41: 41~50 | E41: 8 | F41: 0.6 | G41: 0.3 | H41: 0.1
D42: 51~60 | E42: 12 | F42: 0.6 | G42: 0.3 | H42: 0.1
D43: 61~70 | E43: 19 | F43: 0.55 | G43: 0.3 | H43: 0.15
D44: 71~80 | E44: 30 | F44: 0.55 | G44: 0.3 | H44: 0.15
D45: 81~90 | E45: 50 | F45: 0.55 | G45: 0.3 | H45: 0.15
...

Sheet 装备词条库配置
A1: 附加词条抽取库id | B1: 词条id 库id*10+序号 | C1: 词条品质 | D1: 权重 | F1: 效果id 对应effect_mapping_data表的id | G1: 效果组 （同效果高低等级的两个为一组） 可以跟effect_mapping_data表的效果组不一样 | H1: 属性加成 | I1: 是否放回 | J1: 战力 | K1: 排序 | L1: 描述
A2: random_effect_pool | B2: id | C2: quality | D2: weight | F2: effect_id | G2: effect_group | H2: attr_up | I2: is_back | J2: power | K2: sort | L2: desc_show
B3: =A3*10+1 -> 1 | C3: 紫 | D3: 1000 | F3: 1051 | G3: 1051 | I3: 不放回 | M3: 紫 | N3: 4
M4: 橙 | N4: 5
M5: 红 | N5: 6
M6: 粉 | N6: 7
M7: 彩 | N7: 8
A11: =IFERROR(R11+IF(Q11="通用属性",1,IF(Q11="玩法类",2,IF(Q11="稀有词条",3,0))),"") -> 10401 | B11: =IFERROR(R11+COUNTIFS($R$11:$R11,R11),"") -> 10401 | C11: 紫 | D11: 3000 | F11: =IFERROR(R11+INT((B11-R11-1)/5),"") -> 10400 | G11: =IF(AND(LEFT("[{"&M11&","&CEILING(N11*10000+(O11-N11)/4*(COUNTIF($F$11:F11,F11)-1)*10000,10)&"}]",7)="[{equip",MID("[{"&M11&","&CEILING(N11*10000+(O11-N11)/4*(COUNTIF($F$11:F11,F11)-1)*10000,10)&"}]",8,1)<>"_"),"[{"&M11&","&1&"}]","[{"&M11&","&CEILING(N11*10000+(O11-N11)/4*(COUNTIF($F$11:F11,F11)-1)*10000,10)&"}]") -> [{global_dmg_rate,300}] | H11: 不放回 | J11: 1 | K11: =IF(RIGHT(G11,13)="rune_slot,1}]",_xlfn.XLOOKUP(LEFT(SUBSTITUTE(G11,"[{",""),FIND(",",SUBSTITUTE(G11,"[{",""))-1),Sheet2!B:B,Sheet2!C:C)&"+"&1,_xlfn.XLOOKUP(LEFT(SUBSTITUTE(G11,"[{",""),FIND(",",SUBSTITUTE(G11,"[{",""))-1),Sheet2!B:B,Sheet2!C:C)&"+"&SUBSTITUTE(RIGHT(G11,LEN(G11)-FIND(",",G11)),"}]","")/100&"%") -> 伤害加成+3% | L11: 全职小队Ⅰ | M11: global_dmg_rate | N11: =装备属性!K1084 -> 0.03 | O11: =装备属性!L1084 -> 0.042 | Q11: 通用属性 | R11: 10400
A12: =IFERROR(R12+IF(Q12="通用属性",1,IF(Q12="玩法类",2,IF(Q12="稀有词条",3,0))),"") -> 10401 | B12: =IFERROR(R12+COUNTIFS($R$11:$R12,R12),"") -> 10402 | C12: =IF(MOD(COUNTIF($Q$11:Q11,Q11),5)=0,OFFSET(装备属性!$D$1083,1+INT(COUNTA($Q$11:Q11)/5),0),C11) -> 紫 | D12: 2500 | F12: =IFERROR(R12+INT((B12-R12-1)/5),"") -> 10400 | G12: =IF(AND(LEFT("[{"&M12&","&CEILING(N12*10000+(O12-N12)/4*(COUNTIF($F$11:F12,F12)-1)*10000,10)&"}]",7)="[{equip",MID("[{"&M12&","&CEILING(N12*10000+(O12-N12)/4*(COUNTIF($F$11:F12,F12)-1)*10000,10)&"}]",8,1)<>"_"),"[{"&M12&","&1&"}]","[{"&M12&","&CEILING(N12*10000+(O12-N12)/4*(COUNTIF($F$11:F12,F12)-1)*10000,10)&"}]") -> [{global_dmg_rate,330}] | H12: 不放回 | J12: =IF(MOD(COUNTIF($Q$11:Q11,Q11),5)=0,OFFSET(装备属性!$P$1083,1+INT(COUNTA($Q$11:Q11)/5),0),J11) -> 1 | K12: =IF(RIGHT(G12,13)="rune_slot,1}]",_xlfn.XLOOKUP(LEFT(SUBSTITUTE(G12,"[{",""),FIND(",",SUBSTITUTE(G12,"[{",""))-1),Sheet2!B:B,Sheet2!C:C)&"+"&1,_xlfn.XLOOKUP(LEFT(SUBSTITUTE(G12,"[{",""),FIND(",",SUBSTITUTE(G12,"[{",""))-1),Sheet2!B:B,Sheet2!C:C)&"+"&SUBSTITUTE(RIGHT(G12,LEN(G12)-FIND(",",G12)),"}]","")/100&"%") -> 伤害加成+3.3% | L12: =IF(MOD(COUNTIF($Q$11:Q11,Q11),5)=0,OFFSET(装备属性!$G$1083,1+INT(COUNTA($Q$11:Q11)/5),0),L11) -> 全职小队Ⅰ | M12: =IF(MOD(COUNTIF($Q$11:Q11,Q11),5)=0,OFFSET(装备属性!$H$1083,1+INT(COUNTA($Q$11:Q11)/5),0),M11) -> global_dmg_rate | N12: =IF(MOD(COUNTIF($Q$11:Q11,Q11),5)=0,OFFSET(装备属性!$K$1083,1+INT(COUNTA($Q$11:Q11)/5),0),N11) -> 0.03 | O12: =IF(MOD(COUNTIF($Q$11:Q11,Q11),5)=0,OFFSET(装备属性!$L$1083,1+INT(COUNTA($Q$11:Q11)/5),0),O11) -> 0.042 | Q12: =IF(MOD(COUNTIF($Q$11:Q11,Q11),5)=0,OFFSET(装备属性!$M$1083,1+INT(COUNTA($Q$11:Q11)/5),0),Q11) -> 通用属性 | R12: =IF(MOD(COUNTIF($Q$11:Q11,Q11),5)=0,10000*SUBSTITUTE(SUBSTITUTE(OFFSET(装备属性!$F$1083,1+INT(COUNTA($Q$11:Q11)/5),0),"[",""),"]","")+_xlfn.XLOOKUP(C12,$M$3:$M$7,$N$3:$N$7)*100,R11) -> 10400
A13: =IFERROR(R13+IF(Q13="通用属性",1,IF(Q13="玩法类",2,IF(Q13="稀有词条",3,0))),"") -> 10401 | B13: =IFERROR(R13+COUNTIFS($R$11:$R13,R13),"") -> 10403 | C13: =IF(MOD(COUNTIF($Q$11:Q12,Q12),5)=0,OFFSET(装备属性!$D$1083,1+INT(COUNTA($Q$11:Q12)/5),0),C12) -> 紫 | D13: 2000 | F13: =IFERROR(R13+INT((B13-R13-1)/5),"") -> 10400 | G13: =IF(AND(LEFT("[{"&M13&","&CEILING(N13*10000+(O13-N13)/4*(COUNTIF($F$11:F13,F13)-1)*10000,10)&"}]",7)="[{equip",MID("[{"&M13&","&CEILING(N13*10000+(O13-N13)/4*(COUNTIF($F$11:F13,F13)-1)*10000,10)&"}]",8,1)<>"_"),"[{"&M13&","&1&"}]","[{"&M13&","&CEILING(N13*10000+(O13-N13)/4*(COUNTIF($F$11:F13,F13)-1)*10000,10)&"}]") -> [{global_dmg_rate,360}] | H13: 不放回 | J13: =IF(MOD(COUNTIF($Q$11:Q12,Q12),5)=0,OFFSET(装备属性!$P$1083,1+INT(COUNTA($Q$11:Q12)/5),0),J12) -> 1 | K13: =IF(RIGHT(G13,13)="rune_slot,1}]",_xlfn.XLOOKUP(LEFT(SUBSTITUTE(G13,"[{",""),FIND(",",SUBSTITUTE(G13,"[{",""))-1),Sheet2!B:B,Sheet2!C:C)&"+"&1,_xlfn.XLOOKUP(LEFT(SUBSTITUTE(G13,"[{",""),FIND(",",SUBSTITUTE(G13,"[{",""))-1),Sheet2!B:B,Sheet2!C:C)&"+"&SUBSTITUTE(RIGHT(G13,LEN(G13)-FIND(",",G13)),"}]","")/100&"%") -> 伤害加成+3.6% | L13: =IF(MOD(COUNTIF($Q$11:Q12,Q12),5)=0,OFFSET(装备属性!$G$1083,1+INT(COUNTA($Q$11:Q12)/5),0),L12) -> 全职小队Ⅰ | M13: =IF(MOD(COUNTIF($Q$11:Q12,Q12),5)=0,OFFSET(装备属性!$H$1083,1+INT(COUNTA($Q$11:Q12)/5),0),M12) -> global_dmg_rate | N13: =IF(MOD(COUNTIF($Q$11:Q12,Q12),5)=0,OFFSET(装备属性!$K$1083,1+INT(COUNTA($Q$11:Q12)/5),0),N12) -> 0.03 | O13: =IF(MOD(COUNTIF($Q$11:Q12,Q12),5)=0,OFFSET(装备属性!$L$1083,1+INT(COUNTA($Q$11:Q12)/5),0),O12) -> 0.042 | Q13: =IF(MOD(COUNTIF($Q$11:Q12,Q12),5)=0,OFFSET(装备属性!$M$1083,1+INT(COUNTA($Q$11:Q12)/5),0),Q12) -> 通用属性 | R13: =IF(MOD(COUNTIF($Q$11:Q12,Q12),5)=0,10000*SUBSTITUTE(SUBSTITUTE(OFFSET(装备属性!$F$1083,1+INT(COUNTA($Q$11:Q12)/5),0),"[",""),"]","")+_xlfn.XLOOKUP(C13,$M$3:$M$7,$N$3:$N$7)*100,R12) -> 10400
A14: =IFERROR(R14+IF(Q14="通用属性",1,IF(Q14="玩法类",2,IF(Q14="稀有词条",3,0))),"") -> 10401 | B14: =IFERROR(R14+COUNTIFS($R$11:$R14,R14),"") -> 10404 | C14: =IF(MOD(COUNTIF($Q$11:Q13,Q13),5)=0,OFFSET(装备属性!$D$1083,1+INT(COUNTA($Q$11:Q13)/5),0),C13) -> 紫 | D14: 1500 | F14: =IFERROR(R14+INT((B14-R14-1)/5),"") -> 10400 | G14: =IF(AND(LEFT("[{"&M14&","&CEILING(N14*10000+(O14-N14)/4*(COUNTIF($F$11:F14,F14)-1)*10000,10)&"}]",7)="[{equip",MID("[{"&M14&","&CEILING(N14*10000+(O14-N14)/4*(COUNTIF($F$11:F14,F14)-1)*10000,10)&"}]",8,1)<>"_"),"[{"&M14&","&1&"}]","[{"&M14&","&CEILING(N14*10000+(O14-N14)/4*(COUNTIF($F$11:F14,F14)-1)*10000,10)&"}]") -> [{global_dmg_rate,390}] | H14: 不放回 | J14: =IF(MOD(COUNTIF($Q$11:Q13,Q13),5)=0,OFFSET(装备属性!$P$1083,1+INT(COUNTA($Q$11:Q13)/5),0),J13) -> 1 | K14: =IF(RIGHT(G14,13)="rune_slot,1}]",_xlfn.XLOOKUP(LEFT(SUBSTITUTE(G14,"[{",""),FIND(",",SUBSTITUTE(G14,"[{",""))-1),Sheet2!B:B,Sheet2!C:C)&"+"&1,_xlfn.XLOOKUP(LEFT(SUBSTITUTE(G14,"[{",""),FIND(",",SUBSTITUTE(G14,"[{",""))-1),Sheet2!B:B,Sheet2!C:C)&"+"&SUBSTITUTE(RIGHT(G14,LEN(G14)-FIND(",",G14)),"}]","")/100&"%") -> 伤害加成+3.9% | L14: =IF(MOD(COUNTIF($Q$11:Q13,Q13),5)=0,OFFSET(装备属性!$G$1083,1+INT(COUNTA($Q$11:Q13)/5),0),L13) -> 全职小队Ⅰ | M14: =IF(MOD(COUNTIF($Q$11:Q13,Q13),5)=0,OFFSET(装备属性!$H$1083,1+INT(COUNTA($Q$11:Q13)/5),0),M13) -> global_dmg_rate | N14: =IF(MOD(COUNTIF($Q$11:Q13,Q13),5)=0,OFFSET(装备属性!$K$1083,1+INT(COUNTA($Q$11:Q13)/5),0),N13) -> 0.03 | O14: =IF(MOD(COUNTIF($Q$11:Q13,Q13),5)=0,OFFSET(装备属性!$L$1083,1+INT(COUNTA($Q$11:Q13)/5),0),O13) -> 0.042 | Q14: =IF(MOD(COUNTIF($Q$11:Q13,Q13),5)=0,OFFSET(装备属性!$M$1083,1+INT(COUNTA($Q$11:Q13)/5),0),Q13) -> 通用属性 | R14: =IF(MOD(COUNTIF($Q$11:Q13,Q13),5)=0,10000*SUBSTITUTE(SUBSTITUTE(OFFSET(装备属性!$F$1083,1+INT(COUNTA($Q$11:Q13)/5),0),"[",""),"]","")+_xlfn.XLOOKUP(C14,$M$3:$M$7,$N$3:$N$7)*100,R13) -> 10400
A15: =IFERROR(R15+IF(Q15="通用属性",1,IF(Q15="玩法类",2,IF(Q15="稀有词条",3,0))),"") -> 10401 | B15: =IFERROR(R15+COUNTIFS($R$11:$R15,R15),"") -> 10405 | C15: =IF(MOD(COUNTIF($Q$11:Q14,Q14),5)=0,OFFSET(装备属性!$D$1083,1+INT(COUNTA($Q$11:Q14)/5),0),C14) -> 紫 | D15: 1000 | F15: =IFERROR(R15+INT((B15-R15-1)/5),"") -> 10400 | G15: =IF(AND(LEFT("[{"&M15&","&CEILING(N15*10000+(O15-N15)/4*(COUNTIF($F$11:F15,F15)-1)*10000,10)&"}]",7)="[{equip",MID("[{"&M15&","&CEILING(N15*10000+(O15-N15)/4*(COUNTIF($F$11:F15,F15)-1)*10000,10)&"}]",8,1)<>"_"),"[{"&M15&","&1&"}]","[{"&M15&","&CEILING(N15*10000+(O15-N15)/4*(COUNTIF($F$11:F15,F15)-1)*10000,10)&"}]") -> [{global_dmg_rate,420}] | H15: 不放回 | J15: =IF(MOD(COUNTIF($Q$11:Q14,Q14),5)=0,OFFSET(装备属性!$P$1083,1+INT(COUNTA($Q$11:Q14)/5),0),J14) -> 1 | K15: =IF(RIGHT(G15,13)="rune_slot,1}]",_xlfn.XLOOKUP(LEFT(SUBSTITUTE(G15,"[{",""),FIND(",",SUBSTITUTE(G15,"[{",""))-1),Sheet2!B:B,Sheet2!C:C)&"+"&1,_xlfn.XLOOKUP(LEFT(SUBSTITUTE(G15,"[{",""),FIND(",",SUBSTITUTE(G15,"[{",""))-1),Sheet2!B:B,Sheet2!C:C)&"+"&SUBSTITUTE(RIGHT(G15,LEN(G15)-FIND(",",G15)),"}]","")/100&"%") -> 伤害加成+4.2% | L15: =IF(MOD(COUNTIF($Q$11:Q14,Q14),5)=0,OFFSET(装备属性!$G$1083,1+INT(COUNTA($Q$11:Q14)/5),0),L14) -> 全职小队Ⅰ | M15: =IF(MOD(COUNTIF($Q$11:Q14,Q14),5)=0,OFFSET(装备属性!$H$1083,1+INT(COUNTA($Q$11:Q14)/5),0),M14) -> global_dmg_rate | N15: =IF(MOD(COUNTIF($Q$11:Q14,Q14),5)=0,OFFSET(装备属性!$K$1083,1+INT(COUNTA($Q$11:Q14)/5),0),N14) -> 0.03 | O15: =IF(MOD(COUNTIF($Q$11:Q14,Q14),5)=0,OFFSET(装备属性!$L$1083,1+INT(COUNTA($Q$11:Q14)/5),0),O14) -> 0.042 | Q15: =IF(MOD(COUNTIF($Q$11:Q14,Q14),5)=0,OFFSET(装备属性!$M$1083,1+INT(COUNTA($Q$11:Q14)/5),0),Q14) -> 通用属性 | R15: =IF(MOD(COUNTIF($Q$11:Q14,Q14),5)=0,10000*SUBSTITUTE(SUBSTITUTE(OFFSET(装备属性!$F$1083,1+INT(COUNTA($Q$11:Q14)/5),0),"[",""),"]","")+_xlfn.XLOOKUP(C15,$M$3:$M$7,$N$3:$N$7)*100,R14) -> 10400
A16: =IFERROR(R16+IF(Q16="通用属性",1,IF(Q16="玩法类",2,IF(Q16="稀有词条",3,0))),"") -> 10401 | B16: =IFERROR(R16+COUNTIFS($R$11:$R16,R16),"") -> 10406 | C16: =IF(MOD(COUNTIF($Q$11:Q15,Q15),5)=0,OFFSET(装备属性!$D$1083,1+INT(COUNTA($Q$11:Q15)/5),0),C15) -> 紫 | D16: =D11 -> 3000 | F16: =IFERROR(R16+INT((B16-R16-1)/5),"") -> 10401 | G16: =IF(AND(LEFT("[{"&M16&","&CEILING(N16*10000+(O16-N16)/4*(COUNTIF($F$11:F16,F16)-1)*10000,10)&"}]",7)="[{equip",MID("[{"&M16&","&CEILING(N16*10000+(O16-N16)/4*(COUNTIF($F$11:F16,F16)-1)*10000,10)&"}]",8,1)<>"_"),"[{"&M16&","&1&"}]","[{"&M16&","&CEILING(N16*10000+(O16-N16)/4*(COUNTIF($F$11:F16,F16)-1)*10000,10)&"}]") -> [{dmg_red_rate,100}] | H16: 不放回 | J16: =IF(MOD(COUNTIF($Q$11:Q15,Q15),5)=0,OFFSET(装备属性!$P$1083,1+INT(COUNTA($Q$11:Q15)/5),0),J15) -> 6 | K16: =IF(RIGHT(G16,13)="rune_slot,1}]",_xlfn.XLOOKUP(LEFT(SUBSTITUTE(G16,"[{",""),FIND(",",SUBSTITUTE(G16,"[{",""))-1),Sheet2!B:B,Sheet2!C:C)&"+"&1,_xlfn.XLOOKUP(LEFT(SUBSTITUTE(G16,"[{",""),FIND(",",SUBSTITUTE(G16,"[{",""))-1),Sheet2!B:B,Sheet2!C:C)&"+"&SUBSTITUTE(RIGHT(G16,LEN(G16)-FIND(",",G16)),"}]","")/100&"%") -> 伤害减免+1% | L16: =IF(MOD(COUNTIF($Q$11:Q15,Q15),5)=0,OFFSET(装备属性!$G$1083,1+INT(COUNTA($Q$11:Q15)/5),0),L15) -> 全员抗揍Ⅰ | M16: =IF(MOD(COUNTIF($Q$11:Q15,Q15),5)=0,OFFSET(装备属性!$H$1083,1+INT(COUNTA($Q$11:Q15)/5),0),M15) -> dmg_red_rate | N16: =IF(MOD(COUNTIF($Q$11:Q15,Q15),5)=0,OFFSET(装备属性!$K$1083,1+INT(COUNTA($Q$11:Q15)/5),0),N15) -> 0.01 | O16: =IF(MOD(COUNTIF($Q$11:Q15,Q15),5)=0,OFFSET(装备属性!$L$1083,1+INT(COUNTA($Q$11:Q15)/5),0),O15) -> 0.014 | Q16: =IF(MOD(COUNTIF($Q$11:Q15,Q15),5)=0,OFFSET(装备属性!$M$1083,1+INT(COUNTA($Q$11:Q15)/5),0),Q15) -> 通用属性 | R16: =IF(MOD(COUNTIF($Q$11:Q15,Q15),5)=0,10000*SUBSTITUTE(SUBSTITUTE(OFFSET(装备属性!$F$1083,1+INT(COUNTA($Q$11:Q15)/5),0),"[",""),"]","")+_xlfn.XLOOKUP(C16,$M$3:$M$7,$N$3:$N$7)*100,R15) -> 10400
A17: =IFERROR(R17+IF(Q17="通用属性",1,IF(Q17="玩法类",2,IF(Q17="稀有词条",3,0))),"") -> 10401 | B17: =IFERROR(R17+COUNTIFS($R$11:$R17,R17),"") -> 10407 | C17: =IF(MOD(COUNTIF($Q$11:Q16,Q16),5)=0,OFFSET(装备属性!$D$1083,1+INT(COUNTA($Q$11:Q16)/5),0),C16) -> 紫 | D17: =D12 -> 2500 | F17: =IFERROR(R17+INT((B17-R17-1)/5),"") -> 10401 | G17: =IF(AND(LEFT("[{"&M17&","&CEILING(N17*10000+(O17-N17)/4*(COUNTIF($F$11:F17,F17)-1)*10000,10)&"}]",7)="[{equip",MID("[{"&M17&","&CEILING(N17*10000+(O17-N17)/4*(COUNTIF($F$11:F17,F17)-1)*10000,10)&"}]",8,1)<>"_"),"[{"&M17&","&1&"}]","[{"&M17&","&CEILING(N17*10000+(O17-N17)/4*(COUNTIF($F$11:F17,F17)-1)*10000,10)&"}]") -> [{dmg_red_rate,110}] | H17: 不放回 | J17: =IF(MOD(COUNTIF($Q$11:Q16,Q16),5)=0,OFFSET(装备属性!$P$1083,1+INT(COUNTA($Q$11:Q16)/5),0),J16) -> 6 | K17: =IF(RIGHT(G17,13)="rune_slot,1}]",_xlfn.XLOOKUP(LEFT(SUBSTITUTE(G17,"[{",""),FIND(",",SUBSTITUTE(G17,"[{",""))-1),Sheet2!B:B,Sheet2!C:C)&"+"&1,_xlfn.XLOOKUP(LEFT(SUBSTITUTE(G17,"[{",""),FIND(",",SUBSTITUTE(G17,"[{",""))-1),Sheet2!B:B,Sheet2!C:C)&"+"&SUBSTITUTE(RIGHT(G17,LEN(G17)-FIND(",",G17)),"}]","")/100&"%") -> 伤害减免+1.1% | L17: =IF(MOD(COUNTIF($Q$11:Q16,Q16),5)=0,OFFSET(装备属性!$G$1083,1+INT(COUNTA($Q$11:Q16)/5),0),L16) -> 全员抗揍Ⅰ | M17: =IF(MOD(COUNTIF($Q$11:Q16,Q16),5)=0,OFFSET(装备属性!$H$1083,1+INT(COUNTA($Q$11:Q16)/5),0),M16) -> dmg_red_rate | N17: =IF(MOD(COUNTIF($Q$11:Q16,Q16),5)=0,OFFSET(装备属性!$K$1083,1+INT(COUNTA($Q$11:Q16)/5),0),N16) -> 0.01 | O17: =IF(MOD(COUNTIF($Q$11:Q16,Q16),5)=0,OFFSET(装备属性!$L$1083,1+INT(COUNTA($Q$11:Q16)/5),0),O16) -> 0.014 | Q17: =IF(MOD(COUNTIF($Q$11:Q16,Q16),5)=0,OFFSET(装备属性!$M$1083,1+INT(COUNTA($Q$11:Q16)/5),0),Q16) -> 通用属性 | R17: =IF(MOD(COUNTIF($Q$11:Q16,Q16),5)=0,10000*SUBSTITUTE(SUBSTITUTE(OFFSET(装备属性!$F$1083,1+INT(COUNTA($Q$11:Q16)/5),0),"[",""),"]","")+_xlfn.XLOOKUP(C17,$M$3:$M$7,$N$3:$N$7)*100,R16) -> 10400
A18: =IFERROR(R18+IF(Q18="通用属性",1,IF(Q18="玩法类",2,IF(Q18="稀有词条",3,0))),"") -> 10401 | B18: =IFERROR(R18+COUNTIFS($R$11:$R18,R18),"") -> 10408 | C18: =IF(MOD(COUNTIF($Q$11:Q17,Q17),5)=0,OFFSET(装备属性!$D$1083,1+INT(COUNTA($Q$11:Q17)/5),0),C17) -> 紫 | D18: =D13 -> 2000 | F18: =IFERROR(R18+INT((B18-R18-1)/5),"") -> 10401 | G18: =IF(AND(LEFT("[{"&M18&","&CEILING(N18*10000+(O18-N18)/4*(COUNTIF($F$11:F18,F18)-1)*10000,10)&"}]",7)="[{equip",MID("[{"&M18&","&CEILING(N18*10000+(O18-N18)/4*(COUNTIF($F$11:F18,F18)-1)*10000,10)&"}]",8,1)<>"_"),"[{"&M18&","&1&"}]","[{"&M18&","&CEILING(N18*10000+(O18-N18)/4*(COUNTIF($F$11:F18,F18)-1)*10000,10)&"}]") -> [{dmg_red_rate,120}] | H18: 不放回 | J18: =IF(MOD(COUNTIF($Q$11:Q17,Q17),5)=0,OFFSET(装备属性!$P$1083,1+INT(COUNTA($Q$11:Q17)/5),0),J17) -> 6 | K18: =IF(RIGHT(G18,13)="rune_slot,1}]",_xlfn.XLOOKUP(LEFT(SUBSTITUTE(G18,"[{",""),FIND(",",SUBSTITUTE(G18,"[{",""))-1),Sheet2!B:B,Sheet2!C:C)&"+"&1,_xlfn.XLOOKUP(LEFT(SUBSTITUTE(G18,"[{",""),FIND(",",SUBSTITUTE(G18,"[{",""))-1),Sheet2!B:B,Sheet2!C:C)&"+"&SUBSTITUTE(RIGHT(G18,LEN(G18)-FIND(",",G18)),"}]","")/100&"%") -> 伤害减免+1.2% | L18: =IF(MOD(COUNTIF($Q$11:Q17,Q17),5)=0,OFFSET(装备属性!$G$1083,1+INT(COUNTA($Q$11:Q17)/5),0),L17) -> 全员抗揍Ⅰ | M18: =IF(MOD(COUNTIF($Q$11:Q17,Q17),5)=0,OFFSET(装备属性!$H$1083,1+INT(COUNTA($Q$11:Q17)/5),0),M17) -> dmg_red_rate | N18: =IF(MOD(COUNTIF($Q$11:Q17,Q17),5)=0,OFFSET(装备属性!$K$1083,1+INT(COUNTA($Q$11:Q17)/5),0),N17) -> 0.01 | O18: =IF(MOD(COUNTIF($Q$11:Q17,Q17),5)=0,OFFSET(装备属性!$L$1083,1+INT(COUNTA($Q$11:Q17)/5),0),O17) -> 0.014 | Q18: =IF(MOD(COUNTIF($Q$11:Q17,Q17),5)=0,OFFSET(装备属性!$M$1083,1+INT(COUNTA($Q$11:Q17)/5),0),Q17) -> 通用属性 | R18: =IF(MOD(COUNTIF($Q$11:Q17,Q17),5)=0,10000*SUBSTITUTE(SUBSTITUTE(OFFSET(装备属性!$F$1083,1+INT(COUNTA($Q$11:Q17)/5),0),"[",""),"]","")+_xlfn.XLOOKUP(C18,$M$3:$M$7,$N$3:$N$7)*100,R17) -> 10400
A19: =IFERROR(R19+IF(Q19="通用属性",1,IF(Q19="玩法类",2,IF(Q19="稀有词条",3,0))),"") -> 10401 | B19: =IFERROR(R19+COUNTIFS($R$11:$R19,R19),"") -> 10409 | C19: =IF(MOD(COUNTIF($Q$11:Q18,Q18),5)=0,OFFSET(装备属性!$D$1083,1+INT(COUNTA($Q$11:Q18)/5),0),C18) -> 紫 | D19: =D14 -> 1500 | F19: =IFERROR(R19+INT((B19-R19-1)/5),"") -> 10401 | G19: =IF(AND(LEFT("[{"&M19&","&CEILING(N19*10000+(O19-N19)/4*(COUNTIF($F$11:F19,F19)-1)*10000,10)&"}]",7)="[{equip",MID("[{"&M19&","&CEILING(N19*10000+(O19-N19)/4*(COUNTIF($F$11:F19,F19)-1)*10000,10)&"}]",8,1)<>"_"),"[{"&M19&","&1&"}]","[{"&M19&","&CEILING(N19*10000+(O19-N19)/4*(COUNTIF($F$11:F19,F19)-1)*10000,10)&"}]") -> [{dmg_red_rate,130}] | H19: 不放回 | J19: =IF(MOD(COUNTIF($Q$11:Q18,Q18),5)=0,OFFSET(装备属性!$P$1083,1+INT(COUNTA($Q$11:Q18)/5),0),J18) -> 6 | K19: =IF(RIGHT(G19,13)="rune_slot,1}]",_xlfn.XLOOKUP(LEFT(SUBSTITUTE(G19,"[{",""),FIND(",",SUBSTITUTE(G19,"[{",""))-1),Sheet2!B:B,Sheet2!C:C)&"+"&1,_xlfn.XLOOKUP(LEFT(SUBSTITUTE(G19,"[{",""),FIND(",",SUBSTITUTE(G19,"[{",""))-1),Sheet2!B:B,Sheet2!C:C)&"+"&SUBSTITUTE(RIGHT(G19,LEN(G19)-FIND(",",G19)),"}]","")/100&"%") -> 伤害减免+1.3% | L19: =IF(MOD(COUNTIF($Q$11:Q18,Q18),5)=0,OFFSET(装备属性!$G$1083,1+INT(COUNTA($Q$11:Q18)/5),0),L18) -> 全员抗揍Ⅰ | M19: =IF(MOD(COUNTIF($Q$11:Q18,Q18),5)=0,OFFSET(装备属性!$H$1083,1+INT(COUNTA($Q$11:Q18)/5),0),M18) -> dmg_red_rate | N19: =IF(MOD(COUNTIF($Q$11:Q18,Q18),5)=0,OFFSET(装备属性!$K$1083,1+INT(COUNTA($Q$11:Q18)/5),0),N18) -> 0.01 | O19: =IF(MOD(COUNTIF($Q$11:Q18,Q18),5)=0,OFFSET(装备属性!$L$1083,1+INT(COUNTA($Q$11:Q18)/5),0),O18) -> 0.014 | Q19: =IF(MOD(COUNTIF($Q$11:Q18,Q18),5)=0,OFFSET(装备属性!$M$1083,1+INT(COUNTA($Q$11:Q18)/5),0),Q18) -> 通用属性 | R19: =IF(MOD(COUNTIF($Q$11:Q18,Q18),5)=0,10000*SUBSTITUTE(SUBSTITUTE(OFFSET(装备属性!$F$1083,1+INT(COUNTA($Q$11:Q18)/5),0),"[",""),"]","")+_xlfn.XLOOKUP(C19,$M$3:$M$7,$N$3:$N$7)*100,R18) -> 10400
A20: =IFERROR(R20+IF(Q20="通用属性",1,IF(Q20="玩法类",2,IF(Q20="稀有词条",3,0))),"") -> 10401 | B20: =IFERROR(R20+COUNTIFS($R$11:$R20,R20),"") -> 10410 | C20: =IF(MOD(COUNTIF($Q$11:Q19,Q19),5)=0,OFFSET(装备属性!$D$1083,1+INT(COUNTA($Q$11:Q19)/5),0),C19) -> 紫 | D20: =D15 -> 1000 | F20: =IFERROR(R20+INT((B20-R20-1)/5),"") -> 10401 | G20: =IF(AND(LEFT("[{"&M20&","&CEILING(N20*10000+(O20-N20)/4*(COUNTIF($F$11:F20,F20)-1)*10000,10)&"}]",7)="[{equip",MID("[{"&M20&","&CEILING(N20*10000+(O20-N20)/4*(COUNTIF($F$11:F20,F20)-1)*10000,10)&"}]",8,1)<>"_"),"[{"&M20&","&1&"}]","[{"&M20&","&CEILING(N20*10000+(O20-N20)/4*(COUNTIF($F$11:F20,F20)-1)*10000,10)&"}]") -> [{dmg_red_rate,140}] | H20: 不放回 | J20: =IF(MOD(COUNTIF($Q$11:Q19,Q19),5)=0,OFFSET(装备属性!$P$1083,1+INT(COUNTA($Q$11:Q19)/5),0),J19) -> 6 | K20: =IF(RIGHT(G20,13)="rune_slot,1}]",_xlfn.XLOOKUP(LEFT(SUBSTITUTE(G20,"[{",""),FIND(",",SUBSTITUTE(G20,"[{",""))-1),Sheet2!B:B,Sheet2!C:C)&"+"&1,_xlfn.XLOOKUP(LEFT(SUBSTITUTE(G20,"[{",""),FIND(",",SUBSTITUTE(G20,"[{",""))-1),Sheet2!B:B,Sheet2!C:C)&"+"&SUBSTITUTE(RIGHT(G20,LEN(G20)-FIND(",",G20)),"}]","")/100&"%") -> 伤害减免+1.4% | L20: =IF(MOD(COUNTIF($Q$11:Q19,Q19),5)=0,OFFSET(装备属性!$G$1083,1+INT(COUNTA($Q$11:Q19)/5),0),L19) -> 全员抗揍Ⅰ | M20: =IF(MOD(COUNTIF($Q$11:Q19,Q19),5)=0,OFFSET(装备属性!$H$1083,1+INT(COUNTA($Q$11:Q19)/5),0),M19) -> dmg_red_rate | N20: =IF(MOD(COUNTIF($Q$11:Q19,Q19),5)=0,OFFSET(装备属性!$K$1083,1+INT(COUNTA($Q$11:Q19)/5),0),N19) -> 0.01 | O20: =IF(MOD(COUNTIF($Q$11:Q19,Q19),5)=0,OFFSET(装备属性!$L$1083,1+INT(COUNTA($Q$11:Q19)/5),0),O19) -> 0.014 | Q20: =IF(MOD(COUNTIF($Q$11:Q19,Q19),5)=0,OFFSET(装备属性!$M$1083,1+INT(COUNTA($Q$11:Q19)/5),0),Q19) -> 通用属性 | R20: =IF(MOD(COUNTIF($Q$11:Q19,Q19),5)=0,10000*SUBSTITUTE(SUBSTITUTE(OFFSET(装备属性!$F$1083,1+INT(COUNTA($Q$11:Q19)/5),0),"[",""),"]","")+_xlfn.XLOOKUP(C20,$M$3:$M$7,$N$3:$N$7)*100,R19) -> 10400
A21: =IFERROR(R21+IF(Q21="通用属性",1,IF(Q21="玩法类",2,IF(Q21="稀有词条",3,0))),"") -> 10401 | B21: =IFERROR(R21+COUNTIFS($R$11:$R21,R21),"") -> 10411 | C21: =IF(MOD(COUNTIF($Q$11:Q20,Q20),5)=0,OFFSET(装备属性!$D$1083,1+INT(COUNTA($Q$11:Q20)/5),0),C20) -> 紫 | D21: =D16 -> 3000 | F21: =IFERROR(R21+INT((B21-R21-1)/5),"") -> 10402 | G21: =IF(AND(LEFT("[{"&M21&","&CEILING(N21*10000+(O21-N21)/4*(COUNTIF($F$11:F21,F21)-1)*10000,10)&"}]",7)="[{equip",MID("[{"&M21&","&CEILING(N21*10000+(O21-N21)/4*(COUNTIF($F$11:F21,F21)-1)*10000,10)&"}]",8,1)<>"_"),"[{"&M21&","&1&"}]","[{"&M21&","&CEILING(N21*10000+(O21-N21)/4*(COUNTIF($F$11:F21,F21)-1)*10000,10)&"}]") -> [{all_class_dmg,300}] | H21: 不放回 | J21: =IF(MOD(COUNTIF($Q$11:Q20,Q20),5)=0,OFFSET(装备属性!$P$1083,1+INT(COUNTA($Q$11:Q20)/5),0),J20) -> 2 | K21: =IF(RIGHT(G21,13)="rune_slot,1}]",_xlfn.XLOOKUP(LEFT(SUBSTITUTE(G21,"[{",""),FIND(",",SUBSTITUTE(G21,"[{",""))-1),Sheet2!B:B,Sheet2!C:C)&"+"&1,_xlfn.XLOOKUP(LEFT(SUBSTITUTE(G21,"[{",""),FIND(",",SUBSTITUTE(G21,"[{",""))-1),Sheet2!B:B,Sheet2!C:C)&"+"&SUBSTITUTE(RIGHT(G21,LEN(G21)-FIND(",",G21)),"}]","")/100&"%") -> 上阵五个不同职业增伤+3% | L21: =IF(MOD(COUNTIF($Q$11:Q20,Q20),5)=0,OFFSET(装备属性!$G$1083,1+INT(COUNTA($Q$11:Q20)/5),0),L20) -> 全员出力Ⅰ | M21: =IF(MOD(COUNTIF($Q$11:Q20,Q20),5)=0,OFFSET(装备属性!$H$1083,1+INT(COUNTA($Q$11:Q20)/5),0),M20) -> all_class_dmg | N21: =IF(MOD(COUNTIF($Q$11:Q20,Q20),5)=0,OFFSET(装备属性!$K$1083,1+INT(COUNTA($Q$11:Q20)/5),0),N20) -> 0.03 | O21: =IF(MOD(COUNTIF($Q$11:Q20,Q20),5)=0,OFFSET(装备属性!$L$1083,1+INT(COUNTA($Q$11:Q20)/5),0),O20) -> 0.042 | Q21: =IF(MOD(COUNTIF($Q$11:Q20,Q20),5)=0,OFFSET(装备属性!$M$1083,1+INT(COUNTA($Q$11:Q20)/5),0),Q20) -> 通用属性 | R21: =IF(MOD(COUNTIF($Q$11:Q20,Q20),5)=0,10000*SUBSTITUTE(SUBSTITUTE(OFFSET(装备属性!$F$1083,1+INT(COUNTA($Q$11:Q20)/5),0),"[",""),"]","")+_xlfn.XLOOKUP(C21,$M$3:$M$7,$N$3:$N$7)*100,R20) -> 10400
