Workbook

Sheet 说明
A1: 梦灵养成
A3: 说明
C5: 梦灵升级
D6: 梦灵属性=梦灵初始属性×（1＋（梦灵等级－1）×等级系数）
D7: 梦灵升级消耗【能量特饮】＋【金币】
D8: 梦灵升级本质上是上阵编队位置的升级，替换梦灵，等级继承
D9: 梦灵升级不能超过上阵编队最低等级位置10级
C11: 梦灵升星
D12: 梦灵升星属性＝梦灵等级属性×（1+品质系数）＋梦灵初始属性×升星系数×（品质id-1）
D13: 梦灵升星消耗【本体碎片】＋【金币】
D14: 梦灵升星到一定阶段后，需要【进阶石】
C16: 关联配置
D18: 配置 | E18: 字段 | F18: 值 | G18: 说明
D19: D_单位_unit_data
D20: D_道具_item_data | G20: *涉及梦灵道具与梦灵初始品质
G22: *预留最后一行
A24: 本页结束

Sheet 养成规划
A1: 养成属性
C3: 属性规划
D5: 途径 | E5: 生命百分比 | F5: 攻击百分比 | G5: 暴击伤害
D6: 梦灵 | E6: 4.2 | F6: 4.2 | G6: 9 | H6: *引用属性规划
D8: 养成分项
D9: 梦灵升级 | E9: 4.2 | F9: 420 | L9: *引用属性规划
D10: 梦灵图鉴 | G10: 9 | L10: *特殊属性
A23: 本页结束

Sheet 梦灵属性
A1: 设计思路
C3: 属性规划
D5: 途径 | E5: 生命百分比 | F5: 攻击百分比
D6: 养成1 | E6: 4.2 | F6: 4.2
C8: 养成规划
D10: 满级参数
D11: 养成周期/天 | E11: 180 | F11: *引用商业化框架
D12: 养成成本/钻 | E12: 240000 | F12: *引用商业化框架
D13: 每日碎片产出 | E13: =40*46+18*24 -> 2272
D16: 内容 | E16: 价值
D17: 蓝色梦灵碎片 | E17: 600
D18: 紫色梦灵碎片 | E18: 1200
D19: 橙色梦灵碎片 | E19: 2400
D20: 红色梦灵碎片 | E20: 4800
C23: 梦灵设定
E24: 梦灵职业
D25: 梦灵品质 | E25: 战士 | F25: 法师 | G25: 射手 | H25: 辅助 | I25: 控制 | J25: 毒系 | K25: 总和
D26: 蓝 | F26: 1 | G26: 1 | H26: 1 | K26: =SUM(E26:J26) -> 3
D27: 紫 | E27: 2 | F27: 1 | G27: 1 | H27: 1 | J27: 1 | K27: =SUM(E27:J27) -> 6
D28: 橙 | E28: 1 | F28: 1 | G28: 1 | H28: 1 | I28: 1 | J28: 1 | K28: =SUM(E28:J28) -> 6
D29: 红 | E29: 1 | F29: 1 | G29: 1 | H29: 1 | I29: 1 | J29: 1 | K29: =SUM(E29:J29) -> 6
A33: 梦灵养成数值和消耗
C35: 基础品质系数
D36: 梦灵属性=全局攻击力*（1+品质系数*梦灵等级）
D37: 品质 | E37: 品质系数 | F37: 品质 | G37: 攻击 | H37: 生命 | I37: 技能系数 | J37: 进阶消耗 | K37: 预期养成周期 | L37: 每日产出 | M37: 单价 | N37: 总坑深
D38: 蓝 | E38: 0.04 | F38: 3 | I38: 0.7 | J38: =SUMIFS($J$56:$J$255,$D$56:$D$255,D38,$E$56:$E$255,"<"&E46)/10 -> 2134 | K38: 60 | L38: =梦灵本体产出!$J$41*梦灵本体产出!$E$69*$K38 -> 1643.6137 | M38: 60 | N38: =M38*L38 -> 98616.825 | P38: 1
D39: 紫 | E39: 0.05 | F39: 4 | G39: 60 | H39: 600 | I39: 0.8 | J39: =SUMIFS($J$56:$J$255,$D$56:$D$255,D39,$E$56:$E$255,"<"&E47)/10 -> 874 | K39: 60 | L39: =梦灵本体产出!$K$41*梦灵本体产出!$E$69*$K39 -> 975.18367 | M39: 120 | N39: =M39*L39 -> 117022.04 | P39: 1.2
D40: 橙 | E40: 0.06 | F40: 5 | G40: 120 | H40: 1200 | I40: 1.05 | J40: =SUMIFS($J$56:$J$255,$D$56:$D$255,D40,$E$56:$E$255,"<"&E48)/10 -> 244 | K40: 60 | L40: =梦灵本体产出!$L$41*梦灵本体产出!$E$69*$K40 -> 744.68571 | M40: 240 | N40: =M40*L40 -> 178724.57 | P40: =P38*1.2*1.2 -> 1.44
D41: 红 | E41: 0.1 | F41: 6 | G41: 180 | H41: 1800 | I41: 1.4 | J41: =SUMIFS($J$56:$J$255,$D$56:$D$255,D41,$E$56:$E$255,"<"&E49)/10 -> 184 | K41: 60 | L41: =梦灵本体产出!$M$41*梦灵本体产出!$E$69*$K41 -> 282.08013 | M41: 480 | N41: =M41*L41 -> 135398.46 | P41: =P38*1.2^3 -> 1.728
D42: 彩 | E42: 0.14 | F42: 7 | G42: 240 | H42: 2400 | I42: 1.6 | J42: =SUMIFS($J$56:$J$255,$D$56:$D$255,D42,$E$56:$E$255,"<"&E50)/10 -> 0 | K42: 60 | M42: 960 | N42: =M42*L42 -> 0 | P42: =P39*1.2^4 -> 2.48832
N43: {=SUMPRODUCT(N38:N41,K26:K29)} -> 2882720.9
D44: 升级碎片
D45: 品质 | E45: 期望养成等级 | F45: 进阶消耗
D46: 蓝 | E46: 50 | F46: =SUMIFS($H$56:$H$255,$D$56:$D$255,D46,$E$56:$E$255,"<"&E46) -> 54240
D47: 紫 | E47: 40 | F47: =SUMIFS($H$56:$H$255,$D$56:$D$255,D47,$E$56:$E$255,"<"&E47) -> 50760
D48: 橙 | E48: 30 | F48: =SUMIFS($H$56:$H$255,$D$56:$D$255,D48,$E$56:$E$255,"<"&E48) -> 36480
D49: 红 | E49: 30 | F49: =SUMIFS($H$56:$H$255,$D$56:$D$255,D49,$E$56:$E$255,"<"&E49) -> 45600
D50: 彩 | E50: 30 | F50: =SUMIFS($H$56:$H$255,$D$56:$D$255,D50,$E$56:$E$255,"<"&E50) -> 0
F51: {=SUMPRODUCT(F46:F49,K26:K29)} -> 959760
D53: 品质系数：梦灵每级所提供的属性 | H53: #控制活跃速率
...

Sheet 梦灵属性 (新版)
A1: 设计思路
C3: 属性规划
D5: 途径 | E5: 生命百分比 | F5: 攻击百分比
D6: 养成1 | E6: 4.2 | F6: 4.2
C8: 养成规划
D10: 满级参数
D11: 养成周期/天 | E11: 180 | F11: *引用商业化框架
D12: 养成成本/钻 | E12: 240000 | F12: *引用商业化框架
D13: 每日碎片产出 | E13: =40*46+18*24 -> 2272
D16: 内容 | E16: 价值
D17: 蓝色梦灵碎片 | E17: 600
D18: 紫色梦灵碎片 | E18: 1200
D19: 橙色梦灵碎片 | E19: 2400
D20: 红色梦灵碎片 | E20: 4800
C23: 梦灵设定
E24: 梦灵职业
D25: 梦灵品质 | E25: 战士 | F25: 法师 | G25: 射手 | H25: 辅助 | I25: 控制 | J25: 毒系 | K25: 总和
D26: 蓝 | F26: 1 | G26: 1 | H26: 1 | K26: =SUM(E26:J26) -> 3
D27: 紫 | E27: 2 | F27: 1 | G27: 1 | H27: 1 | J27: 1 | K27: =SUM(E27:J27) -> 6
D28: 橙 | E28: 1 | F28: 1 | G28: 1 | H28: 1 | I28: 1 | J28: 1 | K28: =SUM(E28:J28) -> 6
D29: 红 | E29: 1 | F29: 1 | G29: 1 | H29: 1 | I29: 1 | J29: 1 | K29: =SUM(E29:J29) -> 6
A33: 梦灵养成数值和消耗
C35: 基础品质系数
D36: 梦灵属性=全局攻击力*（1+品质系数*梦灵等级）
D37: 品质 | E37: 品质系数 | F37: 品质 | G37: 攻击 | H37: 生命 | I37: 技能系数 | J37: 进阶消耗 | K37: 预期养成周期 | L37: 每日产出 | M37: 单价 | N37: 总坑深
D38: 蓝 | E38: 0.04 | F38: 3 | I38: 0.7 | J38: =SUMIFS($J$56:$J$255,$D$56:$D$255,D38,$E$56:$E$255,"<"&E46)/10 -> 2134 | K38: 60 | L38: =梦灵本体产出!$J$41*梦灵本体产出!$E$69*$K38 -> 1643.6137 | M38: 60 | N38: =M38*L38 -> 98616.825 | P38: 1
D39: 紫 | E39: 0.05 | F39: 4 | G39: 60 | H39: 600 | I39: 0.8 | J39: =SUMIFS($J$56:$J$255,$D$56:$D$255,D39,$E$56:$E$255,"<"&E47)/10 -> 874 | K39: 60 | L39: =梦灵本体产出!$K$41*梦灵本体产出!$E$69*$K39 -> 975.18367 | M39: 120 | N39: =M39*L39 -> 117022.04 | P39: 1.2
D40: 橙 | E40: 0.06 | F40: 5 | G40: 120 | H40: 1200 | I40: 1.05 | J40: =SUMIFS($J$56:$J$255,$D$56:$D$255,D40,$E$56:$E$255,"<"&E48)/10 -> 244 | K40: 60 | L40: =梦灵本体产出!$L$41*梦灵本体产出!$E$69*$K40 -> 744.68571 | M40: 240 | N40: =M40*L40 -> 178724.57 | P40: =P38*1.2*1.2 -> 1.44
D41: 红 | E41: 0.1 | F41: 6 | G41: 180 | H41: 1800 | I41: 1.4 | J41: =SUMIFS($J$56:$J$255,$D$56:$D$255,D41,$E$56:$E$255,"<"&E49)/10 -> 184 | K41: 60 | L41: =梦灵本体产出!$M$41*梦灵本体产出!$E$69*$K41 -> 282.08013 | M41: 480 | N41: =M41*L41 -> 135398.46 | P41: =P38*1.2^3 -> 1.728
D42: 彩 | E42: 0.14 | F42: 7 | G42: 240 | H42: 2400 | I42: 1.6 | J42: =SUMIFS($J$56:$J$255,$D$56:$D$255,D42,$E$56:$E$255,"<"&E50)/10 -> 0 | K42: 60 | M42: 960 | N42: =M42*L42 -> 0 | P42: =P39*1.2^4 -> 2.48832
N43: {=SUMPRODUCT(N38:N41,K26:K29)} -> 2882720.9
D44: 升级碎片
D45: 品质 | E45: 期望养成等级 | F45: 进阶消耗
D46: 蓝 | E46: 50 | F46: =SUMIFS($H$56:$H$255,$D$56:$D$255,D46,$E$56:$E$255,"<"&E46) -> 54240
D47: 紫 | E47: 40 | F47: =SUMIFS($H$56:$H$255,$D$56:$D$255,D47,$E$56:$E$255,"<"&E47) -> 50760
D48: 橙 | E48: 30 | F48: =SUMIFS($H$56:$H$255,$D$56:$D$255,D48,$E$56:$E$255,"<"&E48) -> 36480
D49: 红 | E49: 30 | F49: =SUMIFS($H$56:$H$255,$D$56:$D$255,D49,$E$56:$E$255,"<"&E49) -> 45600
D50: 彩 | E50: 30 | F50: =SUMIFS($H$56:$H$255,$D$56:$D$255,D50,$E$56:$E$255,"<"&E50) -> 0
F51: {=SUMPRODUCT(F46:F49,K26:K29)} -> 959760
D53: 品质系数：梦灵每级所提供的属性 | H53: #控制活跃速率
...

Sheet 梦灵本体产出
A1: 设计思路 | M1: =13.5+10+2 -> 25.5 | N1: =13.5/M1 -> 0.52941176
M2: 420抽
C3: 梦灵抽卡 | G3: 12 | H3: 12 | I3: 2 | K3: 600抽 | L3: 9 | M3: 1橙C | N3: 6 | P3: =1200*3 -> 3600 | Q3: =2400*7 -> 16800 | R3: =#REF!-P3-Q3 -> #REF!
L4: =3*1.5 -> 4.5 | M4: 6核心抽=2 | P4: 3 | Q4: 7 | R4: 2 | AY4: {12,12,[51010002]},{14,14,[51010001]},{16,16,[51010003]},{17,17,[51010001]},{18,18,[51010001]}
D5: 角色释放（做抽奖数保底） | H5: 期望天数 | L5: =L4+L3 -> 13.5 | M5: 12 | N5: 2 | S5: 300 | X5: 1000 | AA5: 2000 | AG5: 4000 | AP5: 51010001 | AQ5: 51010002 | AR5: 51010003 | AS5: 51010004 | AT5: 51010005 | AU5: 51010006 | AV5: 51010007 | AW5: 51010008 | AX5: 51010009
D6: 招募阶段 | E6: 招募所需次数 | F6: 招募释放 | G6: 英雄品质 | H6: 非R | I6: 小R | J6: 中R | K6: 大R | L6: 预期关卡 | M6: 预期 | N6: id | S6: 首日招募次数 | T6: 效果 | X6: lv2次数 | Y6: 效果 | AA6: lv3次数 | AB6: 效果 | AD6: lv4次数 | AE6: 效果 | AG6: lv5次数 | AH6: 效果 | AL6: 前250抽保底设计 | AP6: 寒冰射手 | AQ6: 炽焰巫师 | AR6: 吟游诗人 | AS6: 摇滚巨石 | AT6: 泥巴少女 | AU6: 忍者鲨手 | AV6: 甜心护士 | AW6: 雷震子 | AX6: 关羽
A7: 1 | B7: 10 | C7: ="{"&N7&","&B7&"}" -> {1310100,10} | D7: 1 | E7: 0 | F7: 寒冰射手 | G7: 3 | H7: 1 | I7: =MAX($E7-$F$70,0)/$E$70 -> 0 | J7: =MAX($E7-$F$71,0)/$E$71 -> 0 | K7: =MAX($E7-$F$72,0)/$E$72 -> 0 | L7: 1 | N7: 1310100 | P7: ="["&_xlfn.TEXTJOIN(",",1,$N$7:N7)&"]" -> [1310100] | S7: 10 | T7: 顺序保底出【摇滚巨石】 | X7: 10~30 | Y7: 顺序保底橙卡A | AA7: 250~280 | AB7: 顺序保底橙卡E | AD7: 80~120 | AE7: 顺序保底红卡A | AG7: 30~60 | AH7: 顺序保底红卡D | AL7: 10 | AM7: 顺序保底出【摇滚巨石】 | AO7: {=SUM(AP7:AX7)-SUMPRODUCT(--(BJ7:BQ7>0))} -> 5 | AP7: 2 | AQ7: 1 | AR7: 1 | AS7: 1 | AY7: ="["&_xlfn.TEXTJOIN(",",1,BR7:BZ39)&"]" -> []
B8: 10 | C8: ="{"&N8&","&B8&"}" -> {1210400,10} | D8: 2 | E8: 0 | F8: 炽焰巫师 | G8: 3 | H8: 1 | I8: =MAX($E8-$F$70,0)/$E$70 -> 0 | J8: =MAX($E8-$F$71,0)/$E$71 -> 0 | K8: =MAX($E8-$F$72,0)/$E$72 -> 0 | L8: 1 | N8: 1210400 | P8: ="["&_xlfn.TEXTJOIN(",",1,$N$7:N8)&"]" -> [1310100,1210400] | S8: 20 | T8: 加上第1次十连，寒冰能升到5级 | X8: 60~80 | Y8: 顺序保底橙卡A | AA8: 540~560 | AB8: 顺序保底橙卡F | AD8: 910~950 | AE8: 顺序保底红卡B | AG8: 1100~1200 | AH8: 顺序保底红卡E | AK8: 4 | AL8: 20 | AM8: 加上第1次十连，寒冰能升到5级 | AO8: {=SUM(AP8:AX8)-SUMPRODUCT(--(BJ8:BQ8>0))} -> 5 | AP8: 3 | AQ8: 1 | AR8: 1
B9: 10 | C9: ="{"&N9&","&B9&"}" -> {1230100,10} | D9: 3 | E9: 0 | F9: 吟游诗人 | G9: 3 | H9: 1 | I9: =MAX($E9-$F$70,0)/$E$70 -> 0 | J9: =MAX($E9-$F$71,0)/$E$71 -> 0 | K9: =MAX($E9-$F$72,0)/$E$72 -> 0 | L9: 1 | N9: 1230100 | P9: ="["&_xlfn.TEXTJOIN(",",1,$N$7:N9)&"]" -> [1310100,1210400,1230100] | S9: 30 | T9: 加上前2次十连，诗人能升到5级 | X9: 110~130 | Y9: 顺序保底橙卡A | AD9: 1740~1780 | AE9: 顺序保底红卡C | AG9: 2200~2300 | AH9: 顺序保底红卡F | AL9: 30 | AM9: 加上前2次十连，诗人能升到5级 | AO9: {=SUM(AP9:AX9)-SUMPRODUCT(--(BJ9:BQ9>0))} -> 8 | AP9: 4 | AQ9: 1 | AR9: 2 | AS9: 1
B10: 5 | C10: ="{"&N10&","&B10&"}" -> {1420200,5} | D10: 4 | E10: 10 | F10: 摇滚巨石 | G10: 3 | H10: 1 | I10: =MAX($E10-$F$70,0)/$E$70 -> 0 | J10: =MAX($E10-$F$71,0)/$E$71 -> 0 | K10: =MAX($E10-$F$72,0)/$E$72 -> 0 | L10: 2 | N10: 1420200 | P10: ="["&_xlfn.TEXTJOIN(",",1,$N$7:N10)&"]" -> [1310100,1210400,1230100,1420200] | S10: 40 | T10: 顺序保底出【泥巴少女】 | X10: 160~180 | Y10: 顺序保底橙卡A | AL10: 40 | AM10: 顺序保底出【泥巴少女】 | AO10: {=SUM(AP10:AX10)-SUMPRODUCT(--(BJ10:BQ10>0))} -> 6 | AP10: 3 | AR10: 2 | AT10: 1
B11: 5 | C11: ="{"&N11&","&B11&"}" -> {1420200,5} | D11: 5 | E11: 10 | F11: 摇滚巨石 | G11: 4 | H11: 1 | I11: =MAX($E11-$F$70,0)/$E$70 -> 0 | J11: =MAX($E11-$F$71,0)/$E$71 -> 0 | K11: =MAX($E11-$F$72,0)/$E$72 -> 0 | N11: 1420200 | P11: ="["&_xlfn.TEXTJOIN(",",1,$N$7:N11)&"]" -> [1310100,1210400,1230100,1420200,1420200] | S11: 50 | T11: 炽焰巫师升到5级 | X11: 210~230 | Y11: 顺序保底橙卡A | AL11: 50 | AM11: 炽焰巫师升到5级 | AO11: {=SUM(AP11:AX11)-SUMPRODUCT(--(BJ11:BQ11>0))} -> 8 | AP11: 4 | AQ11: 1 | AR11: 3
B12: 5 | C12: ="{"&N12&","&B12&"}" -> {1320100,5} | D12: 6 | E12: 40 | F12: 果冻少女 | G12: 4 | H12: 1 | I12: =MAX($E12-$F$70,0)/$E$70 -> 0 | J12: =MAX($E12-$F$71,0)/$E$71 -> 0 | K12: =MAX($E12-$F$72,0)/$E$72 -> 0 | L12: 4 | N12: 1320100 | P12: ="["&_xlfn.TEXTJOIN(",",1,$N$7:N12)&"]" -> [1310100,1210400,1230100,1420200,1420200,1320100] | S12: 60 | T12: 寒冰射手升10级 | W12: =260/100 -> 2.6 | X12: 260~280 | Y12: 顺序保底橙卡B | AK12: 15 | AL12: 60 | AM12: 寒冰射手升10级 | AO12: {=SUM(AP12:AX12)-SUMPRODUCT(--(BJ12:BQ12>0))} -> 7 | AP12: 3 | AQ12: 2 | AR12: 2
B13: 5 | C13: ="{"&N13&","&B13&"}" -> {1310300,5} | D13: 7 | E13: 100 | F13: 雷震子 | G13: 4 | H13: 1 | I13: =MAX($E13-$F$70,0)/$E$70 -> 0 | J13: =MAX($E13-$F$71,0)/$E$71 -> 0 | K13: =MAX($E13-$F$72,0)/$E$72 -> 0 | L13: 8 | N13: 1310300 | P13: ="["&_xlfn.TEXTJOIN(",",1,$N$7:N13)&"]" -> [1310100,1210400,1230100,1420200,1420200,1320100,1310300] | S13: 70 | T13: 顺序保底出【忍者鲨手】 | X13: 310~330 | Y13: 顺序保底橙卡B | AL13: 70 | AO13: {=SUM(AP13:AX13)-SUMPRODUCT(--(BJ13:BQ13>0))} -> 7 | AQ13: 3 | AR13: 3 | AS13: 1
B14: 5 | C14: ="{"&N14&","&B14&"}" -> {1210600,5} | D14: 8 | E14: 190 | F14: 忍者鲨手 | G14: 4 | H14: 2 | I14: =MAX($E14-$F$70,0)/$E$70 -> 0 | J14: =MAX($E14-$F$71,0)/$E$71 -> 0 | K14: =MAX($E14-$F$72,0)/$E$72 -> 0 | L14: 11 | N14: 1210600 | P14: ="["&_xlfn.TEXTJOIN(",",1,$N$7:N14)&"]" -> [1310100,1210400,1230100,1420200,1420200,1320100,1310300,1210600] | S14: 80 | X14: 360~380 | Y14: 顺序保底橙卡B | AL14: 80 | AO14: {=SUM(AP14:AX14)-SUMPRODUCT(--(BJ14:BQ14>0))} -> 5 | AQ14: 2 | AR14: 2 | AT14: 1
B15: 5 | C15: ="{"&N15&","&B15&"}" -> {1230400,5} | D15: 9 | E15: 250 | F15: 甜心护士 | G15: 4 | H15: 2 | I15: =MAX($E15-$F$70,0)/$E$70 -> 0 | J15: =MAX($E15-$F$71,0)/$E$71 -> 0 | K15: =MAX($E15-$F$72,0)/$E$72 -> 0 | L15: 14 | N15: 1230400 | P15: ="["&_xlfn.TEXTJOIN(",",1,$N$7:N15)&"]" -> [1310100,1210400,1230100,1420200,1420200,1320100,1310300,1210600,1230400] | S15: 90 | T15: 诗人升10级 | X15: 410~430 | Y15: 顺序保底橙卡B | AK15: 15 | AL15: 90 | AM15: 诗人升10级 | AO15: {=SUM(AP15:AX15)-SUMPRODUCT(--(BJ15:BQ15>0))} -> 6 | AQ15: 3 | AR15: 3
D16: 10 | E16: 350 | F16: 路人甲 | G16: 5 | H16: =MAX($E16-$F$69*0.05)/$E$69 -> 3.0359116 | I16: =MAX($E16-$F$70*0.2,0)/$E$70 -> 1.5065886 | J16: =MAX($E16-$F$71*0.2,0)/$E$71 -> 0.94360385 | K16: =MAX($E16-$F$72*0.2,0)/$E$72 -> 0.7136541 | L16: 16 | N16: 1210700 | P16: ="["&_xlfn.TEXTJOIN(",",1,$N$7:N16)&"]" -> [1310100,1210400,1230100,1420200,1420200,1320100,1310300,1210600,1230400,1210700] | S16: 100 | T16: 顺序保底出【甜心护士】 | X16: 460~480 | Y16: 顺序保底橙卡B | AL16: 100 | AM16: 顺序保底出【忍者鲨手】 | AO16: {=SUM(AP16:AX16)-SUMPRODUCT(--(BJ16:BQ16>0))} -> 3 | AQ16: 2 | AU16: 1
D17: 11 | E17: 500 | F17: 东方宫主 | G17: 5 | H17: =MAX($E17-$F$69*0.3)/$E$69 -> 2.7458564 | I17: =MAX($E17-$F$70*0.6,0)/$E$70 -> 0.2920937 | J17: =MAX($E17-$F$71*0.6,0)/$E$71 -> 0.1829436 | K17: =MAX($E17-$F$72*0.6,0)/$E$72 -> 0.13836151 | L17: 20 | N17: 1130100 | P17: ="["&_xlfn.TEXTJOIN(",",1,$N$7:N17)&"]" -> [1310100,1210400,1230100,1420200,1420200,1320100,1310300,1210600,1230400,1210700,1130100] | Q17: 单橙 | S17: 110 | T17: 炽焰巫师升10级 | X17: 510~530 | Y17: 顺序保底橙卡C | AK17: 15 | AL17: 110 | AM17: 炽焰巫师升10级 | AO17: {=SUM(AP17:AX17)-SUMPRODUCT(--(BJ17:BQ17>0))} -> 5 | AQ17: 3 | AS17: 1 | AU17: 1
D18: 12 | F18: 镭射 | G18: 5 | N18: 1530100 | P18: ="["&_xlfn.TEXTJOIN(",",1,$N$7:N18)&"]" -> [1310100,1210400,1230100,1420200,1420200,1320100,1310300,1210600,1230400,1210700,1130100,1530100] | Q18: 双橙 | S18: 120 | X18: 560~580 | Y18: 顺序保底橙卡C | AL18: 120 | AO18: {=SUM(AP18:AX18)-SUMPRODUCT(--(BJ18:BQ18>0))} -> 1 | AT18: 1
D19: 13 | E19: 600 | F19: 亚瑟 | G19: 5 | H19: =MAX($E19-$F$69*0.3)/$E$69 -> 3.7127072 | I19: =MAX($E19-$F$70,0)/$E$70 -> 0 | J19: =MAX($E19-$F$71,0)/$E$71 -> 0 | K19: =MAX($E19-$F$72,0)/$E$72 -> 0 | L19: 39 | N19: 1210300 | P19: ="["&_xlfn.TEXTJOIN(",",1,$N$7:N19)&"]" -> [1310100,1210400,1230100,1420200,1420200,1320100,1310300,1210600,1230400,1210700,1130100,1530100,1210300] | Q19: 三橙 | S19: 130 | T19: 顺序保底出【雷震子】 | X19: 610~630 | Y19: 顺序保底橙卡C | AL19: 130 | AM19: 【摇滚巨石-5级】 | AO19: {=SUM(AP19:AX19)-SUMPRODUCT(--(BJ19:BQ19>0))} -> 1 | AS19: 1
D20: 14 | E20: 800 | F20: 唐小僧 | G20: 5 | H20: =MAX($E20-$F$69*0.5)/$E$69 -> 4.2541436 | I20: =MAX($E20-$F$70,0)/$E$70 -> 0.23060029 | J20: =MAX($E20-$F$71,0)/$E$71 -> 0.14442916 | K20: =MAX($E20-$F$72,0)/$E$72 -> 0.10923277 | L20: 45 | N20: 1140100 | P20: ="["&_xlfn.TEXTJOIN(",",1,$N$7:N20)&"]" -> [1310100,1210400,1230100,1420200,1420200,1320100,1310300,1210600,1230400,1210700,1130100,1530100,1210300,1140100] | Q20: 四橙 | S20: 140 | X20: 660~680 | Y20: 顺序保底橙卡C | AL20: 140 | AM20: 顺序保底出【甜心护士】 | AO20: {=SUM(AP20:AX20)-SUMPRODUCT(--(BJ20:BQ20>0))} -> 1 | AV20: 1
D21: 15 | E21: 1200 | F21: 蜘蛛女王 | G21: 5 | H21: =MAX($E21-$F$69*0.5)/$E$69 -> 8.121547 | I21: =MAX($E21-$F$70,0)/$E$70 -> 3.3052709 | J21: =MAX($E21-$F$71,0)/$E$71 -> 2.0701513 | K21: =MAX($E21-$F$72,0)/$E$72 -> 1.5656697 | L21: 51 | N21: 1430700 | P21: ="["&_xlfn.TEXTJOIN(",",1,$N$7:N21)&"]" -> [1310100,1210400,1230100,1420200,1420200,1320100,1310300,1210600,1230400,1210700,1130100,1530100,1210300,1140100,1430700] | Q21: 五橙 | S21: 150 | T21: 【摇滚巨石-5级】 | X21: 710~730 | Y21: 顺序保底橙卡C | AK21: 4 | AL21: 150 | AO21: {=SUM(AP21:AX21)-SUMPRODUCT(--(BJ21:BQ21>0))} -> 2 | AT21: 1 | AU21: 1
D22: 16 | E22: 1800 | F22: 神灯王子 | G22: 6 | H22: =MAX($E22-$F$69*1)/$E$69 -> 10.441989 | I22: =MAX($E22-$F$70,0)/$E$70 -> 7.9172767 | J22: =MAX($E22-$F$71,0)/$E$71 -> 4.9587345 | K22: =MAX($E22-$F$72,0)/$E$72 -> 3.7503251 | L22: 55 | N22: 1140200 | P22: ="["&_xlfn.TEXTJOIN(",",1,$N$7:N22)&"]" -> [1310100,1210400,1230100,1420200,1420200,1320100,1310300,1210600,1230400,1210700,1130100,1530100,1210300,1140100,1430700,1140200] | Q22: 六橙 | S22: 160 | X22: 760~780 | Y22: 顺序保底橙卡D | AL22: 160 | AM22: 【泥巴少女-5级】 | AO22: {=SUM(AP22:AX22)-SUMPRODUCT(--(BJ22:BQ22>0))} -> 1 | AT22: 1
D23: 17 | E23: 2400 | F23: 关羽 | G23: 6 | H23: =MAX($E23-$F$69*1)/$E$69 -> 16.243094 | I23: =MAX($E23-$F$70,0)/$E$70 -> 12.529283 | J23: =MAX($E23-$F$71,0)/$E$71 -> 7.8473177 | K23: =MAX($E23-$F$72,0)/$E$72 -> 5.9349805 | L23: 59 | N23: 1110100 | P23: ="["&_xlfn.TEXTJOIN(",",1,$N$7:N23)&"]" -> [1310100,1210400,1230100,1420200,1420200,1320100,1310300,1210600,1230400,1210700,1130100,1530100,1210300,1140100,1430700,1140200,1110100] | S23: 170 | X23: 810~830 | Y23: 顺序保底橙卡D | AL23: 170 | AO23: {=SUM(AP23:AX23)-SUMPRODUCT(--(BJ23:BQ23>0))} -> 1 | AV23: 1
D24: 18 | E24: 3400 | F24: 后羿 | G24: 6 | H24: =MAX($E24-$F$69*1)/$E$69 -> 25.911602 | I24: =MAX($E24-$F$70,0)/$E$70 -> 20.215959 | J24: =MAX($E24-$F$71,0)/$E$71 -> 12.661623 | K24: =MAX($E24-$F$72,0)/$E$72 -> 9.5760728 | L24: 74 | N24: 1530200 | P24: ="["&_xlfn.TEXTJOIN(",",1,$N$7:N24)&"]" -> [1310100,1210400,1230100,1420200,1420200,1320100,1310300,1210600,1230400,1210700,1130100,1530100,1210300,1140100,1430700,1140200,1110100,1530200] | Q24: 一红 | S24: 180 | T24: 累抽领取【关羽】 | AL24: 180 | AM24: 顺序保底出【雷震子】 | AO24: {=SUM(AP24:AX24)-SUMPRODUCT(--(BJ24:BQ24>0))} -> 1 | AW24: 1
D25: 19 | F25: 神算诸葛 | G25: 6 | L25: =L24+7 -> 81 | N25: 1420300 | P25: ="["&_xlfn.TEXTJOIN(",",1,$N$7:N25)&"]" -> [1310100,1210400,1230100,1420200,1420200,1320100,1310300,1210600,1230400,1210700,1130100,1530100,1210300,1140100,1430700,1140200,1110100,1530200,1420300] | Q25: 二红 | S25: 250 | T25: 最终：【关羽-4级】、【忍者鲨手-4级】、【泥巴少女-4级】、【甜心护士-4级】、【雷震子-5级】 | AH25: 4 | AK25: 3 | AL25: 190 | AO25: {=SUM(AP25:AX25)-SUMPRODUCT(--(BJ25:BQ25>0))} -> 1 | AU25: 1
D26: 20 | E26: 4600 | F26: 海拉 | G26: 6 | H26: =MAX($E26-$F$69*1)/$E$69 -> 37.513812 | I26: =MAX($E26-$F$70,0)/$E$70 -> 29.439971 | J26: =MAX($E26-$F$71,0)/$E$71 -> 18.43879 | K26: =MAX($E26-$F$72,0)/$E$72 -> 13.945384 | L26: 88 | N26: 1410200 | P26: ="["&_xlfn.TEXTJOIN(",",1,$N$7:N26)&"]" -> [1310100,1210400,1230100,1420200,1420200,1320100,1310300,1210600,1230400,1210700,1130100,1530100,1210300,1140100,1430700,1140200,1110100,1530200,1420300,1410200] | Q26: 三红 | AL26: 200 | AO26: {=SUM(AP26:AX26)-SUMPRODUCT(--(BJ26:BQ26>0))} -> 2 | AT26: 1 | AV26: 1
D27: 21 | E27: 5800 | F27: 我爱沙 | H27: =MAX($E27-$F$69*1)/$E$69 -> 49.116022 | I27: =MAX($E27-$F$70,0)/$E$70 -> 38.663982 | J27: =MAX($E27-$F$71,0)/$E$71 -> 24.215956 | K27: =MAX($E27-$F$72,0)/$E$72 -> 18.314694 | L27: 95 | N27: 1130200
D28: 22 | E28: 7000 | F28: 妲己 | H28: =MAX($E28-$F$69*1)/$E$69 -> 60.718232 | I28: =MAX($E28-$F$70,0)/$E$70 -> 47.887994 | J28: =MAX($E28-$F$71,0)/$E$71 -> 29.993122 | K28: =MAX($E28-$F$72,0)/$E$72 -> 22.684005 | L28: 103 | N28: 1120100
D29: 23 | E29: 8200 | F29: 白素贞 | H29: =MAX($E29-$F$69*1)/$E$69 -> 72.320442 | I29: =MAX($E29-$F$70,0)/$E$70 -> 57.112006 | J29: =MAX($E29-$F$71,0)/$E$71 -> 35.770289 | K29: =MAX($E29-$F$72,0)/$E$72 -> 27.053316 | L29: =L28+10 -> 113 | N29: 1550200
D30: 24 | E30: 10500 | F30: 零日骇客 | L30: =L29+12 -> 125 | N30: 1610100 | AL30: 210 | AM30: 【忍者鲨手-5级】 | AO30: {=SUM(AP30:AX30)-SUMPRODUCT(--(BJ30:BQ30>0))} -> 1 | AU30: 1
C31: ="["&_xlfn.TEXTJOIN(",",1,C7:C30)&"]" -> [{1310100,10},{1210400,10},{1230100,10},{1420200,5},{1420200,5},{1320100,5},{1310300,5},{1210600,5},{1230400,5}] | AL31: 220 | AO31: {=SUM(AP31:AX31)-SUMPRODUCT(--(BJ31:BQ31>0))} -> 2 | AT31: 1 | AV31: 1
D32: 抽卡等级 | J32: #当没有满图鉴基本概率低，满图鉴后产的多 | AL32: 230 | AM32: 累抽领取【关羽】 | AO32: {=SUM(AP32:AX32)-SUMPRODUCT(--(BJ32:BQ32>0))} -> 2 | AS32: 1 | AW32: 1
D33: 招募等级 | E33: 金币 | F33: 灵感钥匙 | G33: 职业经验*25 | H33: 职业经验*50 | I33: 职业经验*100 | J33: 蓝卡 | K33: 紫卡 | L33: 橙卡 | M33: 红卡 | N33: 升级经验 | O33: 列3 | P33: 小R | Q33: 中R | R33: 大R | S33: 期望卡数量 | T33: 列1 | U33: 列2 | AK33: 240 | AL33: 【甜心护士-5级】 | AN33: {=SUM(AO33:AW33)-SUMPRODUCT(--(BI33:BP33>0))} -> 2 | AT33: 1 | AU33: 1
C34: 500 | D34: 1 | E34: =1-SUM(F34:M34) -> 0.24 | F34: 0.02 | G34: 0.12 | H34: 0.08 | I34: 0.04 | J34: 0.4 | K34: 0.1 | N34: 450 | P34: =MAX((SUM($N$34:$N34)-OFFSET($F$68,MATCH(P$33,$D$69:$D$72,0),0))/OFFSET($E$68,MATCH(P$33,$D$69:$D$72,0),0),1) -> 1 | Q34: =MAX((SUM($N$34:$N34)-OFFSET($F$68,MATCH(Q$33,$D$69:$D$72,0),0))/OFFSET($E$68,MATCH(Q$33,$D$69:$D$72,0),0),1) -> 1 | R34: =MAX((SUM($N$34:$N34)-OFFSET($F$68,MATCH(R$33,$D$69:$D$72,0),0))/OFFSET($E$68,MATCH(R$33,$D$69:$D$72,0),0),1) -> 1 | S34: 10 | T34: =SUM($N$34:N34) -> 450 | U34: 0 | W34: 1310100 | X34: 1 | AK34: 250 | AN34: {=SUM(AO34:AW34)-SUMPRODUCT(--(BI34:BP34>0))} -> 2 | AR34: 1 | AV34: 1
C35: 1000 | D35: 2 | E35: =1-SUM(F35:M35) -> 0.24 | F35: 0.02 | G35: 0.12 | H35: 0.08 | I35: 0.04 | J35: =50%-SUM(K35:M35) -> 0.355 | K35: 0.12 | L35: 0.025 | N35: =INT(C35/1.1) -> 909 | P35: =MAX((SUM($N$34:$N35)-OFFSET($F$68,MATCH(P$33,$D$69:$D$72,0),0))/OFFSET($E$68,MATCH(P$33,$D$69:$D$72,0),0),1) -> 4.5274524 | Q35: =MAX((SUM($N$34:$N35)-OFFSET($F$68,MATCH(Q$33,$D$69:$D$72,0),0))/OFFSET($E$68,MATCH(Q$33,$D$69:$D$72,0),0),1) -> 2.8356259 | R35: =MAX((SUM($N$34:$N35)-OFFSET($F$68,MATCH(R$33,$D$69:$D$72,0),0))/OFFSET($E$68,MATCH(R$33,$D$69:$D$72,0),0),1) -> 2.1446034 | S35: 10 | T35: =SUM($N$34:N35) -> 1359 | U35: =T34 -> 450 | W35: 1210400 | X35: 2 | AK35: 260 | AN35: {=SUM(AO35:AW35)-SUMPRODUCT(--(BI35:BP35>0))} -> 2 | AS35: 1 | AW35: 1
C36: 2000 | D36: 3 | E36: =1-SUM(F36:M36) -> 0.24 | F36: 0.02 | G36: 0.12 | H36: 0.08 | I36: 0.04 | J36: =50%-SUM(K36:M36) -> 0.31 | K36: 0.14 | L36: 0.05 | N36: =INT(C36/1.1) -> 1818 | P36: =MAX((SUM($N$34:$N36)-OFFSET($F$68,MATCH(P$33,$D$69:$D$72,0),0))/OFFSET($E$68,MATCH(P$33,$D$69:$D$72,0),0),1) -> 18.50183 | Q36: =MAX((SUM($N$34:$N36)-OFFSET($F$68,MATCH(Q$33,$D$69:$D$72,0),0))/OFFSET($E$68,MATCH(Q$33,$D$69:$D$72,0),0),1) -> 11.588033 | R36: =MAX((SUM($N$34:$N36)-OFFSET($F$68,MATCH(R$33,$D$69:$D$72,0),0))/OFFSET($E$68,MATCH(R$33,$D$69:$D$72,0),0),1) -> 8.7641092 | S36: 10 | T36: =SUM($N$34:N36) -> 3177 | U36: =T35 -> 1359 | W36: 1230100 | X36: 3 | AK36: 270 | AN36: {=SUM(AO36:AW36)-SUMPRODUCT(--(BI36:BP36>0))} -> 2 | AT36: 1 | AV36: 1
C37: 3000 | D37: 4 | E37: =1-SUM(F37:M37) -> 0.24 | F37: 0.02 | G37: 0.12 | H37: 0.08 | I37: 0.04 | J37: =50%-SUM(K37:M37) -> 0.26422632 | K37: 0.16 | L37: 0.06 | M37: =Sheet1!H7 -> 0.015773675 | N37: =INT(C37/1.1) -> 2727 | P37: =MAX((SUM($N$34:$N37)-OFFSET($F$68,MATCH(P$33,$D$69:$D$72,0),0))/OFFSET($E$68,MATCH(P$33,$D$69:$D$72,0),0),1) -> 39.463397 | Q37: =MAX((SUM($N$34:$N37)-OFFSET($F$68,MATCH(Q$33,$D$69:$D$72,0),0))/OFFSET($E$68,MATCH(Q$33,$D$69:$D$72,0),0),1) -> 24.716644 | R37: =MAX((SUM($N$34:$N37)-OFFSET($F$68,MATCH(R$33,$D$69:$D$72,0),0))/OFFSET($E$68,MATCH(R$33,$D$69:$D$72,0),0),1) -> 18.693368 | S37: 10 | T37: =SUM($N$34:N37) -> 5904 | U37: =T36 -> 3177 | W37: 1420200 | X37: 4 | AK37: 280 | AL37: 【雷震子-5级】 | AN37: {=SUM(AO37:AW37)-SUMPRODUCT(--(BI37:BP37>0))} -> 2 | AT37: 1 | AV37: 1
C38: 4000 | D38: 5 | E38: =1-SUM(F38:M38) -> 0.24 | F38: 0.02 | G38: 0.12 | H38: 0.08 | I38: 0.04 | J38: =50%-SUM(K38:M38) -> 0.21694207 | K38: 0.18 | L38: 0.08 | M38: =Sheet1!H8 -> 0.023057933 | N38: =INT(C38/1.1) -> 3636 | P38: =MAX((SUM($N$34:$N38)-OFFSET($F$68,MATCH(P$33,$D$69:$D$72,0),0))/OFFSET($E$68,MATCH(P$33,$D$69:$D$72,0),0),1) -> 67.412152 | Q38: =MAX((SUM($N$34:$N38)-OFFSET($F$68,MATCH(Q$33,$D$69:$D$72,0),0))/OFFSET($E$68,MATCH(Q$33,$D$69:$D$72,0),0),1) -> 42.221458 | R38: =MAX((SUM($N$34:$N38)-OFFSET($F$68,MATCH(R$33,$D$69:$D$72,0),0))/OFFSET($E$68,MATCH(R$33,$D$69:$D$72,0),0),1) -> 31.93238 | S38: 10 | T38: =SUM($N$34:N38) -> 9540 | U38: =T37 -> 5904 | W38: 1320100 | X38: 5 | AK38: 290 | AN38: {=SUM(AO38:AW38)-SUMPRODUCT(--(BI38:BP38>0))} -> 2 | AR38: 1 | AW38: 1
C39: 5000 | D39: 6 | E39: =1-SUM(F39:M39) -> 0.24 | F39: 0.02 | G39: 0.12 | H39: 0.08 | I39: 0.04 | J39: =50%-SUM(K39:M39) -> 0.1685022 | K39: 0.2 | L39: 0.1 | M39: =Sheet1!H9 -> 0.031497799 | N39: =INT(C39/1.1) -> 4545 | P39: =MAX((SUM($N$34:$N39)-OFFSET($F$68,MATCH(P$33,$D$69:$D$72,0),0))/OFFSET($E$68,MATCH(P$33,$D$69:$D$72,0),0),1) -> 102.3481 | Q39: =MAX((SUM($N$34:$N39)-OFFSET($F$68,MATCH(Q$33,$D$69:$D$72,0),0))/OFFSET($E$68,MATCH(Q$33,$D$69:$D$72,0),0),1) -> 64.102476 | R39: =MAX((SUM($N$34:$N39)-OFFSET($F$68,MATCH(R$33,$D$69:$D$72,0),0))/OFFSET($E$68,MATCH(R$33,$D$69:$D$72,0),0),1) -> 48.481144 | S39: 10 | T39: =SUM($N$34:N39) -> 14085 | U39: =T38 -> 9540 | W39: 1210600 | X39: 6 | AK39: 300 | AL39: 最终：【关羽-4级】、【忍者鲨手-5级】、【泥巴少女-5级】、【甜心护士-5级】、【雷震子-5级】 | AW39: 1
C40: 999999 | D40: 7 | E40: =1-SUM(F40:M40) -> 0.24 | F40: 0.02 | G40: 0.12 | H40: 0.08 | I40: 0.04 | J40: =50%-SUM(K40:M40) -> 0.13931361 | K40: 0.2 | L40: 0.12 | M40: =Sheet1!H10 -> 0.040686392 | N40: =INT(C40/1.1) -> 909090 | P40: =MAX((SUM($N$34:$N41)-OFFSET($F$68,MATCH(P$33,$D$69:$D$72,0),0))/OFFSET($E$68,MATCH(P$33,$D$69:$D$72,0),0),1) -> 7090.2288 | Q40: =MAX((SUM($N$34:$N41)-OFFSET($F$68,MATCH(Q$33,$D$69:$D$72,0),0))/OFFSET($E$68,MATCH(Q$33,$D$69:$D$72,0),0),1) -> 4440.7393 | R40: =MAX((SUM($N$34:$N41)-OFFSET($F$68,MATCH(R$33,$D$69:$D$72,0),0))/OFFSET($E$68,MATCH(R$33,$D$69:$D$72,0),0),1) -> 3358.5618 | S40: 10 | T40: =SUM($N$34:N40) -> 923175 | U40: =T39 -> 14085 | W40: 1230400 | X40: 7 | AO40: =SUM(AP7:AP39) -> 19 | AP40: =SUM(AQ7:AQ39) -> 19 | AQ40: =SUM(AR7:AR39) -> 21 | AR40: =SUM(AS7:AS39) -> 7 | AS40: =SUM(AT7:AT39) -> 10 | AT40: =SUM(AU7:AU39) -> 6 | AU40: =SUM(AV7:AV39) -> 7 | AV40: =SUM(AW7:AW39) -> 5 | AW40: =SUM(AX7:AX39) -> 0
...

Sheet 梦灵经验产出
A1: 设计思路
C3: 梦灵经验规划
D4: 梦灵经验主要控制等级释放节奏，比升级周期短，纯活跃投放、防止投放导致等级不平衡，在消耗做倍率区分
D5: 满级参数
D6: 养成周期/天 | E6: 60 | F6: *引用商业化框架
D7: 目标坑深(钻石) | E7: =45000*6*2 -> 540000 | F7: *引用商业化框架
D8: 活跃产出(钻石) | E8: =E7/E6/J385*G385 -> 3389.3368
D9: 总产出 | E9: =E7/E6 -> 9000 | R9: 等级 | S9: 蓝品 | T9: 紫品 | U9: 橙品 | V9: 红品
D10: 付费占比 | E10: =(E9-E8)/E9 -> 0.62340702 | R10: 1 | S10: 0 | T10: 0 | U10: 0 | V10: 0
R11: 2 | S11: 24 | T11: 36 | U11: 48 | V11: 72
D12: 梦灵数量 | K12: 概率降低为50% | R12: 3 | S12: 48 | T12: 72 | U12: 96 | V12: 144
D13: 梦灵品质 | E13: 战士 | F13: 法师 | G13: 射手 | H13: 辅助 | I13: 控制 | J13: 毒系 | K13: 召唤 | L13: 期望等级 | M13: 总消耗 | N13: 每日产出 | R13: 4 | S13: 72 | T13: 108 | U13: 144 | V13: 216
D14: 蓝 | F14: 1 | G14: 1 | H14: 1 | L14: 50 | R14: 5 | S14: 96 | T14: 144 | U14: 192 | V14: 288
D15: 紫 | E15: 2 | F15: 1 | G15: 1 | H15: 1 | J15: 1 | L15: 40 | R15: 6 | S15: 120 | T15: 180 | U15: 240 | V15: 360
D16: 橙 | E16: 1 | F16: 1 | G16: 1 | H16: 1 | I16: 1 | J16: 1 | K16: 1 | L16: 30 | R16: 7 | S16: 144 | T16: 216 | U16: 288 | V16: 432
D17: 红 | E17: 1 | F17: 1 | G17: 1 | H17: 1 | I17: 1 | J17: 1 | L17: 30 | R17: 8 | S17: 168 | T17: 252 | U17: 336 | V17: 504
D18: 产出比例 | E18: =--SUM(E14:E17) -> 4 | F18: =SUM(F14:F17) -> 4 | G18: =SUM(G14:G17) -> 4 | H18: =SUM(H14:H17) -> 4 | I18: =SUM(I14:I17) -> 2 | J18: =SUM(J14:J17) -> 3 | K18: =SUM(K14:K17) -> 1 | R18: 9 | S18: 192 | T18: 288 | U18: 384 | V18: 576
D19: 消耗倍率 | R19: 10 | S19: 216 | T19: 324 | U19: 432 | V19: 648
R20: 11 | S20: 480 | T20: 720 | U20: 960 | V20: 1440
R21: 12 | S21: 528 | T21: 792 | U21: 1056 | V21: 1584
G22: 标准消耗 | L22: #以五天的量为基数 | R22: 13 | S22: 576 | T22: 864 | U22: 1152 | V22: 1728
D23: ID | E23: 等级 | F23: 定位 | G23: 蓝品 | H23: 紫品 | I23: 橙品 | J23: 红品 | K23: 彩品 | L23: 消耗倍率 | M23: 停留时间 | R23: 14 | S23: 624 | T23: 936 | U23: 1248 | V23: 1872
D24: 1 | E24: 1 | F24: 标准消耗 | G24: 24 | H24: 36 | I24: 48 | J24: 48 | K24: 60 | L24: 1 | R24: 15 | S24: 672 | T24: 1008 | U24: 1344 | V24: 2016
D25: 2 | E25: 2 | F25: 标准消耗 | G25: 48 | H25: 72 | I25: 96 | J25: 96 | K25: 120 | L25: 2 | R25: 16 | S25: 720 | T25: 1080 | U25: 1440 | V25: 2160
D26: 3 | E26: 3 | F26: 标准消耗 | G26: 72 | H26: 108 | I26: 144 | J26: 144 | K26: 180 | L26: 3 | R26: 17 | S26: 768 | T26: 1152 | U26: 1536 | V26: 2304
D27: 4 | E27: 4 | F27: 标准消耗 | G27: 120 | H27: 180 | I27: 240 | J27: 240 | K27: 300 | L27: 5 | R27: 18 | S27: 816 | T27: 1224 | U27: 1632 | V27: 2448
D28: 5 | E28: 5 | F28: 标准消耗 | G28: 168 | H28: 252 | I28: 336 | J28: 336 | K28: 420 | L28: 7 | R28: 19 | S28: 864 | T28: 1296 | U28: 1728 | V28: 2592
D29: 6 | E29: 6 | F29: 标准消耗 | G29: 216 | H29: 324 | I29: 432 | J29: 432 | K29: 540 | L29: 9 | R29: 20 | S29: 912 | T29: 1368 | U29: 1824 | V29: 2736
D30: 7 | E30: 7 | F30: 标准消耗 | G30: 264 | H30: 396 | I30: 528 | J30: 528 | K30: 660 | L30: 11 | R30: 21 | S30: 960 | T30: 1440 | U30: 1920 | V30: 2880
D31: 8 | E31: 8 | F31: 标准消耗 | G31: 312 | H31: 468 | I31: 624 | J31: 624 | K31: 780 | L31: 13 | R31: 22 | S31: 1008 | T31: 1512 | U31: 2016 | V31: 3024
D32: 9 | E32: 9 | F32: 标准消耗 | G32: 360 | H32: 540 | I32: 720 | J32: 720 | K32: 900 | L32: 15 | R32: 23 | S32: 1056 | T32: 1584 | U32: 2112 | V32: 3168
D33: 10 | E33: 10 | F33: 标准消耗 | G33: 408 | H33: 612 | I33: 816 | J33: 816 | K33: 1020 | L33: 17 | R33: 24 | S33: 1104 | T33: 1656 | U33: 2208 | V33: 3312
D34: 11 | E34: 11 | F34: 标准消耗 | G34: 456 | H34: 684 | I34: 912 | J34: 912 | K34: 1140 | L34: 19 | R34: 25 | S34: 1152 | T34: 1728 | U34: 2304 | V34: 3456
D35: 12 | E35: 12 | F35: 标准消耗 | G35: 504 | H35: 756 | I35: 1008 | J35: 1008 | K35: 1260 | L35: 21 | R35: 26 | S35: 1200 | T35: 1800 | U35: 2400 | V35: 3600
... D58: 35 | E58: 35 | F58: 标准消耗 | G58: 2040 | H58: 3060 | I58: 4080 | J58: 4080 | K58: 5100 | L58: 85 | R58: 49 | S58: 3456 | T58: 3456 | U58: 4608 | V58: 6912
D59: 36 | E59: 36 | F59: 标准消耗 | G59: 2112 | H59: 3168 | I59: 4224 | J59: 4224 | K59: 5280 | L59: 88
D60: 37 | E60: 37 | F60: 标准消耗 | G60: 2184 | H60: 3276 | I60: 4368 | J60: 4368 | K60: 5460 | L60: 91
D61: 38 | E61: 38 | F61: 标准消耗 | G61: 2256 | H61: 3384 | I61: 4512 | J61: 4512 | K61: 5640 | L61: 94
D62: 39 | E62: 39 | F62: 标准消耗 | G62: 2328 | H62: 3492 | I62: 4656 | J62: 4656 | K62: 5820 | L62: 97
D63: 40 | E63: 40 | F63: 标准消耗 | G63: 2400 | H63: 3600 | I63: 4800 | J63: 4800 | K63: 6000 | L63: 100
...

Sheet 梦灵图鉴
A1: 梦灵升星
C3: 属性规划
D5: 途径 | E5: 爆伤 | F5: 期望爆伤
D6: 养成1 | E6: 9 | F6: =OFFSET($F$10,MATCH(30,$E$12:$E$61,1),0)*SUM(梦灵属性!E26:J26)+OFFSET($H$10,MATCH(30,$G$12:$G$61,1),0)*SUM(梦灵属性!$E$27:$J$27)+OFFSET($J$10,MATCH(30,$I$12:$I$61,1),0)*SUM(梦灵属性!$E$28:$J$28)+OFFSET($L$10,MATCH(30,$K$12:$K$61,1),0)*SUM(梦灵属性!$E$29:$J$29) -> 5.55
C8: 养成规划
D10: 养成练度 | E10: 蓝卡期望天数 | F10: 爆伤 | G10: 紫卡期望天数 | H10: 爆伤 | I10: 橙卡期望天数 | J10: 爆伤 | K10: 红卡期望天数 | L10: 爆伤
D11: 0 | E11: 0 | F11: 0 | G11: 0 | H11: 0 | I11: 0 | J11: 0 | K11: 0 | L11: 0
D12: 1 | E12: =IFERROR(MATCH(D12,梦灵本体产出!$K$147:$K$206,1),0) -> 0 | F12: 0.01 | G12: =IFERROR(MATCH($D12,梦灵本体产出!$L$147:$L$206,1),0) -> 0 | H12: 0.012 | I12: =IFERROR(MATCH($D12,梦灵本体产出!$M$147:$M$206,1),0) -> 1 | J12: 0.014 | K12: =IFERROR(MATCH($D12,梦灵本体产出!$N$147:$N$206,1),0) -> 11 | L12: 0.016
D13: 2 | E13: =IFERROR(MATCH(D13,梦灵本体产出!$K$147:$K$206,1),0) -> 0 | F13: =$D13*F$12 -> 0.02 | G13: =IFERROR(MATCH($D13,梦灵本体产出!$L$147:$L$206,1),0) -> 0 | H13: =$D13*H$12 -> 0.024 | I13: =IFERROR(MATCH($D13,梦灵本体产出!$M$147:$M$206,1),0) -> 1 | J13: =$D13*J$12 -> 0.028 | K13: =IFERROR(MATCH($D13,梦灵本体产出!$N$147:$N$206,1),0) -> 12 | L13: =$D13*L$12 -> 0.032
D14: 3 | E14: =IFERROR(MATCH(D14,梦灵本体产出!$K$147:$K$206,1),0) -> 0 | F14: =$D14*F$12 -> 0.03 | G14: =IFERROR(MATCH($D14,梦灵本体产出!$L$147:$L$206,1),0) -> 0 | H14: =$D14*H$12 -> 0.036 | I14: =IFERROR(MATCH($D14,梦灵本体产出!$M$147:$M$206,1),0) -> 1 | J14: =$D14*J$12 -> 0.042 | K14: =IFERROR(MATCH($D14,梦灵本体产出!$N$147:$N$206,1),0) -> 13 | L14: =$D14*L$12 -> 0.048
D15: 4 | E15: =IFERROR(MATCH(D15,梦灵本体产出!$K$147:$K$206,1),0) -> 0 | F15: =$D15*F$12 -> 0.04 | G15: =IFERROR(MATCH($D15,梦灵本体产出!$L$147:$L$206,1),0) -> 0 | H15: =$D15*H$12 -> 0.048 | I15: =IFERROR(MATCH($D15,梦灵本体产出!$M$147:$M$206,1),0) -> 1 | J15: =$D15*J$12 -> 0.056 | K15: =IFERROR(MATCH($D15,梦灵本体产出!$N$147:$N$206,1),0) -> 13 | L15: =$D15*L$12 -> 0.064
D16: 5 | E16: =IFERROR(MATCH(D16,梦灵本体产出!$K$147:$K$206,1),0) -> 0 | F16: =$D16*F$12 -> 0.05 | G16: =IFERROR(MATCH($D16,梦灵本体产出!$L$147:$L$206,1),0) -> 1 | H16: =$D16*H$12 -> 0.06 | I16: =IFERROR(MATCH($D16,梦灵本体产出!$M$147:$M$206,1),0) -> 1 | J16: =$D16*J$12 -> 0.07 | K16: =IFERROR(MATCH($D16,梦灵本体产出!$N$147:$N$206,1),0) -> 13 | L16: =$D16*L$12 -> 0.08
D17: 6 | E17: =IFERROR(MATCH(D17,梦灵本体产出!$K$147:$K$206,1),0) -> 0 | F17: =$D17*F$12 -> 0.06 | G17: =IFERROR(MATCH($D17,梦灵本体产出!$L$147:$L$206,1),0) -> 1 | H17: =$D17*H$12 -> 0.072 | I17: =IFERROR(MATCH($D17,梦灵本体产出!$M$147:$M$206,1),0) -> 3 | J17: =$D17*J$12 -> 0.084 | K17: =IFERROR(MATCH($D17,梦灵本体产出!$N$147:$N$206,1),0) -> 13 | L17: =$D17*L$12 -> 0.096
D18: 7 | E18: =IFERROR(MATCH(D18,梦灵本体产出!$K$147:$K$206,1),0) -> 0 | F18: =$D18*F$12 -> 0.07 | G18: =IFERROR(MATCH($D18,梦灵本体产出!$L$147:$L$206,1),0) -> 2 | H18: =$D18*H$12 -> 0.084 | I18: =IFERROR(MATCH($D18,梦灵本体产出!$M$147:$M$206,1),0) -> 4 | J18: =$D18*J$12 -> 0.098 | K18: =IFERROR(MATCH($D18,梦灵本体产出!$N$147:$N$206,1),0) -> 15 | L18: =$D18*L$12 -> 0.112
D19: 8 | E19: =IFERROR(MATCH(D19,梦灵本体产出!$K$147:$K$206,1),0) -> 0 | F19: =$D19*F$12 -> 0.08 | G19: =IFERROR(MATCH($D19,梦灵本体产出!$L$147:$L$206,1),0) -> 2 | H19: =$D19*H$12 -> 0.096 | I19: =IFERROR(MATCH($D19,梦灵本体产出!$M$147:$M$206,1),0) -> 5 | J19: =$D19*J$12 -> 0.112 | K19: =IFERROR(MATCH($D19,梦灵本体产出!$N$147:$N$206,1),0) -> 17 | L19: =$D19*L$12 -> 0.128
D20: 9 | E20: =IFERROR(MATCH(D20,梦灵本体产出!$K$147:$K$206,1),0) -> 0 | F20: =$D20*F$12 -> 0.09 | G20: =IFERROR(MATCH($D20,梦灵本体产出!$L$147:$L$206,1),0) -> 3 | H20: =$D20*H$12 -> 0.108 | I20: =IFERROR(MATCH($D20,梦灵本体产出!$M$147:$M$206,1),0) -> 6 | J20: =$D20*J$12 -> 0.126 | K20: =IFERROR(MATCH($D20,梦灵本体产出!$N$147:$N$206,1),0) -> 20 | L20: =$D20*L$12 -> 0.144
D21: 10 | E21: =IFERROR(MATCH(D21,梦灵本体产出!$K$147:$K$206,1),0) -> 0 | F21: =$D21*F$12 -> 0.1 | G21: =IFERROR(MATCH($D21,梦灵本体产出!$L$147:$L$206,1),0) -> 4 | H21: =$D21*H$12 -> 0.12 | I21: =IFERROR(MATCH($D21,梦灵本体产出!$M$147:$M$206,1),0) -> 6 | J21: =$D21*J$12 -> 0.14 | K21: =IFERROR(MATCH($D21,梦灵本体产出!$N$147:$N$206,1),0) -> 20 | L21: =$D21*L$12 -> 0.16
D22: 11 | E22: =IFERROR(MATCH(D22,梦灵本体产出!$K$147:$K$206,1),0) -> 0 | F22: =$D22*F$12 -> 0.11 | G22: =IFERROR(MATCH($D22,梦灵本体产出!$L$147:$L$206,1),0) -> 5 | H22: =$D22*H$12 -> 0.132 | I22: =IFERROR(MATCH($D22,梦灵本体产出!$M$147:$M$206,1),0) -> 9 | J22: =$D22*J$12 -> 0.154 | K22: =IFERROR(MATCH($D22,梦灵本体产出!$N$147:$N$206,1),0) -> 23 | L22: =$D22*L$12 -> 0.176
D23: 12 | E23: =IFERROR(MATCH(D23,梦灵本体产出!$K$147:$K$206,1),0) -> 0 | F23: =$D23*F$12 -> 0.12 | G23: =IFERROR(MATCH($D23,梦灵本体产出!$L$147:$L$206,1),0) -> 6 | H23: =$D23*H$12 -> 0.144 | I23: =IFERROR(MATCH($D23,梦灵本体产出!$M$147:$M$206,1),0) -> 12 | J23: =$D23*J$12 -> 0.168 | K23: =IFERROR(MATCH($D23,梦灵本体产出!$N$147:$N$206,1),0) -> 27 | L23: =$D23*L$12 -> 0.192
D24: 13 | E24: =IFERROR(MATCH(D24,梦灵本体产出!$K$147:$K$206,1),0) -> 0 | F24: =$D24*F$12 -> 0.13 | G24: =IFERROR(MATCH($D24,梦灵本体产出!$L$147:$L$206,1),0) -> 6 | H24: =$D24*H$12 -> 0.156 | I24: =IFERROR(MATCH($D24,梦灵本体产出!$M$147:$M$206,1),0) -> 13 | J24: =$D24*J$12 -> 0.182 | K24: =IFERROR(MATCH($D24,梦灵本体产出!$N$147:$N$206,1),0) -> 27 | L24: =$D24*L$12 -> 0.208
... D61: 50 | E61: =IFERROR(MATCH(D61,梦灵本体产出!$K$147:$K$206,1),0) -> 60 | F61: =$D61*F$12 -> 0.5 | G61: =IFERROR(MATCH($D61,梦灵本体产出!$L$147:$L$206,1),0) -> 60 | H61: =$D61*H$12 -> 0.6 | I61: =IFERROR(MATCH($D61,梦灵本体产出!$M$147:$M$206,1),0) -> 60 | J61: =$D61*J$12 -> 0.7 | K61: =IFERROR(MATCH($D61,梦灵本体产出!$N$147:$N$206,1),0) -> 60 | L61: =$D61*L$12 -> 0.8
C64: 养成汇总

Sheet 属性汇总
A2: #目前只计算双月卡玩家进度，后续等数值总表一起拓展
A6: 开服天数 | B6: 梦灵品质练度 | C6: 梦灵等级练度 | D6: 攻击 | E6: 生命 | F6: 攻击比 | G6: 生命比 | H6: 暴击率 | I6: 暴击伤害 | J6: 伤害增加 | K6: 伤害减免 | L6: 固定减伤 | M6: 伤害增加 | N6: 攻击速度 | P6: 梦灵品质练度 | Q6: 梦灵等级练度 | R6: 攻击 | S6: 生命 | T6: 攻击比 | U6: 生命比 | V6: 暴击率 | W6: 暴击伤害 | X6: 伤害增加 | Y6: 伤害减免 | Z6: 固定减伤 | AA6: 伤害增加 | AB6: 攻击速度
A7: 1 | B7: =OFFSET(梦灵本体产出!$G$6,MATCH(A7,梦灵本体产出!$I$7:$I$30,1),0) -> 5 | C7: =MATCH(A7,OFFSET(梦灵属性!#REF!,50*(B7-3),0)) -> #REF! | F7: =_xlfn.XLOOKUP($B7,梦灵属性!$F$38:$F$41,梦灵属性!$E$38:$E$41)*$C7 -> #REF! | G7: =_xlfn.XLOOKUP($B7,梦灵属性!$F$38:$F$41,梦灵属性!$E$38:$E$41)*$C7 -> #REF! | I7: =OFFSET(梦灵图鉴!F$10,MATCH(A7,梦灵图鉴!$E$11:$E$61,1),0)*SUM(梦灵属性!$E$26:$J$26)+OFFSET(梦灵图鉴!H$10,MATCH(A7,梦灵图鉴!$G$11:$G$61,1),0)*SUM(梦灵属性!$E$27:$J$27)+OFFSET(梦灵图鉴!J$10,MATCH(A7,梦灵图鉴!$I$11:$I$61,1),0)*SUM(梦灵属性!$E$28:$J$28)+OFFSET(梦灵图鉴!L$10,MATCH(A7,梦灵图鉴!$K$11:$K$61,1),0)*SUM(梦灵属性!$E$29:$J$29) -> 1.392 | P7: 3 | Q7: 1 | R7: =OFFSET(梦灵属性!G$37,$P7-2,0) -> 0 | S7: =OFFSET(梦灵属性!H$37,$P7-2,0) -> 0 | T7: =OFFSET(梦灵属性!$E$37,$P7-2,0)*$Q7 -> 0.04 | U7: =OFFSET(梦灵属性!$E$37,$P7-2,0)*$Q7 -> 0.04
A8: 2 | B8: =OFFSET(梦灵本体产出!$G$6,MATCH(A8,梦灵本体产出!$I$7:$I$30,1),0) -> 5 | C8: =MATCH(A8,OFFSET(梦灵属性!#REF!,50*(B8-3),0)) -> #REF! | F8: =_xlfn.XLOOKUP(B8,梦灵属性!$F$38:$F$41,梦灵属性!$E$38:$E$41)*C8 -> #REF! | G8: =_xlfn.XLOOKUP($B8,梦灵属性!$F$38:$F$41,梦灵属性!$E$38:$E$41)*$C8 -> #REF! | I8: =OFFSET(梦灵图鉴!F$10,MATCH(A8,梦灵图鉴!$E$11:$E$61,1),0)*SUM(梦灵属性!$E$26:$J$26)+OFFSET(梦灵图鉴!H$10,MATCH(A8,梦灵图鉴!$G$11:$G$61,1),0)*SUM(梦灵属性!$E$27:$J$27)+OFFSET(梦灵图鉴!J$10,MATCH(A8,梦灵图鉴!$I$11:$I$61,1),0)*SUM(梦灵属性!$E$28:$J$28)+OFFSET(梦灵图鉴!L$10,MATCH(A8,梦灵图鉴!$K$11:$K$61,1),0)*SUM(梦灵属性!$E$29:$J$29) -> 1.626 | P8: 3 | Q8: 2 | R8: =OFFSET(梦灵属性!G$37,$P8-2,0) -> 0 | S8: =OFFSET(梦灵属性!H$37,$P8-2,0) -> 0 | T8: =OFFSET(梦灵属性!$E$37,$P8-2,0)*$Q8 -> 0.08 | U8: =OFFSET(梦灵属性!$E$37,$P8-2,0)*$Q8 -> 0.08
A9: 3 | B9: =OFFSET(梦灵本体产出!$G$6,MATCH(A9,梦灵本体产出!$I$7:$I$30,1),0) -> 5 | C9: =MATCH(A9,OFFSET(梦灵属性!#REF!,50*(B9-3),0)) -> #REF! | F9: =_xlfn.XLOOKUP(B9,梦灵属性!$F$38:$F$41,梦灵属性!$E$38:$E$41)*C9 -> #REF! | G9: =_xlfn.XLOOKUP($B9,梦灵属性!$F$38:$F$41,梦灵属性!$E$38:$E$41)*$C9 -> #REF! | I9: =OFFSET(梦灵图鉴!F$10,MATCH(A9,梦灵图鉴!$E$11:$E$61,1),0)*SUM(梦灵属性!$E$26:$J$26)+OFFSET(梦灵图鉴!H$10,MATCH(A9,梦灵图鉴!$G$11:$G$61,1),0)*SUM(梦灵属性!$E$27:$J$27)+OFFSET(梦灵图鉴!J$10,MATCH(A9,梦灵图鉴!$I$11:$I$61,1),0)*SUM(梦灵属性!$E$28:$J$28)+OFFSET(梦灵图鉴!L$10,MATCH(A9,梦灵图鉴!$K$11:$K$61,1),0)*SUM(梦灵属性!$E$29:$J$29) -> 1.872 | P9: 3 | Q9: 3 | R9: =OFFSET(梦灵属性!G$37,$P9-2,0) -> 0 | S9: =OFFSET(梦灵属性!H$37,$P9-2,0) -> 0 | T9: =OFFSET(梦灵属性!$E$37,$P9-2,0)*$Q9 -> 0.12 | U9: =OFFSET(梦灵属性!$E$37,$P9-2,0)*$Q9 -> 0.12
A10: 4 | B10: =OFFSET(梦灵本体产出!$G$6,MATCH(A10,梦灵本体产出!$I$7:$I$30,1),0) -> 5 | C10: =MATCH(A10,OFFSET(梦灵属性!#REF!,50*(B10-3),0)) -> #REF! | F10: =_xlfn.XLOOKUP(B10,梦灵属性!$F$38:$F$41,梦灵属性!$E$38:$E$41)*C10 -> #REF! | G10: =_xlfn.XLOOKUP($B10,梦灵属性!$F$38:$F$41,梦灵属性!$E$38:$E$41)*$C10 -> #REF! | I10: =OFFSET(梦灵图鉴!F$10,MATCH(A10,梦灵图鉴!$E$11:$E$61,1),0)*SUM(梦灵属性!$E$26:$J$26)+OFFSET(梦灵图鉴!H$10,MATCH(A10,梦灵图鉴!$G$11:$G$61,1),0)*SUM(梦灵属性!$E$27:$J$27)+OFFSET(梦灵图鉴!J$10,MATCH(A10,梦灵图鉴!$I$11:$I$61,1),0)*SUM(梦灵属性!$E$28:$J$28)+OFFSET(梦灵图鉴!L$10,MATCH(A10,梦灵图鉴!$K$11:$K$61,1),0)*SUM(梦灵属性!$E$29:$J$29) -> 2.058 | P10: 3 | Q10: 4 | R10: =OFFSET(梦灵属性!G$37,$P10-2,0) -> 0 | S10: =OFFSET(梦灵属性!H$37,$P10-2,0) -> 0 | T10: =OFFSET(梦灵属性!$E$37,$P10-2,0)*$Q10 -> 0.16 | U10: =OFFSET(梦灵属性!$E$37,$P10-2,0)*$Q10 -> 0.16
A11: 5 | B11: =OFFSET(梦灵本体产出!$G$6,MATCH(A11,梦灵本体产出!$I$7:$I$30,1),0) -> 5 | C11: =MATCH(A11,OFFSET(梦灵属性!#REF!,50*(B11-3),0)) -> #REF! | F11: =_xlfn.XLOOKUP(B11,梦灵属性!$F$38:$F$41,梦灵属性!$E$38:$E$41)*C11 -> #REF! | G11: =_xlfn.XLOOKUP($B11,梦灵属性!$F$38:$F$41,梦灵属性!$E$38:$E$41)*$C11 -> #REF! | I11: =OFFSET(梦灵图鉴!F$10,MATCH(A11,梦灵图鉴!$E$11:$E$61,1),0)*SUM(梦灵属性!$E$26:$J$26)+OFFSET(梦灵图鉴!H$10,MATCH(A11,梦灵图鉴!$G$11:$G$61,1),0)*SUM(梦灵属性!$E$27:$J$27)+OFFSET(梦灵图鉴!J$10,MATCH(A11,梦灵图鉴!$I$11:$I$61,1),0)*SUM(梦灵属性!$E$28:$J$28)+OFFSET(梦灵图鉴!L$10,MATCH(A11,梦灵图鉴!$K$11:$K$61,1),0)*SUM(梦灵属性!$E$29:$J$29) -> 2.244 | P11: 3 | Q11: 5 | R11: =OFFSET(梦灵属性!G$37,$P11-2,0) -> 0 | S11: =OFFSET(梦灵属性!H$37,$P11-2,0) -> 0 | T11: =OFFSET(梦灵属性!$E$37,$P11-2,0)*$Q11 -> 0.2 | U11: =OFFSET(梦灵属性!$E$37,$P11-2,0)*$Q11 -> 0.2
A12: 6 | B12: =OFFSET(梦灵本体产出!$G$6,MATCH(A12,梦灵本体产出!$I$7:$I$30,1),0) -> 5 | C12: =MATCH(A12,OFFSET(梦灵属性!#REF!,50*(B12-3),0)) -> #REF! | F12: =_xlfn.XLOOKUP(B12,梦灵属性!$F$38:$F$41,梦灵属性!$E$38:$E$41)*C12 -> #REF! | G12: =_xlfn.XLOOKUP($B12,梦灵属性!$F$38:$F$41,梦灵属性!$E$38:$E$41)*$C12 -> #REF! | I12: =OFFSET(梦灵图鉴!F$10,MATCH(A12,梦灵图鉴!$E$11:$E$61,1),0)*SUM(梦灵属性!$E$26:$J$26)+OFFSET(梦灵图鉴!H$10,MATCH(A12,梦灵图鉴!$G$11:$G$61,1),0)*SUM(梦灵属性!$E$27:$J$27)+OFFSET(梦灵图鉴!J$10,MATCH(A12,梦灵图鉴!$I$11:$I$61,1),0)*SUM(梦灵属性!$E$28:$J$28)+OFFSET(梦灵图鉴!L$10,MATCH(A12,梦灵图鉴!$K$11:$K$61,1),0)*SUM(梦灵属性!$E$29:$J$29) -> 2.616 | P12: 3 | Q12: 6 | R12: =OFFSET(梦灵属性!G$37,$P12-2,0) -> 0 | S12: =OFFSET(梦灵属性!H$37,$P12-2,0) -> 0 | T12: =OFFSET(梦灵属性!$E$37,$P12-2,0)*$Q12 -> 0.24 | U12: =OFFSET(梦灵属性!$E$37,$P12-2,0)*$Q12 -> 0.24
A13: 7 | B13: =OFFSET(梦灵本体产出!$G$6,MATCH(A13,梦灵本体产出!$I$7:$I$30,1),0) -> 5 | C13: =MATCH(A13,OFFSET(梦灵属性!#REF!,50*(B13-3),0)) -> #REF! | F13: =_xlfn.XLOOKUP(B13,梦灵属性!$F$38:$F$41,梦灵属性!$E$38:$E$41)*C13 -> #REF! | G13: =_xlfn.XLOOKUP($B13,梦灵属性!$F$38:$F$41,梦灵属性!$E$38:$E$41)*$C13 -> #REF! | I13: =OFFSET(梦灵图鉴!F$10,MATCH(A13,梦灵图鉴!$E$11:$E$61,1),0)*SUM(梦灵属性!$E$26:$J$26)+OFFSET(梦灵图鉴!H$10,MATCH(A13,梦灵图鉴!$G$11:$G$61,1),0)*SUM(梦灵属性!$E$27:$J$27)+OFFSET(梦灵图鉴!J$10,MATCH(A13,梦灵图鉴!$I$11:$I$61,1),0)*SUM(梦灵属性!$E$28:$J$28)+OFFSET(梦灵图鉴!L$10,MATCH(A13,梦灵图鉴!$K$11:$K$61,1),0)*SUM(梦灵属性!$E$29:$J$29) -> 2.616 | P13: 3 | Q13: 7 | R13: =OFFSET(梦灵属性!G$37,$P13-2,0) -> 0 | S13: =OFFSET(梦灵属性!H$37,$P13-2,0) -> 0 | T13: =OFFSET(梦灵属性!$E$37,$P13-2,0)*$Q13 -> 0.28 | U13: =OFFSET(梦灵属性!$E$37,$P13-2,0)*$Q13 -> 0.28
A14: 8 | B14: =OFFSET(梦灵本体产出!$G$6,MATCH(A14,梦灵本体产出!$I$7:$I$30,1),0) -> 6 | C14: =MATCH(A14,OFFSET(梦灵属性!#REF!,50*(B14-3),0)) -> #REF! | F14: =_xlfn.XLOOKUP(B14,梦灵属性!$F$38:$F$41,梦灵属性!$E$38:$E$41)*C14 -> #REF! | G14: =_xlfn.XLOOKUP($B14,梦灵属性!$F$38:$F$41,梦灵属性!$E$38:$E$41)*$C14 -> #REF! | I14: =OFFSET(梦灵图鉴!F$10,MATCH(A14,梦灵图鉴!$E$11:$E$61,1),0)*SUM(梦灵属性!$E$26:$J$26)+OFFSET(梦灵图鉴!H$10,MATCH(A14,梦灵图鉴!$G$11:$G$61,1),0)*SUM(梦灵属性!$E$27:$J$27)+OFFSET(梦灵图鉴!J$10,MATCH(A14,梦灵图鉴!$I$11:$I$61,1),0)*SUM(梦灵属性!$E$28:$J$28)+OFFSET(梦灵图鉴!L$10,MATCH(A14,梦灵图鉴!$K$11:$K$61,1),0)*SUM(梦灵属性!$E$29:$J$29) -> 2.718 | P14: 3 | Q14: 8 | R14: =OFFSET(梦灵属性!G$37,$P14-2,0) -> 0 | S14: =OFFSET(梦灵属性!H$37,$P14-2,0) -> 0 | T14: =OFFSET(梦灵属性!$E$37,$P14-2,0)*$Q14 -> 0.32 | U14: =OFFSET(梦灵属性!$E$37,$P14-2,0)*$Q14 -> 0.32
A15: 9 | B15: =OFFSET(梦灵本体产出!$G$6,MATCH(A15,梦灵本体产出!$I$7:$I$30,1),0) -> 6 | C15: =MATCH(A15,OFFSET(梦灵属性!#REF!,50*(B15-3),0)) -> #REF! | F15: =_xlfn.XLOOKUP(B15,梦灵属性!$F$38:$F$41,梦灵属性!$E$38:$E$41)*C15 -> #REF! | G15: =_xlfn.XLOOKUP($B15,梦灵属性!$F$38:$F$41,梦灵属性!$E$38:$E$41)*$C15 -> #REF! | I15: =OFFSET(梦灵图鉴!F$10,MATCH(A15,梦灵图鉴!$E$11:$E$61,1),0)*SUM(梦灵属性!$E$26:$J$26)+OFFSET(梦灵图鉴!H$10,MATCH(A15,梦灵图鉴!$G$11:$G$61,1),0)*SUM(梦灵属性!$E$27:$J$27)+OFFSET(梦灵图鉴!J$10,MATCH(A15,梦灵图鉴!$I$11:$I$61,1),0)*SUM(梦灵属性!$E$28:$J$28)+OFFSET(梦灵图鉴!L$10,MATCH(A15,梦灵图鉴!$K$11:$K$61,1),0)*SUM(梦灵属性!$E$29:$J$29) -> 2.802 | P15: 3 | Q15: 9 | R15: =OFFSET(梦灵属性!G$37,$P15-2,0) -> 0 | S15: =OFFSET(梦灵属性!H$37,$P15-2,0) -> 0 | T15: =OFFSET(梦灵属性!$E$37,$P15-2,0)*$Q15 -> 0.36 | U15: =OFFSET(梦灵属性!$E$37,$P15-2,0)*$Q15 -> 0.36
A16: 10 | B16: =OFFSET(梦灵本体产出!$G$6,MATCH(A16,梦灵本体产出!$I$7:$I$30,1),0) -> 6 | C16: =MATCH(A16,OFFSET(梦灵属性!#REF!,50*(B16-3),0)) -> #REF! | F16: =_xlfn.XLOOKUP(B16,梦灵属性!$F$38:$F$41,梦灵属性!$E$38:$E$41)*C16 -> #REF! | G16: =_xlfn.XLOOKUP($B16,梦灵属性!$F$38:$F$41,梦灵属性!$E$38:$E$41)*$C16 -> #REF! | I16: =OFFSET(梦灵图鉴!F$10,MATCH(A16,梦灵图鉴!$E$11:$E$61,1),0)*SUM(梦灵属性!$E$26:$J$26)+OFFSET(梦灵图鉴!H$10,MATCH(A16,梦灵图鉴!$G$11:$G$61,1),0)*SUM(梦灵属性!$E$27:$J$27)+OFFSET(梦灵图鉴!J$10,MATCH(A16,梦灵图鉴!$I$11:$I$61,1),0)*SUM(梦灵属性!$E$28:$J$28)+OFFSET(梦灵图鉴!L$10,MATCH(A16,梦灵图鉴!$K$11:$K$61,1),0)*SUM(梦灵属性!$E$29:$J$29) -> 2.874 | P16: 3 | Q16: 10 | R16: =OFFSET(梦灵属性!G$37,$P16-2,0) -> 0 | S16: =OFFSET(梦灵属性!H$37,$P16-2,0) -> 0 | T16: =OFFSET(梦灵属性!$E$37,$P16-2,0)*$Q16 -> 0.4 | U16: =OFFSET(梦灵属性!$E$37,$P16-2,0)*$Q16 -> 0.4
A17: 11 | B17: =OFFSET(梦灵本体产出!$G$6,MATCH(A17,梦灵本体产出!$I$7:$I$30,1),0) -> 6 | C17: =MATCH(A17,OFFSET(梦灵属性!#REF!,50*(B17-3),0)) -> #REF! | F17: =_xlfn.XLOOKUP(B17,梦灵属性!$F$38:$F$41,梦灵属性!$E$38:$E$41)*C17 -> #REF! | G17: =_xlfn.XLOOKUP($B17,梦灵属性!$F$38:$F$41,梦灵属性!$E$38:$E$41)*$C17 -> #REF! | I17: =OFFSET(梦灵图鉴!F$10,MATCH(A17,梦灵图鉴!$E$11:$E$61,1),0)*SUM(梦灵属性!$E$26:$J$26)+OFFSET(梦灵图鉴!H$10,MATCH(A17,梦灵图鉴!$G$11:$G$61,1),0)*SUM(梦灵属性!$E$27:$J$27)+OFFSET(梦灵图鉴!J$10,MATCH(A17,梦灵图鉴!$I$11:$I$61,1),0)*SUM(梦灵属性!$E$28:$J$28)+OFFSET(梦灵图鉴!L$10,MATCH(A17,梦灵图鉴!$K$11:$K$61,1),0)*SUM(梦灵属性!$E$29:$J$29) -> 3.072 | P17: 3 | Q17: 11 | R17: =OFFSET(梦灵属性!G$37,$P17-2,0) -> 0 | S17: =OFFSET(梦灵属性!H$37,$P17-2,0) -> 0 | T17: =OFFSET(梦灵属性!$E$37,$P17-2,0)*$Q17 -> 0.44 | U17: =OFFSET(梦灵属性!$E$37,$P17-2,0)*$Q17 -> 0.44
A18: 12 | B18: =OFFSET(梦灵本体产出!$G$6,MATCH(A18,梦灵本体产出!$I$7:$I$30,1),0) -> 6 | C18: =MATCH(A18,OFFSET(梦灵属性!#REF!,50*(B18-3),0)) -> #REF! | F18: =_xlfn.XLOOKUP(B18,梦灵属性!$F$38:$F$41,梦灵属性!$E$38:$E$41)*C18 -> #REF! | G18: =_xlfn.XLOOKUP($B18,梦灵属性!$F$38:$F$41,梦灵属性!$E$38:$E$41)*$C18 -> #REF! | I18: =OFFSET(梦灵图鉴!F$10,MATCH(A18,梦灵图鉴!$E$11:$E$61,1),0)*SUM(梦灵属性!$E$26:$J$26)+OFFSET(梦灵图鉴!H$10,MATCH(A18,梦灵图鉴!$G$11:$G$61,1),0)*SUM(梦灵属性!$E$27:$J$27)+OFFSET(梦灵图鉴!J$10,MATCH(A18,梦灵图鉴!$I$11:$I$61,1),0)*SUM(梦灵属性!$E$28:$J$28)+OFFSET(梦灵图鉴!L$10,MATCH(A18,梦灵图鉴!$K$11:$K$61,1),0)*SUM(梦灵属性!$E$29:$J$29) -> 3.252 | P18: 3 | Q18: 12 | R18: =OFFSET(梦灵属性!G$37,$P18-2,0) -> 0 | S18: =OFFSET(梦灵属性!H$37,$P18-2,0) -> 0 | T18: =OFFSET(梦灵属性!$E$37,$P18-2,0)*$Q18 -> 0.48 | U18: =OFFSET(梦灵属性!$E$37,$P18-2,0)*$Q18 -> 0.48
A19: 13 | B19: =OFFSET(梦灵本体产出!$G$6,MATCH(A19,梦灵本体产出!$I$7:$I$30,1),0) -> 6 | C19: =MATCH(A19,OFFSET(梦灵属性!#REF!,50*(B19-3),0)) -> #REF! | F19: =_xlfn.XLOOKUP(B19,梦灵属性!$F$38:$F$41,梦灵属性!$E$38:$E$41)*C19 -> #REF! | G19: =_xlfn.XLOOKUP($B19,梦灵属性!$F$38:$F$41,梦灵属性!$E$38:$E$41)*$C19 -> #REF! | I19: =OFFSET(梦灵图鉴!F$10,MATCH(A19,梦灵图鉴!$E$11:$E$61,1),0)*SUM(梦灵属性!$E$26:$J$26)+OFFSET(梦灵图鉴!H$10,MATCH(A19,梦灵图鉴!$G$11:$G$61,1),0)*SUM(梦灵属性!$E$27:$J$27)+OFFSET(梦灵图鉴!J$10,MATCH(A19,梦灵图鉴!$I$11:$I$61,1),0)*SUM(梦灵属性!$E$28:$J$28)+OFFSET(梦灵图鉴!L$10,MATCH(A19,梦灵图鉴!$K$11:$K$61,1),0)*SUM(梦灵属性!$E$29:$J$29) -> 3.822 | P19: 3 | Q19: 13 | R19: =OFFSET(梦灵属性!G$37,$P19-2,0) -> 0 | S19: =OFFSET(梦灵属性!H$37,$P19-2,0) -> 0 | T19: =OFFSET(梦灵属性!$E$37,$P19-2,0)*$Q19 -> 0.52 | U19: =OFFSET(梦灵属性!$E$37,$P19-2,0)*$Q19 -> 0.52
... A56: 50 | B56: =OFFSET(梦灵本体产出!$G$6,MATCH(A56,梦灵本体产出!$I$7:$I$30,1),0) -> 0 | C56: =MATCH(A56,OFFSET(梦灵属性!#REF!,50*(B56-3),0)) -> #REF! | F56: =_xlfn.XLOOKUP(B56,梦灵属性!$F$38:$F$41,梦灵属性!$E$38:$E$41)*C56 -> #N/A | G56: =_xlfn.XLOOKUP($B56,梦灵属性!$F$38:$F$41,梦灵属性!$E$38:$E$41)*$C56 -> #N/A | I56: =OFFSET(梦灵图鉴!F$10,MATCH(A56,梦灵图鉴!$E$11:$E$61,1),0)*SUM(梦灵属性!$E$26:$J$26)+OFFSET(梦灵图鉴!H$10,MATCH(A56,梦灵图鉴!$G$11:$G$61,1),0)*SUM(梦灵属性!$E$27:$J$27)+OFFSET(梦灵图鉴!J$10,MATCH(A56,梦灵图鉴!$I$11:$I$61,1),0)*SUM(梦灵属性!$E$28:$J$28)+OFFSET(梦灵图鉴!L$10,MATCH(A56,梦灵图鉴!$K$11:$K$61,1),0)*SUM(梦灵属性!$E$29:$J$29) -> 7.278 | P56: 3 | Q56: 50 | R56: =OFFSET(梦灵属性!G$37,$P56-2,0) -> 0 | S56: =OFFSET(梦灵属性!H$37,$P56-2,0) -> 0 | T56: =OFFSET(梦灵属性!$E$37,$P56-2,0)*$Q56 -> 2 | U56: =OFFSET(梦灵属性!$E$37,$P56-2,0)*$Q56 -> 2
A57: 51 | B57: =OFFSET(梦灵本体产出!$G$6,MATCH(A57,梦灵本体产出!$I$7:$I$30,1),0) -> 0 | C57: =MATCH(A57,OFFSET(梦灵属性!#REF!,50*(B57-3),0)) -> #REF! | F57: =_xlfn.XLOOKUP(B57,梦灵属性!$F$38:$F$41,梦灵属性!$E$38:$E$41)*C57 -> #N/A | G57: =_xlfn.XLOOKUP($B57,梦灵属性!$F$38:$F$41,梦灵属性!$E$38:$E$41)*$C57 -> #N/A | I57: =OFFSET(梦灵图鉴!F$10,MATCH(A57,梦灵图鉴!$E$11:$E$61,1),0)*SUM(梦灵属性!$E$26:$J$26)+OFFSET(梦灵图鉴!H$10,MATCH(A57,梦灵图鉴!$G$11:$G$61,1),0)*SUM(梦灵属性!$E$27:$J$27)+OFFSET(梦灵图鉴!J$10,MATCH(A57,梦灵图鉴!$I$11:$I$61,1),0)*SUM(梦灵属性!$E$28:$J$28)+OFFSET(梦灵图鉴!L$10,MATCH(A57,梦灵图鉴!$K$11:$K$61,1),0)*SUM(梦灵属性!$E$29:$J$29) -> 7.362 | P57: =P7+1 -> 4 | Q57: =Q7 -> 1 | R57: =OFFSET(梦灵属性!G$37,$P57-2,0) -> 60 | S57: =OFFSET(梦灵属性!H$37,$P57-2,0) -> 600 | T57: =OFFSET(梦灵属性!$E$37,$P57-2,0)*$Q57 -> 0.05 | U57: =OFFSET(梦灵属性!$E$37,$P57-2,0)*$Q57 -> 0.05
A58: 52 | B58: =OFFSET(梦灵本体产出!$G$6,MATCH(A58,梦灵本体产出!$I$7:$I$30,1),0) -> 0 | C58: =MATCH(A58,OFFSET(梦灵属性!#REF!,50*(B58-3),0)) -> #REF! | F58: =_xlfn.XLOOKUP(B58,梦灵属性!$F$38:$F$41,梦灵属性!$E$38:$E$41)*C58 -> #N/A | G58: =_xlfn.XLOOKUP($B58,梦灵属性!$F$38:$F$41,梦灵属性!$E$38:$E$41)*$C58 -> #N/A | I58: =OFFSET(梦灵图鉴!F$10,MATCH(A58,梦灵图鉴!$E$11:$E$61,1),0)*SUM(梦灵属性!$E$26:$J$26)+OFFSET(梦灵图鉴!H$10,MATCH(A58,梦灵图鉴!$G$11:$G$61,1),0)*SUM(梦灵属性!$E$27:$J$27)+OFFSET(梦灵图鉴!J$10,MATCH(A58,梦灵图鉴!$I$11:$I$61,1),0)*SUM(梦灵属性!$E$28:$J$28)+OFFSET(梦灵图鉴!L$10,MATCH(A58,梦灵图鉴!$K$11:$K$61,1),0)*SUM(梦灵属性!$E$29:$J$29) -> 7.458 | P58: =P8+1 -> 4 | Q58: =Q8 -> 2 | R58: =OFFSET(梦灵属性!G$37,$P58-2,0) -> 60 | S58: =OFFSET(梦灵属性!H$37,$P58-2,0) -> 600 | T58: =OFFSET(梦灵属性!$E$37,$P58-2,0)*$Q58 -> 0.1 | U58: =OFFSET(梦灵属性!$E$37,$P58-2,0)*$Q58 -> 0.1
A59: 53 | B59: =OFFSET(梦灵本体产出!$G$6,MATCH(A59,梦灵本体产出!$I$7:$I$30,1),0) -> 0 | C59: =MATCH(A59,OFFSET(梦灵属性!#REF!,50*(B59-3),0)) -> #REF! | F59: =_xlfn.XLOOKUP(B59,梦灵属性!$F$38:$F$41,梦灵属性!$E$38:$E$41)*C59 -> #N/A | G59: =_xlfn.XLOOKUP($B59,梦灵属性!$F$38:$F$41,梦灵属性!$E$38:$E$41)*$C59 -> #N/A | I59: =OFFSET(梦灵图鉴!F$10,MATCH(A59,梦灵图鉴!$E$11:$E$61,1),0)*SUM(梦灵属性!$E$26:$J$26)+OFFSET(梦灵图鉴!H$10,MATCH(A59,梦灵图鉴!$G$11:$G$61,1),0)*SUM(梦灵属性!$E$27:$J$27)+OFFSET(梦灵图鉴!J$10,MATCH(A59,梦灵图鉴!$I$11:$I$61,1),0)*SUM(梦灵属性!$E$28:$J$28)+OFFSET(梦灵图鉴!L$10,MATCH(A59,梦灵图鉴!$K$11:$K$61,1),0)*SUM(梦灵属性!$E$29:$J$29) -> 7.53 | P59: =P9+1 -> 4 | Q59: =Q9 -> 3 | R59: =OFFSET(梦灵属性!G$37,$P59-2,0) -> 60 | S59: =OFFSET(梦灵属性!H$37,$P59-2,0) -> 600 | T59: =OFFSET(梦灵属性!$E$37,$P59-2,0)*$Q59 -> 0.15 | U59: =OFFSET(梦灵属性!$E$37,$P59-2,0)*$Q59 -> 0.15
A60: 54 | B60: =OFFSET(梦灵本体产出!$G$6,MATCH(A60,梦灵本体产出!$I$7:$I$30,1),0) -> 0 | C60: =MATCH(A60,OFFSET(梦灵属性!#REF!,50*(B60-3),0)) -> #REF! | F60: =_xlfn.XLOOKUP(B60,梦灵属性!$F$38:$F$41,梦灵属性!$E$38:$E$41)*C60 -> #N/A | G60: =_xlfn.XLOOKUP($B60,梦灵属性!$F$38:$F$41,梦灵属性!$E$38:$E$41)*$C60 -> #N/A | I60: =OFFSET(梦灵图鉴!F$10,MATCH(A60,梦灵图鉴!$E$11:$E$61,1),0)*SUM(梦灵属性!$E$26:$J$26)+OFFSET(梦灵图鉴!H$10,MATCH(A60,梦灵图鉴!$G$11:$G$61,1),0)*SUM(梦灵属性!$E$27:$J$27)+OFFSET(梦灵图鉴!J$10,MATCH(A60,梦灵图鉴!$I$11:$I$61,1),0)*SUM(梦灵属性!$E$28:$J$28)+OFFSET(梦灵图鉴!L$10,MATCH(A60,梦灵图鉴!$K$11:$K$61,1),0)*SUM(梦灵属性!$E$29:$J$29) -> 7.53 | P60: =P10+1 -> 4 | Q60: =Q10 -> 4 | R60: =OFFSET(梦灵属性!G$37,$P60-2,0) -> 60 | S60: =OFFSET(梦灵属性!H$37,$P60-2,0) -> 600 | T60: =OFFSET(梦灵属性!$E$37,$P60-2,0)*$Q60 -> 0.2 | U60: =OFFSET(梦灵属性!$E$37,$P60-2,0)*$Q60 -> 0.2
A61: 55 | B61: =OFFSET(梦灵本体产出!$G$6,MATCH(A61,梦灵本体产出!$I$7:$I$30,1),0) -> 0 | C61: =MATCH(A61,OFFSET(梦灵属性!#REF!,50*(B61-3),0)) -> #REF! | F61: =_xlfn.XLOOKUP(B61,梦灵属性!$F$38:$F$41,梦灵属性!$E$38:$E$41)*C61 -> #N/A | G61: =_xlfn.XLOOKUP($B61,梦灵属性!$F$38:$F$41,梦灵属性!$E$38:$E$41)*$C61 -> #N/A | I61: =OFFSET(梦灵图鉴!F$10,MATCH(A61,梦灵图鉴!$E$11:$E$61,1),0)*SUM(梦灵属性!$E$26:$J$26)+OFFSET(梦灵图鉴!H$10,MATCH(A61,梦灵图鉴!$G$11:$G$61,1),0)*SUM(梦灵属性!$E$27:$J$27)+OFFSET(梦灵图鉴!J$10,MATCH(A61,梦灵图鉴!$I$11:$I$61,1),0)*SUM(梦灵属性!$E$28:$J$28)+OFFSET(梦灵图鉴!L$10,MATCH(A61,梦灵图鉴!$K$11:$K$61,1),0)*SUM(梦灵属性!$E$29:$J$29) -> 7.626 | P61: =P11+1 -> 4 | Q61: =Q11 -> 5 | R61: =OFFSET(梦灵属性!G$37,$P61-2,0) -> 60 | S61: =OFFSET(梦灵属性!H$37,$P61-2,0) -> 600 | T61: =OFFSET(梦灵属性!$E$37,$P61-2,0)*$Q61 -> 0.25 | U61: =OFFSET(梦灵属性!$E$37,$P61-2,0)*$Q61 -> 0.25
A62: 56 | B62: =OFFSET(梦灵本体产出!$G$6,MATCH(A62,梦灵本体产出!$I$7:$I$30,1),0) -> 0 | C62: =MATCH(A62,OFFSET(梦灵属性!#REF!,50*(B62-3),0)) -> #REF! | F62: =_xlfn.XLOOKUP(B62,梦灵属性!$F$38:$F$41,梦灵属性!$E$38:$E$41)*C62 -> #N/A | G62: =_xlfn.XLOOKUP($B62,梦灵属性!$F$38:$F$41,梦灵属性!$E$38:$E$41)*$C62 -> #N/A | I62: =OFFSET(梦灵图鉴!F$10,MATCH(A62,梦灵图鉴!$E$11:$E$61,1),0)*SUM(梦灵属性!$E$26:$J$26)+OFFSET(梦灵图鉴!H$10,MATCH(A62,梦灵图鉴!$G$11:$G$61,1),0)*SUM(梦灵属性!$E$27:$J$27)+OFFSET(梦灵图鉴!J$10,MATCH(A62,梦灵图鉴!$I$11:$I$61,1),0)*SUM(梦灵属性!$E$28:$J$28)+OFFSET(梦灵图鉴!L$10,MATCH(A62,梦灵图鉴!$K$11:$K$61,1),0)*SUM(梦灵属性!$E$29:$J$29) -> 7.74 | P62: =P12+1 -> 4 | Q62: =Q12 -> 6 | R62: =OFFSET(梦灵属性!G$37,$P62-2,0) -> 60 | S62: =OFFSET(梦灵属性!H$37,$P62-2,0) -> 600 | T62: =OFFSET(梦灵属性!$E$37,$P62-2,0)*$Q62 -> 0.3 | U62: =OFFSET(梦灵属性!$E$37,$P62-2,0)*$Q62 -> 0.3
A63: 57 | B63: =OFFSET(梦灵本体产出!$G$6,MATCH(A63,梦灵本体产出!$I$7:$I$30,1),0) -> 0 | C63: =MATCH(A63,OFFSET(梦灵属性!#REF!,50*(B63-3),0)) -> #REF! | F63: =_xlfn.XLOOKUP(B63,梦灵属性!$F$38:$F$41,梦灵属性!$E$38:$E$41)*C63 -> #N/A | G63: =_xlfn.XLOOKUP($B63,梦灵属性!$F$38:$F$41,梦灵属性!$E$38:$E$41)*$C63 -> #N/A | I63: =OFFSET(梦灵图鉴!F$10,MATCH(A63,梦灵图鉴!$E$11:$E$61,1),0)*SUM(梦灵属性!$E$26:$J$26)+OFFSET(梦灵图鉴!H$10,MATCH(A63,梦灵图鉴!$G$11:$G$61,1),0)*SUM(梦灵属性!$E$27:$J$27)+OFFSET(梦灵图鉴!J$10,MATCH(A63,梦灵图鉴!$I$11:$I$61,1),0)*SUM(梦灵属性!$E$28:$J$28)+OFFSET(梦灵图鉴!L$10,MATCH(A63,梦灵图鉴!$K$11:$K$61,1),0)*SUM(梦灵属性!$E$29:$J$29) -> 7.74 | P63: =P13+1 -> 4 | Q63: =Q13 -> 7 | R63: =OFFSET(梦灵属性!G$37,$P63-2,0) -> 60 | S63: =OFFSET(梦灵属性!H$37,$P63-2,0) -> 600 | T63: =OFFSET(梦灵属性!$E$37,$P63-2,0)*$Q63 -> 0.35 | U63: =OFFSET(梦灵属性!$E$37,$P63-2,0)*$Q63 -> 0.35
A64: 58 | B64: =OFFSET(梦灵本体产出!$G$6,MATCH(A64,梦灵本体产出!$I$7:$I$30,1),0) -> 0 | C64: =MATCH(A64,OFFSET(梦灵属性!#REF!,50*(B64-3),0)) -> #REF! | F64: =_xlfn.XLOOKUP(B64,梦灵属性!$F$38:$F$41,梦灵属性!$E$38:$E$41)*C64 -> #N/A | G64: =_xlfn.XLOOKUP($B64,梦灵属性!$F$38:$F$41,梦灵属性!$E$38:$E$41)*$C64 -> #N/A | I64: =OFFSET(梦灵图鉴!F$10,MATCH(A64,梦灵图鉴!$E$11:$E$61,1),0)*SUM(梦灵属性!$E$26:$J$26)+OFFSET(梦灵图鉴!H$10,MATCH(A64,梦灵图鉴!$G$11:$G$61,1),0)*SUM(梦灵属性!$E$27:$J$27)+OFFSET(梦灵图鉴!J$10,MATCH(A64,梦灵图鉴!$I$11:$I$61,1),0)*SUM(梦灵属性!$E$28:$J$28)+OFFSET(梦灵图鉴!L$10,MATCH(A64,梦灵图鉴!$K$11:$K$61,1),0)*SUM(梦灵属性!$E$29:$J$29) -> 7.836 | P64: =P14+1 -> 4 | Q64: =Q14 -> 8 | R64: =OFFSET(梦灵属性!G$37,$P64-2,0) -> 60 | S64: =OFFSET(梦灵属性!H$37,$P64-2,0) -> 600 | T64: =OFFSET(梦灵属性!$E$37,$P64-2,0)*$Q64 -> 0.4 | U64: =OFFSET(梦灵属性!$E$37,$P64-2,0)*$Q64 -> 0.4
A65: 59 | B65: =OFFSET(梦灵本体产出!$G$6,MATCH(A65,梦灵本体产出!$I$7:$I$30,1),0) -> 0 | C65: =MATCH(A65,OFFSET(梦灵属性!#REF!,50*(B65-3),0)) -> #REF! | F65: =_xlfn.XLOOKUP(B65,梦灵属性!$F$38:$F$41,梦灵属性!$E$38:$E$41)*C65 -> #N/A | G65: =_xlfn.XLOOKUP($B65,梦灵属性!$F$38:$F$41,梦灵属性!$E$38:$E$41)*$C65 -> #N/A | I65: =OFFSET(梦灵图鉴!F$10,MATCH(A65,梦灵图鉴!$E$11:$E$61,1),0)*SUM(梦灵属性!$E$26:$J$26)+OFFSET(梦灵图鉴!H$10,MATCH(A65,梦灵图鉴!$G$11:$G$61,1),0)*SUM(梦灵属性!$E$27:$J$27)+OFFSET(梦灵图鉴!J$10,MATCH(A65,梦灵图鉴!$I$11:$I$61,1),0)*SUM(梦灵属性!$E$28:$J$28)+OFFSET(梦灵图鉴!L$10,MATCH(A65,梦灵图鉴!$K$11:$K$61,1),0)*SUM(梦灵属性!$E$29:$J$29) -> 7.836 | P65: =P15+1 -> 4 | Q65: =Q15 -> 9 | R65: =OFFSET(梦灵属性!G$37,$P65-2,0) -> 60 | S65: =OFFSET(梦灵属性!H$37,$P65-2,0) -> 600 | T65: =OFFSET(梦灵属性!$E$37,$P65-2,0)*$Q65 -> 0.45 | U65: =OFFSET(梦灵属性!$E$37,$P65-2,0)*$Q65 -> 0.45
A66: 60 | B66: =OFFSET(梦灵本体产出!$G$6,MATCH(A66,梦灵本体产出!$I$7:$I$30,1),0) -> 0 | C66: =MATCH(A66,OFFSET(梦灵属性!#REF!,50*(B66-3),0)) -> #REF! | F66: =_xlfn.XLOOKUP(B66,梦灵属性!$F$38:$F$41,梦灵属性!$E$38:$E$41)*C66 -> #N/A | G66: =_xlfn.XLOOKUP($B66,梦灵属性!$F$38:$F$41,梦灵属性!$E$38:$E$41)*$C66 -> #N/A | I66: =OFFSET(梦灵图鉴!F$10,MATCH(A66,梦灵图鉴!$E$11:$E$61,1),0)*SUM(梦灵属性!$E$26:$J$26)+OFFSET(梦灵图鉴!H$10,MATCH(A66,梦灵图鉴!$G$11:$G$61,1),0)*SUM(梦灵属性!$E$27:$J$27)+OFFSET(梦灵图鉴!J$10,MATCH(A66,梦灵图鉴!$I$11:$I$61,1),0)*SUM(梦灵属性!$E$28:$J$28)+OFFSET(梦灵图鉴!L$10,MATCH(A66,梦灵图鉴!$K$11:$K$61,1),0)*SUM(梦灵属性!$E$29:$J$29) -> 14.1 | P66: =P16+1 -> 4 | Q66: =Q16 -> 10 | R66: =OFFSET(梦灵属性!G$37,$P66-2,0) -> 60 | S66: =OFFSET(梦灵属性!H$37,$P66-2,0) -> 600 | T66: =OFFSET(梦灵属性!$E$37,$P66-2,0)*$Q66 -> 0.5 | U66: =OFFSET(梦灵属性!$E$37,$P66-2,0)*$Q66 -> 0.5
A67: 61 | B67: =OFFSET(梦灵本体产出!$G$6,MATCH(A67,梦灵本体产出!$I$7:$I$30,1),0) -> 0 | C67: =MATCH(A67,OFFSET(梦灵属性!#REF!,50*(B67-3),0)) -> #REF! | F67: =_xlfn.XLOOKUP(B67,梦灵属性!$F$38:$F$41,梦灵属性!$E$38:$E$41)*C67 -> #N/A | G67: =_xlfn.XLOOKUP($B67,梦灵属性!$F$38:$F$41,梦灵属性!$E$38:$E$41)*$C67 -> #N/A | I67: =OFFSET(梦灵图鉴!F$10,MATCH(A67,梦灵图鉴!$E$11:$E$61,1),0)*SUM(梦灵属性!$E$26:$J$26)+OFFSET(梦灵图鉴!H$10,MATCH(A67,梦灵图鉴!$G$11:$G$61,1),0)*SUM(梦灵属性!$E$27:$J$27)+OFFSET(梦灵图鉴!J$10,MATCH(A67,梦灵图鉴!$I$11:$I$61,1),0)*SUM(梦灵属性!$E$28:$J$28)+OFFSET(梦灵图鉴!L$10,MATCH(A67,梦灵图鉴!$K$11:$K$61,1),0)*SUM(梦灵属性!$E$29:$J$29) -> 14.1 | P67: =P17+1 -> 4 | Q67: =Q17 -> 11 | R67: =OFFSET(梦灵属性!G$37,$P67-2,0) -> 60 | S67: =OFFSET(梦灵属性!H$37,$P67-2,0) -> 600 | T67: =OFFSET(梦灵属性!$E$37,$P67-2,0)*$Q67 -> 0.55 | U67: =OFFSET(梦灵属性!$E$37,$P67-2,0)*$Q67 -> 0.55
A68: 62 | B68: =OFFSET(梦灵本体产出!$G$6,MATCH(A68,梦灵本体产出!$I$7:$I$30,1),0) -> 0 | C68: =MATCH(A68,OFFSET(梦灵属性!#REF!,50*(B68-3),0)) -> #REF! | F68: =_xlfn.XLOOKUP(B68,梦灵属性!$F$38:$F$41,梦灵属性!$E$38:$E$41)*C68 -> #N/A | G68: =_xlfn.XLOOKUP($B68,梦灵属性!$F$38:$F$41,梦灵属性!$E$38:$E$41)*$C68 -> #N/A | I68: =OFFSET(梦灵图鉴!F$10,MATCH(A68,梦灵图鉴!$E$11:$E$61,1),0)*SUM(梦灵属性!$E$26:$J$26)+OFFSET(梦灵图鉴!H$10,MATCH(A68,梦灵图鉴!$G$11:$G$61,1),0)*SUM(梦灵属性!$E$27:$J$27)+OFFSET(梦灵图鉴!J$10,MATCH(A68,梦灵图鉴!$I$11:$I$61,1),0)*SUM(梦灵属性!$E$28:$J$28)+OFFSET(梦灵图鉴!L$10,MATCH(A68,梦灵图鉴!$K$11:$K$61,1),0)*SUM(梦灵属性!$E$29:$J$29) -> 14.1 | P68: =P18+1 -> 4 | Q68: =Q18 -> 12 | R68: =OFFSET(梦灵属性!G$37,$P68-2,0) -> 60 | S68: =OFFSET(梦灵属性!H$37,$P68-2,0) -> 600 | T68: =OFFSET(梦灵属性!$E$37,$P68-2,0)*$Q68 -> 0.6 | U68: =OFFSET(梦灵属性!$E$37,$P68-2,0)*$Q68 -> 0.6
... A206: 200 | B206: =OFFSET(梦灵本体产出!$G$6,MATCH(A206,梦灵本体产出!$I$7:$I$30,1),0) -> 0 | C206: =MATCH(A206,OFFSET(梦灵属性!#REF!,50*(B206-3),0)) -> #REF! | F206: =_xlfn.XLOOKUP(B206,梦灵属性!$F$38:$F$41,梦灵属性!$E$38:$E$41)*C206 -> #N/A | G206: =_xlfn.XLOOKUP($B206,梦灵属性!$F$38:$F$41,梦灵属性!$E$38:$E$41)*$C206 -> #N/A | I206: =OFFSET(梦灵图鉴!F$10,MATCH(A206,梦灵图鉴!$E$11:$E$61,1),0)*SUM(梦灵属性!$E$26:$J$26)+OFFSET(梦灵图鉴!H$10,MATCH(A206,梦灵图鉴!$G$11:$G$61,1),0)*SUM(梦灵属性!$E$27:$J$27)+OFFSET(梦灵图鉴!J$10,MATCH(A206,梦灵图鉴!$I$11:$I$61,1),0)*SUM(梦灵属性!$E$28:$J$28)+OFFSET(梦灵图鉴!L$10,MATCH(A206,梦灵图鉴!$K$11:$K$61,1),0)*SUM(梦灵属性!$E$29:$J$29) -> 14.1 | P206: =P156+1 -> 6 | Q206: =Q156 -> 50 | R206: =OFFSET(梦灵属性!G$37,$P206-2,0) -> 180 | S206: =OFFSET(梦灵属性!H$37,$P206-2,0) -> 1800 | T206: =OFFSET(梦灵属性!$E$37,$P206-2,0)*$Q206 -> 5 | U206: =OFFSET(梦灵属性!$E$37,$P206-2,0)*$Q206 -> 5
A207: 201 | B207: =OFFSET(梦灵本体产出!$G$6,MATCH(A207,梦灵本体产出!$I$7:$I$30,1),0) -> 0 | C207: =MATCH(A207,OFFSET(梦灵属性!#REF!,50*(B207-3),0)) -> #REF! | F207: =_xlfn.XLOOKUP(B207,梦灵属性!$F$38:$F$41,梦灵属性!$E$38:$E$41)*C207 -> #N/A | G207: =_xlfn.XLOOKUP($B207,梦灵属性!$F$38:$F$41,梦灵属性!$E$38:$E$41)*$C207 -> #N/A | I207: =OFFSET(梦灵图鉴!F$10,MATCH(A207,梦灵图鉴!$E$11:$E$61,1),0)*SUM(梦灵属性!$E$26:$J$26)+OFFSET(梦灵图鉴!H$10,MATCH(A207,梦灵图鉴!$G$11:$G$61,1),0)*SUM(梦灵属性!$E$27:$J$27)+OFFSET(梦灵图鉴!J$10,MATCH(A207,梦灵图鉴!$I$11:$I$61,1),0)*SUM(梦灵属性!$E$28:$J$28)+OFFSET(梦灵图鉴!L$10,MATCH(A207,梦灵图鉴!$K$11:$K$61,1),0)*SUM(梦灵属性!$E$29:$J$29) -> 14.1
A208: 202 | B208: =OFFSET(梦灵本体产出!$G$6,MATCH(A208,梦灵本体产出!$I$7:$I$30,1),0) -> 0 | C208: =MATCH(A208,OFFSET(梦灵属性!#REF!,50*(B208-3),0)) -> #REF! | F208: =_xlfn.XLOOKUP(B208,梦灵属性!$F$38:$F$41,梦灵属性!$E$38:$E$41)*C208 -> #N/A | G208: =_xlfn.XLOOKUP($B208,梦灵属性!$F$38:$F$41,梦灵属性!$E$38:$E$41)*$C208 -> #N/A | I208: =OFFSET(梦灵图鉴!F$10,MATCH(A208,梦灵图鉴!$E$11:$E$61,1),0)*SUM(梦灵属性!$E$26:$J$26)+OFFSET(梦灵图鉴!H$10,MATCH(A208,梦灵图鉴!$G$11:$G$61,1),0)*SUM(梦灵属性!$E$27:$J$27)+OFFSET(梦灵图鉴!J$10,MATCH(A208,梦灵图鉴!$I$11:$I$61,1),0)*SUM(梦灵属性!$E$28:$J$28)+OFFSET(梦灵图鉴!L$10,MATCH(A208,梦灵图鉴!$K$11:$K$61,1),0)*SUM(梦灵属性!$E$29:$J$29) -> 14.1
A209: 203 | B209: =OFFSET(梦灵本体产出!$G$6,MATCH(A209,梦灵本体产出!$I$7:$I$30,1),0) -> 0 | C209: =MATCH(A209,OFFSET(梦灵属性!#REF!,50*(B209-3),0)) -> #REF! | F209: =_xlfn.XLOOKUP(B209,梦灵属性!$F$38:$F$41,梦灵属性!$E$38:$E$41)*C209 -> #N/A | G209: =_xlfn.XLOOKUP($B209,梦灵属性!$F$38:$F$41,梦灵属性!$E$38:$E$41)*$C209 -> #N/A | I209: =OFFSET(梦灵图鉴!F$10,MATCH(A209,梦灵图鉴!$E$11:$E$61,1),0)*SUM(梦灵属性!$E$26:$J$26)+OFFSET(梦灵图鉴!H$10,MATCH(A209,梦灵图鉴!$G$11:$G$61,1),0)*SUM(梦灵属性!$E$27:$J$27)+OFFSET(梦灵图鉴!J$10,MATCH(A209,梦灵图鉴!$I$11:$I$61,1),0)*SUM(梦灵属性!$E$28:$J$28)+OFFSET(梦灵图鉴!L$10,MATCH(A209,梦灵图鉴!$K$11:$K$61,1),0)*SUM(梦灵属性!$E$29:$J$29) -> 14.1
A210: 204 | B210: =OFFSET(梦灵本体产出!$G$6,MATCH(A210,梦灵本体产出!$I$7:$I$30,1),0) -> 0 | C210: =MATCH(A210,OFFSET(梦灵属性!#REF!,50*(B210-3),0)) -> #REF! | F210: =_xlfn.XLOOKUP(B210,梦灵属性!$F$38:$F$41,梦灵属性!$E$38:$E$41)*C210 -> #N/A | G210: =_xlfn.XLOOKUP($B210,梦灵属性!$F$38:$F$41,梦灵属性!$E$38:$E$41)*$C210 -> #N/A | I210: =OFFSET(梦灵图鉴!F$10,MATCH(A210,梦灵图鉴!$E$11:$E$61,1),0)*SUM(梦灵属性!$E$26:$J$26)+OFFSET(梦灵图鉴!H$10,MATCH(A210,梦灵图鉴!$G$11:$G$61,1),0)*SUM(梦灵属性!$E$27:$J$27)+OFFSET(梦灵图鉴!J$10,MATCH(A210,梦灵图鉴!$I$11:$I$61,1),0)*SUM(梦灵属性!$E$28:$J$28)+OFFSET(梦灵图鉴!L$10,MATCH(A210,梦灵图鉴!$K$11:$K$61,1),0)*SUM(梦灵属性!$E$29:$J$29) -> 14.1
A211: 205 | B211: =OFFSET(梦灵本体产出!$G$6,MATCH(A211,梦灵本体产出!$I$7:$I$30,1),0) -> 0 | C211: =MATCH(A211,OFFSET(梦灵属性!#REF!,50*(B211-3),0)) -> #REF! | F211: =_xlfn.XLOOKUP(B211,梦灵属性!$F$38:$F$41,梦灵属性!$E$38:$E$41)*C211 -> #N/A | G211: =_xlfn.XLOOKUP($B211,梦灵属性!$F$38:$F$41,梦灵属性!$E$38:$E$41)*$C211 -> #N/A | I211: =OFFSET(梦灵图鉴!F$10,MATCH(A211,梦灵图鉴!$E$11:$E$61,1),0)*SUM(梦灵属性!$E$26:$J$26)+OFFSET(梦灵图鉴!H$10,MATCH(A211,梦灵图鉴!$G$11:$G$61,1),0)*SUM(梦灵属性!$E$27:$J$27)+OFFSET(梦灵图鉴!J$10,MATCH(A211,梦灵图鉴!$I$11:$I$61,1),0)*SUM(梦灵属性!$E$28:$J$28)+OFFSET(梦灵图鉴!L$10,MATCH(A211,梦灵图鉴!$K$11:$K$61,1),0)*SUM(梦灵属性!$E$29:$J$29) -> 14.1
A212: 206 | B212: =OFFSET(梦灵本体产出!$G$6,MATCH(A212,梦灵本体产出!$I$7:$I$30,1),0) -> 0 | C212: =MATCH(A212,OFFSET(梦灵属性!#REF!,50*(B212-3),0)) -> #REF! | F212: =_xlfn.XLOOKUP(B212,梦灵属性!$F$38:$F$41,梦灵属性!$E$38:$E$41)*C212 -> #N/A | G212: =_xlfn.XLOOKUP($B212,梦灵属性!$F$38:$F$41,梦灵属性!$E$38:$E$41)*$C212 -> #N/A | I212: =OFFSET(梦灵图鉴!F$10,MATCH(A212,梦灵图鉴!$E$11:$E$61,1),0)*SUM(梦灵属性!$E$26:$J$26)+OFFSET(梦灵图鉴!H$10,MATCH(A212,梦灵图鉴!$G$11:$G$61,1),0)*SUM(梦灵属性!$E$27:$J$27)+OFFSET(梦灵图鉴!J$10,MATCH(A212,梦灵图鉴!$I$11:$I$61,1),0)*SUM(梦灵属性!$E$28:$J$28)+OFFSET(梦灵图鉴!L$10,MATCH(A212,梦灵图鉴!$K$11:$K$61,1),0)*SUM(梦灵属性!$E$29:$J$29) -> 14.1
